5:return {{["x"] = 0, ["y"] = 0, ["z"] = 0, ["name"] = "default:stone_block"}, {["x"] = 0, ["param2"] = 1, ["y"] = 0, ["param1"] = 94, ["z"] = 1, ["name"] = "stairs:stair_stonebrick"}, {["x"] = 0, ["param2"] = 1, ["y"] = 0, ["param1"] = 78, ["z"] = 2, ["name"] = "stairs:stair_stonebrick"}, {["x"] = 0, ["y"] = 0, ["z"] = 3, ["name"] = "default:stone_block"}, {["x"] = 0, ["param2"] = 1, ["y"] = 0, ["param1"] = 62, ["z"] = 4, ["name"] = "stairs:stair_stonebrick"}, {["x"] = 0, ["param2"] = 1, ["y"] = 0, ["param1"] = 78, ["z"] = 5, ["name"] = "stairs:stair_stonebrick"}, {["x"] = 0, ["y"] = 0, ["z"] = 6, ["name"] = "default:stone_block"}, {["x"] = 0, ["param2"] = 1, ["y"] = 0, ["param1"] = 78, ["z"] = 7, ["name"] = "stairs:stair_stonebrick"}, {["x"] = 0, ["param2"] = 1, ["y"] = 0, ["param1"] = 78, ["z"] = 8, ["name"] = "stairs:stair_stonebrick"}, {["x"] = 0, ["y"] = 0, ["z"] = 9, ["name"] = "default:stone_block"}, {["x"] = 0, ["param2"] = 1, ["y"] = 0, ["param1"] = 77, ["z"] = 10, ["name"] = "stairs:stair_stonebrick"}, {["x"] = 0, ["param2"] = 1, ["y"] = 0, ["param1"] = 62, ["z"] = 11, ["name"] = "stairs:stair_stonebrick"}, {["x"] = 0, ["y"] = 0, ["z"] = 12, ["name"] = "default:stone_block"}, {["x"] = 0, ["param2"] = 1, ["y"] = 0, ["param1"] = 78, ["z"] = 13, ["name"] = "stairs:stair_stonebrick"}, {["x"] = 0, ["param2"] = 1, ["y"] = 0, ["param1"] = 94, ["z"] = 14, ["name"] = "stairs:stair_stonebrick"}, {["x"] = 0, ["y"] = 0, ["z"] = 15, ["name"] = "default:stone_block"}, {["x"] = 1, ["y"] = 0, ["param1"] = 4, ["z"] = 0, ["name"] = "default:stone_block"}, {["x"] = 1, ["y"] = 0, ["param1"] = 4, ["z"] = 1, ["name"] = "default:stone_block"}, {["x"] = 1, ["y"] = 0, ["param1"] = 4, ["z"] = 2, ["name"] = "default:stone_block"}, {["x"] = 1, ["y"] = 0, ["param1"] = 4, ["z"] = 3, ["name"] = "default:stone_block"}, {["x"] = 1, ["y"] = 0, ["param1"] = 4, ["z"] = 4, ["name"] = "default:stone_block"}, {["x"] = 1, ["y"] = 0, ["param1"] = 4, ["z"] = 5, ["name"] = "default:stone_block"}, {["x"] = 1, ["y"] = 0, ["param1"] = 4, ["z"] = 6, ["name"] = "default:stone_block"}, {["x"] = 1, ["y"] = 0, ["param1"] = 4, ["z"] = 7, ["name"] = "default:stone_block"}, {["x"] = 1, ["y"] = 0, ["param1"] = 4, ["z"] = 8, ["name"] = "default:stone_block"}, {["x"] = 1, ["y"] = 0, ["param1"] = 4, ["z"] = 9, ["name"] = "default:stone_block"}, {["x"] = 1, ["y"] = 0, ["param1"] = 4, ["z"] = 10, ["name"] = "default:stone_block"}, {["x"] = 1, ["y"] = 0, ["param1"] = 4, ["z"] = 11, ["name"] = "default:stone_block"}, {["x"] = 1, ["y"] = 0, ["param1"] = 4, ["z"] = 12, ["name"] = "default:stone_block"}, {["x"] = 1, ["y"] = 0, ["param1"] = 4, ["z"] = 13, ["name"] = "default:stone_block"}, {["x"] = 1, ["y"] = 0, ["param1"] = 4, ["z"] = 14, ["name"] = "default:stone_block"}, {["x"] = 1, ["y"] = 0, ["param1"] = 4, ["z"] = 15, ["name"] = "default:stone_block"}, {["x"] = 1, ["y"] = 1, ["param1"] = 110, ["z"] = 0, ["name"] = "walls:cobble"}, {["x"] = 1, ["y"] = 1, ["param1"] = 94, ["z"] = 3, ["name"] = "walls:cobble"}, {["x"] = 1, ["y"] = 1, ["param1"] = 94, ["z"] = 6, ["name"] = "walls:cobble"}, {["x"] = 1, ["y"] = 1, ["param1"] = 94, ["z"] = 9, ["name"] = "walls:cobble"}, {["x"] = 1, ["y"] = 1, ["param1"] = 94, ["z"] = 12, ["name"] = "walls:cobble"}, {["x"] = 1, ["y"] = 1, ["param1"] = 110, ["z"] = 15, ["name"] = "walls:cobble"}, {["x"] = 1, ["y"] = 2, ["param1"] = 126, ["z"] = 0, ["name"] = "walls:cobble"}, {["x"] = 1, ["y"] = 2, ["param1"] = 110, ["z"] = 3, ["name"] = "walls:cobble"}, {["x"] = 1, ["y"] = 2, ["param1"] = 110, ["z"] = 6, ["name"] = "walls:cobble"}, {["x"] = 1, ["y"] = 2, ["param1"] = 110, ["z"] = 9, ["name"] = "walls:cobble"}, {["x"] = 1, ["y"] = 2, ["param1"] = 110, ["z"] = 12, ["name"] = "walls:cobble"}, {["x"] = 1, ["y"] = 2, ["param1"] = 126, ["z"] = 15, ["name"] = "walls:cobble"}, {["x"] = 1, ["y"] = 3, ["param1"] = 142, ["z"] = 0, ["name"] = "walls:cobble"}, {["x"] = 1, ["y"] = 3, ["param1"] = 126, ["z"] = 3, ["name"] = "walls:cobble"}, {["x"] = 1, ["y"] = 3, ["param1"] = 126, ["z"] = 6, ["name"] = "walls:cobble"}, {["x"] = 1, ["y"] = 3, ["param1"] = 126, ["z"] = 9, ["name"] = "walls:cobble"}, {["x"] = 1, ["y"] = 3, ["param1"] = 126, ["z"] = 12, ["name"] = "walls:cobble"}, {["x"] = 1, ["y"] = 3, ["param1"] = 142, ["z"] = 15, ["name"] = "walls:cobble"}, {["x"] = 1, ["y"] = 4, ["param1"] = 158, ["z"] = 0, ["name"] = "walls:cobble"}, {["x"] = 1, ["y"] = 4, ["param1"] = 142, ["z"] = 3, ["name"] = "walls:cobble"}, {["x"] = 1, ["y"] = 4, ["param1"] = 142, ["z"] = 6, ["name"] = "walls:cobble"}, {["x"] = 1, ["y"] = 4, ["param1"] = 142, ["z"] = 9, ["name"] = "walls:cobble"}, {["x"] = 1, ["y"] = 4, ["param1"] = 142, ["z"] = 12, ["name"] = "walls:cobble"}, {["x"] = 1, ["y"] = 4, ["param1"] = 158, ["z"] = 15, ["name"] = "walls:cobble"}, {["x"] = 1, ["y"] = 5, ["param1"] = 174, ["z"] = 0, ["name"] = "walls:cobble"}, {["x"] = 1, ["y"] = 5, ["param1"] = 158, ["z"] = 3, ["name"] = "walls:cobble"}, {["x"] = 1, ["y"] = 5, ["param1"] = 158, ["z"] = 6, ["name"] = "walls:cobble"}, {["x"] = 1, ["y"] = 5, ["param1"] = 158, ["z"] = 9, ["name"] = "walls:cobble"}, {["x"] = 1, ["y"] = 5, ["param1"] = 158, ["z"] = 12, ["name"] = "walls:cobble"}, {["x"] = 1, ["y"] = 5, ["param1"] = 174, ["z"] = 15, ["name"] = "walls:cobble"}, {["x"] = 1, ["y"] = 6, ["param1"] = 158, ["z"] = 0, ["name"] = "stairs:slab_silver_sandstone"}, {["x"] = 1, ["y"] = 6, ["param1"] = 174, ["z"] = 1, ["name"] = "stairs:slab_silver_sandstone"}, {["x"] = 1, ["y"] = 6, ["param1"] = 158, ["z"] = 2, ["name"] = "stairs:slab_silver_sandstone"}, {["x"] = 1, ["y"] = 6, ["param1"] = 142, ["z"] = 3, ["name"] = "stairs:slab_silver_sandstone"}, {["x"] = 1, ["y"] = 6, ["param1"] = 142, ["z"] = 4, ["name"] = "stairs:slab_silver_sandstone"}, {["x"] = 1, ["y"] = 6, ["param1"] = 158, ["z"] = 5, ["name"] = "stairs:slab_silver_sandstone"}, {["x"] = 1, ["y"] = 6, ["param1"] = 142, ["z"] = 6, ["name"] = "stairs:slab_silver_sandstone"}, {["x"] = 1, ["y"] = 6, ["param1"] = 158, ["z"] = 7, ["name"] = "stairs:slab_silver_sandstone"}, {["x"] = 1, ["y"] = 6, ["param1"] = 158, ["z"] = 8, ["name"] = "stairs:slab_silver_sandstone"}, {["x"] = 1, ["y"] = 6, ["param1"] = 142, ["z"] = 9, ["name"] = "stairs:slab_silver_sandstone"}, {["x"] = 1, ["y"] = 6, ["param1"] = 158, ["z"] = 10, ["name"] = "stairs:slab_silver_sandstone"}, {["x"] = 1, ["y"] = 6, ["param1"] = 142, ["z"] = 11, ["name"] = "stairs:slab_silver_sandstone"}, {["x"] = 1, ["y"] = 6, ["param1"] = 142, ["z"] = 12, ["name"] = "stairs:slab_silver_sandstone"}, {["x"] = 1, ["y"] = 6, ["param1"] = 158, ["z"] = 13, ["name"] = "stairs:slab_silver_sandstone"}, {["x"] = 1, ["y"] = 6, ["param1"] = 174, ["z"] = 14, ["name"] = "stairs:slab_silver_sandstone"}, {["x"] = 1, ["y"] = 6, ["param1"] = 158, ["z"] = 15, ["name"] = "stairs:slab_silver_sandstone"}, {["x"] = 2, ["y"] = 0, ["param1"] = 4, ["z"] = 0, ["name"] = "default:stone_block"}, {["x"] = 2, ["y"] = 0, ["param1"] = 4, ["z"] = 1, ["name"] = "default:stone_block"}, {["x"] = 2, ["y"] = 0, ["param1"] = 4, ["z"] = 2, ["name"] = "default:stone_block"}, {["x"] = 2, ["y"] = 0, ["param1"] = 4, ["z"] = 3, ["name"] = "default:stone_block"}, {["x"] = 2, ["y"] = 0, ["param1"] = 4, ["z"] = 4, ["name"] = "default:stone_block"}, {["x"] = 2, ["y"] = 0, ["param1"] = 4, ["z"] = 5, ["name"] = "default:stone_block"}, {["x"] = 2, ["y"] = 0, ["param1"] = 4, ["z"] = 6, ["name"] = "default:stone_block"}, {["x"] = 2, ["y"] = 0, ["param1"] = 4, ["z"] = 7, ["name"] = "default:stone_block"}, {["x"] = 2, ["y"] = 0, ["param1"] = 4, ["z"] = 8, ["name"] = "default:stone_block"}, {["x"] = 2, ["y"] = 0, ["param1"] = 4, ["z"] = 9, ["name"] = "default:stone_block"}, {["x"] = 2, ["y"] = 0, ["param1"] = 4, ["z"] = 10, ["name"] = "default:stone_block"}, {["x"] = 2, ["y"] = 0, ["param1"] = 4, ["z"] = 11, ["name"] = "default:stone_block"}, {["x"] = 2, ["y"] = 0, ["param1"] = 4, ["z"] = 12, ["name"] = "default:stone_block"}, {["x"] = 2, ["y"] = 0, ["param1"] = 4, ["z"] = 13, ["name"] = "default:stone_block"}, {["x"] = 2, ["y"] = 0, ["param1"] = 4, ["z"] = 14, ["name"] = "default:stone_block"}, {["x"] = 2, ["y"] = 0, ["param1"] = 4, ["z"] = 15, ["name"] = "default:stone_block"}, {["x"] = 2, ["meta"] = {["fields"] = {["infotext"] = "\27(T@default)\"\27Fof minetest\27E\"\27E", ["text"] = "of minetest", ["formspec"] = "field[text;;${text}]"}, ["inventory"] = {}}, ["param2"] = 2, ["y"] = 4, ["param1"] = 173, ["z"] = 7, ["name"] = "default:sign_wall_wood"}, {["x"] = 2, ["meta"] = {["fields"] = {["infotext"] = "\27(T@default)\"\27FCentral bank\27E\"\27E", ["text"] = "Central bank", ["formspec"] = "field[text;;${text}]"}, ["inventory"] = {}}, ["param2"] = 2, ["y"] = 4, ["param1"] = 173, ["z"] = 8, ["name"] = "default:sign_wall_wood"}, {["x"] = 2, ["param2"] = 1, ["y"] = 6, ["param1"] = 174, ["z"] = 0, ["name"] = "stairs:stair_silver_sandstone"}, {["x"] = 2, ["param2"] = 1, ["y"] = 6, ["param1"] = 190, ["z"] = 1, ["name"] = "stairs:stair_silver_sandstone"}, {["x"] = 2, ["param2"] = 1, ["y"] = 6, ["param1"] = 174, ["z"] = 2, ["name"] = "stairs:stair_silver_sandstone"}, {["x"] = 2, ["param2"] = 1, ["y"] = 6, ["param1"] = 158, ["z"] = 3, ["name"] = "stairs:stair_silver_sandstone"}, {["x"] = 2, ["param2"] = 1, ["y"] = 6, ["param1"] = 158, ["z"] = 4, ["name"] = "stairs:stair_silver_sandstone"}, {["x"] = 2, ["param2"] = 1, ["y"] = 6, ["param1"] = 174, ["z"] = 5, ["name"] = "stairs:stair_silver_sandstone"}, {["x"] = 2, ["param2"] = 1, ["y"] = 6, ["param1"] = 158, ["z"] = 6, ["name"] = "stairs:stair_silver_sandstone"}, {["x"] = 2, ["param2"] = 1, ["y"] = 6, ["param1"] = 174, ["z"] = 7, ["name"] = "stairs:stair_silver_sandstone"}, {["x"] = 2, ["param2"] = 1, ["y"] = 6, ["param1"] = 174, ["z"] = 8, ["name"] = "stairs:stair_silver_sandstone"}, {["x"] = 2, ["param2"] = 1, ["y"] = 6, ["param1"] = 158, ["z"] = 9, ["name"] = "stairs:stair_silver_sandstone"}, {["x"] = 2, ["param2"] = 1, ["y"] = 6, ["param1"] = 174, ["z"] = 10, ["name"] = "stairs:stair_silver_sandstone"}, {["x"] = 2, ["param2"] = 1, ["y"] = 6, ["param1"] = 158, ["z"] = 11, ["name"] = "stairs:stair_silver_sandstone"}, {["x"] = 2, ["param2"] = 1, ["y"] = 6, ["param1"] = 158, ["z"] = 12, ["name"] = "stairs:stair_silver_sandstone"}, {["x"] = 2, ["param2"] = 1, ["y"] = 6, ["param1"] = 174, ["z"] = 13, ["name"] = "stairs:stair_silver_sandstone"}, {["x"] = 2, ["param2"] = 1, ["y"] = 6, ["param1"] = 190, ["z"] = 14, ["name"] = "stairs:stair_silver_sandstone"}, {["x"] = 2, ["param2"] = 1, ["y"] = 6, ["param1"] = 174, ["z"] = 15, ["name"] = "stairs:stair_silver_sandstone"}, {["x"] = 3, ["y"] = 0, ["param1"] = 4, ["z"] = 0, ["name"] = "default:stone_block"}, {["x"] = 3, ["y"] = 0, ["param1"] = 4, ["z"] = 1, ["name"] = "default:stone_block"}, {["x"] = 3, ["y"] = 0, ["param1"] = 4, ["z"] = 2, ["name"] = "default:stone_block"}, {["x"] = 3, ["y"] = 0, ["param1"] = 4, ["z"] = 3, ["name"] = "default:stone_block"}, {["x"] = 3, ["y"] = 0, ["param1"] = 4, ["z"] = 4, ["name"] = "default:stone_block"}, {["x"] = 3, ["y"] = 0, ["param1"] = 4, ["z"] = 5, ["name"] = "default:stone_block"}, {["x"] = 3, ["y"] = 0, ["param1"] = 4, ["z"] = 6, ["name"] = "default:stone_block"}, {["x"] = 3, ["y"] = 0, ["param1"] = 4, ["z"] = 7, ["name"] = "default:stone_block"}, {["x"] = 3, ["y"] = 0, ["param1"] = 4, ["z"] = 8, ["name"] = "default:stone_block"}, {["x"] = 3, ["y"] = 0, ["param1"] = 4, ["z"] = 9, ["name"] = "default:stone_block"}, {["x"] = 3, ["y"] = 0, ["param1"] = 4, ["z"] = 10, ["name"] = "default:stone_block"}, {["x"] = 3, ["y"] = 0, ["param1"] = 4, ["z"] = 11, ["name"] = "default:stone_block"}, {["x"] = 3, ["y"] = 0, ["param1"] = 4, ["z"] = 12, ["name"] = "default:stone_block"}, {["x"] = 3, ["y"] = 0, ["param1"] = 4, ["z"] = 13, ["name"] = "default:stone_block"}, {["x"] = 3, ["y"] = 0, ["param1"] = 4, ["z"] = 14, ["name"] = "default:stone_block"}, {["x"] = 3, ["y"] = 0, ["param1"] = 4, ["z"] = 15, ["name"] = "default:stone_block"}, {["x"] = 3, ["y"] = 1, ["param1"] = 16, ["z"] = 0, ["name"] = "default:silver_sandstone"}, {["x"] = 3, ["param2"] = 23, ["y"] = 1, ["param1"] = 157, ["z"] = 1, ["name"] = "stairs:stair_stonebrick"}, {["x"] = 3, ["param2"] = 23, ["y"] = 1, ["param1"] = 142, ["z"] = 2, ["name"] = "stairs:stair_stonebrick"}, {["x"] = 3, ["y"] = 1, ["param1"] = 16, ["z"] = 3, ["name"] = "default:silver_sandstone"}, {["x"] = 3, ["param2"] = 23, ["y"] = 1, ["param1"] = 125, ["z"] = 4, ["name"] = "stairs:stair_stonebrick"}, {["x"] = 3, ["param2"] = 23, ["y"] = 1, ["param1"] = 141, ["z"] = 5, ["name"] = "stairs:stair_stonebrick"}, {["x"] = 3, ["y"] = 1, ["param1"] = 16, ["z"] = 6, ["name"] = "default:silver_sandstone"}, {["x"] = 3, ["meta"] = {["fields"] = {["state"] = "0"}, ["inventory"] = {}}, ["param2"] = 3, ["y"] = 1, ["param1"] = 142, ["z"] = 7, ["name"] = "doors:door_wood_a"}, {["x"] = 3, ["meta"] = {["fields"] = {["state"] = "2"}, ["inventory"] = {}}, ["param2"] = 3, ["y"] = 1, ["param1"] = 142, ["z"] = 8, ["name"] = "doors:door_wood_b"}, {["x"] = 3, ["y"] = 1, ["param1"] = 16, ["z"] = 9, ["name"] = "default:silver_sandstone"}, {["x"] = 3, ["param2"] = 23, ["y"] = 1, ["param1"] = 141, ["z"] = 10, ["name"] = "stairs:stair_stonebrick"}, {["x"] = 3, ["param2"] = 23, ["y"] = 1, ["param1"] = 126, ["z"] = 11, ["name"] = "stairs:stair_stonebrick"}, {["x"] = 3, ["y"] = 1, ["param1"] = 16, ["z"] = 12, ["name"] = "default:silver_sandstone"}, {["x"] = 3, ["param2"] = 23, ["y"] = 1, ["param1"] = 142, ["z"] = 13, ["name"] = "stairs:stair_stonebrick"}, {["x"] = 3, ["param2"] = 23, ["y"] = 1, ["param1"] = 157, ["z"] = 14, ["name"] = "stairs:stair_stonebrick"}, {["x"] = 3, ["y"] = 1, ["param1"] = 16, ["z"] = 15, ["name"] = "default:silver_sandstone"}, {["x"] = 3, ["y"] = 2, ["param1"] = 16, ["z"] = 0, ["name"] = "default:silver_sandstone"}, {["x"] = 3, ["y"] = 2, ["param1"] = 173, ["z"] = 1, ["name"] = "default:glass"}, {["x"] = 3, ["y"] = 2, ["param1"] = 158, ["z"] = 2, ["name"] = "default:glass"}, {["x"] = 3, ["y"] = 2, ["param1"] = 16, ["z"] = 3, ["name"] = "default:silver_sandstone"}, {["x"] = 3, ["y"] = 2, ["param1"] = 142, ["z"] = 4, ["name"] = "default:glass"}, {["x"] = 3, ["y"] = 2, ["param1"] = 158, ["z"] = 5, ["name"] = "default:glass"}, {["x"] = 3, ["y"] = 2, ["param1"] = 16, ["z"] = 6, ["name"] = "default:silver_sandstone"}, {["x"] = 3, ["param2"] = 3, ["y"] = 2, ["param1"] = 158, ["z"] = 7, ["name"] = "doors:hidden"}, {["x"] = 3, ["param2"] = 2, ["y"] = 2, ["param1"] = 158, ["z"] = 8, ["name"] = "doors:hidden"}, {["x"] = 3, ["y"] = 2, ["param1"] = 16, ["z"] = 9, ["name"] = "default:silver_sandstone"}, {["x"] = 3, ["y"] = 2, ["param1"] = 157, ["z"] = 10, ["name"] = "default:glass"}, {["x"] = 3, ["y"] = 2, ["param1"] = 142, ["z"] = 11, ["name"] = "default:glass"}, {["x"] = 3, ["y"] = 2, ["param1"] = 16, ["z"] = 12, ["name"] = "default:silver_sandstone"}, {["x"] = 3, ["y"] = 2, ["param1"] = 158, ["z"] = 13, ["name"] = "default:glass"}, {["x"] = 3, ["y"] = 2, ["param1"] = 173, ["z"] = 14, ["name"] = "default:glass"}, {["x"] = 3, ["y"] = 2, ["param1"] = 16, ["z"] = 15, ["name"] = "default:silver_sandstone"}, {["x"] = 3, ["y"] = 3, ["param1"] = 16, ["z"] = 0, ["name"] = "default:silver_sandstone"}, {["x"] = 3, ["y"] = 3, ["param1"] = 189, ["z"] = 1, ["name"] = "default:glass"}, {["x"] = 3, ["y"] = 3, ["param1"] = 174, ["z"] = 2, ["name"] = "default:glass"}, {["x"] = 3, ["y"] = 3, ["param1"] = 16, ["z"] = 3, ["name"] = "default:silver_sandstone"}, {["x"] = 3, ["y"] = 3, ["param1"] = 158, ["z"] = 4, ["name"] = "default:glass"}, {["x"] = 3, ["y"] = 3, ["param1"] = 174, ["z"] = 5, ["name"] = "default:glass"}, {["x"] = 3, ["y"] = 3, ["param1"] = 16, ["z"] = 6, ["name"] = "default:silver_sandstone"}, {["x"] = 3, ["param2"] = 23, ["y"] = 3, ["param1"] = 174, ["z"] = 7, ["name"] = "stairs:stair_stonebrick"}, {["x"] = 3, ["param2"] = 23, ["y"] = 3, ["param1"] = 174, ["z"] = 8, ["name"] = "stairs:stair_stonebrick"}, {["x"] = 3, ["y"] = 3, ["param1"] = 16, ["z"] = 9, ["name"] = "default:silver_sandstone"}, {["x"] = 3, ["y"] = 3, ["param1"] = 173, ["z"] = 10, ["name"] = "default:glass"}, {["x"] = 3, ["y"] = 3, ["param1"] = 158, ["z"] = 11, ["name"] = "default:glass"}, {["x"] = 3, ["y"] = 3, ["param1"] = 16, ["z"] = 12, ["name"] = "default:silver_sandstone"}, {["x"] = 3, ["y"] = 3, ["param1"] = 174, ["z"] = 13, ["name"] = "default:glass"}, {["x"] = 3, ["y"] = 3, ["param1"] = 189, ["z"] = 14, ["name"] = "default:glass"}, {["x"] = 3, ["y"] = 3, ["param1"] = 16, ["z"] = 15, ["name"] = "default:silver_sandstone"}, {["x"] = 3, ["y"] = 4, ["param1"] = 16, ["z"] = 0, ["name"] = "default:silver_sandstone"}, {["x"] = 3, ["y"] = 4, ["param1"] = 205, ["z"] = 1, ["name"] = "default:glass"}, {["x"] = 3, ["y"] = 4, ["param1"] = 190, ["z"] = 2, ["name"] = "default:glass"}, {["x"] = 3, ["y"] = 4, ["param1"] = 16, ["z"] = 3, ["name"] = "default:silver_sandstone"}, {["x"] = 3, ["y"] = 4, ["param1"] = 174, ["z"] = 4, ["name"] = "default:glass"}, {["x"] = 3, ["y"] = 4, ["param1"] = 190, ["z"] = 5, ["name"] = "default:glass"}, {["x"] = 3, ["y"] = 4, ["param1"] = 16, ["z"] = 6, ["name"] = "default:silver_sandstone"}, {["x"] = 3, ["y"] = 4, ["z"] = 7, ["name"] = "default:silver_sandstone"}, {["x"] = 3, ["y"] = 4, ["z"] = 8, ["name"] = "default:silver_sandstone"}, {["x"] = 3, ["y"] = 4, ["param1"] = 16, ["z"] = 9, ["name"] = "default:silver_sandstone"}, {["x"] = 3, ["y"] = 4, ["param1"] = 189, ["z"] = 10, ["name"] = "default:glass"}, {["x"] = 3, ["y"] = 4, ["param1"] = 174, ["z"] = 11, ["name"] = "default:glass"}, {["x"] = 3, ["y"] = 4, ["param1"] = 16, ["z"] = 12, ["name"] = "default:silver_sandstone"}, {["x"] = 3, ["y"] = 4, ["param1"] = 190, ["z"] = 13, ["name"] = "default:glass"}, {["x"] = 3, ["y"] = 4, ["param1"] = 205, ["z"] = 14, ["name"] = "default:glass"}, {["x"] = 3, ["y"] = 4, ["param1"] = 16, ["z"] = 15, ["name"] = "default:silver_sandstone"}, {["x"] = 3, ["y"] = 5, ["param1"] = 16, ["z"] = 0, ["name"] = "default:silver_sandstone"}, {["x"] = 3, ["param2"] = 1, ["y"] = 5, ["param1"] = 221, ["z"] = 1, ["name"] = "stairs:stair_stonebrick"}, {["x"] = 3, ["param2"] = 1, ["y"] = 5, ["param1"] = 206, ["z"] = 2, ["name"] = "stairs:stair_stonebrick"}, {["x"] = 3, ["y"] = 5, ["param1"] = 16, ["z"] = 3, ["name"] = "default:silver_sandstone"}, {["x"] = 3, ["param2"] = 1, ["y"] = 5, ["param1"] = 190, ["z"] = 4, ["name"] = "stairs:stair_stonebrick"}, {["x"] = 3, ["param2"] = 1, ["y"] = 5, ["param1"] = 206, ["z"] = 5, ["name"] = "stairs:stair_stonebrick"}, {["x"] = 3, ["y"] = 5, ["param1"] = 16, ["z"] = 6, ["name"] = "default:silver_sandstone"}, {["x"] = 3, ["param2"] = 1, ["y"] = 5, ["param1"] = 206, ["z"] = 7, ["name"] = "stairs:stair_stonebrick"}, {["x"] = 3, ["param2"] = 1, ["y"] = 5, ["param1"] = 206, ["z"] = 8, ["name"] = "stairs:stair_stonebrick"}, {["x"] = 3, ["y"] = 5, ["param1"] = 16, ["z"] = 9, ["name"] = "default:silver_sandstone"}, {["x"] = 3, ["param2"] = 1, ["y"] = 5, ["param1"] = 205, ["z"] = 10, ["name"] = "stairs:stair_stonebrick"}, {["x"] = 3, ["param2"] = 1, ["y"] = 5, ["param1"] = 190, ["z"] = 11, ["name"] = "stairs:stair_stonebrick"}, {["x"] = 3, ["y"] = 5, ["param1"] = 16, ["z"] = 12, ["name"] = "default:silver_sandstone"}, {["x"] = 3, ["param2"] = 1, ["y"] = 5, ["param1"] = 206, ["z"] = 13, ["name"] = "stairs:stair_stonebrick"}, {["x"] = 3, ["param2"] = 1, ["y"] = 5, ["param1"] = 221, ["z"] = 14, ["name"] = "stairs:stair_stonebrick"}, {["x"] = 3, ["y"] = 5, ["param1"] = 16, ["z"] = 15, ["name"] = "default:silver_sandstone"}, {["x"] = 3, ["y"] = 6, ["z"] = 0, ["name"] = "default:silver_sandstone"}, {["x"] = 3, ["y"] = 6, ["z"] = 1, ["name"] = "default:silver_sandstone"}, {["x"] = 3, ["y"] = 6, ["z"] = 2, ["name"] = "default:silver_sandstone"}, {["x"] = 3, ["y"] = 6, ["z"] = 3, ["name"] = "default:silver_sandstone"}, {["x"] = 3, ["y"] = 6, ["z"] = 4, ["name"] = "default:silver_sandstone"}, {["x"] = 3, ["y"] = 6, ["z"] = 5, ["name"] = "default:silver_sandstone"}, {["x"] = 3, ["y"] = 6, ["z"] = 6, ["name"] = "default:silver_sandstone"}, {["x"] = 3, ["y"] = 6, ["z"] = 7, ["name"] = "default:silver_sandstone"}, {["x"] = 3, ["y"] = 6, ["z"] = 8, ["name"] = "default:silver_sandstone"}, {["x"] = 3, ["y"] = 6, ["z"] = 9, ["name"] = "default:silver_sandstone"}, {["x"] = 3, ["y"] = 6, ["z"] = 10, ["name"] = "default:silver_sandstone"}, {["x"] = 3, ["y"] = 6, ["z"] = 11, ["name"] = "default:silver_sandstone"}, {["x"] = 3, ["y"] = 6, ["z"] = 12, ["name"] = "default:silver_sandstone"}, {["x"] = 3, ["y"] = 6, ["z"] = 13, ["name"] = "default:silver_sandstone"}, {["x"] = 3, ["y"] = 6, ["z"] = 14, ["name"] = "default:silver_sandstone"}, {["x"] = 3, ["y"] = 6, ["z"] = 15, ["name"] = "default:silver_sandstone"}, {["x"] = 3, ["param2"] = 20, ["y"] = 7, ["param1"] = 142, ["z"] = 0, ["name"] = "stairs:stair_outer_silver_sandstone"}, {["x"] = 3, ["param2"] = 23, ["y"] = 7, ["param1"] = 158, ["z"] = 1, ["name"] = "stairs:stair_silver_sandstone"}, {["x"] = 3, ["param2"] = 23, ["y"] = 7, ["param1"] = 142, ["z"] = 2, ["name"] = "stairs:stair_silver_sandstone"}, {["x"] = 3, ["param2"] = 23, ["y"] = 7, ["param1"] = 126, ["z"] = 3, ["name"] = "stairs:stair_silver_sandstone"}, {["x"] = 3, ["param2"] = 23, ["y"] = 7, ["param1"] = 126, ["z"] = 4, ["name"] = "stairs:stair_silver_sandstone"}, {["x"] = 3, ["y"] = 7, ["z"] = 5, ["name"] = "default:silver_sandstone"}, {["x"] = 3, ["y"] = 7, ["z"] = 6, ["name"] = "default:silver_sandstone"}, {["x"] = 3, ["y"] = 7, ["z"] = 7, ["name"] = "default:silver_sandstone"}, {["x"] = 3, ["y"] = 7, ["z"] = 8, ["name"] = "default:silver_sandstone"}, {["x"] = 3, ["y"] = 7, ["z"] = 9, ["name"] = "default:silver_sandstone"}, {["x"] = 3, ["y"] = 7, ["z"] = 10, ["name"] = "default:silver_sandstone"}, {["x"] = 3, ["param2"] = 23, ["y"] = 7, ["param1"] = 126, ["z"] = 11, ["name"] = "stairs:stair_silver_sandstone"}, {["x"] = 3, ["param2"] = 23, ["y"] = 7, ["param1"] = 126, ["z"] = 12, ["name"] = "stairs:stair_silver_sandstone"}, {["x"] = 3, ["param2"] = 23, ["y"] = 7, ["param1"] = 142, ["z"] = 13, ["name"] = "stairs:stair_silver_sandstone"}, {["x"] = 3, ["param2"] = 23, ["y"] = 7, ["param1"] = 158, ["z"] = 14, ["name"] = "stairs:stair_silver_sandstone"}, {["x"] = 3, ["param2"] = 23, ["y"] = 7, ["param1"] = 142, ["z"] = 15, ["name"] = "stairs:stair_outer_silver_sandstone"}, {["x"] = 3, ["y"] = 8, ["z"] = 5, ["name"] = "default:silver_sandstone"}, {["x"] = 3, ["y"] = 8, ["z"] = 6, ["name"] = "default:goldblock"}, {["x"] = 3, ["y"] = 8, ["z"] = 7, ["name"] = "default:goldblock"}, {["x"] = 3, ["y"] = 8, ["z"] = 8, ["name"] = "default:goldblock"}, {["x"] = 3, ["y"] = 8, ["z"] = 9, ["name"] = "default:goldblock"}, {["x"] = 3, ["y"] = 8, ["z"] = 10, ["name"] = "default:silver_sandstone"}, {["x"] = 3, ["y"] = 9, ["z"] = 5, ["name"] = "default:silver_sandstone"}, {["x"] = 3, ["y"] = 9, ["z"] = 6, ["name"] = "default:goldblock"}, {["x"] = 3, ["y"] = 9, ["z"] = 7, ["name"] = "default:silver_sandstone"}, {["x"] = 3, ["y"] = 9, ["z"] = 8, ["name"] = "default:silver_sandstone"}, {["x"] = 3, ["y"] = 9, ["z"] = 9, ["name"] = "default:goldblock"}, {["x"] = 3, ["y"] = 9, ["z"] = 10, ["name"] = "default:silver_sandstone"}, {["x"] = 3, ["y"] = 10, ["z"] = 5, ["name"] = "default:silver_sandstone"}, {["x"] = 3, ["y"] = 10, ["z"] = 6, ["name"] = "default:silver_sandstone"}, {["x"] = 3, ["y"] = 10, ["z"] = 7, ["name"] = "default:goldblock"}, {["x"] = 3, ["y"] = 10, ["z"] = 8, ["name"] = "default:goldblock"}, {["x"] = 3, ["y"] = 10, ["z"] = 9, ["name"] = "default:goldblock"}, {["x"] = 3, ["y"] = 10, ["z"] = 10, ["name"] = "default:silver_sandstone"}, {["x"] = 3, ["y"] = 11, ["z"] = 5, ["name"] = "default:silver_sandstone"}, {["x"] = 3, ["y"] = 11, ["z"] = 6, ["name"] = "default:goldblock"}, {["x"] = 3, ["y"] = 11, ["z"] = 7, ["name"] = "default:silver_sandstone"}, {["x"] = 3, ["y"] = 11, ["z"] = 8, ["name"] = "default:silver_sandstone"}, {["x"] = 3, ["y"] = 11, ["z"] = 9, ["name"] = "default:goldblock"}, {["x"] = 3, ["y"] = 11, ["z"] = 10, ["name"] = "default:silver_sandstone"}, {["x"] = 3, ["y"] = 12, ["z"] = 5, ["name"] = "default:silver_sandstone"}, {["x"] = 3, ["y"] = 12, ["z"] = 6, ["name"] = "default:silver_sandstone"}, {["x"] = 3, ["y"] = 12, ["z"] = 7, ["name"] = "default:goldblock"}, {["x"] = 3, ["y"] = 12, ["z"] = 8, ["name"] = "default:goldblock"}, {["x"] = 3, ["y"] = 12, ["z"] = 9, ["name"] = "default:goldblock"}, {["x"] = 3, ["y"] = 12, ["z"] = 10, ["name"] = "default:silver_sandstone"}, {["x"] = 3, ["y"] = 13, ["z"] = 5, ["name"] = "default:silver_sandstone"}, {["x"] = 3, ["y"] = 13, ["z"] = 6, ["name"] = "default:silver_sandstone"}, {["x"] = 3, ["y"] = 13, ["z"] = 7, ["name"] = "default:silver_sandstone"}, {["x"] = 3, ["y"] = 13, ["z"] = 8, ["name"] = "default:silver_sandstone"}, {["x"] = 3, ["y"] = 13, ["z"] = 9, ["name"] = "default:silver_sandstone"}, {["x"] = 3, ["y"] = 13, ["z"] = 10, ["name"] = "default:goldblock"}, {["x"] = 4, ["y"] = 0, ["param1"] = 4, ["z"] = 0, ["name"] = "default:stone_block"}, {["x"] = 4, ["y"] = 0, ["param1"] = 4, ["z"] = 1, ["name"] = "default:stone_block"}, {["x"] = 4, ["y"] = 0, ["param1"] = 4, ["z"] = 2, ["name"] = "default:stone_block"}, {["x"] = 4, ["y"] = 0, ["param1"] = 4, ["z"] = 3, ["name"] = "default:stone_block"}, {["x"] = 4, ["y"] = 0, ["param1"] = 4, ["z"] = 4, ["name"] = "default:stone_block"}, {["x"] = 4, ["y"] = 0, ["param1"] = 4, ["z"] = 5, ["name"] = "default:stone_block"}, {["x"] = 4, ["y"] = 0, ["param1"] = 4, ["z"] = 6, ["name"] = "default:stone_block"}, {["x"] = 4, ["y"] = 0, ["param1"] = 4, ["z"] = 7, ["name"] = "default:stone_block"}, {["x"] = 4, ["y"] = 0, ["param1"] = 4, ["z"] = 8, ["name"] = "default:stone_block"}, {["x"] = 4, ["y"] = 0, ["param1"] = 4, ["z"] = 9, ["name"] = "default:stone_block"}, {["x"] = 4, ["y"] = 0, ["param1"] = 4, ["z"] = 10, ["name"] = "default:stone_block"}, {["x"] = 4, ["y"] = 0, ["param1"] = 4, ["z"] = 11, ["name"] = "default:stone_block"}, {["x"] = 4, ["y"] = 0, ["param1"] = 4, ["z"] = 12, ["name"] = "default:stone_block"}, {["x"] = 4, ["y"] = 0, ["param1"] = 4, ["z"] = 13, ["name"] = "default:stone_block"}, {["x"] = 4, ["y"] = 0, ["param1"] = 4, ["z"] = 14, ["name"] = "default:stone_block"}, {["x"] = 4, ["y"] = 0, ["param1"] = 4, ["z"] = 15, ["name"] = "default:stone_block"}, {["x"] = 4, ["param2"] = 20, ["y"] = 1, ["param1"] = 158, ["z"] = 0, ["name"] = "stairs:stair_stonebrick"}, {["x"] = 4, ["meta"] = {["fields"] = {["formspec"] = "field[text;;${text}]"}, ["inventory"] = {}}, ["param2"] = 2, ["y"] = 1, ["param1"] = 174, ["z"] = 1, ["name"] = "default:sign_wall_wood"}, {["x"] = 4, ["meta"] = {["fields"] = {["formspec"] = "field[text;;${text}]"}, ["inventory"] = {}}, ["param2"] = 4, ["y"] = 1, ["param1"] = 143, ["z"] = 3, ["name"] = "default:sign_wall_wood"}, {["x"] = 4, ["param2"] = 3, ["y"] = 1, ["param1"] = 142, ["z"] = 4, ["name"] = "stairs:stair_wood"}, {["x"] = 4, ["param2"] = 3, ["y"] = 1, ["param1"] = 158, ["z"] = 5, ["name"] = "stairs:stair_wood"}, {["x"] = 4, ["meta"] = {["fields"] = {["formspec"] = "field[text;;${text}]"}, ["inventory"] = {}}, ["param2"] = 5, ["y"] = 1, ["param1"] = 174, ["z"] = 6, ["name"] = "default:sign_wall_wood"}, {["x"] = 4, ["meta"] = {["fields"] = {["formspec"] = "field[text;;${text}]"}, ["inventory"] = {}}, ["param2"] = 4, ["y"] = 1, ["param1"] = 174, ["z"] = 9, ["name"] = "default:sign_wall_wood"}, {["x"] = 4, ["param2"] = 3, ["y"] = 1, ["param1"] = 157, ["z"] = 10, ["name"] = "stairs:stair_wood"}, {["x"] = 4, ["param2"] = 3, ["y"] = 1, ["param1"] = 142, ["z"] = 11, ["name"] = "stairs:stair_wood"}, {["x"] = 4, ["meta"] = {["fields"] = {["formspec"] = "field[text;;${text}]"}, ["inventory"] = {}}, ["param2"] = 5, ["y"] = 1, ["param1"] = 143, ["z"] = 12, ["name"] = "default:sign_wall_wood"}, {["x"] = 4, ["meta"] = {["fields"] = {["formspec"] = "field[text;;${text}]"}, ["inventory"] = {}}, ["param2"] = 2, ["y"] = 1, ["param1"] = 174, ["z"] = 14, ["name"] = "default:sign_wall_wood"}, {["x"] = 4, ["param2"] = 22, ["y"] = 1, ["param1"] = 158, ["z"] = 15, ["name"] = "stairs:stair_stonebrick"}, {["x"] = 4, ["y"] = 2, ["param1"] = 174, ["z"] = 0, ["name"] = "default:glass"}, {["x"] = 4, ["y"] = 2, ["param1"] = 174, ["z"] = 15, ["name"] = "default:glass"}, {["x"] = 4, ["y"] = 3, ["param1"] = 190, ["z"] = 0, ["name"] = "default:glass"}, {["x"] = 4, ["y"] = 3, ["param1"] = 190, ["z"] = 15, ["name"] = "default:glass"}, {["x"] = 4, ["y"] = 4, ["param1"] = 206, ["z"] = 0, ["name"] = "default:glass"}, {["x"] = 4, ["y"] = 4, ["param1"] = 206, ["z"] = 15, ["name"] = "default:glass"}, {["x"] = 4, ["y"] = 5, ["param1"] = 222, ["z"] = 0, ["name"] = "stairs:stair_stonebrick"}, {["x"] = 4, ["y"] = 5, ["param1"] = 238, ["z"] = 1, ["name"] = "default:mese_post_light_junglewood"}, {["x"] = 4, ["y"] = 5, ["param1"] = 238, ["z"] = 6, ["name"] = "default:mese_post_light_junglewood"}, {["x"] = 4, ["y"] = 5, ["param1"] = 238, ["z"] = 9, ["name"] = "default:mese_post_light_junglewood"}, {["x"] = 4, ["y"] = 5, ["param1"] = 238, ["z"] = 14, ["name"] = "default:mese_post_light_junglewood"}, {["x"] = 4, ["param2"] = 2, ["y"] = 5, ["param1"] = 222, ["z"] = 15, ["name"] = "stairs:stair_stonebrick"}, {["x"] = 4, ["y"] = 6, ["z"] = 0, ["name"] = "default:silver_sandstone"}, {["x"] = 4, ["y"] = 6, ["param1"] = 14, ["z"] = 1, ["name"] = "default:silver_sandstone"}, {["x"] = 4, ["y"] = 6, ["param1"] = 15, ["z"] = 2, ["name"] = "default:silver_sandstone"}, {["x"] = 4, ["y"] = 6, ["param1"] = 15, ["z"] = 3, ["name"] = "default:silver_sandstone"}, {["x"] = 4, ["y"] = 6, ["param1"] = 15, ["z"] = 4, ["name"] = "default:silver_sandstone"}, {["x"] = 4, ["y"] = 6, ["param1"] = 15, ["z"] = 5, ["name"] = "default:silver_sandstone"}, {["x"] = 4, ["y"] = 6, ["param1"] = 15, ["z"] = 6, ["name"] = "default:silver_sandstone"}, {["x"] = 4, ["y"] = 6, ["param1"] = 15, ["z"] = 7, ["name"] = "default:silver_sandstone"}, {["x"] = 4, ["y"] = 6, ["param1"] = 15, ["z"] = 8, ["name"] = "default:silver_sandstone"}, {["x"] = 4, ["y"] = 6, ["param1"] = 15, ["z"] = 9, ["name"] = "default:silver_sandstone"}, {["x"] = 4, ["y"] = 6, ["param1"] = 14, ["z"] = 10, ["name"] = "default:silver_sandstone"}, {["x"] = 4, ["y"] = 6, ["param1"] = 14, ["z"] = 11, ["name"] = "default:silver_sandstone"}, {["x"] = 4, ["y"] = 6, ["param1"] = 14, ["z"] = 12, ["name"] = "default:silver_sandstone"}, {["x"] = 4, ["y"] = 6, ["param1"] = 14, ["z"] = 13, ["name"] = "default:silver_sandstone"}, {["x"] = 4, ["y"] = 6, ["z"] = 14, ["name"] = "default:silver_sandstone"}, {["x"] = 4, ["y"] = 6, ["z"] = 15, ["name"] = "default:silver_sandstone"}, {["x"] = 4, ["param2"] = 20, ["y"] = 7, ["param1"] = 158, ["z"] = 0, ["name"] = "stairs:stair_silver_sandstone"}, {["x"] = 4, ["param2"] = 22, ["y"] = 7, ["param1"] = 158, ["z"] = 15, ["name"] = "stairs:stair_silver_sandstone"}, {["x"] = 5, ["y"] = 0, ["param1"] = 4, ["z"] = 0, ["name"] = "default:stone_block"}, {["x"] = 5, ["y"] = 0, ["param1"] = 4, ["z"] = 1, ["name"] = "default:stone_block"}, {["x"] = 5, ["y"] = 0, ["param1"] = 4, ["z"] = 2, ["name"] = "default:stone_block"}, {["x"] = 5, ["y"] = 0, ["param1"] = 4, ["z"] = 3, ["name"] = "default:stone_block"}, {["x"] = 5, ["y"] = 0, ["param1"] = 4, ["z"] = 4, ["name"] = "default:stone_block"}, {["x"] = 5, ["y"] = 0, ["param1"] = 4, ["z"] = 5, ["name"] = "default:stone_block"}, {["x"] = 5, ["y"] = 0, ["param1"] = 4, ["z"] = 6, ["name"] = "default:stone_block"}, {["x"] = 5, ["y"] = 0, ["param1"] = 4, ["z"] = 7, ["name"] = "default:stone_block"}, {["x"] = 5, ["y"] = 0, ["param1"] = 4, ["z"] = 8, ["name"] = "default:stone_block"}, {["x"] = 5, ["y"] = 0, ["param1"] = 4, ["z"] = 9, ["name"] = "default:stone_block"}, {["x"] = 5, ["y"] = 0, ["param1"] = 4, ["z"] = 10, ["name"] = "default:stone_block"}, {["x"] = 5, ["y"] = 0, ["param1"] = 4, ["z"] = 11, ["name"] = "default:stone_block"}, {["x"] = 5, ["y"] = 0, ["param1"] = 4, ["z"] = 12, ["name"] = "default:stone_block"}, {["x"] = 5, ["y"] = 0, ["param1"] = 4, ["z"] = 13, ["name"] = "default:stone_block"}, {["x"] = 5, ["y"] = 0, ["param1"] = 4, ["z"] = 14, ["name"] = "default:stone_block"}, {["x"] = 5, ["y"] = 0, ["param1"] = 4, ["z"] = 15, ["name"] = "default:stone_block"}, {["x"] = 5, ["param2"] = 20, ["y"] = 1, ["param1"] = 142, ["z"] = 0, ["name"] = "stairs:stair_stonebrick"}, {["x"] = 5, ["param2"] = 2, ["y"] = 1, ["param1"] = 158, ["z"] = 1, ["name"] = "stairs:stair_wood"}, {["x"] = 5, ["y"] = 1, ["param1"] = 158, ["z"] = 14, ["name"] = "stairs:stair_wood"}, {["x"] = 5, ["param2"] = 22, ["y"] = 1, ["param1"] = 142, ["z"] = 15, ["name"] = "stairs:stair_stonebrick"}, {["x"] = 5, ["y"] = 2, ["param1"] = 158, ["z"] = 0, ["name"] = "default:glass"}, {["x"] = 5, ["y"] = 2, ["param1"] = 158, ["z"] = 15, ["name"] = "default:glass"}, {["x"] = 5, ["y"] = 3, ["param1"] = 174, ["z"] = 0, ["name"] = "default:glass"}, {["x"] = 5, ["y"] = 3, ["param1"] = 174, ["z"] = 15, ["name"] = "default:glass"}, {["x"] = 5, ["y"] = 4, ["param1"] = 190, ["z"] = 0, ["name"] = "default:glass"}, {["x"] = 5, ["y"] = 4, ["param1"] = 190, ["z"] = 15, ["name"] = "default:glass"}, {["x"] = 5, ["y"] = 5, ["param1"] = 206, ["z"] = 0, ["name"] = "stairs:stair_stonebrick"}, {["x"] = 5, ["param2"] = 2, ["y"] = 5, ["param1"] = 206, ["z"] = 15, ["name"] = "stairs:stair_stonebrick"}, {["x"] = 5, ["y"] = 6, ["z"] = 0, ["name"] = "default:silver_sandstone"}, {["x"] = 5, ["y"] = 6, ["param1"] = 15, ["z"] = 1, ["name"] = "default:silver_sandstone"}, {["x"] = 5, ["y"] = 6, ["param1"] = 15, ["z"] = 2, ["name"] = "default:silver_sandstone"}, {["x"] = 5, ["y"] = 6, ["param1"] = 15, ["z"] = 3, ["name"] = "default:silver_sandstone"}, {["x"] = 5, ["y"] = 6, ["param1"] = 15, ["z"] = 4, ["name"] = "default:silver_sandstone"}, {["x"] = 5, ["y"] = 6, ["param1"] = 15, ["z"] = 5, ["name"] = "default:silver_sandstone"}, {["x"] = 5, ["y"] = 6, ["param1"] = 15, ["z"] = 6, ["name"] = "default:silver_sandstone"}, {["x"] = 5, ["y"] = 6, ["param1"] = 15, ["z"] = 7, ["name"] = "default:silver_sandstone"}, {["x"] = 5, ["y"] = 6, ["param1"] = 15, ["z"] = 8, ["name"] = "default:silver_sandstone"}, {["x"] = 5, ["y"] = 6, ["param1"] = 15, ["z"] = 9, ["name"] = "default:silver_sandstone"}, {["x"] = 5, ["y"] = 6, ["param1"] = 14, ["z"] = 10, ["name"] = "default:silver_sandstone"}, {["x"] = 5, ["y"] = 6, ["param1"] = 14, ["z"] = 11, ["name"] = "default:silver_sandstone"}, {["x"] = 5, ["y"] = 6, ["param1"] = 14, ["z"] = 12, ["name"] = "default:silver_sandstone"}, {["x"] = 5, ["y"] = 6, ["param1"] = 14, ["z"] = 13, ["name"] = "default:silver_sandstone"}, {["x"] = 5, ["y"] = 6, ["param1"] = 14, ["z"] = 14, ["name"] = "default:silver_sandstone"}, {["x"] = 5, ["y"] = 6, ["z"] = 15, ["name"] = "default:silver_sandstone"}, {["x"] = 5, ["param2"] = 20, ["y"] = 7, ["param1"] = 142, ["z"] = 0, ["name"] = "stairs:stair_silver_sandstone"}, {["x"] = 5, ["param2"] = 22, ["y"] = 7, ["param1"] = 142, ["z"] = 15, ["name"] = "stairs:stair_silver_sandstone"}, {["x"] = 6, ["y"] = 0, ["param1"] = 4, ["z"] = 0, ["name"] = "default:stone_block"}, {["x"] = 6, ["y"] = 0, ["param1"] = 4, ["z"] = 1, ["name"] = "default:stone_block"}, {["x"] = 6, ["y"] = 0, ["param1"] = 4, ["z"] = 2, ["name"] = "default:stone_block"}, {["x"] = 6, ["y"] = 0, ["param1"] = 4, ["z"] = 3, ["name"] = "default:stone_block"}, {["x"] = 6, ["y"] = 0, ["param1"] = 4, ["z"] = 4, ["name"] = "default:stone_block"}, {["x"] = 6, ["y"] = 0, ["param1"] = 4, ["z"] = 5, ["name"] = "default:stone_block"}, {["x"] = 6, ["y"] = 0, ["param1"] = 4, ["z"] = 6, ["name"] = "default:stone_block"}, {["x"] = 6, ["y"] = 0, ["param1"] = 4, ["z"] = 7, ["name"] = "default:stone_block"}, {["x"] = 6, ["y"] = 0, ["param1"] = 4, ["z"] = 8, ["name"] = "default:stone_block"}, {["x"] = 6, ["y"] = 0, ["param1"] = 4, ["z"] = 9, ["name"] = "default:stone_block"}, {["x"] = 6, ["y"] = 0, ["param1"] = 4, ["z"] = 10, ["name"] = "default:stone_block"}, {["x"] = 6, ["y"] = 0, ["param1"] = 4, ["z"] = 11, ["name"] = "default:stone_block"}, {["x"] = 6, ["y"] = 0, ["param1"] = 4, ["z"] = 12, ["name"] = "default:stone_block"}, {["x"] = 6, ["y"] = 0, ["param1"] = 4, ["z"] = 13, ["name"] = "default:stone_block"}, {["x"] = 6, ["y"] = 0, ["param1"] = 4, ["z"] = 14, ["name"] = "default:stone_block"}, {["x"] = 6, ["y"] = 0, ["param1"] = 4, ["z"] = 15, ["name"] = "default:stone_block"}, {["x"] = 6, ["y"] = 1, ["param1"] = 16, ["z"] = 0, ["name"] = "default:silver_sandstone"}, {["x"] = 6, ["param2"] = 2, ["y"] = 1, ["param1"] = 141, ["z"] = 1, ["name"] = "stairs:stair_wood"}, {["x"] = 6, ["y"] = 1, ["param1"] = 141, ["z"] = 14, ["name"] = "stairs:stair_wood"}, {["x"] = 6, ["y"] = 1, ["param1"] = 16, ["z"] = 15, ["name"] = "default:silver_sandstone"}, {["x"] = 6, ["y"] = 2, ["param1"] = 16, ["z"] = 0, ["name"] = "default:silver_sandstone"}, {["x"] = 6, ["y"] = 2, ["param1"] = 16, ["z"] = 15, ["name"] = "default:silver_sandstone"}, {["x"] = 6, ["y"] = 3, ["param1"] = 16, ["z"] = 0, ["name"] = "default:silver_sandstone"}, {["x"] = 6, ["y"] = 3, ["param1"] = 16, ["z"] = 15, ["name"] = "default:silver_sandstone"}, {["x"] = 6, ["y"] = 4, ["param1"] = 16, ["z"] = 0, ["name"] = "default:silver_sandstone"}, {["x"] = 6, ["y"] = 4, ["param1"] = 16, ["z"] = 15, ["name"] = "default:silver_sandstone"}, {["x"] = 6, ["y"] = 5, ["param1"] = 16, ["z"] = 0, ["name"] = "default:silver_sandstone"}, {["x"] = 6, ["y"] = 5, ["param1"] = 16, ["z"] = 15, ["name"] = "default:silver_sandstone"}, {["x"] = 6, ["y"] = 6, ["z"] = 0, ["name"] = "default:silver_sandstone"}, {["x"] = 6, ["y"] = 6, ["param1"] = 15, ["z"] = 1, ["name"] = "default:silver_sandstone"}, {["x"] = 6, ["y"] = 6, ["param1"] = 15, ["z"] = 2, ["name"] = "default:silver_sandstone"}, {["x"] = 6, ["y"] = 6, ["param1"] = 15, ["z"] = 3, ["name"] = "default:silver_sandstone"}, {["x"] = 6, ["y"] = 6, ["param1"] = 15, ["z"] = 4, ["name"] = "default:silver_sandstone"}, {["x"] = 6, ["y"] = 6, ["param1"] = 15, ["z"] = 5, ["name"] = "default:silver_sandstone"}, {["x"] = 6, ["y"] = 6, ["param1"] = 15, ["z"] = 6, ["name"] = "default:silver_sandstone"}, {["x"] = 6, ["y"] = 6, ["param1"] = 15, ["z"] = 7, ["name"] = "default:silver_sandstone"}, {["x"] = 6, ["y"] = 6, ["param1"] = 15, ["z"] = 8, ["name"] = "default:silver_sandstone"}, {["x"] = 6, ["y"] = 6, ["param1"] = 15, ["z"] = 9, ["name"] = "default:silver_sandstone"}, {["x"] = 6, ["y"] = 6, ["param1"] = 14, ["z"] = 10, ["name"] = "default:silver_sandstone"}, {["x"] = 6, ["y"] = 6, ["param1"] = 14, ["z"] = 11, ["name"] = "default:silver_sandstone"}, {["x"] = 6, ["y"] = 6, ["param1"] = 14, ["z"] = 12, ["name"] = "default:silver_sandstone"}, {["x"] = 6, ["y"] = 6, ["param1"] = 14, ["z"] = 13, ["name"] = "default:silver_sandstone"}, {["x"] = 6, ["y"] = 6, ["param1"] = 14, ["z"] = 14, ["name"] = "default:silver_sandstone"}, {["x"] = 6, ["y"] = 6, ["z"] = 15, ["name"] = "default:silver_sandstone"}, {["x"] = 6, ["param2"] = 20, ["y"] = 7, ["param1"] = 126, ["z"] = 0, ["name"] = "stairs:stair_silver_sandstone"}, {["x"] = 6, ["param2"] = 22, ["y"] = 7, ["param1"] = 126, ["z"] = 15, ["name"] = "stairs:stair_silver_sandstone"}, {["x"] = 7, ["y"] = 0, ["param1"] = 4, ["z"] = 0, ["name"] = "default:stone_block"}, {["x"] = 7, ["y"] = 0, ["param1"] = 4, ["z"] = 1, ["name"] = "default:stone_block"}, {["x"] = 7, ["y"] = 0, ["param1"] = 4, ["z"] = 2, ["name"] = "default:stone_block"}, {["x"] = 7, ["y"] = 0, ["param1"] = 4, ["z"] = 3, ["name"] = "default:stone_block"}, {["x"] = 7, ["y"] = 0, ["param1"] = 4, ["z"] = 4, ["name"] = "default:stone_block"}, {["x"] = 7, ["y"] = 0, ["param1"] = 4, ["z"] = 5, ["name"] = "default:stone_block"}, {["x"] = 7, ["y"] = 0, ["param1"] = 4, ["z"] = 6, ["name"] = "default:stone_block"}, {["x"] = 7, ["y"] = 0, ["param1"] = 4, ["z"] = 7, ["name"] = "default:stone_block"}, {["x"] = 7, ["y"] = 0, ["param1"] = 4, ["z"] = 8, ["name"] = "default:stone_block"}, {["x"] = 7, ["y"] = 0, ["param1"] = 4, ["z"] = 9, ["name"] = "default:stone_block"}, {["x"] = 7, ["y"] = 0, ["param1"] = 4, ["z"] = 10, ["name"] = "default:stone_block"}, {["x"] = 7, ["y"] = 0, ["param1"] = 4, ["z"] = 11, ["name"] = "default:stone_block"}, {["x"] = 7, ["y"] = 0, ["param1"] = 4, ["z"] = 12, ["name"] = "default:stone_block"}, {["x"] = 7, ["y"] = 0, ["param1"] = 4, ["z"] = 13, ["name"] = "default:stone_block"}, {["x"] = 7, ["y"] = 0, ["param1"] = 4, ["z"] = 14, ["name"] = "default:stone_block"}, {["x"] = 7, ["y"] = 0, ["param1"] = 4, ["z"] = 15, ["name"] = "default:stone_block"}, {["x"] = 7, ["param2"] = 20, ["y"] = 1, ["param1"] = 125, ["z"] = 0, ["name"] = "stairs:stair_stonebrick"}, {["x"] = 7, ["meta"] = {["fields"] = {["formspec"] = "field[text;;${text}]"}, ["inventory"] = {}}, ["param2"] = 3, ["y"] = 1, ["param1"] = 142, ["z"] = 1, ["name"] = "default:sign_wall_wood"}, {["x"] = 7, ["meta"] = {["fields"] = {["formspec"] = "field[text;;${text}]"}, ["inventory"] = {}}, ["param2"] = 3, ["y"] = 1, ["param1"] = 157, ["z"] = 14, ["name"] = "default:sign_wall_wood"}, {["x"] = 7, ["param2"] = 22, ["y"] = 1, ["param1"] = 141, ["z"] = 15, ["name"] = "stairs:stair_stonebrick"}, {["x"] = 7, ["y"] = 2, ["param1"] = 141, ["z"] = 0, ["name"] = "default:glass"}, {["x"] = 7, ["y"] = 2, ["param1"] = 157, ["z"] = 15, ["name"] = "default:glass"}, {["x"] = 7, ["y"] = 3, ["param1"] = 157, ["z"] = 0, ["name"] = "default:glass"}, {["x"] = 7, ["y"] = 3, ["param1"] = 173, ["z"] = 15, ["name"] = "default:glass"}, {["x"] = 7, ["y"] = 4, ["param1"] = 173, ["z"] = 0, ["name"] = "default:glass"}, {["x"] = 7, ["y"] = 4, ["param1"] = 189, ["z"] = 15, ["name"] = "default:glass"}, {["x"] = 7, ["y"] = 5, ["param1"] = 189, ["z"] = 0, ["name"] = "stairs:stair_stonebrick"}, {["x"] = 7, ["param2"] = 2, ["y"] = 5, ["param1"] = 205, ["z"] = 15, ["name"] = "stairs:stair_stonebrick"}, {["x"] = 7, ["y"] = 6, ["z"] = 0, ["name"] = "default:silver_sandstone"}, {["x"] = 7, ["y"] = 6, ["param1"] = 14, ["z"] = 1, ["name"] = "default:silver_sandstone"}, {["x"] = 7, ["y"] = 6, ["param1"] = 14, ["z"] = 2, ["name"] = "default:silver_sandstone"}, {["x"] = 7, ["y"] = 6, ["param1"] = 14, ["z"] = 3, ["name"] = "default:silver_sandstone"}, {["x"] = 7, ["y"] = 6, ["param1"] = 14, ["z"] = 4, ["name"] = "default:silver_sandstone"}, {["x"] = 7, ["y"] = 6, ["param1"] = 14, ["z"] = 5, ["name"] = "default:silver_sandstone"}, {["x"] = 7, ["y"] = 6, ["param1"] = 14, ["z"] = 6, ["name"] = "default:silver_sandstone"}, {["x"] = 7, ["y"] = 6, ["param1"] = 14, ["z"] = 7, ["name"] = "default:silver_sandstone"}, {["x"] = 7, ["y"] = 6, ["param1"] = 14, ["z"] = 8, ["name"] = "default:silver_sandstone"}, {["x"] = 7, ["y"] = 6, ["param1"] = 14, ["z"] = 9, ["name"] = "default:silver_sandstone"}, {["x"] = 7, ["y"] = 6, ["param1"] = 14, ["z"] = 10, ["name"] = "default:silver_sandstone"}, {["x"] = 7, ["y"] = 6, ["param1"] = 14, ["z"] = 11, ["name"] = "default:silver_sandstone"}, {["x"] = 7, ["y"] = 6, ["param1"] = 14, ["z"] = 12, ["name"] = "default:silver_sandstone"}, {["x"] = 7, ["y"] = 6, ["param1"] = 14, ["z"] = 13, ["name"] = "default:silver_sandstone"}, {["x"] = 7, ["y"] = 6, ["param1"] = 14, ["z"] = 14, ["name"] = "default:silver_sandstone"}, {["x"] = 7, ["y"] = 6, ["z"] = 15, ["name"] = "default:silver_sandstone"}, {["x"] = 7, ["param2"] = 20, ["y"] = 7, ["param1"] = 126, ["z"] = 0, ["name"] = "stairs:stair_silver_sandstone"}, {["x"] = 7, ["param2"] = 22, ["y"] = 7, ["param1"] = 142, ["z"] = 15, ["name"] = "stairs:stair_silver_sandstone"}, {["x"] = 8, ["y"] = 0, ["param1"] = 4, ["z"] = 0, ["name"] = "default:stone_block"}, {["x"] = 8, ["y"] = 0, ["param1"] = 4, ["z"] = 1, ["name"] = "default:stone_block"}, {["x"] = 8, ["y"] = 0, ["param1"] = 4, ["z"] = 2, ["name"] = "default:stone_block"}, {["x"] = 8, ["y"] = 0, ["param1"] = 4, ["z"] = 3, ["name"] = "default:stone_block"}, {["x"] = 8, ["y"] = 0, ["param1"] = 4, ["z"] = 4, ["name"] = "default:stone_block"}, {["x"] = 8, ["y"] = 0, ["param1"] = 4, ["z"] = 5, ["name"] = "default:stone_block"}, {["x"] = 8, ["y"] = 0, ["param1"] = 4, ["z"] = 6, ["name"] = "default:stone_block"}, {["x"] = 8, ["y"] = 0, ["param1"] = 4, ["z"] = 7, ["name"] = "default:stone_block"}, {["x"] = 8, ["y"] = 0, ["param1"] = 4, ["z"] = 8, ["name"] = "default:stone_block"}, {["x"] = 8, ["y"] = 0, ["param1"] = 4, ["z"] = 9, ["name"] = "default:stone_block"}, {["x"] = 8, ["y"] = 0, ["param1"] = 4, ["z"] = 10, ["name"] = "default:stone_block"}, {["x"] = 8, ["y"] = 0, ["param1"] = 4, ["z"] = 11, ["name"] = "default:stone_block"}, {["x"] = 8, ["y"] = 0, ["param1"] = 4, ["z"] = 12, ["name"] = "default:stone_block"}, {["x"] = 8, ["y"] = 0, ["param1"] = 4, ["z"] = 13, ["name"] = "default:stone_block"}, {["x"] = 8, ["y"] = 0, ["param1"] = 4, ["z"] = 14, ["name"] = "default:stone_block"}, {["x"] = 8, ["y"] = 0, ["param1"] = 4, ["z"] = 15, ["name"] = "default:stone_block"}, {["x"] = 8, ["param2"] = 20, ["y"] = 1, ["param1"] = 142, ["z"] = 0, ["name"] = "stairs:stair_stonebrick"}, {["x"] = 8, ["param2"] = 22, ["y"] = 1, ["param1"] = 158, ["z"] = 15, ["name"] = "stairs:stair_stonebrick"}, {["x"] = 8, ["y"] = 2, ["param1"] = 158, ["z"] = 0, ["name"] = "default:glass"}, {["x"] = 8, ["y"] = 2, ["param1"] = 174, ["z"] = 15, ["name"] = "default:glass"}, {["x"] = 8, ["y"] = 3, ["param1"] = 174, ["z"] = 0, ["name"] = "default:glass"}, {["x"] = 8, ["y"] = 3, ["param1"] = 190, ["z"] = 15, ["name"] = "default:glass"}, {["x"] = 8, ["y"] = 4, ["param1"] = 190, ["z"] = 0, ["name"] = "default:glass"}, {["x"] = 8, ["y"] = 4, ["param1"] = 206, ["z"] = 15, ["name"] = "default:glass"}, {["x"] = 8, ["y"] = 5, ["param1"] = 206, ["z"] = 0, ["name"] = "stairs:stair_stonebrick"}, {["x"] = 8, ["y"] = 5, ["param1"] = 238, ["z"] = 2, ["name"] = "default:mese_post_light_junglewood"}, {["x"] = 8, ["y"] = 5, ["param1"] = 238, ["z"] = 4, ["name"] = "default:mese_post_light_junglewood"}, {["x"] = 8, ["y"] = 5, ["param1"] = 238, ["z"] = 6, ["name"] = "default:mese_post_light_junglewood"}, {["x"] = 8, ["y"] = 5, ["param1"] = 238, ["z"] = 8, ["name"] = "default:mese_post_light_junglewood"}, {["x"] = 8, ["y"] = 5, ["param1"] = 238, ["z"] = 10, ["name"] = "default:mese_post_light_junglewood"}, {["x"] = 8, ["y"] = 5, ["param1"] = 238, ["z"] = 12, ["name"] = "default:mese_post_light_junglewood"}, {["x"] = 8, ["y"] = 5, ["param1"] = 238, ["z"] = 14, ["name"] = "default:mese_post_light_junglewood"}, {["x"] = 8, ["param2"] = 2, ["y"] = 5, ["param1"] = 222, ["z"] = 15, ["name"] = "stairs:stair_stonebrick"}, {["x"] = 8, ["y"] = 6, ["z"] = 0, ["name"] = "default:silver_sandstone"}, {["x"] = 8, ["y"] = 6, ["param1"] = 14, ["z"] = 1, ["name"] = "default:silver_sandstone"}, {["x"] = 8, ["y"] = 6, ["param1"] = 14, ["z"] = 2, ["name"] = "default:silver_sandstone"}, {["x"] = 8, ["y"] = 6, ["param1"] = 14, ["z"] = 3, ["name"] = "default:silver_sandstone"}, {["x"] = 8, ["y"] = 6, ["param1"] = 14, ["z"] = 4, ["name"] = "default:silver_sandstone"}, {["x"] = 8, ["y"] = 6, ["param1"] = 14, ["z"] = 5, ["name"] = "default:silver_sandstone"}, {["x"] = 8, ["y"] = 6, ["param1"] = 14, ["z"] = 6, ["name"] = "default:silver_sandstone"}, {["x"] = 8, ["y"] = 6, ["param1"] = 14, ["z"] = 7, ["name"] = "default:silver_sandstone"}, {["x"] = 8, ["y"] = 6, ["param1"] = 14, ["z"] = 8, ["name"] = "default:silver_sandstone"}, {["x"] = 8, ["y"] = 6, ["param1"] = 14, ["z"] = 9, ["name"] = "default:silver_sandstone"}, {["x"] = 8, ["y"] = 6, ["param1"] = 14, ["z"] = 10, ["name"] = "default:silver_sandstone"}, {["x"] = 8, ["y"] = 6, ["param1"] = 14, ["z"] = 11, ["name"] = "default:silver_sandstone"}, {["x"] = 8, ["y"] = 6, ["param1"] = 14, ["z"] = 12, ["name"] = "default:silver_sandstone"}, {["x"] = 8, ["y"] = 6, ["param1"] = 14, ["z"] = 13, ["name"] = "default:silver_sandstone"}, {["x"] = 8, ["y"] = 6, ["param1"] = 14, ["z"] = 14, ["name"] = "default:silver_sandstone"}, {["x"] = 8, ["y"] = 6, ["z"] = 15, ["name"] = "default:silver_sandstone"}, {["x"] = 8, ["param2"] = 20, ["y"] = 7, ["param1"] = 142, ["z"] = 0, ["name"] = "stairs:stair_silver_sandstone"}, {["x"] = 8, ["param2"] = 22, ["y"] = 7, ["param1"] = 158, ["z"] = 15, ["name"] = "stairs:stair_silver_sandstone"}, {["x"] = 9, ["y"] = 0, ["param1"] = 4, ["z"] = 0, ["name"] = "default:stone_block"}, {["x"] = 9, ["y"] = 0, ["param1"] = 4, ["z"] = 1, ["name"] = "default:stone_block"}, {["x"] = 9, ["y"] = 0, ["param1"] = 4, ["z"] = 2, ["name"] = "default:stone_block"}, {["x"] = 9, ["y"] = 0, ["param1"] = 4, ["z"] = 3, ["name"] = "default:stone_block"}, {["x"] = 9, ["y"] = 0, ["param1"] = 4, ["z"] = 4, ["name"] = "default:stone_block"}, {["x"] = 9, ["y"] = 0, ["param1"] = 4, ["z"] = 5, ["name"] = "default:stone_block"}, {["x"] = 9, ["y"] = 0, ["param1"] = 4, ["z"] = 6, ["name"] = "default:stone_block"}, {["x"] = 9, ["y"] = 0, ["param1"] = 4, ["z"] = 7, ["name"] = "default:stone_block"}, {["x"] = 9, ["y"] = 0, ["param1"] = 4, ["z"] = 8, ["name"] = "default:stone_block"}, {["x"] = 9, ["y"] = 0, ["param1"] = 4, ["z"] = 9, ["name"] = "default:stone_block"}, {["x"] = 9, ["y"] = 0, ["param1"] = 4, ["z"] = 10, ["name"] = "default:stone_block"}, {["x"] = 9, ["y"] = 0, ["param1"] = 4, ["z"] = 11, ["name"] = "default:stone_block"}, {["x"] = 9, ["y"] = 0, ["param1"] = 4, ["z"] = 12, ["name"] = "default:stone_block"}, {["x"] = 9, ["y"] = 0, ["param1"] = 4, ["z"] = 13, ["name"] = "default:stone_block"}, {["x"] = 9, ["y"] = 0, ["param1"] = 4, ["z"] = 14, ["name"] = "default:stone_block"}, {["x"] = 9, ["y"] = 0, ["param1"] = 4, ["z"] = 15, ["name"] = "default:stone_block"}, {["x"] = 9, ["y"] = 1, ["param1"] = 16, ["z"] = 0, ["name"] = "default:silver_sandstone"}, {["x"] = 9, ["meta"] = {["fields"] = {["state"] = "0"}, ["inventory"] = {}}, ["param2"] = 1, ["y"] = 1, ["param1"] = 142, ["z"] = 1, ["name"] = "doors:door_wood_a"}, {["x"] = 9, ["y"] = 1, ["param1"] = 15, ["z"] = 2, ["name"] = "default:silver_sandstone"}, {["x"] = 9, ["y"] = 1, ["z"] = 3, ["name"] = "default:silver_sandstone"}, {["x"] = 9, ["y"] = 1, ["z"] = 4, ["name"] = "default:silver_sandstone"}, {["x"] = 9, ["param2"] = 23, ["y"] = 1, ["param1"] = 158, ["z"] = 5, ["name"] = "stairs:stair_stonebrick"}, {["x"] = 9, ["y"] = 1, ["param1"] = 15, ["z"] = 6, ["name"] = "default:silver_sandstone"}, {["x"] = 9, ["param2"] = 23, ["y"] = 1, ["param1"] = 158, ["z"] = 7, ["name"] = "stairs:stair_stonebrick"}, {["x"] = 9, ["y"] = 1, ["param1"] = 15, ["z"] = 8, ["name"] = "default:silver_sandstone"}, {["x"] = 9, ["param2"] = 23, ["y"] = 1, ["param1"] = 157, ["z"] = 9, ["name"] = "stairs:stair_stonebrick"}, {["x"] = 9, ["y"] = 1, ["param1"] = 14, ["z"] = 10, ["name"] = "default:silver_sandstone"}, {["x"] = 9, ["param2"] = 23, ["y"] = 1, ["param1"] = 158, ["z"] = 11, ["name"] = "stairs:stair_stonebrick"}, {["x"] = 9, ["y"] = 1, ["param1"] = 15, ["z"] = 12, ["name"] = "default:silver_sandstone"}, {["x"] = 9, ["param2"] = 23, ["y"] = 1, ["param1"] = 158, ["z"] = 13, ["name"] = "stairs:stair_stonebrick"}, {["x"] = 9, ["y"] = 1, ["param1"] = 15, ["z"] = 14, ["name"] = "default:silver_sandstone"}, {["x"] = 9, ["y"] = 1, ["param1"] = 16, ["z"] = 15, ["name"] = "default:silver_sandstone"}, {["x"] = 9, ["y"] = 2, ["param1"] = 16, ["z"] = 0, ["name"] = "default:silver_sandstone"}, {["x"] = 9, ["param2"] = 1, ["y"] = 2, ["param1"] = 158, ["z"] = 1, ["name"] = "doors:hidden"}, {["x"] = 9, ["y"] = 2, ["param1"] = 15, ["z"] = 2, ["name"] = "default:silver_sandstone"}, {["x"] = 9, ["y"] = 2, ["z"] = 3, ["name"] = "default:silver_sandstone"}, {["x"] = 9, ["y"] = 2, ["param1"] = 15, ["z"] = 4, ["name"] = "default:silver_sandstone"}, {["x"] = 9, ["param2"] = 21, ["y"] = 2, ["param1"] = 174, ["z"] = 5, ["name"] = "doors:trapdoor_open"}, {["x"] = 9, ["y"] = 2, ["param1"] = 15, ["z"] = 6, ["name"] = "default:silver_sandstone"}, {["x"] = 9, ["param2"] = 21, ["y"] = 2, ["param1"] = 174, ["z"] = 7, ["name"] = "doors:trapdoor_open"}, {["x"] = 9, ["y"] = 2, ["param1"] = 15, ["z"] = 8, ["name"] = "default:silver_sandstone"}, {["x"] = 9, ["param2"] = 21, ["y"] = 2, ["param1"] = 173, ["z"] = 9, ["name"] = "doors:trapdoor_open"}, {["x"] = 9, ["y"] = 2, ["param1"] = 14, ["z"] = 10, ["name"] = "default:silver_sandstone"}, {["x"] = 9, ["param2"] = 21, ["y"] = 2, ["param1"] = 174, ["z"] = 11, ["name"] = "doors:trapdoor_open"}, {["x"] = 9, ["y"] = 2, ["param1"] = 15, ["z"] = 12, ["name"] = "default:silver_sandstone"}, {["x"] = 9, ["param2"] = 21, ["y"] = 2, ["param1"] = 174, ["z"] = 13, ["name"] = "doors:trapdoor_open"}, {["x"] = 9, ["y"] = 2, ["param1"] = 15, ["z"] = 14, ["name"] = "default:silver_sandstone"}, {["x"] = 9, ["y"] = 2, ["param1"] = 16, ["z"] = 15, ["name"] = "default:silver_sandstone"}, {["x"] = 9, ["y"] = 3, ["param1"] = 16, ["z"] = 0, ["name"] = "default:silver_sandstone"}, {["x"] = 9, ["y"] = 3, ["z"] = 1, ["name"] = "default:silver_sandstone"}, {["x"] = 9, ["y"] = 3, ["param1"] = 15, ["z"] = 2, ["name"] = "default:silver_sandstone"}, {["x"] = 9, ["y"] = 3, ["z"] = 3, ["name"] = "default:silver_sandstone"}, {["x"] = 9, ["y"] = 3, ["param1"] = 15, ["z"] = 4, ["name"] = "default:silver_sandstone"}, {["x"] = 9, ["param2"] = 1, ["y"] = 3, ["param1"] = 190, ["z"] = 5, ["name"] = "xpanes:bar_flat"}, {["x"] = 9, ["y"] = 3, ["param1"] = 15, ["z"] = 6, ["name"] = "default:silver_sandstone"}, {["x"] = 9, ["param2"] = 1, ["y"] = 3, ["param1"] = 190, ["z"] = 7, ["name"] = "xpanes:bar_flat"}, {["x"] = 9, ["y"] = 3, ["param1"] = 15, ["z"] = 8, ["name"] = "default:silver_sandstone"}, {["x"] = 9, ["param2"] = 3, ["y"] = 3, ["param1"] = 189, ["z"] = 9, ["name"] = "xpanes:bar_flat"}, {["x"] = 9, ["y"] = 3, ["z"] = 10, ["name"] = "default:silver_sandstone"}, {["x"] = 9, ["param2"] = 1, ["y"] = 3, ["param1"] = 190, ["z"] = 11, ["name"] = "xpanes:bar_flat"}, {["x"] = 9, ["y"] = 3, ["param1"] = 15, ["z"] = 12, ["name"] = "default:silver_sandstone"}, {["x"] = 9, ["param2"] = 1, ["y"] = 3, ["param1"] = 190, ["z"] = 13, ["name"] = "xpanes:bar_flat"}, {["x"] = 9, ["y"] = 3, ["param1"] = 15, ["z"] = 14, ["name"] = "default:silver_sandstone"}, {["x"] = 9, ["y"] = 3, ["param1"] = 16, ["z"] = 15, ["name"] = "default:silver_sandstone"}, {["x"] = 9, ["y"] = 4, ["param1"] = 16, ["z"] = 0, ["name"] = "default:silver_sandstone"}, {["x"] = 9, ["y"] = 4, ["z"] = 1, ["name"] = "default:silver_sandstone"}, {["x"] = 9, ["y"] = 4, ["z"] = 2, ["name"] = "default:silver_sandstone"}, {["x"] = 9, ["y"] = 4, ["z"] = 3, ["name"] = "default:silver_sandstone"}, {["x"] = 9, ["y"] = 4, ["z"] = 4, ["name"] = "default:silver_sandstone"}, {["x"] = 9, ["param2"] = 1, ["y"] = 4, ["param1"] = 206, ["z"] = 5, ["name"] = "xpanes:bar_flat"}, {["x"] = 9, ["y"] = 4, ["z"] = 6, ["name"] = "default:silver_sandstone"}, {["x"] = 9, ["param2"] = 1, ["y"] = 4, ["param1"] = 206, ["z"] = 7, ["name"] = "xpanes:bar_flat"}, {["x"] = 9, ["y"] = 4, ["z"] = 8, ["name"] = "default:silver_sandstone"}, {["x"] = 9, ["param2"] = 1, ["y"] = 4, ["param1"] = 205, ["z"] = 9, ["name"] = "xpanes:bar_flat"}, {["x"] = 9, ["y"] = 4, ["z"] = 10, ["name"] = "default:silver_sandstone"}, {["x"] = 9, ["param2"] = 1, ["y"] = 4, ["param1"] = 206, ["z"] = 11, ["name"] = "xpanes:bar_flat"}, {["x"] = 9, ["y"] = 4, ["z"] = 12, ["name"] = "default:silver_sandstone"}, {["x"] = 9, ["param2"] = 1, ["y"] = 4, ["param1"] = 206, ["z"] = 13, ["name"] = "xpanes:bar_flat"}, {["x"] = 9, ["y"] = 4, ["z"] = 14, ["name"] = "default:silver_sandstone"}, {["x"] = 9, ["y"] = 4, ["z"] = 15, ["name"] = "default:silver_sandstone"}, {["x"] = 9, ["y"] = 5, ["param1"] = 16, ["z"] = 0, ["name"] = "default:silver_sandstone"}, {["x"] = 9, ["y"] = 5, ["z"] = 1, ["name"] = "default:silver_sandstone"}, {["x"] = 9, ["y"] = 5, ["z"] = 2, ["name"] = "default:silver_sandstone"}, {["x"] = 9, ["y"] = 5, ["z"] = 3, ["name"] = "default:silver_sandstone"}, {["x"] = 9, ["y"] = 5, ["z"] = 4, ["name"] = "default:silver_sandstone"}, {["x"] = 9, ["param2"] = 1, ["y"] = 5, ["param1"] = 222, ["z"] = 5, ["name"] = "stairs:stair_stonebrick"}, {["x"] = 9, ["y"] = 5, ["z"] = 6, ["name"] = "default:silver_sandstone"}, {["x"] = 9, ["param2"] = 1, ["y"] = 5, ["param1"] = 222, ["z"] = 7, ["name"] = "stairs:stair_stonebrick"}, {["x"] = 9, ["y"] = 5, ["z"] = 8, ["name"] = "default:silver_sandstone"}, {["x"] = 9, ["param2"] = 1, ["y"] = 5, ["param1"] = 221, ["z"] = 9, ["name"] = "stairs:stair_stonebrick"}, {["x"] = 9, ["y"] = 5, ["z"] = 10, ["name"] = "default:silver_sandstone"}, {["x"] = 9, ["param2"] = 1, ["y"] = 5, ["param1"] = 222, ["z"] = 11, ["name"] = "stairs:stair_stonebrick"}, {["x"] = 9, ["y"] = 5, ["z"] = 12, ["name"] = "default:silver_sandstone"}, {["x"] = 9, ["param2"] = 1, ["y"] = 5, ["param1"] = 222, ["z"] = 13, ["name"] = "stairs:stair_stonebrick"}, {["x"] = 9, ["y"] = 5, ["z"] = 14, ["name"] = "default:silver_sandstone"}, {["x"] = 9, ["y"] = 5, ["param1"] = 16, ["z"] = 15, ["name"] = "default:silver_sandstone"}, {["x"] = 9, ["y"] = 6, ["z"] = 0, ["name"] = "default:silver_sandstone"}, {["x"] = 9, ["y"] = 6, ["z"] = 1, ["name"] = "default:silver_sandstone"}, {["x"] = 9, ["y"] = 6, ["z"] = 2, ["name"] = "default:silver_sandstone"}, {["x"] = 9, ["y"] = 6, ["z"] = 3, ["name"] = "default:silver_sandstone"}, {["x"] = 9, ["y"] = 6, ["z"] = 4, ["name"] = "default:silver_sandstone"}, {["x"] = 9, ["y"] = 6, ["z"] = 5, ["name"] = "default:silver_sandstone"}, {["x"] = 9, ["y"] = 6, ["z"] = 6, ["name"] = "default:silver_sandstone"}, {["x"] = 9, ["y"] = 6, ["z"] = 7, ["name"] = "default:silver_sandstone"}, {["x"] = 9, ["y"] = 6, ["z"] = 8, ["name"] = "default:silver_sandstone"}, {["x"] = 9, ["y"] = 6, ["param1"] = 14, ["z"] = 9, ["name"] = "default:silver_sandstone"}, {["x"] = 9, ["y"] = 6, ["param1"] = 14, ["z"] = 10, ["name"] = "default:silver_sandstone"}, {["x"] = 9, ["y"] = 6, ["param1"] = 14, ["z"] = 11, ["name"] = "default:silver_sandstone"}, {["x"] = 9, ["y"] = 6, ["param1"] = 14, ["z"] = 12, ["name"] = "default:silver_sandstone"}, {["x"] = 9, ["y"] = 6, ["param1"] = 14, ["z"] = 13, ["name"] = "default:silver_sandstone"}, {["x"] = 9, ["y"] = 6, ["param1"] = 14, ["z"] = 14, ["name"] = "default:silver_sandstone"}, {["x"] = 9, ["y"] = 6, ["z"] = 15, ["name"] = "default:silver_sandstone"}, {["x"] = 9, ["param2"] = 20, ["y"] = 7, ["param1"] = 126, ["z"] = 0, ["name"] = "stairs:stair_silver_sandstone"}, {["x"] = 9, ["param2"] = 22, ["y"] = 7, ["param1"] = 142, ["z"] = 15, ["name"] = "stairs:stair_silver_sandstone"}, {["x"] = 10, ["y"] = 0, ["param1"] = 4, ["z"] = 0, ["name"] = "default:stone_block"}, {["x"] = 10, ["y"] = 0, ["param1"] = 4, ["z"] = 1, ["name"] = "default:stone_block"}, {["x"] = 10, ["y"] = 0, ["param1"] = 4, ["z"] = 2, ["name"] = "default:stone_block"}, {["x"] = 10, ["y"] = 0, ["param1"] = 4, ["z"] = 3, ["name"] = "default:stone_block"}, {["x"] = 10, ["y"] = 0, ["param1"] = 4, ["z"] = 4, ["name"] = "default:stone_block"}, {["x"] = 10, ["y"] = 0, ["param1"] = 4, ["z"] = 5, ["name"] = "default:stone_block"}, {["x"] = 10, ["y"] = 0, ["param1"] = 4, ["z"] = 6, ["name"] = "default:stone_block"}, {["x"] = 10, ["y"] = 0, ["param1"] = 4, ["z"] = 7, ["name"] = "default:stone_block"}, {["x"] = 10, ["y"] = 0, ["param1"] = 4, ["z"] = 8, ["name"] = "default:stone_block"}, {["x"] = 10, ["y"] = 0, ["param1"] = 4, ["z"] = 9, ["name"] = "default:stone_block"}, {["x"] = 10, ["y"] = 0, ["param1"] = 4, ["z"] = 10, ["name"] = "default:stone_block"}, {["x"] = 10, ["y"] = 0, ["param1"] = 4, ["z"] = 11, ["name"] = "default:stone_block"}, {["x"] = 10, ["y"] = 0, ["param1"] = 4, ["z"] = 12, ["name"] = "default:stone_block"}, {["x"] = 10, ["y"] = 0, ["param1"] = 4, ["z"] = 13, ["name"] = "default:stone_block"}, {["x"] = 10, ["y"] = 0, ["param1"] = 4, ["z"] = 14, ["name"] = "default:stone_block"}, {["x"] = 10, ["y"] = 0, ["param1"] = 4, ["z"] = 15, ["name"] = "default:stone_block"}, {["x"] = 10, ["y"] = 1, ["param1"] = 110, ["z"] = 0, ["name"] = "walls:cobble"}, {["x"] = 10, ["y"] = 1, ["z"] = 2, ["name"] = "default:silver_sandstone"}, {["x"] = 10, ["y"] = 1, ["param1"] = 142, ["z"] = 15, ["name"] = "walls:cobble"}, {["x"] = 10, ["y"] = 2, ["param1"] = 126, ["z"] = 0, ["name"] = "walls:cobble"}, {["x"] = 10, ["y"] = 2, ["z"] = 2, ["name"] = "default:silver_sandstone"}, {["x"] = 10, ["y"] = 2, ["param1"] = 158, ["z"] = 15, ["name"] = "walls:cobble"}, {["x"] = 10, ["y"] = 3, ["param1"] = 110, ["z"] = 0, ["name"] = "walls:cobble"}, {["x"] = 10, ["y"] = 3, ["z"] = 2, ["name"] = "default:silver_sandstone"}, {["x"] = 10, ["y"] = 3, ["param1"] = 174, ["z"] = 15, ["name"] = "walls:cobble"}, {["x"] = 10, ["y"] = 4, ["param1"] = 126, ["z"] = 0, ["name"] = "walls:cobble"}, {["x"] = 10, ["y"] = 4, ["z"] = 2, ["name"] = "default:silver_sandstone"}, {["x"] = 10, ["y"] = 4, ["param1"] = 190, ["z"] = 15, ["name"] = "walls:cobble"}, {["x"] = 10, ["y"] = 5, ["param1"] = 142, ["z"] = 0, ["name"] = "stairs:stair_stonebrick"}, {["x"] = 10, ["y"] = 5, ["z"] = 2, ["name"] = "default:silver_sandstone"}, {["x"] = 10, ["y"] = 5, ["param1"] = 238, ["z"] = 5, ["name"] = "default:mese_post_light_junglewood"}, {["x"] = 10, ["y"] = 5, ["param1"] = 238, ["z"] = 7, ["name"] = "default:mese_post_light_junglewood"}, {["x"] = 10, ["y"] = 5, ["param1"] = 238, ["z"] = 9, ["name"] = "default:mese_post_light_junglewood"}, {["x"] = 10, ["y"] = 5, ["param1"] = 238, ["z"] = 11, ["name"] = "default:mese_post_light_junglewood"}, {["x"] = 10, ["y"] = 5, ["param1"] = 238, ["z"] = 13, ["name"] = "default:mese_post_light_junglewood"}, {["x"] = 10, ["param2"] = 2, ["y"] = 5, ["param1"] = 206, ["z"] = 15, ["name"] = "stairs:stair_stonebrick"}, {["x"] = 10, ["y"] = 6, ["z"] = 0, ["name"] = "default:silver_sandstone"}, {["x"] = 10, ["y"] = 6, ["param1"] = 62, ["z"] = 1, ["name"] = "default:silver_sandstone"}, {["x"] = 10, ["y"] = 6, ["param1"] = 78, ["z"] = 2, ["name"] = "default:silver_sandstone"}, {["x"] = 10, ["y"] = 6, ["param1"] = 94, ["z"] = 3, ["name"] = "default:silver_sandstone"}, {["x"] = 10, ["y"] = 6, ["param1"] = 94, ["z"] = 4, ["name"] = "default:silver_sandstone"}, {["x"] = 10, ["y"] = 6, ["param1"] = 110, ["z"] = 5, ["name"] = "default:silver_sandstone"}, {["x"] = 10, ["y"] = 6, ["param1"] = 94, ["z"] = 6, ["name"] = "default:silver_sandstone"}, {["x"] = 10, ["y"] = 6, ["param1"] = 110, ["z"] = 7, ["name"] = "default:silver_sandstone"}, {["x"] = 10, ["y"] = 6, ["param1"] = 110, ["z"] = 8, ["name"] = "default:silver_sandstone"}, {["x"] = 10, ["y"] = 6, ["param1"] = 126, ["z"] = 9, ["name"] = "default:silver_sandstone"}, {["x"] = 10, ["y"] = 6, ["param1"] = 110, ["z"] = 10, ["name"] = "default:silver_sandstone"}, {["x"] = 10, ["y"] = 6, ["param1"] = 94, ["z"] = 11, ["name"] = "default:silver_sandstone"}, {["x"] = 10, ["y"] = 6, ["param1"] = 94, ["z"] = 12, ["name"] = "default:silver_sandstone"}, {["x"] = 10, ["y"] = 6, ["param1"] = 110, ["z"] = 13, ["name"] = "default:silver_sandstone"}, {["x"] = 10, ["y"] = 6, ["param1"] = 94, ["z"] = 14, ["name"] = "default:silver_sandstone"}, {["x"] = 10, ["y"] = 6, ["z"] = 15, ["name"] = "default:silver_sandstone"}, {["x"] = 10, ["param2"] = 20, ["y"] = 7, ["param1"] = 110, ["z"] = 0, ["name"] = "stairs:stair_silver_sandstone"}, {["x"] = 10, ["param2"] = 22, ["y"] = 7, ["param1"] = 142, ["z"] = 15, ["name"] = "stairs:stair_silver_sandstone"}, {["x"] = 11, ["y"] = 0, ["param1"] = 4, ["z"] = 0, ["name"] = "default:stone_block"}, {["x"] = 11, ["y"] = 0, ["param1"] = 4, ["z"] = 1, ["name"] = "default:stone_block"}, {["x"] = 11, ["y"] = 0, ["param1"] = 4, ["z"] = 2, ["name"] = "default:stone_block"}, {["x"] = 11, ["y"] = 0, ["param1"] = 4, ["z"] = 3, ["name"] = "default:stone_block"}, {["x"] = 11, ["y"] = 0, ["param1"] = 4, ["z"] = 4, ["name"] = "default:stone_block"}, {["x"] = 11, ["y"] = 0, ["param1"] = 4, ["z"] = 5, ["name"] = "default:stone_block"}, {["x"] = 11, ["y"] = 0, ["param1"] = 4, ["z"] = 6, ["name"] = "default:stone_block"}, {["x"] = 11, ["y"] = 0, ["param1"] = 4, ["z"] = 7, ["name"] = "default:stone_block"}, {["x"] = 11, ["y"] = 0, ["param1"] = 4, ["z"] = 8, ["name"] = "default:stone_block"}, {["x"] = 11, ["y"] = 0, ["param1"] = 4, ["z"] = 9, ["name"] = "default:stone_block"}, {["x"] = 11, ["y"] = 0, ["param1"] = 4, ["z"] = 10, ["name"] = "default:stone_block"}, {["x"] = 11, ["y"] = 0, ["param1"] = 4, ["z"] = 11, ["name"] = "default:stone_block"}, {["x"] = 11, ["y"] = 0, ["param1"] = 4, ["z"] = 12, ["name"] = "default:stone_block"}, {["x"] = 11, ["y"] = 0, ["param1"] = 4, ["z"] = 13, ["name"] = "default:stone_block"}, {["x"] = 11, ["y"] = 0, ["param1"] = 4, ["z"] = 14, ["name"] = "default:stone_block"}, {["x"] = 11, ["y"] = 0, ["param1"] = 4, ["z"] = 15, ["name"] = "default:stone_block"}, {["x"] = 11, ["y"] = 1, ["param1"] = 94, ["z"] = 0, ["name"] = "walls:cobble"}, {["x"] = 11, ["y"] = 1, ["z"] = 2, ["name"] = "default:silver_sandstone"}, {["x"] = 11, ["param2"] = 1, ["y"] = 1, ["param1"] = 158, ["z"] = 5, ["name"] = "stairs:stair_wood"}, {["x"] = 11, ["param2"] = 1, ["y"] = 1, ["param1"] = 158, ["z"] = 7, ["name"] = "stairs:stair_wood"}, {["x"] = 11, ["param2"] = 1, ["y"] = 1, ["param1"] = 158, ["z"] = 9, ["name"] = "stairs:stair_wood"}, {["x"] = 11, ["param2"] = 1, ["y"] = 1, ["param1"] = 158, ["z"] = 11, ["name"] = "stairs:stair_wood"}, {["x"] = 11, ["param2"] = 1, ["y"] = 1, ["param1"] = 158, ["z"] = 13, ["name"] = "stairs:stair_wood"}, {["x"] = 11, ["y"] = 1, ["param1"] = 126, ["z"] = 15, ["name"] = "walls:cobble"}, {["x"] = 11, ["y"] = 2, ["param1"] = 110, ["z"] = 0, ["name"] = "walls:cobble"}, {["x"] = 11, ["y"] = 2, ["z"] = 2, ["name"] = "default:silver_sandstone"}, {["x"] = 11, ["y"] = 2, ["param1"] = 142, ["z"] = 15, ["name"] = "walls:cobble"}, {["x"] = 11, ["y"] = 3, ["param1"] = 94, ["z"] = 0, ["name"] = "walls:cobble"}, {["x"] = 11, ["y"] = 3, ["z"] = 2, ["name"] = "default:silver_sandstone"}, {["x"] = 11, ["y"] = 3, ["param1"] = 158, ["z"] = 15, ["name"] = "walls:cobble"}, {["x"] = 11, ["y"] = 4, ["param1"] = 110, ["z"] = 0, ["name"] = "walls:cobble"}, {["x"] = 11, ["y"] = 4, ["z"] = 2, ["name"] = "default:silver_sandstone"}, {["x"] = 11, ["y"] = 4, ["param1"] = 174, ["z"] = 15, ["name"] = "walls:cobble"}, {["x"] = 11, ["y"] = 5, ["param1"] = 126, ["z"] = 0, ["name"] = "stairs:stair_stonebrick"}, {["x"] = 11, ["y"] = 5, ["z"] = 2, ["name"] = "default:silver_sandstone"}, {["x"] = 11, ["param2"] = 2, ["y"] = 5, ["param1"] = 190, ["z"] = 15, ["name"] = "stairs:stair_stonebrick"}, {["x"] = 11, ["y"] = 6, ["z"] = 0, ["name"] = "default:silver_sandstone"}, {["x"] = 11, ["y"] = 6, ["param1"] = 46, ["z"] = 1, ["name"] = "default:silver_sandstone"}, {["x"] = 11, ["y"] = 6, ["param1"] = 62, ["z"] = 2, ["name"] = "default:silver_sandstone"}, {["x"] = 11, ["y"] = 6, ["param1"] = 78, ["z"] = 3, ["name"] = "default:silver_sandstone"}, {["x"] = 11, ["y"] = 6, ["param1"] = 78, ["z"] = 4, ["name"] = "default:silver_sandstone"}, {["x"] = 11, ["y"] = 6, ["param1"] = 94, ["z"] = 5, ["name"] = "default:silver_sandstone"}, {["x"] = 11, ["y"] = 6, ["param1"] = 78, ["z"] = 6, ["name"] = "default:silver_sandstone"}, {["x"] = 11, ["y"] = 6, ["param1"] = 94, ["z"] = 7, ["name"] = "default:silver_sandstone"}, {["x"] = 11, ["y"] = 6, ["param1"] = 94, ["z"] = 8, ["name"] = "default:silver_sandstone"}, {["x"] = 11, ["y"] = 6, ["param1"] = 110, ["z"] = 9, ["name"] = "default:silver_sandstone"}, {["x"] = 11, ["y"] = 6, ["param1"] = 94, ["z"] = 10, ["name"] = "default:silver_sandstone"}, {["x"] = 11, ["y"] = 6, ["param1"] = 78, ["z"] = 11, ["name"] = "default:silver_sandstone"}, {["x"] = 11, ["y"] = 6, ["param1"] = 78, ["z"] = 12, ["name"] = "default:silver_sandstone"}, {["x"] = 11, ["y"] = 6, ["param1"] = 94, ["z"] = 13, ["name"] = "default:silver_sandstone"}, {["x"] = 11, ["y"] = 6, ["param1"] = 78, ["z"] = 14, ["name"] = "default:silver_sandstone"}, {["x"] = 11, ["y"] = 6, ["z"] = 15, ["name"] = "default:silver_sandstone"}, {["x"] = 11, ["param2"] = 20, ["y"] = 7, ["param1"] = 94, ["z"] = 0, ["name"] = "stairs:stair_silver_sandstone"}, {["x"] = 11, ["param2"] = 22, ["y"] = 7, ["param1"] = 126, ["z"] = 15, ["name"] = "stairs:stair_silver_sandstone"}, {["x"] = 12, ["y"] = 0, ["param1"] = 4, ["z"] = 0, ["name"] = "default:stone_block"}, {["x"] = 12, ["y"] = 0, ["param1"] = 4, ["z"] = 1, ["name"] = "default:stone_block"}, {["x"] = 12, ["y"] = 0, ["param1"] = 4, ["z"] = 2, ["name"] = "default:stone_block"}, {["x"] = 12, ["y"] = 0, ["param1"] = 4, ["z"] = 3, ["name"] = "default:stone_block"}, {["x"] = 12, ["y"] = 0, ["param1"] = 4, ["z"] = 4, ["name"] = "default:stone_block"}, {["x"] = 12, ["y"] = 0, ["param1"] = 4, ["z"] = 5, ["name"] = "default:stone_block"}, {["x"] = 12, ["y"] = 0, ["param1"] = 4, ["z"] = 6, ["name"] = "default:stone_block"}, {["x"] = 12, ["y"] = 0, ["param1"] = 4, ["z"] = 7, ["name"] = "default:stone_block"}, {["x"] = 12, ["y"] = 0, ["param1"] = 4, ["z"] = 8, ["name"] = "default:stone_block"}, {["x"] = 12, ["y"] = 0, ["param1"] = 4, ["z"] = 9, ["name"] = "default:stone_block"}, {["x"] = 12, ["y"] = 0, ["param1"] = 4, ["z"] = 10, ["name"] = "default:stone_block"}, {["x"] = 12, ["y"] = 0, ["param1"] = 4, ["z"] = 11, ["name"] = "default:stone_block"}, {["x"] = 12, ["y"] = 0, ["param1"] = 4, ["z"] = 12, ["name"] = "default:stone_block"}, {["x"] = 12, ["y"] = 0, ["param1"] = 4, ["z"] = 13, ["name"] = "default:stone_block"}, {["x"] = 12, ["y"] = 0, ["param1"] = 4, ["z"] = 14, ["name"] = "default:stone_block"}, {["x"] = 12, ["y"] = 0, ["param1"] = 4, ["z"] = 15, ["name"] = "default:stone_block"}, {["x"] = 12, ["y"] = 1, ["param1"] = 16, ["z"] = 0, ["name"] = "default:silver_sandstone"}, {["x"] = 12, ["y"] = 1, ["z"] = 2, ["name"] = "default:silver_sandstone"}, {["x"] = 12, ["param2"] = 1, ["y"] = 1, ["param1"] = 142, ["z"] = 4, ["name"] = "xpanes:bar_flat"}, {["x"] = 12, ["param2"] = 3, ["y"] = 1, ["param1"] = 157, ["z"] = 5, ["name"] = "xpanes:bar_flat"}, {["x"] = 12, ["param2"] = 3, ["y"] = 1, ["param1"] = 142, ["z"] = 6, ["name"] = "xpanes:bar_flat"}, {["x"] = 12, ["param2"] = 3, ["y"] = 1, ["param1"] = 141, ["z"] = 7, ["name"] = "xpanes:bar_flat"}, {["x"] = 12, ["param2"] = 3, ["y"] = 1, ["param1"] = 158, ["z"] = 8, ["name"] = "xpanes:bar_flat"}, {["x"] = 12, ["param2"] = 3, ["y"] = 1, ["param1"] = 141, ["z"] = 9, ["name"] = "xpanes:bar_flat"}, {["x"] = 12, ["param2"] = 3, ["y"] = 1, ["param1"] = 140, ["z"] = 10, ["name"] = "xpanes:bar_flat"}, {["x"] = 12, ["param2"] = 3, ["y"] = 1, ["param1"] = 157, ["z"] = 11, ["name"] = "xpanes:bar_flat"}, {["x"] = 12, ["param2"] = 3, ["y"] = 1, ["param1"] = 142, ["z"] = 12, ["name"] = "xpanes:bar_flat"}, {["x"] = 12, ["param2"] = 3, ["y"] = 1, ["param1"] = 141, ["z"] = 13, ["name"] = "xpanes:bar_flat"}, {["x"] = 12, ["param2"] = 3, ["y"] = 1, ["param1"] = 158, ["z"] = 14, ["name"] = "xpanes:bar_flat"}, {["x"] = 12, ["y"] = 1, ["param1"] = 16, ["z"] = 15, ["name"] = "default:silver_sandstone"}, {["x"] = 12, ["y"] = 2, ["param1"] = 16, ["z"] = 0, ["name"] = "default:silver_sandstone"}, {["x"] = 12, ["y"] = 2, ["z"] = 2, ["name"] = "default:silver_sandstone"}, {["x"] = 12, ["param2"] = 1, ["y"] = 2, ["param1"] = 158, ["z"] = 4, ["name"] = "xpanes:bar_flat"}, {["x"] = 12, ["param2"] = 3, ["y"] = 2, ["param1"] = 174, ["z"] = 5, ["name"] = "xpanes:bar_flat"}, {["x"] = 12, ["param2"] = 3, ["y"] = 2, ["param1"] = 158, ["z"] = 6, ["name"] = "xpanes:bar_flat"}, {["x"] = 12, ["param2"] = 3, ["y"] = 2, ["param1"] = 157, ["z"] = 7, ["name"] = "xpanes:bar_flat"}, {["x"] = 12, ["param2"] = 3, ["y"] = 2, ["param1"] = 174, ["z"] = 8, ["name"] = "xpanes:bar_flat"}, {["x"] = 12, ["param2"] = 3, ["y"] = 2, ["param1"] = 157, ["z"] = 9, ["name"] = "xpanes:bar_flat"}, {["x"] = 12, ["param2"] = 3, ["y"] = 2, ["param1"] = 156, ["z"] = 10, ["name"] = "xpanes:bar_flat"}, {["x"] = 12, ["param2"] = 3, ["y"] = 2, ["param1"] = 173, ["z"] = 11, ["name"] = "xpanes:bar_flat"}, {["x"] = 12, ["param2"] = 3, ["y"] = 2, ["param1"] = 158, ["z"] = 12, ["name"] = "xpanes:bar_flat"}, {["x"] = 12, ["param2"] = 3, ["y"] = 2, ["param1"] = 158, ["z"] = 13, ["name"] = "xpanes:bar_flat"}, {["x"] = 12, ["param2"] = 3, ["y"] = 2, ["param1"] = 174, ["z"] = 14, ["name"] = "xpanes:bar_flat"}, {["x"] = 12, ["y"] = 2, ["param1"] = 16, ["z"] = 15, ["name"] = "default:silver_sandstone"}, {["x"] = 12, ["y"] = 3, ["param1"] = 16, ["z"] = 0, ["name"] = "default:silver_sandstone"}, {["x"] = 12, ["y"] = 3, ["z"] = 2, ["name"] = "default:silver_sandstone"}, {["x"] = 12, ["param2"] = 1, ["y"] = 3, ["param1"] = 158, ["z"] = 3, ["name"] = "xpanes:bar_flat"}, {["x"] = 12, ["param2"] = 3, ["y"] = 3, ["param1"] = 174, ["z"] = 4, ["name"] = "xpanes:bar_flat"}, {["x"] = 12, ["param2"] = 3, ["y"] = 3, ["param1"] = 190, ["z"] = 5, ["name"] = "xpanes:bar_flat"}, {["x"] = 12, ["param2"] = 3, ["y"] = 3, ["param1"] = 174, ["z"] = 6, ["name"] = "xpanes:bar_flat"}, {["x"] = 12, ["param2"] = 3, ["y"] = 3, ["param1"] = 174, ["z"] = 7, ["name"] = "xpanes:bar_flat"}, {["x"] = 12, ["param2"] = 3, ["y"] = 3, ["param1"] = 190, ["z"] = 8, ["name"] = "xpanes:bar_flat"}, {["x"] = 12, ["param2"] = 3, ["y"] = 3, ["param1"] = 173, ["z"] = 9, ["name"] = "xpanes:bar_flat"}, {["x"] = 12, ["param2"] = 3, ["y"] = 3, ["param1"] = 172, ["z"] = 10, ["name"] = "xpanes:bar_flat"}, {["x"] = 12, ["param2"] = 3, ["y"] = 3, ["param1"] = 189, ["z"] = 11, ["name"] = "xpanes:bar_flat"}, {["x"] = 12, ["param2"] = 3, ["y"] = 3, ["param1"] = 174, ["z"] = 12, ["name"] = "xpanes:bar_flat"}, {["x"] = 12, ["param2"] = 3, ["y"] = 3, ["param1"] = 174, ["z"] = 13, ["name"] = "xpanes:bar_flat"}, {["x"] = 12, ["param2"] = 3, ["y"] = 3, ["param1"] = 190, ["z"] = 14, ["name"] = "xpanes:bar_flat"}, {["x"] = 12, ["y"] = 3, ["param1"] = 16, ["z"] = 15, ["name"] = "default:silver_sandstone"}, {["x"] = 12, ["y"] = 4, ["param1"] = 16, ["z"] = 0, ["name"] = "default:silver_sandstone"}, {["x"] = 12, ["y"] = 4, ["z"] = 2, ["name"] = "default:silver_sandstone"}, {["x"] = 12, ["param2"] = 1, ["y"] = 4, ["param1"] = 174, ["z"] = 3, ["name"] = "xpanes:bar_flat"}, {["x"] = 12, ["param2"] = 3, ["y"] = 4, ["param1"] = 190, ["z"] = 4, ["name"] = "xpanes:bar_flat"}, {["x"] = 12, ["param2"] = 3, ["y"] = 4, ["param1"] = 206, ["z"] = 5, ["name"] = "xpanes:bar_flat"}, {["x"] = 12, ["param2"] = 3, ["y"] = 4, ["param1"] = 190, ["z"] = 6, ["name"] = "xpanes:bar_flat"}, {["x"] = 12, ["param2"] = 3, ["y"] = 4, ["param1"] = 190, ["z"] = 7, ["name"] = "xpanes:bar_flat"}, {["x"] = 12, ["param2"] = 3, ["y"] = 4, ["param1"] = 206, ["z"] = 8, ["name"] = "xpanes:bar_flat"}, {["x"] = 12, ["param2"] = 3, ["y"] = 4, ["param1"] = 189, ["z"] = 9, ["name"] = "xpanes:bar_flat"}, {["x"] = 12, ["param2"] = 3, ["y"] = 4, ["param1"] = 188, ["z"] = 10, ["name"] = "xpanes:bar_flat"}, {["x"] = 12, ["param2"] = 3, ["y"] = 4, ["param1"] = 205, ["z"] = 11, ["name"] = "xpanes:bar_flat"}, {["x"] = 12, ["param2"] = 3, ["y"] = 4, ["param1"] = 190, ["z"] = 12, ["name"] = "xpanes:bar_flat"}, {["x"] = 12, ["param2"] = 3, ["y"] = 4, ["param1"] = 190, ["z"] = 13, ["name"] = "xpanes:bar_flat"}, {["x"] = 12, ["param2"] = 3, ["y"] = 4, ["param1"] = 206, ["z"] = 14, ["name"] = "xpanes:bar_flat"}, {["x"] = 12, ["y"] = 4, ["param1"] = 16, ["z"] = 15, ["name"] = "default:silver_sandstone"}, {["x"] = 12, ["y"] = 5, ["param1"] = 16, ["z"] = 0, ["name"] = "default:silver_sandstone"}, {["x"] = 12, ["y"] = 5, ["z"] = 2, ["name"] = "default:silver_sandstone"}, {["x"] = 12, ["param2"] = 1, ["y"] = 5, ["param1"] = 190, ["z"] = 3, ["name"] = "xpanes:bar_flat"}, {["x"] = 12, ["param2"] = 3, ["y"] = 5, ["param1"] = 206, ["z"] = 4, ["name"] = "xpanes:bar_flat"}, {["x"] = 12, ["param2"] = 3, ["y"] = 5, ["param1"] = 222, ["z"] = 5, ["name"] = "xpanes:bar_flat"}, {["x"] = 12, ["param2"] = 3, ["y"] = 5, ["param1"] = 206, ["z"] = 6, ["name"] = "xpanes:bar_flat"}, {["x"] = 12, ["param2"] = 3, ["y"] = 5, ["param1"] = 206, ["z"] = 7, ["name"] = "xpanes:bar_flat"}, {["x"] = 12, ["param2"] = 3, ["y"] = 5, ["param1"] = 222, ["z"] = 8, ["name"] = "xpanes:bar_flat"}, {["x"] = 12, ["param2"] = 3, ["y"] = 5, ["param1"] = 205, ["z"] = 9, ["name"] = "xpanes:bar_flat"}, {["x"] = 12, ["param2"] = 3, ["y"] = 5, ["param1"] = 204, ["z"] = 10, ["name"] = "xpanes:bar_flat"}, {["x"] = 12, ["param2"] = 3, ["y"] = 5, ["param1"] = 221, ["z"] = 11, ["name"] = "xpanes:bar_flat"}, {["x"] = 12, ["param2"] = 3, ["y"] = 5, ["param1"] = 206, ["z"] = 12, ["name"] = "xpanes:bar_flat"}, {["x"] = 12, ["param2"] = 3, ["y"] = 5, ["param1"] = 206, ["z"] = 13, ["name"] = "xpanes:bar_flat"}, {["x"] = 12, ["param2"] = 3, ["y"] = 5, ["param1"] = 222, ["z"] = 14, ["name"] = "xpanes:bar_flat"}, {["x"] = 12, ["y"] = 5, ["param1"] = 16, ["z"] = 15, ["name"] = "default:silver_sandstone"}, {["x"] = 12, ["y"] = 6, ["z"] = 0, ["name"] = "default:silver_sandstone"}, {["x"] = 12, ["y"] = 6, ["param1"] = 30, ["z"] = 1, ["name"] = "default:silver_sandstone"}, {["x"] = 12, ["y"] = 6, ["param1"] = 46, ["z"] = 2, ["name"] = "default:silver_sandstone"}, {["x"] = 12, ["y"] = 6, ["param1"] = 62, ["z"] = 3, ["name"] = "default:silver_sandstone"}, {["x"] = 12, ["y"] = 6, ["param1"] = 62, ["z"] = 4, ["name"] = "default:silver_sandstone"}, {["x"] = 12, ["y"] = 6, ["param1"] = 78, ["z"] = 5, ["name"] = "default:silver_sandstone"}, {["x"] = 12, ["y"] = 6, ["param1"] = 62, ["z"] = 6, ["name"] = "default:silver_sandstone"}, {["x"] = 12, ["y"] = 6, ["param1"] = 78, ["z"] = 7, ["name"] = "default:silver_sandstone"}, {["x"] = 12, ["y"] = 6, ["param1"] = 78, ["z"] = 8, ["name"] = "default:silver_sandstone"}, {["x"] = 12, ["y"] = 6, ["param1"] = 94, ["z"] = 9, ["name"] = "default:silver_sandstone"}, {["x"] = 12, ["y"] = 6, ["param1"] = 78, ["z"] = 10, ["name"] = "default:silver_sandstone"}, {["x"] = 12, ["y"] = 6, ["param1"] = 62, ["z"] = 11, ["name"] = "default:silver_sandstone"}, {["x"] = 12, ["y"] = 6, ["param1"] = 62, ["z"] = 12, ["name"] = "default:silver_sandstone"}, {["x"] = 12, ["y"] = 6, ["param1"] = 78, ["z"] = 13, ["name"] = "default:silver_sandstone"}, {["x"] = 12, ["y"] = 6, ["param1"] = 62, ["z"] = 14, ["name"] = "default:silver_sandstone"}, {["x"] = 12, ["y"] = 6, ["z"] = 15, ["name"] = "default:silver_sandstone"}, {["x"] = 12, ["param2"] = 20, ["y"] = 7, ["param1"] = 78, ["z"] = 0, ["name"] = "stairs:stair_silver_sandstone"}, {["x"] = 12, ["param2"] = 22, ["y"] = 7, ["param1"] = 142, ["z"] = 15, ["name"] = "stairs:stair_silver_sandstone"}, {["x"] = 13, ["y"] = 0, ["param1"] = 4, ["z"] = 0, ["name"] = "default:stone_block"}, {["x"] = 13, ["y"] = 0, ["param1"] = 4, ["z"] = 1, ["name"] = "default:stone_block"}, {["x"] = 13, ["y"] = 0, ["param1"] = 4, ["z"] = 2, ["name"] = "default:stone_block"}, {["x"] = 13, ["y"] = 0, ["param1"] = 4, ["z"] = 3, ["name"] = "default:stone_block"}, {["x"] = 13, ["y"] = 0, ["param1"] = 4, ["z"] = 4, ["name"] = "default:stone_block"}, {["x"] = 13, ["y"] = 0, ["param1"] = 4, ["z"] = 5, ["name"] = "default:stone_block"}, {["x"] = 13, ["y"] = 0, ["param1"] = 4, ["z"] = 6, ["name"] = "default:stone_block"}, {["x"] = 13, ["y"] = 0, ["param1"] = 4, ["z"] = 7, ["name"] = "default:stone_block"}, {["x"] = 13, ["y"] = 0, ["param1"] = 4, ["z"] = 8, ["name"] = "default:stone_block"}, {["x"] = 13, ["y"] = 0, ["param1"] = 4, ["z"] = 9, ["name"] = "default:stone_block"}, {["x"] = 13, ["y"] = 0, ["param1"] = 4, ["z"] = 10, ["name"] = "default:stone_block"}, {["x"] = 13, ["y"] = 0, ["param1"] = 4, ["z"] = 11, ["name"] = "default:stone_block"}, {["x"] = 13, ["y"] = 0, ["param1"] = 4, ["z"] = 12, ["name"] = "default:stone_block"}, {["x"] = 13, ["y"] = 0, ["param1"] = 4, ["z"] = 13, ["name"] = "default:stone_block"}, {["x"] = 13, ["y"] = 0, ["param1"] = 4, ["z"] = 14, ["name"] = "default:stone_block"}, {["x"] = 13, ["y"] = 0, ["param1"] = 4, ["z"] = 15, ["name"] = "default:stone_block"}, {["x"] = 13, ["y"] = 1, ["param1"] = 94, ["z"] = 0, ["name"] = "walls:cobble"}, {["x"] = 13, ["meta"] = {["fields"] = {["state"] = "0"}, ["inventory"] = {}}, ["param2"] = 2, ["y"] = 1, ["param1"] = 126, ["z"] = 2, ["name"] = "doors:door_wood_a"}, {["x"] = 13, ["param2"] = 1, ["y"] = 1, ["param1"] = 141, ["z"] = 3, ["name"] = "doors:trapdoor_open"}, {["x"] = 13, ["param2"] = 1, ["y"] = 1, ["param1"] = 157, ["z"] = 4, ["name"] = "doors:trapdoor_open"}, {["x"] = 13, ["param2"] = 1, ["y"] = 1, ["param1"] = 157, ["z"] = 6, ["name"] = "doors:trapdoor_open"}, {["x"] = 13, ["param2"] = 1, ["y"] = 1, ["param1"] = 157, ["z"] = 7, ["name"] = "doors:trapdoor_open"}, {["x"] = 13, ["param2"] = 1, ["y"] = 1, ["param1"] = 156, ["z"] = 9, ["name"] = "doors:trapdoor_open"}, {["x"] = 13, ["param2"] = 1, ["y"] = 1, ["param1"] = 155, ["z"] = 10, ["name"] = "doors:trapdoor_open"}, {["x"] = 13, ["param2"] = 1, ["y"] = 1, ["param1"] = 157, ["z"] = 12, ["name"] = "doors:trapdoor_open"}, {["x"] = 13, ["param2"] = 1, ["y"] = 1, ["param1"] = 157, ["z"] = 13, ["name"] = "doors:trapdoor_open"}, {["x"] = 13, ["y"] = 1, ["param1"] = 158, ["z"] = 15, ["name"] = "walls:cobble"}, {["x"] = 13, ["y"] = 2, ["param1"] = 110, ["z"] = 0, ["name"] = "walls:cobble"}, {["x"] = 13, ["param2"] = 2, ["y"] = 2, ["param1"] = 142, ["z"] = 2, ["name"] = "doors:hidden"}, {["x"] = 13, ["param2"] = 1, ["y"] = 2, ["param1"] = 158, ["z"] = 3, ["name"] = "doors:trapdoor_open"}, {["x"] = 13, ["param2"] = 1, ["y"] = 2, ["param1"] = 174, ["z"] = 4, ["name"] = "doors:trapdoor_open"}, {["x"] = 13, ["param2"] = 1, ["y"] = 2, ["param1"] = 174, ["z"] = 6, ["name"] = "doors:trapdoor_open"}, {["x"] = 13, ["param2"] = 1, ["y"] = 2, ["param1"] = 174, ["z"] = 7, ["name"] = "doors:trapdoor_open"}, {["x"] = 13, ["param2"] = 1, ["y"] = 2, ["param1"] = 172, ["z"] = 9, ["name"] = "doors:trapdoor_open"}, {["x"] = 13, ["param2"] = 1, ["y"] = 2, ["param1"] = 172, ["z"] = 10, ["name"] = "doors:trapdoor_open"}, {["x"] = 13, ["param2"] = 1, ["y"] = 2, ["param1"] = 174, ["z"] = 12, ["name"] = "doors:trapdoor_open"}, {["x"] = 13, ["param2"] = 1, ["y"] = 2, ["param1"] = 174, ["z"] = 13, ["name"] = "doors:trapdoor_open"}, {["x"] = 13, ["y"] = 2, ["param1"] = 174, ["z"] = 15, ["name"] = "walls:cobble"}, {["x"] = 13, ["y"] = 3, ["param1"] = 94, ["z"] = 0, ["name"] = "walls:cobble"}, {["x"] = 13, ["y"] = 3, ["z"] = 2, ["name"] = "default:silver_sandstone"}, {["x"] = 13, ["y"] = 3, ["param1"] = 190, ["z"] = 15, ["name"] = "walls:cobble"}, {["x"] = 13, ["y"] = 4, ["param1"] = 78, ["z"] = 0, ["name"] = "walls:cobble"}, {["x"] = 13, ["y"] = 4, ["z"] = 2, ["name"] = "default:silver_sandstone"}, {["x"] = 13, ["y"] = 4, ["param1"] = 206, ["z"] = 15, ["name"] = "walls:cobble"}, {["x"] = 13, ["y"] = 5, ["param1"] = 94, ["z"] = 0, ["name"] = "stairs:stair_stonebrick"}, {["x"] = 13, ["y"] = 5, ["z"] = 2, ["name"] = "default:silver_sandstone"}, {["x"] = 13, ["y"] = 5, ["param1"] = 238, ["z"] = 5, ["name"] = "default:mese_post_light_junglewood"}, {["x"] = 13, ["y"] = 5, ["param1"] = 238, ["z"] = 8, ["name"] = "default:mese_post_light_junglewood"}, {["x"] = 13, ["y"] = 5, ["param1"] = 238, ["z"] = 11, ["name"] = "default:mese_post_light_junglewood"}, {["x"] = 13, ["y"] = 5, ["param1"] = 238, ["z"] = 14, ["name"] = "default:mese_post_light_junglewood"}, {["x"] = 13, ["param2"] = 2, ["y"] = 5, ["param1"] = 222, ["z"] = 15, ["name"] = "stairs:stair_stonebrick"}, {["x"] = 13, ["y"] = 6, ["z"] = 0, ["name"] = "default:silver_sandstone"}, {["x"] = 13, ["y"] = 6, ["param1"] = 14, ["z"] = 1, ["name"] = "default:silver_sandstone"}, {["x"] = 13, ["y"] = 6, ["param1"] = 30, ["z"] = 2, ["name"] = "default:silver_sandstone"}, {["x"] = 13, ["y"] = 6, ["param1"] = 46, ["z"] = 3, ["name"] = "default:silver_sandstone"}, {["x"] = 13, ["y"] = 6, ["param1"] = 46, ["z"] = 4, ["name"] = "default:silver_sandstone"}, {["x"] = 13, ["y"] = 6, ["param1"] = 62, ["z"] = 5, ["name"] = "default:silver_sandstone"}, {["x"] = 13, ["y"] = 6, ["param1"] = 46, ["z"] = 6, ["name"] = "default:silver_sandstone"}, {["x"] = 13, ["y"] = 6, ["param1"] = 62, ["z"] = 7, ["name"] = "default:silver_sandstone"}, {["x"] = 13, ["y"] = 6, ["param1"] = 62, ["z"] = 8, ["name"] = "default:silver_sandstone"}, {["x"] = 13, ["y"] = 6, ["param1"] = 78, ["z"] = 9, ["name"] = "default:silver_sandstone"}, {["x"] = 13, ["y"] = 6, ["param1"] = 62, ["z"] = 10, ["name"] = "default:silver_sandstone"}, {["x"] = 13, ["y"] = 6, ["param1"] = 46, ["z"] = 11, ["name"] = "default:silver_sandstone"}, {["x"] = 13, ["y"] = 6, ["param1"] = 46, ["z"] = 12, ["name"] = "default:silver_sandstone"}, {["x"] = 13, ["y"] = 6, ["param1"] = 62, ["z"] = 13, ["name"] = "default:silver_sandstone"}, {["x"] = 13, ["y"] = 6, ["param1"] = 46, ["z"] = 14, ["name"] = "default:silver_sandstone"}, {["x"] = 13, ["y"] = 6, ["z"] = 15, ["name"] = "default:silver_sandstone"}, {["x"] = 13, ["param2"] = 20, ["y"] = 7, ["param1"] = 62, ["z"] = 0, ["name"] = "stairs:stair_silver_sandstone"}, {["x"] = 13, ["param2"] = 22, ["y"] = 7, ["param1"] = 158, ["z"] = 15, ["name"] = "stairs:stair_silver_sandstone"}, {["x"] = 14, ["y"] = 0, ["param1"] = 4, ["z"] = 0, ["name"] = "default:stone_block"}, {["x"] = 14, ["y"] = 0, ["param1"] = 4, ["z"] = 1, ["name"] = "default:stone_block"}, {["x"] = 14, ["y"] = 0, ["param1"] = 4, ["z"] = 2, ["name"] = "default:stone_block"}, {["x"] = 14, ["y"] = 0, ["param1"] = 4, ["z"] = 3, ["name"] = "default:stone_block"}, {["x"] = 14, ["y"] = 0, ["param1"] = 4, ["z"] = 4, ["name"] = "default:stone_block"}, {["x"] = 14, ["y"] = 0, ["param1"] = 4, ["z"] = 5, ["name"] = "default:stone_block"}, {["x"] = 14, ["y"] = 0, ["param1"] = 4, ["z"] = 6, ["name"] = "default:stone_block"}, {["x"] = 14, ["y"] = 0, ["param1"] = 4, ["z"] = 7, ["name"] = "default:stone_block"}, {["x"] = 14, ["y"] = 0, ["param1"] = 4, ["z"] = 8, ["name"] = "default:stone_block"}, {["x"] = 14, ["y"] = 0, ["param1"] = 4, ["z"] = 9, ["name"] = "default:stone_block"}, {["x"] = 14, ["y"] = 0, ["param1"] = 4, ["z"] = 10, ["name"] = "default:stone_block"}, {["x"] = 14, ["y"] = 0, ["param1"] = 4, ["z"] = 11, ["name"] = "default:stone_block"}, {["x"] = 14, ["y"] = 0, ["param1"] = 4, ["z"] = 12, ["name"] = "default:stone_block"}, {["x"] = 14, ["y"] = 0, ["param1"] = 4, ["z"] = 13, ["name"] = "default:stone_block"}, {["x"] = 14, ["y"] = 0, ["param1"] = 4, ["z"] = 14, ["name"] = "default:stone_block"}, {["x"] = 14, ["y"] = 0, ["param1"] = 4, ["z"] = 15, ["name"] = "default:stone_block"}, {["x"] = 14, ["y"] = 1, ["param1"] = 78, ["z"] = 0, ["name"] = "walls:cobble"}, {["x"] = 14, ["y"] = 1, ["z"] = 2, ["name"] = "default:silver_sandstone"}, {["x"] = 14, ["meta"] = {["fields"] = {["infotext"] = "\27(T@default)Chest\27E"}, ["inventory"] = {["main"] = {"", "", "", "", "", "", "", "", "", "", "", "", "", "", "", "", "", "", "", "", "", "", "", "", "", "", "", "", "", "", "", ""}}}, ["param2"] = 1, ["y"] = 1, ["param1"] = 124, ["z"] = 3, ["name"] = "default:chest"}, {["x"] = 14, ["meta"] = {["fields"] = {["infotext"] = "\27(T@default)Chest\27E"}, ["inventory"] = {["main"] = {"", "", "", "", "", "", "", "", "", "", "", "", "", "", "", "", "", "", "", "", "", "", "", "", "", "", "", "", "", "", "", ""}}}, ["param2"] = 1, ["y"] = 1, ["param1"] = 141, ["z"] = 4, ["name"] = "default:chest"}, {["x"] = 14, ["y"] = 1, ["z"] = 5, ["name"] = "default:silver_sandstone"}, {["x"] = 14, ["meta"] = {["fields"] = {["infotext"] = "\27(T@default)Chest\27E"}, ["inventory"] = {["main"] = {"default:axe_mese", "default:axe_mese", "default:axe_mese", "default:axe_mese", "default:axe_mese", "default:axe_mese", "default:axe_mese", "default:axe_mese", "default:shovel_mese", "default:shovel_mese", "default:shovel_mese", "default:shovel_mese", "default:shovel_mese", "default:shovel_mese", "default:shovel_mese", "default:shovel_mese", "default:pick_mese", "default:pick_mese", "default:pick_mese", "default:pick_mese", "default:pick_mese", "default:pick_mese", "default:pick_mese", "default:pick_mese", "default:sword_mese", "default:sword_mese", "default:sword_mese", "default:sword_mese", "default:sword_mese", "default:sword_mese", "default:sword_mese", "default:sword_mese"}}}, ["param2"] = 1, ["y"] = 1, ["param1"] = 141, ["z"] = 6, ["name"] = "default:chest"}, {["x"] = 14, ["meta"] = {["fields"] = {["infotext"] = "\27(T@default)Chest\27E"}, ["inventory"] = {["main"] = {"default:stone_with_mese 99", "default:stone_with_mese 99", "default:stone_with_mese 99", "default:stone_with_mese 99", "default:stone_with_mese 99", "default:stone_with_mese 99", "default:stone_with_mese 99", "default:stone_with_mese 99", "default:stone_with_mese 99", "default:stone_with_mese 99", "default:stone_with_mese 99", "default:stone_with_mese 99", "default:stone_with_mese 99", "default:stone_with_mese 99", "default:stone_with_mese 99", "default:stone_with_mese 99", "default:stone_with_mese 99", "default:stone_with_mese 99", "default:stone_with_mese 99", "default:stone_with_mese 99", "default:stone_with_mese 99", "default:stone_with_mese 99", "default:stone_with_mese 99", "default:stone_with_mese 99", "default:stone_with_mese 99", "default:stone_with_mese 99", "default:stone_with_mese 99", "default:stone_with_mese 99", "default:stone_with_mese 99", "default:stone_with_mese 99", "default:stone_with_mese 99", "default:stone_with_mese 99"}}}, ["param2"] = 1, ["y"] = 1, ["param1"] = 141, ["z"] = 7, ["name"] = "default:chest"}, {["x"] = 14, ["y"] = 1, ["z"] = 8, ["name"] = "default:silver_sandstone"}, {["x"] = 14, ["meta"] = {["fields"] = {["infotext"] = "\27(T@default)Chest\27E"}, ["inventory"] = {["main"] = {"default:axe_diamond", "default:axe_diamond", "default:axe_diamond", "default:axe_diamond", "default:axe_diamond", "default:axe_diamond", "default:axe_diamond", "default:axe_diamond", "default:shovel_diamond", "default:shovel_diamond", "default:shovel_diamond", "default:shovel_diamond", "default:shovel_diamond", "default:shovel_diamond", "default:shovel_diamond", "default:shovel_diamond", "default:pick_diamond", "default:pick_diamond", "default:pick_diamond", "default:pick_diamond", "default:pick_diamond", "default:pick_diamond", "default:pick_diamond", "default:pick_diamond", "default:sword_diamond", "default:sword_diamond", "default:sword_diamond", "default:sword_diamond", "default:sword_diamond", "default:sword_diamond", "default:sword_diamond", "default:sword_diamond"}}}, ["param2"] = 1, ["y"] = 1, ["param1"] = 139, ["z"] = 9, ["name"] = "default:chest"}, {["x"] = 14, ["meta"] = {["fields"] = {["infotext"] = "\27(T@default)Chest\27E"}, ["inventory"] = {["main"] = {"default:stone_with_diamond 99", "default:stone_with_diamond 99", "default:stone_with_diamond 99", "default:stone_with_diamond 99", "default:stone_with_diamond 99", "default:stone_with_diamond 99", "default:stone_with_diamond 99", "default:stone_with_diamond 99", "default:stone_with_diamond 99", "default:stone_with_diamond 99", "default:stone_with_diamond 99", "default:stone_with_diamond 99", "default:stone_with_diamond 99", "default:stone_with_diamond 99", "default:stone_with_diamond 99", "default:stone_with_diamond 99", "default:stone_with_diamond 99", "default:stone_with_diamond 99", "default:stone_with_diamond 99", "default:stone_with_diamond 99", "default:stone_with_diamond 99", "default:stone_with_diamond 99", "default:stone_with_diamond 99", "default:stone_with_diamond 99", "default:stone_with_diamond 99", "default:stone_with_diamond 99", "default:stone_with_diamond 99", "default:stone_with_diamond 99", "default:stone_with_diamond 99", "default:stone_with_diamond 99", "default:stone_with_diamond 99", "default:stone_with_diamond 99"}}}, ["param2"] = 1, ["y"] = 1, ["param1"] = 138, ["z"] = 10, ["name"] = "default:chest"}, {["x"] = 14, ["y"] = 1, ["z"] = 11, ["name"] = "default:silver_sandstone"}, {["x"] = 14, ["meta"] = {["fields"] = {["infotext"] = "\27(T@default)Chest\27E"}, ["inventory"] = {["main"] = {"default:gold_lump 99", "default:gold_lump 99", "default:gold_lump 99", "default:gold_lump 99", "default:gold_lump 99", "default:gold_lump 99", "default:gold_lump 99", "default:gold_lump 99", "default:gold_lump 99", "default:gold_lump 99", "default:gold_lump 99", "default:gold_lump 99", "default:gold_lump 99", "default:gold_lump 99", "default:gold_lump 99", "default:gold_lump 99", "default:gold_lump 99", "default:gold_lump 99", "default:gold_lump 99", "default:gold_lump 99", "default:gold_lump 99", "default:gold_lump 99", "default:gold_lump 99", "default:gold_lump 99", "default:gold_lump 99", "default:gold_lump 99", "default:gold_lump 99", "default:gold_lump 99", "default:gold_lump 99", "default:gold_lump 99", "default:gold_lump 99", "default:gold_lump 99"}}}, ["param2"] = 1, ["y"] = 1, ["param1"] = 141, ["z"] = 12, ["name"] = "default:chest"}, {["x"] = 14, ["meta"] = {["fields"] = {["infotext"] = "\27(T@default)Chest\27E"}, ["inventory"] = {["main"] = {"default:stone_with_gold 99", "default:stone_with_gold 99", "default:stone_with_gold 99", "default:stone_with_gold 99", "default:stone_with_gold 99", "default:stone_with_gold 99", "default:stone_with_gold 99", "default:stone_with_gold 99", "default:stone_with_gold 99", "default:stone_with_gold 99", "default:stone_with_gold 99", "default:stone_with_gold 99", "default:stone_with_gold 99", "default:stone_with_gold 99", "default:stone_with_gold 99", "default:stone_with_gold 99", "default:stone_with_gold 99", "default:stone_with_gold 99", "default:stone_with_gold 99", "default:stone_with_gold 99", "default:stone_with_gold 99", "default:stone_with_gold 99", "default:stone_with_gold 99", "default:stone_with_gold 99", "default:stone_with_gold 99", "default:stone_with_gold 99", "default:stone_with_gold 99", "default:stone_with_gold 99", "default:stone_with_gold 99", "default:stone_with_gold 99", "default:stone_with_gold 99", "default:stone_with_gold 99"}}}, ["param2"] = 1, ["y"] = 1, ["param1"] = 140, ["z"] = 13, ["name"] = "default:chest"}, {["x"] = 14, ["y"] = 1, ["z"] = 14, ["name"] = "default:silver_sandstone"}, {["x"] = 14, ["y"] = 1, ["param1"] = 142, ["z"] = 15, ["name"] = "walls:cobble"}, {["x"] = 14, ["y"] = 2, ["param1"] = 94, ["z"] = 0, ["name"] = "walls:cobble"}, {["x"] = 14, ["y"] = 2, ["z"] = 2, ["name"] = "default:silver_sandstone"}, {["x"] = 14, ["meta"] = {["fields"] = {["infotext"] = "\27(T@default)Chest\27E"}, ["inventory"] = {["main"] = {"", "", "", "", "", "", "", "", "", "", "", "", "", "", "", "", "", "", "", "", "", "", "", "", "", "", "", "", "", "", "", ""}}}, ["param2"] = 1, ["y"] = 2, ["param1"] = 141, ["z"] = 3, ["name"] = "default:chest"}, {["x"] = 14, ["meta"] = {["fields"] = {["infotext"] = "\27(T@default)Chest\27E"}, ["inventory"] = {["main"] = {"", "", "", "", "", "", "", "", "", "", "", "", "", "", "", "", "", "", "", "", "", "", "", "", "", "", "", "", "", "", "", ""}}}, ["param2"] = 1, ["y"] = 2, ["param1"] = 158, ["z"] = 4, ["name"] = "default:chest"}, {["x"] = 14, ["y"] = 2, ["z"] = 5, ["name"] = "default:silver_sandstone"}, {["x"] = 14, ["meta"] = {["fields"] = {["infotext"] = "\27(T@default)Chest\27E"}, ["inventory"] = {["main"] = {"default:mese_crystal 99", "default:mese_crystal 99", "default:mese_crystal 99", "default:mese_crystal 99", "default:mese_crystal 99", "default:mese_crystal 99", "default:mese_crystal 99", "default:mese_crystal 99", "default:mese_crystal 99", "default:mese_crystal 99", "default:mese_crystal 99", "default:mese_crystal 99", "default:mese_crystal 99", "default:mese_crystal 99", "default:mese_crystal 99", "default:mese_crystal 99", "default:mese_crystal 99", "default:mese_crystal 99", "default:mese_crystal 99", "default:mese_crystal 99", "default:mese_crystal 99", "default:mese_crystal 99", "default:mese_crystal 99", "default:mese_crystal 99", "default:mese_crystal 99", "default:mese_crystal 99", "default:mese_crystal 99", "default:mese_crystal 99", "default:mese_crystal 99", "default:mese_crystal 99", "default:mese_crystal 99", "default:mese_crystal 99"}}}, ["param2"] = 1, ["y"] = 2, ["param1"] = 158, ["z"] = 6, ["name"] = "default:chest"}, {["x"] = 14, ["meta"] = {["fields"] = {["infotext"] = "\27(T@default)Chest\27E"}, ["inventory"] = {["main"] = {"default:mese 99", "default:mese 99", "default:mese 99", "default:mese 99", "default:mese 99", "default:mese 99", "default:mese 99", "default:mese 99", "default:mese 99", "default:mese 99", "default:mese 99", "default:mese 99", "default:mese 99", "default:mese 99", "default:mese 99", "default:mese 99", "default:mese 99", "default:mese 99", "default:mese 99", "default:mese 99", "default:mese 99", "default:mese 99", "default:mese 99", "default:mese 99", "default:mese 99", "default:mese 99", "default:mese 99", "default:mese 99", "default:mese 99", "default:mese 99", "default:mese 99", "default:mese 99"}}}, ["param2"] = 1, ["y"] = 2, ["param1"] = 158, ["z"] = 7, ["name"] = "default:chest"}, {["x"] = 14, ["y"] = 2, ["z"] = 8, ["name"] = "default:silver_sandstone"}, {["x"] = 14, ["meta"] = {["fields"] = {["infotext"] = "\27(T@default)Chest\27E"}, ["inventory"] = {["main"] = {"default:diamond 99", "default:diamond 99", "default:diamond 99", "default:diamond 99", "default:diamond 99", "default:diamond 99", "default:diamond 99", "default:diamond 99", "default:diamond 99", "default:diamond 99", "default:diamond 99", "default:diamond 99", "default:diamond 99", "default:diamond 99", "default:diamond 99", "default:diamond 99", "default:diamond 99", "default:diamond 99", "default:diamond 99", "default:diamond 99", "default:diamond 99", "default:diamond 99", "default:diamond 99", "default:diamond 99", "default:diamond 99", "default:diamond 99", "default:diamond 99", "default:diamond 99", "default:diamond 99", "default:diamond 99", "default:diamond 99", "default:diamond 99"}}}, ["param2"] = 1, ["y"] = 2, ["param1"] = 155, ["z"] = 9, ["name"] = "default:chest"}, {["x"] = 14, ["meta"] = {["fields"] = {["infotext"] = "\27(T@default)Chest\27E"}, ["inventory"] = {["main"] = {"default:diamondblock 99", "default:diamondblock 99", "default:diamondblock 99", "default:diamondblock 99", "default:diamondblock 99", "default:diamondblock 99", "default:diamondblock 99", "default:diamondblock 99", "default:diamondblock 99", "default:diamondblock 99", "default:diamondblock 99", "default:diamondblock 99", "default:diamondblock 99", "default:diamondblock 99", "default:diamondblock 99", "default:diamondblock 99", "default:diamondblock 99", "default:diamondblock 99", "default:diamondblock 99", "default:diamondblock 99", "default:diamondblock 99", "default:diamondblock 99", "default:diamondblock 99", "default:diamondblock 99", "default:diamondblock 99", "default:diamondblock 99", "default:diamondblock 99", "default:diamondblock 99", "default:diamondblock 99", "default:diamondblock 99", "default:diamondblock 99", "default:diamondblock 99"}}}, ["param2"] = 1, ["y"] = 2, ["param1"] = 155, ["z"] = 10, ["name"] = "default:chest"}, {["x"] = 14, ["y"] = 2, ["z"] = 11, ["name"] = "default:silver_sandstone"}, {["x"] = 14, ["meta"] = {["fields"] = {["infotext"] = "\27(T@default)Chest\27E"}, ["inventory"] = {["main"] = {"default:gold_ingot 99", "default:gold_ingot 99", "default:gold_ingot 99", "default:gold_ingot 99", "default:gold_ingot 99", "default:gold_ingot 99", "default:gold_ingot 99", "default:gold_ingot 99", "default:gold_ingot 99", "default:gold_ingot 99", "default:gold_ingot 99", "default:gold_ingot 99", "default:gold_ingot 99", "default:gold_ingot 99", "default:gold_ingot 99", "default:gold_ingot 99", "default:gold_ingot 99", "default:gold_ingot 99", "default:gold_ingot 99", "default:gold_ingot 99", "default:gold_ingot 99", "default:gold_ingot 99", "default:gold_ingot 99", "default:gold_ingot 99", "default:gold_ingot 99", "default:gold_ingot 99", "default:gold_ingot 99", "default:gold_ingot 99", "default:gold_ingot 99", "default:gold_ingot 99", "default:gold_ingot 99", "default:gold_ingot 99"}}}, ["param2"] = 1, ["y"] = 2, ["param1"] = 158, ["z"] = 12, ["name"] = "default:chest"}, {["x"] = 14, ["meta"] = {["fields"] = {["infotext"] = "\27(T@default)Chest\27E"},