5:return {{["x"] = 0, ["y"] = 0, ["z"] = 0, ["name"] = "default:dirt"}, {["x"] = 0, ["y"] = 0, ["z"] = 1, ["name"] = "default:dirt"}, {["x"] = 0, ["y"] = 0, ["z"] = 2, ["name"] = "default:dirt"}, {["x"] = 0, ["y"] = 0, ["z"] = 3, ["name"] = "default:dirt"}, {["x"] = 0, ["y"] = 0, ["z"] = 4, ["name"] = "default:dirt"}, {["x"] = 0, ["y"] = 0, ["z"] = 5, ["name"] = "default:dirt"}, {["x"] = 0, ["y"] = 0, ["z"] = 6, ["name"] = "default:dirt"}, {["x"] = 0, ["y"] = 0, ["z"] = 7, ["name"] = "default:dirt"}, {["x"] = 0, ["y"] = 0, ["z"] = 8, ["name"] = "default:dirt"}, {["x"] = 0, ["y"] = 0, ["z"] = 9, ["name"] = "default:dirt"}, {["x"] = 0, ["y"] = 0, ["z"] = 10, ["name"] = "default:dirt"}, {["x"] = 0, ["y"] = 0, ["z"] = 11, ["name"] = "default:dirt"}, {["x"] = 0, ["y"] = 0, ["z"] = 12, ["name"] = "default:dirt"}, {["x"] = 0, ["y"] = 0, ["z"] = 13, ["name"] = "default:dirt"}, {["x"] = 0, ["y"] = 0, ["z"] = 14, ["name"] = "default:dirt"}, {["x"] = 0, ["y"] = 0, ["z"] = 15, ["name"] = "default:dirt"}, {["x"] = 0, ["y"] = 0, ["z"] = 16, ["name"] = "default:dirt_with_coniferous_litter"}, {["x"] = 0, ["y"] = 0, ["z"] = 17, ["name"] = "default:dirt_with_coniferous_litter"}, {["x"] = 0, ["y"] = 0, ["z"] = 18, ["name"] = "default:dirt_with_coniferous_litter"}, {["x"] = 0, ["y"] = 1, ["z"] = 0, ["name"] = "default:stonebrick"}, {["x"] = 0, ["y"] = 1, ["z"] = 1, ["name"] = "default:stone"}, {["x"] = 0, ["y"] = 1, ["z"] = 2, ["name"] = "default:stone"}, {["x"] = 0, ["y"] = 1, ["z"] = 3, ["name"] = "default:stonebrick"}, {["x"] = 0, ["y"] = 1, ["z"] = 4, ["name"] = "default:stone"}, {["x"] = 0, ["y"] = 1, ["z"] = 5, ["name"] = "default:stone"}, {["x"] = 0, ["y"] = 1, ["z"] = 6, ["name"] = "default:stonebrick"}, {["x"] = 0, ["y"] = 1, ["z"] = 7, ["name"] = "default:stone"}, {["x"] = 0, ["y"] = 1, ["z"] = 8, ["name"] = "default:stone"}, {["x"] = 0, ["y"] = 1, ["z"] = 9, ["name"] = "default:stonebrick"}, {["x"] = 0, ["y"] = 1, ["z"] = 10, ["name"] = "default:stone"}, {["x"] = 0, ["y"] = 1, ["z"] = 11, ["name"] = "default:stone"}, {["x"] = 0, ["y"] = 1, ["z"] = 12, ["name"] = "default:stonebrick"}, {["x"] = 0, ["y"] = 1, ["z"] = 13, ["name"] = "default:stone"}, {["x"] = 0, ["y"] = 1, ["z"] = 14, ["name"] = "default:stone"}, {["x"] = 0, ["y"] = 1, ["z"] = 15, ["name"] = "default:stonebrick"}, {["x"] = 0, ["y"] = 2, ["z"] = 0, ["name"] = "default:stone"}, {["x"] = 0, ["param2"] = 3, ["y"] = 2, ["param1"] = 15, ["z"] = 1, ["name"] = "xpanes:bar_flat"}, {["x"] = 0, ["param2"] = 3, ["y"] = 2, ["param1"] = 15, ["z"] = 2, ["name"] = "xpanes:bar_flat"}, {["x"] = 0, ["y"] = 2, ["z"] = 3, ["name"] = "default:stone"}, {["x"] = 0, ["param2"] = 3, ["y"] = 2, ["param1"] = 15, ["z"] = 4, ["name"] = "xpanes:bar_flat"}, {["x"] = 0, ["param2"] = 3, ["y"] = 2, ["param1"] = 15, ["z"] = 5, ["name"] = "xpanes:bar_flat"}, {["x"] = 0, ["y"] = 2, ["z"] = 6, ["name"] = "default:stone"}, {["x"] = 0, ["param2"] = 3, ["y"] = 2, ["param1"] = 15, ["z"] = 7, ["name"] = "xpanes:bar_flat"}, {["x"] = 0, ["param2"] = 3, ["y"] = 2, ["param1"] = 15, ["z"] = 8, ["name"] = "xpanes:bar_flat"}, {["x"] = 0, ["y"] = 2, ["z"] = 9, ["name"] = "default:stone"}, {["x"] = 0, ["param2"] = 3, ["y"] = 2, ["param1"] = 15, ["z"] = 10, ["name"] = "xpanes:bar_flat"}, {["x"] = 0, ["param2"] = 3, ["y"] = 2, ["param1"] = 15, ["z"] = 11, ["name"] = "xpanes:bar_flat"}, {["x"] = 0, ["y"] = 2, ["z"] = 12, ["name"] = "default:stone"}, {["x"] = 0, ["param2"] = 3, ["y"] = 2, ["param1"] = 15, ["z"] = 13, ["name"] = "xpanes:bar_flat"}, {["x"] = 0, ["param2"] = 3, ["y"] = 2, ["param1"] = 15, ["z"] = 14, ["name"] = "xpanes:bar_flat"}, {["x"] = 0, ["y"] = 2, ["z"] = 15, ["name"] = "default:stone"}, {["x"] = 0, ["y"] = 3, ["z"] = 0, ["name"] = "default:stone"}, {["x"] = 0, ["param2"] = 3, ["y"] = 3, ["param1"] = 15, ["z"] = 1, ["name"] = "xpanes:bar_flat"}, {["x"] = 0, ["param2"] = 3, ["y"] = 3, ["param1"] = 15, ["z"] = 2, ["name"] = "xpanes:bar_flat"}, {["x"] = 0, ["y"] = 3, ["z"] = 3, ["name"] = "default:stone"}, {["x"] = 0, ["param2"] = 3, ["y"] = 3, ["param1"] = 15, ["z"] = 4, ["name"] = "xpanes:bar_flat"}, {["x"] = 0, ["param2"] = 3, ["y"] = 3, ["param1"] = 15, ["z"] = 5, ["name"] = "xpanes:bar_flat"}, {["x"] = 0, ["y"] = 3, ["z"] = 6, ["name"] = "default:stone"}, {["x"] = 0, ["param2"] = 3, ["y"] = 3, ["param1"] = 15, ["z"] = 7, ["name"] = "xpanes:bar_flat"}, {["x"] = 0, ["param2"] = 3, ["y"] = 3, ["param1"] = 15, ["z"] = 8, ["name"] = "xpanes:bar_flat"}, {["x"] = 0, ["y"] = 3, ["z"] = 9, ["name"] = "default:stone"}, {["x"] = 0, ["param2"] = 3, ["y"] = 3, ["param1"] = 15, ["z"] = 10, ["name"] = "xpanes:bar_flat"}, {["x"] = 0, ["param2"] = 3, ["y"] = 3, ["param1"] = 15, ["z"] = 11, ["name"] = "xpanes:bar_flat"}, {["x"] = 0, ["y"] = 3, ["z"] = 12, ["name"] = "default:stone"}, {["x"] = 0, ["param2"] = 3, ["y"] = 3, ["param1"] = 15, ["z"] = 13, ["name"] = "xpanes:bar_flat"}, {["x"] = 0, ["param2"] = 3, ["y"] = 3, ["param1"] = 15, ["z"] = 14, ["name"] = "xpanes:bar_flat"}, {["x"] = 0, ["y"] = 3, ["z"] = 15, ["name"] = "default:stone"}, {["x"] = 0, ["y"] = 4, ["param1"] = 14, ["z"] = 0, ["name"] = "walls:cobble"}, {["x"] = 0, ["y"] = 4, ["param1"] = 14, ["z"] = 3, ["name"] = "walls:cobble"}, {["x"] = 0, ["y"] = 4, ["param1"] = 14, ["z"] = 6, ["name"] = "walls:cobble"}, {["x"] = 0, ["y"] = 4, ["param1"] = 14, ["z"] = 9, ["name"] = "walls:cobble"}, {["x"] = 0, ["y"] = 4, ["param1"] = 14, ["z"] = 12, ["name"] = "walls:cobble"}, {["x"] = 0, ["y"] = 4, ["param1"] = 14, ["z"] = 15, ["name"] = "walls:cobble"}, {["x"] = 0, ["param2"] = 1, ["y"] = 5, ["param1"] = 15, ["z"] = 0, ["name"] = "xpanes:bar_flat"}, {["x"] = 0, ["param2"] = 1, ["y"] = 5, ["param1"] = 15, ["z"] = 3, ["name"] = "xpanes:bar_flat"}, {["x"] = 0, ["param2"] = 1, ["y"] = 5, ["param1"] = 15, ["z"] = 6, ["name"] = "xpanes:bar_flat"}, {["x"] = 0, ["param2"] = 1, ["y"] = 5, ["param1"] = 15, ["z"] = 9, ["name"] = "xpanes:bar_flat"}, {["x"] = 0, ["param2"] = 1, ["y"] = 5, ["param1"] = 15, ["z"] = 12, ["name"] = "xpanes:bar_flat"}, {["x"] = 0, ["param2"] = 2, ["y"] = 5, ["param1"] = 15, ["z"] = 15, ["name"] = "xpanes:bar_flat"}, {["x"] = 1, ["y"] = 0, ["z"] = 0, ["name"] = "default:dirt"}, {["x"] = 1, ["y"] = 0, ["z"] = 1, ["name"] = "default:dirt_with_coniferous_litter"}, {["x"] = 1, ["y"] = 0, ["z"] = 2, ["name"] = "default:dirt_with_coniferous_litter"}, {["x"] = 1, ["y"] = 0, ["z"] = 3, ["name"] = "default:dirt_with_coniferous_litter"}, {["x"] = 1, ["y"] = 0, ["z"] = 4, ["name"] = "default:dirt_with_coniferous_litter"}, {["x"] = 1, ["y"] = 0, ["z"] = 5, ["name"] = "default:dirt_with_coniferous_litter"}, {["x"] = 1, ["y"] = 0, ["z"] = 6, ["name"] = "default:dirt_with_coniferous_litter"}, {["x"] = 1, ["y"] = 0, ["z"] = 7, ["name"] = "default:dirt_with_coniferous_litter"}, {["x"] = 1, ["y"] = 0, ["z"] = 8, ["name"] = "default:dirt_with_coniferous_litter"}, {["x"] = 1, ["y"] = 0, ["z"] = 9, ["name"] = "default:dirt_with_coniferous_litter"}, {["x"] = 1, ["y"] = 0, ["z"] = 10, ["name"] = "default:dirt_with_coniferous_litter"}, {["x"] = 1, ["y"] = 0, ["z"] = 11, ["name"] = "default:dirt_with_coniferous_litter"}, {["x"] = 1, ["y"] = 0, ["z"] = 12, ["name"] = "default:dirt_with_coniferous_litter"}, {["x"] = 1, ["y"] = 0, ["z"] = 13, ["name"] = "default:dirt_with_coniferous_litter"}, {["x"] = 1, ["y"] = 0, ["z"] = 14, ["name"] = "default:dirt_with_coniferous_litter"}, {["x"] = 1, ["y"] = 0, ["z"] = 15, ["name"] = "default:dirt"}, {["x"] = 1, ["y"] = 0, ["z"] = 16, ["name"] = "default:dirt_with_coniferous_litter"}, {["x"] = 1, ["y"] = 0, ["z"] = 17, ["name"] = "default:dirt_with_coniferous_litter"}, {["x"] = 1, ["y"] = 0, ["z"] = 18, ["name"] = "default:dirt_with_coniferous_litter"}, {["x"] = 1, ["y"] = 1, ["z"] = 0, ["name"] = "default:stone"}, {["x"] = 1, ["y"] = 1, ["param1"] = 15, ["z"] = 8, ["name"] = "flowers:mushroom_brown"}, {["x"] = 1, ["y"] = 1, ["z"] = 15, ["name"] = "default:stone"}, {["x"] = 1, ["y"] = 2, ["param1"] = 15, ["z"] = 0, ["name"] = "xpanes:bar_flat"}, {["x"] = 1, ["y"] = 2, ["param1"] = 15, ["z"] = 15, ["name"] = "xpanes:bar_flat"}, {["x"] = 1, ["y"] = 3, ["param1"] = 15, ["z"] = 0, ["name"] = "xpanes:bar_flat"}, {["x"] = 1, ["y"] = 3, ["param1"] = 15, ["z"] = 15, ["name"] = "xpanes:bar_flat"}, {["x"] = 2, ["y"] = 0, ["z"] = 0, ["name"] = "default:dirt"}, {["x"] = 2, ["y"] = 0, ["z"] = 1, ["name"] = "default:dirt_with_coniferous_litter"}, {["x"] = 2, ["y"] = 0, ["z"] = 2, ["name"] = "default:dirt_with_coniferous_litter"}, {["x"] = 2, ["y"] = 0, ["z"] = 3, ["name"] = "default:dirt"}, {["x"] = 2, ["y"] = 0, ["z"] = 4, ["name"] = "default:dirt_with_rainforest_litter"}, {["x"] = 2, ["y"] = 0, ["z"] = 5, ["name"] = "default:dirt_with_rainforest_litter"}, {["x"] = 2, ["y"] = 0, ["z"] = 6, ["name"] = "default:dirt_with_coniferous_litter"}, {["x"] = 2, ["y"] = 0, ["z"] = 7, ["name"] = "default:dirt"}, {["x"] = 2, ["y"] = 0, ["z"] = 8, ["name"] = "default:dirt_with_rainforest_litter"}, {["x"] = 2, ["y"] = 0, ["z"] = 9, ["name"] = "default:dirt_with_rainforest_litter"}, {["x"] = 2, ["y"] = 0, ["z"] = 10, ["name"] = "default:dirt_with_coniferous_litter"}, {["x"] = 2, ["y"] = 0, ["z"] = 11, ["name"] = "default:dirt"}, {["x"] = 2, ["y"] = 0, ["z"] = 12, ["name"] = "default:dirt_with_rainforest_litter"}, {["x"] = 2, ["y"] = 0, ["z"] = 13, ["name"] = "default:dirt_with_rainforest_litter"}, {["x"] = 2, ["y"] = 0, ["z"] = 14, ["name"] = "default:dirt_with_coniferous_litter"}, {["x"] = 2, ["y"] = 0, ["z"] = 15, ["name"] = "default:dirt"}, {["x"] = 2, ["y"] = 0, ["z"] = 16, ["name"] = "default:dirt_with_coniferous_litter"}, {["x"] = 2, ["y"] = 0, ["z"] = 17, ["name"] = "default:dirt_with_coniferous_litter"}, {["x"] = 2, ["y"] = 0, ["z"] = 18, ["name"] = "default:dirt_with_coniferous_litter"}, {["x"] = 2, ["y"] = 1, ["z"] = 0, ["name"] = "default:stone"}, {["x"] = 2, ["param2"] = 8, ["y"] = 1, ["param1"] = 14, ["z"] = 3, ["name"] = "stairs:slab_cobble"}, {["x"] = 2, ["y"] = 1, ["param1"] = 15, ["z"] = 4, ["name"] = "flowers:viola"}, {["x"] = 2, ["param2"] = 8, ["y"] = 1, ["param1"] = 14, ["z"] = 7, ["name"] = "stairs:slab_cobble"}, {["x"] = 2, ["param2"] = 8, ["y"] = 1, ["param1"] = 14, ["z"] = 11, ["name"] = "stairs:slab_cobble"}, {["x"] = 2, ["y"] = 1, ["z"] = 15, ["name"] = "default:stone"}, {["x"] = 2, ["y"] = 2, ["param1"] = 15, ["z"] = 0, ["name"] = "xpanes:bar_flat"}, {["x"] = 2, ["y"] = 2, ["param1"] = 15, ["z"] = 15, ["name"] = "xpanes:bar_flat"}, {["x"] = 2, ["y"] = 3, ["param1"] = 15, ["z"] = 0, ["name"] = "xpanes:bar_flat"}, {["x"] = 2, ["y"] = 3, ["param1"] = 15, ["z"] = 15, ["name"] = "xpanes:bar_flat"}, {["x"] = 3, ["y"] = 0, ["z"] = 0, ["name"] = "default:dirt"}, {["x"] = 3, ["y"] = 0, ["z"] = 1, ["name"] = "default:dirt_with_coniferous_litter"}, {["x"] = 3, ["y"] = 0, ["z"] = 2, ["name"] = "default:dirt_with_coniferous_litter"}, {["x"] = 3, ["y"] = 0, ["z"] = 3, ["name"] = "default:dirt_with_coniferous_litter"}, {["x"] = 3, ["y"] = 0, ["z"] = 4, ["name"] = "default:dirt_with_coniferous_litter"}, {["x"] = 3, ["y"] = 0, ["z"] = 5, ["name"] = "default:dirt_with_coniferous_litter"}, {["x"] = 3, ["y"] = 0, ["z"] = 6, ["name"] = "default:dirt_with_coniferous_litter"}, {["x"] = 3, ["y"] = 0, ["z"] = 7, ["name"] = "default:dirt_with_coniferous_litter"}, {["x"] = 3, ["y"] = 0, ["z"] = 8, ["name"] = "default:dirt_with_coniferous_litter"}, {["x"] = 3, ["y"] = 0, ["z"] = 9, ["name"] = "default:dirt_with_coniferous_litter"}, {["x"] = 3, ["y"] = 0, ["z"] = 10, ["name"] = "default:dirt_with_coniferous_litter"}, {["x"] = 3, ["y"] = 0, ["z"] = 11, ["name"] = "default:dirt_with_coniferous_litter"}, {["x"] = 3, ["y"] = 0, ["z"] = 12, ["name"] = "default:dirt_with_coniferous_litter"}, {["x"] = 3, ["y"] = 0, ["z"] = 13, ["name"] = "default:dirt_with_coniferous_litter"}, {["x"] = 3, ["y"] = 0, ["z"] = 14, ["name"] = "default:dirt_with_coniferous_litter"}, {["x"] = 3, ["y"] = 0, ["z"] = 15, ["name"] = "default:dirt"}, {["x"] = 3, ["y"] = 0, ["z"] = 16, ["name"] = "default:dirt_with_coniferous_litter"}, {["x"] = 3, ["y"] = 0, ["z"] = 17, ["name"] = "default:dirt_with_coniferous_litter"}, {["x"] = 3, ["y"] = 0, ["z"] = 18, ["name"] = "default:dirt_with_coniferous_litter"}, {["x"] = 3, ["y"] = 1, ["z"] = 0, ["name"] = "default:stonebrick"}, {["x"] = 3, ["y"] = 1, ["z"] = 15, ["name"] = "default:stonebrick"}, {["x"] = 3, ["y"] = 2, ["z"] = 0, ["name"] = "default:stone"}, {["x"] = 3, ["y"] = 2, ["z"] = 15, ["name"] = "default:stone"}, {["x"] = 3, ["y"] = 3, ["z"] = 0, ["name"] = "default:stone"}, {["x"] = 3, ["y"] = 3, ["z"] = 15, ["name"] = "default:stone"}, {["x"] = 3, ["y"] = 4, ["param1"] = 14, ["z"] = 0, ["name"] = "walls:cobble"}, {["x"] = 3, ["y"] = 4, ["param1"] = 14, ["z"] = 15, ["name"] = "walls:cobble"}, {["x"] = 3, ["y"] = 5, ["param1"] = 15, ["z"] = 0, ["name"] = "xpanes:bar_flat"}, {["x"] = 3, ["param2"] = 2, ["y"] = 5, ["param1"] = 15, ["z"] = 15, ["name"] = "xpanes:bar_flat"}, {["x"] = 4, ["y"] = 0, ["z"] = 0, ["name"] = "default:dirt"}, {["x"] = 4, ["y"] = 0, ["z"] = 1, ["name"] = "default:dirt_with_coniferous_litter"}, {["x"] = 4, ["y"] = 0, ["z"] = 2, ["name"] = "default:dirt_with_coniferous_litter"}, {["x"] = 4, ["y"] = 0, ["z"] = 3, ["name"] = "default:dirt"}, {["x"] = 4, ["y"] = 0, ["z"] = 4, ["name"] = "default:dirt_with_rainforest_litter"}, {["x"] = 4, ["y"] = 0, ["z"] = 5, ["name"] = "default:dirt_with_rainforest_litter"}, {["x"] = 4, ["y"] = 0, ["z"] = 6, ["name"] = "default:dirt_with_coniferous_litter"}, {["x"] = 4, ["y"] = 0, ["z"] = 7, ["name"] = "default:dirt_with_coniferous_litter"}, {["x"] = 4, ["y"] = 0, ["z"] = 8, ["name"] = "default:dirt_with_rainforest_litter"}, {["x"] = 4, ["y"] = 0, ["z"] = 9, ["name"] = "default:dirt_with_rainforest_litter"}, {["x"] = 4, ["y"] = 0, ["z"] = 10, ["name"] = "default:dirt"}, {["x"] = 4, ["y"] = 0, ["z"] = 11, ["name"] = "default:dirt"}, {["x"] = 4, ["y"] = 0, ["z"] = 12, ["name"] = "default:dirt_with_rainforest_litter"}, {["x"] = 4, ["y"] = 0, ["z"] = 13, ["name"] = "default:dirt_with_rainforest_litter"}, {["x"] = 4, ["y"] = 0, ["z"] = 14, ["name"] = "default:dirt_with_coniferous_litter"}, {["x"] = 4, ["y"] = 0, ["z"] = 15, ["name"] = "default:dirt"}, {["x"] = 4, ["y"] = 0, ["z"] = 16, ["name"] = "default:dirt_with_coniferous_litter"}, {["x"] = 4, ["y"] = 0, ["z"] = 17, ["name"] = "default:dirt_with_coniferous_litter"}, {["x"] = 4, ["y"] = 0, ["z"] = 18, ["name"] = "default:dirt_with_coniferous_litter"}, {["x"] = 4, ["y"] = 1, ["z"] = 0, ["name"] = "default:stone"}, {["x"] = 4, ["param2"] = 8, ["y"] = 1, ["param1"] = 14, ["z"] = 3, ["name"] = "stairs:slab_cobble"}, {["x"] = 4, ["param2"] = 8, ["y"] = 1, ["param1"] = 14, ["z"] = 7, ["name"] = "stairs:slab_cobble"}, {["x"] = 4, ["param2"] = 8, ["y"] = 1, ["param1"] = 14, ["z"] = 11, ["name"] = "stairs:slab_cobble"}, {["x"] = 4, ["y"] = 1, ["param1"] = 15, ["z"] = 12, ["name"] = "flowers:tulip_black"}, {["x"] = 4, ["y"] = 1, ["param1"] = 15, ["z"] = 14, ["name"] = "flowers:mushroom_brown"}, {["x"] = 4, ["y"] = 1, ["z"] = 15, ["name"] = "default:stone"}, {["x"] = 4, ["y"] = 2, ["param1"] = 15, ["z"] = 0, ["name"] = "xpanes:bar_flat"}, {["x"] = 4, ["y"] = 2, ["param1"] = 15, ["z"] = 15, ["name"] = "xpanes:bar_flat"}, {["x"] = 4, ["y"] = 3, ["param1"] = 15, ["z"] = 0, ["name"] = "xpanes:bar_flat"}, {["x"] = 4, ["y"] = 3, ["param1"] = 15, ["z"] = 15, ["name"] = "xpanes:bar_flat"}, {["x"] = 5, ["y"] = 0, ["z"] = 0, ["name"] = "default:dirt"}, {["x"] = 5, ["y"] = 0, ["z"] = 1, ["name"] = "default:dirt_with_coniferous_litter"}, {["x"] = 5, ["y"] = 0, ["z"] = 2, ["name"] = "default:dirt_with_coniferous_litter"}, {["x"] = 5, ["y"] = 0, ["z"] = 3, ["name"] = "default:dirt_with_coniferous_litter"}, {["x"] = 5, ["y"] = 0, ["z"] = 4, ["name"] = "default:dirt_with_coniferous_litter"}, {["x"] = 5, ["y"] = 0, ["z"] = 5, ["name"] = "default:dirt_with_coniferous_litter"}, {["x"] = 5, ["y"] = 0, ["z"] = 6, ["name"] = "default:dirt_with_coniferous_litter"}, {["x"] = 5, ["y"] = 0, ["z"] = 7, ["name"] = "default:dirt_with_coniferous_litter"}, {["x"] = 5, ["y"] = 0, ["z"] = 8, ["name"] = "default:dirt_with_coniferous_litter"}, {["x"] = 5, ["y"] = 0, ["z"] = 9, ["name"] = "default:dirt_with_coniferous_litter"}, {["x"] = 5, ["y"] = 0, ["z"] = 10, ["name"] = "default:dirt_with_coniferous_litter"}, {["x"] = 5, ["y"] = 0, ["z"] = 11, ["name"] = "default:dirt_with_coniferous_litter"}, {["x"] = 5, ["y"] = 0, ["z"] = 12, ["name"] = "default:dirt_with_coniferous_litter"}, {["x"] = 5, ["y"] = 0, ["z"] = 13, ["name"] = "default:dirt_with_coniferous_litter"}, {["x"] = 5, ["y"] = 0, ["z"] = 14, ["name"] = "default:dirt_with_coniferous_litter"}, {["x"] = 5, ["y"] = 0, ["z"] = 15, ["name"] = "default:dirt"}, {["x"] = 5, ["y"] = 0, ["z"] = 16, ["name"] = "default:dirt_with_coniferous_litter"}, {["x"] = 5, ["y"] = 0, ["z"] = 17, ["name"] = "default:dirt_with_coniferous_litter"}, {["x"] = 5, ["y"] = 0, ["z"] = 18, ["name"] = "default:dirt_with_coniferous_litter"}, {["x"] = 5, ["y"] = 1, ["z"] = 0, ["name"] = "default:stone"}, {["x"] = 5, ["y"] = 1, ["param1"] = 15, ["z"] = 9, ["name"] = "flowers:mushroom_brown"}, {["x"] = 5, ["y"] = 1, ["param1"] = 15, ["z"] = 10, ["name"] = "flowers:mushroom_brown"}, {["x"] = 5, ["y"] = 1, ["z"] = 15, ["name"] = "default:stone"}, {["x"] = 5, ["y"] = 2, ["param1"] = 15, ["z"] = 0, ["name"] = "xpanes:bar_flat"}, {["x"] = 5, ["y"] = 2, ["param1"] = 15, ["z"] = 15, ["name"] = "xpanes:bar_flat"}, {["x"] = 5, ["y"] = 3, ["param1"] = 15, ["z"] = 0, ["name"] = "xpanes:bar_flat"}, {["x"] = 5, ["y"] = 3, ["param1"] = 15, ["z"] = 15, ["name"] = "xpanes:bar_flat"}, {["x"] = 5, ["y"] = 7, ["z"] = 2, ["name"] = "default:stonebrick"}, {["x"] = 5, ["y"] = 7, ["z"] = 3, ["name"] = "default:stonebrick"}, {["x"] = 5, ["y"] = 7, ["z"] = 4, ["name"] = "default:stonebrick"}, {["x"] = 5, ["y"] = 7, ["z"] = 5, ["name"] = "default:stonebrick"}, {["x"] = 5, ["y"] = 8, ["z"] = 2, ["name"] = "default:stonebrick"}, {["x"] = 5, ["y"] = 8, ["z"] = 3, ["name"] = "default:stonebrick"}, {["x"] = 5, ["y"] = 8, ["z"] = 4, ["name"] = "default:stonebrick"}, {["x"] = 5, ["y"] = 8, ["z"] = 5, ["name"] = "default:stonebrick"}, {["x"] = 5, ["y"] = 9, ["z"] = 2, ["name"] = "default:stonebrick"}, {["x"] = 5, ["y"] = 9, ["z"] = 4, ["name"] = "default:stonebrick"}, {["x"] = 6, ["y"] = 0, ["z"] = 0, ["name"] = "default:dirt"}, {["x"] = 6, ["y"] = 0, ["z"] = 1, ["name"] = "default:dirt_with_coniferous_litter"}, {["x"] = 6, ["y"] = 0, ["z"] = 2, ["name"] = "default:wood"}, {["x"] = 6, ["y"] = 0, ["z"] = 3, ["name"] = "default:wood"}, {["x"] = 6, ["y"] = 0, ["z"] = 4, ["name"] = "default:wood"}, {["x"] = 6, ["y"] = 0, ["z"] = 5, ["name"] = "default:wood"}, {["x"] = 6, ["y"] = 0, ["z"] = 6, ["name"] = "default:dirt_with_coniferous_litter"}, {["x"] = 6, ["y"] = 0, ["z"] = 7, ["name"] = "default:dirt_with_coniferous_litter"}, {["x"] = 6, ["y"] = 0, ["z"] = 8, ["name"] = "default:dirt_with_coniferous_litter"}, {["x"] = 6, ["y"] = 0, ["z"] = 9, ["name"] = "default:dirt_with_coniferous_litter"}, {["x"] = 6, ["y"] = 0, ["z"] = 10, ["name"] = "default:dirt_with_coniferous_litter"}, {["x"] = 6, ["y"] = 0, ["z"] = 11, ["name"] = "default:dirt_with_coniferous_litter"}, {["x"] = 6, ["y"] = 0, ["z"] = 12, ["name"] = "default:dirt_with_coniferous_litter"}, {["x"] = 6, ["y"] = 0, ["z"] = 13, ["name"] = "default:dirt_with_coniferous_litter"}, {["x"] = 6, ["y"] = 0, ["z"] = 14, ["name"] = "default:dirt_with_coniferous_litter"}, {["x"] = 6, ["y"] = 0, ["z"] = 15, ["name"] = "default:dirt"}, {["x"] = 6, ["y"] = 0, ["z"] = 16, ["name"] = "default:dirt_with_coniferous_litter"}, {["x"] = 6, ["y"] = 0, ["z"] = 17, ["name"] = "default:dirt_with_coniferous_litter"}, {["x"] = 6, ["y"] = 0, ["z"] = 18, ["name"] = "default:dirt_with_coniferous_litter"}, {["x"] = 6, ["y"] = 1, ["z"] = 0, ["name"] = "default:stonebrick"}, {["x"] = 6, ["y"] = 1, ["z"] = 2, ["name"] = "default:stonebrick"}, {["x"] = 6, ["y"] = 1, ["z"] = 3, ["name"] = "default:stonebrick"}, {["x"] = 6, ["y"] = 1, ["z"] = 4, ["name"] = "default:stonebrick"}, {["x"] = 6, ["y"] = 1, ["z"] = 5, ["name"] = "default:stonebrick"}, {["x"] = 6, ["y"] = 1, ["param1"] = 15, ["z"] = 9, ["name"] = "flowers:mushroom_brown"}, {["x"] = 6, ["y"] = 1, ["param1"] = 15, ["z"] = 11, ["name"] = "flowers:mushroom_brown"}, {["x"] = 6, ["y"] = 1, ["z"] = 15, ["name"] = "default:stonebrick"}, {["x"] = 6, ["param2"] = 3, ["y"] = 1, ["param1"] = 15, ["z"] = 16, ["name"] = "xpanes:bar_flat"}, {["x"] = 6, ["param2"] = 3, ["y"] = 1, ["param1"] = 15, ["z"] = 17, ["name"] = "xpanes:bar_flat"}, {["x"] = 6, ["param2"] = 3, ["y"] = 1, ["param1"] = 15, ["z"] = 18, ["name"] = "xpanes:bar_flat"}, {["x"] = 6, ["y"] = 2, ["z"] = 0, ["name"] = "default:stone"}, {["x"] = 6, ["y"] = 2, ["z"] = 2, ["name"] = "default:stonebrick"}, {["x"] = 6, ["y"] = 2, ["z"] = 3, ["name"] = "default:stonebrick"}, {["x"] = 6, ["y"] = 2, ["z"] = 4, ["name"] = "default:stonebrick"}, {["x"] = 6, ["y"] = 2, ["z"] = 5, ["name"] = "default:stonebrick"}, {["x"] = 6, ["y"] = 2, ["z"] = 15, ["name"] = "default:stone"}, {["x"] = 6, ["param2"] = 3, ["y"] = 2, ["param1"] = 15, ["z"] = 16, ["name"] = "xpanes:bar_flat"}, {["x"] = 6, ["param2"] = 3, ["y"] = 2, ["param1"] = 15, ["z"] = 17, ["name"] = "xpanes:bar_flat"}, {["x"] = 6, ["param2"] = 3, ["y"] = 2, ["param1"] = 15, ["z"] = 18, ["name"] = "xpanes:bar_flat"}, {["x"] = 6, ["y"] = 3, ["z"] = 0, ["name"] = "default:stone"}, {["x"] = 6, ["y"] = 3, ["z"] = 2, ["name"] = "default:stonebrick"}, {["x"] = 6, ["y"] = 3, ["z"] = 3, ["name"] = "default:stonebrick"}, {["x"] = 6, ["y"] = 3, ["z"] = 4, ["name"] = "default:stonebrick"}, {["x"] = 6, ["y"] = 3, ["z"] = 5, ["name"] = "default:stonebrick"}, {["x"] = 6, ["y"] = 3, ["z"] = 15, ["name"] = "default:stone"}, {["x"] = 6, ["param2"] = 3, ["y"] = 3, ["param1"] = 15, ["z"] = 16, ["name"] = "xpanes:bar_flat"}, {["x"] = 6, ["param2"] = 3, ["y"] = 3, ["param1"] = 15, ["z"] = 17, ["name"] = "xpanes:bar_flat"}, {["x"] = 6, ["param2"] = 3, ["y"] = 3, ["param1"] = 15, ["z"] = 18, ["name"] = "xpanes:bar_flat"}, {["x"] = 6, ["y"] = 4, ["param1"] = 14, ["z"] = 0, ["name"] = "walls:cobble"}, {["x"] = 6, ["y"] = 4, ["z"] = 2, ["name"] = "default:stonebrick"}, {["x"] = 6, ["y"] = 4, ["z"] = 3, ["name"] = "default:stonebrick"}, {["x"] = 6, ["y"] = 4, ["z"] = 4, ["name"] = "default:stonebrick"}, {["x"] = 6, ["y"] = 4, ["z"] = 5, ["name"] = "default:stonebrick"}, {["x"] = 6, ["y"] = 4, ["param1"] = 14, ["z"] = 15, ["name"] = "walls:cobble"}, {["x"] = 6, ["y"] = 5, ["param1"] = 15, ["z"] = 0, ["name"] = "xpanes:bar_flat"}, {["x"] = 6, ["y"] = 5, ["z"] = 2, ["name"] = "default:stonebrick"}, {["x"] = 6, ["y"] = 5, ["z"] = 3, ["name"] = "default:stonebrick"}, {["x"] = 6, ["y"] = 5, ["z"] = 4, ["name"] = "default:stonebrick"}, {["x"] = 6, ["y"] = 5, ["z"] = 5, ["name"] = "default:stonebrick"}, {["x"] = 6, ["param2"] = 2, ["y"] = 5, ["param1"] = 15, ["z"] = 15, ["name"] = "xpanes:bar_flat"}, {["x"] = 6, ["y"] = 6, ["z"] = 2, ["name"] = "default:stonebrick"}, {["x"] = 6, ["y"] = 6, ["z"] = 3, ["name"] = "default:stonebrick"}, {["x"] = 6, ["y"] = 6, ["z"] = 4, ["name"] = "default:stonebrick"}, {["x"] = 6, ["y"] = 6, ["z"] = 5, ["name"] = "default:stonebrick"}, {["x"] = 6, ["y"] = 7, ["z"] = 1, ["name"] = "default:stonebrick"}, {["x"] = 6, ["y"] = 7, ["z"] = 2, ["name"] = "default:stonebrick"}, {["x"] = 6, ["y"] = 7, ["z"] = 3, ["name"] = "default:stonebrick"}, {["x"] = 6, ["y"] = 7, ["z"] = 4, ["name"] = "default:stonebrick"}, {["x"] = 6, ["y"] = 7, ["z"] = 5, ["name"] = "default:stonebrick"}, {["x"] = 6, ["y"] = 7, ["z"] = 6, ["name"] = "default:stonebrick"}, {["x"] = 6, ["y"] = 8, ["z"] = 1, ["name"] = "default:stonebrick"}, {["x"] = 6, ["y"] = 8, ["z"] = 6, ["name"] = "default:stonebrick"}, {["x"] = 6, ["y"] = 9, ["z"] = 6, ["name"] = "default:stonebrick"}, {["x"] = 7, ["y"] = 0, ["z"] = 0, ["name"] = "default:dirt"}, {["x"] = 7, ["y"] = 0, ["z"] = 1, ["name"] = "default:dirt_with_coniferous_litter"}, {["x"] = 7, ["y"] = 0, ["z"] = 2, ["name"] = "default:wood"}, {["x"] = 7, ["y"] = 0, ["z"] = 3, ["name"] = "default:wood"}, {["x"] = 7, ["y"] = 0, ["z"] = 4, ["name"] = "default:wood"}, {["x"] = 7, ["y"] = 0, ["z"] = 5, ["name"] = "default:wood"}, {["x"] = 7, ["y"] = 0, ["z"] = 6, ["name"] = "default:wood"}, {["x"] = 7, ["y"] = 0, ["z"] = 7, ["name"] = "default:wood"}, {["x"] = 7, ["y"] = 0, ["z"] = 8, ["name"] = "default:wood"}, {["x"] = 7, ["y"] = 0, ["z"] = 9, ["name"] = "default:wood"}, {["x"] = 7, ["y"] = 0, ["z"] = 10, ["name"] = "default:wood"}, {["x"] = 7, ["y"] = 0, ["z"] = 11, ["name"] = "default:wood"}, {["x"] = 7, ["y"] = 0, ["z"] = 12, ["name"] = "default:wood"}, {["x"] = 7, ["y"] = 0, ["z"] = 13, ["name"] = "default:wood"}, {["x"] = 7, ["y"] = 0, ["z"] = 14, ["name"] = "default:wood"}, {["x"] = 7, ["y"] = 0, ["z"] = 15, ["name"] = "default:wood"}, {["x"] = 7, ["y"] = 0, ["z"] = 16, ["name"] = "default:wood"}, {["x"] = 7, ["y"] = 0, ["z"] = 17, ["name"] = "default:wood"}, {["x"] = 7, ["y"] = 0, ["z"] = 18, ["name"] = "default:wood"}, {["x"] = 7, ["y"] = 1, ["z"] = 0, ["name"] = "default:stone"}, {["x"] = 7, ["y"] = 1, ["z"] = 2, ["name"] = "default:stonebrick"}, {["x"] = 7, ["param2"] = 2, ["y"] = 1, ["param1"] = 12, ["z"] = 4, ["name"] = "stairs:stair_wood"}, {["x"] = 7, ["y"] = 2, ["param1"] = 15, ["z"] = 0, ["name"] = "xpanes:bar_flat"}, {["x"] = 7, ["y"] = 2, ["z"] = 2, ["name"] = "default:stonebrick"}, {["x"] = 7, ["param2"] = 2, ["y"] = 2, ["param1"] = 11, ["z"] = 3, ["name"] = "stairs:stair_wood"}, {["x"] = 7, ["y"] = 3, ["param1"] = 15, ["z"] = 0, ["name"] = "xpanes:bar_flat"}, {["x"] = 7, ["y"] = 3, ["z"] = 2, ["name"] = "default:stonebrick"}, {["x"] = 7, ["y"] = 4, ["z"] = 2, ["name"] = "default:stonebrick"}, {["x"] = 7, ["y"] = 4, ["z"] = 5, ["name"] = "default:stonebrick"}, {["x"] = 7, ["y"] = 5, ["z"] = 2, ["name"] = "default:stonebrick"}, {["x"] = 7, ["param2"] = 3, ["y"] = 5, ["param1"] = 14, ["z"] = 4, ["name"] = "stairs:stair_wood"}, {["x"] = 7, ["y"] = 5, ["z"] = 5, ["name"] = "default:stonebrick"}, {["x"] = 7, ["y"] = 6, ["z"] = 2, ["name"] = "default:stonebrick"}, {["x"] = 7, ["param2"] = 2, ["y"] = 6, ["param1"] = 14, ["z"] = 3, ["name"] = "stairs:stair_wood"}, {["x"] = 7, ["y"] = 6, ["z"] = 5, ["name"] = "default:stonebrick"}, {["x"] = 7, ["y"] = 7, ["z"] = 1, ["name"] = "default:stonebrick"}, {["x"] = 7, ["y"] = 7, ["z"] = 2, ["name"] = "default:stonebrick"}, {["x"] = 7, ["y"] = 7, ["z"] = 5, ["name"] = "default:stonebrick"}, {["x"] = 7, ["y"] = 7, ["z"] = 6, ["name"] = "default:stonebrick"}, {["x"] = 7, ["y"] = 8, ["z"] = 1, ["name"] = "default:stonebrick"}, {["x"] = 7, ["y"] = 8, ["z"] = 6, ["name"] = "default:stonebrick"}, {["x"] = 7, ["y"] = 9, ["z"] = 1, ["name"] = "default:stonebrick"}, {["x"] = 8, ["y"] = 0, ["z"] = 0, ["name"] = "default:dirt"}, {["x"] = 8, ["y"] = 0, ["z"] = 1, ["name"] = "default:dirt_with_coniferous_litter"}, {["x"] = 8, ["y"] = 0, ["z"] = 2, ["name"] = "default:wood"}, {["x"] = 8, ["y"] = 0, ["z"] = 3, ["name"] = "default:wood"}, {["x"] = 8, ["y"] = 0, ["z"] = 4, ["name"] = "default:wood"}, {["x"] = 8, ["y"] = 0, ["z"] = 5, ["name"] = "default:wood"}, {["x"] = 8, ["y"] = 0, ["z"] = 6, ["name"] = "default:wood"}, {["x"] = 8, ["y"] = 0, ["z"] = 7, ["name"] = "default:wood"}, {["x"] = 8, ["y"] = 0, ["z"] = 8, ["name"] = "default:wood"}, {["x"] = 8, ["y"] = 0, ["z"] = 9, ["name"] = "default:wood"}, {["x"] = 8, ["y"] = 0, ["z"] = 10, ["name"] = "default:wood"}, {["x"] = 8, ["y"] = 0, ["z"] = 11, ["name"] = "default:wood"}, {["x"] = 8, ["y"] = 0, ["z"] = 12, ["name"] = "default:wood"}, {["x"] = 8, ["y"] = 0, ["z"] = 13, ["name"] = "default:wood"}, {["x"] = 8, ["y"] = 0, ["z"] = 14, ["name"] = "default:wood"}, {["x"] = 8, ["y"] = 0, ["z"] = 15, ["name"] = "default:wood"}, {["x"] = 8, ["y"] = 0, ["z"] = 16, ["name"] = "default:wood"}, {["x"] = 8, ["y"] = 0, ["z"] = 17, ["name"] = "default:wood"}, {["x"] = 8, ["y"] = 0, ["z"] = 18, ["name"] = "default:wood"}, {["x"] = 8, ["y"] = 1, ["z"] = 0, ["name"] = "default:stone"}, {["x"] = 8, ["y"] = 1, ["z"] = 2, ["name"] = "default:stonebrick"}, {["x"] = 8, ["y"] = 2, ["param1"] = 15, ["z"] = 0, ["name"] = "xpanes:bar_flat"}, {["x"] = 8, ["y"] = 2, ["z"] = 2, ["name"] = "default:stonebrick"}, {["x"] = 8, ["y"] = 3, ["param1"] = 15, ["z"] = 0, ["name"] = "xpanes:bar_flat"}, {["x"] = 8, ["y"] = 3, ["z"] = 2, ["name"] = "default:stonebrick"}, {["x"] = 8, ["param2"] = 1, ["y"] = 3, ["param1"] = 12, ["z"] = 3, ["name"] = "stairs:stair_wood"}, {["x"] = 8, ["y"] = 4, ["z"] = 2, ["name"] = "default:stonebrick"}, {["x"] = 8, ["y"] = 4, ["param1"] = 14, ["z"] = 4, ["name"] = "stairs:stair_wood"}, {["x"] = 8, ["y"] = 4, ["z"] = 5, ["name"] = "default:stonebrick"}, {["x"] = 8, ["y"] = 5, ["z"] = 2, ["name"] = "default:stonebrick"}, {["x"] = 8, ["y"] = 5, ["z"] = 5, ["name"] = "default:stonebrick"}, {["x"] = 8, ["y"] = 6, ["z"] = 2, ["name"] = "default:stonebrick"}, {["x"] = 8, ["y"] = 6, ["z"] = 5, ["name"] = "default:stonebrick"}, {["x"] = 8, ["y"] = 7, ["z"] = 1, ["name"] = "default:stonebrick"}, {["x"] = 8, ["y"] = 7, ["z"] = 2, ["name"] = "default:stonebrick"}, {["x"] = 8, ["param2"] = 1, ["y"] = 7, ["param1"] = 14, ["z"] = 3, ["name"] = "stairs:stair_wood"}, {["x"] = 8, ["y"] = 7, ["z"] = 5, ["name"] = "default:stonebrick"}, {["x"] = 8, ["y"] = 7, ["z"] = 6, ["name"] = "default:stonebrick"}, {["x"] = 8, ["y"] = 8, ["z"] = 1, ["name"] = "default:stonebrick"}, {["x"] = 8, ["y"] = 8, ["z"] = 6, ["name"] = "default:stonebrick"}, {["x"] = 8, ["y"] = 9, ["z"] = 6, ["name"] = "default:stonebrick"}, {["x"] = 9, ["y"] = 0, ["z"] = 0, ["name"] = "default:dirt"}, {["x"] = 9, ["y"] = 0, ["z"] = 1, ["name"] = "default:dirt_with_coniferous_litter"}, {["x"] = 9, ["y"] = 0, ["z"] = 2, ["name"] = "default:wood"}, {["x"] = 9, ["y"] = 0, ["z"] = 3, ["name"] = "default:wood"}, {["x"] = 9, ["y"] = 0, ["z"] = 4, ["name"] = "default:wood"}, {["x"] = 9, ["y"] = 0, ["z"] = 5, ["name"] = "default:wood"}, {["x"] = 9, ["y"] = 0, ["z"] = 6, ["name"] = "default:dirt_with_coniferous_litter"}, {["x"] = 9, ["y"] = 0, ["z"] = 7, ["name"] = "default:dirt_with_coniferous_litter"}, {["x"] = 9, ["y"] = 0, ["z"] = 8, ["name"] = "default:dirt_with_coniferous_litter"}, {["x"] = 9, ["y"] = 0, ["z"] = 9, ["name"] = "default:dirt_with_coniferous_litter"}, {["x"] = 9, ["y"] = 0, ["z"] = 10, ["name"] = "default:dirt_with_coniferous_litter"}, {["x"] = 9, ["y"] = 0, ["z"] = 11, ["name"] = "default:dirt_with_coniferous_litter"}, {["x"] = 9, ["y"] = 0, ["z"] = 12, ["name"] = "default:dirt_with_coniferous_litter"}, {["x"] = 9, ["y"] = 0, ["z"] = 13, ["name"] = "default:dirt_with_coniferous_litter"}, {["x"] = 9, ["y"] = 0, ["z"] = 14, ["name"] = "default:dirt_with_coniferous_litter"}, {["x"] = 9, ["y"] = 0, ["z"] = 15, ["name"] = "default:dirt"}, {["x"] = 9, ["y"] = 0, ["z"] = 16, ["name"] = "default:dirt_with_coniferous_litter"}, {["x"] = 9, ["y"] = 0, ["z"] = 17, ["name"] = "default:dirt_with_coniferous_litter"}, {["x"] = 9, ["y"] = 0, ["z"] = 18, ["name"] = "default:dirt_with_coniferous_litter"}, {["x"] = 9, ["y"] = 1, ["z"] = 0, ["name"] = "default:stonebrick"}, {["x"] = 9, ["y"] = 1, ["z"] = 2, ["name"] = "default:stonebrick"}, {["x"] = 9, ["y"] = 1, ["z"] = 3, ["name"] = "default:stonebrick"}, {["x"] = 9, ["y"] = 1, ["z"] = 4, ["name"] = "default:stonebrick"}, {["x"] = 9, ["y"] = 1, ["z"] = 5, ["name"] = "default:stonebrick"}, {["x"] = 9, ["y"] = 1, ["param1"] = 15, ["z"] = 7, ["name"] = "flowers:mushroom_brown"}, {["x"] = 9, ["y"] = 1, ["param1"] = 15, ["z"] = 12, ["name"] = "flowers:mushroom_brown"}, {["x"] = 9, ["y"] = 1, ["param1"] = 15, ["z"] = 14, ["name"] = "flowers:mushroom_brown"}, {["x"] = 9, ["y"] = 1, ["z"] = 15, ["name"] = "default:stonebrick"}, {["x"] = 9, ["param2"] = 3, ["y"] = 1, ["param1"] = 15, ["z"] = 16, ["name"] = "xpanes:bar_flat"}, {["x"] = 9, ["param2"] = 3, ["y"] = 1, ["param1"] = 15, ["z"] = 17, ["name"] = "xpanes:bar_flat"}, {["x"] = 9, ["param2"] = 3, ["y"] = 1, ["param1"] = 15, ["z"] = 18, ["name"] = "xpanes:bar_flat"}, {["x"] = 9, ["y"] = 2, ["z"] = 0, ["name"] = "default:stone"}, {["x"] = 9, ["y"] = 2, ["z"] = 2, ["name"] = "default:stonebrick"}, {["x"] = 9, ["y"] = 2, ["z"] = 3, ["name"] = "default:stonebrick"}, {["x"] = 9, ["y"] = 2, ["z"] = 4, ["name"] = "default:stonebrick"}, {["x"] = 9, ["y"] = 2, ["z"] = 5, ["name"] = "default:stonebrick"}, {["x"] = 9, ["y"] = 2, ["z"] = 15, ["name"] = "default:stone"}, {["x"] = 9, ["param2"] = 3, ["y"] = 2, ["param1"] = 15, ["z"] = 16, ["name"] = "xpanes:bar_flat"}, {["x"] = 9, ["param2"] = 3, ["y"] = 2, ["param1"] = 15, ["z"] = 17, ["name"] = "xpanes:bar_flat"}, {["x"] = 9, ["param2"] = 3, ["y"] = 2, ["param1"] = 15, ["z"] = 18, ["name"] = "xpanes:bar_flat"}, {["x"] = 9, ["y"] = 3, ["z"] = 0, ["name"] = "default:stone"}, {["x"] = 9, ["y"] = 3, ["z"] = 2, ["name"] = "default:stonebrick"}, {["x"] = 9, ["y"] = 3, ["z"] = 3, ["name"] = "default:stonebrick"}, {["x"] = 9, ["y"] = 3, ["z"] = 4, ["name"] = "default:stonebrick"}, {["x"] = 9, ["y"] = 3, ["z"] = 5, ["name"] = "default:stonebrick"}, {["x"] = 9, ["y"] = 3, ["z"] = 15, ["name"] = "default:stone"}, {["x"] = 9, ["param2"] = 3, ["y"] = 3, ["param1"] = 15, ["z"] = 16, ["name"] = "xpanes:bar_flat"}, {["x"] = 9, ["param2"] = 3, ["y"] = 3, ["param1"] = 15, ["z"] = 17, ["name"] = "xpanes:bar_flat"}, {["x"] = 9, ["param2"] = 3, ["y"] = 3, ["param1"] = 15, ["z"] = 18, ["name"] = "xpanes:bar_flat"}, {["x"] = 9, ["y"] = 4, ["param1"] = 14, ["z"] = 0, ["name"] = "walls:cobble"}, {["x"] = 9, ["y"] = 4, ["z"] = 2, ["name"] = "default:stonebrick"}, {["x"] = 9, ["y"] = 4, ["z"] = 3, ["name"] = "default:stonebrick"}, {["x"] = 9, ["y"] = 4, ["z"] = 4, ["name"] = "default:stonebrick"}, {["x"] = 9, ["y"] = 4, ["z"] = 5, ["name"] = "default:stonebrick"}, {["x"] = 9, ["y"] = 4, ["param1"] = 14, ["z"] = 15, ["name"] = "walls:cobble"}, {["x"] = 9, ["y"] = 5, ["param1"] = 15, ["z"] = 0, ["name"] = "xpanes:bar_flat"}, {["x"] = 9, ["y"] = 5, ["z"] = 2, ["name"] = "default:stonebrick"}, {["x"] = 9, ["y"] = 5, ["z"] = 3, ["name"] = "default:stonebrick"}, {["x"] = 9, ["y"] = 5, ["z"] = 4, ["name"] = "default:stonebrick"}, {["x"] = 9, ["y"] = 5, ["z"] = 5, ["name"] = "default:stonebrick"}, {["x"] = 9, ["param2"] = 2, ["y"] = 5, ["param1"] = 15, ["z"] = 15, ["name"] = "xpanes:bar_flat"}, {["x"] = 9, ["y"] = 6, ["z"] = 2, ["name"] = "default:stonebrick"}, {["x"] = 9, ["y"] = 6, ["z"] = 3, ["name"] = "default:stonebrick"}, {["x"] = 9, ["y"] = 6, ["z"] = 4, ["name"] = "default:stonebrick"}, {["x"] = 9, ["y"] = 6, ["z"] = 5, ["name"] = "default:stonebrick"}, {["x"] = 9, ["y"] = 7, ["z"] = 1, ["name"] = "default:stonebrick"}, {["x"] = 9, ["y"] = 7, ["z"] = 2, ["name"] = "default:stonebrick"}, {["x"] = 9, ["y"] = 7, ["z"] = 3, ["name"] = "default:stonebrick"}, {["x"] = 9, ["y"] = 7, ["z"] = 4, ["name"] = "default:stonebrick"}, {["x"] = 9, ["y"] = 7, ["z"] = 5, ["name"] = "default:stonebrick"}, {["x"] = 9, ["y"] = 7, ["z"] = 6, ["name"] = "default:stonebrick"}, {["x"] = 9, ["y"] = 8, ["z"] = 1, ["name"] = "default:stonebrick"}, {["x"] = 9, ["y"] = 8, ["z"] = 6, ["name"] = "default:stonebrick"}, {["x"] = 9, ["y"] = 9, ["z"] = 1, ["name"] = "default:stonebrick"}, {["x"] = 10, ["y"] = 0, ["z"] = 0, ["name"] = "default:dirt"}, {["x"] = 10, ["y"] = 0, ["z"] = 1, ["name"] = "default:dirt_with_coniferous_litter"}, {["x"] = 10, ["y"] = 0, ["z"] = 2, ["name"] = "default:dirt_with_coniferous_litter"}, {["x"] = 10, ["y"] = 0, ["z"] = 3, ["name"] = "default:dirt_with_coniferous_litter"}, {["x"] = 10, ["y"] = 0, ["z"] = 4, ["name"] = "default:dirt_with_coniferous_litter"}, {["x"] = 10, ["y"] = 0, ["z"] = 5, ["name"] = "default:dirt_with_coniferous_litter"}, {["x"] = 10, ["y"] = 0, ["z"] = 6, ["name"] = "default:dirt_with_coniferous_litter"}, {["x"] = 10, ["y"] = 0, ["z"] = 7, ["name"] = "default:dirt_with_coniferous_litter"}, {["x"] = 10, ["y"] = 0, ["z"] = 8, ["name"] = "default:dirt_with_coniferous_litter"}, {["x"] = 10, ["y"] = 0, ["z"] = 9, ["name"] = "default:dirt_with_coniferous_litter"}, {["x"] = 10, ["y"] = 0, ["z"] = 10, ["name"] = "default:dirt_with_coniferous_litter"}, {["x"] = 10, ["y"] = 0, ["z"] = 11, ["name"] = "default:dirt_with_coniferous_litter"}, {["x"] = 10, ["y"] = 0, ["z"] = 12, ["name"] = "default:dirt_with_coniferous_litter"}, {["x"] = 10, ["y"] = 0, ["z"] = 13, ["name"] = "default:dirt_with_coniferous_litter"}, {["x"] = 10, ["y"] = 0, ["z"] = 14, ["name"] = "default:dirt_with_coniferous_litter"}, {["x"] = 10, ["y"] = 0, ["z"] = 15, ["name"] = "default:dirt"}, {["x"] = 10, ["y"] = 0, ["z"] = 16, ["name"] = "default:dirt_with_coniferous_litter"}, {["x"] = 10, ["y"] = 0, ["z"] = 17, ["name"] = "default:dirt_with_coniferous_litter"}, {["x"] = 10, ["y"] = 0, ["z"] = 18, ["name"] = "default:dirt_with_coniferous_litter"}, {["x"] = 10, ["y"] = 1, ["z"] = 0, ["name"] = "default:stone"}, {["x"] = 10, ["y"] = 1, ["param1"] = 14, ["z"] = 2, ["name"] = "flowers:mushroom_brown"}, {["x"] = 10, ["y"] = 1, ["param1"] = 15, ["z"] = 9, ["name"] = "flowers:mushroom_brown"}, {["x"] = 10, ["y"] = 1, ["z"] = 15, ["name"] = "default:stone"}, {["x"] = 10, ["y"] = 2, ["param1"] = 15, ["z"] = 0, ["name"] = "xpanes:bar_flat"}, {["x"] = 10, ["y"] = 2, ["param1"] = 15, ["z"] = 15, ["name"] = "xpanes:bar_flat"}, {["x"] = 10, ["y"] = 3, ["param1"] = 15, ["z"] = 0, ["name"] = "xpanes:bar_flat"}, {["x"] = 10, ["y"] = 3, ["param1"] = 15, ["z"] = 15, ["name"] = "xpanes:bar_flat"}, {["x"] = 10, ["y"] = 7, ["z"] = 2, ["name"] = "default:stonebrick"}, {["x"] = 10, ["y"] = 7, ["z"] = 3, ["name"] = "default:stonebrick"}, {["x"] = 10, ["y"] = 7, ["z"] = 4, ["name"] = "default:stonebrick"}, {["x"] = 10, ["y"] = 7, ["z"] = 5, ["name"] = "default:stonebrick"}, {["x"] = 10, ["y"] = 8, ["z"] = 2, ["name"] = "default:stonebrick"}, {["x"] = 10, ["y"] = 8, ["z"] = 3, ["name"] = "default:stonebrick"}, {["x"] = 10, ["y"] = 8, ["z"] = 4, ["name"] = "default:stonebrick"}, {["x"] = 10, ["y"] = 8, ["z"] = 5, ["name"] = "default:stonebrick"}, {["x"] = 10, ["y"] = 9, ["z"] = 3, ["name"] = "default:stonebrick"}, {["x"] = 10, ["y"] = 9, ["z"] = 5, ["name"] = "default:stonebrick"}, {["x"] = 11, ["y"] = 0, ["z"] = 0, ["name"] = "default:dirt"}, {["x"] = 11, ["y"] = 0, ["z"] = 1, ["name"] = "default:dirt_with_coniferous_litter"}, {["x"] = 11, ["y"] = 0, ["z"] = 2, ["name"] = "default:dirt_with_coniferous_litter"}, {["x"] = 11, ["y"] = 0, ["z"] = 3, ["name"] = "default:dirt_with_rainforest_litter"}, {["x"] = 11, ["y"] = 0, ["z"] = 4, ["name"] = "default:dirt_with_rainforest_litter"}, {["x"] = 11, ["y"] = 0, ["z"] = 5, ["name"] = "default:dirt_with_rainforest_litter"}, {["x"] = 11, ["y"] = 0, ["z"] = 6, ["name"] = "default:dirt_with_coniferous_litter"}, {["x"] = 11, ["y"] = 0, ["z"] = 7, ["name"] = "default:dirt_with_coniferous_litter"}, {["x"] = 11, ["y"] = 0, ["z"] = 8, ["name"] = "default:dirt_with_rainforest_litter"}, {["x"] = 11, ["y"] = 0, ["z"] = 9, ["name"] = "default:dirt_with_rainforest_litter"}, {["x"] = 11, ["y"] = 0, ["z"] = 10, ["name"] = "default:dirt_with_coniferous_litter"}, {["x"] = 11, ["y"] = 0, ["z"] = 11, ["name"] = "default:dirt_with_coniferous_litter"}, {["x"] = 11, ["y"] = 0, ["z"] = 12, ["name"] = "default:dirt_with_rainforest_litter"}, {["x"] = 11, ["y"] = 0, ["z"] = 13, ["name"] = "default:dirt_with_rainforest_litter"}, {["x"] = 11, ["y"] = 0, ["z"] = 14, ["name"] = "default:dirt_with_coniferous_litter"}, {["x"] = 11, ["y"] = 0, ["z"] = 15, ["name"] = "default:dirt"}, {["x"] = 11, ["y"] = 0, ["z"] = 16, ["name"] = "default:dirt_with_coniferous_litter"}, {["x"] = 11, ["y"] = 0, ["z"] = 17, ["name"] = "default:dirt_with_coniferous_litter"}, {["x"] = 11, ["y"] = 0, ["z"] = 18, ["name"] = "default:dirt_with_coniferous_litter"}, {["x"] = 11, ["y"] = 1, ["z"] = 0, ["name"] = "default:stone"}, {["x"] = 11, ["y"] = 1, ["param1"] = 15, ["z"] = 2, ["name"] = "flowers:mushroom_brown"}, {["x"] = 11, ["param2"] = 8, ["y"] = 1, ["param1"] = 14, ["z"] = 3, ["name"] = "stairs:slab_cobble"}, {["x"] = 11, ["param2"] = 8, ["y"] = 1, ["param1"] = 14, ["z"] = 7, ["name"] = "stairs:slab_cobble"}, {["x"] = 11, ["y"] = 1, ["param1"] = 15, ["z"] = 8, ["name"] = "flowers:dandelion_white"}, {["x"] = 11, ["param2"] = 8, ["y"] = 1, ["param1"] = 14, ["z"] = 11, ["name"] = "stairs:slab_cobble"}, {["x"] = 11, ["y"] = 1, ["z"] = 15, ["name"] = "default:stone"}, {["x"] = 11, ["y"] = 2, ["param1"] = 15, ["z"] = 0, ["name"] = "xpanes:bar_flat"}, {["x"] = 11, ["y"] = 2, ["param1"] = 15, ["z"] = 15, ["name"] = "xpanes:bar_flat"}, {["x"] = 11, ["y"] = 3, ["param1"] = 15, ["z"] = 0, ["name"] = "xpanes:bar_flat"}, {["x"] = 11, ["y"] = 3, ["param1"] = 15, ["z"] = 15, ["name"] = "xpanes:bar_flat"}, {["x"] = 12, ["y"] = 0, ["z"] = 0, ["name"] = "default:dirt"}, {["x"] = 12, ["y"] = 0, ["z"] = 1, ["name"] = "default:dirt_with_coniferous_litter"}, {["x"] = 12, ["y"] = 0, ["z"] = 2, ["name"] = "default:dirt_with_coniferous_litter"}, {["x"] = 12, ["y"] = 0, ["z"] = 3, ["name"] = "default:dirt_with_coniferous_litter"}, {["x"] = 12, ["y"] = 0, ["z"] = 4, ["name"] = "default:dirt_with_coniferous_litter"}, {["x"] = 12, ["y"] = 0, ["z"] = 5, ["name"] = "default:dirt_with_coniferous_litter"}, {["x"] = 12, ["y"] = 0, ["z"] = 6, ["name"] = "default:dirt_with_coniferous_litter"}, {["x"] = 12, ["y"] = 0, ["z"] = 7, ["name"] = "default:dirt_with_coniferous_litter"}, {["x"] = 12, ["y"] = 0, ["z"] = 8, ["name"] = "default:dirt_with_coniferous_litter"}, {["x"] = 12, ["y"] = 0, ["z"] = 9, ["name"] = "default:dirt_with_coniferous_litter"}, {["x"] = 12, ["y"] = 0, ["z"] = 10, ["name"] = "default:dirt_with_coniferous_litter"}, {["x"] = 12, ["y"] = 0, ["z"] = 11, ["name"] = "default:dirt_with_coniferous_litter"}, {["x"] = 12, ["y"] = 0, ["z"] = 12, ["name"] = "default:dirt_with_coniferous_litter"}, {["x"] = 12, ["y"] = 0, ["z"] = 13, ["name"] = "default:dirt_with_coniferous_litter"}, {["x"] = 12, ["y"] = 0, ["z"] = 14, ["name"] = "default:dirt_with_coniferous_litter"}, {["x"] = 12, ["y"] = 0, ["z"] = 15, ["name"] = "default:dirt"}, {["x"] = 12, ["y"] = 0, ["z"] = 16, ["name"] = "default:dirt_with_coniferous_litter"}, {["x"] = 12, ["y"] = 0, ["z"] = 17, ["name"] = "default:dirt_with_coniferous_litter"}, {["x"] = 12, ["y"] = 0, ["z"] = 18, ["name"] = "default:dirt_with_coniferous_litter"}, {["x"] = 12, ["y"] = 1, ["z"] = 0, ["name"] = "default:stonebrick"}, {["x"] = 12, ["y"] = 1, ["param1"] = 15, ["z"] = 7, ["name"] = "flowers:mushroom_brown"}, {["x"] = 12, ["y"] = 1, ["z"] = 15, ["name"] = "default:stonebrick"}, {["x"] = 12, ["y"] = 2, ["z"] = 0, ["name"] = "default:stone"}, {["x"] = 12, ["y"] = 2, ["z"] = 15, ["name"] = "default:stone"}, {["x"] = 12, ["y"] = 3, ["z"] = 0, ["name"] = "default:stone"}, {["x"] = 12, ["y"] = 3, ["z"] = 15, ["name"] = "default:stone"}, {["x"] = 12, ["y"] = 4, ["param1"] = 14, ["z"] = 0, ["name"] = "walls:cobble"}, {["x"] = 12, ["y"] = 4, ["param1"] = 14, ["z"] = 15, ["name"] = "walls:cobble"}, {["x"] = 12, ["y"] = 5, ["param1"] = 15, ["z"] = 0, ["name"] = "xpanes:bar_flat"}, {["x"] = 12, ["param2"] = 2, ["y"] = 5, ["param1"] = 15, ["z"] = 15, ["name"] = "xpanes:bar_flat"}, {["x"] = 13, ["y"] = 0, ["z"] = 0, ["name"] = "default:dirt"}, {["x"] = 13, ["y"] = 0, ["z"] = 1, ["name"] = "default:dirt_with_coniferous_litter"}, {["x"] = 13, ["y"] = 0, ["z"] = 2, ["name"] = "default:dirt_with_coniferous_litter"}, {["x"] = 13, ["y"] = 0, ["z"] = 3, ["name"] = "default:dirt"}, {["x"] = 13, ["y"] = 0, ["z"] = 4, ["name"] = "default:dirt_with_rainforest_litter"}, {["x"] = 13, ["y"] = 0, ["z"] = 5, ["name"] = "default:dirt_with_rainforest_litter"}, {["x"] = 13, ["y"] = 0, ["z"] = 6, ["name"] = "default:dirt_with_coniferous_litter"}, {["x"] = 13, ["y"] = 0, ["z"] = 7, ["name"] = "default:dirt"}, {["x"] = 13, ["y"] = 0, ["z"] = 8, ["name"] = "default:dirt_with_rainforest_litter"}, {["x"] = 13, ["y"] = 0, ["z"] = 9, ["name"] = "default:dirt_with_rainforest_litter"}, {["x"] = 13, ["y"] = 0, ["z"] = 10, ["name"] = "default:dirt_with_coniferous_litter"}, {["x"] = 13, ["y"] = 0, ["z"] = 11, ["name"] = "default:dirt"}, {["x"] = 13, ["y"] = 0, ["z"] = 12, ["name"] = "default:dirt_with_rainforest_litter"}, {["x"] = 13, ["y"] = 0, ["z"] = 13, ["name"] = "default:dirt_with_rainforest_litter"}, {["x"] = 13, ["y"] = 0, ["z"] = 14, ["name"] = "default:dirt_with_coniferous_litter"}, {["x"] = 13, ["y"] = 0, ["z"] = 15, ["name"] = "default:dirt"}, {["x"] = 13, ["y"] = 0, ["z"] = 16, ["name"] = "default:dirt_with_coniferous_litter"}, {["x"] = 13, ["y"] = 0, ["z"] = 17, ["name"] = "default:dirt_with_coniferous_litter"}, {["x"] = 13, ["y"] = 0, ["z"] = 18, ["name"] = "default:dirt_with_coniferous_litter"}, {["x"] = 13, ["y"] = 1, ["z"] = 0, ["name"] = "default:stone"}, {["x"] = 13, ["y"] = 1, ["param1"] = 15, ["z"] = 1, ["name"] = "flowers:mushroom_brown"}, {["x"] = 13, ["param2"] = 8, ["y"] = 1, ["param1"] = 14, ["z"] = 3, ["name"] = "stairs:slab_cobble"}, {["x"] = 13, ["param2"] = 8, ["y"] = 1, ["param1"] = 14, ["z"] = 7, ["name"] = "stairs:slab_cobble"}, {["x"] = 13, ["param2"] = 8, ["y"] = 1, ["param1"] = 14, ["z"] = 11, ["name"] = "stairs:slab_cobble"}, {["x"] = 13, ["y"] = 1, ["param1"] = 15, ["z"] = 12, ["name"] = "flowers:rose"}, {["x"] = 13, ["y"] = 1, ["param1"] = 15, ["z"] = 14, ["name"] = "flowers:mushroom_brown"}, {["x"] = 13, ["y"] = 1, ["z"] = 15, ["name"] = "default:stone"}, {["x"] = 13, ["y"] = 2, ["param1"] = 15, ["z"] = 0, ["name"] = "xpanes:bar_flat"}, {["x"] = 13, ["y"] = 2, ["param1"] = 15, ["z"] = 15, ["name"] = "xpanes:bar_flat"}, {["x"] = 13, ["y"] = 3, ["param1"] = 15, ["z"] = 0, ["name"] = "xpanes:bar_flat"}, {["x"] = 13, ["y"] = 3, ["param1"] = 15, ["z"] = 15, ["name"] = "xpanes:bar_flat"}, {["x"] = 14, ["y"] = 0, ["z"] = 0, ["name"] = "default:dirt"}, {["x"] = 14, ["y"] = 0, ["z"] = 1, ["name"] = "default:dirt_with_coniferous_litter"}, {["x"] = 14, ["y"] = 0, ["z"] = 2, ["name"] = "default:dirt_with_coniferous_litter"}, {["x"] = 14, ["y"] = 0, ["z"] = 3, ["name"] = "default:dirt_with_coniferous_litter"}, {["x"] = 14, ["y"] = 0, ["z"] = 4, ["name"] = "default:dirt_with_coniferous_litter"}, {["x"] = 14, ["y"] = 0, ["z"] = 5, ["name"] = "default:dirt_with_coniferous_litter"}, {["x"] = 14, ["y"] = 0, ["z"] = 6, ["name"] = "default:dirt_with_coniferous_litter"}, {["x"] = 14, ["y"] = 0, ["z"] = 7, ["name"] = "default:dirt_with_coniferous_litter"}, {["x"] = 14, ["y"] = 0, ["z"] = 8, ["name"] = "default:dirt_with_coniferous_litter"}, {["x"] = 14, ["y"] = 0, ["z"] = 9, ["name"] = "default:dirt_with_coniferous_litter"}, {["x"] = 14, ["y"] = 0, ["z"] = 10, ["name"] = "default:dirt_with_coniferous_litter"}, {["x"] = 14, ["y"] = 0, ["z"] = 11, ["name"] = "default:dirt_with_coniferous_litter"}, {["x"] = 14, ["y"] = 0, ["z"] = 12, ["name"] = "default:dirt_with_coniferous_litter"}, {["x"] = 14, ["y"] = 0, ["z"] = 13, ["name"] = "default:dirt_with_coniferous_litter"}, {["x"] = 14, ["y"] = 0, ["z"] = 14, ["name"] = "default:dirt_with_coniferous_litter"}, {["x"] = 14, ["y"] = 0, ["z"] = 15, ["name"] = "default:dirt"}, {["x"] = 14, ["y"] = 0, ["z"] = 16, ["name"] = "default:dirt_with_coniferous_litter"}, {["x"] = 14, ["y"] = 0, ["z"] = 17, ["name"] = "default:dirt_with_coniferous_litter"}, {["x"] = 14, ["y"] = 0, ["z"] = 18, ["name"] = "default:dirt_with_coniferous_litter"}, {["x"] = 14, ["y"] = 1, ["z"] = 0, ["name"] = "default:stone"}, {["x"] = 14, ["y"] = 1, ["param1"] = 15, ["z"] = 5, ["name"] = "flowers:mushroom_brown"}, {["x"] = 14, ["y"] = 1, ["param1"] = 15, ["z"] = 8, ["name"] = "flowers:mushroom_brown"}, {["x"] = 14, ["y"] = 1, ["param1"] = 15, ["z"] = 11, ["name"] = "flowers:mushroom_brown"}, {["x"] = 14, ["y"] = 1, ["z"] = 15, ["name"] = "default:stone"}, {["x"] = 14, ["y"] = 2, ["param1"] = 15, ["z"] = 0, ["name"] = "xpanes:bar_flat"}, {["x"] = 14, ["y"] = 2, ["param1"] = 15, ["z"] = 15, ["name"] = "xpanes:bar_flat"}, {["x"] = 14, ["y"] = 3, ["param1"] = 15, ["z"] = 0, ["name"] = "xpanes:bar_flat"}, {["x"] = 14, ["y"] = 3, ["param1"] = 15, ["z"] = 15, ["name"] = "xpanes:bar_flat"}, {["x"] = 15, ["y"] = 0, ["z"] = 0, ["name"] = "default:dirt"}, {["x"] = 15, ["y"] = 0, ["z"] = 1, ["name"] = "default:dirt"}, {["x"] = 15, ["y"] = 0, ["z"] = 2, ["name"] = "default:dirt"}, {["x"] = 15, ["y"] = 0, ["z"] = 3, ["name"] = "default:dirt"}, {["x"] = 15, ["y"] = 0, ["z"] = 4, ["name"] = "default:dirt"}, {["x"] = 15, ["y"] = 0, ["z"] = 5, ["name"] = "default:dirt"}, {["x"] = 15, ["y"] = 0, ["z"] = 6, ["name"] = "default:dirt"}, {["x"] = 15, ["y"] = 0, ["z"] = 7, ["name"] = "default:dirt"}, {["x"] = 15, ["y"] = 0, ["z"] = 8, ["name"] = "default:dirt"}, {["x"] = 15, ["y"] = 0, ["z"] = 9, ["name"] = "default:dirt"}, {["x"] = 15, ["y"] = 0, ["z"] = 10, ["name"] = "default:dirt"}, {["x"] = 15, ["y"] = 0, ["z"] = 11, ["name"] = "default:dirt"}, {["x"] = 15, ["y"] = 0, ["z"] = 12, ["name"] = "default:dirt"}, {["x"] = 15, ["y"] = 0, ["z"] = 13, ["name"] = "default:dirt"}, {["x"] = 15, ["y"] = 0, ["z"] = 14, ["name"] = "default:dirt_with_coniferous_litter"}, {["x"] = 15, ["y"] = 0, ["z"] = 15, ["name"] = "default:dirt"}, {["x"] = 15, ["y"] = 0, ["z"] = 16, ["name"] = "default:dirt_with_coniferous_litter"}, {["x"] = 15, ["y"] = 0, ["z"] = 17, ["name"] = "default:dirt_with_coniferous_litter"}, {["x"] = 15, ["y"] = 0, ["z"] = 18, ["name"] = "default:dirt_with_coniferous_litter"}, {["x"] = 15, ["y"] = 1, ["z"] = 0, ["name"] = "default:stonebrick"}, {["x"] = 15, ["y"] = 1, ["z"] = 1, ["name"] = "default:stone"}, {["x"] = 15, ["y"] = 1, ["z"] = 2, ["name"] = "default:stone"}, {["x"] = 15, ["y"] = 1, ["z"] = 3, ["name"] = "default:stonebrick"}, {["x"] = 15, ["y"] = 1, ["z"] = 4, ["name"] = "default:stone"}, {["x"] = 15, ["y"] = 1, ["z"] = 5, ["name"] = "default:stone"}, {["x"] = 15, ["y"] = 1, ["z"] = 6, ["name"] = "default:stonebrick"}, {["x"] = 15, ["y"] = 1, ["z"] = 7, ["name"] = "default:stone"}, {["x"] = 15, ["y"] = 1, ["z"] = 8, ["name"] = "default:stone"}, {["x"] = 15, ["y"] = 1, ["z"] = 9, ["name"] = "default:stonebrick"}, {["x"] = 15, ["y"] = 1, ["z"] = 10, ["name"] = "default:stone"}, {["x"] = 15, ["y"] = 1, ["z"] = 11, ["name"] = "default:stone"}, {["x"] = 15, ["y"] = 1, ["z"] = 12, ["name"] = "default:stonebrick"}, {["x"] = 15, ["y"] = 1, ["z"] = 13, ["name"] = "default:stone"}, {["x"] = 15, ["y"] = 1, ["z"] = 14, ["name"] = "default:stone"}, {["x"] = 15, ["y"] = 1, ["z"] = 15, ["name"] = "default:stonebrick"}, {["x"] = 15, ["y"] = 2, ["z"] = 0, ["name"] = "default:stone"}, {["x"] = 15, ["param2"] = 3, ["y"] = 2, ["param1"] = 15, ["z"] = 1, ["name"] = "xpanes:bar_flat"}, {["x"] = 15, ["param2"] = 3, ["y"] = 2, ["param1"] = 15, ["z"] = 2, ["name"] = "xpanes:bar_flat"}, {["x"] = 15, ["y"] = 2, ["z"] = 3, ["name"] = "default:stone"}, {["x"] = 15, ["param2"] = 3, ["y"] = 2, ["param1"] = 15, ["z"] = 4, ["name"] = "xpanes:bar_flat"}, {["x"] = 15, ["param2"] = 3, ["y"] = 2, ["param1"] = 15, ["z"] = 5, ["name"] = "xpanes:bar_flat"}, {["x"] = 15, ["y"] = 2, ["z"] = 6, ["name"] = "default:stone"}, {["x"] = 15, ["param2"] = 3, ["y"] = 2, ["param1"] = 15, ["z"] = 7, ["name"] = "xpanes:bar_flat"}, {["x"] = 15, ["param2"] = 3, ["y"] = 2, ["param1"] = 15, ["z"] = 8, ["name"] = "xpanes:bar_flat"}, {["x"] = 15, ["y"] = 2, ["z"] = 9, ["name"] = "default:stone"}, {["x"] = 15, ["param2"] = 3, ["y"] = 2, ["param1"] = 15, ["z"] = 10, ["name"] = "xpanes:bar_flat"}, {["x"] = 15, ["param2"] = 3, ["y"] = 2, ["param1"] = 15, ["z"] = 11, ["name"] = "xpanes:bar_flat"}, {["x"] = 15, ["y"] = 2, ["z"] = 12, ["name"] = "default:stone"}, {["x"] = 15, ["param2"] = 3, ["y"] = 2, ["param1"] = 15, ["z"] = 13, ["name"] = "xpanes:bar_flat"}, {["x"] = 15, ["param2"] = 3, ["y"] = 2, ["param1"] = 15, ["z"] = 14, ["name"] = "xpanes:bar_flat"}, {["x"] = 15, ["y"] = 2, ["z"] = 15, ["name"] = "default:stone"}, {["x"] = 15, ["y"] = 3, ["z"] = 0, ["name"] = "default:stone"}, {["x"] = 15, ["param2"] = 3, ["y"] = 3, ["param1"] = 15, ["z"] = 1, ["name"] = "xpanes:bar_flat"}, {["x"] = 15, ["param2"] = 3, ["y"] = 3, ["param1"] = 15, ["z"] = 2, ["name"] = "xpanes:bar_flat"}, {["x"] = 15, ["y"] = 3, ["z"] = 3, ["name"] = "default:stone"}, {["x"] = 15, ["param2"] = 3, ["y"] = 3, ["param1"] = 15, ["z"] = 4, ["name"] = "xpanes:bar_flat"}, {["x"] = 15, ["param2"] = 3, ["y"] = 3, ["param1"] = 15, ["z"] = 5, ["name"] = "xpanes:bar_flat"}, {["x"] = 15, ["y"] = 3, ["z"] = 6, ["name"] = "default:stone"}, {["x"] = 15, ["param2"] = 3, ["y"] = 3, ["param1"] = 15, ["z"] = 7, ["name"] = "xpanes:bar_flat"}, {["x"] = 15, ["param2"] = 3, ["y"] = 3, ["param1"] = 15, ["z"] = 8, ["name"] = "xpanes:bar_flat"}, {["x"] = 15, ["y"] = 3, ["z"] = 9, ["name"] = "default:stone"}, {["x"] = 15, ["param2"] = 3, ["y"] = 3, ["param1"] = 15, ["z"] = 10, ["name"] = "xpanes:bar_flat"}, {["x"] = 15, ["param2"] = 3, ["y"] = 3, ["param1"] = 15, ["z"] = 11, ["name"] = "xpanes:bar_flat"}, {["x"] = 15, ["y"] = 3, ["z"] = 12, ["name"] = "default:stone"}, {["x"] = 15, ["param2"] = 3, ["y"] = 3, ["param1"] = 15, ["z"] = 13, ["name"] = "xpanes:bar_flat"}, {["x"] = 15, ["param2"] = 3, ["y"] = 3, ["param1"] = 15, ["z"] = 14, ["name"] = "xpanes:bar_flat"}, {["x"] = 15, ["y"] = 3, ["z"] = 15, ["name"] = "default:stone"}, {["x"] = 15, ["y"] = 4, ["param1"] = 14, ["z"] = 0, ["name"] = "walls:cobble"}, {["x"] = 15, ["y"] = 4, ["param1"] = 14, ["z"] = 3, ["name"] = "walls:cobble"}, {["x"] = 15, ["y"] = 4, ["param1"] = 14, ["z"] = 6, ["name"] = "walls:cobble"}, {["x"] = 15, ["y"] = 4, ["param1"] = 14, ["z"] = 9, ["name"] = "walls:cobble"}, {["x"] = 15, ["y"] = 4, ["param1"] = 14, ["z"] = 12, ["name"] = "walls:cobble"}, {["x"] = 15, ["y"] = 4, ["param1"] = 14, ["z"] = 15, ["name"] = "walls:cobble"}, {["x"] = 15, ["y"] = 5, ["param1"] = 15, ["z"] = 0, ["name"] = "xpanes:bar_flat"}, {["x"] = 15, ["param2"] = 3, ["y"] = 5, ["param1"] = 15, ["z"] = 3, ["name"] = "xpanes:bar_flat"}, {["x"] = 15, ["param2"] = 3, ["y"] = 5, ["param1"] = 15, ["z"] = 6, ["name"] = "xpanes:bar_flat"}, {["x"] = 15, ["param2"] = 3, ["y"] = 5, ["param1"] = 15, ["z"] = 9, ["name"] = "xpanes:bar_flat"}, {["x"] = 15, ["param2"] = 3, ["y"] = 5, ["param1"] = 15, ["z"] = 12, ["name"] = "xpanes:bar_flat"}, {["x"] = 15, ["param2"] = 2, ["y"] = 5, ["param1"] = 15, ["z"] = 15, ["name"] = "xpanes:bar_flat"}}