5:return {{["x"] = 0, ["param2"] = 1, ["y"] = 0, ["param1"] = 78, ["z"] = 0, ["name"] = "default:aspen_leaves"}, {["x"] = 0, ["param2"] = 1, ["y"] = 0, ["param1"] = 94, ["z"] = 1, ["name"] = "stairs:slab_stone"}, {["x"] = 0, ["param2"] = 1, ["y"] = 0, ["param1"] = 110, ["z"] = 2, ["name"] = "stairs:slab_stone"}, {["x"] = 0, ["param2"] = 1, ["y"] = 0, ["param1"] = 126, ["z"] = 3, ["name"] = "stairs:slab_stone"}, {["x"] = 0, ["param2"] = 1, ["y"] = 0, ["param1"] = 110, ["z"] = 4, ["name"] = "stairs:slab_stone"}, {["x"] = 0, ["param2"] = 1, ["y"] = 0, ["param1"] = 94, ["z"] = 5, ["name"] = "stairs:slab_stone"}, {["x"] = 0, ["param2"] = 1, ["y"] = 0, ["param1"] = 110, ["z"] = 6, ["name"] = "stairs:slab_stone"}, {["x"] = 0, ["param2"] = 2, ["y"] = 0, ["param1"] = 126, ["z"] = 7, ["name"] = "stairs:slab_stone"}, {["x"] = 0, ["y"] = 0, ["param1"] = 110, ["z"] = 8, ["name"] = "stairs:slab_stone"}, {["x"] = 0, ["y"] = 0, ["param1"] = 94, ["z"] = 9, ["name"] = "stairs:slab_stone"}, {["x"] = 0, ["param2"] = 1, ["y"] = 0, ["param1"] = 78, ["z"] = 10, ["name"] = "default:aspen_leaves"}, {["x"] = 0, ["param2"] = 2, ["y"] = 5, ["param1"] = 207, ["z"] = 3, ["name"] = "default:torch_wall"}, {["x"] = 0, ["param2"] = 2, ["y"] = 5, ["param1"] = 207, ["z"] = 7, ["name"] = "default:torch_wall"}, {["x"] = 1, ["param2"] = 1, ["y"] = 0, ["param1"] = 62, ["z"] = 0, ["name"] = "default:aspen_leaves"}, {["x"] = 1, ["y"] = 0, ["z"] = 1, ["name"] = "default:brick"}, {["x"] = 1, ["y"] = 0, ["z"] = 2, ["name"] = "default:brick"}, {["x"] = 1, ["y"] = 0, ["z"] = 3, ["name"] = "default:brick"}, {["x"] = 1, ["y"] = 0, ["z"] = 4, ["name"] = "default:stone_block"}, {["x"] = 1, ["y"] = 0, ["z"] = 5, ["name"] = "default:stone_block"}, {["x"] = 1, ["y"] = 0, ["z"] = 6, ["name"] = "default:stone_block"}, {["x"] = 1, ["y"] = 0, ["z"] = 7, ["name"] = "default:brick"}, {["x"] = 1, ["y"] = 0, ["z"] = 8, ["name"] = "default:brick"}, {["x"] = 1, ["y"] = 0, ["z"] = 9, ["name"] = "default:brick"}, {["x"] = 1, ["param2"] = 1, ["y"] = 0, ["param1"] = 62, ["z"] = 10, ["name"] = "default:aspen_leaves"}, {["x"] = 1, ["y"] = 1, ["param1"] = 15, ["z"] = 1, ["name"] = "default:brick"}, {["x"] = 1, ["y"] = 1, ["param1"] = 13, ["z"] = 2, ["name"] = "default:brick"}, {["x"] = 1, ["y"] = 1, ["param1"] = 14, ["z"] = 3, ["name"] = "default:brick"}, {["x"] = 1, ["y"] = 1, ["z"] = 7, ["name"] = "default:brick"}, {["x"] = 1, ["y"] = 1, ["z"] = 8, ["name"] = "default:brick"}, {["x"] = 1, ["y"] = 1, ["z"] = 9, ["name"] = "default:brick"}, {["x"] = 1, ["y"] = 2, ["param1"] = 15, ["z"] = 1, ["name"] = "default:brick"}, {["x"] = 1, ["y"] = 2, ["param1"] = 14, ["z"] = 2, ["name"] = "default:brick"}, {["x"] = 1, ["y"] = 2, ["param1"] = 14, ["z"] = 3, ["name"] = "default:brick"}, {["x"] = 1, ["y"] = 2, ["z"] = 7, ["name"] = "default:brick"}, {["x"] = 1, ["y"] = 2, ["z"] = 8, ["name"] = "default:brick"}, {["x"] = 1, ["y"] = 2, ["z"] = 9, ["name"] = "default:brick"}, {["x"] = 1, ["y"] = 3, ["z"] = 1, ["name"] = "default:stonebrick"}, {["x"] = 1, ["y"] = 3, ["z"] = 2, ["name"] = "the_build_spawner:grey"}, {["x"] = 1, ["y"] = 3, ["param1"] = 14, ["z"] = 3, ["name"] = "default:brick"}, {["x"] = 1, ["y"] = 3, ["param1"] = 15, ["z"] = 7, ["name"] = "default:brick"}, {["x"] = 1, ["y"] = 3, ["z"] = 8, ["name"] = "the_build_spawner:grey"}, {["x"] = 1, ["y"] = 3, ["z"] = 9, ["name"] = "default:stonebrick"}, {["x"] = 1, ["y"] = 4, ["z"] = 1, ["name"] = "the_build_spawner:grey"}, {["x"] = 1, ["y"] = 4, ["z"] = 2, ["name"] = "the_build_spawner:grey"}, {["x"] = 1, ["y"] = 4, ["param1"] = 14, ["z"] = 3, ["name"] = "default:brick"}, {["x"] = 1, ["y"] = 4, ["param1"] = 15, ["z"] = 7, ["name"] = "default:brick"}, {["x"] = 1, ["y"] = 4, ["z"] = 8, ["name"] = "the_build_spawner:grey"}, {["x"] = 1, ["y"] = 4, ["z"] = 9, ["name"] = "the_build_spawner:grey"}, {["x"] = 1, ["y"] = 5, ["z"] = 1, ["name"] = "default:stonebrick"}, {["x"] = 1, ["y"] = 5, ["z"] = 2, ["name"] = "the_build_spawner:grey"}, {["x"] = 1, ["y"] = 5, ["param1"] = 14, ["z"] = 3, ["name"] = "default:brick"}, {["x"] = 1, ["param2"] = 22, ["y"] = 5, ["param1"] = 174, ["z"] = 4, ["name"] = "stairs:stair_brick"}, {["x"] = 1, ["param2"] = 20, ["y"] = 5, ["param1"] = 174, ["z"] = 6, ["name"] = "stairs:stair_brick"}, {["x"] = 1, ["y"] = 5, ["param1"] = 15, ["z"] = 7, ["name"] = "default:brick"}, {["x"] = 1, ["y"] = 5, ["z"] = 8, ["name"] = "the_build_spawner:grey"}, {["x"] = 1, ["y"] = 5, ["z"] = 9, ["name"] = "default:stonebrick"}, {["x"] = 1, ["y"] = 6, ["z"] = 1, ["name"] = "the_build_spawner:grey"}, {["x"] = 1, ["y"] = 6, ["z"] = 2, ["name"] = "the_build_spawner:grey"}, {["x"] = 1, ["y"] = 6, ["param1"] = 14, ["z"] = 3, ["name"] = "default:brick"}, {["x"] = 1, ["y"] = 6, ["param1"] = 15, ["z"] = 4, ["name"] = "default:brick"}, {["x"] = 1, ["y"] = 6, ["param1"] = 15, ["z"] = 5, ["name"] = "default:brick"}, {["x"] = 1, ["y"] = 6, ["param1"] = 15, ["z"] = 6, ["name"] = "default:brick"}, {["x"] = 1, ["y"] = 6, ["param1"] = 15, ["z"] = 7, ["name"] = "default:brick"}, {["x"] = 1, ["y"] = 6, ["z"] = 8, ["name"] = "the_build_spawner:grey"}, {["x"] = 1, ["y"] = 6, ["z"] = 9, ["name"] = "the_build_spawner:grey"}, {["x"] = 1, ["y"] = 7, ["z"] = 1, ["name"] = "default:stonebrick"}, {["x"] = 1, ["y"] = 7, ["param1"] = 14, ["z"] = 2, ["name"] = "the_build_spawner:grey"}, {["x"] = 1, ["y"] = 7, ["z"] = 3, ["name"] = "the_build_spawner:grey"}, {["x"] = 1, ["y"] = 7, ["param1"] = 14, ["z"] = 4, ["name"] = "default:brick"}, {["x"] = 1, ["y"] = 7, ["param1"] = 14, ["z"] = 5, ["name"] = "default:brick"}, {["x"] = 1, ["y"] = 7, ["param1"] = 14, ["z"] = 6, ["name"] = "default:brick"}, {["x"] = 1, ["y"] = 7, ["z"] = 7, ["name"] = "the_build_spawner:grey"}, {["x"] = 1, ["y"] = 7, ["param1"] = 14, ["z"] = 8, ["name"] = "the_build_spawner:grey"}, {["x"] = 1, ["y"] = 7, ["z"] = 9, ["name"] = "default:stonebrick"}, {["x"] = 1, ["meta"] = {["fields"] = {}, ["inventory"] = {}}, ["y"] = 8, ["param1"] = 188, ["z"] = 1, ["name"] = "the_build_spawner:grey"}, {["x"] = 1, ["meta"] = {["fields"] = {}, ["inventory"] = {}}, ["y"] = 8, ["param1"] = 188, ["z"] = 2, ["name"] = "the_build_spawner:grey"}, {["x"] = 1, ["meta"] = {["fields"] = {}, ["inventory"] = {}}, ["y"] = 8, ["param1"] = 188, ["z"] = 3, ["name"] = "the_build_spawner:grey"}, {["x"] = 1, ["meta"] = {["fields"] = {}, ["inventory"] = {}}, ["y"] = 8, ["param1"] = 188, ["z"] = 4, ["name"] = "the_build_spawner:grey"}, {["x"] = 1, ["meta"] = {["fields"] = {}, ["inventory"] = {}}, ["y"] = 8, ["param1"] = 147, ["z"] = 5, ["name"] = "default:brick"}, {["x"] = 1, ["meta"] = {["fields"] = {}, ["inventory"] = {}}, ["y"] = 8, ["param1"] = 188, ["z"] = 6, ["name"] = "the_build_spawner:grey"}, {["x"] = 1, ["meta"] = {["fields"] = {}, ["inventory"] = {}}, ["y"] = 8, ["param1"] = 188, ["z"] = 7, ["name"] = "the_build_spawner:grey"}, {["x"] = 1, ["meta"] = {["fields"] = {}, ["inventory"] = {}}, ["y"] = 8, ["param1"] = 188, ["z"] = 8, ["name"] = "the_build_spawner:grey"}, {["x"] = 1, ["meta"] = {["fields"] = {}, ["inventory"] = {}}, ["y"] = 8, ["param1"] = 188, ["z"] = 9, ["name"] = "the_build_spawner:grey"}, {["x"] = 1, ["meta"] = {["fields"] = {}, ["inventory"] = {}}, ["y"] = 9, ["param1"] = 188, ["z"] = 1, ["name"] = "the_build_spawner:grey"}, {["x"] = 1, ["meta"] = {["fields"] = {}, ["inventory"] = {}}, ["y"] = 9, ["param1"] = 188, ["z"] = 2, ["name"] = "the_build_spawner:grey"}, {["x"] = 1, ["meta"] = {["fields"] = {}, ["inventory"] = {}}, ["y"] = 9, ["param1"] = 188, ["z"] = 3, ["name"] = "the_build_spawner:grey"}, {["x"] = 1, ["meta"] = {["fields"] = {}, ["inventory"] = {}}, ["y"] = 9, ["param1"] = 188, ["z"] = 4, ["name"] = "the_build_spawner:grey"}, {["x"] = 1, ["meta"] = {["fields"] = {}, ["inventory"] = {}}, ["y"] = 9, ["param1"] = 188, ["z"] = 5, ["name"] = "the_build_spawner:grey"}, {["x"] = 1, ["meta"] = {["fields"] = {}, ["inventory"] = {}}, ["y"] = 9, ["param1"] = 188, ["z"] = 6, ["name"] = "the_build_spawner:grey"}, {["x"] = 1, ["meta"] = {["fields"] = {}, ["inventory"] = {}}, ["y"] = 9, ["param1"] = 188, ["z"] = 7, ["name"] = "the_build_spawner:grey"}, {["x"] = 1, ["meta"] = {["fields"] = {}, ["inventory"] = {}}, ["y"] = 9, ["param1"] = 188, ["z"] = 8, ["name"] = "the_build_spawner:grey"}, {["x"] = 1, ["meta"] = {["fields"] = {}, ["inventory"] = {}}, ["y"] = 9, ["param1"] = 188, ["z"] = 9, ["name"] = "the_build_spawner:grey"}, {["x"] = 1, ["y"] = 10, ["param1"] = 78, ["z"] = 1, ["name"] = "stairs:slab_acacia_wood"}, {["x"] = 1, ["meta"] = {["fields"] = {}, ["inventory"] = {}}, ["y"] = 10, ["param1"] = 188, ["z"] = 2, ["name"] = "the_build_spawner:grey"}, {["x"] = 1, ["meta"] = {["fields"] = {}, ["inventory"] = {}}, ["y"] = 10, ["param1"] = 188, ["z"] = 3, ["name"] = "the_build_spawner:grey"}, {["x"] = 1, ["meta"] = {["fields"] = {}, ["inventory"] = {}}, ["y"] = 10, ["param1"] = 188, ["z"] = 4, ["name"] = "the_build_spawner:grey"}, {["x"] = 1, ["param2"] = 3, ["y"] = 10, ["param1"] = 78, ["z"] = 5, ["name"] = "xpanes:pane_flat"}, {["x"] = 1, ["meta"] = {["fields"] = {}, ["inventory"] = {}}, ["y"] = 10, ["param1"] = 188, ["z"] = 6, ["name"] = "the_build_spawner:grey"}, {["x"] = 1, ["meta"] = {["fields"] = {}, ["inventory"] = {}}, ["y"] = 10, ["param1"] = 188, ["z"] = 7, ["name"] = "the_build_spawner:grey"}, {["x"] = 1, ["meta"] = {["fields"] = {}, ["inventory"] = {}}, ["y"] = 10, ["param1"] = 188, ["z"] = 8, ["name"] = "the_build_spawner:grey"}, {["x"] = 1, ["param2"] = 3, ["y"] = 10, ["param1"] = 78, ["z"] = 9, ["name"] = "stairs:slab_acacia_wood"}, {["x"] = 1, ["y"] = 11, ["param1"] = 78, ["z"] = 2, ["name"] = "stairs:slab_acacia_wood"}, {["x"] = 1, ["meta"] = {["fields"] = {}, ["inventory"] = {}}, ["y"] = 11, ["param1"] = 188, ["z"] = 3, ["name"] = "the_build_spawner:grey"}, {["x"] = 1, ["meta"] = {["fields"] = {}, ["inventory"] = {}}, ["y"] = 11, ["param1"] = 188, ["z"] = 4, ["name"] = "the_build_spawner:grey"}, {["x"] = 1, ["param2"] = 3, ["y"] = 11, ["param1"] = 62, ["z"] = 5, ["name"] = "xpanes:pane_flat"}, {["x"] = 1, ["meta"] = {["fields"] = {}, ["inventory"] = {}}, ["y"] = 11, ["param1"] = 188, ["z"] = 6, ["name"] = "the_build_spawner:grey"}, {["x"] = 1, ["meta"] = {["fields"] = {}, ["inventory"] = {}}, ["y"] = 11, ["param1"] = 188, ["z"] = 7, ["name"] = "the_build_spawner:grey"}, {["x"] = 1, ["param2"] = 3, ["y"] = 11, ["param1"] = 78, ["z"] = 8, ["name"] = "stairs:slab_acacia_wood"}, {["x"] = 1, ["y"] = 12, ["param1"] = 78, ["z"] = 3, ["name"] = "stairs:slab_acacia_wood"}, {["x"] = 1, ["meta"] = {["fields"] = {}, ["inventory"] = {}}, ["y"] = 12, ["param1"] = 188, ["z"] = 4, ["name"] = "the_build_spawner:grey"}, {["x"] = 1, ["meta"] = {["fields"] = {}, ["inventory"] = {}}, ["y"] = 12, ["param1"] = 188, ["z"] = 5, ["name"] = "the_build_spawner:grey"}, {["x"] = 1, ["meta"] = {["fields"] = {}, ["inventory"] = {}}, ["y"] = 12, ["param1"] = 188, ["z"] = 6, ["name"] = "the_build_spawner:grey"}, {["x"] = 1, ["param2"] = 2, ["y"] = 12, ["param1"] = 78, ["z"] = 7, ["name"] = "stairs:slab_acacia_wood"}, {["x"] = 1, ["y"] = 13, ["param1"] = 46, ["z"] = 4, ["name"] = "stairs:slab_acacia_wood"}, {["x"] = 1, ["meta"] = {["fields"] = {}, ["inventory"] = {}}, ["y"] = 13, ["param1"] = 188, ["z"] = 5, ["name"] = "the_build_spawner:grey"}, {["x"] = 1, ["param2"] = 2, ["y"] = 13, ["param1"] = 46, ["z"] = 6, ["name"] = "stairs:slab_acacia_wood"}, {["x"] = 1, ["param2"] = 2, ["y"] = 14, ["param1"] = 14, ["z"] = 5, ["name"] = "stairs:slab_acacia_wood"}, {["x"] = 2, ["param2"] = 1, ["y"] = 0, ["param1"] = 62, ["z"] = 0, ["name"] = "default:aspen_leaves"}, {["x"] = 2, ["y"] = 0, ["z"] = 1, ["name"] = "default:brick"}, {["x"] = 2, ["y"] = 0, ["z"] = 2, ["name"] = "default:stone_block"}, {["x"] = 2, ["y"] = 0, ["z"] = 3, ["name"] = "default:stone_block"}, {["x"] = 2, ["y"] = 0, ["z"] = 4, ["name"] = "default:stone_block"}, {["x"] = 2, ["y"] = 0, ["z"] = 5, ["name"] = "default:stone_block"}, {["x"] = 2, ["y"] = 0, ["z"] = 6, ["name"] = "default:stone_block"}, {["x"] = 2, ["y"] = 0, ["z"] = 7, ["name"] = "default:stone_block"}, {["x"] = 2, ["y"] = 0, ["z"] = 8, ["name"] = "default:stone_block"}, {["x"] = 2, ["y"] = 0, ["z"] = 9, ["name"] = "default:brick"}, {["x"] = 2, ["param2"] = 1, ["y"] = 0, ["param1"] = 62, ["z"] = 10, ["name"] = "default:aspen_leaves"}, {["x"] = 2, ["y"] = 1, ["param1"] = 15, ["z"] = 1, ["name"] = "default:brick"}, {["x"] = 2, ["param2"] = 12, ["y"] = 1, ["param1"] = 141, ["z"] = 4, ["name"] = "stairs:slab_acacia_wood"}, {["x"] = 2, ["meta"] = {["fields"] = {["state"] = "0"}, ["inventory"] = {}}, ["param2"] = 1, ["y"] = 1, ["param1"] = 126, ["z"] = 5, ["name"] = "doors:door_wood_a"}, {["x"] = 2, ["param2"] = 12, ["y"] = 1, ["param1"] = 141, ["z"] = 6, ["name"] = "stairs:slab_acacia_wood"}, {["x"] = 2, ["y"] = 1, ["param1"] = 15, ["z"] = 9, ["name"] = "default:brick"}, {["x"] = 2, ["y"] = 2, ["param1"] = 15, ["z"] = 1, ["name"] = "default:brick"}, {["x"] = 2, ["param2"] = 12, ["y"] = 2, ["param1"] = 157, ["z"] = 4, ["name"] = "stairs:slab_acacia_wood"}, {["x"] = 2, ["param2"] = 1, ["y"] = 2, ["param1"] = 141, ["z"] = 5, ["name"] = "doors:hidden"}, {["x"] = 2, ["param2"] = 12, ["y"] = 2, ["param1"] = 157, ["z"] = 6, ["name"] = "stairs:slab_acacia_wood"}, {["x"] = 2, ["y"] = 2, ["param1"] = 15, ["z"] = 9, ["name"] = "default:brick"}, {["x"] = 2, ["y"] = 3, ["param1"] = 15, ["z"] = 1, ["name"] = "the_build_spawner:grey"}, {["x"] = 2, ["param2"] = 5, ["y"] = 3, ["param1"] = 204, ["z"] = 2, ["name"] = "default:torch_wall"}, {["x"] = 2, ["param2"] = 12, ["y"] = 3, ["param1"] = 173, ["z"] = 4, ["name"] = "stairs:slab_acacia_wood"}, {["x"] = 2, ["param2"] = 12, ["y"] = 3, ["param1"] = 157, ["z"] = 5, ["name"] = "stairs:slab_acacia_wood"}, {["x"] = 2, ["param2"] = 12, ["y"] = 3, ["param1"] = 173, ["z"] = 6, ["name"] = "stairs:slab_acacia_wood"}, {["x"] = 2, ["param2"] = 4, ["y"] = 3, ["param1"] = 204, ["z"] = 8, ["name"] = "default:torch_wall"}, {["x"] = 2, ["y"] = 3, ["param1"] = 15, ["z"] = 9, ["name"] = "the_build_spawner:grey"}, {["x"] = 2, ["y"] = 4, ["param1"] = 15, ["z"] = 1, ["name"] = "the_build_spawner:grey"}, {["x"] = 2, ["param2"] = 12, ["y"] = 4, ["param1"] = 157, ["z"] = 4, ["name"] = "stairs:slab_acacia_wood"}, {["x"] = 2, ["param2"] = 12, ["y"] = 4, ["param1"] = 141, ["z"] = 5, ["name"] = "stairs:slab_acacia_wood"}, {["x"] = 2, ["param2"] = 12, ["y"] = 4, ["param1"] = 157, ["z"] = 6, ["name"] = "stairs:slab_acacia_wood"}, {["x"] = 2, ["y"] = 4, ["param1"] = 15, ["z"] = 9, ["name"] = "the_build_spawner:grey"}, {["x"] = 2, ["y"] = 5, ["param1"] = 15, ["z"] = 1, ["name"] = "the_build_spawner:grey"}, {["x"] = 2, ["param2"] = 12, ["y"] = 5, ["param1"] = 157, ["z"] = 4, ["name"] = "stairs:slab_acacia_wood"}, {["x"] = 2, ["param2"] = 12, ["y"] = 5, ["param1"] = 141, ["z"] = 5, ["name"] = "stairs:slab_acacia_wood"}, {["x"] = 2, ["param2"] = 12, ["y"] = 5, ["param1"] = 157, ["z"] = 6, ["name"] = "stairs:slab_acacia_wood"}, {["x"] = 2, ["y"] = 5, ["param1"] = 15, ["z"] = 9, ["name"] = "the_build_spawner:grey"}, {["x"] = 2, ["y"] = 6, ["param1"] = 15, ["z"] = 1, ["name"] = "the_build_spawner:grey"}, {["x"] = 2, ["y"] = 6, ["param1"] = 15, ["z"] = 9, ["name"] = "the_build_spawner:grey"}, {["x"] = 2, ["y"] = 7, ["param1"] = 14, ["z"] = 1, ["name"] = "the_build_spawner:grey"}, {["x"] = 2, ["y"] = 7, ["param1"] = 14, ["z"] = 9, ["name"] = "the_build_spawner:grey"}, {["x"] = 2, ["meta"] = {["fields"] = {}, ["inventory"] = {}}, ["y"] = 8, ["param1"] = 110, ["z"] = 1, ["name"] = "stairs:stair_acacia_wood"}, {["x"] = 2, ["meta"] = {["fields"] = {}, ["inventory"] = {}}, ["param2"] = 2, ["y"] = 8, ["param1"] = 110, ["z"] = 9, ["name"] = "stairs:stair_acacia_wood"}, {["x"] = 2, ["meta"] = {["fields"] = {}, ["inventory"] = {}}, ["y"] = 9, ["param1"] = 110, ["z"] = 2, ["name"] = "stairs:stair_acacia_wood"}, {["x"] = 2, ["meta"] = {["fields"] = {}, ["inventory"] = {}}, ["param2"] = 2, ["y"] = 9, ["param1"] = 110, ["z"] = 8, ["name"] = "stairs:stair_acacia_wood"}, {["x"] = 2, ["meta"] = {["fields"] = {}, ["inventory"] = {}}, ["y"] = 10, ["param1"] = 78, ["z"] = 3, ["name"] = "stairs:stair_acacia_wood"}, {["x"] = 2, ["meta"] = {["fields"] = {}, ["inventory"] = {}}, ["param2"] = 2, ["y"] = 10, ["param1"] = 78, ["z"] = 7, ["name"] = "stairs:stair_acacia_wood"}, {["x"] = 2, ["y"] = 11, ["param1"] = 62, ["z"] = 4, ["name"] = "stairs:stair_acacia_wood"}, {["x"] = 2, ["param2"] = 2, ["y"] = 11, ["param1"] = 62, ["z"] = 6, ["name"] = "stairs:stair_acacia_wood"}, {["x"] = 2, ["param2"] = 3, ["y"] = 12, ["param1"] = 30, ["z"] = 5, ["name"] = "stairs:slab_acacia_wood"}, {["x"] = 3, ["param2"] = 1, ["y"] = 0, ["param1"] = 78, ["z"] = 0, ["name"] = "default:aspen_leaves"}, {["x"] = 3, ["y"] = 0, ["z"] = 1, ["name"] = "default:brick"}, {["x"] = 3, ["y"] = 0, ["z"] = 2, ["name"] = "default:stone_block"}, {["x"] = 3, ["y"] = 0, ["z"] = 3, ["name"] = "default:stone_block"}, {["x"] = 3, ["y"] = 0, ["z"] = 4, ["name"] = "default:stone_block"}, {["x"] = 3, ["y"] = 0, ["z"] = 5, ["name"] = "default:stone_block"}, {["x"] = 3, ["y"] = 0, ["z"] = 6, ["name"] = "default:stone_block"}, {["x"] = 3, ["y"] = 0, ["z"] = 7, ["name"] = "default:stone_block"}, {["x"] = 3, ["y"] = 0, ["z"] = 8, ["name"] = "default:stone_block"}, {["x"] = 3, ["y"] = 0, ["z"] = 9, ["name"] = "default:brick"}, {["x"] = 3, ["param2"] = 1, ["y"] = 0, ["param1"] = 78, ["z"] = 10, ["name"] = "default:aspen_leaves"}, {["x"] = 3, ["y"] = 1, ["param1"] = 15, ["z"] = 1, ["name"] = "default:brick"}, {["x"] = 3, ["param2"] = 3, ["y"] = 1, ["param1"] = 154, ["z"] = 2, ["name"] = "stairs:stair_acacia_wood"}, {["x"] = 3, ["param2"] = 3, ["y"] = 1, ["param1"] = 139, ["z"] = 3, ["name"] = "stairs:stair_acacia_wood"}, {["x"] = 3, ["param2"] = 3, ["y"] = 1, ["param1"] = 124, ["z"] = 4, ["name"] = "stairs:stair_acacia_wood"}, {["x"] = 3, ["param2"] = 3, ["y"] = 1, ["param1"] = 124, ["z"] = 6, ["name"] = "stairs:stair_acacia_wood"}, {["x"] = 3, ["param2"] = 3, ["y"] = 1, ["param1"] = 139, ["z"] = 7, ["name"] = "stairs:stair_acacia_wood"}, {["x"] = 3, ["param2"] = 3, ["y"] = 1, ["param1"] = 154, ["z"] = 8, ["name"] = "stairs:stair_acacia_wood"}, {["x"] = 3, ["y"] = 1, ["param1"] = 15, ["z"] = 9, ["name"] = "default:brick"}, {["x"] = 3, ["y"] = 2, ["param1"] = 15, ["z"] = 1, ["name"] = "default:brick"}, {["x"] = 3, ["y"] = 2, ["param1"] = 15, ["z"] = 9, ["name"] = "default:brick"}, {["x"] = 3, ["y"] = 3, ["param1"] = 15, ["z"] = 1, ["name"] = "the_build_spawner:grey"}, {["x"] = 3, ["y"] = 3, ["param1"] = 15, ["z"] = 9, ["name"] = "the_build_spawner:grey"}, {["x"] = 3, ["y"] = 4, ["param1"] = 158, ["z"] = 1, ["name"] = "default:glass"}, {["x"] = 3, ["y"] = 4, ["param1"] = 158, ["z"] = 9, ["name"] = "default:glass"}, {["x"] = 3, ["y"] = 5, ["param1"] = 142, ["z"] = 1, ["name"] = "default:glass"}, {["x"] = 3, ["y"] = 5, ["param1"] = 142, ["z"] = 9, ["name"] = "default:glass"}, {["x"] = 3, ["y"] = 6, ["param1"] = 126, ["z"] = 1, ["name"] = "default:glass"}, {["x"] = 3, ["y"] = 6, ["param1"] = 126, ["z"] = 9, ["name"] = "default:glass"}, {["x"] = 3, ["y"] = 7, ["param1"] = 14, ["z"] = 1, ["name"] = "the_build_spawner:grey"}, {["x"] = 3, ["y"] = 7, ["param1"] = 14, ["z"] = 9, ["name"] = "the_build_spawner:grey"}, {["x"] = 3, ["meta"] = {["fields"] = {}, ["inventory"] = {}}, ["y"] = 8, ["param1"] = 94, ["z"] = 1, ["name"] = "stairs:stair_acacia_wood"}, {["x"] = 3, ["meta"] = {["fields"] = {}, ["inventory"] = {}}, ["param2"] = 2, ["y"] = 8, ["param1"] = 94, ["z"] = 9, ["name"] = "stairs:stair_acacia_wood"}, {["x"] = 3, ["meta"] = {["fields"] = {}, ["inventory"] = {}}, ["y"] = 9, ["param1"] = 94, ["z"] = 2, ["name"] = "stairs:stair_acacia_wood"}, {["x"] = 3, ["meta"] = {["fields"] = {}, ["inventory"] = {}}, ["param2"] = 2, ["y"] = 9, ["param1"] = 94, ["z"] = 8, ["name"] = "stairs:stair_acacia_wood"}, {["x"] = 3, ["meta"] = {["fields"] = {}, ["inventory"] = {}}, ["y"] = 10, ["param1"] = 62, ["z"] = 3, ["name"] = "stairs:stair_acacia_wood"}, {["x"] = 3, ["meta"] = {["fields"] = {}, ["inventory"] = {}}, ["param2"] = 2, ["y"] = 10, ["param1"] = 62, ["z"] = 7, ["name"] = "stairs:stair_acacia_wood"}, {["x"] = 3, ["y"] = 11, ["param1"] = 46, ["z"] = 4, ["name"] = "stairs:stair_acacia_wood"}, {["x"] = 3, ["param2"] = 2, ["y"] = 11, ["param1"] = 46, ["z"] = 6, ["name"] = "stairs:stair_acacia_wood"}, {["x"] = 3, ["param2"] = 3, ["y"] = 12, ["param1"] = 14, ["z"] = 5, ["name"] = "stairs:slab_acacia_wood"}, {["x"] = 4, ["param2"] = 1, ["y"] = 0, ["param1"] = 62, ["z"] = 0, ["name"] = "default:aspen_leaves"}, {["x"] = 4, ["y"] = 0, ["z"] = 1, ["name"] = "default:brick"}, {["x"] = 4, ["y"] = 0, ["z"] = 2, ["name"] = "default:stone_block"}, {["x"] = 4, ["y"] = 0, ["z"] = 3, ["name"] = "default:stone_block"}, {["x"] = 4, ["y"] = 0, ["z"] = 4, ["name"] = "default:stone_block"}, {["x"] = 4, ["y"] = 0, ["z"] = 5, ["name"] = "default:stone_block"}, {["x"] = 4, ["y"] = 0, ["z"] = 6, ["name"] = "default:stone_block"}, {["x"] = 4, ["y"] = 0, ["z"] = 7, ["name"] = "default:stone_block"}, {["x"] = 4, ["y"] = 0, ["z"] = 8, ["name"] = "default:stone_block"}, {["x"] = 4, ["y"] = 0, ["z"] = 9, ["name"] = "default:brick"}, {["x"] = 4, ["param2"] = 1, ["y"] = 0, ["param1"] = 62, ["z"] = 10, ["name"] = "default:aspen_leaves"}, {["x"] = 4, ["y"] = 1, ["param1"] = 15, ["z"] = 1, ["name"] = "default:brick"}, {["x"] = 4, ["y"] = 1, ["param1"] = 15, ["z"] = 9, ["name"] = "default:brick"}, {["x"] = 4, ["y"] = 2, ["param1"] = 15, ["z"] = 1, ["name"] = "default:brick"}, {["x"] = 4, ["y"] = 2, ["param1"] = 15, ["z"] = 9, ["name"] = "default:brick"}, {["x"] = 4, ["y"] = 3, ["param1"] = 15, ["z"] = 1, ["name"] = "the_build_spawner:grey"}, {["x"] = 4, ["param2"] = 5, ["y"] = 3, ["param1"] = 204, ["z"] = 2, ["name"] = "default:torch_wall"}, {["x"] = 4, ["param2"] = 4, ["y"] = 3, ["param1"] = 204, ["z"] = 8, ["name"] = "default:torch_wall"}, {["x"] = 4, ["y"] = 3, ["param1"] = 15, ["z"] = 9, ["name"] = "the_build_spawner:grey"}, {["x"] = 4, ["y"] = 4, ["param1"] = 15, ["z"] = 1, ["name"] = "the_build_spawner:grey"}, {["x"] = 4, ["y"] = 4, ["param1"] = 15, ["z"] = 9, ["name"] = "the_build_spawner:grey"}, {["x"] = 4, ["y"] = 5, ["param1"] = 15, ["z"] = 1, ["name"] = "the_build_spawner:grey"}, {["x"] = 4, ["y"] = 5, ["param1"] = 15, ["z"] = 9, ["name"] = "the_build_spawner:grey"}, {["x"] = 4, ["y"] = 6, ["param1"] = 15, ["z"] = 1, ["name"] = "the_build_spawner:grey"}, {["x"] = 4, ["y"] = 6, ["param1"] = 15, ["z"] = 9, ["name"] = "the_build_spawner:grey"}, {["x"] = 4, ["y"] = 7, ["param1"] = 14, ["z"] = 1, ["name"] = "the_build_spawner:grey"}, {["x"] = 4, ["y"] = 7, ["param1"] = 14, ["z"] = 9, ["name"] = "the_build_spawner:grey"}, {["x"] = 4, ["meta"] = {["fields"] = {}, ["inventory"] = {}}, ["y"] = 8, ["param1"] = 110, ["z"] = 1, ["name"] = "stairs:stair_acacia_wood"}, {["x"] = 4, ["meta"] = {["fields"] = {}, ["inventory"] = {}}, ["param2"] = 2, ["y"] = 8, ["param1"] = 110, ["z"] = 9, ["name"] = "stairs:stair_acacia_wood"}, {["x"] = 4, ["meta"] = {["fields"] = {}, ["inventory"] = {}}, ["y"] = 9, ["param1"] = 110, ["z"] = 2, ["name"] = "stairs:stair_acacia_wood"}, {["x"] = 4, ["meta"] = {["fields"] = {}, ["inventory"] = {}}, ["param2"] = 2, ["y"] = 9, ["param1"] = 110, ["z"] = 8, ["name"] = "stairs:stair_acacia_wood"}, {["x"] = 4, ["meta"] = {["fields"] = {}, ["inventory"] = {}}, ["y"] = 10, ["param1"] = 78, ["z"] = 3, ["name"] = "stairs:stair_acacia_wood"}, {["x"] = 4, ["meta"] = {["fields"] = {}, ["inventory"] = {}}, ["param2"] = 2, ["y"] = 10, ["param1"] = 78, ["z"] = 7, ["name"] = "stairs:stair_acacia_wood"}, {["x"] = 4, ["y"] = 11, ["param1"] = 46, ["z"] = 4, ["name"] = "stairs:stair_acacia_wood"}, {["x"] = 4, ["param2"] = 2, ["y"] = 11, ["param1"] = 46, ["z"] = 6, ["name"] = "stairs:stair_acacia_wood"}, {["x"] = 4, ["param2"] = 3, ["y"] = 12, ["param1"] = 14, ["z"] = 5, ["name"] = "stairs:slab_acacia_wood"}, {["x"] = 5, ["param2"] = 1, ["y"] = 0, ["param1"] = 78, ["z"] = 0, ["name"] = "default:aspen_leaves"}, {["x"] = 5, ["y"] = 0, ["z"] = 1, ["name"] = "default:brick"}, {["x"] = 5, ["y"] = 0, ["z"] = 2, ["name"] = "default:stone_block"}, {["x"] = 5, ["y"] = 0, ["z"] = 3, ["name"] = "default:stone_block"}, {["x"] = 5, ["y"] = 0, ["z"] = 4, ["name"] = "default:stone_block"}, {["x"] = 5, ["y"] = 0, ["z"] = 5, ["name"] = "default:stone_block"}, {["x"] = 5, ["y"] = 0, ["z"] = 6, ["name"] = "default:stone_block"}, {["x"] = 5, ["y"] = 0, ["z"] = 7, ["name"] = "default:stone_block"}, {["x"] = 5, ["y"] = 0, ["z"] = 8, ["name"] = "default:stone_block"}, {["x"] = 5, ["y"] = 0, ["z"] = 9, ["name"] = "default:brick"}, {["x"] = 5, ["param2"] = 1, ["y"] = 0, ["param1"] = 78, ["z"] = 10, ["name"] = "default:aspen_leaves"}, {["x"] = 5, ["y"] = 1, ["param1"] = 15, ["z"] = 1, ["name"] = "default:brick"}, {["x"] = 5, ["param2"] = 3, ["y"] = 1, ["param1"] = 154, ["z"] = 2, ["name"] = "stairs:stair_acacia_wood"}, {["x"] = 5, ["param2"] = 3, ["y"] = 1, ["param1"] = 137, ["z"] = 3, ["name"] = "stairs:stair_acacia_wood"}, {["x"] = 5, ["param2"] = 3, ["y"] = 1, ["param1"] = 122, ["z"] = 4, ["name"] = "stairs:stair_acacia_wood"}, {["x"] = 5, ["param2"] = 3, ["y"] = 1, ["param1"] = 122, ["z"] = 6, ["name"] = "stairs:stair_acacia_wood"}, {["x"] = 5, ["param2"] = 3, ["y"] = 1, ["param1"] = 137, ["z"] = 7, ["name"] = "stairs:stair_acacia_wood"}, {["x"] = 5, ["param2"] = 3, ["y"] = 1, ["param1"] = 154, ["z"] = 8, ["name"] = "stairs:stair_acacia_wood"}, {["x"] = 5, ["y"] = 1, ["param1"] = 15, ["z"] = 9, ["name"] = "default:brick"}, {["x"] = 5, ["y"] = 2, ["param1"] = 15, ["z"] = 1, ["name"] = "default:brick"}, {["x"] = 5, ["y"] = 2, ["param1"] = 15, ["z"] = 9, ["name"] = "default:brick"}, {["x"] = 5, ["y"] = 3, ["param1"] = 15, ["z"] = 1, ["name"] = "the_build_spawner:grey"}, {["x"] = 5, ["y"] = 3, ["param1"] = 15, ["z"] = 9, ["name"] = "the_build_spawner:grey"}, {["x"] = 5, ["y"] = 4, ["param1"] = 158, ["z"] = 1, ["name"] = "default:glass"}, {["x"] = 5, ["y"] = 4, ["param1"] = 158, ["z"] = 9, ["name"] = "default:glass"}, {["x"] = 5, ["y"] = 5, ["param1"] = 142, ["z"] = 1, ["name"] = "default:glass"}, {["x"] = 5, ["y"] = 5, ["param1"] = 142, ["z"] = 9, ["name"] = "default:glass"}, {["x"] = 5, ["y"] = 6, ["param1"] = 126, ["z"] = 1, ["name"] = "default:glass"}, {["x"] = 5, ["y"] = 6, ["param1"] = 126, ["z"] = 9, ["name"] = "default:glass"}, {["x"] = 5, ["y"] = 7, ["param1"] = 14, ["z"] = 1, ["name"] = "the_build_spawner:grey"}, {["x"] = 5, ["y"] = 7, ["param1"] = 14, ["z"] = 9, ["name"] = "the_build_spawner:grey"}, {["x"] = 5, ["meta"] = {["fields"] = {}, ["inventory"] = {}}, ["y"] = 8, ["param1"] = 94, ["z"] = 1, ["name"] = "stairs:stair_acacia_wood"}, {["x"] = 5, ["meta"] = {["fields"] = {}, ["inventory"] = {}}, ["param2"] = 2, ["y"] = 8, ["param1"] = 94, ["z"] = 9, ["name"] = "stairs:stair_acacia_wood"}, {["x"] = 5, ["meta"] = {["fields"] = {}, ["inventory"] = {}}, ["y"] = 9, ["param1"] = 94, ["z"] = 2, ["name"] = "stairs:stair_acacia_wood"}, {["x"] = 5, ["meta"] = {["fields"] = {}, ["inventory"] = {}}, ["param2"] = 2, ["y"] = 9, ["param1"] = 94, ["z"] = 8, ["name"] = "stairs:stair_acacia_wood"}, {["x"] = 5, ["meta"] = {["fields"] = {}, ["inventory"] = {}}, ["y"] = 10, ["param1"] = 62, ["z"] = 3, ["name"] = "stairs:stair_acacia_wood"}, {["x"] = 5, ["y"] = 10, ["z"] = 4, ["name"] = "the_build_spawner:grey"}, {["x"] = 5, ["y"] = 10, ["z"] = 5, ["name"] = "the_build_spawner:grey"}, {["x"] = 5, ["y"] = 10, ["z"] = 6, ["name"] = "the_build_spawner:grey"}, {["x"] = 5, ["meta"] = {["fields"] = {}, ["inventory"] = {}}, ["param2"] = 2, ["y"] = 10, ["param1"] = 62, ["z"] = 7, ["name"] = "stairs:stair_acacia_wood"}, {["x"] = 5, ["y"] = 11, ["z"] = 4, ["name"] = "the_build_spawner:grey"}, {["x"] = 5, ["y"] = 11, ["z"] = 5, ["name"] = "the_build_spawner:grey"}, {["x"] = 5, ["y"] = 11, ["z"] = 6, ["name"] = "the_build_spawner:grey"}, {["x"] = 5, ["y"] = 12, ["z"] = 4, ["name"] = "the_build_spawner:grey"}, {["x"] = 5, ["y"] = 12, ["z"] = 5, ["name"] = "the_build_spawner:grey"}, {["x"] = 5, ["y"] = 12, ["z"] = 6, ["name"] = "the_build_spawner:grey"}, {["x"] = 5, ["y"] = 13, ["z"] = 4, ["name"] = "the_build_spawner:grey"}, {["x"] = 5, ["y"] = 13, ["z"] = 6, ["name"] = "the_build_spawner:grey"}, {["x"] = 5, ["y"] = 14, ["z"] = 4, ["name"] = "the_build_spawner:grey"}, {["x"] = 5, ["y"] = 14, ["z"] = 5, ["name"] = "the_build_spawner:grey"}, {["x"] = 5, ["y"] = 14, ["z"] = 6, ["name"] = "the_build_spawner:grey"}, {["x"] = 5, ["param2"] = 1, ["y"] = 15, ["param1"] = 14, ["z"] = 4, ["name"] = "stairs:stair_outer_acacia_wood"}, {["x"] = 5, ["param2"] = 1, ["y"] = 15, ["param1"] = 14, ["z"] = 5, ["name"] = "stairs:stair_acacia_wood"}, {["x"] = 5, ["param2"] = 2, ["y"] = 15, ["param1"] = 14, ["z"] = 6, ["name"] = "stairs:stair_outer_acacia_wood"}, {["x"] = 6, ["param2"] = 1, ["y"] = 0, ["param1"] = 62, ["z"] = 0, ["name"] = "default:aspen_leaves"}, {["x"] = 6, ["y"] = 0, ["z"] = 1, ["name"] = "default:brick"}, {["x"] = 6, ["y"] = 0, ["z"] = 2, ["name"] = "default:stone_block"}, {["x"] = 6, ["y"] = 0, ["z"] = 3, ["name"] = "default:stone_block"}, {["x"] = 6, ["y"] = 0, ["z"] = 4, ["name"] = "default:stone_block"}, {["x"] = 6, ["y"] = 0, ["z"] = 5, ["name"] = "default:stone_block"}, {["x"] = 6, ["y"] = 0, ["z"] = 6, ["name"] = "default:stone_block"}, {["x"] = 6, ["y"] = 0, ["z"] = 7, ["name"] = "default:stone_block"}, {["x"] = 6, ["y"] = 0, ["z"] = 8, ["name"] = "default:stone_block"}, {["x"] = 6, ["y"] = 0, ["z"] = 9, ["name"] = "default:brick"}, {["x"] = 6, ["param2"] = 1, ["y"] = 0, ["param1"] = 62, ["z"] = 10, ["name"] = "default:aspen_leaves"}, {["x"] = 6, ["y"] = 1, ["param1"] = 15, ["z"] = 1, ["name"] = "default:brick"}, {["x"] = 6, ["y"] = 1, ["param1"] = 15, ["z"] = 9, ["name"] = "default:brick"}, {["x"] = 6, ["y"] = 2, ["param1"] = 15, ["z"] = 1, ["name"] = "default:brick"}, {["x"] = 6, ["y"] = 2, ["param1"] = 15, ["z"] = 9, ["name"] = "default:brick"}, {["x"] = 6, ["y"] = 3, ["param1"] = 15, ["z"] = 1, ["name"] = "the_build_spawner:grey"}, {["x"] = 6, ["param2"] = 5, ["y"] = 3, ["param1"] = 204, ["z"] = 2, ["name"] = "default:torch_wall"}, {["x"] = 6, ["param2"] = 4, ["y"] = 3, ["param1"] = 204, ["z"] = 8, ["name"] = "default:torch_wall"}, {["x"] = 6, ["y"] = 3, ["param1"] = 15, ["z"] = 9, ["name"] = "the_build_spawner:grey"}, {["x"] = 6, ["y"] = 4, ["param1"] = 15, ["z"] = 1, ["name"] = "the_build_spawner:grey"}, {["x"] = 6, ["y"] = 4, ["param1"] = 15, ["z"] = 9, ["name"] = "the_build_spawner:grey"}, {["x"] = 6, ["y"] = 5, ["param1"] = 15, ["z"] = 1, ["name"] = "the_build_spawner:grey"}, {["x"] = 6, ["y"] = 5, ["z"] = 9, ["name"] = "the_build_spawner:grey"}, {["x"] = 6, ["y"] = 6, ["param1"] = 15, ["z"] = 1, ["name"] = "the_build_spawner:grey"}, {["x"] = 6, ["y"] = 6, ["z"] = 9, ["name"] = "the_build_spawner:grey"}, {["x"] = 6, ["y"] = 7, ["param1"] = 14, ["z"] = 1, ["name"] = "the_build_spawner:grey"}, {["x"] = 6, ["y"] = 7, ["param1"] = 14, ["z"] = 9, ["name"] = "the_build_spawner:grey"}, {["x"] = 6, ["meta"] = {["fields"] = {}, ["inventory"] = {}}, ["y"] = 8, ["param1"] = 110, ["z"] = 1, ["name"] = "stairs:stair_acacia_wood"}, {["x"] = 6, ["meta"] = {["fields"] = {}, ["inventory"] = {}}, ["param2"] = 2, ["y"] = 8, ["param1"] = 110, ["z"] = 9, ["name"] = "stairs:stair_acacia_wood"}, {["x"] = 6, ["meta"] = {["fields"] = {}, ["inventory"] = {}}, ["y"] = 9, ["param1"] = 110, ["z"] = 2, ["name"] = "stairs:stair_acacia_wood"}, {["x"] = 6, ["meta"] = {["fields"] = {}, ["inventory"] = {}}, ["param2"] = 2, ["y"] = 9, ["param1"] = 110, ["z"] = 8, ["name"] = "stairs:stair_acacia_wood"}, {["x"] = 6, ["meta"] = {["fields"] = {}, ["inventory"] = {}}, ["y"] = 10, ["param1"] = 78, ["z"] = 3, ["name"] = "stairs:stair_acacia_wood"}, {["x"] = 6, ["y"] = 10, ["z"] = 4, ["name"] = "the_build_spawner:grey"}, {["x"] = 6, ["y"] = 10, ["z"] = 6, ["name"] = "the_build_spawner:grey"}, {["x"] = 6, ["meta"] = {["fields"] = {}, ["inventory"] = {}}, ["param2"] = 2, ["y"] = 10, ["param1"] = 78, ["z"] = 7, ["name"] = "stairs:stair_acacia_wood"}, {["x"] = 6, ["y"] = 11, ["z"] = 4, ["name"] = "the_build_spawner:grey"}, {["x"] = 6, ["y"] = 11, ["z"] = 6, ["name"] = "the_build_spawner:grey"}, {["x"] = 6, ["y"] = 12, ["z"] = 4, ["name"] = "the_build_spawner:grey"}, {["x"] = 6, ["y"] = 12, ["z"] = 5, ["name"] = "default:goldblock"}, {["x"] = 6, ["y"] = 12, ["z"] = 6, ["name"] = "the_build_spawner:grey"}, {["x"] = 6, ["y"] = 13, ["z"] = 5, ["name"] = "default:goldblock"}, {["x"] = 6, ["y"] = 14, ["z"] = 4, ["name"] = "the_build_spawner:grey"}, {["x"] = 6, ["y"] = 14, ["z"] = 5, ["name"] = "the_build_spawner:grey"}, {["x"] = 6, ["y"] = 14, ["z"] = 6, ["name"] = "the_build_spawner:grey"}, {["x"] = 6, ["y"] = 15, ["param1"] = 14, ["z"] = 4, ["name"] = "stairs:stair_acacia_wood"}, {["x"] = 6, ["y"] = 15, ["z"] = 5, ["name"] = "default:acacia_wood"}, {["x"] = 6, ["param2"] = 2, ["y"] = 15, ["param1"] = 14, ["z"] = 6, ["name"] = "stairs:stair_acacia_wood"}, {["x"] = 6, ["y"] = 16, ["z"] = 5, ["name"] = "default:acacia_wood"}, {["x"] = 6, ["y"] = 17, ["z"] = 5, ["name"] = "default:acacia_wood"}, {["x"] = 6, ["y"] = 18, ["z"] = 4, ["name"] = "default:acacia_wood"}, {["x"] = 6, ["y"] = 18, ["z"] = 5, ["name"] = "default:acacia_wood"}, {["x"] = 6, ["y"] = 18, ["z"] = 6, ["name"] = "default:acacia_wood"}, {["x"] = 6, ["y"] = 19, ["z"] = 5, ["name"] = "default:acacia_wood"}, {["x"] = 7, ["param2"] = 1, ["y"] = 0, ["param1"] = 78, ["z"] = 0, ["name"] = "default:aspen_leaves"}, {["x"] = 7, ["y"] = 0, ["z"] = 1, ["name"] = "default:brick"}, {["x"] = 7, ["y"] = 0, ["z"] = 2, ["name"] = "default:stone_block"}, {["x"] = 7, ["y"] = 0, ["z"] = 3, ["name"] = "default:stone_block"}, {["x"] = 7, ["y"] = 0, ["z"] = 4, ["name"] = "default:stone_block"}, {["x"] = 7, ["y"] = 0, ["z"] = 5, ["name"] = "default:stone_block"}, {["x"] = 7, ["y"] = 0, ["z"] = 6, ["name"] = "default:stone_block"}, {["x"] = 7, ["y"] = 0, ["z"] = 7, ["name"] = "default:stone_block"}, {["x"] = 7, ["y"] = 0, ["z"] = 8, ["name"] = "default:stone_block"}, {["x"] = 7, ["y"] = 0, ["z"] = 9, ["name"] = "default:brick"}, {["x"] = 7, ["param2"] = 1, ["y"] = 0, ["param1"] = 78, ["z"] = 10, ["name"] = "default:aspen_leaves"}, {["x"] = 7, ["y"] = 1, ["param1"] = 15, ["z"] = 1, ["name"] = "default:brick"}, {["x"] = 7, ["y"] = 1, ["param1"] = 15, ["z"] = 9, ["name"] = "default:brick"}, {["x"] = 7, ["y"] = 2, ["param1"] = 15, ["z"] = 1, ["name"] = "default:brick"}, {["x"] = 7, ["y"] = 2, ["param1"] = 15, ["z"] = 9, ["name"] = "default:brick"}, {["x"] = 7, ["y"] = 3, ["param1"] = 15, ["z"] = 1, ["name"] = "the_build_spawner:grey"}, {["x"] = 7, ["y"] = 3, ["param1"] = 15, ["z"] = 9, ["name"] = "the_build_spawner:grey"}, {["x"] = 7, ["y"] = 4, ["param1"] = 158, ["z"] = 1, ["name"] = "default:glass"}, {["x"] = 7, ["y"] = 4, ["param1"] = 158, ["z"] = 9, ["name"] = "default:glass"}, {["x"] = 7, ["y"] = 5, ["param1"] = 142, ["z"] = 1, ["name"] = "default:glass"}, {["x"] = 7, ["y"] = 5, ["param1"] = 142, ["z"] = 9, ["name"] = "default:glass"}, {["x"] = 7, ["y"] = 6, ["param1"] = 126, ["z"] = 1, ["name"] = "default:glass"}, {["x"] = 7, ["y"] = 6, ["param1"] = 126, ["z"] = 9, ["name"] = "default:glass"}, {["x"] = 7, ["y"] = 7, ["param1"] = 14, ["z"] = 1, ["name"] = "the_build_spawner:grey"}, {["x"] = 7, ["y"] = 7, ["param1"] = 14, ["z"] = 9, ["name"] = "the_build_spawner:grey"}, {["x"] = 7, ["meta"] = {["fields"] = {}, ["inventory"] = {}}, ["y"] = 8, ["param1"] = 94, ["z"] = 1, ["name"] = "stairs:stair_acacia_wood"}, {["x"] = 7, ["meta"] = {["fields"] = {}, ["inventory"] = {}}, ["param2"] = 2, ["y"] = 8, ["param1"] = 94, ["z"] = 9, ["name"] = "stairs:stair_acacia_wood"}, {["x"] = 7, ["meta"] = {["fields"] = {}, ["inventory"] = {}}, ["y"] = 9, ["param1"] = 94, ["z"] = 2, ["name"] = "stairs:stair_acacia_wood"}, {["x"] = 7, ["meta"] = {["fields"] = {}, ["inventory"] = {}}, ["param2"] = 2, ["y"] = 9, ["param1"] = 94, ["z"] = 8, ["name"] = "stairs:stair_acacia_wood"}, {["x"] = 7, ["meta"] = {["fields"] = {}, ["inventory"] = {}}, ["y"] = 10, ["param1"] = 62, ["z"] = 3, ["name"] = "stairs:stair_acacia_wood"}, {["x"] = 7, ["y"] = 10, ["z"] = 4, ["name"] = "the_build_spawner:grey"}, {["x"] = 7, ["y"] = 10, ["z"] = 5, ["name"] = "the_build_spawner:grey"}, {["x"] = 7, ["y"] = 10, ["z"] = 6, ["name"] = "the_build_spawner:grey"}, {["x"] = 7, ["meta"] = {["fields"] = {}, ["inventory"] = {}}, ["param2"] = 2, ["y"] = 10, ["param1"] = 62, ["z"] = 7, ["name"] = "stairs:stair_acacia_wood"}, {["x"] = 7, ["y"] = 11, ["z"] = 4, ["name"] = "the_build_spawner:grey"}, {["x"] = 7, ["y"] = 11, ["z"] = 5, ["name"] = "the_build_spawner:grey"}, {["x"] = 7, ["y"] = 11, ["z"] = 6, ["name"] = "the_build_spawner:grey"}, {["x"] = 7, ["y"] = 12, ["z"] = 4, ["name"] = "the_build_spawner:grey"}, {["x"] = 7, ["y"] = 12, ["z"] = 5, ["name"] = "the_build_spawner:grey"}, {["x"] = 7, ["y"] = 12, ["z"] = 6, ["name"] = "the_build_spawner:grey"}, {["x"] = 7, ["y"] = 13, ["z"] = 4, ["name"] = "the_build_spawner:grey"}, {["x"] = 7, ["y"] = 13, ["z"] = 6, ["name"] = "the_build_spawner:grey"}, {["x"] = 7, ["y"] = 14, ["z"] = 4, ["name"] = "the_build_spawner:grey"}, {["x"] = 7, ["y"] = 14, ["z"] = 5, ["name"] = "the_build_spawner:grey"}, {["x"] = 7, ["y"] = 14, ["z"] = 6, ["name"] = "the_build_spawner:grey"}, {["x"] = 7, ["y"] = 15, ["param1"] = 14, ["z"] = 4, ["name"] = "stairs:stair_outer_acacia_wood"}, {["x"] = 7, ["param2"] = 3, ["y"] = 15, ["param1"] = 14, ["z"] = 5, ["name"] = "stairs:stair_acacia_wood"}, {["x"] = 7, ["param2"] = 3, ["y"] = 15, ["param1"] = 14, ["z"] = 6, ["name"] = "stairs:stair_outer_acacia_wood"}, {["x"] = 8, ["param2"] = 1, ["y"] = 0, ["param1"] = 62, ["z"] = 0, ["name"] = "default:aspen_leaves"}, {["x"] = 8, ["y"] = 0, ["z"] = 1, ["name"] = "default:brick"}, {["x"] = 8, ["y"] = 0, ["z"] = 2, ["name"] = "default:stone_block"}, {["x"] = 8, ["y"] = 0, ["z"] = 3, ["name"] = "default:stone_block"}, {["x"] = 8, ["y"] = 0, ["z"] = 4, ["name"] = "default:stone_block"}, {["x"] = 8, ["y"] = 0, ["z"] = 5, ["name"] = "default:stone_block"}, {["x"] = 8, ["y"] = 0, ["z"] = 6, ["name"] = "default:stone_block"}, {["x"] = 8, ["y"] = 0, ["z"] = 7, ["name"] = "default:stone_block"}, {["x"] = 8, ["y"] = 0, ["z"] = 8, ["name"] = "default:stone_block"}, {["x"] = 8, ["y"] = 0, ["z"] = 9, ["name"] = "default:brick"}, {["x"] = 8, ["param2"] = 1, ["y"] = 0, ["param1"] = 62, ["z"] = 10, ["name"] = "default:aspen_leaves"}, {["x"] = 8, ["y"] = 1, ["param1"] = 15, ["z"] = 1, ["name"] = "default:brick"}, {["x"] = 8, ["param2"] = 1, ["y"] = 1, ["param1"] = 137, ["z"] = 4, ["name"] = "stairs:stair_outer_acacia_wood"}, {["x"] = 8, ["param2"] = 1, ["y"] = 1, ["param1"] = 122, ["z"] = 5, ["name"] = "stairs:stair_acacia_wood"}, {["x"] = 8, ["param2"] = 2, ["y"] = 1, ["param1"] = 139, ["z"] = 6, ["name"] = "stairs:stair_outer_acacia_wood"}, {["x"] = 8, ["y"] = 1, ["param1"] = 15, ["z"] = 9, ["name"] = "default:brick"}, {["x"] = 8, ["y"] = 2, ["param1"] = 15, ["z"] = 1, ["name"] = "default:brick"}, {["x"] = 8, ["y"] = 2, ["param1"] = 15, ["z"] = 9, ["name"] = "default:brick"}, {["x"] = 8, ["y"] = 3, ["param1"] = 15, ["z"] = 1, ["name"] = "the_build_spawner:grey"}, {["x"] = 8, ["param2"] = 5, ["y"] = 3, ["param1"] = 204, ["z"] = 2, ["name"] = "default:torch_wall"}, {["x"] = 8, ["param2"] = 4, ["y"] = 3, ["param1"] = 205, ["z"] = 8, ["name"] = "default:torch_wall"}, {["x"] = 8, ["y"] = 3, ["param1"] = 15, ["z"] = 9, ["name"] = "the_build_spawner:grey"}, {["x"] = 8, ["y"] = 4, ["param1"] = 15, ["z"] = 1, ["name"] = "the_build_spawner:grey"}, {["x"] = 8, ["y"] = 4, ["param1"] = 15, ["z"] = 9, ["name"] = "the_build_spawner:grey"}, {["x"] = 8, ["y"] = 5, ["param1"] = 15, ["z"] = 1, ["name"] = "the_build_spawner:grey"}, {["x"] = 8, ["y"] = 5, ["param1"] = 15, ["z"] = 9, ["name"] = "the_build_spawner:grey"}, {["x"] = 8, ["y"] = 6, ["param1"] = 15, ["z"] = 1, ["name"] = "the_build_spawner:grey"}, {["x"] = 8, ["y"] = 6, ["param1"] = 15, ["z"] = 9, ["name"] = "the_build_spawner:grey"}, {["x"] = 8, ["y"] = 7, ["param1"] = 14, ["z"] = 1, ["name"] = "the_build_spawner:grey"}, {["x"] = 8, ["y"] = 7, ["param1"] = 14, ["z"] = 9, ["name"] = "the_build_spawner:grey"}, {["x"] = 8, ["meta"] = {["fields"] = {}, ["inventory"] = {}}, ["y"] = 8, ["param1"] = 110, ["z"] = 1, ["name"] = "stairs:stair_acacia_wood"}, {["x"] = 8, ["meta"] = {["fields"] = {}, ["inventory"] = {}}, ["param2"] = 2, ["y"] = 8, ["param1"] = 110, ["z"] = 9, ["name"] = "stairs:stair_acacia_wood"}, {["x"] = 8, ["meta"] = {["fields"] = {}, ["inventory"] = {}}, ["y"] = 9, ["param1"] = 110, ["z"] = 2, ["name"] = "stairs:stair_acacia_wood"}, {["x"] = 8, ["meta"] = {["fields"] = {}, ["inventory"] = {}}, ["param2"] = 2, ["y"] = 9, ["param1"] = 110, ["z"] = 8, ["name"] = "stairs:stair_acacia_wood"}, {["x"] = 8, ["meta"] = {["fields"] = {}, ["inventory"] = {}}, ["y"] = 10, ["param1"] = 78, ["z"] = 3, ["name"] = "stairs:stair_acacia_wood"}, {["x"] = 8, ["meta"] = {["fields"] = {}, ["inventory"] = {}}, ["param2"] = 2, ["y"] = 10, ["param1"] = 78, ["z"] = 7, ["name"] = "stairs:stair_acacia_wood"}, {["x"] = 8, ["y"] = 11, ["param1"] = 46, ["z"] = 4, ["name"] = "stairs:stair_acacia_wood"}, {["x"] = 8, ["param2"] = 2, ["y"] = 11, ["param1"] = 46, ["z"] = 6, ["name"] = "stairs:stair_acacia_wood"}, {["x"] = 8, ["y"] = 12, ["param1"] = 14, ["z"] = 5, ["name"] = "stairs:slab_acacia_wood"}, {["x"] = 9, ["param2"] = 1, ["y"] = 0, ["param1"] = 78, ["z"] = 0, ["name"] = "default:aspen_leaves"}, {["x"] = 9, ["y"] = 0, ["z"] = 1, ["name"] = "default:brick"}, {["x"] = 9, ["y"] = 0, ["z"] = 2, ["name"] = "default:stone_block"}, {["x"] = 9, ["y"] = 0, ["z"] = 3, ["name"] = "default:stone_block"}, {["x"] = 9, ["y"] = 0, ["z"] = 4, ["name"] = "default:stone_block"}, {["x"] = 9, ["y"] = 0, ["z"] = 5, ["name"] = "default:stone_block"}, {["x"] = 9, ["y"] = 0, ["z"] = 6, ["name"] = "default:stone_block"}, {["x"] = 9, ["y"] = 0, ["z"] = 7, ["name"] = "default:stone_block"}, {["x"] = 9, ["y"] = 0, ["z"] = 8, ["name"] = "default:stone_block"}, {["x"] = 9, ["y"] = 0, ["z"] = 9, ["name"] = "default:brick"}, {["x"] = 9, ["param2"] = 1, ["y"] = 0, ["param1"] = 78, ["z"] = 10, ["name"] = "default:aspen_leaves"}, {["x"] = 9, ["y"] = 1, ["param1"] = 15, ["z"] = 1, ["name"] = "default:brick"}, {["x"] = 9, ["y"] = 1, ["z"] = 2, ["name"] = "default:acacia_wood"}, {["x"] = 9, ["y"] = 1, ["z"] = 3, ["name"] = "default:acacia_wood"}, {["x"] = 9, ["y"] = 1, ["z"] = 4, ["name"] = "default:acacia_wood"}, {["x"] = 9, ["y"] = 1, ["z"] = 5, ["name"] = "default:acacia_wood"}, {["x"] = 9, ["y"] = 1, ["z"] = 6, ["name"] = "default:acacia_wood"}, {["x"] = 9, ["y"] = 1, ["z"] = 7, ["name"] = "default:acacia_wood"}, {["x"] = 9, ["y"] = 1, ["z"] = 8, ["name"] = "default:acacia_wood"}, {["x"] = 9, ["y"] = 1, ["param1"] = 15, ["z"] = 9, ["name"] = "default:brick"}, {["x"] = 9, ["y"] = 2, ["param1"] = 15, ["z"] = 1, ["name"] = "default:brick"}, {["x"] = 9, ["param2"] = 16, ["y"] = 2, ["param1"] = 124, ["z"] = 5, ["name"] = "stairs:slab_acacia_wood"}, {["x"] = 9, ["y"] = 2, ["param1"] = 15, ["z"] = 9, ["name"] = "default:brick"}, {["x"] = 9, ["y"] = 3, ["param1"] = 15, ["z"] = 1, ["name"] = "the_build_spawner:grey"}, {["x"] = 9, ["y"] = 3, ["param1"] = 15, ["z"] = 9, ["name"] = "the_build_spawner:grey"}, {["x"] = 9, ["y"] = 4, ["param1"] = 158, ["z"] = 1, ["name"] = "default:glass"}, {["x"] = 9, ["y"] = 4, ["param1"] = 158, ["z"] = 9, ["name"] = "default:glass"}, {["x"] = 9, ["y"] = 5, ["param1"] = 142, ["z"] = 1, ["name"] = "default:glass"}, {["x"] = 9, ["y"] = 5, ["param1"] = 142, ["z"] = 9, ["name"] = "default:glass"}, {["x"] = 9, ["y"] = 6, ["param1"] = 126, ["z"] = 1, ["name"] = "default:glass"}, {["x"] = 9, ["y"] = 6, ["param1"] = 126, ["z"] = 9, ["name"] = "default:glass"}, {["x"] = 9, ["y"] = 7, ["param1"] = 14, ["z"] = 1, ["name"] = "the_build_spawner:grey"}, {["x"] = 9, ["y"] = 7, ["param1"] = 14, ["z"] = 9, ["name"] = "the_build_spawner:grey"}, {["x"] = 9, ["meta"] = {["fields"] = {}, ["inventory"] = {}}, ["y"] = 8, ["param1"] = 94, ["z"] = 1, ["name"] = "stairs:stair_acacia_wood"}, {["x"] = 9, ["meta"] = {["fields"] = {}, ["inventory"] = {}}, ["param2"] = 2, ["y"] = 8, ["param1"] = 94, ["z"] = 9, ["name"] = "stairs:stair_acacia_wood"}, {["x"] = 9, ["meta"] = {["fields"] = {}, ["inventory"] = {}}, ["y"] = 9, ["param1"] = 94, ["z"] = 2, ["name"] = "stairs:stair_acacia_wood"}, {["x"] = 9, ["meta"] = {["fields"] = {}, ["inventory"] = {}}, ["param2"] = 2, ["y"] = 9, ["param1"] = 94, ["z"] = 8, ["name"] = "stairs:stair_acacia_wood"}, {["x"] = 9, ["meta"] = {["fields"] = {}, ["inventory"] = {}}, ["y"] = 10, ["param1"] = 62, ["z"] = 3, ["name"] = "stairs:stair_acacia_wood"}, {["x"] = 9, ["meta"] = {["fields"] = {}, ["inventory"] = {}}, ["param2"] = 2, ["y"] = 10, ["param1"] = 62, ["z"] = 7, ["name"] = "stairs:stair_acacia_wood"}, {["x"] = 9, ["y"] = 11, ["param1"] = 30, ["z"] = 4, ["name"] = "stairs:stair_acacia_wood"}, {["x"] = 9, ["param2"] = 2, ["y"] = 11, ["param1"] = 30, ["z"] = 6, ["name"] = "stairs:stair_acacia_wood"}, {["x"] = 9, ["y"] = 12, ["param1"] = 14, ["z"] = 5, ["name"] = "stairs:slab_acacia_wood"}, {["x"] = 10, ["param2"] = 1, ["y"] = 0, ["param1"] = 62, ["z"] = 0, ["name"] = "default:aspen_leaves"}, {["x"] = 10, ["y"] = 0, ["z"] = 1, ["name"] = "default:brick"}, {["x"] = 10, ["y"] = 0, ["z"] = 2, ["name"] = "default:stone_block"}, {["x"] = 10, ["y"] = 0, ["z"] = 3, ["name"] = "default:stone_block"}, {["x"] = 10, ["y"] = 0, ["z"] = 4, ["name"] = "default:stone_block"}, {["x"] = 10, ["y"] = 0, ["z"] = 5, ["name"] = "default:stone_block"}, {["x"] = 10, ["y"] = 0, ["z"] = 6, ["name"] = "default:stone_block"}, {["x"] = 10, ["y"] = 0, ["z"] = 7, ["name"] = "default:stone_block"}, {["x"] = 10, ["y"] = 0, ["z"] = 8, ["name"] = "default:stone_block"}, {["x"] = 10, ["y"] = 0, ["z"] = 9, ["name"] = "default:brick"}, {["x"] = 10, ["param2"] = 1, ["y"] = 0, ["param1"] = 62, ["z"] = 10, ["name"] = "default:aspen_leaves"}, {["x"] = 10, ["y"] = 1, ["param1"] = 15, ["z"] = 1, ["name"] = "default:brick"}, {["x"] = 10, ["y"] = 1, ["z"] = 2, ["name"] = "default:acacia_wood"}, {["x"] = 10, ["y"] = 1, ["z"] = 3, ["name"] = "default:acacia_wood"}, {["x"] = 10, ["y"] = 1, ["z"] = 4, ["name"] = "default:acacia_wood"}, {["x"] = 10, ["y"] = 1, ["z"] = 5, ["name"] = "default:acacia_wood"}, {["x"] = 10, ["y"] = 1, ["z"] = 6, ["name"] = "default:acacia_wood"}, {["x"] = 10, ["y"] = 1, ["z"] = 7, ["name"] = "default:acacia_wood"}, {["x"] = 10, ["y"] = 1, ["z"] = 8, ["name"] = "default:acacia_wood"}, {["x"] = 10, ["y"] = 1, ["param1"] = 15, ["z"] = 9, ["name"] = "default:brick"}, {["x"] = 10, ["y"] = 2, ["param1"] = 15, ["z"] = 1, ["name"] = "default:brick"}, {["x"] = 10, ["y"] = 2, ["param1"] = 15, ["z"] = 9, ["name"] = "default:brick"}, {["x"] = 10, ["y"] = 3, ["param1"] = 15, ["z"] = 1, ["name"] = "the_build_spawner:grey"}, {["x"] = 10, ["param2"] = 5, ["y"] = 3, ["param1"] = 204, ["z"] = 2, ["name"] = "default:torch_wall"}, {["x"] = 10, ["param2"] = 23, ["y"] = 3, ["param1"] = 172, ["z"] = 4, ["name"] = "doors:trapdoor"}, {["x"] = 10, ["param2"] = 23, ["y"] = 3, ["param1"] = 157, ["z"] = 5, ["name"] = "doors:trapdoor"}, {["x"] = 10, ["param2"] = 23, ["y"] = 3, ["param1"] = 174, ["z"] = 6, ["name"] = "doors:trapdoor"}, {["x"] = 10, ["param2"] = 4, ["y"] = 3, ["param1"] = 207, ["z"] = 8, ["name"] = "default:torch_wall"}, {["x"] = 10, ["y"] = 3, ["param1"] = 15, ["z"] = 9, ["name"] = "the_build_spawner:grey"}, {["x"] = 10, ["y"] = 4, ["param1"] = 15, ["z"] = 1, ["name"] = "the_build_spawner:grey"}, {["x"] = 10, ["y"] = 4, ["param1"] = 156, ["z"] = 4, ["name"] = "vessels:glass_bottle"}, {["x"] = 10, ["param2"] = 16, ["y"] = 4, ["param1"] = 141, ["z"] = 5, ["name"] = "stairs:slab_acacia_wood"}, {["x"] = 10, ["y"] = 4, ["param1"] = 15, ["z"] = 9, ["name"] = "the_build_spawner:grey"}, {["x"] = 10, ["y"] = 5, ["param1"] = 15, ["z"] = 1, ["name"] = "the_build_spawner:grey"}, {["x"] = 10, ["param2"] = 16, ["y"] = 5, ["param1"] = 125, ["z"] = 5, ["name"] = "stairs:slab_acacia_wood"}, {["x"] = 10, ["y"] = 5, ["param1"] = 15, ["z"] = 9, ["name"] = "the_build_spawner:grey"}, {["x"] = 10, ["y"] = 6, ["param1"] = 15, ["z"] = 1, ["name"] = "the_build_spawner:grey"}, {["x"] = 10, ["param2"] = 16, ["y"] = 6, ["param1"] = 124, ["z"] = 4, ["name"] = "stairs:slab_acacia_wood"}, {["x"] = 10, ["param2"] = 16, ["y"] = 6, ["param1"] = 109, ["z"] = 5, ["name"] = "stairs:slab_acacia_wood"}, {["x"] = 10, ["param2"] = 16, ["y"] = 6, ["param1"] = 126, ["z"] = 6, ["name"] = "stairs:slab_acacia_wood"}, {["x"] = 10, ["y"] = 6, ["param1"] = 15, ["z"] = 9, ["name"] = "the_build_spawner:grey"}, {["x"] = 10, ["y"] = 7, ["param1"] = 14, ["z"] = 1, ["name"] = "the_build_spawner:grey"}, {["x"] = 10, ["param2"] = 16, ["y"] = 7, ["param1"] = 92, ["z"] = 5, ["name"] = "stairs:slab_acacia_wood"}, {["x"] = 10, ["y"] = 7, ["param1"] = 14, ["z"] = 9, ["name"] = "the_build_spawner:grey"}, {["x"] = 10, ["meta"] = {["fields"] = {}, ["inventory"] = {}}, ["y"] = 8, ["param1"] = 110, ["z"] = 1, ["name"] = "stairs:stair_acacia_wood"}, {["x"] = 10, ["meta"] = {["fields"] = {}, ["inventory"] = {}}, ["param2"] = 2, ["y"] = 8, ["param1"] = 110, ["z"] = 9, ["name"] = "stairs:stair_acacia_wood"}, {["x"] = 10, ["meta"] = {["fields"] = {}, ["inventory"] = {}}, ["y"] = 9, ["param1"] = 110, ["z"] = 2, ["name"] = "stairs:stair_acacia_wood"}, {["x"] = 10, ["meta"] = {["fields"] = {}, ["inventory"] = {}}, ["param2"] = 2, ["y"] = 9, ["param1"] = 110, ["z"] = 8, ["name"] = "stairs:stair_acacia_wood"}, {["x"] = 10, ["meta"] = {["fields"] = {}, ["inventory"] = {}}, ["y"] = 10, ["param1"] = 78, ["z"] = 3, ["name"] = "stairs:stair_acacia_wood"}, {["x"] = 10, ["meta"] = {["fields"] = {}, ["inventory"] = {}}, ["param2"] = 2, ["y"] = 10, ["param1"] = 78, ["z"] = 7, ["name"] = "stairs:stair_acacia_wood"}, {["x"] = 10, ["y"] = 11, ["param1"] = 46, ["z"] = 4, ["name"] = "stairs:stair_acacia_wood"}, {["x"] = 10, ["param2"] = 2, ["y"] = 11, ["param1"] = 46, ["z"] = 6, ["name"] = "stairs:stair_acacia_wood"}, {["x"] = 10, ["y"] = 12, ["param1"] = 14, ["z"] = 5, ["name"] = "stairs:slab_acacia_wood"}, {["x"] = 11, ["param2"] = 1, ["y"] = 0, ["param1"] = 46, ["z"] = 0, ["name"] = "default:aspen_leaves"}, {["x"] = 11, ["y"] = 0, ["z"] = 1, ["name"] = "default:brick"}, {["x"] = 11, ["y"] = 0, ["z"] = 2, ["name"] = "default:brick"}, {["x"] = 11, ["y"] = 0, ["z"] = 3, ["name"] = "default:brick"}, {["x"] = 11, ["y"] = 0, ["z"] = 4, ["name"] = "default:brick"}, {["x"] = 11, ["y"] = 0, ["z"] = 5, ["name"] = "default:brick"}, {["x"] = 11, ["y"] = 0, ["z"] = 6, ["name"] = "default:brick"}, {["x"] = 11, ["y"] = 0, ["z"] = 7, ["name"] = "default:brick"}, {["x"] = 11, ["y"] = 0, ["z"] = 8, ["name"] = "default:brick"}, {["x"] = 11, ["y"] = 0, ["z"] = 9, ["name"] = "default:brick"}, {["x"] = 11, ["param2"] = 1, ["y"] = 0, ["param1"] = 46, ["z"] = 10, ["name"] = "default:aspen_leaves"}, {["x"] = 11, ["y"] = 1, ["param1"] = 15, ["z"] = 1, ["name"] = "default:brick"}, {["x"] = 11, ["y"] = 1, ["param1"] = 14, ["z"] = 2, ["name"] = "default:brick"}, {["x"] = 11, ["y"] = 1, ["param1"] = 14, ["z"] = 3, ["name"] = "default:brick"}, {["x"] = 11, ["y"] = 1, ["param1"] = 15, ["z"] = 4, ["name"] = "default:brick"}, {["x"] = 11, ["y"] = 1, ["param1"] = 15, ["z"] = 5, ["name"] = "default:brick"}, {["x"] = 11, ["y"] = 1, ["param1"] = 15, ["z"] = 6, ["name"] = "default:brick"}, {["x"] = 11, ["y"] = 1, ["param1"] = 15, ["z"] = 7, ["name"] = "default:brick"}, {["x"] = 11, ["y"] = 1, ["param1"] = 15, ["z"] = 8, ["name"] = "default:brick"}, {["x"] = 11, ["y"] = 1, ["param1"] = 15, ["z"] = 9, ["name"] = "default:brick"}, {["x"] = 11, ["y"] = 2, ["param1"] = 15, ["z"] = 1, ["name"] = "default:brick"}, {["x"] = 11, ["y"] = 2, ["param1"] = 14, ["z"] = 2, ["name"] = "default:brick"}, {["x"] = 11, ["y"] = 2, ["param1"] = 14, ["z"] = 3, ["name"] = "default:brick"}, {["x"] = 11, ["y"] = 2, ["z"] = 4, ["name"] = "default:brick"}, {["x"] = 11, ["y"] = 2, ["param1"] = 15, ["z"] = 5, ["name"] = "default:brick"}, {["x"] = 11, ["y"] = 2, ["param1"] = 15, ["z"] = 6, ["name"] = "default:brick"}, {["x"] = 11, ["y"] = 2, ["param1"] = 15, ["z"] = 7, ["name"] = "default:brick"}, {["x"] = 11, ["y"] = 2, ["param1"] = 15, ["z"] = 8, ["name"] = "default:brick"}, {["x"] = 11, ["y"] = 2, ["param1"] = 15, ["z"] = 9, ["name"] = "default:brick"}, {["x"] = 11, ["y"] = 3, ["z"] = 1, ["name"] = "default:stonebrick"}, {["x"] = 11, ["y"] = 3, ["param1"] = 13, ["z"] = 2, ["name"] = "the_build_spawner:grey"}, {["x"] = 11, ["y"] = 3, ["param1"] = 14, ["z"] = 3, ["name"] = "the_build_spawner:grey"}, {["x"] = 11, ["y"] = 3, ["param1"] = 15, ["z"] = 4, ["name"] = "the_build_spawner:grey"}, {["x"] = 11, ["y"] = 3, ["param1"] = 15, ["z"] = 5, ["name"] = "the_build_spawner:grey"}, {["x"] = 11, ["y"] = 3, ["param1"] = 15, ["z"] = 6, ["name"] = "the_build_spawner:grey"}, {["x"] = 11, ["y"] = 3, ["param1"] = 15, ["z"] = 7, ["name"] = "the_build_spawner:grey"}, {["x"] = 11, ["y"] = 3, ["param1"] = 15, ["z"] = 8, ["name"] = "the_build_spawner:grey"}, {["x"] = 11, ["y"] = 3, ["z"] = 9, ["name"] = "default:stonebrick"}, {["x"] = 11, ["y"] = 4, ["param1"] = 15, ["z"] = 1, ["name"] = "the_build_spawner:grey"}, {["x"] = 11, ["y"] = 4, ["param1"] = 14, ["z"] = 2, ["name"] = "the_build_spawner:grey"}, {["x"] = 11, ["y"] = 4, ["param1"] = 14, ["z"] = 3, ["name"] = "the_build_spawner:grey"}, {["x"] = 11, ["y"] = 4, ["param1"] = 15, ["z"] = 4, ["name"] = "the_build_spawner:grey"}, {["x"] = 11, ["y"] = 4, ["param1"] = 15, ["z"] = 5, ["name"] = "the_build_spawner:grey"}, {["x"] = 11, ["y"] = 4, ["param1"] = 15, ["z"] = 6, ["name"] = "the_build_spawner:grey"}, {["x"] = 11, ["y"] = 4, ["param1"] = 15, ["z"] = 7, ["name"] = "the_build_spawner:grey"}, {["x"] = 11, ["y"] = 4, ["param1"] = 15, ["z"] = 8, ["name"] = "the_build_spawner:grey"}, {["x"] = 11, ["y"] = 4, ["param1"] = 15, ["z"] = 9, ["name"] = "the_build_spawner:grey"}, {["x"] = 11, ["y"] = 5, ["z"] = 1, ["name"] = "default:stonebrick"}, {["x"] = 11, ["y"] = 5, ["param1"] = 14, ["z"] = 2, ["name"] = "the_build_spawner:grey"}, {["x"] = 11, ["y"] = 5, ["param1"] = 14, ["z"] = 3, ["name"] = "the_build_spawner:grey"}, {["x"] = 11, ["y"] = 5, ["param1"] = 15, ["z"] = 4, ["name"] = "the_build_spawner:grey"}, {["x"] = 11, ["y"] = 5, ["param1"] = 15, ["z"] = 5, ["name"] = "the_build_spawner:grey"}, {["x"] = 11, ["y"] = 5, ["param1"] = 15, ["z"] = 6, ["name"] = "the_build_spawner:grey"}, {["x"] = 11, ["y"] = 5, ["param1"] = 15, ["z"] = 7, ["name"] = "the_build_spawner:grey"}, {["x"] = 11, ["y"] = 5, ["param1"] = 15, ["z"] = 8, ["name"] = "the_build_spawner:grey"}, {["x"] = 11, ["y"] = 5, ["z"] = 9, ["name"] = "default:stonebrick"}, {["x"] = 11, ["y"] = 6, ["param1"] = 15, ["z"] = 1, ["name"] = "the_build_spawner:grey"}, {["x"] = 11, ["y"] = 6, ["param1"] = 14, ["z"] = 2, ["name"] = "the_build_spawner:grey"}, {["x"] = 11, ["y"] = 6, ["param1"] = 14, ["z"] = 3, ["name"] = "the_build_spawner:grey"}, {["x"] = 11, ["y"] = 6, ["param1"] = 15, ["z"] = 4, ["name"] = "the_build_spawner:grey"}, {["x"] = 11, ["y"] = 6, ["param1"] = 15, ["z"] = 5, ["name"] = "the_build_spawner:grey"}, {["x"] = 11, ["y"] = 6, ["param1"] = 15, ["z"] = 6, ["name"] = "the_build_spawner:grey"}, {["x"] = 11, ["y"] = 6, ["param1"] = 15, ["z"] = 7, ["name"] = "the_build_spawner:grey"}, {["x"] = 11, ["y"] = 6, ["param1"] = 15, ["z"] = 8, ["name"] = "the_build_spawner:grey"}, {["x"] = 11, ["y"] = 6, ["param1"] = 15, ["z"] = 9, ["name"] = "the_build_spawner:grey"}, {["x"] = 11, ["y"] = 7, ["z"] = 1, ["name"] = "default:stonebrick"}, {["x"] = 11, ["y"] = 7, ["param1"] = 14, ["z"] = 2, ["name"] = "the_build_spawner:grey"}, {["x"] = 11, ["y"] = 7, ["param1"] = 14, ["z"] = 3, ["name"] = "the_build_spawner:grey"}, {["x"] = 11, ["y"] = 7, ["param1"] = 14, ["z"] = 4, ["name"] = "the_build_spawner:grey"}, {["x"] = 11, ["y"] = 7, ["param1"] = 14, ["z"] = 5, ["name"] = "the_build_spawner:grey"}, {["x"] = 11, ["y"] = 7, ["param1"] = 14, ["z"] = 6, ["name"] = "the_build_spawner:grey"}, {["x"] = 11, ["y"] = 7, ["param1"] = 14, ["z"] = 7, ["name"] = "the_build_spawner:grey"}, {["x"] = 11, ["y"] = 7, ["param1"] = 14, ["z"] = 8, ["name"] = "the_build_spawner:grey"}, {["x"] = 11, ["y"] = 7, ["z"] = 9, ["name"] = "default:stonebrick"}, {["x"] = 11, ["meta"] = {["fields"] = {}, ["inventory"] = {}}, ["y"] = 8, ["param1"] = 188, ["z"] = 1, ["name"] = "the_build_spawner:grey"}, {["x"] = 11, ["meta"] = {["fields"] = {}, ["inventory"] = {}}, ["y"] = 8, ["param1"] = 188, ["z"] = 2, ["name"] = "the_build_spawner:grey"}, {["x"] = 11, ["meta"] = {["fields"] = {}, ["inventory"] = {}}, ["y"] = 8, ["param1"] = 188, ["z"] = 3, ["name"] = "the_build_spawner:grey"}, {["x"] = 11, ["meta"] = {["fields"] = {}, ["inventory"] = {}}, ["y"] = 8, ["param1"] = 188, ["z"] = 4, ["name"] = "the_build_spawner:grey"}, {["x"] = 11, ["param2"] = 3, ["y"] = 8, ["param1"] = 62, ["z"] = 5, ["name"] = "doors:trapdoor_open"}, {["x"] = 11, ["meta"] = {["fields"] = {}, ["inventory"] = {}}, ["y"] = 8, ["param1"] = 188, ["z"] = 6, ["name"] = "the_build_spawner:grey"}, {["x"] = 11, ["meta"] = {["fields"] = {}, ["inventory"] = {}}, ["y"] = 8, ["param1"] = 188, ["z"] = 7, ["name"] = "the_build_spawner:grey"}, {["x"] = 11, ["meta"] = {["fields"] = {}, ["inventory"] = {}}, ["y"] = 8, ["param1"] = 188, ["z"] = 8, ["name"] = "the_build_spawner:grey"}, {["x"] = 11, ["meta"] = {["fields"] = {}, ["inventory"] = {}}, ["y"] = 8, ["param1"] = 188, ["z"] = 9, ["name"] = "the_build_spawner:grey"}, {["x"] = 11, ["meta"] = {["fields"] = {}, ["inventory"] = {}}, ["y"] = 9, ["param1"] = 188, ["z"] = 1, ["name"] = "the_build_spawner:grey"}, {["x"] = 11, ["meta"] = {["fields"] = {}, ["inventory"] = {}}, ["y"] = 9, ["param1"] = 188, ["z"] = 2, ["name"] = "the_build_spawner:grey"}, {["x"] = 11, ["meta"] = {["fields"] = {}, ["inventory"] = {}}, ["y"] = 9, ["param1"] = 188, ["z"] = 3, ["name"] = "the_build_spawner:grey"}, {["x"] = 11, ["meta"] = {["fields"] = {}, ["inventory"] = {}}, ["y"] = 9, ["param1"] = 188, ["z"] = 4, ["name"] = "the_build_spawner:grey"}, {["x"] = 11, ["meta"] = {["fields"] = {}, ["inventory"] = {}}, ["y"] = 9, ["param1"] = 188, ["z"] = 5, ["name"] = "the_build_spawner:grey"}, {["x"] = 11, ["meta"] = {["fields"] = {}, ["inventory"] = {}}, ["y"] = 9, ["param1"] = 188, ["z"] = 6, ["name"] = "the_build_spawner:grey"}, {["x"] = 11, ["meta"] = {["fields"] = {}, ["inventory"] = {}}, ["y"] = 9, ["param1"] = 188, ["z"] = 7, ["name"] = "the_build_spawner:grey"}, {["x"] = 11, ["meta"] = {["fields"] = {}, ["inventory"] = {}}, ["y"] = 9, ["param1"] = 188, ["z"] = 8, ["name"] = "the_build_spawner:grey"}, {["x"] = 11, ["meta"] = {["fields"] = {}, ["inventory"] = {}}, ["y"] = 9, ["param1"] = 188, ["z"] = 9, ["name"] = "the_build_spawner:grey"}, {["x"] = 11, ["param2"] = 1, ["y"] = 10, ["param1"] = 62, ["z"] = 1, ["name"] = "stairs:slab_acacia_wood"}, {["x"] = 11, ["meta"] = {["fields"] = {}, ["inventory"] = {}}, ["y"] = 10, ["param1"] = 188, ["z"] = 2, ["name"] = "the_build_spawner:grey"}, {["x"] = 11, ["meta"] = {["fields"] = {}, ["inventory"] = {}}, ["y"] = 10, ["param1"] = 188, ["z"] = 3, ["name"] = "the_build_spawner:grey"}, {["x"] = 11, ["meta"] = {["fields"] = {}, ["inventory"] = {}}, ["y"] = 10, ["param1"] = 188, ["z"] = 4, ["name"] = "the_build_spawner:grey"}, {["x"] = 11, ["meta"] = {["fields"] = {}, ["inventory"] = {}}, ["y"] = 10, ["param1"] = 188, ["z"] = 5, ["name"] = "the_build_spawner:grey"}, {["x"] = 11, ["meta"] = {["fields"] = {}, ["inventory"] = {}}, ["y"] = 10, ["param1"] = 188, ["z"] = 6, ["name"] = "the_build_spawner:grey"}, {["x"] = 11, ["meta"] = {["fields"] = {}, ["inventory"] = {}}, ["y"] = 10, ["param1"] = 188, ["z"] = 7, ["name"] = "the_build_spawner:grey"}, {["x"] = 11, ["meta"] = {["fields"] = {}, ["inventory"] = {}}, ["y"] = 10, ["param1"] = 188, ["z"] = 8, ["name"] = "the_build_spawner:grey"}, {["x"] = 11, ["param2"] = 1, ["y"] = 10, ["param1"] = 62, ["z"] = 9, ["name"] = "stairs:slab_acacia_wood"}, {["x"] = 11, ["y"] = 11, ["param1"] = 62, ["z"] = 2, ["name"] = "stairs:slab_acacia_wood"}, {["x"] = 11, ["meta"] = {["fields"] = {}, ["inventory"] = {}}, ["y"] = 11, ["param1"] = 188, ["z"] = 3, ["name"] = "the_build_spawner:grey"}, {["x"] = 11, ["meta"] = {["fields"] = {}, ["inventory"] = {}}, ["y"] = 11, ["param1"] = 188, ["z"] = 4, ["name"] = "the_build_spawner:grey"}, {["x"] = 11, ["meta"] = {["fields"] = {}, ["inventory"] = {}}, ["y"] = 11, ["param1"] = 188, ["z"] = 5, ["name"] = "the_build_spawner:grey"}, {["x"] = 11, ["meta"] = {["fields"] = {}, ["inventory"] = {}}, ["y"] = 11, ["param1"] = 188, ["z"] = 6, ["name"] = "the_build_spawner:grey"}, {["x"] = 11, ["meta"] = {["fields"] = {}, ["inventory"] = {}}, ["y"] = 11, ["param1"] = 188, ["z"] = 7, ["name"] = "the_build_spawner:grey"}, {["x"] = 11, ["param2"] = 2, ["y"] = 11, ["param1"] = 62, ["z"] = 8, ["name"] = "stairs:slab_acacia_wood"}, {["x"] = 11, ["y"] = 12, ["param1"] = 30, ["z"] = 3, ["name"] = "stairs:slab_acacia_wood"}, {["x"] = 11, ["meta"] = {["fields"] = {}, ["inventory"] = {}}, ["y"] = 12, ["param1"] = 188, ["z"] = 4, ["name"] = "the_build_spawner:grey"}, {["x"] = 11, ["meta"] = {["fields"] = {}, ["inventory"] = {}}, ["y"] = 12, ["param1"] = 188, ["z"] = 5, ["name"] = "the_build_spawner:grey"}, {["x"] = 11, ["meta"] = {["fields"] = {}, ["inventory"] = {}}, ["y"] = 12, ["param1"] = 188, ["z"] = 6, ["name"] = "the_build_spawner:grey"}, {["x"] = 11, ["param2"] = 2, ["y"] = 12, ["param1"] = 30, ["z"] = 7, ["name"] = "stairs:slab_acacia_wood"}, {["x"] = 11, ["y"] = 13, ["param1"] = 14, ["z"] = 4, ["name"] = "stairs:slab_acacia_wood"}, {["x"] = 11, ["meta"] = {["fields"] = {}, ["inventory"] = {}}, ["y"] = 13, ["param1"] = 188, ["z"] = 5, ["name"] = "the_build_spawner:grey"}, {["x"] = 11, ["param2"] = 2, ["y"] = 13, ["param1"] = 14, ["z"] = 6, ["name"] = "stairs:slab_acacia_wood"}, {["x"] = 11, ["y"] = 14, ["param1"] = 14, ["z"] = 5, ["name"] = "stairs:slab_acacia_wood"}}