5:return {{["x"] = 0, ["y"] = 0, ["param1"] = 23, ["z"] = 0, ["name"] = "default:dirt_with_grass"}, {["x"] = 0, ["y"] = 0, ["param1"] = 23, ["z"] = 1, ["name"] = "default:dirt_with_grass"}, {["x"] = 0, ["y"] = 0, ["param1"] = 23, ["z"] = 2, ["name"] = "default:dirt_with_grass"}, {["x"] = 0, ["y"] = 0, ["param1"] = 23, ["z"] = 3, ["name"] = "default:dirt_with_grass"}, {["x"] = 0, ["y"] = 0, ["param1"] = 23, ["z"] = 4, ["name"] = "default:dirt_with_grass"}, {["x"] = 0, ["y"] = 0, ["param1"] = 23, ["z"] = 5, ["name"] = "default:dirt_with_grass"}, {["x"] = 0, ["y"] = 0, ["param1"] = 23, ["z"] = 6, ["name"] = "default:dirt_with_grass"}, {["x"] = 0, ["y"] = 0, ["param1"] = 23, ["z"] = 7, ["name"] = "default:dirt_with_grass"}, {["x"] = 0, ["y"] = 0, ["param1"] = 23, ["z"] = 8, ["name"] = "default:dirt_with_grass"}, {["x"] = 0, ["y"] = 0, ["param1"] = 23, ["z"] = 9, ["name"] = "default:dirt_with_grass"}, {["x"] = 0, ["y"] = 0, ["param1"] = 23, ["z"] = 10, ["name"] = "default:dirt_with_grass"}, {["x"] = 0, ["y"] = 0, ["param1"] = 23, ["z"] = 11, ["name"] = "default:dirt_with_grass"}, {["x"] = 0, ["y"] = 0, ["param1"] = 23, ["z"] = 12, ["name"] = "default:dirt_with_grass"}, {["x"] = 0, ["y"] = 0, ["param1"] = 23, ["z"] = 13, ["name"] = "default:dirt_with_grass"}, {["x"] = 0, ["y"] = 0, ["z"] = 14, ["name"] = "default:dirt_with_grass"}, {["x"] = 0, ["y"] = 0, ["z"] = 15, ["name"] = "default:dirt_with_grass"}, {["x"] = 0, ["y"] = 0, ["z"] = 16, ["name"] = "default:dirt_with_grass"}, {["x"] = 0, ["y"] = 0, ["z"] = 17, ["name"] = "default:dirt_with_grass"}, {["x"] = 0, ["param2"] = 2, ["y"] = 6, ["param1"] = 92, ["z"] = 0, ["name"] = "stairs:slab_stone_block"}, {["x"] = 0, ["param2"] = 2, ["y"] = 6, ["param1"] = 107, ["z"] = 1, ["name"] = "stairs:slab_stone_block"}, {["x"] = 0, ["param2"] = 2, ["y"] = 6, ["param1"] = 123, ["z"] = 2, ["name"] = "stairs:slab_stone_block"}, {["x"] = 0, ["param2"] = 2, ["y"] = 6, ["param1"] = 139, ["z"] = 3, ["name"] = "stairs:slab_stone_block"}, {["x"] = 0, ["param2"] = 2, ["y"] = 6, ["param1"] = 123, ["z"] = 4, ["name"] = "stairs:slab_stone_block"}, {["x"] = 0, ["param2"] = 2, ["y"] = 6, ["param1"] = 139, ["z"] = 5, ["name"] = "stairs:slab_stone_block"}, {["x"] = 0, ["param2"] = 2, ["y"] = 6, ["param1"] = 123, ["z"] = 6, ["name"] = "stairs:slab_stone_block"}, {["x"] = 0, ["param2"] = 2, ["y"] = 6, ["param1"] = 107, ["z"] = 7, ["name"] = "stairs:slab_stone_block"}, {["x"] = 0, ["param2"] = 2, ["y"] = 6, ["param1"] = 91, ["z"] = 8, ["name"] = "stairs:slab_stone_block"}, {["x"] = 0, ["param2"] = 2, ["y"] = 6, ["param1"] = 107, ["z"] = 9, ["name"] = "stairs:slab_stone_block"}, {["x"] = 0, ["param2"] = 2, ["y"] = 6, ["param1"] = 107, ["z"] = 10, ["name"] = "stairs:slab_stone_block"}, {["x"] = 0, ["param2"] = 2, ["y"] = 6, ["param1"] = 123, ["z"] = 11, ["name"] = "stairs:slab_stone_block"}, {["x"] = 0, ["param2"] = 2, ["y"] = 6, ["param1"] = 140, ["z"] = 12, ["name"] = "stairs:slab_stone_block"}, {["x"] = 0, ["param2"] = 2, ["y"] = 6, ["param1"] = 125, ["z"] = 13, ["name"] = "stairs:slab_stone_block"}, {["x"] = 0, ["param2"] = 2, ["y"] = 6, ["param1"] = 110, ["z"] = 14, ["name"] = "stairs:slab_stone_block"}, {["x"] = 0, ["param2"] = 21, ["y"] = 11, ["param1"] = 14, ["z"] = 0, ["name"] = "stairs:slab_stone_block"}, {["x"] = 0, ["param2"] = 21, ["y"] = 11, ["param1"] = 30, ["z"] = 1, ["name"] = "stairs:slab_stone_block"}, {["x"] = 0, ["param2"] = 21, ["y"] = 11, ["param1"] = 46, ["z"] = 2, ["name"] = "stairs:slab_stone_block"}, {["x"] = 0, ["param2"] = 21, ["y"] = 11, ["param1"] = 62, ["z"] = 3, ["name"] = "stairs:slab_stone_block"}, {["x"] = 0, ["param2"] = 21, ["y"] = 11, ["param1"] = 78, ["z"] = 4, ["name"] = "stairs:slab_stone_block"}, {["x"] = 0, ["param2"] = 21, ["y"] = 11, ["param1"] = 94, ["z"] = 5, ["name"] = "stairs:slab_stone_block"}, {["x"] = 0, ["param2"] = 21, ["y"] = 11, ["param1"] = 110, ["z"] = 6, ["name"] = "stairs:slab_stone_block"}, {["x"] = 0, ["param2"] = 21, ["y"] = 11, ["param1"] = 126, ["z"] = 7, ["name"] = "stairs:slab_stone_block"}, {["x"] = 0, ["param2"] = 21, ["y"] = 11, ["param1"] = 142, ["z"] = 8, ["name"] = "stairs:slab_stone_block"}, {["x"] = 0, ["param2"] = 21, ["y"] = 11, ["param1"] = 158, ["z"] = 9, ["name"] = "stairs:slab_stone_block"}, {["x"] = 0, ["param2"] = 21, ["y"] = 11, ["param1"] = 174, ["z"] = 10, ["name"] = "stairs:slab_stone_block"}, {["x"] = 0, ["param2"] = 21, ["y"] = 11, ["param1"] = 158, ["z"] = 11, ["name"] = "stairs:slab_stone_block"}, {["x"] = 0, ["param2"] = 21, ["y"] = 11, ["param1"] = 142, ["z"] = 12, ["name"] = "stairs:slab_stone_block"}, {["x"] = 0, ["param2"] = 21, ["y"] = 11, ["param1"] = 125, ["z"] = 13, ["name"] = "stairs:slab_stone_block"}, {["x"] = 0, ["param2"] = 21, ["y"] = 11, ["param1"] = 110, ["z"] = 14, ["name"] = "stairs:slab_stone_block"}, {["x"] = 1, ["y"] = 0, ["param1"] = 23, ["z"] = 0, ["name"] = "default:dirt_with_grass"}, {["x"] = 1, ["y"] = 0, ["param1"] = 150, ["z"] = 1, ["name"] = "the_build_spawner:white"}, {["x"] = 1, ["y"] = 0, ["param1"] = 150, ["z"] = 2, ["name"] = "the_build_spawner:white"}, {["x"] = 1, ["y"] = 0, ["param1"] = 150, ["z"] = 3, ["name"] = "the_build_spawner:white"}, {["x"] = 1, ["y"] = 0, ["param1"] = 150, ["z"] = 4, ["name"] = "the_build_spawner:white"}, {["x"] = 1, ["y"] = 0, ["param1"] = 150, ["z"] = 5, ["name"] = "the_build_spawner:white"}, {["x"] = 1, ["y"] = 0, ["param1"] = 150, ["z"] = 6, ["name"] = "the_build_spawner:white"}, {["x"] = 1, ["y"] = 0, ["param1"] = 150, ["z"] = 7, ["name"] = "the_build_spawner:white"}, {["x"] = 1, ["y"] = 0, ["param1"] = 150, ["z"] = 8, ["name"] = "the_build_spawner:white"}, {["x"] = 1, ["y"] = 0, ["param1"] = 150, ["z"] = 9, ["name"] = "the_build_spawner:white"}, {["x"] = 1, ["y"] = 0, ["param1"] = 150, ["z"] = 10, ["name"] = "the_build_spawner:white"}, {["x"] = 1, ["y"] = 0, ["param1"] = 150, ["z"] = 11, ["name"] = "the_build_spawner:white"}, {["x"] = 1, ["y"] = 0, ["param1"] = 150, ["z"] = 12, ["name"] = "the_build_spawner:white"}, {["x"] = 1, ["y"] = 0, ["param1"] = 150, ["z"] = 13, ["name"] = "the_build_spawner:white"}, {["x"] = 1, ["y"] = 0, ["z"] = 14, ["name"] = "default:dirt_with_grass"}, {["x"] = 1, ["y"] = 0, ["z"] = 15, ["name"] = "default:dirt_with_grass"}, {["x"] = 1, ["y"] = 0, ["z"] = 16, ["name"] = "default:dirt_with_grass"}, {["x"] = 1, ["y"] = 0, ["z"] = 17, ["name"] = "default:dirt_with_grass"}, {["x"] = 1, ["y"] = 1, ["param1"] = 150, ["z"] = 1, ["name"] = "the_build_spawner:white"}, {["x"] = 1, ["y"] = 1, ["param1"] = 150, ["z"] = 2, ["name"] = "the_build_spawner:white"}, {["x"] = 1, ["y"] = 1, ["param1"] = 150, ["z"] = 3, ["name"] = "the_build_spawner:white"}, {["x"] = 1, ["y"] = 1, ["param1"] = 150, ["z"] = 4, ["name"] = "the_build_spawner:white"}, {["x"] = 1, ["y"] = 1, ["param1"] = 150, ["z"] = 5, ["name"] = "the_build_spawner:white"}, {["x"] = 1, ["y"] = 1, ["param1"] = 150, ["z"] = 6, ["name"] = "the_build_spawner:white"}, {["x"] = 1, ["y"] = 1, ["param1"] = 150, ["z"] = 7, ["name"] = "the_build_spawner:white"}, {["x"] = 1, ["y"] = 1, ["param1"] = 150, ["z"] = 8, ["name"] = "the_build_spawner:white"}, {["x"] = 1, ["y"] = 1, ["param1"] = 150, ["z"] = 9, ["name"] = "the_build_spawner:white"}, {["x"] = 1, ["y"] = 1, ["param1"] = 150, ["z"] = 10, ["name"] = "the_build_spawner:white"}, {["x"] = 1, ["y"] = 1, ["param1"] = 150, ["z"] = 11, ["name"] = "the_build_spawner:white"}, {["x"] = 1, ["y"] = 1, ["param1"] = 150, ["z"] = 12, ["name"] = "the_build_spawner:white"}, {["x"] = 1, ["y"] = 1, ["param1"] = 150, ["z"] = 13, ["name"] = "the_build_spawner:white"}, {["x"] = 1, ["y"] = 1, ["param1"] = 63, ["z"] = 17, ["name"] = "default:grass_1"}, {["x"] = 1, ["y"] = 2, ["param1"] = 150, ["z"] = 1, ["name"] = "the_build_spawner:white"}, {["x"] = 1, ["y"] = 2, ["param1"] = 187, ["z"] = 2, ["name"] = "default:glass"}, {["x"] = 1, ["y"] = 2, ["param1"] = 170, ["z"] = 3, ["name"] = "default:glass"}, {["x"] = 1, ["y"] = 2, ["param1"] = 150, ["z"] = 4, ["name"] = "the_build_spawner:white"}, {["x"] = 1, ["y"] = 2, ["param1"] = 153, ["z"] = 5, ["name"] = "default:glass"}, {["x"] = 1, ["y"] = 2, ["param1"] = 136, ["z"] = 6, ["name"] = "default:glass"}, {["x"] = 1, ["y"] = 2, ["param1"] = 150, ["z"] = 7, ["name"] = "the_build_spawner:white"}, {["x"] = 1, ["y"] = 2, ["param1"] = 103, ["z"] = 8, ["name"] = "default:glass"}, {["x"] = 1, ["y"] = 2, ["param1"] = 104, ["z"] = 9, ["name"] = "default:glass"}, {["x"] = 1, ["y"] = 2, ["param1"] = 150, ["z"] = 10, ["name"] = "the_build_spawner:white"}, {["x"] = 1, ["y"] = 2, ["param1"] = 138, ["z"] = 11, ["name"] = "default:glass"}, {["x"] = 1, ["y"] = 2, ["param1"] = 155, ["z"] = 12, ["name"] = "default:glass"}, {["x"] = 1, ["y"] = 2, ["param1"] = 150, ["z"] = 13, ["name"] = "the_build_spawner:white"}, {["x"] = 1, ["y"] = 3, ["param1"] = 150, ["z"] = 1, ["name"] = "the_build_spawner:white"}, {["x"] = 1, ["y"] = 3, ["param1"] = 170, ["z"] = 2, ["name"] = "default:glass"}, {["x"] = 1, ["y"] = 3, ["param1"] = 170, ["z"] = 3, ["name"] = "default:glass"}, {["x"] = 1, ["y"] = 3, ["param1"] = 150, ["z"] = 4, ["name"] = "the_build_spawner:white"}, {["x"] = 1, ["y"] = 3, ["param1"] = 170, ["z"] = 5, ["name"] = "default:glass"}, {["x"] = 1, ["y"] = 3, ["param1"] = 153, ["z"] = 6, ["name"] = "default:glass"}, {["x"] = 1, ["y"] = 3, ["z"] = 7, ["name"] = "the_build_spawner:white"}, {["x"] = 1, ["y"] = 3, ["param1"] = 119, ["z"] = 8, ["name"] = "default:glass"}, {["x"] = 1, ["y"] = 3, ["param1"] = 120, ["z"] = 9, ["name"] = "default:glass"}, {["x"] = 1, ["y"] = 3, ["param1"] = 150, ["z"] = 10, ["name"] = "the_build_spawner:white"}, {["x"] = 1, ["y"] = 3, ["param1"] = 154, ["z"] = 11, ["name"] = "default:glass"}, {["x"] = 1, ["y"] = 3, ["param1"] = 171, ["z"] = 12, ["name"] = "default:glass"}, {["x"] = 1, ["y"] = 3, ["param1"] = 150, ["z"] = 13, ["name"] = "the_build_spawner:white"}, {["x"] = 1, ["y"] = 4, ["param1"] = 150, ["z"] = 1, ["name"] = "the_build_spawner:white"}, {["x"] = 1, ["y"] = 4, ["param1"] = 170, ["z"] = 2, ["name"] = "default:glass"}, {["x"] = 1, ["y"] = 4, ["param1"] = 187, ["z"] = 3, ["name"] = "default:glass"}, {["x"] = 1, ["y"] = 4, ["param1"] = 150, ["z"] = 4, ["name"] = "the_build_spawner:white"}, {["x"] = 1, ["y"] = 4, ["param1"] = 187, ["z"] = 5, ["name"] = "default:glass"}, {["x"] = 1, ["y"] = 4, ["param1"] = 170, ["z"] = 6, ["name"] = "default:glass"}, {["x"] = 1, ["y"] = 4, ["param1"] = 150, ["z"] = 7, ["name"] = "the_build_spawner:white"}, {["x"] = 1, ["y"] = 4, ["param1"] = 136, ["z"] = 8, ["name"] = "default:glass"}, {["x"] = 1, ["y"] = 4, ["param1"] = 136, ["z"] = 9, ["name"] = "default:glass"}, {["x"] = 1, ["y"] = 4, ["param1"] = 150, ["z"] = 10, ["name"] = "the_build_spawner:white"}, {["x"] = 1, ["y"] = 4, ["param1"] = 170, ["z"] = 11, ["name"] = "default:glass"}, {["x"] = 1, ["y"] = 4, ["param1"] = 187, ["z"] = 12, ["name"] = "default:glass"}, {["x"] = 1, ["y"] = 4, ["param1"] = 150, ["z"] = 13, ["name"] = "the_build_spawner:white"}, {["x"] = 1, ["y"] = 5, ["param1"] = 150, ["z"] = 1, ["name"] = "the_build_spawner:white"}, {["x"] = 1, ["y"] = 5, ["param1"] = 150, ["z"] = 2, ["name"] = "the_build_spawner:white"}, {["x"] = 1, ["y"] = 5, ["param1"] = 150, ["z"] = 3, ["name"] = "the_build_spawner:white"}, {["x"] = 1, ["y"] = 5, ["param1"] = 150, ["z"] = 4, ["name"] = "the_build_spawner:white"}, {["x"] = 1, ["y"] = 5, ["param1"] = 150, ["z"] = 5, ["name"] = "the_build_spawner:white"}, {["x"] = 1, ["y"] = 5, ["param1"] = 150, ["z"] = 6, ["name"] = "the_build_spawner:white"}, {["x"] = 1, ["y"] = 5, ["param1"] = 150, ["z"] = 7, ["name"] = "the_build_spawner:white"}, {["x"] = 1, ["y"] = 5, ["param1"] = 150, ["z"] = 8, ["name"] = "the_build_spawner:white"}, {["x"] = 1, ["y"] = 5, ["param1"] = 150, ["z"] = 9, ["name"] = "the_build_spawner:white"}, {["x"] = 1, ["y"] = 5, ["z"] = 10, ["name"] = "the_build_spawner:white"}, {["x"] = 1, ["y"] = 5, ["param1"] = 150, ["z"] = 11, ["name"] = "the_build_spawner:white"}, {["x"] = 1, ["y"] = 5, ["param1"] = 150, ["z"] = 12, ["name"] = "the_build_spawner:white"}, {["x"] = 1, ["y"] = 5, ["param1"] = 150, ["z"] = 13, ["name"] = "the_build_spawner:white"}, {["x"] = 1, ["param2"] = 2, ["y"] = 6, ["param1"] = 108, ["z"] = 0, ["name"] = "stairs:slab_stone_block"}, {["x"] = 1, ["y"] = 6, ["param1"] = 150, ["z"] = 1, ["name"] = "the_build_spawner:white"}, {["x"] = 1, ["y"] = 6, ["param1"] = 150, ["z"] = 2, ["name"] = "the_build_spawner:white"}, {["x"] = 1, ["y"] = 6, ["param1"] = 150, ["z"] = 3, ["name"] = "the_build_spawner:white"}, {["x"] = 1, ["y"] = 6, ["param1"] = 150, ["z"] = 4, ["name"] = "the_build_spawner:white"}, {["x"] = 1, ["y"] = 6, ["param1"] = 150, ["z"] = 5, ["name"] = "the_build_spawner:white"}, {["x"] = 1, ["y"] = 6, ["param1"] = 150, ["z"] = 6, ["name"] = "the_build_spawner:white"}, {["x"] = 1, ["y"] = 6, ["param1"] = 150, ["z"] = 7, ["name"] = "the_build_spawner:white"}, {["x"] = 1, ["y"] = 6, ["param1"] = 150, ["z"] = 8, ["name"] = "the_build_spawner:white"}, {["x"] = 1, ["y"] = 6, ["param1"] = 150, ["z"] = 9, ["name"] = "the_build_spawner:white"}, {["x"] = 1, ["y"] = 6, ["param1"] = 150, ["z"] = 10, ["name"] = "the_build_spawner:white"}, {["x"] = 1, ["y"] = 6, ["z"] = 11, ["name"] = "the_build_spawner:white"}, {["x"] = 1, ["y"] = 6, ["param1"] = 150, ["z"] = 12, ["name"] = "the_build_spawner:white"}, {["x"] = 1, ["y"] = 6, ["param1"] = 150, ["z"] = 13, ["name"] = "the_build_spawner:white"}, {["x"] = 1, ["param2"] = 2, ["y"] = 6, ["param1"] = 126, ["z"] = 14, ["name"] = "stairs:slab_stone_block"}, {["x"] = 1, ["y"] = 7, ["param1"] = 150, ["z"] = 1, ["name"] = "the_build_spawner:white"}, {["x"] = 1, ["y"] = 7, ["param1"] = 150, ["z"] = 2, ["name"] = "the_build_spawner:white"}, {["x"] = 1, ["y"] = 7, ["param1"] = 150, ["z"] = 3, ["name"] = "the_build_spawner:white"}, {["x"] = 1, ["y"] = 7, ["param1"] = 150, ["z"] = 4, ["name"] = "the_build_spawner:white"}, {["x"] = 1, ["y"] = 7, ["param1"] = 150, ["z"] = 5, ["name"] = "the_build_spawner:white"}, {["x"] = 1, ["y"] = 7, ["param1"] = 150, ["z"] = 6, ["name"] = "the_build_spawner:white"}, {["x"] = 1, ["y"] = 7, ["param1"] = 150, ["z"] = 7, ["name"] = "the_build_spawner:white"}, {["x"] = 1, ["y"] = 7, ["param1"] = 150, ["z"] = 8, ["name"] = "the_build_spawner:white"}, {["x"] = 1, ["y"] = 7, ["param1"] = 150, ["z"] = 9, ["name"] = "the_build_spawner:white"}, {["x"] = 1, ["y"] = 7, ["param1"] = 150, ["z"] = 10, ["name"] = "the_build_spawner:white"}, {["x"] = 1, ["y"] = 7, ["param1"] = 150, ["z"] = 11, ["name"] = "the_build_spawner:white"}, {["x"] = 1, ["y"] = 7, ["param1"] = 150, ["z"] = 12, ["name"] = "the_build_spawner:white"}, {["x"] = 1, ["y"] = 7, ["param1"] = 150, ["z"] = 13, ["name"] = "the_build_spawner:white"}, {["x"] = 1, ["y"] = 8, ["param1"] = 150, ["z"] = 1, ["name"] = "the_build_spawner:white"}, {["x"] = 1, ["y"] = 8, ["param1"] = 77, ["z"] = 2, ["name"] = "default:glass"}, {["x"] = 1, ["y"] = 8, ["param1"] = 93, ["z"] = 3, ["name"] = "default:glass"}, {["x"] = 1, ["y"] = 8, ["param1"] = 150, ["z"] = 4, ["name"] = "the_build_spawner:white"}, {["x"] = 1, ["y"] = 8, ["param1"] = 93, ["z"] = 5, ["name"] = "default:glass"}, {["x"] = 1, ["y"] = 8, ["param1"] = 77, ["z"] = 6, ["name"] = "default:glass"}, {["x"] = 1, ["y"] = 8, ["param1"] = 150, ["z"] = 7, ["name"] = "the_build_spawner:white"}, {["x"] = 1, ["y"] = 8, ["param1"] = 141, ["z"] = 8, ["name"] = "default:glass"}, {["x"] = 1, ["y"] = 8, ["param1"] = 157, ["z"] = 9, ["name"] = "default:glass"}, {["x"] = 1, ["y"] = 8, ["param1"] = 150, ["z"] = 10, ["name"] = "the_build_spawner:white"}, {["x"] = 1, ["y"] = 8, ["param1"] = 157, ["z"] = 11, ["name"] = "default:glass"}, {["x"] = 1, ["y"] = 8, ["param1"] = 141, ["z"] = 12, ["name"] = "default:glass"}, {["x"] = 1, ["y"] = 8, ["param1"] = 150, ["z"] = 13, ["name"] = "the_build_spawner:white"}, {["x"] = 1, ["y"] = 9, ["param1"] = 150, ["z"] = 1, ["name"] = "the_build_spawner:white"}, {["x"] = 1, ["y"] = 9, ["param1"] = 62, ["z"] = 2, ["name"] = "default:glass"}, {["x"] = 1, ["y"] = 9, ["param1"] = 78, ["z"] = 3, ["name"] = "default:glass"}, {["x"] = 1, ["y"] = 9, ["param1"] = 150, ["z"] = 4, ["name"] = "the_build_spawner:white"}, {["x"] = 1, ["y"] = 9, ["param1"] = 78, ["z"] = 5, ["name"] = "default:glass"}, {["x"] = 1, ["y"] = 9, ["param1"] = 94, ["z"] = 6, ["name"] = "default:glass"}, {["x"] = 1, ["y"] = 9, ["param1"] = 150, ["z"] = 7, ["name"] = "the_build_spawner:white"}, {["x"] = 1, ["y"] = 9, ["param1"] = 158, ["z"] = 8, ["name"] = "default:glass"}, {["x"] = 1, ["y"] = 9, ["param1"] = 174, ["z"] = 9, ["name"] = "default:glass"}, {["x"] = 1, ["y"] = 9, ["param1"] = 150, ["z"] = 10, ["name"] = "the_build_spawner:white"}, {["x"] = 1, ["y"] = 9, ["param1"] = 174, ["z"] = 11, ["name"] = "default:glass"}, {["x"] = 1, ["y"] = 9, ["param1"] = 158, ["z"] = 12, ["name"] = "default:glass"}, {["x"] = 1, ["y"] = 9, ["param1"] = 150, ["z"] = 13, ["name"] = "the_build_spawner:white"}, {["x"] = 1, ["y"] = 10, ["param1"] = 150, ["z"] = 1, ["name"] = "the_build_spawner:white"}, {["x"] = 1, ["y"] = 10, ["param1"] = 46, ["z"] = 2, ["name"] = "default:glass"}, {["x"] = 1, ["y"] = 10, ["param1"] = 62, ["z"] = 3, ["name"] = "default:glass"}, {["x"] = 1, ["y"] = 10, ["param1"] = 150, ["z"] = 4, ["name"] = "the_build_spawner:white"}, {["x"] = 1, ["y"] = 10, ["param1"] = 94, ["z"] = 5, ["name"] = "default:glass"}, {["x"] = 1, ["y"] = 10, ["param1"] = 110, ["z"] = 6, ["name"] = "default:glass"}, {["x"] = 1, ["y"] = 10, ["param1"] = 150, ["z"] = 7, ["name"] = "the_build_spawner:white"}, {["x"] = 1, ["y"] = 10, ["param1"] = 174, ["z"] = 8, ["name"] = "default:glass"}, {["x"] = 1, ["y"] = 10, ["param1"] = 190, ["z"] = 9, ["name"] = "default:glass"}, {["x"] = 1, ["y"] = 10, ["param1"] = 150, ["z"] = 10, ["name"] = "the_build_spawner:white"}, {["x"] = 1, ["y"] = 10, ["param1"] = 190, ["z"] = 11, ["name"] = "default:glass"}, {["x"] = 1, ["y"] = 10, ["param1"] = 174, ["z"] = 12, ["name"] = "default:glass"}, {["x"] = 1, ["y"] = 10, ["param1"] = 150, ["z"] = 13, ["name"] = "the_build_spawner:white"}, {["x"] = 1, ["param2"] = 21, ["y"] = 11, ["param1"] = 30, ["z"] = 0, ["name"] = "stairs:slab_stone_block"}, {["x"] = 1, ["y"] = 11, ["param1"] = 150, ["z"] = 1, ["name"] = "the_build_spawner:white"}, {["x"] = 1, ["y"] = 11, ["param1"] = 150, ["z"] = 2, ["name"] = "the_build_spawner:white"}, {["x"] = 1, ["y"] = 11, ["param1"] = 150, ["z"] = 3, ["name"] = "the_build_spawner:white"}, {["x"] = 1, ["y"] = 11, ["param1"] = 150, ["z"] = 4, ["name"] = "the_build_spawner:white"}, {["x"] = 1, ["y"] = 11, ["param1"] = 150, ["z"] = 5, ["name"] = "the_build_spawner:white"}, {["x"] = 1, ["y"] = 11, ["param1"] = 150, ["z"] = 6, ["name"] = "the_build_spawner:white"}, {["x"] = 1, ["y"] = 11, ["param1"] = 150, ["z"] = 7, ["name"] = "the_build_spawner:white"}, {["x"] = 1, ["y"] = 11, ["param1"] = 150, ["z"] = 8, ["name"] = "the_build_spawner:white"}, {["x"] = 1, ["y"] = 11, ["param1"] = 150, ["z"] = 9, ["name"] = "the_build_spawner:white"}, {["x"] = 1, ["y"] = 11, ["param1"] = 150, ["z"] = 10, ["name"] = "the_build_spawner:white"}, {["x"] = 1, ["y"] = 11, ["param1"] = 150, ["z"] = 11, ["name"] = "the_build_spawner:white"}, {["x"] = 1, ["y"] = 11, ["param1"] = 150, ["z"] = 12, ["name"] = "the_build_spawner:white"}, {["x"] = 1, ["y"] = 11, ["param1"] = 150, ["z"] = 13, ["name"] = "the_build_spawner:white"}, {["x"] = 1, ["param2"] = 21, ["y"] = 11, ["param1"] = 126, ["z"] = 14, ["name"] = "stairs:slab_stone_block"}, {["x"] = 1, ["y"] = 12, ["param1"] = 62, ["z"] = 1, ["name"] = "stairs:slab_stone_block"}, {["x"] = 1, ["y"] = 12, ["param1"] = 78, ["z"] = 2, ["name"] = "stairs:slab_stone_block"}, {["x"] = 1, ["y"] = 12, ["param1"] = 94, ["z"] = 3, ["name"] = "stairs:slab_stone_block"}, {["x"] = 1, ["y"] = 12, ["param1"] = 110, ["z"] = 4, ["name"] = "stairs:slab_stone_block"}, {["x"] = 1, ["y"] = 12, ["param1"] = 126, ["z"] = 5, ["name"] = "stairs:slab_stone_block"}, {["x"] = 1, ["y"] = 12, ["param1"] = 142, ["z"] = 6, ["name"] = "stairs:slab_stone_block"}, {["x"] = 1, ["y"] = 12, ["param1"] = 158, ["z"] = 7, ["name"] = "stairs:slab_stone_block"}, {["x"] = 1, ["y"] = 12, ["param1"] = 174, ["z"] = 8, ["name"] = "stairs:slab_stone_block"}, {["x"] = 1, ["y"] = 12, ["param1"] = 190, ["z"] = 9, ["name"] = "stairs:slab_stone_block"}, {["x"] = 1, ["y"] = 12, ["param1"] = 206, ["z"] = 10, ["name"] = "stairs:slab_stone_block"}, {["x"] = 1, ["y"] = 12, ["param1"] = 190, ["z"] = 11, ["name"] = "stairs:slab_stone_block"}, {["x"] = 1, ["y"] = 12, ["param1"] = 174, ["z"] = 12, ["name"] = "stairs:slab_stone_block"}, {["x"] = 1, ["param2"] = 3, ["y"] = 12, ["param1"] = 158, ["z"] = 13, ["name"] = "stairs:slab_stone_block"}, {["x"] = 2, ["y"] = 0, ["param1"] = 23, ["z"] = 0, ["name"] = "default:dirt_with_grass"}, {["x"] = 2, ["y"] = 0, ["param1"] = 150, ["z"] = 1, ["name"] = "the_build_spawner:white"}, {["x"] = 2, ["y"] = 0, ["z"] = 2, ["name"] = "the_build_spawner:white"}, {["x"] = 2, ["y"] = 0, ["param1"] = 23, ["z"] = 3, ["name"] = "the_build_spawner:black"}, {["x"] = 2, ["y"] = 0, ["z"] = 4, ["name"] = "the_build_spawner:white"}, {["x"] = 2, ["y"] = 0, ["param1"] = 23, ["z"] = 5, ["name"] = "the_build_spawner:black"}, {["x"] = 2, ["y"] = 0, ["z"] = 6, ["name"] = "the_build_spawner:white"}, {["x"] = 2, ["y"] = 0, ["param1"] = 23, ["z"] = 7, ["name"] = "the_build_spawner:black"}, {["x"] = 2, ["y"] = 0, ["z"] = 8, ["name"] = "the_build_spawner:white"}, {["x"] = 2, ["y"] = 0, ["param1"] = 23, ["z"] = 9, ["name"] = "the_build_spawner:black"}, {["x"] = 2, ["y"] = 0, ["z"] = 10, ["name"] = "the_build_spawner:white"}, {["x"] = 2, ["y"] = 0, ["param1"] = 23, ["z"] = 11, ["name"] = "the_build_spawner:black"}, {["x"] = 2, ["y"] = 0, ["z"] = 12, ["name"] = "the_build_spawner:white"}, {["x"] = 2, ["y"] = 0, ["param1"] = 150, ["z"] = 13, ["name"] = "the_build_spawner:white"}, {["x"] = 2, ["y"] = 0, ["z"] = 14, ["name"] = "default:dirt_with_grass"}, {["x"] = 2, ["y"] = 0, ["z"] = 15, ["name"] = "default:dirt_with_grass"}, {["x"] = 2, ["y"] = 0, ["z"] = 16, ["name"] = "default:dirt_with_grass"}, {["x"] = 2, ["y"] = 0, ["z"] = 17, ["name"] = "default:dirt_with_grass"}, {["x"] = 2, ["y"] = 1, ["param1"] = 150, ["z"] = 1, ["name"] = "the_build_spawner:white"}, {["x"] = 2, ["y"] = 1, ["z"] = 7, ["name"] = "the_build_spawner:white"}, {["x"] = 2, ["meta"] = {["fields"] = {["formspec"] = "field[text;;${text}]"}, ["inventory"] = {}}, ["param2"] = 4, ["y"] = 1, ["param1"] = 103, ["z"] = 8, ["name"] = "default:sign_wall_wood"}, {["x"] = 2, ["param2"] = 3, ["y"] = 1, ["param1"] = 104, ["z"] = 9, ["name"] = "stairs:stair_wood"}, {["x"] = 2, ["param2"] = 3, ["y"] = 1, ["param1"] = 121, ["z"] = 10, ["name"] = "stairs:stair_wood"}, {["x"] = 2, ["param2"] = 3, ["y"] = 1, ["param1"] = 138, ["z"] = 11, ["name"] = "stairs:stair_wood"}, {["x"] = 2, ["y"] = 1, ["z"] = 12, ["name"] = "default:wood"}, {["x"] = 2, ["y"] = 1, ["param1"] = 150, ["z"] = 13, ["name"] = "the_build_spawner:white"}, {["x"] = 2, ["y"] = 2, ["param1"] = 187, ["z"] = 1, ["name"] = "default:glass"}, {["x"] = 2, ["y"] = 2, ["z"] = 7, ["name"] = "the_build_spawner:white"}, {["x"] = 2, ["y"] = 2, ["param1"] = 157, ["z"] = 13, ["name"] = "default:glass"}, {["x"] = 2, ["y"] = 3, ["param1"] = 171, ["z"] = 1, ["name"] = "default:glass"}, {["x"] = 2, ["y"] = 3, ["z"] = 7, ["name"] = "the_build_spawner:white"}, {["x"] = 2, ["y"] = 3, ["param1"] = 173, ["z"] = 13, ["name"] = "default:glass"}, {["x"] = 2, ["y"] = 4, ["param1"] = 171, ["z"] = 1, ["name"] = "default:glass"}, {["x"] = 2, ["y"] = 4, ["z"] = 7, ["name"] = "the_build_spawner:white"}, {["x"] = 2, ["y"] = 4, ["param1"] = 189, ["z"] = 13, ["name"] = "default:glass"}, {["x"] = 2, ["y"] = 5, ["param1"] = 150, ["z"] = 1, ["name"] = "the_build_spawner:white"}, {["x"] = 2, ["y"] = 5, ["param1"] = 238, ["z"] = 4, ["name"] = "default:mese_post_light_aspen_wood"}, {["x"] = 2, ["y"] = 5, ["z"] = 7, ["name"] = "the_build_spawner:white"}, {["x"] = 2, ["y"] = 5, ["z"] = 12, ["name"] = "the_build_spawner:white"}, {["x"] = 2, ["y"] = 5, ["param1"] = 150, ["z"] = 13, ["name"] = "the_build_spawner:white"}, {["x"] = 2, ["param2"] = 2, ["y"] = 6, ["param1"] = 124, ["z"] = 0, ["name"] = "stairs:slab_stone_block"}, {["x"] = 2, ["y"] = 6, ["param1"] = 150, ["z"] = 1, ["name"] = "the_build_spawner:white"}, {["x"] = 2, ["y"] = 6, ["param1"] = 28, ["z"] = 2, ["name"] = "the_build_spawner:white"}, {["x"] = 2, ["y"] = 6, ["param1"] = 44, ["z"] = 3, ["name"] = "the_build_spawner:white"}, {["x"] = 2, ["y"] = 6, ["param1"] = 60, ["z"] = 4, ["name"] = "the_build_spawner:white"}, {["x"] = 2, ["y"] = 6, ["param1"] = 76, ["z"] = 5, ["name"] = "the_build_spawner:white"}, {["x"] = 2, ["y"] = 6, ["param1"] = 92, ["z"] = 6, ["name"] = "the_build_spawner:white"}, {["x"] = 2, ["y"] = 6, ["param1"] = 108, ["z"] = 7, ["name"] = "the_build_spawner:white"}, {["x"] = 2, ["y"] = 6, ["param1"] = 124, ["z"] = 8, ["name"] = "the_build_spawner:white"}, {["x"] = 2, ["y"] = 6, ["param1"] = 108, ["z"] = 9, ["name"] = "the_build_spawner:white"}, {["x"] = 2, ["y"] = 6, ["param1"] = 92, ["z"] = 10, ["name"] = "the_build_spawner:white"}, {["x"] = 2, ["y"] = 6, ["param1"] = 108, ["z"] = 11, ["name"] = "the_build_spawner:white"}, {["x"] = 2, ["y"] = 6, ["z"] = 12, ["name"] = "the_build_spawner:white"}, {["x"] = 2, ["y"] = 6, ["param1"] = 150, ["z"] = 13, ["name"] = "the_build_spawner:white"}, {["x"] = 2, ["param2"] = 2, ["y"] = 6, ["param1"] = 142, ["z"] = 14, ["name"] = "stairs:slab_stone_block"}, {["x"] = 2, ["y"] = 7, ["param1"] = 150, ["z"] = 1, ["name"] = "the_build_spawner:white"}, {["x"] = 2, ["meta"] = {["fields"] = {["formspec"] = "field[text;;${text}]"}, ["inventory"] = {}}, ["param2"] = 2, ["y"] = 7, ["param1"] = 45, ["z"] = 2, ["name"] = "default:sign_wall_wood"}, {["x"] = 2, ["meta"] = {["fields"] = {["formspec"] = "field[text;;${text}]"}, ["inventory"] = {}}, ["param2"] = 4, ["y"] = 7, ["param1"] = 61, ["z"] = 3, ["name"] = "default:sign_wall_wood"}, {["x"] = 2, ["param2"] = 3, ["y"] = 7, ["param1"] = 45, ["z"] = 4, ["name"] = "stairs:stair_wood"}, {["x"] = 2, ["param2"] = 3, ["y"] = 7, ["param1"] = 61, ["z"] = 5, ["name"] = "stairs:stair_wood"}, {["x"] = 2, ["meta"] = {["fields"] = {["formspec"] = "field[text;;${text}]"}, ["inventory"] = {}}, ["param2"] = 5, ["y"] = 7, ["param1"] = 77, ["z"] = 6, ["name"] = "default:sign_wall_wood"}, {["x"] = 2, ["y"] = 7, ["z"] = 7, ["name"] = "the_build_spawner:white"}, {["x"] = 2, ["y"] = 7, ["z"] = 8, ["name"] = "default:steelblock"}, {["x"] = 2, ["y"] = 7, ["z"] = 10, ["name"] = "default:steelblock"}, {["x"] = 2, ["y"] = 7, ["z"] = 12, ["name"] = "default:steelblock"}, {["x"] = 2, ["y"] = 7, ["param1"] = 150, ["z"] = 13, ["name"] = "the_build_spawner:white"}, {["x"] = 2, ["y"] = 8, ["param1"] = 77, ["z"] = 1, ["name"] = "default:glass"}, {["x"] = 2, ["y"] = 8, ["z"] = 7, ["name"] = "the_build_spawner:white"}, {["x"] = 2, ["y"] = 8, ["param1"] = 141, ["z"] = 13, ["name"] = "default:glass"}, {["x"] = 2, ["y"] = 9, ["param1"] = 62, ["z"] = 1, ["name"] = "default:glass"}, {["x"] = 2, ["y"] = 9, ["z"] = 7, ["name"] = "the_build_spawner:white"}, {["x"] = 2, ["y"] = 9, ["param1"] = 158, ["z"] = 13, ["name"] = "default:glass"}, {["x"] = 2, ["y"] = 10, ["param1"] = 46, ["z"] = 1, ["name"] = "default:glass"}, {["x"] = 2, ["y"] = 10, ["z"] = 7, ["name"] = "the_build_spawner:white"}, {["x"] = 2, ["y"] = 10, ["param1"] = 174, ["z"] = 13, ["name"] = "default:glass"}, {["x"] = 2, ["param2"] = 21, ["y"] = 11, ["param1"] = 46, ["z"] = 0, ["name"] = "stairs:slab_stone_block"}, {["x"] = 2, ["y"] = 11, ["param1"] = 150, ["z"] = 1, ["name"] = "the_build_spawner:white"}, {["x"] = 2, ["y"] = 11, ["z"] = 7, ["name"] = "the_build_spawner:white"}, {["x"] = 2, ["y"] = 11, ["param1"] = 238, ["z"] = 10, ["name"] = "default:mese_post_light_aspen_wood"}, {["x"] = 2, ["y"] = 11, ["param1"] = 150, ["z"] = 13, ["name"] = "the_build_spawner:white"}, {["x"] = 2, ["param2"] = 21, ["y"] = 11, ["param1"] = 142, ["z"] = 14, ["name"] = "stairs:slab_stone_block"}, {["x"] = 2, ["y"] = 12, ["param1"] = 78, ["z"] = 1, ["name"] = "stairs:slab_stone_block"}, {["x"] = 2, ["y"] = 12, ["param1"] = 94, ["z"] = 2, ["name"] = "stairs:slab_stone_block"}, {["x"] = 2, ["y"] = 12, ["param1"] = 110, ["z"] = 3, ["name"] = "stairs:slab_stone_block"}, {["x"] = 2, ["y"] = 12, ["param1"] = 126, ["z"] = 4, ["name"] = "stairs:slab_stone_block"}, {["x"] = 2, ["y"] = 12, ["param1"] = 142, ["z"] = 5, ["name"] = "stairs:slab_stone_block"}, {["x"] = 2, ["y"] = 12, ["param1"] = 158, ["z"] = 6, ["name"] = "stairs:slab_stone_block"}, {["x"] = 2, ["y"] = 12, ["param1"] = 174, ["z"] = 7, ["name"] = "stairs:slab_stone_block"}, {["x"] = 2, ["y"] = 12, ["param1"] = 190, ["z"] = 8, ["name"] = "stairs:slab_stone_block"}, {["x"] = 2, ["y"] = 12, ["param1"] = 206, ["z"] = 9, ["name"] = "stairs:slab_stone_block"}, {["x"] = 2, ["y"] = 12, ["param1"] = 222, ["z"] = 10, ["name"] = "stairs:slab_stone_block"}, {["x"] = 2, ["y"] = 12, ["param1"] = 206, ["z"] = 11, ["name"] = "stairs:slab_stone_block"}, {["x"] = 2, ["y"] = 12, ["param1"] = 190, ["z"] = 12, ["name"] = "stairs:slab_stone_block"}, {["x"] = 2, ["y"] = 12, ["param1"] = 174, ["z"] = 13, ["name"] = "stairs:slab_stone_block"}, {["x"] = 3, ["y"] = 0, ["param1"] = 23, ["z"] = 0, ["name"] = "default:dirt_with_grass"}, {["x"] = 3, ["y"] = 0, ["param1"] = 150, ["z"] = 1, ["name"] = "the_build_spawner:white"}, {["x"] = 3, ["y"] = 0, ["param1"] = 23, ["z"] = 2, ["name"] = "the_build_spawner:black"}, {["x"] = 3, ["y"] = 0, ["z"] = 3, ["name"] = "the_build_spawner:white"}, {["x"] = 3, ["y"] = 0, ["param1"] = 23, ["z"] = 4, ["name"] = "the_build_spawner:black"}, {["x"] = 3, ["y"] = 0, ["z"] = 5, ["name"] = "the_build_spawner:white"}, {["x"] = 3, ["y"] = 0, ["param1"] = 23, ["z"] = 6, ["name"] = "the_build_spawner:black"}, {["x"] = 3, ["y"] = 0, ["z"] = 7, ["name"] = "the_build_spawner:white"}, {["x"] = 3, ["y"] = 0, ["param1"] = 23, ["z"] = 8, ["name"] = "the_build_spawner:black"}, {["x"] = 3, ["y"] = 0, ["z"] = 9, ["name"] = "the_build_spawner:white"}, {["x"] = 3, ["y"] = 0, ["param1"] = 23, ["z"] = 10, ["name"] = "the_build_spawner:black"}, {["x"] = 3, ["y"] = 0, ["z"] = 11, ["name"] = "the_build_spawner:white"}, {["x"] = 3, ["y"] = 0, ["param1"] = 23, ["z"] = 12, ["name"] = "the_build_spawner:black"}, {["x"] = 3, ["y"] = 0, ["param1"] = 150, ["z"] = 13, ["name"] = "the_build_spawner:white"}, {["x"] = 3, ["y"] = 0, ["z"] = 14, ["name"] = "default:dirt_with_grass"}, {["x"] = 3, ["y"] = 0, ["z"] = 15, ["name"] = "default:dirt_with_grass"}, {["x"] = 3, ["y"] = 0, ["z"] = 16, ["name"] = "default:dirt_with_grass"}, {["x"] = 3, ["y"] = 0, ["z"] = 17, ["name"] = "default:dirt_with_grass"}, {["x"] = 3, ["y"] = 1, ["param1"] = 150, ["z"] = 1, ["name"] = "the_build_spawner:white"}, {["x"] = 3, ["meta"] = {["fields"] = {["infotext"] = "\27(T@default)Chest\27E"}, ["inventory"] = {["main"] = {"", "", "", "", "", "", "", "", "", "", "", "", "", "", "", "", "", "", "", "", "", "", "", "", "", "", "", "", "", "", "", ""}}}, ["param2"] = 2, ["y"] = 1, ["param1"] = 204, ["z"] = 2, ["name"] = "default:chest"}, {["x"] = 3, ["y"] = 1, ["z"] = 7, ["name"] = "the_build_spawner:white"}, {["x"] = 3, ["param2"] = 3, ["y"] = 1, ["param1"] = 137, ["z"] = 10, ["name"] = "stairs:slab_wood"}, {["x"] = 3, ["y"] = 1, ["param1"] = 171, ["z"] = 12, ["name"] = "stairs:stair_wood"}, {["x"] = 3, ["y"] = 1, ["param1"] = 150, ["z"] = 13, ["name"] = "the_build_spawner:white"}, {["x"] = 3, ["y"] = 2, ["param1"] = 204, ["z"] = 1, ["name"] = "default:glass"}, {["x"] = 3, ["y"] = 2, ["z"] = 7, ["name"] = "the_build_spawner:white"}, {["x"] = 3, ["y"] = 2, ["param1"] = 173, ["z"] = 13, ["name"] = "default:glass"}, {["x"] = 3, ["y"] = 3, ["param1"] = 187, ["z"] = 1, ["name"] = "default:glass"}, {["x"] = 3, ["param2"] = 8, ["y"] = 3, ["param1"] = 187, ["z"] = 6, ["name"] = "stairs:slab_obsidianbrick"}, {["x"] = 3, ["y"] = 3, ["z"] = 7, ["name"] = "the_build_spawner:white"}, {["x"] = 3, ["y"] = 3, ["param1"] = 189, ["z"] = 13, ["name"] = "default:glass"}, {["x"] = 3, ["y"] = 4, ["param1"] = 187, ["z"] = 1, ["name"] = "default:glass"}, {["x"] = 3, ["param2"] = 8, ["y"] = 4, ["param1"] = 204, ["z"] = 6, ["name"] = "stairs:slab_obsidianbrick"}, {["x"] = 3, ["y"] = 4, ["z"] = 7, ["name"] = "the_build_spawner:white"}, {["x"] = 3, ["y"] = 4, ["param1"] = 205, ["z"] = 13, ["name"] = "default:glass"}, {["x"] = 3, ["y"] = 5, ["param1"] = 150, ["z"] = 1, ["name"] = "the_build_spawner:white"}, {["x"] = 3, ["y"] = 5, ["z"] = 7, ["name"] = "the_build_spawner:white"}, {["x"] = 3, ["y"] = 5, ["z"] = 12, ["name"] = "the_build_spawner:white"}, {["x"] = 3, ["y"] = 5, ["param1"] = 150, ["z"] = 13, ["name"] = "the_build_spawner:white"}, {["x"] = 3, ["param2"] = 2, ["y"] = 6, ["param1"] = 140, ["z"] = 0, ["name"] = "stairs:slab_stone_block"}, {["x"] = 3, ["y"] = 6, ["param1"] = 150, ["z"] = 1, ["name"] = "the_build_spawner:white"}, {["x"] = 3, ["y"] = 6, ["param1"] = 44, ["z"] = 2, ["name"] = "the_build_spawner:white"}, {["x"] = 3, ["y"] = 6, ["param1"] = 60, ["z"] = 3, ["name"] = "the_build_spawner:white"}, {["x"] = 3, ["y"] = 6, ["param1"] = 76, ["z"] = 4, ["name"] = "the_build_spawner:white"}, {["x"] = 3, ["y"] = 6, ["param1"] = 92, ["z"] = 5, ["name"] = "the_build_spawner:white"}, {["x"] = 3, ["y"] = 6, ["param1"] = 108, ["z"] = 6, ["name"] = "the_build_spawner:white"}, {["x"] = 3, ["y"] = 6, ["param1"] = 124, ["z"] = 7, ["name"] = "the_build_spawner:white"}, {["x"] = 3, ["y"] = 6, ["param1"] = 140, ["z"] = 8, ["name"] = "the_build_spawner:white"}, {["x"] = 3, ["y"] = 6, ["param1"] = 124, ["z"] = 9, ["name"] = "the_build_spawner:white"}, {["x"] = 3, ["y"] = 6, ["param1"] = 108, ["z"] = 10, ["name"] = "the_build_spawner:white"}, {["x"] = 3, ["y"] = 6, ["param1"] = 124, ["z"] = 11, ["name"] = "the_build_spawner:white"}, {["x"] = 3, ["y"] = 6, ["param1"] = 108, ["z"] = 12, ["name"] = "the_build_spawner:white"}, {["x"] = 3, ["y"] = 6, ["param1"] = 150, ["z"] = 13, ["name"] = "the_build_spawner:white"}, {["x"] = 3, ["param2"] = 2, ["y"] = 6, ["param1"] = 158, ["z"] = 14, ["name"] = "stairs:slab_stone_block"}, {["x"] = 3, ["y"] = 7, ["param1"] = 150, ["z"] = 1, ["name"] = "the_build_spawner:white"}, {["x"] = 3, ["param2"] = 2, ["y"] = 7, ["param1"] = 61, ["z"] = 2, ["name"] = "stairs:stair_wood"}, {["x"] = 3, ["y"] = 7, ["z"] = 7, ["name"] = "the_build_spawner:white"}, {["x"] = 3, ["y"] = 7, ["z"] = 8, ["name"] = "default:steelblock"}, {["x"] = 3, ["y"] = 7, ["z"] = 10, ["name"] = "default:steelblock"}, {["x"] = 3, ["y"] = 7, ["z"] = 12, ["name"] = "default:steelblock"}, {["x"] = 3, ["y"] = 7, ["param1"] = 150, ["z"] = 13, ["name"] = "the_build_spawner:white"}, {["x"] = 3, ["y"] = 8, ["param1"] = 93, ["z"] = 1, ["name"] = "default:glass"}, {["x"] = 3, ["y"] = 8, ["z"] = 7, ["name"] = "the_build_spawner:white"}, {["x"] = 3, ["y"] = 8, ["param1"] = 157, ["z"] = 13, ["name"] = "default:glass"}, {["x"] = 3, ["y"] = 9, ["param1"] = 77, ["z"] = 1, ["name"] = "default:glass"}, {["x"] = 3, ["y"] = 9, ["z"] = 7, ["name"] = "the_build_spawner:white"}, {["x"] = 3, ["y"] = 9, ["param1"] = 173, ["z"] = 13, ["name"] = "default:glass"}, {["x"] = 3, ["y"] = 10, ["param1"] = 61, ["z"] = 1, ["name"] = "default:glass"}, {["x"] = 3, ["y"] = 10, ["z"] = 7, ["name"] = "the_build_spawner:white"}, {["x"] = 3, ["y"] = 10, ["param1"] = 189, ["z"] = 13, ["name"] = "default:glass"}, {["x"] = 3, ["param2"] = 21, ["y"] = 11, ["param1"] = 61, ["z"] = 0, ["name"] = "stairs:slab_stone_block"}, {["x"] = 3, ["y"] = 11, ["param1"] = 150, ["z"] = 1, ["name"] = "the_build_spawner:white"}, {["x"] = 3, ["y"] = 11, ["z"] = 7, ["name"] = "the_build_spawner:white"}, {["x"] = 3, ["y"] = 11, ["param1"] = 150, ["z"] = 13, ["name"] = "the_build_spawner:white"}, {["x"] = 3, ["param2"] = 21, ["y"] = 11, ["param1"] = 158, ["z"] = 14, ["name"] = "stairs:slab_stone_block"}, {["x"] = 3, ["y"] = 12, ["param1"] = 93, ["z"] = 1, ["name"] = "stairs:slab_stone_block"}, {["x"] = 3, ["y"] = 12, ["param1"] = 109, ["z"] = 2, ["name"] = "stairs:slab_stone_block"}, {["x"] = 3, ["y"] = 12, ["param1"] = 125, ["z"] = 3, ["name"] = "stairs:slab_stone_block"}, {["x"] = 3, ["y"] = 12, ["param1"] = 141, ["z"] = 4, ["name"] = "stairs:slab_stone_block"}, {["x"] = 3, ["y"] = 12, ["param1"] = 157, ["z"] = 5, ["name"] = "stairs:slab_stone_block"}, {["x"] = 3, ["y"] = 12, ["param1"] = 173, ["z"] = 6, ["name"] = "stairs:slab_stone_block"}, {["x"] = 3, ["y"] = 12, ["param1"] = 189, ["z"] = 7, ["name"] = "stairs:slab_stone_block"}, {["x"] = 3, ["y"] = 12, ["param1"] = 205, ["z"] = 8, ["name"] = "stairs:slab_stone_block"}, {["x"] = 3, ["y"] = 12, ["param1"] = 189, ["z"] = 9, ["name"] = "stairs:slab_stone_block"}, {["x"] = 3, ["y"] = 12, ["param1"] = 205, ["z"] = 10, ["name"] = "stairs:slab_stone_block"}, {["x"] = 3, ["y"] = 12, ["param1"] = 189, ["z"] = 11, ["name"] = "stairs:slab_stone_block"}, {["x"] = 3, ["y"] = 12, ["param1"] = 205, ["z"] = 12, ["name"] = "stairs:slab_stone_block"}, {["x"] = 3, ["y"] = 12, ["param1"] = 190, ["z"] = 13, ["name"] = "stairs:slab_stone_block"}, {["x"] = 4, ["y"] = 0, ["param1"] = 23, ["z"] = 0, ["name"] = "default:dirt_with_grass"}, {["x"] = 4, ["y"] = 0, ["param1"] = 150, ["z"] = 1, ["name"] = "the_build_spawner:white"}, {["x"] = 4, ["y"] = 0, ["z"] = 2, ["name"] = "the_build_spawner:white"}, {["x"] = 4, ["y"] = 0, ["param1"] = 23, ["z"] = 3, ["name"] = "the_build_spawner:black"}, {["x"] = 4, ["y"] = 0, ["z"] = 4, ["name"] = "the_build_spawner:white"}, {["x"] = 4, ["y"] = 0, ["param1"] = 23, ["z"] = 5, ["name"] = "the_build_spawner:black"}, {["x"] = 4, ["y"] = 0, ["z"] = 6, ["name"] = "the_build_spawner:white"}, {["x"] = 4, ["y"] = 0, ["param1"] = 23, ["z"] = 7, ["name"] = "the_build_spawner:black"}, {["x"] = 4, ["y"] = 0, ["z"] = 8, ["name"] = "the_build_spawner:white"}, {["x"] = 4, ["y"] = 0, ["param1"] = 23, ["z"] = 9, ["name"] = "the_build_spawner:black"}, {["x"] = 4, ["y"] = 0, ["z"] = 10, ["name"] = "the_build_spawner:white"}, {["x"] = 4, ["y"] = 0, ["param1"] = 23, ["z"] = 11, ["name"] = "the_build_spawner:black"}, {["x"] = 4, ["y"] = 0, ["z"] = 12, ["name"] = "the_build_spawner:white"}, {["x"] = 4, ["y"] = 0, ["param1"] = 150, ["z"] = 13, ["name"] = "the_build_spawner:white"}, {["x"] = 4, ["y"] = 0, ["z"] = 14, ["name"] = "default:dirt_with_grass"}, {["x"] = 4, ["y"] = 0, ["z"] = 15, ["name"] = "default:dirt_with_grass"}, {["x"] = 4, ["y"] = 0, ["z"] = 16, ["name"] = "default:dirt_with_grass"}, {["x"] = 4, ["y"] = 0, ["z"] = 17, ["name"] = "default:dirt_with_grass"}, {["x"] = 4, ["y"] = 1, ["param1"] = 150, ["z"] = 1, ["name"] = "the_build_spawner:white"}, {["x"] = 4, ["y"] = 1, ["z"] = 2, ["name"] = "default:steelblock"}, {["x"] = 4, ["y"] = 1, ["z"] = 7, ["name"] = "the_build_spawner:white"}, {["x"] = 4, ["param2"] = 3, ["y"] = 1, ["param1"] = 153, ["z"] = 10, ["name"] = "stairs:slab_wood"}, {["x"] = 4, ["y"] = 1, ["param1"] = 187, ["z"] = 12, ["name"] = "stairs:stair_wood"}, {["x"] = 4, ["y"] = 1, ["param1"] = 150, ["z"] = 13, ["name"] = "the_build_spawner:white"}, {["x"] = 4, ["y"] = 2, ["param1"] = 150, ["z"] = 1, ["name"] = "the_build_spawner:white"}, {["x"] = 4, ["y"] = 2, ["param1"] = 238, ["z"] = 2, ["name"] = "default:mese_post_light_pine_wood"}, {["x"] = 4, ["y"] = 2, ["z"] = 7, ["name"] = "the_build_spawner:white"}, {["x"] = 4, ["y"] = 2, ["param1"] = 150, ["z"] = 13, ["name"] = "the_build_spawner:white"}, {["x"] = 4, ["y"] = 3, ["param1"] = 150, ["z"] = 1, ["name"] = "the_build_spawner:white"}, {["x"] = 4, ["param2"] = 2, ["y"] = 3, ["param1"] = 221, ["z"] = 2, ["name"] = "doors:trapdoor"}, {["x"] = 4, ["param2"] = 8, ["y"] = 3, ["param1"] = 204, ["z"] = 6, ["name"] = "stairs:slab_obsidianbrick"}, {["x"] = 4, ["y"] = 3, ["z"] = 7, ["name"] = "the_build_spawner:white"}, {["x"] = 4, ["y"] = 3, ["param1"] = 204, ["z"] = 11, ["name"] = "butterflies:butterfly_white"}, {["x"] = 4, ["y"] = 3, ["param1"] = 150, ["z"] = 13, ["name"] = "the_build_spawner:white"}, {["x"] = 4, ["y"] = 4, ["param1"] = 150, ["z"] = 1, ["name"] = "the_build_spawner:white"}, {["x"] = 4, ["param2"] = 8, ["y"] = 4, ["param1"] = 221, ["z"] = 6, ["name"] = "stairs:slab_obsidianbrick"}, {["x"] = 4, ["y"] = 4, ["z"] = 7, ["name"] = "the_build_spawner:white"}, {["x"] = 4, ["y"] = 4, ["param1"] = 238, ["z"] = 12, ["name"] = "default:mese_post_light_aspen_wood"}, {["x"] = 4, ["y"] = 4, ["param1"] = 150, ["z"] = 13, ["name"] = "the_build_spawner:white"}, {["x"] = 4, ["y"] = 5, ["param1"] = 150, ["z"] = 1, ["name"] = "the_build_spawner:white"}, {["x"] = 4, ["y"] = 5, ["param1"] = 238, ["z"] = 2, ["name"] = "default:mese_post_light_aspen_wood"}, {["x"] = 4, ["y"] = 5, ["param1"] = 238, ["z"] = 6, ["name"] = "default:mese_post_light_aspen_wood"}, {["x"] = 4, ["y"] = 5, ["z"] = 7, ["name"] = "the_build_spawner:white"}, {["x"] = 4, ["y"] = 5, ["z"] = 12, ["name"] = "the_build_spawner:white"}, {["x"] = 4, ["y"] = 5, ["param1"] = 150, ["z"] = 13, ["name"] = "the_build_spawner:white"}, {["x"] = 4, ["param2"] = 2, ["y"] = 6, ["param1"] = 124, ["z"] = 0, ["name"] = "stairs:slab_stone_block"}, {["x"] = 4, ["y"] = 6, ["param1"] = 150, ["z"] = 1, ["name"] = "the_build_spawner:white"}, {["x"] = 4, ["y"] = 6, ["param1"] = 59, ["z"] = 2, ["name"] = "the_build_spawner:white"}, {["x"] = 4, ["y"] = 6, ["param1"] = 76, ["z"] = 3, ["name"] = "the_build_spawner:white"}, {["x"] = 4, ["y"] = 6, ["param1"] = 92, ["z"] = 4, ["name"] = "the_build_spawner:white"}, {["x"] = 4, ["y"] = 6, ["param1"] = 108, ["z"] = 5, ["name"] = "the_build_spawner:white"}, {["x"] = 4, ["y"] = 6, ["param1"] = 124, ["z"] = 6, ["name"] = "the_build_spawner:white"}, {["x"] = 4, ["y"] = 6, ["param1"] = 140, ["z"] = 7, ["name"] = "the_build_spawner:white"}, {["x"] = 4, ["y"] = 6, ["param1"] = 156, ["z"] = 8, ["name"] = "the_build_spawner:white"}, {["x"] = 4, ["y"] = 6, ["param1"] = 140, ["z"] = 9, ["name"] = "the_build_spawner:white"}, {["x"] = 4, ["y"] = 6, ["param1"] = 124, ["z"] = 10, ["name"] = "the_build_spawner:white"}, {["x"] = 4, ["y"] = 6, ["param1"] = 140, ["z"] = 11, ["name"] = "the_build_spawner:white"}, {["x"] = 4, ["y"] = 6, ["param1"] = 123, ["z"] = 12, ["name"] = "the_build_spawner:white"}, {["x"] = 4, ["y"] = 6, ["param1"] = 150, ["z"] = 13, ["name"] = "the_build_spawner:white"}, {["x"] = 4, ["param2"] = 2, ["y"] = 6, ["param1"] = 142, ["z"] = 14, ["name"] = "stairs:slab_stone_block"}, {["x"] = 4, ["y"] = 7, ["param1"] = 150, ["z"] = 1, ["name"] = "the_build_spawner:white"}, {["x"] = 4, ["param2"] = 2, ["y"] = 7, ["param1"] = 44, ["z"] = 2, ["name"] = "stairs:stair_wood"}, {["x"] = 4, ["y"] = 7, ["z"] = 7, ["name"] = "the_build_spawner:white"}, {["x"] = 4, ["y"] = 7, ["param1"] = 150, ["z"] = 13, ["name"] = "the_build_spawner:white"}, {["x"] = 4, ["y"] = 8, ["param1"] = 150, ["z"] = 1, ["name"] = "the_build_spawner:white"}, {["x"] = 4, ["y"] = 8, ["z"] = 7, ["name"] = "the_build_spawner:white"}, {["x"] = 4, ["y"] = 8, ["param1"] = 150, ["z"] = 13, ["name"] = "the_build_spawner:white"}, {["x"] = 4, ["y"] = 9, ["param1"] = 150, ["z"] = 1, ["name"] = "the_build_spawner:white"}, {["x"] = 4, ["y"] = 9, ["z"] = 7, ["name"] = "the_build_spawner:white"}, {["x"] = 4, ["y"] = 9, ["param1"] = 150, ["z"] = 13, ["name"] = "the_build_spawner:white"}, {["x"] = 4, ["y"] = 10, ["param1"] = 150, ["z"] = 1, ["name"] = "the_build_spawner:white"}, {["x"] = 4, ["y"] = 10, ["z"] = 7, ["name"] = "the_build_spawner:white"}, {["x"] = 4, ["y"] = 10, ["param1"] = 150, ["z"] = 13, ["name"] = "the_build_spawner:white"}, {["x"] = 4, ["param2"] = 21, ["y"] = 11, ["param1"] = 77, ["z"] = 0, ["name"] = "stairs:slab_stone_block"}, {["x"] = 4, ["y"] = 11, ["param1"] = 150, ["z"] = 1, ["name"] = "the_build_spawner:white"}, {["x"] = 4, ["y"] = 11, ["z"] = 7, ["name"] = "the_build_spawner:white"}, {["x"] = 4, ["y"] = 11, ["param1"] = 238, ["z"] = 8, ["name"] = "default:mese_post_light_aspen_wood"}, {["x"] = 4, ["y"] = 11, ["param1"] = 238, ["z"] = 12, ["name"] = "default:mese_post_light_aspen_wood"}, {["x"] = 4, ["y"] = 11, ["param1"] = 150, ["z"] = 13, ["name"] = "the_build_spawner:white"}, {["x"] = 4, ["param2"] = 21, ["y"] = 11, ["param1"] = 174, ["z"] = 14, ["name"] = "stairs:slab_stone_block"}, {["x"] = 4, ["y"] = 12, ["param1"] = 109, ["z"] = 1, ["name"] = "stairs:slab_stone_block"}, {["x"] = 4, ["y"] = 12, ["param1"] = 125, ["z"] = 2, ["name"] = "stairs:slab_stone_block"}, {["x"] = 4, ["y"] = 12, ["param1"] = 141, ["z"] = 3, ["name"] = "stairs:slab_stone_block"}, {["x"] = 4, ["y"] = 12, ["param1"] = 157, ["z"] = 4, ["name"] = "stairs:slab_stone_block"}, {["x"] = 4, ["y"] = 12, ["param1"] = 173, ["z"] = 5, ["name"] = "stairs:slab_stone_block"}, {["x"] = 4, ["y"] = 12, ["param1"] = 189, ["z"] = 6, ["name"] = "stairs:slab_stone_block"}, {["x"] = 4, ["y"] = 12, ["param1"] = 205, ["z"] = 7, ["name"] = "stairs:slab_stone_block"}, {["x"] = 4, ["y"] = 12, ["param1"] = 221, ["z"] = 8, ["name"] = "stairs:slab_stone_block"}, {["x"] = 4, ["y"] = 12, ["param1"] = 205, ["z"] = 9, ["name"] = "stairs:slab_stone_block"}, {["x"] = 4, ["y"] = 12, ["param1"] = 189, ["z"] = 10, ["name"] = "stairs:slab_stone_block"}, {["x"] = 4, ["y"] = 12, ["param1"] = 205, ["z"] = 11, ["name"] = "stairs:slab_stone_block"}, {["x"] = 4, ["y"] = 12, ["param1"] = 221, ["z"] = 12, ["name"] = "stairs:slab_stone_block"}, {["x"] = 4, ["y"] = 12, ["param1"] = 206, ["z"] = 13, ["name"] = "stairs:slab_stone_block"}, {["x"] = 5, ["y"] = 0, ["param1"] = 23, ["z"] = 0, ["name"] = "default:dirt_with_grass"}, {["x"] = 5, ["y"] = 0, ["param1"] = 150, ["z"] = 1, ["name"] = "the_build_spawner:white"}, {["x"] = 5, ["y"] = 0, ["param1"] = 23, ["z"] = 2, ["name"] = "the_build_spawner:black"}, {["x"] = 5, ["y"] = 0, ["z"] = 3, ["name"] = "the_build_spawner:white"}, {["x"] = 5, ["y"] = 0, ["param1"] = 23, ["z"] = 4, ["name"] = "the_build_spawner:black"}, {["x"] = 5, ["y"] = 0, ["z"] = 5, ["name"] = "the_build_spawner:white"}, {["x"] = 5, ["y"] = 0, ["param1"] = 23, ["z"] = 6, ["name"] = "the_build_spawner:black"}, {["x"] = 5, ["y"] = 0, ["z"] = 7, ["name"] = "the_build_spawner:white"}, {["x"] = 5, ["y"] = 0, ["param1"] = 23, ["z"] = 8, ["name"] = "the_build_spawner:black"}, {["x"] = 5, ["y"] = 0, ["z"] = 9, ["name"] = "the_build_spawner:white"}, {["x"] = 5, ["y"] = 0, ["param1"] = 23, ["z"] = 10, ["name"] = "the_build_spawner:black"}, {["x"] = 5, ["y"] = 0, ["z"] = 11, ["name"] = "the_build_spawner:white"}, {["x"] = 5, ["y"] = 0, ["param1"] = 23, ["z"] = 12, ["name"] = "the_build_spawner:black"}, {["x"] = 5, ["y"] = 0, ["param1"] = 150, ["z"] = 13, ["name"] = "the_build_spawner:white"}, {["x"] = 5, ["y"] = 0, ["z"] = 14, ["name"] = "default:dirt_with_grass"}, {["x"] = 5, ["y"] = 0, ["z"] = 15, ["name"] = "default:dirt_with_grass"}, {["x"] = 5, ["y"] = 0, ["z"] = 16, ["name"] = "default:dirt_with_grass"}, {["x"] = 5, ["y"] = 0, ["z"] = 17, ["name"] = "default:dirt_with_grass"}, {["x"] = 5, ["y"] = 1, ["param1"] = 150, ["z"] = 1, ["name"] = "the_build_spawner:white"}, {["x"] = 5, ["param2"] = 2, ["y"] = 1, ["param1"] = 204, ["z"] = 2, ["name"] = "beds:bed_top"}, {["x"] = 5, ["param2"] = 2, ["y"] = 1, ["param1"] = 187, ["z"] = 3, ["name"] = "beds:bed_bottom"}, {["x"] = 5, ["param2"] = 2, ["y"] = 1, ["param1"] = 170, ["z"] = 4, ["name"] = "doors:trapdoor_open"}, {["x"] = 5, ["y"] = 1, ["z"] = 7, ["name"] = "the_build_spawner:white"}, {["x"] = 5, ["meta"] = {["fields"] = {["formspec"] = "field[text;;${text}]"}, ["inventory"] = {}}, ["param2"] = 3, ["y"] = 1, ["param1"] = 137, ["z"] = 10, ["name"] = "default:sign_wall_wood"}, {["x"] = 5, ["y"] = 1, ["param1"] = 171, ["z"] = 12, ["name"] = "stairs:stair_wood"}, {["x"] = 5, ["y"] = 1, ["param1"] = 150, ["z"] = 13, ["name"] = "the_build_spawner:white"}, {["x"] = 5, ["y"] = 2, ["param1"] = 204, ["z"] = 1, ["name"] = "default:glass"}, {["x"] = 5, ["y"] = 2, ["z"] = 7, ["name"] = "the_build_spawner:white"}, {["x"] = 5, ["y"] = 2, ["param1"] = 173, ["z"] = 13, ["name"] = "default:glass"}, {["x"] = 5, ["y"] = 3, ["param1"] = 187, ["z"] = 1, ["name"] = "default:glass"}, {["x"] = 5, ["param2"] = 8, ["y"] = 3, ["param1"] = 187, ["z"] = 6, ["name"] = "stairs:slab_obsidianbrick"}, {["x"] = 5, ["y"] = 3, ["z"] = 7, ["name"] = "the_build_spawner:white"}, {["x"] = 5, ["y"] = 3, ["param1"] = 189, ["z"] = 13, ["name"] = "default:glass"}, {["x"] = 5, ["y"] = 4, ["param1"] = 187, ["z"] = 1, ["name"] = "default:glass"}, {["x"] = 5, ["param2"] = 8, ["y"] = 4, ["param1"] = 204, ["z"] = 6, ["name"] = "stairs:slab_obsidianbrick"}, {["x"] = 5, ["y"] = 4, ["z"] = 7, ["name"] = "the_build_spawner:white"}, {["x"] = 5, ["y"] = 4, ["param1"] = 205, ["z"] = 13, ["name"] = "default:glass"}, {["x"] = 5, ["y"] = 5, ["param1"] = 150, ["z"] = 1, ["name"] = "the_build_spawner:white"}, {["x"] = 5, ["y"] = 5, ["z"] = 7, ["name"] = "the_build_spawner:white"}, {["x"] = 5, ["y"] = 5, ["z"] = 12, ["name"] = "the_build_spawner:white"}, {["x"] = 5, ["y"] = 5, ["param1"] = 150, ["z"] = 13, ["name"] = "the_build_spawner:white"}, {["x"] = 5, ["param2"] = 2, ["y"] = 6, ["param1"] = 140, ["z"] = 0, ["name"] = "stairs:slab_stone_block"}, {["x"] = 5, ["y"] = 6, ["param1"] = 150, ["z"] = 1, ["name"] = "the_build_spawner:white"}, {["x"] = 5, ["y"] = 6, ["param1"] = 76, ["z"] = 2, ["name"] = "the_build_spawner:white"}, {["x"] = 5, ["y"] = 6, ["param1"] = 92, ["z"] = 3, ["name"] = "the_build_spawner:white"}, {["x"] = 5, ["y"] = 6, ["param1"] = 108, ["z"] = 4, ["name"] = "the_build_spawner:white"}, {["x"] = 5, ["y"] = 6, ["param1"] = 124, ["z"] = 5, ["name"] = "the_build_spawner:white"}, {["x"] = 5, ["y"] = 6, ["param1"] = 140, ["z"] = 6, ["name"] = "the_build_spawner:white"}, {["x"] = 5, ["y"] = 6, ["param1"] = 156, ["z"] = 7, ["name"] = "the_build_spawner:white"}, {["x"] = 5, ["y"] = 6, ["param1"] = 172, ["z"] = 8, ["name"] = "the_build_spawner:white"}, {["x"] = 5, ["y"] = 6, ["param1"] = 156, ["z"] = 9, ["name"] = "the_build_spawner:white"}, {["x"] = 5, ["y"] = 6, ["param1"] = 140, ["z"] = 10, ["name"] = "the_build_spawner:white"}, {["x"] = 5, ["y"] = 6, ["param1"] = 156, ["z"] = 11, ["name"] = "the_build_spawner:white"}, {["x"] = 5, ["y"] = 6, ["param1"] = 140, ["z"] = 12, ["name"] = "the_build_spawner:white"}, {["x"] = 5, ["y"] = 6, ["param1"] = 150, ["z"] = 13, ["name"] = "the_build_spawner:white"}, {["x"] = 5, ["param2"] = 2, ["y"] = 6, ["param1"] = 158, ["z"] = 14, ["name"] = "stairs:slab_stone_block"}, {["x"] = 5, ["y"] = 7, ["param1"] = 150, ["z"] = 1, ["name"] = "the_build_spawner:white"}, {["x"] = 5, ["meta"] = {["fields"] = {["formspec"] = "field[text;;${text}]"}, ["inventory"] = {}}, ["param2"] = 3, ["y"] = 7, ["param1"] = 61, ["z"] = 2, ["name"] = "default:sign_wall_wood"}, {["x"] = 5, ["y"] = 7, ["z"] = 7, ["name"] = "the_build_spawner:white"}, {["x"] = 5, ["y"] = 7, ["z"] = 10, ["name"] = "default:steelblock"}, {["x"] = 5, ["y"] = 7, ["z"] = 12, ["name"] = "default:steelblock"}, {["x"] = 5, ["y"] = 7, ["param1"] = 150, ["z"] = 13, ["name"] = "the_build_spawner:white"}, {["x"] = 5, ["y"] = 8, ["param1"] = 93, ["z"] = 1, ["name"] = "default:glass"}, {["x"] = 5, ["y"] = 8, ["z"] = 7, ["name"] = "the_build_spawner:white"}, {["x"] = 5, ["y"] = 8, ["param1"] = 157, ["z"] = 13, ["name"] = "default:glass"}, {["x"] = 5, ["y"] = 9, ["param1"] = 78, ["z"] = 1, ["name"] = "default:glass"}, {["x"] = 5, ["y"] = 9, ["z"] = 7, ["name"] = "the_build_spawner:white"}, {["x"] = 5, ["y"] = 9, ["param1"] = 174, ["z"] = 13, ["name"] = "default:glass"}, {["x"] = 5, ["y"] = 10, ["param1"] = 62, ["z"] = 1, ["name"] = "default:glass"}, {["x"] = 5, ["y"] = 10, ["z"] = 7, ["name"] = "the_build_spawner:white"}, {["x"] = 5, ["y"] = 10, ["param1"] = 190, ["z"] = 13, ["name"] = "default:glass"}, {["x"] = 5, ["param2"] = 21, ["y"] = 11, ["param1"] = 62, ["z"] = 0, ["name"] = "stairs:slab_stone_block"}, {["x"] = 5, ["y"] = 11, ["param1"] = 150, ["z"] = 1, ["name"] = "the_build_spawner:white"}, {["x"] = 5, ["y"] = 11, ["z"] = 7, ["name"] = "the_build_spawner:white"}, {["x"] = 5, ["y"] = 11, ["param1"] = 150, ["z"] = 13, ["name"] = "the_build_spawner:white"}, {["x"] = 5, ["param2"] = 21, ["y"] = 11, ["param1"] = 158, ["z"] = 14, ["name"] = "stairs:slab_stone_block"}, {["x"] = 5, ["y"] = 12, ["param1"] = 94, ["z"] = 1, ["name"] = "stairs:slab_stone_block"}, {["x"] = 5, ["y"] = 12, ["param1"] = 110, ["z"] = 2, ["name"] = "stairs:slab_stone_block"}, {["x"] = 5, ["y"] = 12, ["param1"] = 126, ["z"] = 3, ["name"] = "stairs:slab_stone_block"}, {["x"] = 5, ["y"] = 12, ["param1"] = 142, ["z"] = 4, ["name"] = "stairs:slab_stone_block"}, {["x"] = 5, ["y"] = 12, ["param1"] = 158, ["z"] = 5, ["name"] = "stairs:slab_stone_block"}, {["x"] = 5, ["y"] = 12, ["param1"] = 174, ["z"] = 6, ["name"] = "stairs:slab_stone_block"}, {["x"] = 5, ["y"] = 12, ["param1"] = 190, ["z"] = 7, ["name"] = "stairs:slab_stone_block"}, {["x"] = 5, ["y"] = 12, ["param1"] = 206, ["z"] = 8, ["name"] = "stairs:slab_stone_block"}, {["x"] = 5, ["y"] = 12, ["param1"] = 190, ["z"] = 9, ["name"] = "stairs:slab_stone_block"}, {["x"] = 5, ["y"] = 12, ["param1"] = 206, ["z"] = 10, ["name"] = "stairs:slab_stone_block"}, {["x"] = 5, ["y"] = 12, ["param1"] = 190, ["z"] = 11, ["name"] = "stairs:slab_stone_block"}, {["x"] = 5, ["y"] = 12, ["param1"] = 206, ["z"] = 12, ["name"] = "stairs:slab_stone_block"}, {["x"] = 5, ["y"] = 12, ["param1"] = 190, ["z"] = 13, ["name"] = "stairs:slab_stone_block"}, {["x"] = 6, ["y"] = 0, ["param1"] = 23, ["z"] = 0, ["name"] = "default:dirt_with_grass"}, {["x"] = 6, ["y"] = 0, ["param1"] = 150, ["z"] = 1, ["name"] = "the_build_spawner:white"}, {["x"] = 6, ["y"] = 0, ["z"] = 2, ["name"] = "the_build_spawner:white"}, {["x"] = 6, ["y"] = 0, ["param1"] = 23, ["z"] = 3, ["name"] = "the_build_spawner:black"}, {["x"] = 6, ["y"] = 0, ["z"] = 4, ["name"] = "the_build_spawner:white"}, {["x"] = 6, ["y"] = 0, ["param1"] = 23, ["z"] = 5, ["name"] = "the_build_spawner:black"}, {["x"] = 6, ["y"] = 0, ["z"] = 6, ["name"] = "the_build_spawner:white"}, {["x"] = 6, ["y"] = 0, ["param1"] = 23, ["z"] = 7, ["name"] = "the_build_spawner:black"}, {["x"] = 6, ["y"] = 0, ["z"] = 8, ["name"] = "the_build_spawner:white"}, {["x"] = 6, ["y"] = 0, ["param1"] = 23, ["z"] = 9, ["name"] = "the_build_spawner:black"}, {["x"] = 6, ["y"] = 0, ["z"] = 10, ["name"] = "the_build_spawner:white"}, {["x"] = 6, ["y"] = 0, ["param1"] = 23, ["z"] = 11, ["name"] = "the_build_spawner:black"}, {["x"] = 6, ["y"] = 0, ["z"] = 12, ["name"] = "the_build_spawner:white"}, {["x"] = 6, ["y"] = 0, ["z"] = 13, ["name"] = "the_build_spawner:white"}, {["x"] = 6, ["y"] = 0, ["z"] = 14, ["name"] = "default:dirt_with_grass"}, {["x"] = 6, ["y"] = 0, ["z"] = 15, ["name"] = "default:dirt_with_grass"}, {["x"] = 6, ["y"] = 0, ["z"] = 16, ["name"] = "default:dirt_with_grass"}, {["x"] = 6, ["y"] = 0, ["z"] = 17, ["name"] = "default:dirt_with_grass"}, {["x"] = 6, ["y"] = 1, ["param1"] = 150, ["z"] = 1, ["name"] = "the_build_spawner:white"}, {["x"] = 6, ["param2"] = 3, ["y"] = 1, ["param1"] = 187, ["z"] = 2, ["name"] = "doors:trapdoor_open"}, {["x"] = 6, ["meta"] = {["fields"] = {["state"] = "0"}, ["inventory"] = {}}, ["param2"] = 2, ["y"] = 1, ["param1"] = 153, ["z"] = 7, ["name"] = "doors:door_wood_a"}, {["x"] = 6, ["meta"] = {["fields"] = {["formspec"] = "field[text;;${text}]"}, ["inventory"] = {}}, ["param2"] = 3, ["y"] = 1, ["param1"] = 171, ["z"] = 12, ["name"] = "default:sign_wall_wood"}, {["x"] = 6, ["y"] = 1, ["param1"] = 150, ["z"] = 13, ["name"] = "the_build_spawner:white"}, {["x"] = 6, ["y"] = 1, ["param1"] = 111, ["z"] = 16, ["name"] = "default:grass_1"}, {["x"] = 6, ["y"] = 2, ["param1"] = 187, ["z"] = 1, ["name"] = "default:glass"}, {["x"] = 6, ["param2"] = 2, ["y"] = 2, ["param1"] = 170, ["z"] = 7, ["name"] = "doors:hidden"}, {["x"] = 6, ["y"] = 2, ["param1"] = 173, ["z"] = 13, ["name"] = "default:glass"}, {["x"] = 6, ["y"] = 3, ["param1"] = 171, ["z"] = 1, ["name"] = "default:glass"}, {["x"] = 6, ["param2"] = 22, ["y"] = 3, ["param1"] = 187, ["z"] = 7, ["name"] = "stairs:stair_silver_sandstone"}, {["x"] = 6, ["y"] = 3, ["param1"] = 189, ["z"] = 13, ["name"] = "default:glass"}, {["x"] = 6, ["y"] = 4, ["param1"] = 171, ["z"] = 1, ["name"] = "default:glass"}, {["x"] = 6, ["y"] = 4, ["z"] = 7, ["name"] = "the_build_spawner:white"}, {["x"] = 6, ["meta"] = {["fields"] = {["infotext"] = "\27(T@default)\"\27F1\27E\"\27E", ["text"] = "1", ["formspec"] = "field[text;;${text}]"}, ["inventory"] = {}}, ["param2"] = 5, ["y"] = 4, ["param1"] = 221, ["z"] = 8, ["name"] = "default:sign_wall_wood"}, {["x"] = 6, ["y"] = 4, ["param1"] = 205, ["z"] = 13, ["name"] = "default:glass"}, {["x"] = 6, ["y"] = 5, ["param1"] = 150, ["z"] = 1, ["name"] = "the_build_spawner:white"}, {["x"] = 6, ["y"] = 5, ["param1"] = 238, ["z"] = 4, ["name"] = "default:mese_post_light_aspen_wood"}, {["x"] = 6, ["y"] = 5, ["z"] = 7, ["name"] = "the_build_spawner:white"}, {["x"] = 6, ["y"] = 5, ["z"] = 12, ["name"] = "the_build_spawner:white"}, {["x"] = 6, ["y"] = 5, ["param1"] = 150, ["z"] = 13, ["name"] = "the_build_spawner:white"}, {["x"] = 6, ["param2"] = 2, ["y"] = 6, ["param1"] = 124, ["z"] = 0, ["name"] = "stairs:slab_stone_block"}, {["x"] = 6, ["y"] = 6, ["param1"] = 150, ["z"] = 1, ["name"] = "the_build_spawner:white"}, {["x"] = 6, ["y"] = 6, ["param1"] = 92, ["z"] = 2, ["name"] = "the_build_spawner:white"}, {["x"] = 6, ["y"] = 6, ["param1"] = 108, ["z"] = 3, ["name"] = "the_build_spawner:white"}, {["x"] = 6, ["y"] = 6, ["param1"] = 124, ["z"] = 4, ["name"] = "the_build_spawner:white"}, {["x"] = 6, ["y"] = 6, ["param1"] = 140, ["z"] = 5, ["name"] = "the_build_spawner:white"}, {["x"] = 6, ["y"] = 6, ["param1"] = 156, ["z"] = 6, ["name"] = "the_build_spawner:white"}, {["x"] = 6, ["y"] = 6, ["param1"] = 172, ["z"] = 7, ["name"] = "the_build_spawner:white"}, {["x"] = 6, ["y"] = 6, ["param1"] = 188, ["z"] = 8, ["name"] = "the_build_spawner:white"}, {["x"] = 6, ["y"] = 6, ["param1"] = 172, ["z"] = 9, ["name"] = "the_build_spawner:white"}, {["x"] = 6, ["y"] = 6, ["param1"] = 156, ["z"] = 10, ["name"] = "the_build_spawner:white"}, {["x"] = 6, ["y"] = 6, ["param1"] = 172, ["z"] = 11, ["name"] = "the_build_spawner:white"}, {["x"] = 6, ["y"] = 6, ["param1"] = 156, ["z"] = 12, ["name"] = "the_build_spawner:white"}, {["x"] = 6, ["y"] = 6, ["param1"] = 150, ["z"] = 13, ["name"] = "the_build_spawner:white"}, {["x"] = 6, ["param2"] = 2, ["y"] = 6, ["param1"] = 158, ["z"] = 14, ["name"] = "stairs:slab_stone_block"}, {["x"] = 6, ["y"] = 7, ["param1"] = 150, ["z"] = 1, ["name"] = "the_build_spawner:white"}, {["x"] = 6, ["meta"] = {["fields"] = {["formspec"] = "field[text;;${text}]"}, ["inventory"] = {}}, ["param2"] = 2, ["y"] = 7, ["param1"] = 45, ["z"] = 2, ["name"] = "default:sign_wall_wood"}, {["x"] = 6, ["meta"] = {["fields"] = {["state"] = "0"}, ["inventory"] = {}}, ["param2"] = 2, ["y"] = 7, ["param1"] = 124, ["z"] = 7, ["name"] = "doors:door_wood_a"}, {["x"] = 6, ["y"] = 7, ["z"] = 10, ["name"] = "default:steelblock"}, {["x"] = 6, ["y"] = 7, ["z"] = 12, ["name"] = "default:steelblock"}, {["x"] = 6, ["y"] = 7, ["param1"] = 150, ["z"] = 13, ["name"] = "the_build_spawner:white"}, {["x"] = 6, ["y"] = 8, ["param1"] = 77, ["z"] = 1, ["name"] = "default:glass"}, {["x"] = 6, ["param2"] = 2, ["y"] = 8, ["param1"] = 141, ["z"] = 7, ["name"] = "doors:hidden"}, {["x"] = 6, ["y"] = 8, ["param1"] = 142, ["z"] = 13, ["name"] = "default:glass"}, {["x"] = 6, ["y"] = 9, ["param1"] = 62, ["z"] = 1, ["name"] = "default:glass"}, {["x"] = 6, ["param2"] = 20, ["y"] = 9, ["param1"] = 158, ["z"] = 7, ["name"] = "stairs:stair_silver_sandstone"}, {["x"] = 6, ["y"] = 9, ["param1"] = 158, ["z"] = 13, ["name"] = "default:glass"}, {["x"] = 6, ["y"] = 10, ["param1"] = 46, ["z"] = 1, ["name"] = "default:glass"}, {["x"] = 6, ["meta"] = {["fields"] = {["infotext"] = "\27(T@default)\"\27FDead body room\27E\"\27E", ["text"] = "Dead body room", ["formspec"] = "field[text;;${text}]"}, ["inventory"] = {}}, ["param2"] = 4, ["y"] = 10, ["param1"] = 127, ["z"] = 6, ["name"] = "default:sign_wall_wood"}, {["x"] = 6, ["y"] = 10, ["z"] = 7, ["name"] = "the_build_spawner:white"}, {["x"] = 6, ["y"] = 10, ["param1"] = 174, ["z"] = 13, ["name"] = "default:glass"}, {["x"] = 6, ["param2"] = 21, ["y"] = 11, ["param1"] = 46, ["z"] = 0, ["name"] = "stairs:slab_stone_block"}, {["x"] = 6, ["y"] = 11, ["param1"] = 150, ["z"] = 1, ["name"] = "the_build_spawner:white"}, {["x"] = 6, ["y"] = 11, ["z"] = 7, ["name"] = "the_build_spawner:white"}, {["x"] = 6, ["y"] = 11, ["param1"] = 238, ["z"] = 10, ["name"] = "default:mese_post_light_aspen_wood"}, {["x"] = 6, ["y"] = 11, ["param1"] = 150, ["z"] = 13, ["name"] = "the_build_spawner:white"}, {["x"] = 6, ["param2"] = 21, ["y"] = 11, ["param1"] = 142, ["z"] = 14, ["name"] = "stairs:slab_stone_block"}, {["x"] = 6, ["y"] = 12, ["param1"] = 78, ["z"] = 1, ["name"] = "stairs:slab_stone_block"}, {["x"] = 6, ["y"] = 12, ["param1"] = 94, ["z"] = 2, ["name"] = "stairs:slab_stone_block"}, {["x"] = 6, ["y"] = 12, ["param1"] = 110, ["z"] = 3, ["name"] = "stairs:slab_stone_block"}, {["x"] = 6, ["y"] = 12, ["param1"] = 126, ["z"] = 4, ["name"] = "stairs:slab_stone_block"}, {["x"] = 6, ["y"] = 12, ["param1"] = 142, ["z"] = 5, ["name"] = "stairs:slab_stone_block"}, {["x"] = 6, ["y"] = 12, ["param1"] = 158, ["z"] = 6, ["name"] = "stairs:slab_stone_block"}, {["x"] = 6, ["y"] = 12, ["param1"] = 174, ["z"] = 7, ["name"] = "stairs:slab_stone_block"}, {["x"] = 6, ["y"] = 12, ["param1"] = 190, ["z"] = 8, ["name"] = "stairs:slab_stone_block"}, {["x"] = 6, ["y"] = 12, ["param1"] = 206, ["z"] = 9, ["name"] = "stairs:slab_stone_block"}, {["x"] = 6, ["y"] = 12, ["param1"] = 222, ["z"] = 10, ["name"] = "stairs:slab_stone_block"}, {["x"] = 6, ["y"] = 12, ["param1"] = 206, ["z"] = 11, ["name"] = "stairs:slab_stone_block"}, {["x"] = 6, ["y"] = 12, ["param1"] = 190, ["z"] = 12, ["name"] = "stairs:slab_stone_block"}, {["x"] = 6, ["y"] = 12, ["param1"] = 174, ["z"] = 13, ["name"] = "stairs:slab_stone_block"}, {["x"] = 7, ["y"] = 0, ["param1"] = 23, ["z"] = 0, ["name"] = "default:dirt_with_grass"}, {["x"] = 7, ["y"] = 0, ["param1"] = 150, ["z"] = 1, ["name"] = "the_build_spawner:white"}, {["x"] = 7, ["y"] = 0, ["z"] = 2, ["name"] = "the_build_spawner:black"}, {["x"] = 7, ["y"] = 0, ["z"] = 3, ["name"] = "the_build_spawner:white"}, {["x"] = 7, ["y"] = 0, ["param1"] = 23, ["z"] = 4, ["name"] = "the_build_spawner:black"}, {["x"] = 7, ["y"] = 0, ["z"] = 5, ["name"] = "the_build_spawner:white"}, {["x"] = 7, ["y"] = 0, ["param1"] = 23, ["z"] = 6, ["name"] = "the_build_spawner:black"}, {["x"] = 7, ["y"] = 0, ["z"] = 7, ["name"] = "the_build_spawner:white"}, {["x"] = 7, ["y"] = 0, ["param1"] = 23, ["z"] = 8, ["name"] = "the_build_spawner:black"}, {["x"] = 7, ["y"] = 0, ["z"] = 9, ["name"] = "the_build_spawner:white"}, {["x"] = 7, ["y"] = 0, ["param1"] = 23, ["z"] = 10, ["name"] = "the_build_spawner:black"}, {["x"] = 7, ["y"] = 0, ["z"] = 11, ["name"] = "the_build_spawner:white"}, {["x"] = 7, ["y"] = 0, ["param1"] = 23, ["z"] = 12, ["name"] = "the_build_spawner:black"}, {["x"] = 7, ["y"] = 0, ["param1"] = 150, ["z"] = 13, ["name"] = "the_build_spawner:white"}, {["x"] = 7, ["y"] = 0, ["z"] = 14, ["name"] = "default:dirt"}, {["x"] = 7, ["param2"] = 23, ["y"] = 0, ["param1"] = 93, ["z"] = 15, ["name"] = "stairs:slab_stone_block"}, {["x"] = 7, ["param2"] = 21, ["y"] = 0, ["param1"] = 77, ["z"] = 16, ["name"] = "stairs:slab_stone_block"}, {["x"] = 7, ["y"] = 0, ["z"] = 17, ["name"] = "default:dirt_with_grass"}, {["x"] = 7, ["y"] = 1, ["param1"] = 150, ["z"] = 1, ["name"] = "the_build_spawner:white"}, {["x"] = 7, ["y"] = 1, ["z"] = 2, ["name"] = "the_build_spawner:white"}, {["x"] = 7, ["y"] = 1, ["z"] = 3, ["name"] = "the_build_spawner:white"}, {["x"] = 7, ["y"] = 1, ["z"] = 4, ["name"] = "the_build_spawner:white"}, {["x"] = 7, ["y"] = 1, ["z"] = 5, ["name"] = "the_build_spawner:white"}, {["x"] = 7, ["y"] = 1, ["z"] = 6, ["name"] = "the_build_spawner:white"}, {["x"] = 7, ["y"] = 1, ["z"] = 7, ["name"] = "the_build_spawner:white"}, {["x"] = 7, ["y"] = 1, ["param1"] = 187, ["z"] = 12, ["name"] = "default:fence_wood"}, {["x"] = 7, ["y"] = 1, ["param1"] = 150, ["z"] = 13, ["name"] = "the_build_spawner:white"}, {["x"] = 7, ["y"] = 1, ["z"] = 14, ["name"] = "the_build_spawner:white"}, {["x"] = 7, ["y"] = 1, ["param1"] = 110, ["z"] = 15, ["name"] = "walls:cobble"}, {["x"] = 7, ["y"] = 1, ["param1"] = 94, ["z"] = 16, ["name"] = "walls:cobble"}, {["x"] = 7, ["y"] = 2, ["param1"] = 150, ["z"] = 1, ["name"] = "the_build_spawner:white"}, {["x"] = 7, ["y"] = 2, ["z"] = 2, ["name"] = "the_build_spawner:white"}, {["x"] = 7, ["y"] = 2, ["z"] = 3, ["name"] = "the_build_spawner:white"}, {["x"] = 7, ["y"] = 2, ["z"] = 4, ["name"] = "the_build_spawner:white"}, {["x"] = 7, ["y"] = 2, ["z"] = 5, ["name"] = "the_build_spawner:white"}, {["x"] = 7, ["y"] = 2, ["z"] = 6, ["name"] = "the_build_spawner:white"}, {["x"] = 7, ["y"] = 2, ["z"] = 7, ["name"] = "the_build_spawner:white"}, {["x"] = 7, ["param2"] = 1, ["y"] = 2, ["param1"] = 204, ["z"] = 12, ["name"] = "default:aspen_leaves"}, {["x"] = 7, ["y"] = 2, ["param1"] = 150, ["z"] = 13, ["name"] = "the_build_spawner:white"}, {["x"] = 7, ["y"] = 2, ["z"] = 14, ["name"] = "the_build_spawner:white"}, {["x"] = 7, ["y"] = 2, ["param1"] = 110, ["z"] = 16, ["name"] = "walls:cobble"}, {["x"] = 7, ["y"] = 3, ["param1"] = 150, ["z"] = 1, ["name"] = "the_build_spawner:white"}, {["x"] = 7, ["y"] = 3, ["z"] = 2, ["name"] = "the_build_spawner:white"}, {["x"] = 7, ["y"] = 3, ["z"] = 3, ["name"] = "the_build_spawner:white"}, {["x"] = 7, ["y"] = 3, ["z"] = 4, ["name"] = "the_build_spawner:white"}, {["x"] = 7, ["y"] = 3, ["z"] = 5, ["name"] = "the_build_spawner:white"}, {["x"] = 7, ["y"] = 3, ["z"] = 6, ["name"] = "the_build_spawner:white"}, {["x"] = 7, ["y"] = 3, ["z"] = 7, ["name"] = "the_build_spawner:white"}, {["x"] = 7, ["param2"] = 1, ["y"] = 3, ["param1"] = 221, ["z"] = 12, ["name"] = "default:aspen_leaves"}, {["x"] = 7, ["y"] = 3, ["param1"] = 150, ["z"] = 13, ["name"] = "the_build_spawner:white"}, {["x"] = 7, ["y"] = 3, ["z"] = 14, ["name"] = "the_build_spawner:white"}, {["x"] = 7, ["y"] = 3, ["param1"] = 126, ["z"] = 16, ["name"] = "walls:cobble"}, {["x"] = 7, ["y"] = 4, ["param1"] = 150, ["z"] = 1, ["name"] = "the_build_spawner:white"}, {["x"] = 7, ["y"] = 4, ["z"] = 2, ["name"] = "the_build_spawner:white"}, {["x"] = 7, ["y"] = 4, ["z"] = 3, ["name"] = "the_build_spawner:white"}, {["x"] = 7, ["y"] = 4, ["z"] = 4, ["name"] = "the_build_spawner:white"}, {["x"] = 7, ["y"] = 4, ["z"] = 5, ["name"] = "the_build_spawner:white"}, {["x"] = 7, ["y"] = 4, ["z"] = 6, ["name"] = "the_build_spawner:white"}, {["x"] = 7, ["y"] = 4, ["z"] = 7, ["name"] = "the_build_spawner:white"}, {["x"] = 7, ["y"] = 4, ["param1"] = 238, ["z"] = 8, ["name"] = "default:mese_post_light_aspen_wood"}, {["x"] = 7, ["y"] = 4, ["param1"] = 238, ["z"] = 12, ["name"] = "default:mese_post_light_aspen_wood"}, {["x"] = 7, ["y"] = 4, ["param1"] = 150, ["z"] = 13, ["name"] = "the_build_spawner:white"}, {["x"] = 7, ["y"] = 4, ["z"] = 14, ["name"] = "the_build_spawner:white"}, {["x"] = 7, ["y"] = 4, ["param1"] = 142, ["z"] = 16, ["name"] = "walls:cobble"}, {["x"] = 7, ["y"] = 5, ["param1"] = 150, ["z"] = 1, ["name"] = "the_build_spawner:white"}, {["x"] = 7, ["y"] = 5, ["z"] = 2, ["name"] = "the_build_spawner:white"}, {["x"] = 7, ["y"] = 5, ["z"] = 3, ["name"] = "the_build_spawner:white"}, {["x"] = 7, ["y"] = 5, ["z"] = 4, ["name"] = "the_build_spawner:white"}, {["x"] = 7, ["y"] = 5, ["z"] = 5, ["name"] = "the_build_spawner:white"}, {["x"] = 7, ["y"] = 5, ["z"] = 6, ["name"] = "the_build_spawner:white"}, {["x"] = 7, ["y"] = 5, ["z"] = 7, ["name"] = "the_build_spawner:white"}, {["x"] = 7, ["y"] = 5, ["z"] = 8, ["name"] = "the_build_spawner:white"}, {["x"] = 7, ["y"] = 5, ["z"] = 9, ["name"] = "the_build_spawner:white"}, {["x"] = 7, ["y"] = 5, ["z"] = 10, ["name"] = "the_build_spawner:white"}, {["x"] = 7, ["y"] = 5, ["z"] = 11, ["name"] = "the_build_spawner:white"}, {["x"] = 7, ["y"] = 5, ["z"] = 12, ["name"] = "the_build_spawner:white"}, {["x"] = 7, ["y"] = 5, ["param1"] = 150, ["z"] = 13, ["name"] = "the_build_spawner:white"}, {["x"] = 7, ["y"] = 5, ["z"] = 14, ["name"] = "the_build_spawner:white"}, {["x"] = 7, ["param2"] = 2, ["y"] = 5, ["param1"] = 142, ["z"] = 15, ["name"] = "stairs:slab_stone_block"}, {["x"] = 7, ["param2"] = 2, ["y"] = 5, ["param1"] = 126, ["z"] = 16, ["name"] = "stairs:slab_stone_block"}, {["x"] = 7, ["param2"] = 2, ["y"] = 5, ["param1"] = 110, ["z"] = 17, ["name"] = "stairs:slab_stone_block"}, {["x"] = 7, ["param2"] = 2, ["y"] = 6, ["param1"] = 140, ["z"] = 0, ["name"] = "stairs:slab_stone_block"}, {["x"] = 7, ["y"] = 6, ["param1"] = 150, ["z"] = 1, ["name"] = "the_build_spawner:white"}, {["x"] = 7, ["y"] = 6, ["param1"] = 76, ["z"] = 2, ["name"] = "the_build_spawner:white"}, {["x"] = 7, ["y"] = 6, ["param1"] = 92, ["z"] = 3, ["name"] = "the_build_spawner:white"}, {["x"] = 7, ["y"] = 6, ["param1"] = 108, ["z"] = 4, ["name"] = "the_build_spawner:white"}, {["x"] = 7, ["y"] = 6, ["param1"] = 124, ["z"] = 5, ["name"] = "the_build_spawner:white"}, {["x"] = 7, ["y"] = 6, ["param1"] = 140, ["z"] = 6, ["name"] = "the_build_spawner:white"}, {["x"] = 7, ["y"] = 6, ["param1"] = 156, ["z"] = 7, ["name"] = "the_build_spawner:white"}, {["x"] = 7, ["y"] = 6, ["param1"] = 172, ["z"] = 8, ["name"] = "the_build_spawner:white"}, {["x"] = 7, ["y"] = 6, ["param1"] = 156, ["z"] = 9, ["name"] = "the_build_spawner:white"}, {["x"] = 7, ["y"] = 6, ["param1"] = 140, ["z"] = 10, ["name"] = "the_build_spawner:white"}, {["x"] = 7, ["y"] = 6, ["param1"] = 156, ["z"] = 11, ["name"] = "the_build_spawner:white"}, {["x"] = 7, ["y"] = 6, ["param1"] = 140, ["z"] = 12, ["name"] = "the_build_spawner:white"}, {["x"] = 7, ["y"] = 6, ["param1"] = 150, ["z"] = 13, ["name"] = "the_build_spawner:white"}, {["x"] = 7, ["param2"] = 2, ["y"] = 6, ["param1"] = 142, ["z"] = 14, ["name"] = "stairs:slab_stone_block"}, {["x"] = 7, ["y"] = 7, ["param1"] = 150, ["z"] = 1, ["name"] = "the_build_spawner:white"}, {["x"] = 7, ["param2"] = 2, ["y"] = 7, ["param1"] = 61, ["z"] = 2, ["name"] = "stairs:stair_wood"}, {["x"] = 7, ["y"] = 7, ["z"] = 7, ["name"] = "the_build_spawner:white"}, {["x"] = 7, ["y"] = 7, ["z"] = 8, ["name"] = "the_build_spawner:white"}, {["x"] = 7, ["y"] = 7, ["z"] = 9, ["name"] = "the_build_spawner:white"}, {["x"] = 7, ["y"] = 7, ["z"] = 10, ["name"] = "the_build_spawner:white"}, {["x"] = 7, ["y"] = 7, ["z"] = 11, ["name"] = "the_build_spawner:white"}, {["x"] = 7, ["y"] = 7, ["z"] = 12, ["name"] = "the_build_spawner:white"}, {["x"] = 7, ["y"] = 7, ["param1"] = 150, ["z"] = 13, ["name"] = "the_build_spawner:white"}, {["x"] = 7, ["y"] = 8, ["param1"] = 150, ["z"] = 1, ["name"] = "the_build_spawner:white"}, {["x"] = 7, ["y"] = 8, ["z"] = 7, ["name"] = "the_build_spawner:white"}, {["x"] = 7, ["y"] = 8, ["z"] = 8, ["name"] = "the_build_spawner:white"}, {["x"] = 7, ["y"] = 8, ["z"] = 9, ["name"] = "the_build_spawner:white"}, {["x"] = 7, ["y"] = 8, ["z"] = 10, ["name"] = "the_build_spawner:white"}, {["x"] = 7, ["y"] = 8, ["z"] = 11, ["name"] = "the_build_spawner:white"}, {["x"] = 7, ["y"] = 8, ["z"] = 12, ["name"] = "the_build_spawner:white"}, {["x"] = 7, ["y"] = 8, ["param1"] = 150, ["z"] = 13, ["name"] = "the_build_spawner:white"}, {["x"] = 7, ["y"] = 9, ["param1"] = 150, ["z"] = 1, ["name"] = "the_build_spawner:white"}, {["x"] = 7, ["y"] = 9, ["z"] = 7, ["name"] = "the_build_spawner:white"}, {["x"] = 7, ["y"] = 9, ["z"] = 8, ["name"] = "the_build_spawner:white"}, {["x"] = 7, ["y"] = 9, ["z"] = 9, ["name"] = "the_build_spawner:white"}, {["x"] = 7, ["y"] = 9, ["z"] = 10, ["name"] = "the_build_spawner:white"}, {["x"] = 7, ["y"] = 9, ["z"] = 11, ["name"] = "the_build_spawner:white"}, {["x"] = 7, ["y"] = 9, ["z"] = 12, ["name"] = "the_build_spawner:white"}, {["x"] = 7, ["y"] = 9, ["param1"] = 150, ["z"] = 13, ["name"] = "the_build_spawner:white"}, {["x"] = 7, ["y"] = 10, ["param1"] = 150, ["z"] = 1, ["name"] = "the_build_spawner:white"}, {["x"] = 7, ["y"] = 10, ["z"] = 7, ["name"] = "the_build_spawner:white"}, {["x"] = 7, ["y"] = 10, ["z"] = 8, ["name"] = "the_build_spawner:white"}, {["x"] = 7, ["y"] = 10, ["z"] = 9, ["name"] = "the_build_spawner:white"}, {["x"] = 7, ["y"] = 10, ["z"] = 10, ["name"] = "the_build_spawner:white"}, {["x"] = 7, ["y"] = 10, ["z"] = 11, ["name"] = "the_build_spawner:white"}, {["x"] = 7, ["y"] = 10, ["z"] = 12, ["name"] = "the_build_spawner:white"}, {["x"] = 7, ["y"] = 10, ["param1"] = 150, ["z"] = 13, ["name"] = "the_build_spawner:white"}, {["x"] = 7, ["param2"] = 21, ["y"] = 11, ["param1"] = 62, ["z"] = 0, ["name"] = "stairs:slab_stone_block"}, {["x"] = 7, ["y"] = 11, ["param1"] = 150, ["z"] = 1, ["name"] = "the_build_spawner:white"}, {["x"] = 7, ["y"] = 11, ["z"] = 7, ["name"] = "the_build_spawner:white"}, {["x"] = 7, ["y"] = 11, ["z"] = 8, ["name"] = "the_build_spawner:white"}, {["x"] = 7, ["y"] = 11, ["z"] = 9, ["name"] = "the_build_spawner:white"}, {["x"] = 7, ["y"] = 11, ["z"] = 10, ["name"] = "the_build_spawner:white"}, {["x"] = 7, ["y"] = 11, ["z"] = 11, ["name"] = "the_build_spawner:white"}, {["x"] = 7, ["y"] = 11, ["z"] = 12, ["name"] = "the_build_spawner:white"}, {["x"] = 7, ["y"] = 11, ["param1"] = 150, ["z"] = 13, ["name"] = "the_build_spawner:white"}, {["x"] = 7, ["param2"] = 21, ["y"] = 11, ["param1"] = 126, ["z"] = 14, ["name"] = "stairs:slab_stone_block"}, {["x"] = 7, ["y"] = 12, ["param1"] = 62, ["z"] = 1, ["name"] = "stairs:slab_stone_block"}, {["x"] = 7, ["y"] = 12, ["param1"] = 78, ["z"] = 2, ["name"] = "stairs:slab_stone_block"}, {["x"] = 7, ["y"] = 12, ["param1"] = 94, ["z"] = 3, ["name"] = "stairs:slab_stone_block"}, {["x"] = 7, ["y"] = 12, ["param1"] = 110, ["z"] = 4, ["name"] = "stairs:slab_stone_block"}, {["x"] = 7, ["y"] = 12, ["param1"] = 126, ["z"] = 5, ["name"] = "stairs:slab_stone_block"}, {["x"] = 7, ["y"] = 12, ["param1"] = 142, ["z"] = 6, ["name"] = "stairs:slab_stone_block"}, {["x"] = 7, ["y"] = 12, ["param1"] = 158, ["z"] = 7, ["name"] = "stairs:slab_stone_block"}, {["x"] = 7, ["y"] = 12, ["param1"] = 174, ["z"] = 8, ["name"] = "stairs:slab_stone_block"}, {["x"] = 7, ["y"] = 12, ["param1"] = 190, ["z"] = 9, ["name"] = "stairs:slab_stone_block"}, {["x"] = 7, ["y"] = 12, ["param1"] = 206, ["z"] = 10, ["name"] = "stairs:slab_stone_block"}, {["x"] = 7, ["y"] = 12, ["param1"] = 190, ["z"] = 11, ["name"] = "stairs:slab_stone_block"}, {["x"] = 7, ["y"] = 12, ["param1"] = 174, ["z"] = 12, ["name"] = "stairs:slab_stone_block"}, {["x"] = 7, ["y"] = 12, ["param1"] = 158, ["z"] = 13, ["name"] = "stairs:slab_stone_block"}, {["x"] = 8, ["y"] = 0, ["param1"] = 23, ["z"] = 0, ["name"] = "default:dirt_with_grass"}, {["x"] = 8, ["y"] = 0, ["param1"] = 150, ["z"] = 1, ["name"] = "the_build_spawner:white"}, {["x"] = 8, ["y"] = 0, ["z"] = 2, ["name"] = "the_build_spawner:white"}, {["x"] = 8, ["y"] = 0, ["z"] = 3, ["name"] = "the_build_spawner:black"}, {["x"] = 8, ["y"] = 0, ["z"] = 4, ["name"] = "the_build_spawner:white"}, {["x"] = 8, ["y"] = 0, ["param1"] = 23, ["z"] = 5, ["name"] = "the_build_spawner:black"}, {["x"] = 8, ["y"] = 0, ["z"] = 6, ["name"] = "the_build_spawner:white"}, {["x"] = 8, ["y"] = 0, ["param1"] = 23, ["z"] = 7, ["name"] = "the_build_spawner:black"}, {["x"] = 8, ["y"] = 0, ["z"] = 8, ["name"] = "the_build_spawner:white"}, {["x"] = 8, ["y"] = 0, ["param1"] = 23, ["z"] = 9, ["name"] = "the_build_spawner:black"}, {["x"] = 8, ["y"] = 0, ["z"] = 10, ["name"] = "the_build_spawner:white"}, {["x"] = 8, ["y"] = 0, ["param1"] = 23, ["z"] = 11, ["name"] = "the_build_spawner:black"}, {["x"] = 8, ["y"] = 0, ["z"] = 12, ["name"] = "the_build_spawner:white"}, {["x"] = 8, ["y"] = 0, ["param1"] = 150, ["z"] = 13, ["name"] = "the_build_spawner:white"}, {["x"] = 8, ["param2"] = 22, ["y"] = 0, ["param1"] = 123, ["z"] = 14, ["name"] = "stairs:slab_stone_block"}, {["x"] = 8, ["param2"] = 23, ["y"] = 0, ["param1"] = 108, ["z"] = 15, ["name"] = "stairs:slab_stone_block"}, {["x"] = 8, ["param2"] = 21, ["y"] = 0, ["param1"] = 92, ["z"] = 16, ["name"] = "stairs:slab_stone_block"}, {["x"] = 8, ["y"] = 0, ["z"] = 17, ["name"] = "default:dirt_with_grass"}, {["x"] = 8, ["y"] = 1, ["param1"] = 150, ["z"] = 1, ["name"] = "the_build_spawner:white"}, {["x"] = 8, ["meta"] = {["fields"] = {["state"] = "2"}, ["inventory"] = {}}, ["param2"] = 2, ["y"] = 1, ["param1"] = 155, ["z"] = 13, ["name"] = "doors:door_wood_b"}, {["x"] = 8, ["y"] = 2, ["param1"] = 171, ["z"] = 1, ["name"] = "default:glass"}, {["x"] = 8, ["param2"] = 1, ["y"] = 2, ["param1"] = 171, ["z"] = 13, ["name"] = "doors:hidden"}, {["x"] = 8, ["y"] = 3, ["param1"] = 187, ["z"] = 1, ["name"] = "default:glass"}, {["x"] = 8, ["param2"] = 22, ["y"] = 3, ["param1"] = 187, ["z"] = 13, ["name"] = "stairs:stair_silver_sandstone"}, {["x"] = 8, ["y"] = 4, ["param1"] = 204, ["z"] = 1, ["name"] = "default:glass"}, {["x"] = 8, ["y"] = 4, ["z"] = 7, ["name"] = "the_build_spawner:white"}, {["x"] = 8, ["y"] = 4, ["param1"] = 150, ["z"] = 13, ["name"] = "the_build_spawner:white"}, {["x"] = 8, ["y"] = 5, ["param1"] = 150, ["z"] = 1, ["name"] = "the_build_spawner:white"}, {["x"] = 8, ["y"] = 5, ["param1"] = 238, ["z"] = 2, ["name"] = "default:mese_post_light_aspen_wood"}, {["x"] = 8, ["y"] = 5, ["param1"] = 238, ["z"] = 6, ["name"] = "default:mese_post_light_aspen_wood"}, {["x"] = 8, ["y"] = 5, ["z"] = 7, ["name"] = "the_build_spawner:white"}, {["x"] = 8, ["y"] = 5, ["z"] = 12, ["name"] = "the_build_spawner:white"}, {["x"] = 8, ["y"] = 5, ["param1"] = 150, ["z"] = 13, ["name"] = "the_build_spawner:white"}, {["x"] = 8, ["y"] = 5, ["z"] = 14, ["name"] = "the_build_spawner:white"}, {["x"] = 8, ["param2"] = 2, ["y"] = 5, ["param1"] = 126, ["z"] = 15, ["name"] = "stairs:slab_stone_block"}, {["x"] = 8, ["param2"] = 2, ["y"] = 5, ["param1"] = 110, ["z"] = 16, ["name"] = "stairs:slab_stone_block"}, {["x"] = 8, ["param2"] = 2, ["y"] = 5, ["param1"] = 94, ["z"] = 17, ["name"] = "stairs:slab_stone_block"}, {["x"] = 8, ["param2"] = 2, ["y"] = 6, ["param1"] = 156, ["z"] = 0, ["name"] = "stairs:slab_stone_block"}, {["x"] = 8, ["y"] = 6, ["param1"] = 150, ["z"] = 1, ["name"] = "the_build_spawner:white"}, {["x"] = 8, ["y"] = 6, ["param1"] = 92, ["z"] = 2, ["name"] = "the_build_spawner:white"}, {["x"] = 8, ["y"] = 6, ["param1"] = 108, ["z"] = 3, ["name"] = "the_build_spawner:white"}, {["x"] = 8, ["y"] = 6, ["param1"] = 124, ["z"] = 4, ["name"] = "the_build_spawner:white"}, {["x"] = 8, ["y"] = 6, ["param1"] = 140, ["z"] = 5, ["name"] = "the_build_spawner:white"}, {["x"] = 8, ["y"] = 6, ["param1"] = 156, ["z"] = 6, ["name"] = "the_build_spawner:white"}, {["x"] = 8, ["y"] = 6, ["param1"] = 172, ["z"] = 7, ["name"] = "the_build_spawner:white"}, {["x"] = 8, ["y"] = 6, ["param1"] = 188, ["z"] = 8, ["name"] = "the_build_spawner:white"}, {["x"] = 8, ["y"] = 6, ["param1"] = 172, ["z"] = 9, ["name"] = "the_build_spawner:white"}, {["x"] = 8, ["y"] = 6, ["param1"] = 156, ["z"] = 10, ["name"] = "the_build_spawner:white"}, {["x"] = 8, ["y"] = 6, ["param1"] = 172, ["z"] = 11, ["name"] = "the_build_spawner:white"}, {["x"] = 8, ["y"] = 6, ["param1"] = 156, ["z"] = 12, ["name"] = "the_build_spawner:white"}, {["x"] = 8, ["y"] = 6, ["z"] = 13, ["name"] = "the_build_spawner:white"}, {["x"] = 8, ["param2"] = 2, ["y"] = 6, ["param1"] = 126, ["z"] = 14, ["name"] = "stairs:slab_stone_block"}, {["x"] = 8, ["y"] = 7, ["param1"] = 150, ["z"] = 1, ["name"] = "the_build_spawner:white"}, {["x"] = 8, ["param2"] = 2, ["y"] = 7, ["param1"] = 77, ["z"] = 2, ["name"] = "stairs:stair_wood"}, {["x"] = 8, ["y"] = 7, ["z"] = 7, ["name"] = "the_build_spawner:white"}, {["x"] = 8, ["meta"] = {["fields"] = {["infotext"] = "\27(T@default)Chest\27E"}, ["inventory"] = {["main"] = {"", "", "", "", "", "", "", "", "", "", "", "", "", "", "", "", "", "", "", "", "", "", "", "", "", "", "", "", "", "", "", ""}}}, ["param2"] = 2, ["y"] = 7, ["param1"] = 140, ["z"] = 8, ["name"] = "default:chest"}, {["x"] = 8, ["param2"] = 21, ["y"] = 7, ["param1"] = 172, ["z"] = 10, ["name"] = "stairs:stair_steelblock"}, {["x"] = 8, ["y"] = 7, ["param1"] = 157, ["z"] = 11, ["name"] = "stairs:slab_steelblock"}, {["x"] = 8, ["param2"] = 4, ["y"] = 7, ["param1"] = 141, ["z"] = 12, ["name"] = "stairs:slab_steelblock"}, {["x"] = 8, ["y"] = 7, ["param1"] = 150, ["z"] = 13, ["name"] = "the_build_spawner:white"}, {["x"] = 8, ["y"] = 8, ["param1"] = 109, ["z"] = 1, ["name"] = "default:glass"}, {["x"] = 8, ["y"] = 8, ["z"] = 7, ["name"] = "the_build_spawner:white"}, {["x"] = 8, ["meta"] = {["fields"] = {["infotext"] = "\27(T@default)Empty Bookshelf\27E", ["formspec"] = "size[8,7;]list[context;books;0,0.3;8,2;]list[current_player;main;0,2.85;8,1;]list[current_player;main;0,4.08;8,3;8]listring[context;books]listring[current_player;main]image[0,2.85;1,1;gui_hb_bg.png]image[1,2.85;1,1;gui_hb_bg.png]image[2,2.85;1,1;gui_hb_bg.png]image[3,2.85;1,1;gui_hb_bg.png]image[4,2.85;1,1;gui_hb_bg.png]image[5,2.85;1,1;gui_hb_bg.png]image[6,2.85;1,1;gui_hb_bg.png]image[7,2.85;1,1;gui_hb_bg.png]image[0,0.3;1,1;default_bookshelf_slot.png]image[1,0.3;1,1;default_bookshelf_slot.png]image[2,0.3;1,1;default_bookshelf_slot.png]image[3,0.3;1,1;default_bookshelf_slot.png]image[4,0.3;1,1;default_bookshelf_slot.png]image[5,0.3;1,1;default_bookshelf_slot.png]image[6,0.3;1,1;default_bookshelf_slot.png]image[7,0.3;1,1;default_bookshelf_slot.png]image[0,1.3;1,1;default_bookshelf_slot.png]image[1,1.3;1,1;default_bookshelf_slot.png]image[2,1.3;1,1;default_bookshelf_slot.png]image[3,1.3;1,1;default_bookshelf_slot.png]image[4,1.3;1,1;default_bookshelf_slot.png]image[5,1.3;1,1;default_bookshelf_slot.png]image[6,1.3;1,1;default_bookshelf_slot.png]image[7,1.3;1,1;default_bookshelf_slot.png]"}, ["inventory"] = {["books"] = {"", "", "", "", "", "", "", "", "", "", "", "", "", "", "", ""}}}, ["param2"] = 2, ["y"] = 8, ["z"] = 8, ["name"] = "default:bookshelf"}, {["x"] = 8, ["y"] = 8, ["param1"] = 141, ["z"] = 13, ["name"] = "default:glass"}, {["x"] = 8, ["y"] = 9, ["param1"] = 94, ["z"] = 1, ["name"] = "default:glass"}, {["x"] = 8, ["y"] = 9, ["z"] = 7, ["name"] = "the_build_spawner:white"}, {["x"] = 8, ["y"] = 9, ["param1"] = 158, ["z"] = 13, ["name"] = "default:glass"}, {["x"] = 8, ["y"] = 10, ["param1"] = 78, ["z"] = 1, ["name"] = "default:glass"}, {["x"] = 8, ["y"] = 10, ["z"] = 7, ["name"] = "the_build_spawner:white"}, {["x"] = 8, ["y"] = 10, ["param1"] = 174, ["z"] = 13, ["name"] = "default:glass"}, {["x"] = 8, ["param2"] = 21, ["y"] = 11, ["param1"] = 78, ["z"] = 0, ["name"] = "stairs:slab_stone_block"}, {["x"] = 8, ["y"] = 11, ["param1"] = 150, ["z"] = 1, ["name"] = "the_build_spawner:white"}, {["x"] = 8, ["y"] = 11, ["z"] = 7, ["name"] = "the_build_spawner:white"}, {["x"] = 8, ["y"] = 11, ["param1"] = 238, ["z"] = 10, ["name"] = "default:mese_post_light_aspen_wood"}, {["x"] = 8, ["y"] = 11, ["param1"] = 150, ["z"] = 13, ["name"] = "the_build_spawner:white"}, {["x"] = 8, ["param2"] = 21, ["y"] = 11, ["param1"] = 142, ["z"] = 14, ["name"] = "stairs:slab_stone_block"}, {["x"] = 8, ["y"] = 12, ["param1"] = 78, ["z"] = 1, ["name"] = "stairs:slab_stone_block"}, {["x"] = 8, ["y"] = 12, ["param1"] = 94, ["z"] = 2, ["name"] = "stairs:slab_stone_block"}, {["x"] = 8, ["y"] = 12, ["param1"] = 110, ["z"] = 3, ["name"] = "stairs:slab_stone_block"}, {["x"] = 8, ["y"] = 12, ["param1"] = 126, ["z"] = 4, ["name"] = "stairs:slab_stone_block"}, {["x"] = 8, ["y"] = 12, ["param1"] = 142, ["z"] = 5, ["name"] = "stairs:slab_stone_block"}, {["x"] = 8, ["y"] = 12, ["param1"] = 158, ["z"] = 6, ["name"] = "stairs:slab_stone_block"}, {["x"] = 8, ["y"] = 12, ["param1"] = 174, ["z"] = 7, ["name"] = "stairs:slab_stone_block"}, {["x"] = 8, ["y"] = 12, ["param1"] = 190, ["z"] = 8, ["name"] = "stairs:slab_stone_block"}, {["x"] = 8, ["y"] = 12, ["param1"] = 206, ["z"] = 9, ["name"] = "stairs:slab_stone_block"}, {["x"] = 8, ["y"] = 12, ["param1"] = 222, ["z"] = 10, ["name"] = "stairs:slab_stone_block"}, {["x"] = 8, ["y"] = 12, ["param1"] = 206, ["z"] = 11, ["name"] = "stairs:slab_stone_block"}, {["x"] = 8, ["y"] = 12, ["param1"] = 190, ["z"] = 12, ["name"] = "stairs:slab_stone_block"}, {["x"] = 8, ["y"] = 12, ["param1"] = 174, ["z"] = 13, ["name"] = "stairs:slab_stone_block"}, {["x"] = 9, ["y"] = 0, ["param1"] = 23, ["z"] = 0, ["name"] = "default:dirt_with_grass"}, {["x"] = 9, ["y"] = 0, ["param1"] = 150, ["z"] = 1, ["name"] = "the_build_spawner:white"}, {["x"] = 9, ["y"] = 0, ["param1"] = 23, ["z"] = 2, ["name"] = "the_build_spawner:black"}, {["x"] = 9, ["y"] = 0, ["z"] = 3, ["name"] = "the_build_spawner:white"}, {["x"] = 9, ["y"] = 0, ["param1"] = 23, ["z"] = 4, ["name"] = "the_build_spawner:black"}, {["x"] = 9, ["y"] = 0, ["z"] = 5, ["name"] = "the_build_spawner:white"}, {["x"] = 9, ["y"] = 0, ["param1"] = 23, ["z"] = 6, ["name"] = "the_build_spawner:black"}, {["x"] = 9, ["y"] = 0, ["z"] = 7, ["name"] = "the_build_spawner:white"}, {["x"] = 9, ["y"] = 0, ["param1"] = 23, ["z"] = 8, ["name"] = "the_build_spawner:black"}, {["x"] = 9, ["y"] = 0, ["z"] = 9, ["name"] = "the_build_spawner:white"}, {["x"] = 9, ["y"] = 0, ["param1"] = 23, ["z"] = 10, ["name"] = "the_build_spawner:black"}, {["x"] = 9, ["y"] = 0, ["z"] = 11, ["name"] = "the_build_spawner:white"}, {["x"] = 9, ["y"] = 0, ["param1"] = 23, ["z"] = 12, ["name"] = "the_build_spawner:black"}, {["x"] = 9, ["y"] = 0, ["param1"] = 150, ["z"] = 13, ["name"] = "the_build_spawner:white"}, {["x"] = 9, ["param2"] = 22, ["y"] = 0, ["param1"] = 106, ["z"] = 14, ["name"] = "stairs:slab_stone_block"}, {["x"] = 9, ["param2"] = 23, ["y"] = 0, ["param1"] = 91, ["z"] = 15, ["name"] = "stairs:slab_stone_block"}, {["x"] = 9, ["param2"] = 21, ["y"] = 0, ["param1"] = 76, ["z"] = 16, ["name"] = "stairs:slab_stone_block"}, {["x"] = 9, ["y"] = 0, ["z"] = 17, ["name"] = "default:dirt_with_grass"}, {["x"] = 9, ["y"] = 1, ["param1"] = 150, ["z"] = 1, ["name"] = "the_build_spawner:white"}, {["x"] = 9, ["meta"] = {["fields"] = {["formspec"] = "field[text;;${text}]"}, ["inventory"] = {}}, ["param2"] = 2, ["y"] = 1, ["param1"] = 136, ["z"] = 5, ["name"] = "default:sign_wall_wood"}, {["x"] = 9, ["y"] = 1, ["z"] = 7, ["name"] = "the_build_spawner:white"}, {["x"] = 9, ["meta"] = {["fields"] = {["state"] = "0"}, ["inventory"] = {}}, ["param2"] = 2, ["y"] = 1, ["param1"] = 138, ["z"] = 13, ["name"] = "doors:door_wood_a"}, {["x"] = 9, ["y"] = 2, ["param1"] = 155, ["z"] = 1, ["name"] = "default:glass"}, {["x"] = 9, ["y"] = 2, ["param1"] = 153, ["z"] = 7, ["name"] = "default:glass"}, {["x"] = 9, ["param2"] = 2, ["y"] = 2, ["param1"] = 154, ["z"] = 13, ["name"] = "doors:hidden"}, {["x"] = 9, ["y"] = 3, ["param1"] = 171, ["z"] = 1, ["name"] = "default:glass"}, {["x"] = 9, ["param2"] = 22, ["y"] = 3, ["param1"] = 170, ["z"] = 13, ["name"] = "stairs:stair_silver_sandstone"}, {["x"] = 9, ["y"] = 4, ["param1"] = 187, ["z"] = 1, ["name"] = "default:glass"}, {["x"] = 9, ["y"] = 4, ["z"] = 7, ["name"] = "the_build_spawner:white"}, {["x"] = 9, ["y"] = 4, ["param1"] = 150, ["z"] = 13, ["name"] = "the_build_spawner:white"}, {["x"] = 9, ["y"] = 5, ["param1"] = 150, ["z"] = 1, ["name"] = "the_build_spawner:white"}, {["x"] = 9, ["y"] = 5, ["z"] = 7, ["name"] = "the_build_spawner:white"}, {["x"] = 9, ["y"] = 5, ["z"] = 12, ["name"] = "the_build_spawner:white"}, {["x"] = 9, ["y"] = 5, ["param1"] = 150, ["z"] = 13, ["name"] = "the_build_spawner:white"}, {["x"] = 9, ["y"] = 5, ["z"] = 14, ["name"] = "the_build_spawner:white"}, {["x"] = 9, ["param2"] = 2, ["y"] = 5, ["param1"] = 110, ["z"] = 15, ["name"] = "stairs:slab_stone_block"}, {["x"] = 9, ["param2"] = 2, ["y"] = 5, ["param1"] = 94, ["z"] = 16, ["name"] = "stairs:slab_stone_block"}, {["x"] = 9, ["param2"] = 2, ["y"] = 5, ["param1"] = 78, ["z"] = 17, ["name"] = "stairs:slab_stone_block"}, {["x"] = 9, ["param2"] = 2, ["y"] = 6, ["param1"] = 140, ["z"] = 0, ["name"] = "stairs:slab_stone_block"}, {["x"] = 9, ["y"] = 6, ["param1"] = 150, ["z"] = 1, ["name"] = "the_build_spawner:white"}, {["x"] = 9, ["y"] = 6, ["param1"] = 76, ["z"] = 2, ["name"] = "the_build_spawner:white"}, {["x"] = 9, ["y"] = 6, ["param1"] = 92, ["z"] = 3, ["name"] = "the_build_spawner:white"}, {["x"] = 9, ["y"] = 6, ["param1"] = 108, ["z"] = 4, ["name"] = "the_build_spawner:white"}, {["x"] = 9, ["y"] = 6, ["param1"] = 124, ["z"] = 5, ["name"] = "the_build_spawner:white"}, {["x"] = 9, ["y"] = 6, ["param1"] = 140, ["z"] = 6, ["name"] = "the_build_spawner:white"}, {["x"] = 9, ["y"] = 6, ["param1"] = 156, ["z"] = 7, ["name"] = "the_build_spawner:white"}, {["x"] = 9, ["y"] = 6, ["param1"] = 172, ["z"] = 8, ["name"] = "the_build_spawner:white"}, {["x"] = 9, ["y"] = 6, ["param1"] = 156, ["z"] = 9, ["name"] = "the_build_spawner:white"}, {["x"] = 9, ["y"] = 6, ["param1"] = 140, ["z"] = 10, ["name"] = "the_build_spawner:white"}, {["x"] = 9, ["y"] = 6, ["param1"] = 156, ["z"] = 11, ["name"] = "the_build_spawner:white"}, {["x"] = 9, ["y"] = 6, ["param1"] = 140, ["z"] = 12, ["name"] = "the_build_spawner:white"}, {["x"] = 9, ["y"] = 6, ["z"] = 13, ["name"] = "the_build_spawner:white"}, {["x"] = 9, ["param2"] = 2, ["y"] = 6, ["param1"] = 110, ["z"] = 14, ["name"] = "stairs:slab_stone_block"}, {["x"] = 9, ["y"] = 7, ["param1"] = 150, ["z"] = 1, ["name"] = "the_build_spawner:white"}, {["x"] = 9, ["meta"] = {["fields"] = {["formspec"] = "field[text;;${text}]"}, ["inventory"] = {}}, ["param2"] = 3, ["y"] = 7, ["param1"] = 61, ["z"] = 2, ["name"] = "default:sign_wall_wood"}, {["x"] = 9, ["y"] = 7, ["z"] = 7, ["name"] = "the_build_spawner:white"}, {["x"] = 9, ["param2"] = 8, ["y"] = 7, ["param1"] = 157, ["z"] = 8, ["name"] = "stairs:slab_steelblock"}, {["x"] = 9, ["param2"] = 2, ["y"] = 7, ["param1"] = 142, ["z"] = 9, ["name"] = "stairs:slab_steelblock"}, {["x"] = 9, ["param2"] = 21, ["y"] = 7, ["param1"] = 157, ["z"] = 10, ["name"] = "stairs:slab_steelblock"}, {["x"] = 9, ["y"] = 7, ["param1"] = 150, ["z"] = 13, ["name"] = "the_build_spawner:white"}, {["x"] = 9, ["y"] = 8, ["param1"] = 93, ["z"] = 1, ["name"] = "default:glass"}, {["x"] = 9, ["y"] = 8, ["z"] = 7, ["name"] = "the_build_spawner:white"}, {["x"] = 9, ["param2"] = 8, ["y"] = 8, ["param1"] = 174, ["z"] = 8, ["name"] = "stairs:slab_steelblock"}, {["x"] = 9, ["y"] = 8, ["param1"] = 157, ["z"] = 13, ["name"] = "default:glass"}, {["x"] = 9, ["y"] = 9, ["param1"] = 78, ["z"] = 1, ["name"] = "default:glass"}, {["x"] = 9, ["y"] = 9, ["z"] = 7, ["name"] = "the_build_spawner:white"}, {["x"] = 9, ["y"] = 9, ["param1"] = 174, ["z"] = 13, ["name"] = "default:glass"}, {["x"] = 9, ["y"] = 10, ["param1"] = 62, ["z"] = 1, ["name"] = "default:glass"}, {["x"] = 9, ["y"] = 10, ["z"] = 7, ["name"] = "the_build_spawner:white"}, {["x"] = 9, ["y"] = 10, ["param1"] = 190, ["z"] = 13, ["name"] = "default:glass"}, {["x"] = 9, ["param2"] = 21, ["y"] = 11, ["param1"] = 62, ["z"] = 0, ["name"] = "stairs:slab_stone_block"}, {["x"] = 9, ["y"] = 11, ["param1"] = 150, ["z"] = 1, ["name"] = "the_build_spawner:white"}, {["x"] = 9, ["y"] = 11, ["z"] = 7, ["name"] = "the_build_spawner:white"}, {["x"] = 9, ["y"] = 11, ["param1"] = 150, ["z"] = 13, ["name"] = "the_build_spawner:white"}, {["x"] = 9, ["param2"] = 21, ["y"] = 11, ["param1"] = 158, ["z"] = 14, ["name"] = "stairs:slab_stone_block"}, {["x"] = 9, ["y"] = 12, ["param1"] = 94, ["z"] = 1, ["name"] = "stairs:slab_stone_block"}, {["x"] = 9, ["y"] = 12, ["param1"] = 110, ["z"] = 2, ["name"] = "stairs:slab_stone_block"}, {["x"] = 9, ["y"] = 12, ["param1"] = 126, ["z"] = 3, ["name"] = "stairs:slab_stone_block"}, {["x"] = 9, ["y"] = 12, ["param1"] = 142, ["z"] = 4, ["name"] = "stairs:slab_stone_block"}, {["x"] = 9, ["y"] = 12, ["param1"] = 158, ["z"] = 5, ["name"] = "stairs:slab_stone_block"}, {["x"] = 9, ["y"] = 12, ["param1"] = 174, ["z"] = 6, ["name"] = "stairs:slab_stone_block"}, {["x"] = 9, ["y"] = 12, ["param1"] = 190, ["z"] = 7, ["name"] = "stairs:slab_stone_block"}, {["x"] = 9, ["y"] = 12, ["param1"] = 206, ["z"] = 8, ["name"] = "stairs:slab_stone_block"}, {["x"] = 9, ["y"] = 12, ["param1"] = 190, ["z"] = 9, ["name"] = "stairs:slab_stone_block"}, {["x"] = 9, ["y"] = 12, ["param1"] = 206, ["z"] = 10, ["name"] = "stairs:slab_stone_block"}, {["x"] = 9, ["y"] = 12, ["param1"] = 190, ["z"] = 11, ["name"] = "stairs:slab_stone_block"}, {["x"] = 9, ["y"] = 12, ["param1"] = 206, ["z"] = 12, ["name"] = "stairs:slab_stone_block"}, {["x"] = 9, ["y"] = 12, ["param1"] = 190, ["z"] = 13, ["name"] = "stairs:slab_stone_block"}, {["x"] = 10, ["y"] = 0, ["param1"] = 23, ["z"] = 0, ["name"] = "default:dirt_with_grass"}, {["x"] = 10, ["y"] = 0, ["param1"] = 150, ["z"] = 1, ["name"] = "the_build_spawner:white"}, {["x"] = 10, ["y"] = 0, ["z"] = 2, ["name"] = "the_build_spawner:white"}, {["x"] = 10, ["y"] = 0, ["param1"] = 23, ["z"] = 3, ["name"] = "the_build_spawner:black"}, {["x"] = 10, ["y"] = 0, ["z"] = 4, ["name"] = "the_build_spawner:white"}, {["x"] = 10, ["y"] = 0, ["param1"] = 23, ["z"] = 5, ["name"] = "the_build_spawner:black"}, {["x"] = 10, ["y"] = 0, ["z"] = 6, ["name"] = "the_build_spawner:white"}, {["x"] = 10, ["y"] = 0, ["param1"] = 23, ["z"] = 7, ["name"] = "the_build_spawner:black"}, {["x"] = 10, ["y"] = 0, ["z"] = 8, ["name"] = "the_build_spawner:white"}, {["x"] = 10, ["y"] = 0, ["param1"] = 23, ["z"] = 9, ["name"] = "the_build_spawner:black"}, {["x"] = 10, ["y"] = 0, ["z"] = 10, ["name"] = "the_build_spawner:white"}, {["x"] = 10, ["y"] = 0, ["param1"] = 23, ["z"] = 11, ["name"] = "the_build_spawner:black"}, {["x"] = 10, ["y"] = 0, ["z"] = 12, ["name"] = "the_build_spawner:white"}, {["x"] = 10, ["y"] = 0, ["param1"] = 150, ["z"] = 13, ["name"] = "the_build_spawner:white"}, {["x"] = 10, ["param2"] = 22, ["y"] = 0, ["param1"] = 90, ["z"] = 14, ["name"] = "stairs:slab_stone_block"}, {["x"] = 10, ["param2"] = 23, ["y"] = 0, ["param1"] = 75, ["z"] = 15, ["name"] = "stairs:slab_stone_block"}, {["x"] = 10, ["param2"] = 21, ["y"] = 0, ["param1"] = 60, ["z"] = 16, ["name"] = "stairs:slab_stone_block"}, {["x"] = 10, ["y"] = 0, ["z"] = 17, ["name"] = "default:dirt_with_grass"}, {["x"] = 10, ["y"] = 1, ["param1"] = 150, ["z"] = 1, ["name"] = "the_build_spawner:white"}, {["x"] = 10, ["param2"] = 2, ["y"] = 1, ["param1"] = 119, ["z"] = 5, ["name"] = "stairs:stair_wood"}, {["x"] = 10, ["y"] = 1, ["z"] = 7, ["name"] = "the_build_spawner:white"}, {["x"] = 10, ["meta"] = {["fields"] = {["infotext"] = "\27(T@default)\"\27Freception\27E\"\27E", ["formspec"] = "field[text;;${text}]", ["text"] = "reception"}, ["inventory"] = {}}, ["param2"] = 5, ["y"] = 1, ["param1"] = 136, ["z"] = 8, ["name"] = "default:sign_wall_wood"}, {["x"] = 10, ["y"] = 1, ["param1"] = 136, ["z"] = 12, ["name"] = "default:fence_wood"}, {["x"] = 10, ["y"] = 1, ["param1"] = 150, ["z"] = 13, ["name"] = "the_build_spawner:white"}, {["x"] = 10, ["y"] = 2, ["param1"] = 150, ["z"] = 1, ["name"] = "the_build_spawner:white"}, {["x"] = 10, ["y"] = 2, ["param1"] = 136, ["z"] = 7, ["name"] = "default:glass"}, {["x"] = 10, ["param2"] = 1, ["y"] = 2, ["param1"] = 153, ["z"] = 12, ["name"] = "default:aspen_leaves"}, {["x"] = 10, ["y"] = 2, ["param1"] = 150, ["z"] = 13, ["name"] = "the_build_spawner:white"}, {["x"] = 10, ["y"] = 3, ["param1"] = 150, ["z"] = 1, ["name"] = "the_build_spawner:white"}, {["x"] = 10, ["param2"] = 1, ["y"] = 3, ["param1"] = 170, ["z"] = 12, ["name"] = "default:aspen_leaves"}, {["x"] = 10, ["y"] = 3, ["param1"] = 150, ["z"] = 13, ["name"] = "the_build_spawner:white"}, {["x"] = 10, ["y"] = 4, ["param1"] = 150, ["z"] = 1, ["name"] = "the_build_spawner:white"}, {["x"] = 10, ["y"] = 4, ["z"] = 7, ["name"] = "the_build_spawner:white"}, {["x"] = 10, ["y"] = 4, ["param1"] = 150, ["z"] = 13, ["name"] = "the_build_spawner:white"}, {["x"] = 10, ["y"] = 5, ["param1"] = 150, ["z"] = 1, ["name"] = "the_build_spawner:white"}, {["x"] = 10, ["y"] = 5, ["z"] = 7, ["name"] = "the_build_spawner:white"}, {["x"] = 10, ["y"] = 5, ["z"] = 12, ["name"] = "the_build_spawner:white"}, {["x"] = 10, ["y"] = 5, ["param1"] = 150, ["z"] = 13, ["name"] = "the_build_spawner:white"}, {["x"] = 10, ["y"] = 5, ["z"] = 14, ["name"] = "the_build_spawner:white"}, {["x"] = 10, ["param2"] = 2, ["y"] = 5, ["param1"] = 94, ["z"] = 15, ["name"] = "stairs:slab_stone_block"}, {["x"] = 10, ["param2"] = 2, ["y"] = 5, ["param1"] = 78, ["z"] = 16, ["name"] = "stairs:slab_stone_block"}, {["x"] = 10, ["param2"] = 2, ["y"] = 5, ["param1"] = 62, ["z"] = 17, ["name"] = "stairs:slab_stone_block"}, {["x"] = 10, ["param2"] = 2, ["y"] = 6, ["param1"] = 124, ["z"] = 0, ["name"] = "stairs:slab_stone_block"}, {["x"] = 10, ["y"] = 6, ["param1"] = 150, ["z"] = 1, ["name"] = "the_build_spawner:white"}, {["x"] = 10, ["y"] = 6, ["param1"] = 60, ["z"] = 2, ["name"] = "the_build_spawner:white"}, {["x"] = 10, ["y"] = 6, ["param1"] = 76, ["z"] = 3, ["name"] = "the_build_spawner:white"}, {["x"] = 10, ["y"] = 6, ["param1"] = 92, ["z"] = 4, ["name"] = "the_build_spawner:white"}, {["x"] = 10, ["y"] = 6, ["param1"] = 108, ["z"] = 5, ["name"] = "the_build_spawner:white"}, {["x"] = 10, ["y"] = 6, ["param1"] = 124, ["z"] = 6, ["name"] = "the_build_spawner:white"}, {["x"] = 10, ["y"] = 6, ["param1"] = 140, ["z"] = 7, ["name"] = "the_build_spawner:white"}, {["x"] = 10, ["y"] = 6, ["param1"] = 156, ["z"] = 8, ["name"] = "the_build_spawner:white"}, {["x"] = 10, ["y"] = 6, ["param1"] = 140, ["z"] = 9, ["name"] = "the_build_spawner:white"}, {["x"] = 10, ["y"] = 6, ["param1"] = 124, ["z"] = 10, ["name"] = "the_build_spawner:white"}, {["x"] = 10, ["y"] = 6, ["param1"] = 140, ["z"] = 11, ["name"] = "the_build_spawner:white"}, {["x"] = 10, ["y"] = 6, ["param1"] = 124, ["z"] = 12, ["name"] = "the_build_spawner:white"}, {["x"] = 10, ["y"] = 6, ["param1"] = 150, ["z"] = 13, ["name"] = "the_build_spawner:white"}, {["x"] = 10, ["param2"] = 2, ["y"] = 6, ["param1"] = 94, ["z"] = 14, ["name"] = "stairs:slab_stone_block"}, {["x"] = 10, ["y"] = 7, ["param1"] = 150, ["z"] = 1, ["name"] = "the_build_spawner:white"}, {["x"] = 10, ["meta"] = {["fields"] = {["formspec"] = "field[text;;${text}]"}, ["inventory"] = {}}, ["param2"] = 2, ["y"] = 7, ["param1"] = 45, ["z"] = 2, ["name"] = "default:sign_wall_wood"}, {["x"] = 10, ["y"] = 7, ["z"] = 7, ["name"] = "the_build_spawner:white"}, {["x"] = 10, ["y"] = 7, ["z"] = 8, ["name"] = "default:steelblock"}, {["x"] = 10, ["param2"] = 22, ["y"] = 7, ["param1"] = 157, ["z"] = 9, ["name"] = "doors:trapdoor"}, {["x"] = 10, ["param2"] = 23, ["y"] = 7, ["param1"] = 141, ["z"] = 10, ["name"] = "stairs:stair_steelblock"}, {["x"] = 10, ["y"] = 7, ["param1"] = 157, ["z"] = 11, ["name"] = "stairs:slab_steelblock"}, {["x"] = 10, ["param2"] = 4, ["y"] = 7, ["param1"] = 172, ["z"] = 12, ["name"] = "stairs:slab_steelblock"}, {["x"] = 10, ["y"] = 7, ["param1"] = 150, ["z"] = 13, ["name"] = "the_build_spawner:white"}, {["x"] = 10, ["y"] = 8, ["param1"] = 150, ["z"] = 1, ["name"] = "the_build_spawner:white"}, {["x"] = 10, ["y"] = 8, ["z"] = 7, ["name"] = "the_build_spawner:white"}, {["x"] = 10, ["y"] = 8, ["param1"] = 150, ["z"] = 13, ["name"] = "the_build_spawner:white"}, {["x"] = 10, ["y"] = 9, ["param1"] = 150, ["z"] = 1, ["name"] = "the_build_spawner:white"}, {["x"] = 10, ["y"] = 9, ["z"] = 7, ["name"] = "the_build_spawner:white"}, {["x"] = 10, ["y"] = 9, ["param1"] = 150, ["z"] = 13, ["name"] = "the_build_spawner:white"}, {["x"] = 10, ["y"] = 10, ["param1"] = 150, ["z"] = 1, ["name"] = "the_build_spawner:white"}, {["x"] = 10, ["y"] = 10, ["z"] = 7, ["name"] = "the_build_spawner:white"}, {["x"] = 10, ["y"] = 10, ["param1"] = 150, ["z"] = 13, ["name"] = "the_build_spawner:white"}, {["x"] = 10, ["param2"] = 21, ["y"] = 11, ["param1"] = 78, ["z"] = 0, ["name"] = "stairs:slab_stone_block"}, {["x"] = 10, ["y"] = 11, ["param1"] = 150, ["z"] = 1, ["name"] = "the_build_spawner:white"}, {["x"] = 10, ["y"] = 11, ["z"] = 7, ["name"] = "the_build_spawner:white"}, {["x"] = 10, ["y"] = 11, ["param1"] = 238, ["z"] = 8, ["name"] = "default:mese_post_light_aspen_wood"}, {["x"] = 10, ["y"] = 11, ["param1"] = 238, ["z"] = 12, ["name"] = "default:mese_post_light_aspen_wood"}, {["x"] = 10, ["y"] = 11, ["param1"] = 150, ["z"] = 13, ["name"] = "the_build_spawner:white"}, {["x"] = 10, ["param2"] = 21, ["y"] = 11, ["param1"] = 174, ["z"] = 14, ["name"] = "stairs:slab_stone_block"},