5:return {{["x"] = 0, ["y"] = 0, ["param1"] = 14, ["z"] = 0, ["name"] = "default:stone"}, {["x"] = 0, ["y"] = 0, ["z"] = 1, ["name"] = "default:stone"}, {["x"] = 0, ["y"] = 0, ["z"] = 2, ["name"] = "default:stone"}, {["x"] = 0, ["y"] = 0, ["z"] = 3, ["name"] = "default:stone"}, {["x"] = 0, ["y"] = 0, ["z"] = 4, ["name"] = "default:stone"}, {["x"] = 0, ["y"] = 0, ["z"] = 5, ["name"] = "default:stone"}, {["x"] = 0, ["y"] = 0, ["z"] = 6, ["name"] = "default:stone"}, {["x"] = 0, ["y"] = 0, ["z"] = 7, ["name"] = "default:stone"}, {["x"] = 0, ["y"] = 0, ["z"] = 8, ["name"] = "default:stone"}, {["x"] = 0, ["y"] = 0, ["z"] = 9, ["name"] = "default:stone"}, {["x"] = 0, ["y"] = 0, ["z"] = 10, ["name"] = "default:stone"}, {["x"] = 0, ["y"] = 0, ["z"] = 11, ["name"] = "default:stone"}, {["x"] = 0, ["y"] = 0, ["z"] = 12, ["name"] = "default:stone"}, {["x"] = 0, ["y"] = 0, ["z"] = 13, ["name"] = "default:stone"}, {["x"] = 0, ["y"] = 0, ["z"] = 14, ["name"] = "default:stone"}, {["x"] = 0, ["y"] = 0, ["z"] = 15, ["name"] = "default:dirt"}, {["x"] = 0, ["y"] = 1, ["z"] = 0, ["name"] = "default:dirt_with_grass"}, {["x"] = 0, ["y"] = 1, ["z"] = 1, ["name"] = "default:dirt_with_grass"}, {["x"] = 0, ["y"] = 1, ["z"] = 2, ["name"] = "default:dirt_with_grass"}, {["x"] = 0, ["y"] = 1, ["param1"] = 14, ["z"] = 3, ["name"] = "default:dirt_with_grass"}, {["x"] = 0, ["y"] = 1, ["param1"] = 14, ["z"] = 4, ["name"] = "default:dirt_with_grass"}, {["x"] = 0, ["y"] = 1, ["param1"] = 14, ["z"] = 5, ["name"] = "default:dirt_with_grass"}, {["x"] = 0, ["y"] = 1, ["param1"] = 14, ["z"] = 6, ["name"] = "default:dirt_with_grass"}, {["x"] = 0, ["y"] = 1, ["param1"] = 14, ["z"] = 7, ["name"] = "default:dirt_with_grass"}, {["x"] = 0, ["y"] = 1, ["z"] = 8, ["name"] = "default:stone_block"}, {["x"] = 0, ["param2"] = 1, ["y"] = 1, ["param1"] = 62, ["z"] = 9, ["name"] = "stairs:stair_stone_block"}, {["x"] = 0, ["param2"] = 1, ["y"] = 1, ["param1"] = 78, ["z"] = 10, ["name"] = "stairs:stair_stone_block"}, {["x"] = 0, ["y"] = 1, ["z"] = 11, ["name"] = "default:stone_block"}, {["x"] = 0, ["param2"] = 1, ["y"] = 1, ["param1"] = 110, ["z"] = 12, ["name"] = "stairs:slab_wood"}, {["x"] = 0, ["param2"] = 1, ["y"] = 1, ["param1"] = 110, ["z"] = 13, ["name"] = "stairs:slab_wood"}, {["x"] = 0, ["y"] = 1, ["z"] = 14, ["name"] = "the_build_spawner:white"}, {["x"] = 0, ["y"] = 1, ["z"] = 15, ["name"] = "default:dirt_with_grass"}, {["x"] = 0, ["param2"] = 1, ["y"] = 2, ["param1"] = 62, ["z"] = 0, ["name"] = "default:aspen_leaves"}, {["x"] = 0, ["param2"] = 1, ["y"] = 2, ["param1"] = 78, ["z"] = 1, ["name"] = "default:aspen_leaves"}, {["x"] = 0, ["param2"] = 1, ["y"] = 2, ["param1"] = 94, ["z"] = 2, ["name"] = "default:aspen_leaves"}, {["x"] = 0, ["param2"] = 1, ["y"] = 2, ["param1"] = 110, ["z"] = 3, ["name"] = "default:aspen_leaves"}, {["x"] = 0, ["param2"] = 1, ["y"] = 2, ["param1"] = 94, ["z"] = 4, ["name"] = "default:aspen_leaves"}, {["x"] = 0, ["param2"] = 1, ["y"] = 2, ["param1"] = 78, ["z"] = 5, ["name"] = "default:aspen_leaves"}, {["x"] = 0, ["param2"] = 1, ["y"] = 2, ["param1"] = 62, ["z"] = 6, ["name"] = "default:aspen_leaves"}, {["x"] = 0, ["param2"] = 1, ["y"] = 2, ["param1"] = 46, ["z"] = 7, ["name"] = "default:aspen_leaves"}, {["x"] = 0, ["y"] = 2, ["z"] = 11, ["name"] = "the_build_spawner:white"}, {["x"] = 0, ["y"] = 2, ["z"] = 14, ["name"] = "the_build_spawner:white"}, {["x"] = 0, ["param2"] = 1, ["y"] = 2, ["param1"] = 94, ["z"] = 15, ["name"] = "default:aspen_leaves"}, {["x"] = 0, ["y"] = 3, ["z"] = 11, ["name"] = "the_build_spawner:white"}, {["x"] = 0, ["y"] = 3, ["z"] = 14, ["name"] = "the_build_spawner:white"}, {["x"] = 0, ["y"] = 4, ["z"] = 11, ["name"] = "the_build_spawner:white"}, {["x"] = 0, ["y"] = 4, ["z"] = 12, ["name"] = "the_build_spawner:white"}, {["x"] = 0, ["y"] = 4, ["z"] = 13, ["name"] = "the_build_spawner:white"}, {["x"] = 0, ["y"] = 4, ["z"] = 14, ["name"] = "the_build_spawner:white"}, {["x"] = 0, ["y"] = 4, ["z"] = 15, ["name"] = "the_build_spawner:white"}, {["x"] = 0, ["y"] = 5, ["z"] = 11, ["name"] = "the_build_spawner:white"}, {["x"] = 0, ["y"] = 5, ["param1"] = 206, ["z"] = 12, ["name"] = "default:glass"}, {["x"] = 0, ["y"] = 5, ["param1"] = 206, ["z"] = 13, ["name"] = "default:glass"}, {["x"] = 0, ["y"] = 5, ["z"] = 14, ["name"] = "the_build_spawner:white"}, {["x"] = 0, ["y"] = 6, ["z"] = 11, ["name"] = "the_build_spawner:white"}, {["x"] = 0, ["y"] = 6, ["param1"] = 190, ["z"] = 12, ["name"] = "default:glass"}, {["x"] = 0, ["y"] = 6, ["param1"] = 190, ["z"] = 13, ["name"] = "default:glass"}, {["x"] = 0, ["y"] = 6, ["z"] = 14, ["name"] = "the_build_spawner:white"}, {["x"] = 0, ["y"] = 6, ["z"] = 15, ["name"] = "the_build_spawner:white"}, {["x"] = 0, ["y"] = 7, ["z"] = 11, ["name"] = "the_build_spawner:white"}, {["x"] = 0, ["y"] = 7, ["z"] = 12, ["name"] = "the_build_spawner:white"}, {["x"] = 0, ["y"] = 7, ["z"] = 13, ["name"] = "the_build_spawner:white"}, {["x"] = 0, ["y"] = 7, ["z"] = 14, ["name"] = "the_build_spawner:white"}, {["x"] = 1, ["y"] = 0, ["z"] = 0, ["name"] = "default:stone"}, {["x"] = 1, ["y"] = 0, ["z"] = 1, ["name"] = "default:stone"}, {["x"] = 1, ["y"] = 0, ["z"] = 2, ["name"] = "default:stone"}, {["x"] = 1, ["y"] = 0, ["z"] = 3, ["name"] = "default:stone"}, {["x"] = 1, ["y"] = 0, ["z"] = 4, ["name"] = "default:stone"}, {["x"] = 1, ["y"] = 0, ["z"] = 5, ["name"] = "default:stone"}, {["x"] = 1, ["y"] = 0, ["z"] = 6, ["name"] = "default:stone"}, {["x"] = 1, ["y"] = 0, ["z"] = 7, ["name"] = "default:stone"}, {["x"] = 1, ["y"] = 0, ["z"] = 8, ["name"] = "default:stone"}, {["x"] = 1, ["y"] = 0, ["z"] = 9, ["name"] = "default:stone"}, {["x"] = 1, ["y"] = 0, ["z"] = 10, ["name"] = "default:stone"}, {["x"] = 1, ["y"] = 0, ["z"] = 11, ["name"] = "default:stone"}, {["x"] = 1, ["y"] = 0, ["z"] = 12, ["name"] = "default:stone"}, {["x"] = 1, ["y"] = 0, ["z"] = 13, ["name"] = "default:stone"}, {["x"] = 1, ["y"] = 0, ["z"] = 14, ["name"] = "default:stone"}, {["x"] = 1, ["y"] = 0, ["z"] = 15, ["name"] = "default:dirt"}, {["x"] = 1, ["y"] = 1, ["z"] = 0, ["name"] = "default:dirt_with_grass"}, {["x"] = 1, ["y"] = 1, ["z"] = 1, ["name"] = "default:stone_block"}, {["x"] = 1, ["y"] = 1, ["z"] = 2, ["name"] = "default:stone_block"}, {["x"] = 1, ["y"] = 1, ["param1"] = 15, ["z"] = 3, ["name"] = "default:stone_block"}, {["x"] = 1, ["y"] = 1, ["param1"] = 15, ["z"] = 4, ["name"] = "default:stone_block"}, {["x"] = 1, ["y"] = 1, ["param1"] = 15, ["z"] = 5, ["name"] = "default:stone_block"}, {["x"] = 1, ["y"] = 1, ["param1"] = 15, ["z"] = 6, ["name"] = "default:stone_block"}, {["x"] = 1, ["y"] = 1, ["param1"] = 15, ["z"] = 7, ["name"] = "default:stone_block"}, {["x"] = 1, ["y"] = 1, ["z"] = 8, ["name"] = "default:stone_block"}, {["x"] = 1, ["y"] = 1, ["z"] = 9, ["name"] = "default:stone_block"}, {["x"] = 1, ["y"] = 1, ["z"] = 10, ["name"] = "default:stone_block"}, {["x"] = 1, ["y"] = 1, ["z"] = 11, ["name"] = "default:stone_block"}, {["x"] = 1, ["param2"] = 1, ["y"] = 1, ["param1"] = 93, ["z"] = 12, ["name"] = "stairs:slab_wood"}, {["x"] = 1, ["param2"] = 1, ["y"] = 1, ["param1"] = 93, ["z"] = 13, ["name"] = "stairs:slab_wood"}, {["x"] = 1, ["y"] = 1, ["z"] = 14, ["name"] = "the_build_spawner:white"}, {["x"] = 1, ["y"] = 1, ["param1"] = 14, ["z"] = 15, ["name"] = "default:dirt_with_grass"}, {["x"] = 1, ["param2"] = 1, ["y"] = 2, ["param1"] = 46, ["z"] = 0, ["name"] = "default:aspen_leaves"}, {["x"] = 1, ["y"] = 2, ["z"] = 1, ["name"] = "the_build_spawner:white"}, {["x"] = 1, ["y"] = 2, ["z"] = 2, ["name"] = "the_build_spawner:white"}, {["x"] = 1, ["y"] = 2, ["z"] = 3, ["name"] = "the_build_spawner:white"}, {["x"] = 1, ["y"] = 2, ["z"] = 4, ["name"] = "the_build_spawner:white"}, {["x"] = 1, ["y"] = 2, ["z"] = 5, ["name"] = "the_build_spawner:white"}, {["x"] = 1, ["y"] = 2, ["z"] = 6, ["name"] = "the_build_spawner:white"}, {["x"] = 1, ["y"] = 2, ["z"] = 7, ["name"] = "the_build_spawner:white"}, {["x"] = 1, ["y"] = 2, ["z"] = 8, ["name"] = "the_build_spawner:white"}, {["x"] = 1, ["meta"] = {["fields"] = {["state"] = "3"}, ["inventory"] = {}}, ["y"] = 2, ["param1"] = 61, ["z"] = 9, ["name"] = "doors:door_wood_d"}, {["x"] = 1, ["meta"] = {["fields"] = {["state"] = "0"}, ["inventory"] = {}}, ["param2"] = 1, ["y"] = 2, ["param1"] = 77, ["z"] = 10, ["name"] = "doors:door_wood_a"}, {["x"] = 1, ["y"] = 2, ["z"] = 11, ["name"] = "the_build_spawner:white"}, {["x"] = 1, ["y"] = 2, ["z"] = 14, ["name"] = "the_build_spawner:white"}, {["x"] = 1, ["param2"] = 1, ["y"] = 2, ["param1"] = 78, ["z"] = 15, ["name"] = "default:aspen_leaves"}, {["x"] = 1, ["y"] = 3, ["param1"] = 15, ["z"] = 1, ["name"] = "the_build_spawner:white"}, {["x"] = 1, ["y"] = 3, ["z"] = 2, ["name"] = "the_build_spawner:white"}, {["x"] = 1, ["y"] = 3, ["param1"] = 141, ["z"] = 3, ["name"] = "default:glass"}, {["x"] = 1, ["y"] = 3, ["param1"] = 125, ["z"] = 4, ["name"] = "default:glass"}, {["x"] = 1, ["y"] = 3, ["z"] = 5, ["name"] = "the_build_spawner:white"}, {["x"] = 1, ["y"] = 3, ["param1"] = 93, ["z"] = 6, ["name"] = "default:glass"}, {["x"] = 1, ["y"] = 3, ["param1"] = 77, ["z"] = 7, ["name"] = "default:glass"}, {["x"] = 1, ["y"] = 3, ["z"] = 8, ["name"] = "the_build_spawner:white"}, {["x"] = 1, ["y"] = 3, ["param1"] = 77, ["z"] = 9, ["name"] = "doors:hidden"}, {["x"] = 1, ["param2"] = 1, ["y"] = 3, ["param1"] = 93, ["z"] = 10, ["name"] = "doors:hidden"}, {["x"] = 1, ["y"] = 3, ["z"] = 11, ["name"] = "the_build_spawner:white"}, {["x"] = 1, ["y"] = 3, ["z"] = 14, ["name"] = "the_build_spawner:white"}, {["x"] = 1, ["y"] = 4, ["param1"] = 15, ["z"] = 1, ["name"] = "the_build_spawner:white"}, {["x"] = 1, ["y"] = 4, ["z"] = 2, ["name"] = "the_build_spawner:white"}, {["x"] = 1, ["y"] = 4, ["param1"] = 157, ["z"] = 3, ["name"] = "default:glass"}, {["x"] = 1, ["y"] = 4, ["param1"] = 141, ["z"] = 4, ["name"] = "default:glass"}, {["x"] = 1, ["y"] = 4, ["z"] = 5, ["name"] = "the_build_spawner:white"}, {["x"] = 1, ["y"] = 4, ["param1"] = 109, ["z"] = 6, ["name"] = "default:glass"}, {["x"] = 1, ["y"] = 4, ["param1"] = 93, ["z"] = 7, ["name"] = "default:glass"}, {["x"] = 1, ["y"] = 4, ["z"] = 8, ["name"] = "the_build_spawner:white"}, {["x"] = 1, ["y"] = 4, ["z"] = 9, ["name"] = "the_build_spawner:white"}, {["x"] = 1, ["y"] = 4, ["z"] = 10, ["name"] = "the_build_spawner:white"}, {["x"] = 1, ["y"] = 4, ["z"] = 11, ["name"] = "the_build_spawner:white"}, {["x"] = 1, ["y"] = 4, ["z"] = 12, ["name"] = "the_build_spawner:white"}, {["x"] = 1, ["y"] = 4, ["z"] = 13, ["name"] = "the_build_spawner:white"}, {["x"] = 1, ["y"] = 4, ["z"] = 14, ["name"] = "the_build_spawner:white"}, {["x"] = 1, ["y"] = 4, ["z"] = 15, ["name"] = "the_build_spawner:white"}, {["x"] = 1, ["y"] = 5, ["z"] = 1, ["name"] = "the_build_spawner:white"}, {["x"] = 1, ["y"] = 5, ["z"] = 2, ["name"] = "the_build_spawner:white"}, {["x"] = 1, ["y"] = 5, ["param1"] = 141, ["z"] = 3, ["name"] = "default:glass"}, {["x"] = 1, ["y"] = 5, ["param1"] = 125, ["z"] = 4, ["name"] = "default:glass"}, {["x"] = 1, ["y"] = 5, ["z"] = 5, ["name"] = "the_build_spawner:white"}, {["x"] = 1, ["y"] = 5, ["param1"] = 93, ["z"] = 6, ["name"] = "default:glass"}, {["x"] = 1, ["y"] = 5, ["param1"] = 77, ["z"] = 7, ["name"] = "default:glass"}, {["x"] = 1, ["y"] = 5, ["z"] = 8, ["name"] = "the_build_spawner:white"}, {["x"] = 1, ["y"] = 5, ["z"] = 9, ["name"] = "the_build_spawner:white"}, {["x"] = 1, ["y"] = 5, ["z"] = 10, ["name"] = "the_build_spawner:white"}, {["x"] = 1, ["y"] = 5, ["z"] = 11, ["name"] = "the_build_spawner:white"}, {["x"] = 1, ["y"] = 5, ["param1"] = 221, ["z"] = 12, ["name"] = "default:glass"}, {["x"] = 1, ["y"] = 5, ["param1"] = 221, ["z"] = 13, ["name"] = "default:glass"}, {["x"] = 1, ["y"] = 5, ["param1"] = 15, ["z"] = 14, ["name"] = "the_build_spawner:white"}, {["x"] = 1, ["y"] = 6, ["z"] = 1, ["name"] = "the_build_spawner:white"}, {["x"] = 1, ["y"] = 6, ["z"] = 2, ["name"] = "the_build_spawner:white"}, {["x"] = 1, ["y"] = 6, ["z"] = 3, ["name"] = "the_build_spawner:white"}, {["x"] = 1, ["y"] = 6, ["z"] = 4, ["name"] = "the_build_spawner:white"}, {["x"] = 1, ["y"] = 6, ["z"] = 5, ["name"] = "the_build_spawner:white"}, {["x"] = 1, ["y"] = 6, ["z"] = 6, ["name"] = "the_build_spawner:white"}, {["x"] = 1, ["y"] = 6, ["z"] = 7, ["name"] = "the_build_spawner:white"}, {["x"] = 1, ["y"] = 6, ["z"] = 8, ["name"] = "the_build_spawner:white"}, {["x"] = 1, ["y"] = 6, ["z"] = 9, ["name"] = "the_build_spawner:white"}, {["x"] = 1, ["y"] = 6, ["z"] = 10, ["name"] = "the_build_spawner:white"}, {["x"] = 1, ["y"] = 6, ["z"] = 11, ["name"] = "the_build_spawner:white"}, {["x"] = 1, ["y"] = 6, ["param1"] = 205, ["z"] = 12, ["name"] = "default:glass"}, {["x"] = 1, ["y"] = 6, ["param1"] = 205, ["z"] = 13, ["name"] = "default:glass"}, {["x"] = 1, ["y"] = 6, ["z"] = 14, ["name"] = "the_build_spawner:white"}, {["x"] = 1, ["y"] = 6, ["param1"] = 15, ["z"] = 15, ["name"] = "the_build_spawner:white"}, {["x"] = 1, ["y"] = 7, ["z"] = 11, ["name"] = "the_build_spawner:white"}, {["x"] = 1, ["y"] = 7, ["z"] = 12, ["name"] = "the_build_spawner:white"}, {["x"] = 1, ["y"] = 7, ["z"] = 13, ["name"] = "the_build_spawner:white"}, {["x"] = 1, ["y"] = 7, ["z"] = 14, ["name"] = "the_build_spawner:white"}, {["x"] = 2, ["y"] = 0, ["z"] = 0, ["name"] = "default:stone"}, {["x"] = 2, ["y"] = 0, ["z"] = 1, ["name"] = "default:stone"}, {["x"] = 2, ["y"] = 0, ["z"] = 2, ["name"] = "default:stone"}, {["x"] = 2, ["y"] = 0, ["z"] = 3, ["name"] = "default:stone"}, {["x"] = 2, ["y"] = 0, ["z"] = 4, ["name"] = "default:stone"}, {["x"] = 2, ["y"] = 0, ["z"] = 5, ["name"] = "default:stone"}, {["x"] = 2, ["y"] = 0, ["z"] = 6, ["name"] = "default:stone"}, {["x"] = 2, ["y"] = 0, ["z"] = 7, ["name"] = "default:stone"}, {["x"] = 2, ["y"] = 0, ["z"] = 8, ["name"] = "default:stone"}, {["x"] = 2, ["y"] = 0, ["z"] = 9, ["name"] = "default:stone"}, {["x"] = 2, ["y"] = 0, ["z"] = 10, ["name"] = "default:stone"}, {["x"] = 2, ["y"] = 0, ["z"] = 11, ["name"] = "default:stone"}, {["x"] = 2, ["y"] = 0, ["z"] = 12, ["name"] = "default:stone"}, {["x"] = 2, ["y"] = 0, ["z"] = 13, ["name"] = "default:stone"}, {["x"] = 2, ["y"] = 0, ["z"] = 14, ["name"] = "default:stone"}, {["x"] = 2, ["y"] = 0, ["z"] = 15, ["name"] = "default:dirt"}, {["x"] = 2, ["y"] = 1, ["param1"] = 15, ["z"] = 0, ["name"] = "default:dirt_with_grass"}, {["x"] = 2, ["y"] = 1, ["z"] = 1, ["name"] = "default:stone_block"}, {["x"] = 2, ["y"] = 1, ["param1"] = 15, ["z"] = 2, ["name"] = "default:stone_block"}, {["x"] = 2, ["y"] = 1, ["param1"] = 15, ["z"] = 3, ["name"] = "default:stone_block"}, {["x"] = 2, ["y"] = 1, ["param1"] = 15, ["z"] = 4, ["name"] = "default:stone_block"}, {["x"] = 2, ["y"] = 1, ["param1"] = 15, ["z"] = 5, ["name"] = "default:stone_block"}, {["x"] = 2, ["y"] = 1, ["param1"] = 15, ["z"] = 6, ["name"] = "default:stone_block"}, {["x"] = 2, ["y"] = 1, ["param1"] = 15, ["z"] = 7, ["name"] = "default:stone_block"}, {["x"] = 2, ["y"] = 1, ["param1"] = 15, ["z"] = 8, ["name"] = "default:stone_block"}, {["x"] = 2, ["y"] = 1, ["param1"] = 15, ["z"] = 9, ["name"] = "default:stone_block"}, {["x"] = 2, ["y"] = 1, ["param1"] = 15, ["z"] = 10, ["name"] = "default:stone_block"}, {["x"] = 2, ["y"] = 1, ["z"] = 11, ["name"] = "default:stone_block"}, {["x"] = 2, ["param2"] = 1, ["y"] = 1, ["param1"] = 76, ["z"] = 12, ["name"] = "stairs:slab_wood"}, {["x"] = 2, ["param2"] = 1, ["y"] = 1, ["param1"] = 76, ["z"] = 13, ["name"] = "stairs:slab_wood"}, {["x"] = 2, ["y"] = 1, ["z"] = 14, ["name"] = "the_build_spawner:white"}, {["x"] = 2, ["y"] = 1, ["param1"] = 14, ["z"] = 15, ["name"] = "default:dirt_with_grass"}, {["x"] = 2, ["param2"] = 1, ["y"] = 2, ["param1"] = 30, ["z"] = 0, ["name"] = "default:aspen_leaves"}, {["x"] = 2, ["y"] = 2, ["param1"] = 15, ["z"] = 1, ["name"] = "the_build_spawner:white"}, {["x"] = 2, ["meta"] = {["fields"] = {["seat"] = "return {[\"anim\"] = {[\"mesh\"] = \"character_sitting.b3d\", [\"loop\"] = true, [\"blend\"] = 0, [\"range\"] = {[\"y\"] = 80, [\"x\"] = 1}, [\"speed\"] = 15}, [\"pos\"] = {[\"y\"] = 10.199999999999999, [\"x\"] = -14, [\"z\"] = -58}}"}, ["inventory"] = {}}, ["param2"] = 2, ["y"] = 2, ["param1"] = 139, ["z"] = 3, ["name"] = "luxury_decor:simple_white_middle_footstool"}, {["x"] = 2, ["meta"] = {["fields"] = {["state"] = "0"}, ["inventory"] = {}}, ["param2"] = 2, ["y"] = 2, ["param1"] = 75, ["z"] = 11, ["name"] = "doors:door_wood_a"}, {["x"] = 2, ["y"] = 2, ["z"] = 14, ["name"] = "the_build_spawner:white"}, {["x"] = 2, ["param2"] = 1, ["y"] = 2, ["param1"] = 62, ["z"] = 15, ["name"] = "default:aspen_leaves"}, {["x"] = 2, ["y"] = 3, ["param1"] = 15, ["z"] = 1, ["name"] = "the_build_spawner:white"}, {["x"] = 2, ["param2"] = 2, ["y"] = 3, ["param1"] = 91, ["z"] = 11, ["name"] = "doors:hidden"}, {["x"] = 2, ["y"] = 3, ["z"] = 14, ["name"] = "the_build_spawner:white"}, {["x"] = 2, ["y"] = 4, ["param1"] = 15, ["z"] = 1, ["name"] = "the_build_spawner:white"}, {["x"] = 2, ["param2"] = 2, ["y"] = 4, ["param1"] = 187, ["z"] = 2, ["name"] = "luxury_decor:wall_glass_lamp_on"}, {["x"] = 2, ["y"] = 4, ["z"] = 11, ["name"] = "the_build_spawner:white"}, {["x"] = 2, ["y"] = 4, ["z"] = 12, ["name"] = "the_build_spawner:white"}, {["x"] = 2, ["y"] = 4, ["z"] = 13, ["name"] = "the_build_spawner:white"}, {["x"] = 2, ["y"] = 4, ["z"] = 14, ["name"] = "the_build_spawner:white"}, {["x"] = 2, ["y"] = 4, ["z"] = 15, ["name"] = "the_build_spawner:white"}, {["x"] = 2, ["y"] = 5, ["z"] = 1, ["name"] = "the_build_spawner:white"}, {["x"] = 2, ["y"] = 5, ["z"] = 2, ["name"] = "the_build_spawner:white"}, {["x"] = 2, ["y"] = 5, ["z"] = 3, ["name"] = "the_build_spawner:white"}, {["x"] = 2, ["y"] = 5, ["z"] = 4, ["name"] = "the_build_spawner:white"}, {["x"] = 2, ["y"] = 5, ["z"] = 5, ["name"] = "the_build_spawner:white"}, {["x"] = 2, ["y"] = 5, ["z"] = 6, ["name"] = "the_build_spawner:white"}, {["x"] = 2, ["y"] = 5, ["z"] = 7, ["name"] = "the_build_spawner:white"}, {["x"] = 2, ["y"] = 5, ["z"] = 8, ["name"] = "the_build_spawner:white"}, {["x"] = 2, ["y"] = 5, ["z"] = 9, ["name"] = "the_build_spawner:white"}, {["x"] = 2, ["y"] = 5, ["z"] = 10, ["name"] = "the_build_spawner:white"}, {["x"] = 2, ["y"] = 5, ["z"] = 11, ["name"] = "the_build_spawner:white"}, {["x"] = 2, ["y"] = 5, ["param1"] = 238, ["z"] = 12, ["name"] = "default:meselamp"}, {["x"] = 2, ["y"] = 5, ["param1"] = 238, ["z"] = 13, ["name"] = "default:meselamp"}, {["x"] = 2, ["y"] = 5, ["param1"] = 15, ["z"] = 14, ["name"] = "the_build_spawner:white"}, {["x"] = 2, ["y"] = 6, ["param1"] = 15, ["z"] = 1, ["name"] = "the_build_spawner:white"}, {["x"] = 2, ["y"] = 6, ["param1"] = 15, ["z"] = 14, ["name"] = "the_build_spawner:white"}, {["x"] = 2, ["y"] = 6, ["param1"] = 15, ["z"] = 15, ["name"] = "the_build_spawner:white"}, {["x"] = 3, ["y"] = 0, ["z"] = 0, ["name"] = "default:stone"}, {["x"] = 3, ["y"] = 0, ["z"] = 1, ["name"] = "default:stone"}, {["x"] = 3, ["y"] = 0, ["z"] = 2, ["name"] = "default:stone"}, {["x"] = 3, ["y"] = 0, ["z"] = 3, ["name"] = "default:stone"}, {["x"] = 3, ["y"] = 0, ["z"] = 4, ["name"] = "default:stone"}, {["x"] = 3, ["y"] = 0, ["z"] = 5, ["name"] = "default:stone"}, {["x"] = 3, ["y"] = 0, ["z"] = 6, ["name"] = "default:stone"}, {["x"] = 3, ["y"] = 0, ["z"] = 7, ["name"] = "default:stone"}, {["x"] = 3, ["y"] = 0, ["z"] = 8, ["name"] = "default:stone"}, {["x"] = 3, ["y"] = 0, ["z"] = 9, ["name"] = "default:stone"}, {["x"] = 3, ["y"] = 0, ["z"] = 10, ["name"] = "default:stone"}, {["x"] = 3, ["y"] = 0, ["z"] = 11, ["name"] = "default:stone"}, {["x"] = 3, ["y"] = 0, ["z"] = 12, ["name"] = "default:stone"}, {["x"] = 3, ["y"] = 0, ["z"] = 13, ["name"] = "default:stone"}, {["x"] = 3, ["y"] = 0, ["z"] = 14, ["name"] = "default:stone"}, {["x"] = 3, ["y"] = 0, ["z"] = 15, ["name"] = "default:dirt_with_grass"}, {["x"] = 3, ["y"] = 1, ["param1"] = 15, ["z"] = 0, ["name"] = "default:dirt_with_grass"}, {["x"] = 3, ["y"] = 1, ["z"] = 1, ["name"] = "default:stone_block"}, {["x"] = 3, ["y"] = 1, ["param1"] = 15, ["z"] = 2, ["name"] = "default:stone_block"}, {["x"] = 3, ["y"] = 1, ["param1"] = 15, ["z"] = 3, ["name"] = "default:stone_block"}, {["x"] = 3, ["y"] = 1, ["param1"] = 15, ["z"] = 4, ["name"] = "default:stone_block"}, {["x"] = 3, ["y"] = 1, ["param1"] = 15, ["z"] = 5, ["name"] = "default:stone_block"}, {["x"] = 3, ["y"] = 1, ["param1"] = 15, ["z"] = 6, ["name"] = "default:stone_block"}, {["x"] = 3, ["y"] = 1, ["param1"] = 15, ["z"] = 7, ["name"] = "default:stone_block"}, {["x"] = 3, ["y"] = 1, ["param1"] = 15, ["z"] = 8, ["name"] = "default:stone_block"}, {["x"] = 3, ["y"] = 1, ["param1"] = 15, ["z"] = 9, ["name"] = "default:stone_block"}, {["x"] = 3, ["y"] = 1, ["param1"] = 15, ["z"] = 10, ["name"] = "default:stone_block"}, {["x"] = 3, ["y"] = 1, ["z"] = 11, ["name"] = "default:stone_block"}, {["x"] = 3, ["param2"] = 1, ["y"] = 1, ["param1"] = 59, ["z"] = 12, ["name"] = "stairs:slab_wood"}, {["x"] = 3, ["param2"] = 1, ["y"] = 1, ["param1"] = 59, ["z"] = 13, ["name"] = "stairs:slab_wood"}, {["x"] = 3, ["y"] = 1, ["z"] = 14, ["name"] = "the_build_spawner:white"}, {["x"] = 3, ["y"] = 1, ["param1"] = 14, ["z"] = 15, ["name"] = "default:dirt_with_grass"}, {["x"] = 3, ["param2"] = 1, ["y"] = 2, ["param1"] = 14, ["z"] = 0, ["name"] = "default:aspen_leaves"}, {["x"] = 3, ["y"] = 2, ["param1"] = 15, ["z"] = 1, ["name"] = "the_build_spawner:white"}, {["x"] = 3, ["param2"] = 22, ["y"] = 2, ["param1"] = 137, ["z"] = 2, ["name"] = "stairs:stair_wood"}, {["x"] = 3, ["meta"] = {["fields"] = {["seat"] = "return {[\"anim\"] = {[\"mesh\"] = \"character_sitting.b3d\", [\"loop\"] = true, [\"blend\"] = 0, [\"range\"] = {[\"y\"] = 80, [\"x\"] = 1}, [\"speed\"] = 15}, [\"pos\"] = {[\"y\"] = 10.199999999999999, [\"x\"] = -13, [\"z\"] = -55}}"}, ["inventory"] = {}}, ["y"] = 2, ["param1"] = 74, ["z"] = 6, ["name"] = "luxury_decor:simple_1_white_sofa"}, {["x"] = 3, ["y"] = 2, ["z"] = 11, ["name"] = "the_build_spawner:white"}, {["x"] = 3, ["y"] = 2, ["z"] = 14, ["name"] = "the_build_spawner:white"}, {["x"] = 3, ["param2"] = 1, ["y"] = 2, ["param1"] = 46, ["z"] = 15, ["name"] = "default:aspen_leaves"}, {["x"] = 3, ["y"] = 3, ["param1"] = 15, ["z"] = 1, ["name"] = "the_build_spawner:white"}, {["x"] = 3, ["param2"] = 4, ["y"] = 3, ["param1"] = 154, ["z"] = 2, ["name"] = "stairs:slab_obsidian"}, {["x"] = 3, ["y"] = 3, ["z"] = 11, ["name"] = "the_build_spawner:white"}, {["x"] = 3, ["y"] = 3, ["z"] = 14, ["name"] = "the_build_spawner:white"}, {["x"] = 3, ["y"] = 4, ["param1"] = 15, ["z"] = 1, ["name"] = "the_build_spawner:white"}, {["x"] = 3, ["param2"] = 4, ["y"] = 4, ["param1"] = 170, ["z"] = 2, ["name"] = "stairs:slab_obsidian"}, {["x"] = 3, ["y"] = 4, ["z"] = 11, ["name"] = "the_build_spawner:white"}, {["x"] = 3, ["y"] = 4, ["z"] = 12, ["name"] = "the_build_spawner:white"}, {["x"] = 3, ["y"] = 4, ["z"] = 13, ["name"] = "the_build_spawner:white"}, {["x"] = 3, ["y"] = 4, ["z"] = 14, ["name"] = "the_build_spawner:white"}, {["x"] = 3, ["y"] = 4, ["z"] = 15, ["name"] = "the_build_spawner:white"}, {["x"] = 3, ["y"] = 5, ["z"] = 1, ["name"] = "the_build_spawner:white"}, {["x"] = 3, ["y"] = 5, ["z"] = 2, ["name"] = "the_build_spawner:white"}, {["x"] = 3, ["y"] = 5, ["z"] = 3, ["name"] = "the_build_spawner:white"}, {["x"] = 3, ["y"] = 5, ["z"] = 4, ["name"] = "the_build_spawner:white"}, {["x"] = 3, ["y"] = 5, ["z"] = 5, ["name"] = "the_build_spawner:white"}, {["x"] = 3, ["y"] = 5, ["z"] = 6, ["name"] = "the_build_spawner:white"}, {["x"] = 3, ["y"] = 5, ["z"] = 7, ["name"] = "the_build_spawner:white"}, {["x"] = 3, ["y"] = 5, ["z"] = 8, ["name"] = "the_build_spawner:white"}, {["x"] = 3, ["y"] = 5, ["z"] = 9, ["name"] = "the_build_spawner:white"}, {["x"] = 3, ["y"] = 5, ["z"] = 10, ["name"] = "the_build_spawner:white"}, {["x"] = 3, ["y"] = 5, ["z"] = 11, ["name"] = "the_build_spawner:white"}, {["x"] = 3, ["y"] = 5, ["z"] = 12, ["name"] = "the_build_spawner:white"}, {["x"] = 3, ["y"] = 5, ["z"] = 13, ["name"] = "the_build_spawner:white"}, {["x"] = 3, ["y"] = 5, ["param1"] = 15, ["z"] = 14, ["name"] = "the_build_spawner:white"}, {["x"] = 3, ["y"] = 6, ["param1"] = 15, ["z"] = 1, ["name"] = "the_build_spawner:white"}, {["x"] = 3, ["y"] = 6, ["param1"] = 15, ["z"] = 14, ["name"] = "the_build_spawner:white"}, {["x"] = 3, ["y"] = 6, ["param1"] = 15, ["z"] = 15, ["name"] = "the_build_spawner:white"}, {["x"] = 4, ["y"] = 0, ["z"] = 0, ["name"] = "default:stone"}, {["x"] = 4, ["y"] = 0, ["z"] = 1, ["name"] = "default:stone"}, {["x"] = 4, ["y"] = 0, ["z"] = 2, ["name"] = "default:stone"}, {["x"] = 4, ["y"] = 0, ["z"] = 3, ["name"] = "default:stone"}, {["x"] = 4, ["y"] = 0, ["z"] = 4, ["name"] = "default:stone"}, {["x"] = 4, ["y"] = 0, ["z"] = 5, ["name"] = "default:stone"}, {["x"] = 4, ["y"] = 0, ["z"] = 6, ["name"] = "default:stone"}, {["x"] = 4, ["y"] = 0, ["z"] = 7, ["name"] = "default:stone"}, {["x"] = 4, ["y"] = 0, ["z"] = 8, ["name"] = "default:stone"}, {["x"] = 4, ["y"] = 0, ["z"] = 9, ["name"] = "default:stone"}, {["x"] = 4, ["y"] = 0, ["z"] = 10, ["name"] = "default:stone"}, {["x"] = 4, ["y"] = 0, ["z"] = 11, ["name"] = "default:stone"}, {["x"] = 4, ["y"] = 0, ["z"] = 12, ["name"] = "default:stone"}, {["x"] = 4, ["y"] = 0, ["z"] = 13, ["name"] = "default:stone"}, {["x"] = 4, ["y"] = 0, ["z"] = 14, ["name"] = "default:stone"}, {["x"] = 4, ["y"] = 0, ["z"] = 15, ["name"] = "default:dirt"}, {["x"] = 4, ["y"] = 1, ["param1"] = 15, ["z"] = 0, ["name"] = "default:dirt_with_grass"}, {["x"] = 4, ["y"] = 1, ["z"] = 1, ["name"] = "default:stone_block"}, {["x"] = 4, ["y"] = 1, ["param1"] = 15, ["z"] = 2, ["name"] = "default:stone_block"}, {["x"] = 4, ["y"] = 1, ["param1"] = 15, ["z"] = 3, ["name"] = "default:stone_block"}, {["x"] = 4, ["y"] = 1, ["param1"] = 15, ["z"] = 4, ["name"] = "default:stone_block"}, {["x"] = 4, ["y"] = 1, ["param1"] = 15, ["z"] = 5, ["name"] = "default:stone_block"}, {["x"] = 4, ["y"] = 1, ["param1"] = 15, ["z"] = 6, ["name"] = "default:stone_block"}, {["x"] = 4, ["y"] = 1, ["param1"] = 15, ["z"] = 7, ["name"] = "default:stone_block"}, {["x"] = 4, ["y"] = 1, ["param1"] = 15, ["z"] = 8, ["name"] = "default:stone_block"}, {["x"] = 4, ["y"] = 1, ["param1"] = 15, ["z"] = 9, ["name"] = "default:stone_block"}, {["x"] = 4, ["y"] = 1, ["param1"] = 15, ["z"] = 10, ["name"] = "default:stone_block"}, {["x"] = 4, ["y"] = 1, ["z"] = 11, ["name"] = "default:stone_block"}, {["x"] = 4, ["y"] = 1, ["z"] = 12, ["name"] = "default:stone_block"}, {["x"] = 4, ["y"] = 1, ["z"] = 13, ["name"] = "default:stone_block"}, {["x"] = 4, ["y"] = 1, ["z"] = 14, ["name"] = "default:stone_block"}, {["x"] = 4, ["y"] = 1, ["param1"] = 14, ["z"] = 15, ["name"] = "default:dirt_with_grass"}, {["x"] = 4, ["param2"] = 1, ["y"] = 2, ["param1"] = 14, ["z"] = 0, ["name"] = "default:aspen_leaves"}, {["x"] = 4, ["y"] = 2, ["param1"] = 15, ["z"] = 1, ["name"] = "the_build_spawner:white"}, {["x"] = 4, ["param2"] = 22, ["y"] = 2, ["param1"] = 120, ["z"] = 2, ["name"] = "stairs:stair_wood"}, {["x"] = 4, ["y"] = 2, ["param1"] = 89, ["z"] = 4, ["name"] = "luxury_decor:luxury_metallic_table"}, {["x"] = 4, ["meta"] = {["fields"] = {["seat"] = "return {[\"anim\"] = {[\"mesh\"] = \"character_sitting.b3d\", [\"loop\"] = true, [\"blend\"] = 0, [\"range\"] = {[\"y\"] = 80, [\"x\"] = 1}, [\"speed\"] = 15}, [\"pos\"] = {[\"y\"] = 10.199999999999999, [\"x\"] = -12, [\"z\"] = -55}}"}, ["inventory"] = {}}, ["y"] = 2, ["param1"] = 59, ["z"] = 6, ["name"] = "luxury_decor:simple_1_white_sofa"}, {["x"] = 4, ["y"] = 2, ["z"] = 11, ["name"] = "the_build_spawner:white"}, {["x"] = 4, ["y"] = 2, ["z"] = 12, ["name"] = "the_build_spawner:white"}, {["x"] = 4, ["y"] = 2, ["z"] = 13, ["name"] = "the_build_spawner:white"}, {["x"] = 4, ["y"] = 2, ["z"] = 14, ["name"] = "the_build_spawner:white"}, {["x"] = 4, ["param2"] = 1, ["y"] = 2, ["param1"] = 30, ["z"] = 15, ["name"] = "default:aspen_leaves"}, {["x"] = 4, ["y"] = 3, ["param1"] = 15, ["z"] = 1, ["name"] = "the_build_spawner:white"}, {["x"] = 4, ["param2"] = 4, ["y"] = 3, ["param1"] = 137, ["z"] = 2, ["name"] = "stairs:slab_obsidian"}, {["x"] = 4, ["y"] = 3, ["z"] = 11, ["name"] = "the_build_spawner:white"}, {["x"] = 4, ["y"] = 3, ["z"] = 12, ["name"] = "the_build_spawner:white"}, {["x"] = 4, ["y"] = 3, ["z"] = 13, ["name"] = "the_build_spawner:white"}, {["x"] = 4, ["y"] = 3, ["z"] = 14, ["name"] = "the_build_spawner:white"}, {["x"] = 4, ["y"] = 4, ["param1"] = 15, ["z"] = 1, ["name"] = "the_build_spawner:white"}, {["x"] = 4, ["param2"] = 4, ["y"] = 4, ["param1"] = 153, ["z"] = 2, ["name"] = "stairs:slab_obsidian"}, {["x"] = 4, ["y"] = 4, ["z"] = 11, ["name"] = "the_build_spawner:white"}, {["x"] = 4, ["y"] = 4, ["z"] = 12, ["name"] = "the_build_spawner:white"}, {["x"] = 4, ["y"] = 4, ["z"] = 13, ["name"] = "the_build_spawner:white"}, {["x"] = 4, ["y"] = 4, ["z"] = 14, ["name"] = "the_build_spawner:white"}, {["x"] = 4, ["y"] = 4, ["z"] = 15, ["name"] = "the_build_spawner:white"}, {["x"] = 4, ["y"] = 5, ["z"] = 1, ["name"] = "the_build_spawner:white"}, {["x"] = 4, ["y"] = 5, ["z"] = 2, ["name"] = "the_build_spawner:white"}, {["x"] = 4, ["y"] = 5, ["z"] = 3, ["name"] = "the_build_spawner:white"}, {["x"] = 4, ["y"] = 5, ["z"] = 4, ["name"] = "the_build_spawner:white"}, {["x"] = 4, ["y"] = 5, ["z"] = 5, ["name"] = "the_build_spawner:white"}, {["x"] = 4, ["y"] = 5, ["z"] = 6, ["name"] = "the_build_spawner:white"}, {["x"] = 4, ["y"] = 5, ["z"] = 7, ["name"] = "the_build_spawner:white"}, {["x"] = 4, ["y"] = 5, ["z"] = 8, ["name"] = "the_build_spawner:white"}, {["x"] = 4, ["y"] = 5, ["z"] = 9, ["name"] = "the_build_spawner:white"}, {["x"] = 4, ["y"] = 5, ["z"] = 10, ["name"] = "the_build_spawner:white"}, {["x"] = 4, ["y"] = 5, ["z"] = 11, ["name"] = "the_build_spawner:white"}, {["x"] = 4, ["y"] = 5, ["z"] = 12, ["name"] = "the_build_spawner:white"}, {["x"] = 4, ["y"] = 5, ["z"] = 13, ["name"] = "the_build_spawner:white"}, {["x"] = 4, ["y"] = 5, ["param1"] = 15, ["z"] = 14, ["name"] = "the_build_spawner:white"}, {["x"] = 4, ["y"] = 6, ["param1"] = 15, ["z"] = 1, ["name"] = "the_build_spawner:white"}, {["x"] = 4, ["y"] = 6, ["param1"] = 15, ["z"] = 14, ["name"] = "the_build_spawner:white"}, {["x"] = 4, ["y"] = 6, ["param1"] = 15, ["z"] = 15, ["name"] = "the_build_spawner:white"}, {["x"] = 5, ["y"] = 0, ["z"] = 0, ["name"] = "default:stone"}, {["x"] = 5, ["y"] = 0, ["z"] = 1, ["name"] = "default:stone"}, {["x"] = 5, ["y"] = 0, ["z"] = 2, ["name"] = "default:stone"}, {["x"] = 5, ["y"] = 0, ["z"] = 3, ["name"] = "default:stone"}, {["x"] = 5, ["y"] = 0, ["z"] = 4, ["name"] = "default:stone"}, {["x"] = 5, ["y"] = 0, ["z"] = 5, ["name"] = "default:stone"}, {["x"] = 5, ["y"] = 0, ["z"] = 6, ["name"] = "default:stone"}, {["x"] = 5, ["y"] = 0, ["z"] = 7, ["name"] = "default:stone"}, {["x"] = 5, ["y"] = 0, ["z"] = 8, ["name"] = "default:stone"}, {["x"] = 5, ["y"] = 0, ["z"] = 9, ["name"] = "default:stone"}, {["x"] = 5, ["y"] = 0, ["z"] = 10, ["name"] = "default:stone"}, {["x"] = 5, ["y"] = 0, ["z"] = 11, ["name"] = "default:stone"}, {["x"] = 5, ["y"] = 0, ["z"] = 12, ["name"] = "default:stone"}, {["x"] = 5, ["y"] = 0, ["z"] = 13, ["name"] = "default:stone"}, {["x"] = 5, ["y"] = 0, ["z"] = 14, ["name"] = "default:stone"}, {["x"] = 5, ["y"] = 0, ["z"] = 15, ["name"] = "default:dirt"}, {["x"] = 5, ["y"] = 1, ["param1"] = 15, ["z"] = 0, ["name"] = "default:dirt_with_grass"}, {["x"] = 5, ["y"] = 1, ["z"] = 1, ["name"] = "default:stone_block"}, {["x"] = 5, ["y"] = 1, ["param1"] = 15, ["z"] = 2, ["name"] = "default:stone_block"}, {["x"] = 5, ["y"] = 1, ["param1"] = 15, ["z"] = 3, ["name"] = "default:stone_block"}, {["x"] = 5, ["y"] = 1, ["param1"] = 15, ["z"] = 4, ["name"] = "default:stone_block"}, {["x"] = 5, ["y"] = 1, ["param1"] = 15, ["z"] = 5, ["name"] = "default:stone_block"}, {["x"] = 5, ["y"] = 1, ["param1"] = 15, ["z"] = 6, ["name"] = "default:stone_block"}, {["x"] = 5, ["y"] = 1, ["param1"] = 15, ["z"] = 7, ["name"] = "default:stone_block"}, {["x"] = 5, ["y"] = 1, ["param1"] = 15, ["z"] = 8, ["name"] = "default:stone_block"}, {["x"] = 5, ["y"] = 1, ["param1"] = 15, ["z"] = 9, ["name"] = "default:stone_block"}, {["x"] = 5, ["y"] = 1, ["param1"] = 15, ["z"] = 10, ["name"] = "default:stone_block"}, {["x"] = 5, ["y"] = 1, ["param1"] = 15, ["z"] = 11, ["name"] = "default:stone_block"}, {["x"] = 5, ["y"] = 1, ["param1"] = 14, ["z"] = 12, ["name"] = "default:stone_block"}, {["x"] = 5, ["y"] = 1, ["z"] = 13, ["name"] = "default:stone_block"}, {["x"] = 5, ["y"] = 1, ["z"] = 14, ["name"] = "default:stone_block"}, {["x"] = 5, ["y"] = 1, ["param1"] = 14, ["z"] = 15, ["name"] = "default:dirt_with_grass"}, {["x"] = 5, ["param2"] = 1, ["y"] = 2, ["param1"] = 14, ["z"] = 0, ["name"] = "default:aspen_leaves"}, {["x"] = 5, ["y"] = 2, ["param1"] = 15, ["z"] = 1, ["name"] = "the_build_spawner:white"}, {["x"] = 5, ["param2"] = 22, ["y"] = 2, ["param1"] = 136, ["z"] = 2, ["name"] = "stairs:stair_wood"}, {["x"] = 5, ["meta"] = {["fields"] = {["seat"] = "return {[\"anim\"] = {[\"mesh\"] = \"character_sitting.b3d\", [\"loop\"] = true, [\"blend\"] = 0, [\"range\"] = {[\"y\"] = 80, [\"x\"] = 1}, [\"speed\"] = 15}, [\"pos\"] = {[\"y\"] = 10.199999999999999, [\"x\"] = -11, [\"z\"] = -55}}"}, ["inventory"] = {}}, ["y"] = 2, ["param1"] = 76, ["z"] = 6, ["name"] = "luxury_decor:simple_1_white_sofa"}, {["x"] = 5, ["y"] = 2, ["z"] = 14, ["name"] = "the_build_spawner:white"}, {["x"] = 5, ["param2"] = 1, ["y"] = 2, ["param1"] = 14, ["z"] = 15, ["name"] = "default:aspen_leaves"}, {["x"] = 5, ["y"] = 3, ["param1"] = 15, ["z"] = 1, ["name"] = "the_build_spawner:white"}, {["x"] = 5, ["param2"] = 4, ["y"] = 3, ["param1"] = 153, ["z"] = 2, ["name"] = "stairs:slab_obsidian"}, {["x"] = 5, ["y"] = 3, ["z"] = 14, ["name"] = "the_build_spawner:white"}, {["x"] = 5, ["y"] = 4, ["param1"] = 15, ["z"] = 1, ["name"] = "the_build_spawner:white"}, {["x"] = 5, ["param2"] = 4, ["y"] = 4, ["param1"] = 170, ["z"] = 2, ["name"] = "stairs:slab_obsidian"}, {["x"] = 5, ["y"] = 4, ["z"] = 14, ["name"] = "the_build_spawner:white"}, {["x"] = 5, ["y"] = 4, ["z"] = 15, ["name"] = "the_build_spawner:white"}, {["x"] = 5, ["y"] = 5, ["z"] = 1, ["name"] = "the_build_spawner:white"}, {["x"] = 5, ["y"] = 5, ["z"] = 2, ["name"] = "the_build_spawner:white"}, {["x"] = 5, ["y"] = 5, ["z"] = 3, ["name"] = "the_build_spawner:white"}, {["x"] = 5, ["y"] = 5, ["z"] = 4, ["name"] = "the_build_spawner:white"}, {["x"] = 5, ["y"] = 5, ["z"] = 5, ["name"] = "the_build_spawner:white"}, {["x"] = 5, ["y"] = 5, ["z"] = 6, ["name"] = "the_build_spawner:white"}, {["x"] = 5, ["y"] = 5, ["z"] = 7, ["name"] = "the_build_spawner:white"}, {["x"] = 5, ["y"] = 5, ["z"] = 8, ["name"] = "the_build_spawner:white"}, {["x"] = 5, ["y"] = 5, ["z"] = 9, ["name"] = "the_build_spawner:white"}, {["x"] = 5, ["y"] = 5, ["z"] = 10, ["name"] = "the_build_spawner:white"}, {["x"] = 5, ["y"] = 5, ["z"] = 11, ["name"] = "the_build_spawner:white"}, {["x"] = 5, ["y"] = 5, ["z"] = 12, ["name"] = "the_build_spawner:white"}, {["x"] = 5, ["y"] = 5, ["z"] = 13, ["name"] = "the_build_spawner:white"}, {["x"] = 5, ["y"] = 5, ["param1"] = 15, ["z"] = 14, ["name"] = "the_build_spawner:white"}, {["x"] = 5, ["y"] = 6, ["param1"] = 15, ["z"] = 1, ["name"] = "the_build_spawner:white"}, {["x"] = 5, ["y"] = 6, ["param1"] = 15, ["z"] = 14, ["name"] = "the_build_spawner:white"}, {["x"] = 5, ["y"] = 6, ["param1"] = 15, ["z"] = 15, ["name"] = "the_build_spawner:white"}, {["x"] = 6, ["y"] = 0, ["z"] = 0, ["name"] = "default:stone"}, {["x"] = 6, ["y"] = 0, ["z"] = 1, ["name"] = "default:stone"}, {["x"] = 6, ["y"] = 0, ["z"] = 2, ["name"] = "default:stone"}, {["x"] = 6, ["y"] = 0, ["z"] = 3, ["name"] = "default:stone"}, {["x"] = 6, ["y"] = 0, ["z"] = 4, ["name"] = "default:stone"}, {["x"] = 6, ["y"] = 0, ["z"] = 5, ["name"] = "default:stone"}, {["x"] = 6, ["y"] = 0, ["z"] = 6, ["name"] = "default:stone"}, {["x"] = 6, ["y"] = 0, ["z"] = 7, ["name"] = "default:stone"}, {["x"] = 6, ["y"] = 0, ["z"] = 8, ["name"] = "default:stone"}, {["x"] = 6, ["y"] = 0, ["z"] = 9, ["name"] = "default:stone"}, {["x"] = 6, ["y"] = 0, ["z"] = 10, ["name"] = "default:stone"}, {["x"] = 6, ["y"] = 0, ["z"] = 11, ["name"] = "default:stone"}, {["x"] = 6, ["y"] = 0, ["z"] = 12, ["name"] = "default:stone"}, {["x"] = 6, ["y"] = 0, ["z"] = 13, ["name"] = "default:stone"}, {["x"] = 6, ["y"] = 0, ["z"] = 14, ["name"] = "default:stone"}, {["x"] = 6, ["y"] = 0, ["z"] = 15, ["name"] = "default:dirt"}, {["x"] = 6, ["y"] = 1, ["param1"] = 15, ["z"] = 0, ["name"] = "default:dirt_with_grass"}, {["x"] = 6, ["y"] = 1, ["z"] = 1, ["name"] = "default:stone_block"}, {["x"] = 6, ["y"] = 1, ["param1"] = 15, ["z"] = 2, ["name"] = "default:stone_block"}, {["x"] = 6, ["y"] = 1, ["param1"] = 15, ["z"] = 3, ["name"] = "default:stone_block"}, {["x"] = 6, ["y"] = 1, ["param1"] = 15, ["z"] = 4, ["name"] = "default:stone_block"}, {["x"] = 6, ["y"] = 1, ["param1"] = 15, ["z"] = 5, ["name"] = "default:stone_block"}, {["x"] = 6, ["y"] = 1, ["param1"] = 15, ["z"] = 6, ["name"] = "default:stone_block"}, {["x"] = 6, ["y"] = 1, ["param1"] = 15, ["z"] = 7, ["name"] = "default:stone_block"}, {["x"] = 6, ["y"] = 1, ["param1"] = 15, ["z"] = 8, ["name"] = "default:stone_block"}, {["x"] = 6, ["y"] = 1, ["param1"] = 15, ["z"] = 9, ["name"] = "default:stone_block"}, {["x"] = 6, ["y"] = 1, ["param1"] = 15, ["z"] = 10, ["name"] = "default:stone_block"}, {["x"] = 6, ["y"] = 1, ["param1"] = 15, ["z"] = 11, ["name"] = "default:stone_block"}, {["x"] = 6, ["y"] = 1, ["param1"] = 14, ["z"] = 12, ["name"] = "default:stone_block"}, {["x"] = 6, ["y"] = 1, ["z"] = 13, ["name"] = "default:stone_block"}, {["x"] = 6, ["y"] = 1, ["z"] = 14, ["name"] = "default:stone_block"}, {["x"] = 6, ["y"] = 1, ["param1"] = 14, ["z"] = 15, ["name"] = "default:dirt_with_grass"}, {["x"] = 6, ["param2"] = 1, ["y"] = 2, ["param1"] = 14, ["z"] = 0, ["name"] = "default:aspen_leaves"}, {["x"] = 6, ["y"] = 2, ["param1"] = 15, ["z"] = 1, ["name"] = "the_build_spawner:white"}, {["x"] = 6, ["meta"] = {["fields"] = {["seat"] = "return {[\"anim\"] = {[\"mesh\"] = \"character_sitting.b3d\", [\"loop\"] = true, [\"blend\"] = 0, [\"range\"] = {[\"y\"] = 80, [\"x\"] = 1}, [\"speed\"] = 15}, [\"pos\"] = {[\"y\"] = 10.199999999999999, [\"x\"] = -10, [\"z\"] = -57}}"}, ["inventory"] = {}}, ["param2"] = 1, ["y"] = 2, ["param1"] = 123, ["z"] = 4, ["name"] = "luxury_decor:simple_1_white_sofa"}, {["x"] = 6, ["meta"] = {["fields"] = {["seat"] = "return {[\"anim\"] = {[\"mesh\"] = \"character_sitting.b3d\", [\"loop\"] = true, [\"blend\"] = 0, [\"range\"] = {[\"y\"] = 80, [\"x\"] = 1}, [\"speed\"] = 15}, [\"pos\"] = {[\"y\"] = 10.199999999999999, [\"x\"] = -10, [\"z\"] = -56}}"}, ["inventory"] = {}}, ["param2"] = 1, ["y"] = 2, ["param1"] = 108, ["z"] = 5, ["name"] = "luxury_decor:simple_1_white_sofa"}, {["x"] = 6, ["meta"] = {["fields"] = {["seat"] = "return {[\"anim\"] = {[\"frame_speed\"] = 15, [\"mesh\"] = \"character_sitting.b3d\", [\"frame_blend\"] = 0, [\"range\"] = {[\"y\"] = 80, [\"x\"] = 1}, [\"loop\"] = true}, [\"pos\"] = {[\"y\"] = 10.32, [\"x\"] = -10, [\"z\"] = -50}}"}, ["inventory"] = {}}, ["param2"] = 3, ["y"] = 2, ["param1"] = 142, ["z"] = 11, ["name"] = "luxury_decor:luxury_wooden_chair_with_cushion"}, {["x"] = 6, ["meta"] = {["fields"] = {["seat"] = "return {[\"anim\"] = {[\"frame_speed\"] = 15, [\"mesh\"] = \"character_sitting.b3d\", [\"frame_blend\"] = 0, [\"range\"] = {[\"y\"] = 80, [\"x\"] = 1}, [\"loop\"] = true}, [\"pos\"] = {[\"y\"] = 10.32, [\"x\"] = -10, [\"z\"] = -49}}"}, ["inventory"] = {}}, ["param2"] = 3, ["y"] = 2, ["param1"] = 125, ["z"] = 12, ["name"] = "luxury_decor:luxury_wooden_chair_with_cushion"}, {["x"] = 6, ["y"] = 2, ["z"] = 14, ["name"] = "the_build_spawner:white"}, {["x"] = 6, ["param2"] = 1, ["y"] = 2, ["param1"] = 14, ["z"] = 15, ["name"] = "default:aspen_leaves"}, {["x"] = 6, ["y"] = 3, ["param1"] = 15, ["z"] = 1, ["name"] = "the_build_spawner:white"}, {["x"] = 6, ["y"] = 3, ["z"] = 14, ["name"] = "the_build_spawner:white"}, {["x"] = 6, ["y"] = 4, ["param1"] = 15, ["z"] = 1, ["name"] = "the_build_spawner:white"}, {["x"] = 6, ["param2"] = 2, ["y"] = 4, ["param1"] = 187, ["z"] = 2, ["name"] = "luxury_decor:wall_glass_lamp_on"}, {["x"] = 6, ["y"] = 4, ["z"] = 14, ["name"] = "the_build_spawner:white"}, {["x"] = 6, ["y"] = 4, ["z"] = 15, ["name"] = "the_build_spawner:white"}, {["x"] = 6, ["y"] = 5, ["z"] = 1, ["name"] = "the_build_spawner:white"}, {["x"] = 6, ["y"] = 5, ["z"] = 2, ["name"] = "the_build_spawner:white"}, {["x"] = 6, ["y"] = 5, ["z"] = 3, ["name"] = "the_build_spawner:white"}, {["x"] = 6, ["y"] = 5, ["z"] = 4, ["name"] = "the_build_spawner:white"}, {["x"] = 6, ["y"] = 5, ["z"] = 5, ["name"] = "the_build_spawner:white"}, {["x"] = 6, ["y"] = 5, ["z"] = 6, ["name"] = "the_build_spawner:white"}, {["x"] = 6, ["y"] = 5, ["z"] = 7, ["name"] = "the_build_spawner:white"}, {["x"] = 6, ["y"] = 5, ["z"] = 8, ["name"] = "the_build_spawner:white"}, {["x"] = 6, ["y"] = 5, ["param1"] = 63, ["z"] = 9, ["name"] = "the_build_spawner:white"}, {["x"] = 6, ["y"] = 5, ["param1"] = 47, ["z"] = 10, ["name"] = "the_build_spawner:white"}, {["x"] = 6, ["y"] = 5, ["param1"] = 31, ["z"] = 11, ["name"] = "the_build_spawner:white"}, {["x"] = 6, ["y"] = 5, ["param1"] = 30, ["z"] = 12, ["name"] = "the_build_spawner:white"}, {["x"] = 6, ["y"] = 5, ["param1"] = 13, ["z"] = 13, ["name"] = "the_build_spawner:white"}, {["x"] = 6, ["y"] = 5, ["param1"] = 15, ["z"] = 14, ["name"] = "the_build_spawner:white"}, {["x"] = 6, ["y"] = 6, ["param1"] = 14, ["z"] = 1, ["name"] = "the_build_spawner:white"}, {["x"] = 6, ["y"] = 6, ["param1"] = 15, ["z"] = 14, ["name"] = "the_build_spawner:white"}, {["x"] = 6, ["y"] = 6, ["param1"] = 15, ["z"] = 15, ["name"] = "the_build_spawner:white"}, {["x"] = 7, ["y"] = 0, ["z"] = 0, ["name"] = "default:stone"}, {["x"] = 7, ["y"] = 0, ["z"] = 1, ["name"] = "default:stone"}, {["x"] = 7, ["y"] = 0, ["z"] = 2, ["name"] = "default:stone"}, {["x"] = 7, ["y"] = 0, ["z"] = 3, ["name"] = "default:stone"}, {["x"] = 7, ["y"] = 0, ["z"] = 4, ["name"] = "default:stone"}, {["x"] = 7, ["y"] = 0, ["z"] = 5, ["name"] = "default:stone"}, {["x"] = 7, ["y"] = 0, ["z"] = 6, ["name"] = "default:stone"}, {["x"] = 7, ["y"] = 0, ["z"] = 7, ["name"] = "default:stone"}, {["x"] = 7, ["y"] = 0, ["z"] = 8, ["name"] = "default:stone"}, {["x"] = 7, ["y"] = 0, ["z"] = 9, ["name"] = "default:stone"}, {["x"] = 7, ["y"] = 0, ["z"] = 10, ["name"] = "default:stone"}, {["x"] = 7, ["y"] = 0, ["z"] = 11, ["name"] = "default:stone"}, {["x"] = 7, ["y"] = 0, ["z"] = 12, ["name"] = "default:stone"}, {["x"] = 7, ["y"] = 0, ["z"] = 13, ["name"] = "default:stone"}, {["x"] = 7, ["y"] = 0, ["z"] = 14, ["name"] = "default:stone"}, {["x"] = 7, ["y"] = 0, ["z"] = 15, ["name"] = "default:dirt"}, {["x"] = 7, ["y"] = 1, ["param1"] = 15, ["z"] = 0, ["name"] = "default:dirt_with_grass"}, {["x"] = 7, ["y"] = 1, ["z"] = 1, ["name"] = "default:stone_block"}, {["x"] = 7, ["y"] = 1, ["param1"] = 15, ["z"] = 2, ["name"] = "default:stone_block"}, {["x"] = 7, ["y"] = 1, ["param1"] = 15, ["z"] = 3, ["name"] = "default:stone_block"}, {["x"] = 7, ["y"] = 1, ["param1"] = 15, ["z"] = 4, ["name"] = "default:stone_block"}, {["x"] = 7, ["y"] = 1, ["param1"] = 15, ["z"] = 5, ["name"] = "default:stone_block"}, {["x"] = 7, ["y"] = 1, ["param1"] = 15, ["z"] = 6, ["name"] = "default:stone_block"}, {["x"] = 7, ["y"] = 1, ["param1"] = 15, ["z"] = 7, ["name"] = "default:stone_block"}, {["x"] = 7, ["y"] = 1, ["param1"] = 15, ["z"] = 8, ["name"] = "default:stone_block"}, {["x"] = 7, ["y"] = 1, ["param1"] = 15, ["z"] = 9, ["name"] = "default:stone_block"}, {["x"] = 7, ["y"] = 1, ["param1"] = 15, ["z"] = 10, ["name"] = "default:stone_block"}, {["x"] = 7, ["y"] = 1, ["param1"] = 15, ["z"] = 11, ["name"] = "default:stone_block"}, {["x"] = 7, ["y"] = 1, ["param1"] = 14, ["z"] = 12, ["name"] = "default:stone_block"}, {["x"] = 7, ["y"] = 1, ["param1"] = 14, ["z"] = 13, ["name"] = "default:stone_block"}, {["x"] = 7, ["y"] = 1, ["z"] = 14, ["name"] = "default:stone_block"}, {["x"] = 7, ["y"] = 1, ["param1"] = 14, ["z"] = 15, ["name"] = "default:dirt_with_grass"}, {["x"] = 7, ["param2"] = 1, ["y"] = 2, ["param1"] = 14, ["z"] = 0, ["name"] = "default:aspen_leaves"}, {["x"] = 7, ["y"] = 2, ["param1"] = 15, ["z"] = 1, ["name"] = "the_build_spawner:white"}, {["x"] = 7, ["meta"] = {["fields"] = {["formspec"] = "size[9,11.5]image_button[0.5, 0;1, 2;open_button.png;sw_bedt1_1;]image_button[0.5, 2.5;1, 2;open_button.png;sw_bedt1_2;]image_button[0.5, 5;1, 2;open_button.png;sw_bedt1_3;]list[current_player;main;0.5,7.5;8,4;]"}, ["inventory"] = {["main"] = {"", "", "", "", "", "", "", "", "", "", "", "", "", "", "", "", "", "", "", "", "", "", "", "", "", "", "", "", "", "", "", ""}}}, ["param2"] = 1, ["y"] = 2, ["param1"] = 136, ["z"] = 2, ["name"] = "luxury_decor:simple_wooden_bedside_table_1"}, {["x"] = 7, ["meta"] = {["fields"] = {["formspec"] = "size[9,11.5]image_button[0.5, 0;1, 2;open_button.png;sw_bedt1_1;]image_button[0.5, 2.5;1, 2;open_button.png;sw_bedt1_2;]image_button[0.5, 5;1, 2;open_button.png;sw_bedt1_3;]list[current_player;main;0.5,7.5;8,4;]"}, ["inventory"] = {["main"] = {"", "", "", "", "", "", "", "", "", "", "", "", "", "", "", "", "", "", "", "", "", "", "", "", "", "", "", "", "", "", "", ""}}}, ["param2"] = 1, ["y"] = 2, ["param1"] = 121, ["z"] = 3, ["name"] = "luxury_decor:simple_wooden_bedside_table_1"}, {["x"] = 7, ["y"] = 2, ["z"] = 4, ["name"] = "the_build_spawner:white"}, {["x"] = 7, ["y"] = 2, ["z"] = 5, ["name"] = "the_build_spawner:white"}, {["x"] = 7, ["y"] = 2, ["z"] = 6, ["name"] = "the_build_spawner:white"}, {["x"] = 7, ["meta"] = {["fields"] = {["seat"] = "return {[\"anim\"] = {[\"frame_speed\"] = 15, [\"mesh\"] = \"character_sitting.b3d\", [\"frame_blend\"] = 0, [\"range\"] = {[\"y\"] = 80, [\"x\"] = 1}, [\"loop\"] = true}, [\"pos\"] = {[\"y\"] = 10.32, [\"x\"] = -9, [\"z\"] = -51}}"}, ["inventory"] = {}}, ["param2"] = 2, ["y"] = 2, ["param1"] = 142, ["z"] = 10, ["name"] = "luxury_decor:luxury_wooden_chair_with_cushion"}, {["x"] = 7, ["param2"] = 3, ["y"] = 2, ["param1"] = 140, ["z"] = 12, ["name"] = "luxury_decor:simple_wooden_table"}, {["x"] = 7, ["meta"] = {["fields"] = {["seat"] = "return {[\"anim\"] = {[\"frame_speed\"] = 15, [\"mesh\"] = \"character_sitting.b3d\", [\"frame_blend\"] = 0, [\"range\"] = {[\"y\"] = 80, [\"x\"] = 1}, [\"loop\"] = true}, [\"pos\"] = {[\"y\"] = 10.32, [\"x\"] = -9, [\"z\"] = -48}}"}, ["inventory"] = {}}, ["y"] = 2, ["param1"] = 123, ["z"] = 13, ["name"] = "luxury_decor:luxury_wooden_chair_with_cushion"}, {["x"] = 7, ["y"] = 2, ["z"] = 14, ["name"] = "the_build_spawner:white"}, {["x"] = 7, ["param2"] = 1, ["y"] = 2, ["param1"] = 14, ["z"] = 15, ["name"] = "default:aspen_leaves"}, {["x"] = 7, ["y"] = 3, ["param1"] = 15, ["z"] = 1, ["name"] = "the_build_spawner:white"}, {["x"] = 7, ["y"] = 3, ["z"] = 4, ["name"] = "the_build_spawner:white"}, {["x"] = 7, ["y"] = 3, ["z"] = 5, ["name"] = "the_build_spawner:white"}, {["x"] = 7, ["y"] = 3, ["z"] = 6, ["name"] = "the_build_spawner:white"}, {["x"] = 7, ["param2"] = 1, ["y"] = 3, ["param1"] = 174, ["z"] = 11, ["name"] = "luxury_decor:brass_candlestick"}, {["x"] = 7, ["y"] = 3, ["z"] = 14, ["name"] = "the_build_spawner:white"}, {["x"] = 7, ["y"] = 4, ["param1"] = 15, ["z"] = 1, ["name"] = "the_build_spawner:white"}, {["x"] = 7, ["y"] = 4, ["z"] = 2, ["name"] = "the_build_spawner:white"}, {["x"] = 7, ["y"] = 4, ["z"] = 3, ["name"] = "the_build_spawner:white"}, {["x"] = 7, ["y"] = 4, ["z"] = 4, ["name"] = "the_build_spawner:white"}, {["x"] = 7, ["y"] = 4, ["z"] = 5, ["name"] = "the_build_spawner:white"}, {["x"] = 7, ["y"] = 4, ["z"] = 6, ["name"] = "the_build_spawner:white"}, {["x"] = 7, ["y"] = 4, ["z"] = 14, ["name"] = "the_build_spawner:white"}, {["x"] = 7, ["y"] = 4, ["z"] = 15, ["name"] = "the_build_spawner:white"}, {["x"] = 7, ["y"] = 5, ["z"] = 1, ["name"] = "the_build_spawner:white"}, {["x"] = 7, ["y"] = 5, ["z"] = 2, ["name"] = "the_build_spawner:white"}, {["x"] = 7, ["y"] = 5, ["z"] = 3, ["name"] = "the_build_spawner:white"}, {["x"] = 7, ["y"] = 5, ["z"] = 4, ["name"] = "the_build_spawner:white"}, {["x"] = 7, ["y"] = 5, ["z"] = 5, ["name"] = "the_build_spawner:white"}, {["x"] = 7, ["y"] = 5, ["z"] = 6, ["name"] = "the_build_spawner:white"}, {["x"] = 7, ["y"] = 5, ["param1"] = 79, ["z"] = 7, ["name"] = "the_build_spawner:white"}, {["x"] = 7, ["y"] = 5, ["param1"] = 63, ["z"] = 8, ["name"] = "the_build_spawner:white"}, {["x"] = 7, ["y"] = 5, ["param1"] = 47, ["z"] = 9, ["name"] = "the_build_spawner:white"}, {["x"] = 7, ["y"] = 5, ["param1"] = 31, ["z"] = 10, ["name"] = "the_build_spawner:white"}, {["x"] = 7, ["y"] = 5, ["param1"] = 31, ["z"] = 11, ["name"] = "the_build_spawner:white"}, {["x"] = 7, ["y"] = 5, ["param1"] = 46, ["z"] = 12, ["name"] = "the_build_spawner:white"}, {["x"] = 7, ["y"] = 5, ["param1"] = 30, ["z"] = 13, ["name"] = "the_build_spawner:white"}, {["x"] = 7, ["y"] = 5, ["param1"] = 15, ["z"] = 14, ["name"] = "the_build_spawner:white"}, {["x"] = 7, ["y"] = 6, ["param1"] = 14, ["z"] = 1, ["name"] = "the_build_spawner:white"}, {["x"] = 7, ["y"] = 6, ["z"] = 3, ["name"] = "the_build_spawner:white"}, {["x"] = 7, ["y"] = 6, ["z"] = 4, ["name"] = "the_build_spawner:white"}, {["x"] = 7, ["y"] = 6, ["z"] = 5, ["name"] = "the_build_spawner:white"}, {["x"] = 7, ["y"] = 6, ["z"] = 6, ["name"] = "the_build_spawner:white"}, {["x"] = 7, ["y"] = 6, ["param1"] = 15, ["z"] = 14, ["name"] = "the_build_spawner:white"}, {["x"] = 7, ["y"] = 6, ["param1"] = 15, ["z"] = 15, ["name"] = "the_build_spawner:white"}, {["x"] = 8, ["y"] = 0, ["z"] = 0, ["name"] = "default:stone"}, {["x"] = 8, ["y"] = 0, ["z"] = 1, ["name"] = "default:stone"}, {["x"] = 8, ["y"] = 0, ["z"] = 2, ["name"] = "default:stone"}, {["x"] = 8, ["y"] = 0, ["z"] = 3, ["name"] = "default:stone"}, {["x"] = 8, ["y"] = 0, ["z"] = 4, ["name"] = "default:stone"}, {["x"] = 8, ["y"] = 0, ["z"] = 5, ["name"] = "default:stone"}, {["x"] = 8, ["y"] = 0, ["z"] = 6, ["name"] = "default:stone"}, {["x"] = 8, ["y"] = 0, ["z"] = 7, ["name"] = "default:stone"}, {["x"] = 8, ["y"] = 0, ["z"] = 8, ["name"] = "default:stone"}, {["x"] = 8, ["y"] = 0, ["z"] = 9, ["name"] = "default:stone"}, {["x"] = 8, ["y"] = 0, ["z"] = 10, ["name"] = "default:stone"}, {["x"] = 8, ["y"] = 0, ["z"] = 11, ["name"] = "default:stone"}, {["x"] = 8, ["y"] = 0, ["z"] = 12, ["name"] = "default:stone"}, {["x"] = 8, ["y"] = 0, ["z"] = 13, ["name"] = "default:stone"}, {["x"] = 8, ["y"] = 0, ["z"] = 14, ["name"] = "default:stone"}, {["x"] = 8, ["y"] = 0, ["z"] = 15, ["name"] = "default:dirt"}, {["x"] = 8, ["y"] = 1, ["param1"] = 15, ["z"] = 0, ["name"] = "default:dirt_with_grass"}, {["x"] = 8, ["y"] = 1, ["z"] = 1, ["name"] = "default:stone_block"}, {["x"] = 8, ["y"] = 1, ["param1"] = 15, ["z"] = 2, ["name"] = "default:stone_block"}, {["x"] = 8, ["y"] = 1, ["param1"] = 15, ["z"] = 3, ["name"] = "default:stone_block"}, {["x"] = 8, ["y"] = 1, ["param1"] = 15, ["z"] = 4, ["name"] = "default:stone_block"}, {["x"] = 8, ["y"] = 1, ["param1"] = 15, ["z"] = 5, ["name"] = "default:stone_block"}, {["x"] = 8, ["y"] = 1, ["param1"] = 15, ["z"] = 6, ["name"] = "default:stone_block"}, {["x"] = 8, ["y"] = 1, ["param1"] = 15, ["z"] = 7, ["name"] = "default:stone_block"}, {["x"] = 8, ["y"] = 1, ["param1"] = 15, ["z"] = 8, ["name"] = "default:stone_block"}, {["x"] = 8, ["y"] = 1, ["param1"] = 15, ["z"] = 9, ["name"] = "default:stone_block"}, {["x"] = 8, ["y"] = 1, ["param1"] = 15, ["z"] = 10, ["name"] = "default:stone_block"}, {["x"] = 8, ["y"] = 1, ["param1"] = 15, ["z"] = 11, ["name"] = "default:stone_block"}, {["x"] = 8, ["y"] = 1, ["param1"] = 14, ["z"] = 12, ["name"] = "default:stone_block"}, {["x"] = 8, ["y"] = 1, ["param1"] = 14, ["z"] = 13, ["name"] = "default:stone_block"}, {["x"] = 8, ["y"] = 1, ["z"] = 14, ["name"] = "default:stone_block"}, {["x"] = 8, ["y"] = 1, ["param1"] = 14, ["z"] = 15, ["name"] = "default:dirt_with_grass"}, {["x"] = 8, ["param2"] = 1, ["y"] = 2, ["param1"] = 14, ["z"] = 0, ["name"] = "default:aspen_leaves"}, {["x"] = 8, ["y"] = 2, ["param1"] = 15, ["z"] = 1, ["name"] = "the_build_spawner:white"}, {["x"] = 8, ["y"] = 2, ["z"] = 2, ["name"] = "the_build_spawner:white"}, {["x"] = 8, ["y"] = 2, ["z"] = 3, ["name"] = "the_build_spawner:white"}, {["x"] = 8, ["param2"] = 2, ["y"] = 2, ["param1"] = 46, ["z"] = 5, ["name"] = "stairs:stair_stone_block"}, {["x"] = 8, ["meta"] = {["fields"] = {["seat"] = "return {[\"anim\"] = {[\"frame_speed\"] = 15, [\"mesh\"] = \"character_sitting.b3d\", [\"frame_blend\"] = 0, [\"range\"] = {[\"y\"] = 80, [\"x\"] = 1}, [\"loop\"] = true}, [\"pos\"] = {[\"y\"] = 10.32, [\"x\"] = -8, [\"z\"] = -50}}"}, ["inventory"] = {}}, ["param2"] = 1, ["y"] = 2, ["param1"] = 142, ["z"] = 11, ["name"] = "luxury_decor:luxury_wooden_chair_with_cushion"}, {["x"] = 8, ["meta"] = {["fields"] = {["seat"] = "return {[\"anim\"] = {[\"frame_speed\"] = 15, [\"mesh\"] = \"character_sitting.b3d\", [\"frame_blend\"] = 0, [\"range\"] = {[\"y\"] = 80, [\"x\"] = 1}, [\"loop\"] = true}, [\"pos\"] = {[\"y\"] = 10.32, [\"x\"] = -8, [\"z\"] = -49}}"}, ["inventory"] = {}}, ["param2"] = 1, ["y"] = 2, ["param1"] = 125, ["z"] = 12, ["name"] = "luxury_decor:luxury_wooden_chair_with_cushion"}, {["x"] = 8, ["y"] = 2, ["z"] = 14, ["name"] = "the_build_spawner:white"}, {["x"] = 8, ["param2"] = 1, ["y"] = 2, ["param1"] = 14, ["z"] = 15, ["name"] = "default:aspen_leaves"}, {["x"] = 8, ["y"] = 3, ["param1"] = 15, ["z"] = 1, ["name"] = "the_build_spawner:white"}, {["x"] = 8, ["y"] = 3, ["z"] = 2, ["name"] = "the_build_spawner:white"}, {["x"] = 8, ["y"] = 3, ["z"] = 3, ["name"] = "the_build_spawner:white"}, {["x"] = 8, ["param2"] = 2, ["y"] = 3, ["param1"] = 46, ["z"] = 4, ["name"] = "stairs:stair_stone_block"}, {["x"] = 8, ["y"] = 3, ["z"] = 14, ["name"] = "the_build_spawner:white"}, {["x"] = 8, ["y"] = 4, ["param1"] = 15, ["z"] = 1, ["name"] = "the_build_spawner:white"}, {["x"] = 8, ["y"] = 4, ["z"] = 2, ["name"] = "default:stone_block"}, {["x"] = 8, ["param2"] = 2, ["y"] = 4, ["param1"] = 14, ["z"] = 3, ["name"] = "stairs:stair_stone_block"}, {["x"] = 8, ["y"] = 4, ["z"] = 14, ["name"] = "the_build_spawner:white"}, {["x"] = 8, ["y"] = 4, ["z"] = 15, ["name"] = "the_build_spawner:white"}, {["x"] = 8, ["y"] = 5, ["z"] = 1, ["name"] = "the_build_spawner:white"}, {["x"] = 8, ["param2"] = 2, ["y"] = 5, ["param1"] = 14, ["z"] = 2, ["name"] = "stairs:stair_stone_block"}, {["x"] = 8, ["y"] = 5, ["z"] = 6, ["name"] = "the_build_spawner:white"}, {["x"] = 8, ["y"] = 5, ["param1"] = 63, ["z"] = 7, ["name"] = "the_build_spawner:white"}, {["x"] = 8, ["y"] = 5, ["param1"] = 47, ["z"] = 8, ["name"] = "the_build_spawner:white"}, {["x"] = 8, ["y"] = 5, ["param1"] = 31, ["z"] = 9, ["name"] = "the_build_spawner:white"}, {["x"] = 8, ["y"] = 5, ["param1"] = 31, ["z"] = 10, ["name"] = "the_build_spawner:white"}, {["x"] = 8, ["y"] = 5, ["param1"] = 47, ["z"] = 11, ["name"] = "the_build_spawner:white"}, {["x"] = 8, ["y"] = 5, ["param1"] = 62, ["z"] = 12, ["name"] = "the_build_spawner:white"}, {["x"] = 8, ["y"] = 5, ["param1"] = 46, ["z"] = 13, ["name"] = "the_build_spawner:white"}, {["x"] = 8, ["y"] = 5, ["param1"] = 15, ["z"] = 14, ["name"] = "the_build_spawner:white"}, {["x"] = 8, ["y"] = 6, ["param1"] = 15, ["z"] = 1, ["name"] = "the_build_spawner:white"}, {["x"] = 8, ["y"] = 6, ["z"] = 6, ["name"] = "the_build_spawner:white"}, {["x"] = 8, ["y"] = 6, ["param1"] = 15, ["z"] = 14, ["name"] = "the_build_spawner:white"}, {["x"] = 8, ["y"] = 6, ["param1"] = 15, ["z"] = 15, ["name"] = "the_build_spawner:white"}, {["x"] = 9, ["y"] = 0, ["z"] = 0, ["name"] = "default:stone"}, {["x"] = 9, ["y"] = 0, ["z"] = 1, ["name"] = "default:stone"}, {["x"] = 9, ["y"] = 0, ["z"] = 2, ["name"] = "default:stone"}, {["x"] = 9, ["y"] = 0, ["z"] = 3, ["name"] = "default:stone"}, {["x"] = 9, ["y"] = 0, ["z"] = 4, ["name"] = "default:stone"}, {["x"] = 9, ["y"] = 0, ["z"] = 5, ["name"] = "default:stone"}, {["x"] = 9, ["y"] = 0, ["z"] = 6, ["name"] = "default:stone"}, {["x"] = 9, ["y"] = 0, ["z"] = 7, ["name"] = "default:stone"}, {["x"] = 9, ["y"] = 0, ["z"] = 8, ["name"] = "default:stone"}, {["x"] = 9, ["y"] = 0, ["z"] = 9, ["name"] = "default:stone"}, {["x"] = 9, ["y"] = 0, ["z"] = 10, ["name"] = "default:stone"}, {["x"] = 9, ["y"] = 0, ["z"] = 11, ["name"] = "default:stone"}, {["x"] = 9, ["y"] = 0, ["z"] = 12, ["name"] = "default:stone"}, {["x"] = 9, ["y"] = 0, ["z"] = 13, ["name"] = "default:stone"}, {["x"] = 9, ["y"] = 0, ["z"] = 14, ["name"] = "default:stone"}, {["x"] = 9, ["y"] = 0, ["z"] = 15, ["name"] = "default:dirt"}, {["x"] = 9, ["y"] = 1, ["param1"] = 15, ["z"] = 0, ["name"] = "default:dirt_with_grass"}, {["x"] = 9, ["y"] = 1, ["z"] = 1, ["name"] = "default:stone_block"}, {["x"] = 9, ["y"] = 1, ["param1"] = 15, ["z"] = 2, ["name"] = "default:stone_block"}, {["x"] = 9, ["y"] = 1, ["param1"] = 15, ["z"] = 3, ["name"] = "default:stone_block"}, {["x"] = 9, ["y"] = 1, ["param1"] = 15, ["z"] = 4, ["name"] = "default:stone_block"}, {["x"] = 9, ["y"] = 1, ["param1"] = 15, ["z"] = 5, ["name"] = "default:stone_block"}, {["x"] = 9, ["y"] = 1, ["param1"] = 15, ["z"] = 6, ["name"] = "default:stone_block"}, {["x"] = 9, ["y"] = 1, ["param1"] = 15, ["z"] = 7, ["name"] = "default:stone_block"}, {["x"] = 9, ["y"] = 1, ["param1"] = 15, ["z"] = 8, ["name"] = "default:stone_block"}, {["x"] = 9, ["y"] = 1, ["param1"] = 15, ["z"] = 9, ["name"] = "default:stone_block"}, {["x"] = 9, ["y"] = 1, ["param1"] = 15, ["z"] = 10, ["name"] = "default:stone_block"}, {["x"] = 9, ["y"] = 1, ["param1"] = 15, ["z"] = 11, ["name"] = "default:stone_block"}, {["x"] = 9, ["y"] = 1, ["param1"] = 14, ["z"] = 12, ["name"] = "default:stone_block"}, {["x"] = 9, ["y"] = 1, ["param1"] = 14, ["z"] = 13, ["name"] = "default:stone_block"}, {["x"] = 9, ["y"] = 1, ["z"] = 14, ["name"] = "default:stone_block"}, {["x"] = 9, ["y"] = 1, ["param1"] = 14, ["z"] = 15, ["name"] = "default:dirt_with_grass"}, {["x"] = 9, ["param2"] = 1, ["y"] = 2, ["param1"] = 14, ["z"] = 0, ["name"] = "default:aspen_leaves"}, {["x"] = 9, ["y"] = 2, ["param1"] = 15, ["z"] = 1, ["name"] = "the_build_spawner:white"}, {["x"] = 9, ["param2"] = 2, ["y"] = 2, ["param1"] = 30, ["z"] = 5, ["name"] = "stairs:stair_stone_block"}, {["x"] = 9, ["y"] = 2, ["z"] = 14, ["name"] = "the_build_spawner:white"}, {["x"] = 9, ["param2"] = 1, ["y"] = 2, ["param1"] = 14, ["z"] = 15, ["name"] = "default:aspen_leaves"}, {["x"] = 9, ["y"] = 3, ["param1"] = 15, ["z"] = 1, ["name"] = "the_build_spawner:white"}, {["x"] = 9, ["param2"] = 2, ["y"] = 3, ["param1"] = 30, ["z"] = 4, ["name"] = "stairs:stair_stone_block"}, {["x"] = 9, ["y"] = 3, ["z"] = 14, ["name"] = "the_build_spawner:white"}, {["x"] = 9, ["y"] = 4, ["param1"] = 15, ["z"] = 1, ["name"] = "the_build_spawner:white"}, {["x"] = 9, ["y"] = 4, ["z"] = 2, ["name"] = "default:stone_block"}, {["x"] = 9, ["param2"] = 2, ["y"] = 4, ["param1"] = 14, ["z"] = 3, ["name"] = "stairs:stair_stone_block"}, {["x"] = 9, ["y"] = 4, ["z"] = 14, ["name"] = "the_build_spawner:white"}, {["x"] = 9, ["y"] = 4, ["z"] = 15, ["name"] = "the_build_spawner:white"}, {["x"] = 9, ["y"] = 5, ["z"] = 1, ["name"] = "the_build_spawner:white"}, {["x"] = 9, ["param2"] = 2, ["y"] = 5, ["param1"] = 14, ["z"] = 2, ["name"] = "stairs:stair_stone_block"}, {["x"] = 9, ["y"] = 5, ["z"] = 6, ["name"] = "the_build_spawner:white"}, {["x"] = 9, ["y"] = 5, ["param1"] = 47, ["z"] = 7, ["name"] = "the_build_spawner:white"}, {["x"] = 9, ["y"] = 5, ["param1"] = 47, ["z"] = 8, ["name"] = "the_build_spawner:white"}, {["x"] = 9, ["y"] = 5, ["param1"] = 31, ["z"] = 9, ["name"] = "the_build_spawner:white"}, {["x"] = 9, ["y"] = 5, ["param1"] = 47, ["z"] = 10, ["name"] = "the_build_spawner:white"}, {["x"] = 9, ["y"] = 5, ["param1"] = 63, ["z"] = 11, ["name"] = "the_build_spawner:white"}, {["x"] = 9, ["y"] = 5, ["param1"] = 78, ["z"] = 12, ["name"] = "the_build_spawner:white"}, {["x"] = 9, ["y"] = 5, ["param1"] = 62, ["z"] = 13, ["name"] = "the_build_spawner:white"}, {["x"] = 9, ["y"] = 5, ["param1"] = 15, ["z"] = 14, ["name"] = "the_build_spawner:white"}, {["x"] = 9, ["y"] = 6, ["param1"] = 15, ["z"] = 1, ["name"] = "the_build_spawner:white"}, {["x"] = 9, ["y"] = 6, ["z"] = 6, ["name"] = "the_build_spawner:white"}, {["x"] = 9, ["y"] = 6, ["param1"] = 31, ["z"] = 14, ["name"] = "the_build_spawner:white"}, {["x"] = 9, ["y"] = 6, ["param1"] = 15, ["z"] = 15, ["name"] = "the_build_spawner:white"}, {["x"] = 10, ["y"] = 0, ["z"] = 0, ["name"] = "default:stone"}, {["x"] = 10, ["y"] = 0, ["z"] = 1, ["name"] = "default:stone"}, {["x"] = 10, ["y"] = 0, ["z"] = 2, ["name"] = "default:stone"}, {["x"] = 10, ["y"] = 0, ["z"] = 3, ["name"] = "default:stone"}, {["x"] = 10, ["y"] = 0, ["z"] = 4, ["name"] = "default:stone"}, {["x"] = 10, ["y"] = 0, ["z"] = 5, ["name"] = "default:stone"}, {["x"] = 10, ["y"] = 0, ["z"] = 6, ["name"] = "default:stone"}, {["x"] = 10, ["y"] = 0, ["z"] = 7, ["name"] = "default:stone"}, {["x"] = 10, ["y"] = 0, ["z"] = 8, ["name"] = "default:stone"}, {["x"] = 10, ["y"] = 0, ["z"] = 9, ["name"] = "default:stone"}, {["x"] = 10, ["y"] = 0, ["z"] = 10, ["name"] = "default:stone"}, {["x"] = 10, ["y"] = 0, ["z"] = 11, ["name"] = "default:stone"}, {["x"] = 10, ["y"] = 0, ["z"] = 12, ["name"] = "default:stone"}, {["x"] = 10, ["y"] = 0, ["z"] = 13, ["name"] = "default:stone"}, {["x"] = 10, ["y"] = 0, ["z"] = 14, ["name"] = "default:stone"}, {["x"] = 10, ["y"] = 0, ["z"] = 15, ["name"] = "default:dirt_with_grass"}, {["x"] = 10, ["y"] = 1, ["param1"] = 15, ["z"] = 0, ["name"] = "default:dirt_with_grass"}, {["x"] = 10, ["y"] = 1, ["z"] = 1, ["name"] = "default:stone_block"}, {["x"] = 10, ["y"] = 1, ["param1"] = 15, ["z"] = 2, ["name"] = "default:stone_block"}, {["x"] = 10, ["y"] = 1, ["param1"] = 15, ["z"] = 3, ["name"] = "default:stone_block"}, {["x"] = 10, ["y"] = 1, ["param1"] = 15, ["z"] = 4, ["name"] = "default:stone_block"}, {["x"] = 10, ["y"] = 1, ["param1"] = 15, ["z"] = 5, ["name"] = "default:stone_block"}, {["x"] = 10, ["y"] = 1, ["param1"] = 15, ["z"] = 6, ["name"] = "default:stone_block"}, {["x"] = 10, ["y"] = 1, ["param1"] = 15, ["z"] = 7, ["name"] = "default:stone_block"}, {["x"] = 10, ["y"] = 1, ["param1"] = 15, ["z"] = 8, ["name"] = "default:stone_block"}, {["x"] = 10, ["y"] = 1, ["param1"] = 15, ["z"] = 9, ["name"] = "default:stone_block"}, {["x"] = 10, ["y"] = 1, ["param1"] = 15, ["z"] = 10, ["name"] = "default:stone_block"}, {["x"] = 10, ["y"] = 1, ["param1"] = 15, ["z"] = 11, ["name"] = "default:stone_block"}, {["x"] = 10, ["y"] = 1, ["param1"] = 14, ["z"] = 12, ["name"] = "default:stone_block"}, {["x"] = 10, ["y"] = 1, ["param1"] = 13, ["z"] = 13, ["name"] = "default:stone_block"}, {["x"] = 10, ["y"] = 1, ["z"] = 14, ["name"] = "default:stone_block"}, {["x"] = 10, ["y"] = 1, ["param1"] = 14, ["z"] = 15, ["name"] = "default:dirt_with_grass"}, {["x"] = 10, ["param2"] = 1, ["y"] = 2, ["param1"] = 14, ["z"] = 0, ["name"] = "default:aspen_leaves"}, {["x"] = 10, ["y"] = 2, ["param1"] = 15, ["z"] = 1, ["name"] = "the_build_spawner:white"}, {["x"] = 10, ["y"] = 2, ["z"] = 2, ["name"] = "the_build_spawner:white"}, {["x"] = 10, ["y"] = 2, ["z"] = 3, ["name"] = "the_build_spawner:white"}, {["x"] = 10, ["y"] = 2, ["z"] = 4, ["name"] = "the_build_spawner:white"}, {["x"] = 10, ["y"] = 2, ["z"] = 5, ["name"] = "the_build_spawner:white"}, {["x"] = 10, ["y"] = 2, ["z"] = 6, ["name"] = "the_build_spawner:white"}, {["x"] = 10, ["y"] = 2, ["z"] = 14, ["name"] = "the_build_spawner:white"}, {["x"] = 10, ["param2"] = 1, ["y"] = 2, ["param1"] = 14, ["z"] = 15, ["name"] = "default:aspen_leaves"}, {["x"] = 10, ["y"] = 3, ["param1"] = 15, ["z"] = 1, ["name"] = "the_build_spawner:white"}, {["x"] = 10, ["y"] = 3, ["z"] = 2, ["name"] = "the_build_spawner:white"}, {["x"] = 10, ["y"] = 3, ["z"] = 3, ["name"] = "the_build_spawner:white"}, {["x"] = 10, ["y"] = 3, ["z"] = 4, ["name"] = "the_build_spawner:white"}, {["x"] = 10, ["y"] = 3, ["z"] = 5, ["name"] = "the_build_spawner:white"}, {["x"] = 10, ["y"] = 3, ["z"] = 6, ["name"] = "the_build_spawner:white"}, {["x"] = 10, ["y"] = 3, ["z"] = 14, ["name"] = "the_build_spawner:white"}, {["x"] = 10, ["y"] = 4, ["param1"] = 15, ["z"] = 1, ["name"] = "the_build_spawner:white"}, {["x"] = 10, ["y"] = 4, ["z"] = 2, ["name"] = "the_build_spawner:white"}, {["x"] = 10, ["y"] = 4, ["z"] = 3, ["name"] = "the_build_spawner:white"}, {["x"] = 10, ["y"] = 4, ["z"] = 4, ["name"] = "the_build_spawner:white"}, {["x"] = 10, ["y"] = 4, ["z"] = 5, ["name"] = "the_build_spawner:white"}, {["x"] = 10, ["y"] = 4, ["z"] = 6, ["name"] = "the_build_spawner:white"}, {["x"] = 10, ["y"] = 4, ["z"] = 14, ["name"] = "the_build_spawner:white"}, {["x"] = 10, ["y"] = 4, ["z"] = 15, ["name"] = "the_build_spawner:white"}, {["x"] = 10, ["y"] = 5, ["z"] = 1, ["name"] = "the_build_spawner:white"}, {["x"] = 10, ["y"] = 5, ["z"] = 2, ["name"] = "the_build_spawner:white"}, {["x"] = 10, ["y"] = 5, ["z"] = 3, ["name"] = "the_build_spawner:white"}, {["x"] = 10, ["y"] = 5, ["z"] = 4, ["name"] = "the_build_spawner:white"}, {["x"] = 10, ["y"] = 5, ["z"] = 5, ["name"] = "the_build_spawner:white"}, {["x"] = 10, ["y"] = 5, ["z"] = 6, ["name"] = "the_build_spawner:white"}, {["x"] = 10, ["y"] = 5, ["param1"] = 47, ["z"] = 7, ["name"] = "the_build_spawner:white"}, {["x"] = 10, ["y"] = 5, ["param1"] = 63, ["z"] = 8, ["name"] = "the_build_spawner:white"}, {["x"] = 10, ["y"] = 5, ["param1"] = 47, ["z"] = 9, ["name"] = "the_build_spawner:white"}, {["x"] = 10, ["y"] = 5, ["param1"] = 63, ["z"] = 10, ["name"] = "the_build_spawner:white"}, {["x"] = 10, ["y"] = 5, ["param1"] = 79, ["z"] = 11, ["name"] = "the_build_spawner:white"}, {["x"] = 10, ["y"] = 5, ["param1"] = 94, ["z"] = 12, ["name"] = "the_build_spawner:white"}, {["x"] = 10, ["y"] = 5, ["param1"] = 78, ["z"] = 13, ["name"] = "the_build_spawner:white"}, {["x"] = 10, ["y"] = 5, ["param1"] = 15, ["z"] = 14, ["name"] = "the_build_spawner:white"}, {["x"] = 10, ["y"] = 6, ["param1"] = 15, ["z"] = 1, ["name"] = "the_build_spawner:white"}, {["x"] = 10, ["y"] = 6, ["z"] = 2, ["name"] = "the_build_spawner:white"}, {["x"] = 10, ["y"] = 6, ["z"] = 3, ["name"] = "the_build_spawner:white"}, {["x"] = 10, ["y"] = 6, ["z"] = 4, ["name"] = "the_build_spawner:white"}, {["x"] = 10, ["y"] = 6, ["z"] = 5, ["name"] = "the_build_spawner:white"}, {["x"] = 10, ["y"] = 6, ["z"] = 6, ["name"] = "the_build_spawner:white"}, {["x"] = 10, ["y"] = 6, ["param1"] = 47, ["z"] = 14, ["name"] = "the_build_spawner:white"}, {["x"] = 10, ["y"] = 6, ["param1"] = 31, ["z"] = 15, ["name"] = "the_build_spawner:white"}, {["x"] = 11, ["y"] = 0, ["z"] = 0, ["name"] = "default:stone"}, {["x"] = 11, ["y"] = 0, ["z"] = 1, ["name"] = "default:stone"}, {["x"] = 11, ["y"] = 0, ["z"] = 2, ["name"] = "default:stone"}, {["x"] = 11, ["y"] = 0, ["z"] = 3, ["name"] = "default:stone"}, {["x"] = 11, ["y"] = 0, ["z"] = 4, ["name"] = "default:stone"}, {["x"] = 11, ["y"] = 0, ["z"] = 5, ["name"] = "default:stone"}, {["x"] = 11, ["y"] = 0, ["z"] = 6, ["name"] = "default:stone"}, {["x"] = 11, ["y"] = 0, ["z"] = 7, ["name"] = "default:stone"}, {["x"] = 11, ["y"] = 0, ["z"] = 8, ["name"] = "default:stone"}, {["x"] = 11, ["y"] = 0, ["z"] = 9, ["name"] = "default:stone"}, {["x"] = 11, ["y"] = 0, ["z"] = 10, ["name"] = "default:stone"}, {["x"] = 11, ["y"] = 0, ["z"] = 11, ["name"] = "default:stone"}, {["x"] = 11, ["y"] = 0, ["z"] = 12, ["name"] = "default:stone"}, {["x"] = 11, ["y"] = 0, ["z"] = 13, ["name"] = "default:stone"}, {["x"] = 11, ["y"] = 0, ["z"] = 14, ["name"] = "default:stone"}, {["x"] = 11, ["y"] = 0, ["z"] = 15, ["name"] = "default:dirt"}, {["x"] = 11, ["y"] = 1, ["param1"] = 15, ["z"] = 0, ["name"] = "default:dirt_with_grass"}, {["x"] = 11, ["y"] = 1, ["z"] = 1, ["name"] = "default:stone_block"}, {["x"] = 11, ["y"] = 1, ["param1"] = 15, ["z"] = 2, ["name"] = "default:stone_block"}, {["x"] = 11, ["y"] = 1, ["param1"] = 15, ["z"] = 3, ["name"] = "default:stone_block"}, {["x"] = 11, ["y"] = 1, ["param1"] = 15, ["z"] = 4, ["name"] = "default:stone_block"}, {["x"] = 11, ["y"] = 1, ["param1"] = 15, ["z"] = 5, ["name"] = "default:stone_block"}, {["x"] = 11, ["y"] = 1, ["param1"] = 15, ["z"] = 6, ["name"] = "default:stone_block"}, {["x"] = 11, ["y"] = 1, ["param1"] = 15, ["z"] = 7, ["name"] = "default:stone_block"}, {["x"] = 11, ["y"] = 1, ["param1"] = 15, ["z"] = 8, ["name"] = "default:stone_block"}, {["x"] = 11, ["y"] = 1, ["param1"] = 15, ["z"] = 9, ["name"] = "default:stone_block"}, {["x"] = 11, ["y"] = 1, ["param1"] = 15, ["z"] = 10, ["name"] = "default:stone_block"}, {["x"] = 11, ["y"] = 1, ["param1"] = 15, ["z"] = 11, ["name"] = "default:stone_block"}, {["x"] = 11, ["y"] = 1, ["param1"] = 14, ["z"] = 12, ["name"] = "default:stone_block"}, {["x"] = 11, ["y"] = 1, ["param1"] = 14, ["z"] = 13, ["name"] = "default:stone_block"}, {["x"] = 11, ["y"] = 1, ["z"] = 14, ["name"] = "default:stone_block"}, {["x"] = 11, ["y"] = 1, ["param1"] = 14, ["z"] = 15, ["name"] = "default:dirt_with_grass"}, {["x"] = 11, ["param2"] = 1, ["y"] = 2, ["param1"] = 14, ["z"] = 0, ["name"] = "default:aspen_leaves"}, {["x"] = 11, ["y"] = 2, ["param1"] = 15, ["z"] = 1, ["name"] = "the_build_spawner:white"}, {["x"] = 11, ["meta"] = {["fields"] = {["formspec"] = "size[9,11.5]image_button[0.5, 0;1, 2;open_button.png;sw_bedt1_1;]image_button[0.5, 2.5;1, 2;open_button.png;sw_bedt1_2;]image_button[0.5, 5;1, 2;open_button.png;sw_bedt1_3;]list[current_player;main;0.5,7.5;8,4;]"}, ["inventory"] = {["main"] = {"", "", "", "", "", "", "", "", "", "", "", "", "", "", "", "", "", "", "", "", "", "", "", "", "", "", "", "", "", "", "", ""}}}, ["param2"] = 2, ["y"] = 2, ["param1"] = 158, ["z"] = 2, ["name"] = "luxury_decor:simple_wooden_bedside_table_1"}, {["x"] = 11, ["meta"] = {["fields"] = {["state"] = "0"}, ["inventory"] = {}}, ["param2"] = 2, ["y"] = 2, ["param1"] = 94, ["z"] = 6, ["name"] = "doors:door_wood_a"}, {["x"] = 11, ["y"] = 2, ["z"] = 10, ["name"] = "the_build_spawner:white"}, {["x"] = 11, ["y"] = 2, ["z"] = 13, ["name"] = "the_build_spawner:white"}, {["x"] = 11, ["y"] = 2, ["z"] = 14, ["name"] = "the_build_spawner:white"}, {["x"] = 11, ["param2"] = 1, ["y"] = 2, ["param1"] = 14, ["z"] = 15, ["name"] = "default:aspen_leaves"}, {["x"] = 11, ["y"] = 3, ["param1"] = 15, ["z"] = 1, ["name"] = "the_build_spawner:white"}, {["x"] = 11, ["meta"] = {["fields"] = {["formspec"] = "size[9,11.5]image_button[0.5, 0;1, 2;open_button.png;sw_bedt1_1;]image_button[0.5, 2.5;1, 2;open_button.png;sw_bedt1_2;]image_button[0.5, 5;1, 2;open_button.png;sw_bedt1_3;]list[current_player;main;0.5,7.5;8,4;]"}, ["inventory"] = {["main"] = {"", "", "", "", "", "", "", "", "", "", "", "", "", "", "", "", "", "", "", "", "", "", "", "", "", "", "", "", "", "", "", ""}}}, ["param2"] = 2, ["y"] = 3, ["param1"] = 174, ["z"] = 2, ["name"] = "luxury_decor:simple_wooden_bedside_table_1"}, {["x"] = 11, ["param2"] = 2, ["y"] = 3, ["param1"] = 110, ["z"] = 6, ["name"] = "doors:hidden"}, {["x"] = 11, ["y"] = 3, ["z"] = 10, ["name"] = "the_build_spawner:white"}, {["x"] = 11, ["y"] = 3, ["z"] = 13, ["name"] = "the_build_spawner:white"}, {["x"] = 11, ["y"] = 3, ["z"] = 14, ["name"] = "the_build_spawner:white"}, {["x"] = 11, ["y"] = 4, ["param1"] = 15, ["z"] = 1, ["name"] = "the_build_spawner:white"}, {["x"] = 11, ["param2"] = 2, ["y"] = 4, ["param1"] = 190, ["z"] = 2, ["name"] = "luxury_decor:wall_glass_lamp_on"}, {["x"] = 11, ["y"] = 4, ["z"] = 6, ["name"] = "the_build_spawner:white"}, {["x"] = 11, ["y"] = 4, ["z"] = 10, ["name"] = "the_build_spawner:white"}, {["x"] = 11, ["y"] = 4, ["z"] = 11, ["name"] = "the_build_spawner:white"}, {["x"] = 11, ["y"] = 4, ["z"] = 12, ["name"] = "the_build_spawner:white"}, {["x"] = 11, ["y"] = 4, ["z"] = 13, ["name"] = "the_build_spawner:white"}, {["x"] = 11, ["y"] = 4, ["z"] = 14, ["name"] = "the_build_spawner:white"}, {["x"] = 11, ["y"] = 4, ["z"] = 15, ["name"] = "the_build_spawner:white"}, {["x"] = 11, ["y"] = 5, ["z"] = 1, ["name"] = "the_build_spawner:white"}, {["x"] = 11, ["y"] = 5, ["param1"] = 15, ["z"] = 2, ["name"] = "the_build_spawner:white"}, {["x"] = 11, ["y"] = 5, ["param1"] = 15, ["z"] = 3, ["name"] = "the_build_spawner:white"}, {["x"] = 11, ["y"] = 5, ["param1"] = 15, ["z"] = 4, ["name"] = "the_build_spawner:white"}, {["x"] = 11, ["y"] = 5, ["param1"] = 31, ["z"] = 5, ["name"] = "the_build_spawner:white"}, {["x"] = 11, ["y"] = 5, ["z"] = 6, ["name"] = "the_build_spawner:white"}, {["x"] = 11, ["y"] = 5, ["param1"] = 63, ["z"] = 7, ["name"] = "the_build_spawner:white"}, {["x"] = 11, ["y"] = 5, ["param1"] = 79, ["z"] = 8, ["name"] = "the_build_spawner:white"}, {["x"] = 11, ["y"] = 5, ["param1"] = 63, ["z"] = 9, ["name"] = "the_build_spawner:white"}, {["x"] = 11, ["y"] = 5, ["z"] = 10, ["name"] = "the_build_spawner:white"}, {["x"] = 11, ["y"] = 5, ["z"] = 11, ["name"] = "the_build_spawner:white"}, {["x"] = 11, ["y"] = 5, ["z"] = 12, ["name"] = "the_build_spawner:white"}, {["x"] = 11, ["y"] = 5, ["z"] = 13, ["name"] = "the_build_spawner:white"}, {["x"] = 11, ["y"] = 5, ["param1"] = 15, ["z"] = 14, ["name"] = "the_build_spawner:white"}, {["x"] = 11, ["y"] = 6, ["param1"] = 15, ["z"] = 1, ["name"] = "the_build_spawner:white"}, {["x"] = 11, ["y"] = 6, ["param1"] = 63, ["z"] = 14, ["name"] = "the_build_spawner:white"}, {["x"] = 11, ["y"] = 6, ["param1"] = 47, ["z"] = 15, ["name"] = "the_build_spawner:white"}, {["x"] = 12, ["y"] = 0, ["z"] = 0, ["name"] = "default:stone"}, {["x"] = 12, ["y"] = 0, ["z"] = 1, ["name"] = "default:stone"}, {["x"] = 12, ["y"] = 0, ["z"] = 2, ["name"] = "default:stone"}, {["x"] = 12, ["y"] = 0, ["z"] = 3, ["name"] = "default:stone"}, {["x"] = 12, ["y"] = 0, ["z"] = 4, ["name"] = "default:stone"}, {["x"] = 12, ["y"] = 0, ["z"] = 5, ["name"] = "default:stone"}, {["x"] = 12, ["y"] = 0, ["z"] = 6, ["name"] = "default:stone"}, {["x"] = 12, ["y"] = 0, ["z"] = 7, ["name"] = "default:stone"}, {["x"] = 12, ["y"] = 0, ["z"] = 8, ["name"] = "default:stone"}, {["x"] = 12, ["y"] = 0, ["z"] = 9, ["name"] = "default:stone"}, {["x"] = 12, ["y"] = 0, ["z"] = 10, ["name"] = "default:stone"}, {["x"] = 12, ["y"] = 0, ["z"] = 11, ["name"] = "default:stone"}, {["x"] = 12, ["y"] = 0, ["z"] = 12, ["name"] = "default:stone"}, {["x"] = 12, ["y"] = 0, ["z"] = 13, ["name"] = "default:stone"}, {["x"] = 12, ["y"] = 0, ["z"] = 14, ["name"] = "default:stone"}, {["x"] = 12, ["y"] = 0, ["z"] = 15, ["name"] = "default:dirt"}, {["x"] = 12, ["y"] = 1, ["param1"] = 15, ["z"] = 0, ["name"] = "default:dirt_with_grass"}, {["x"] = 12, ["y"] = 1, ["z"] = 1, ["name"] = "default:stone_block"}, {["x"] = 12, ["y"] = 1, ["param1"] = 15, ["z"] = 2, ["name"] = "default:stone_block"}, {["x"] = 12, ["y"] = 1, ["param1"] = 15, ["z"] = 3, ["name"] = "default:stone_block"}, {["x"] = 12, ["y"] = 1, ["param1"] = 15, ["z"] = 4, ["name"] = "default:stone_block"}, {["x"] = 12, ["y"] = 1, ["param1"] = 15, ["z"] = 5, ["name"] = "default:stone_block"}, {["x"] = 12, ["y"] = 1, ["param1"] = 15, ["z"] = 6, ["name"] = "default:stone_block"}, {["x"] = 12, ["y"] = 1, ["param1"] = 15, ["z"] = 7, ["name"] = "default:stone_block"}, {["x"] = 12, ["y"] = 1, ["param1"] = 15, ["z"] = 8, ["name"] = "default:stone_block"}, {["x"] = 12, ["y"] = 1, ["param1"] = 15, ["z"] = 9, ["name"] = "default:stone_block"}, {["x"] = 12, ["y"] = 1, ["param1"] = 15, ["z"] = 10, ["name"] = "default:stone_block"}, {["x"] = 12, ["y"] = 1, ["param1"] = 15, ["z"] = 11, ["name"] = "default:stone_block"}, {["x"] = 12, ["y"] = 1, ["param1"] = 14, ["z"] = 12, ["name"] = "default:stone_block"}, {["x"] = 12, ["y"] = 1, ["param1"] = 14, ["z"] = 13, ["name"] = "default:stone_block"}, {["x"] = 12, ["y"] = 1, ["z"] = 14, ["name"] = "default:stone_block"}, {["x"] = 12, ["y"] = 1, ["param1"] = 14, ["z"] = 15, ["name"] = "default:dirt_with_grass"}, {["x"] = 12, ["param2"] = 1, ["y"] = 2, ["param1"] = 14, ["z"] = 0, ["name"] = "default:aspen_leaves"}, {["x"] = 12, ["y"] = 2, ["param1"] = 15, ["z"] = 1, ["name"] = "the_build_spawner:white"}, {["x"] = 12, ["y"] = 2, ["z"] = 6, ["name"] = "the_build_spawner:white"}, {["x"] = 12, ["y"] = 2, ["z"] = 7, ["name"] = "the_build_spawner:white"}, {["x"] = 12, ["meta"] = {["fields"] = {["state"] = "0"}, ["inventory"] = {}}, ["param2"] = 3, ["y"] = 2, ["param1"] = 110, ["z"] = 8, ["name"] = "doors:door_wood_a"}, {["x"] = 12, ["y"] = 2, ["z"] = 9, ["name"] = "the_build_spawner:white"}, {["x"] = 12, ["meta"] = {["fields"] = {["formspec"] = "size[10,11.5]image_button[0.5, 0.5;3, 6;open_button.png;fridge_closed;]list[current_player;main;1,7;8,4;]"}, ["inventory"] = {["main"] = {"", "", "", "", "", "", "", "", "", "", "", "", "", "", "", "", "", "", "", "", "", "", "", "", "", "", "", "", "", "", "", ""}}}, ["param2"] = 2, ["y"] = 2, ["param1"] = 142, ["z"] = 10, ["name"] = "luxury_decor:fridge_1"}, {["x"] = 12, ["meta"] = {["fields"] = {["formspec"] = "size[9,8.5]image_button[0.5, 0.5;2, 3;open_button.png;kwc_with_sink1;]list[current_player;main;0.5,4.5;8,4;]"}, ["inventory"] = {["main"] = {"", "", "", "", "", "", "", "", "", "", "", "", "", "", "", "", "", "", "", "", "", "", "", "", "", "", "", "", "", "", "", ""}}}, ["y"] = 2, ["param1"] = 157, ["z"] = 13, ["name"] = "luxury_decor:kitchen_wooden_cabinet_with_sink_1"}, {["x"] = 12, ["y"] = 2, ["z"] = 14, ["name"] = "the_build_spawner:white"}, {["x"] = 12, ["param2"] = 1, ["y"] = 2, ["param1"] = 14, ["z"] = 15, ["name"] = "default:aspen_leaves"}, {["x"] = 12, ["y"] = 3, ["param1"] = 15, ["z"] = 1, ["name"] = "the_build_spawner:white"}, {["x"] = 12, ["y"] = 3, ["param1"] = 110, ["z"] = 5, ["name"] = "luxury_decor:bright_wall_wooden_shelf"}, {["x"] = 12, ["y"] = 3, ["z"] = 6, ["name"] = "the_build_spawner:white"}, {["x"] = 12, ["y"] = 3, ["z"] = 7, ["name"] = "the_build_spawner:white"}, {["x"] = 12, ["param2"] = 3, ["y"] = 3, ["param1"] = 126, ["z"] = 8, ["name"] = "doors:hidden"}, {["x"] = 12, ["y"] = 3, ["z"] = 9, ["name"] = "the_build_spawner:white"}, {["x"] = 12, ["y"] = 3, ["param1"] = 173, ["z"] = 13, ["name"] = "luxury_decor:kitchen_tap_off"}, {["x"] = 12, ["y"] = 3, ["z"] = 14, ["name"] = "the_build_spawner:white"}, {["x"] = 12, ["y"] = 4, ["param1"] = 15, ["z"] = 1, ["name"] = "the_build_spawner:white"}, {["x"] = 12, ["y"] = 4, ["z"] = 6, ["name"] = "the_build_spawner:white"}, {["x"] = 12, ["y"] = 4, ["z"] = 7, ["name"] = "the_build_spawner:white"}, {["x"] = 12, ["y"] = 4, ["z"] = 8, ["name"] = "the_build_spawner:white"}, {["x"] = 12, ["y"] = 4, ["z"] = 9, ["name"] = "the_build_spawner:white"}, {["x"] = 12, ["param2"] = 20, ["y"] = 4, ["param1"] = 189, ["z"] = 13, ["name"] = "luxury_decor:wall_glass_lamp_on"}, {["x"] = 12, ["y"] = 4, ["z"] = 14, ["name"] = "the_build_spawner:white"}, {["x"] = 12, ["y"] = 4, ["z"] = 15, ["name"] = "the_build_spawner:white"}, {["x"] = 12, ["y"] = 5, ["z"] = 1, ["name"] = "the_build_spawner:white"}, {["x"] = 12, ["y"] = 5, ["param1"] = 15, ["z"] = 2, ["name"] = "the_build_spawner:white"}, {["x"] = 12, ["y"] = 5, ["param1"] = 15, ["z"] = 3, ["name"] = "the_build_spawner:white"}, {["x"] = 12, ["y"] = 5, ["param1"] = 15, ["z"] = 4, ["name"] = "the_build_spawner:white"}, {["x"] = 12, ["y"] = 5, ["param1"] = 15, ["z"] = 5, ["name"] = "the_build_spawner:white"}, {["x"] = 12, ["y"] = 5, ["z"] = 6, ["name"] = "the_build_spawner:white"}, {["x"] = 12, ["y"] = 5, ["z"] = 7, ["name"] = "the_build_spawner:white"}, {["x"] = 12, ["y"] = 5, ["z"] = 8, ["name"] = "the_build_spawner:white"}, {["x"] = 12, ["y"] = 5, ["z"] = 9, ["name"] = "the_build_spawner:white"}, {["x"] = 12, ["y"] = 5, ["z"] = 10, ["name"] = "the_build_spawner:white"}, {["x"] = 12, ["y"] = 5, ["param1"] = 143, ["z"] = 11, ["name"] = "the_build_spawner:white"}, {["x"] = 12, ["y"] = 5, ["param1"] = 158, ["z"] = 12, ["name"] = "the_build_spawner:white"}, {["x"] = 12, ["y"] = 5, ["z"] = 13, ["name"] = "the_build_spawner:white"}, {["x"] = 12, ["y"] = 5, ["param1"] = 15, ["z"] = 14, ["name"] = "the_build_spawner:white"}, {["x"] = 12, ["y"] = 6, ["param1"] = 15, ["z"] = 1, ["name"] = "the_build_spawner:white"}, {["x"] = 12, ["y"] = 6, ["param1"] = 79, ["z"] = 14, ["name"] = "the_build_spawner:white"}, {["x"] = 12, ["y"] = 6, ["param1"] = 63, ["z"] = 15, ["name"] = "the_build_spawner:white"}, {["x"] = 13, ["y"] = 0, ["z"] = 0, ["name"] = "default:stone"}, {["x"] = 13, ["y"] = 0, ["z"] = 1, ["name"] = "default:stone"}, {["x"] = 13, ["y"] = 0, ["z"] = 2, ["name"] = "default:stone"}, {["x"] = 13, ["y"] = 0, ["z"] = 3, ["name"] = "default:stone"}, {["x"] = 13, ["y"] = 0, ["z"] = 4, ["name"] = "default:stone"}, {["x"] = 13, ["y"] = 0, ["z"] = 5, ["name"] = "default:stone"}, {["x"] = 13, ["y"] = 0, ["z"] = 6, ["name"] = "default:stone"}, {["x"] = 13, ["y"] = 0, ["z"] = 7, ["name"] = "default:stone"}, {["x"] = 13, ["y"] = 0, ["z"] = 8, ["name"] = "default:stone"}, {["x"] = 13, ["y"] = 0, ["z"] = 9, ["name"] = "default:stone"}, {["x"] = 13, ["y"] = 0, ["z"] = 10, ["name"] = "default:stone"}, {["x"] = 13, ["y"] = 0, ["z"] = 11, ["name"] = "default:stone"}, {["x"] = 13, ["y"] = 0, ["z"] = 12, ["name"] = "default:stone"}, {["x"] = 13, ["y"] = 0, ["z"] = 13, ["name"] = "default:stone"}, {["x"] = 13, ["y"] = 0, ["z"] = 14, ["name"] = "default:stone"}, {["x"] = 13, ["y"] = 0, ["z"] = 15, ["name"] = "default:dirt"}, {["x"] = 13, ["y"] = 1, ["param1"] = 15, ["z"] = 0, ["name"] = "default:dirt_with_grass"}, {["x"] = 13, ["y"] = 1, ["z"] = 1, ["name"] = "default:stone_block"}, {["x"] = 13, ["y"] = 1, ["param1"] = 15, ["z"] = 2, ["name"] = "default:stone_block"}, {["x"] = 13, ["y"] = 1, ["param1"] = 15, ["z"] = 3, ["name"] = "default:stone_block"}, {["x"] = 13, ["y"] = 1, ["param1"] = 15, ["z"] = 4, ["name"] = "default:stone_block"}, {["x"] = 13, ["y"] = 1, ["param1"] = 15, ["z"] = 5, ["name"] = "default:stone_block"}, {["x"] = 13, ["y"] = 1, ["param1"] = 15, ["z"] = 6, ["name"] = "default:stone_block"}, {["x"] = 13, ["y"] = 1, ["param1"] = 15, ["z"] = 7, ["name"] = "default:stone_block"}, {["x"] = 13, ["y"] = 1, ["param1"] = 15, ["z"] = 8, ["name"] = "default:stone_block"}, {["x"] = 13, ["y"] = 1, ["param1"] = 15, ["z"] = 9, ["name"] = "default:stone_block"}, {["x"] = 13, ["y"] = 1, ["param1"] = 15, ["z"] = 10, ["name"] = "default:stone_block"}, {["x"] = 13, ["y"] = 1, ["param1"] = 15, ["z"] = 11, ["name"] = "default:stone_block"}, {["x"] = 13, ["y"] = 1, ["param1"] = 14, ["z"] = 12, ["name"] = "default:stone_block"}, {["x"] = 13, ["y"] = 1, ["param1"] = 14, ["z"] = 13, ["name"] = "default:stone_block"}, {["x"] = 13, ["y"] = 1, ["z"] = 14, ["name"] = "default:stone_block"}, {["x"] = 13, ["y"] = 1, ["param1"] = 14, ["z"] = 15, ["name"] = "default:dirt_with_grass"}, {["x"] = 13, ["param2"] = 1, ["y"] = 2, ["param1"] = 14, ["z"] = 0, ["name"] = "default:aspen_leaves"}, {["x"] = 13, ["y"] = 2, ["param1"] = 15, ["z"] = 1, ["name"] = "the_build_spawner:white"}, {["x"] = 13, ["param2"] = 2, ["y"] = 2, ["param1"] = 142, ["z"] = 2, ["name"] = "luxury_decor:royal_double_bed_blue"}, {["x"] = 13, ["y"] = 2, ["z"] = 6, ["name"] = "the_build_spawner:white"}, {["x"] = 13, ["y"] = 2, ["param1"] = 140, ["z"] = 7, ["name"] = "luxury_decor:laminate"}, {["x"] = 13, ["y"] = 2, ["param1"] = 125, ["z"] = 8, ["name"] = "luxury_decor:laminate"}, {["x"] = 13, ["y"] = 2, ["z"] = 9, ["name"] = "the_build_spawner:white"}, {["x"] = 13, ["meta"] = {["fields"] = {["formspec"] = "size[9,10.5]image_button[0.5, 0.5;2, 4;open_button.png;kwc_with_two_doors1;]list[current_player;main;0.5,5;8,4;]"}, ["inventory"] = {["main"] = {"", "", "", "", "", "", "", "", "", "", "", "", "", "", "", "", "", "", "", "", "", "", "", "", "", "", "", "", "", "", "", ""}}}, ["param2"] = 2, ["y"] = 2, ["param1"] = 158, ["z"] = 10, ["name"] = "luxury_decor:kitchen_wooden_cabinet_with_two_doors_1"}, {["x"] = 13, ["meta"] = {["fields"] = {["formspec"] = "size[9,10.5]image_button[0.5, 0.5;2, 4;open_button.png;kwc_with_two_doors1;]list[current_player;main;0.5,5;8,4;]"}, ["inventory"] = {["main"] = {"", "", "", "", "", "", "", "", "", "", "", "", "", "", "", "", "", "", "", "", "", "", "", "", "", "", "", "", "", "", "", ""}}}, ["y"] = 2, ["param1"] = 157, ["z"] = 13, ["name"] = "luxury_decor:kitchen_wooden_cabinet_with_two_doors_1"}, {["x"] = 13, ["y"] = 2, ["z"] = 14, ["name"] = "the_build_spawner:white"}, {["x"] = 13, ["param2"] = 1, ["y"] = 2, ["param1"] = 14, ["z"] = 15, ["name"] = "default:aspen_leaves"}, {["x"] = 13, ["y"] = 3, ["param1"] = 15, ["z"] = 1, ["name"] = "the_build_spawner:white"}, {["x"] = 13, ["y"] = 3, ["param1"] = 110, ["z"] = 5, ["name"] = "luxury_decor:bright_wall_wooden_shelf"}, {["x"] = 13, ["y"] = 3, ["z"] = 6, ["name"] = "the_build_spawner:white"}, {["x"] = 13, ["param2"] = 2, ["y"] = 3, ["param1"] = 156, ["z"] = 7, ["name"] = "luxury_decor:dark_wall_wooden_shelf"}, {["x"] = 13, ["y"] = 3, ["z"] = 9, ["name"] = "the_build_spawner:white"}, {["x"] = 13, ["y"] = 3, ["z"] = 14, ["name"] = "the_build_spawner:white"}, {["x"] = 13, ["y"] = 4, ["param1"] = 15, ["z"] = 1, ["name"] = "the_build_spawner:white"}, {["x"] = 13, ["y"] = 4, ["z"] = 6, ["name"] = "the_build_spawner:white"}, {["x"] = 13, ["y"] = 4, ["z"] = 9, ["name"] = "the_build_spawner:white"}, {["x"] = 13, ["param2"] = 22, ["y"] = 4, ["param1"] = 190, ["z"] = 10, ["name"] = "luxury_decor:wall_glass_lamp_on"}, {["x"] = 13, ["param2"] = 20, ["y"] = 4, ["param1"] = 189, ["z"] = 13, ["name"] = "luxury_decor:wall_glass_lamp_on"}, {["x"] = 13, ["y"] = 4, ["z"] = 14, ["name"] = "the_build_spawner:white"}, {["x"] = 13, ["y"] = 4, ["z"] = 15, ["name"] = "the_build_spawner:white"}, {["x"] = 13, ["y"] = 5, ["z"] = 1, ["name"] = "the_build_spawner:white"}, {["x"] = 13, ["y"] = 5, ["param1"] = 15, ["z"] = 2, ["name"] = "the_build_spawner:white"}, {["x"] = 13, ["y"] = 5, ["param1"] = 15, ["z"] = 3, ["name"] = "the_build_spawner:white"}, {["x"] = 13, ["y"] = 5, ["param1"] = 15, ["z"] = 4, ["name"] = "the_build_spawner:white"}, {["x"] = 13, ["y"] = 5, ["param1"] = 31, ["z"] = 5, ["name"] = "the_build_spawner:white"}, {["x"] = 13, ["y"] = 5, ["z"] = 6, ["name"] = "the_build_spawner:white"}, {["x"] = 13, ["y"] = 5, ["z"] = 7, ["name"] = "the_build_spawner:white"}, {["x"] = 13, ["y"] = 5, ["z"] = 8, ["name"] = "the_build_spawner:white"}, {["x"] = 13, ["y"] = 5, ["z"] = 9, ["name"] = "the_build_spawner:white"}, {["x"] = 13, ["y"] = 5, ["z"] = 10, ["name"] = "the_build_spawner:white"}, {["x"] = 13, ["y"] = 5, ["param1"] = 159, ["z"] = 11, ["name"] = "the_build_spawner:white"}, {["x"] = 13, ["y"] = 5, ["param1"] = 158, ["z"] = 12, ["name"] = "the_build_spawner:white"}, {["x"] = 13, ["y"] = 5, ["z"] = 13, ["name"] = "the_build_spawner:white"}, {["x"] = 13, ["y"] = 5, ["param1"] = 15, ["z"] = 14, ["name"] = "the_build_spawner:white"}, {["x"] = 13, ["y"] = 6, ["param1"] = 15, ["z"] = 1, ["name"] = "the_build_spawner:white"}, {["x"] = 13, ["y"] = 6, ["param1"] = 95, ["z"] = 14, ["name"] = "the_build_spawner:white"}, {["x"] = 13, ["y"] = 6, ["param1"] = 79, ["z"] = 15, ["name"] = "the_build_spawner:white"}, {["x"] = 14, ["y"] = 0, ["z"] = 0, ["name"] = "default:stone"}, {["x"] = 14, ["y"] = 0, ["z"] = 1, ["name"] = "default:stone"}, {["x"] = 14, ["y"] = 0, ["z"] = 2, ["name"] = "default:stone"}, {["x"] = 14, ["y"] = 0, ["z"] = 3, ["name"] = "default:stone"}, {["x"] = 14, ["y"] = 0, ["z"] = 4, ["name"] = "default:stone"}, {["x"] = 14, ["y"] = 0, ["z"] = 5, ["name"] = "default:stone"}, {["x"] = 14, ["y"] = 0, ["z"] = 6, ["name"] = "default:stone"}, {["x"] = 14, ["y"] = 0, ["z"] = 7, ["name"] = "default:stone"}, {["x"] = 14, ["y"] = 0, ["z"] = 8, ["name"] = "default:stone"}, {["x"] = 14, ["y"] = 0, ["z"] = 9, ["name"] = "default:stone"}, {["x"] = 14, ["y"] = 0, ["z"] = 10, ["name"] = "default:stone"}, {["x"] = 14, ["y"] = 0, ["z"] = 11, ["name"] = "default:stone"}, {["x"] = 14, ["y"] = 0, ["z"] = 12, ["name"] = "default:stone"}, {["x"] = 14, ["y"] = 0, ["z"] = 13, ["name"] = "default:stone"}, {["x"] = 14, ["y"] = 0, ["z"] = 14, ["name"] = "default:stone"}, {["x"] = 14, ["y"] = 0, ["z"] = 15, ["name"] = "default:dirt_with_grass"}, {["x"] = 14, ["y"] = 1, ["param1"] = 15, ["z"] = 0, ["name"] = "default:dirt_with_grass"}, {["x"] = 14, ["y"] = 1, ["z"] = 1, ["name"] = "default:stone_block"}, {["x"] = 14, ["y"] = 1, ["param1"] = 15, ["z"] = 2, ["name"] = "default:stone_block"}, {["x"] = 14, ["y"] = 1, ["param1"] = 15, ["z"] = 3, ["name"] = "default:stone_block"}, {["x"] = 14, ["y"] = 1, ["param1"] = 15, ["z"] = 4, ["name"] = "default:stone_block"}, {["x"] = 14, ["y"] = 1, ["param1"] = 15, ["z"] = 5, ["name"] = "default:stone_block"}, {["x"] = 14, ["y"] = 1, ["param1"] = 15, ["z"] = 6, ["name"] = "default:stone_block"}, {["x"] = 14, ["y"] = 1, ["param1"] = 15, ["z"] = 7, ["name"] = "default:stone_block"}, {["x"] = 14, ["y"] = 1, ["param1"] = 15, ["z"] = 8, ["name"] = "default:stone_block"}, {["x"] = 14, ["y"] = 1, ["param1"] = 15, ["z"] = 9, ["name"] = "default:stone_block"}, {["x"] = 14, ["y"] = 1, ["param1"] = 15, ["z"] = 10, ["name"] = "default:stone_block"}, {["x"] = 14, ["y"] = 1, ["param1"] = 15, ["z"] = 11, ["name"] = "default:stone_block"}, {["x"] = 14, ["y"] = 1, ["param1"] = 14, ["z"] = 12, ["name"] = "default:stone_block"}, {["x"] = 14, ["y"] = 1, ["param1"] = 14, ["z"] = 13, ["name"] = "default:stone_block"}, {["x"] = 14, ["y"] = 1, ["z"] = 14, ["name"] = "default:stone_block"}, {["x"] = 14, ["y"] = 1, ["param1"] = 14, ["z"] = 15, ["name"] = "default:dirt_with_grass"}, {["x"] = 14, ["param2"] = 1, ["y"] = 2, ["param1"] = 14, ["z"] = 0, ["name"] = "default:aspen_leaves"}, {["x"] = 14, ["y"] = 2, ["param1"] = 15, ["z"] = 1, ["name"] = "the_build_spawner:white"}, {["x"] = 14, ["meta"] = {["fields"] = {["formspec"] = "size[9,11.5]image_button[0.5, 0;1, 2;open_button.png;sw_bedt1_1;]image_button[0.5, 2.5;1, 2;open_button.png;sw_bedt1_2;]image_button[0.5, 5;1, 2;open_button.png;sw_bedt1_3;]list[current_player;main;0.5,7.5;8,4;]"}, ["inventory"] = {["main"] = {"", "", "", "", "", "", "", "", "", "", "", "", "", "", "", "", "", "", "", "", "", "", "", "", "", "", "", "", "", "", "", ""}}}, ["param2"] = 2, ["y"] = 2, ["param1"] = 158, ["z"] = 2, ["name"] = "luxury_decor:simple_wooden_bedside_table_1"}, {["x"] = 14, ["y"] = 2, ["z"] = 6, ["name"] = "the_build_spawner:white"}, {["x"] = 14, ["meta"] = {["fields"] = {["formspec"] = "size[9,8.5]image_button[0.5, 0.5;2, 3;open_button.png;kwc_with_sink1;]list[current_player;main;0.5,4.5;8,4;]"}, ["inventory"] = {["main"] = {"", "", "", "", "", "", "", "", "", "", "", "", "", "", "", "", "", "", "", "", "", "", "", "", "", "", "", "", "", "", "", ""}}}, ["param2"] = 2, ["y"] = 2, ["param1"] = 155, ["z"] = 7, ["name"] = "luxury_decor:kitchen_wooden_cabinet_with_sink_1"}, {["x"] = 14, ["y"] = 2, ["param1"] = 140, ["z"] = 8, ["name"] = "luxury_decor:laminate"}, {["x"] = 14, ["y"] = 2, ["z"] = 9, ["name"] = "the_build_spawner:white"}, {["x"] = 14, ["y"] = 2, ["z"] = 10, ["name"] = "the_build_spawner:white"}, {["x"] = 14, ["param2"] = 1, ["y"] = 2, ["param1"] = 126, ["z"] = 11, ["name"] = "luxury_decor:cooker"}, {["x"] = 14, ["param2"] = 1, ["y"] = 2, ["param1"] = 125, ["z"] = 12, ["name"] = "luxury_decor:kitchen_wooden_table"}, {["x"] = 14, ["y"] = 2, ["z"] = 13, ["name"] = "the_build_spawner:white"}, {["x"] = 14, ["y"] = 2, ["z"] = 14, ["name"] = "the_build_spawner:white"}, {["x"] = 14, ["param2"] = 1, ["y"] = 2, ["param1"] = 14, ["z"] = 15, ["name"] = "default:aspen_leaves"}, {["x"] = 14, ["y"] = 3, ["param1"] = 15, ["z"] = 1, ["name"] = "the_build_spawner:white"}, {["x"] = 14, ["y"] = 3, ["param1"] = 126, ["z"] = 5, ["name"] = "luxury_decor:bright_wall_wooden_shelf"}, {["x"] = 14, ["y"] = 3, ["z"] = 6, ["name"] = "the_build_spawner:white"}, {["x"] = 14, ["param2"] = 2, ["y"] = 3, ["param1"] = 171, ["z"] = 7, ["name"] = "luxury_decor:kitchen_tap_off"}, {["x"] = 14, ["y"] = 3, ["z"] = 9, ["name"] = "the_build_spawner:white"}, {["x"] = 14, ["y"] = 3, ["z"] = 10, ["name"] = "the_build_spawner:white"}, {["x"] = 14, ["param2"] = 1, ["y"] = 3, ["param1"] = 141, ["z"] = 12, ["name"] = "luxury_decor:glass_vase"}, {["x"] = 14, ["y"] = 3, ["z"] = 13, ["name"] = "the_build_spawner:white"}, {["x"] = 14, ["y"] = 3, ["z"] = 14, ["name"] = "the_build_spawner:white"}, {["x"] = 14, ["y"] = 4, ["param1"] = 15, ["z"] = 1, ["name"] = "the_build_spawner:white"}, {["x"] = 14, ["param2"] = 2, ["y"] = 4, ["param1"] = 190, ["z"] = 2, ["name"] = "luxury_decor:wall_glass_lamp_on"}, {["x"] = 14, ["y"] = 4, ["z"] = 6, ["name"] = "the_build_spawner:white"}, {["x"] = 14, ["param2"] = 22, ["y"] = 4, ["param1"] = 187, ["z"] = 7, ["name"] = "luxury_decor:wall_glass_lamp_on"}, {["x"] = 14, ["y"] = 4, ["z"] = 9, ["name"] = "the_build_spawner:white"}, {["x"] = 14, ["y"] = 4, ["z"] = 10, ["name"] = "the_build_spawner:white"}, {["x"] = 14, ["y"] = 4, ["z"] = 13, ["name"] = "the_build_spawner:white"}, {["x"] = 14, ["y"] = 4, ["z"] = 14, ["name"] = "the_build_spawner:white"}, {["x"] = 14, ["y"] = 4, ["z"] = 15, ["name"] = "the_build_spawner:white"}, {["x"] = 14, ["y"] = 5, ["z"] = 1, ["name"] = "the_build_spawner:white"}, {["x"] = 14, ["y"] = 5, ["param1"] = 15, ["z"] = 2, ["name"] = "the_build_spawner:white"}, {["x"] = 14, ["y"] = 5, ["param1"] = 15, ["z"] = 3, ["name"] = "the_build_spawner:white"}, {["x"] = 14, ["y"] = 5, ["param1"] = 15, ["z"] = 4, ["name"] = "the_build_spawner:white"}, {["x"] = 14, ["y"] = 5, ["param1"] = 15, ["z"] = 5, ["name"] = "the_build_spawner:white"}, {["x"] = 14, ["y"] = 5, ["z"] = 6, ["name"] = "the_build_spawner:white"}, {["x"] = 14, ["y"] = 5, ["z"] = 7, ["name"] = "the_build_spawner:white"}, {["x"] = 14, ["y"] = 5, ["z"] = 8, ["name"] = "the_build_spawner:white"}, {["x"] = 14, ["y"] = 5, ["z"] = 9, ["name"] = "the_build_spawner:white"}, {["x"] = 14, ["y"] = 5, ["z"] = 10, ["name"] = "the_build_spawner:white"}, {["x"] = 14, ["y"] = 5, ["z"] = 11, ["name"] = "the_build_spawner:white"}, {["x"] = 14, ["y"] = 5, ["z"] = 12, ["name"] = "the_build_spawner:white"}, {["x"] = 14, ["y"] = 5, ["z"] = 13, ["name"] = "the_build_spawner:white"}, {["x"] = 14, ["y"] = 5, ["param1"] = 15, ["z"] = 14, ["name"] = "the_build_spawner:white"}, {["x"] = 14, ["y"] = 6, ["param1"] = 15, ["z"] = 1, ["name"] = "the_build_spawner:white"}, {["x"] = 14, ["y"] = 6, ["param1"] = 79, ["z"] = 14, ["name"] = "the_build_spawner:white"}, {["x"] = 14, ["y"] = 6, ["param1"] = 63, ["z"] = 15, ["name"] = "the_build_spawner:white"}, {["x"] = 15, ["y"] = 0, ["z"] = 0, ["name"] = "default:stone"}, {["x"] = 15, ["y"] = 0, ["z"] = 1, ["name"] = "default:stone"}, {["x"] = 15, ["y"] = 0, ["z"] = 2, ["name"] = "default:stone"}, {["x"] = 15, ["y"] = 0, ["z"] = 3, ["name"] = "default:stone"}, {["x"] = 15, ["y"] = 0, ["z"] = 4, ["name"] = "default:stone"}, {["x"] = 15, ["y"] = 0, ["z"] = 5, ["name"] = "default:stone"}, {["x"] = 15, ["y"] = 0, ["z"] = 6, ["name"] = "default:stone"}, {["x"] = 15, ["y"] = 0, ["z"] = 7, ["name"] = "default:stone"}, {["x"] = 15, ["y"] = 0, ["z"] = 8, ["name"] = "default:stone"}, {["x"] = 15, ["y"] = 0, ["z"] = 9, ["name"] = "default:stone"}, {["x"] = 15, ["y"] = 0, ["z"] = 10, ["name"] = "default:stone"}, {["x"] = 15, ["y"] = 0, ["z"] = 11, ["name"] = "default:stone"}, {["x"] = 15, ["y"] = 0, ["z"] = 12, ["name"] = "default:stone"}, {["x"] = 15, ["y"] = 0, ["z"] = 13, ["name"] = "default:stone"}, {["x"] = 15, ["y"] = 0, ["z"] = 14, ["name"] = "default:stone"}, {["x"] = 15, ["y"] = 0, ["z"] = 15, ["name"] = "default:dirt"}, {["x"] = 15, ["y"] = 1, ["param1"] = 14, ["z"] = 0, ["name"] = "default:dirt_with_grass"}, {["x"] = 15, ["y"] = 1, ["z"] = 1, ["name"] = "default:stone_block"}, {["x"] = 15, ["y"] = 1, ["z"] = 2, ["name"] = "default:stone_block"}, {["x"] = 15, ["y"] = 1, ["z"] = 3, ["name"] = "default:stone_block"}, {["x"] = 15, ["y"] = 1, ["z"] = 4, ["name"] = "default:stone_block"}, {["x"] = 15, ["y"] = 1, ["z"] = 5, ["name"] = "default:stone_block"}, {["x"] = 15, ["y"] = 1, ["z"] = 6, ["name"] = "default:stone_block"}, {["x"] = 15, ["y"] = 1, ["z"] = 7, ["name"] = "default:stone_block"}, {["x"] = 15, ["y"] = 1, ["z"] = 8, ["name"] = "default:stone_block"}, {["x"] = 15, ["y"] = 1, ["z"] = 9, ["name"] = "default:stone_block"}, {["x"] = 15, ["y"] = 1, ["z"] = 10, ["name"] = "default:stone_block"}, {["x"] = 15, ["y"] = 1, ["z"] = 11, ["name"] = "default:stone_block"}, {["x"] = 15, ["y"] = 1, ["z"] = 12, ["name"] = "default:stone_block"}, {["x"] = 15, ["y"] = 1, ["z"] = 13, ["name"] = "default:stone_block"}, {["x"] = 15, ["y"] = 1, ["z"] = 14, ["name"] = "default:stone_block"}, {["x"] = 15, ["y"] = 1, ["param1"] = 14, ["z"] = 15, ["name"] = "default:dirt_with_grass"}, {["x"] = 15, ["param2"] = 1, ["y"] = 2, ["param1"] = 13, ["z"] = 0, ["name"] = "default:aspen_leaves"}, {["x"] = 15, ["y"] = 2, ["z"] = 1, ["name"] = "the_build_spawner:white"}, {["x"] = 15, ["y"] = 2, ["param1"] = 14, ["z"] = 2, ["name"] = "the_build_spawner:white"}, {["x"] = 15, ["y"] = 2, ["param1"] = 14, ["z"] = 3, ["name"] = "the_build_spawner:white"}, {["x"] = 15, ["y"] = 2, ["param1"] = 14, ["z"] = 4, ["name"] = "the_build_spawner:white"}, {["x"] = 15, ["y"] = 2, ["param1"] = 14, ["z"] = 5, ["name"] = "the_build_spawner:white"}, {["x"] = 15, ["y"] = 2, ["param1"] = 14, ["z"] = 6, ["name"] = "the_build_spawner:white"}, {["x"] = 15, ["y"] = 2, ["param1"] = 14, ["z"] = 7, ["name"] = "the_build_spawner:white"}, {["x"] = 15, ["y"] = 2, ["param1"] = 14, ["z"] = 8, ["name"] = "the_build_spawner:white"}, {["x"] = 15, ["y"] = 2, ["param1"] = 14, ["z"] = 9, ["name"] = "the_build_spawner:white"}, {["x"] = 15, ["y"] = 2, ["param1"] = 14, ["z"] = 10, ["name"] = "the_build_spawner:white"}, {["x"] = 15, ["y"] = 2, ["param1"] = 14, ["z"] = 11, ["name"] = "the_build_spawner:white"}, {["x"] = 15, ["y"] = 2, ["z"] = 12, ["name"] = "the_build_spawner:white"}, {["x"] = 15, ["y"] = 2, ["z"] = 13, ["name"] = "the_build_spawner:white"}, {["x"] = 15, ["y"] = 2, ["z"] = 14, ["name"] = "the_build_spawner:white"}, {["x"] = 15, ["param2"] = 1, ["y"] = 2, ["param1"] = 13, ["z"] = 15, ["name"] = "default:aspen_leaves"}, {["x"] = 15, ["y"] = 3, ["param1"] = 14, ["z"] = 1, ["name"] = "the_build_spawner:white"}, {["x"] = 15, ["y"] = 3, ["param1"] = 14, ["z"] = 2, ["name"] = "the_build_spawner:white"}, {["x"] = 15, ["y"] = 3, ["param1"] = 14, ["z"] = 3, ["name"] = "the_build_spawner:white"}, {["x"] = 15, ["y"] = 3, ["param1"] = 14, ["z"] = 4, ["name"] = "the_build_spawner:white"}, {["x"] = 15, ["y"] = 3, ["param1"] = 14, ["z"] = 5, ["name"] = "the_build_spawner:white"}, {["x"] = 15, ["y"] = 3, ["param1"] = 14, ["z"] = 6, ["name"] = "the_build_spawner:white"}, {["x"] = 15, ["y"] = 3, ["param1"] = 14, ["z"] = 7, ["name"] = "the_build_spawner:white"}, {["x"] = 15, ["y"] = 3, ["param1"] = 14, ["z"] = 8, ["name"] = "the_build_spawner:white"}, {["x"] = 15, ["y"] = 3, ["param1"] = 14, ["z"] = 9, ["name"] = "the_build_spawner:white"}, {["x"] = 15, ["y"] = 3, ["param1"] = 14, ["z"] = 10, ["name"] = "the_build_spawner:white"}, {["x"] = 15, ["y"] = 3, ["param1"] = 14, ["z"] = 11, ["name"] = "the_build_spawner:white"}, {["x"] = 15, ["y"] = 3, ["param1"] = 14, ["z"] = 12, ["name"] = "the_build_spawner:white"}, {["x"] = 15, ["y"] = 3, ["z"] = 13, ["name"] = "the_build_spawner:white"}, {["x"] = 15, ["y"] = 3, ["z"] = 14, ["name"] = "the_build_spawner:white"}, {["x"] = 15, ["y"] = 4, ["param1"] = 14, ["z"] = 1, ["name"] = "the_build_spawner:white"}, {["x"] = 15, ["y"] = 4, ["param1"] = 14, ["z"] = 2, ["name"] = "the_build_spawner:white"}, {["x"] = 15, ["y"] = 4, ["param1"] = 14, ["z"] = 3, ["name"] = "the_build_spawner:white"}, {["x"] = 15, ["y"] = 4, ["param1"] = 14, ["z"] = 4, ["name"] = "the_build_spawner:white"}, {["x"] = 15, ["y"] = 4, ["param1"] = 14, ["z"] = 5, ["name"] = "the_build_spawner:white"}, {["x"] = 15, ["y"] = 4, ["param1"] = 14, ["z"] = 6, ["name"] = "the_build_spawner:white"}, {["x"] = 15, ["y"] = 4, ["param1"] = 14, ["z"] = 7, ["name"] = "the_build_spawner:white"}, {["x"] = 15, ["y"] = 4, ["param1"] = 14, ["z"] = 8, ["name"] = "the_build_spawner:white"}, {["x"] = 15, ["y"] = 4, ["param1"] = 14, ["z"] = 9, ["name"] = "the_build_spawner:white"}, {["x"] = 15, ["y"] = 4, ["param1"] = 14, ["z"] = 10, ["name"] = "the_build_spawner:white"}, {["x"] = 15, ["y"] = 4, ["param1"] = 14, ["z"] = 11, ["name"] = "the_build_spawner:white"}, {["x"] = 15, ["y"] = 4, ["param1"] = 14, ["z"] = 12, ["name"] = "the_build_spawner:white"},