5:return {{["x"] = 0, ["y"] = 0, ["param1"] = 14, ["z"] = 0, ["name"] = "default:stone"}, {["x"] = 0, ["y"] = 0, ["param1"] = 30, ["z"] = 1, ["name"] = "default:stone"}, {["x"] = 0, ["y"] = 0, ["param1"] = 46, ["z"] = 2, ["name"] = "default:stone"}, {["x"] = 0, ["y"] = 0, ["param1"] = 62, ["z"] = 3, ["name"] = "default:stone"}, {["x"] = 0, ["y"] = 0, ["param1"] = 78, ["z"] = 4, ["name"] = "default:stone"}, {["x"] = 0, ["y"] = 0, ["param1"] = 78, ["z"] = 5, ["name"] = "default:stone"}, {["x"] = 0, ["y"] = 0, ["param1"] = 78, ["z"] = 6, ["name"] = "default:stone"}, {["x"] = 0, ["y"] = 0, ["param1"] = 78, ["z"] = 7, ["name"] = "default:stone"}, {["x"] = 0, ["y"] = 0, ["param1"] = 78, ["z"] = 8, ["name"] = "default:stone"}, {["x"] = 0, ["y"] = 0, ["param1"] = 78, ["z"] = 9, ["name"] = "default:stone"}, {["x"] = 0, ["y"] = 0, ["param1"] = 78, ["z"] = 10, ["name"] = "default:stone"}, {["x"] = 0, ["y"] = 0, ["param1"] = 78, ["z"] = 11, ["name"] = "default:stone"}, {["x"] = 0, ["y"] = 0, ["param1"] = 78, ["z"] = 12, ["name"] = "default:stone"}, {["x"] = 0, ["y"] = 0, ["param1"] = 78, ["z"] = 13, ["name"] = "default:stone"}, {["x"] = 0, ["y"] = 0, ["param1"] = 78, ["z"] = 14, ["name"] = "default:stone"}, {["x"] = 0, ["y"] = 0, ["param1"] = 78, ["z"] = 15, ["name"] = "default:stone"}, {["x"] = 0, ["y"] = 0, ["param1"] = 78, ["z"] = 16, ["name"] = "default:stone"}, {["x"] = 0, ["y"] = 0, ["param1"] = 78, ["z"] = 17, ["name"] = "default:stone"}, {["x"] = 0, ["y"] = 0, ["param1"] = 78, ["z"] = 18, ["name"] = "default:stone"}, {["x"] = 0, ["y"] = 0, ["param1"] = 78, ["z"] = 19, ["name"] = "default:stone"}, {["x"] = 0, ["y"] = 0, ["param1"] = 78, ["z"] = 20, ["name"] = "default:stone"}, {["x"] = 0, ["y"] = 0, ["param1"] = 62, ["z"] = 21, ["name"] = "default:stone"}, {["x"] = 0, ["y"] = 0, ["z"] = 22, ["name"] = "default:dirt"}, {["x"] = 0, ["y"] = 1, ["z"] = 0, ["name"] = "default:dirt_with_grass"}, {["x"] = 0, ["y"] = 1, ["z"] = 1, ["name"] = "default:dirt_with_grass"}, {["x"] = 0, ["y"] = 1, ["z"] = 2, ["name"] = "default:dirt_with_grass"}, {["x"] = 0, ["y"] = 1, ["z"] = 3, ["name"] = "default:dirt_with_grass"}, {["x"] = 0, ["y"] = 1, ["z"] = 4, ["name"] = "default:dirt_with_grass"}, {["x"] = 0, ["y"] = 1, ["z"] = 5, ["name"] = "default:dirt_with_grass"}, {["x"] = 0, ["y"] = 1, ["z"] = 6, ["name"] = "default:dirt_with_grass"}, {["x"] = 0, ["y"] = 1, ["z"] = 7, ["name"] = "default:dirt_with_grass"}, {["x"] = 0, ["y"] = 1, ["z"] = 8, ["name"] = "default:dirt_with_grass"}, {["x"] = 0, ["y"] = 1, ["z"] = 9, ["name"] = "default:silver_sandstone"}, {["x"] = 0, ["param2"] = 1, ["y"] = 1, ["param1"] = 14, ["z"] = 10, ["name"] = "stairs:stair_silver_sandstone"}, {["x"] = 0, ["param2"] = 1, ["y"] = 1, ["param1"] = 14, ["z"] = 11, ["name"] = "stairs:stair_silver_sandstone"}, {["x"] = 0, ["y"] = 1, ["z"] = 12, ["name"] = "default:silver_sandstone"}, {["x"] = 0, ["y"] = 1, ["z"] = 13, ["name"] = "default:dirt_with_grass"}, {["x"] = 0, ["y"] = 1, ["z"] = 14, ["name"] = "default:dirt_with_grass"}, {["x"] = 0, ["y"] = 1, ["z"] = 15, ["name"] = "default:dirt_with_grass"}, {["x"] = 0, ["y"] = 1, ["z"] = 16, ["name"] = "default:dirt_with_grass"}, {["x"] = 0, ["y"] = 1, ["z"] = 17, ["name"] = "default:dirt_with_grass"}, {["x"] = 0, ["y"] = 1, ["z"] = 18, ["name"] = "default:dirt_with_grass"}, {["x"] = 0, ["y"] = 1, ["z"] = 19, ["name"] = "default:dirt_with_grass"}, {["x"] = 0, ["y"] = 1, ["z"] = 20, ["name"] = "default:dirt_with_grass"}, {["x"] = 0, ["y"] = 1, ["z"] = 21, ["name"] = "default:dirt_with_grass"}, {["x"] = 0, ["y"] = 1, ["z"] = 22, ["name"] = "default:dirt_with_grass"}, {["x"] = 1, ["y"] = 0, ["param1"] = 30, ["z"] = 0, ["name"] = "default:stone"}, {["x"] = 1, ["y"] = 0, ["param1"] = 45, ["z"] = 1, ["name"] = "default:stone"}, {["x"] = 1, ["y"] = 0, ["param1"] = 61, ["z"] = 2, ["name"] = "default:stone"}, {["x"] = 1, ["y"] = 0, ["param1"] = 77, ["z"] = 3, ["name"] = "default:stone"}, {["x"] = 1, ["y"] = 0, ["param1"] = 93, ["z"] = 4, ["name"] = "default:stone"}, {["x"] = 1, ["y"] = 0, ["param1"] = 93, ["z"] = 5, ["name"] = "default:stone"}, {["x"] = 1, ["y"] = 0, ["param1"] = 93, ["z"] = 6, ["name"] = "default:stone"}, {["x"] = 1, ["y"] = 0, ["param1"] = 93, ["z"] = 7, ["name"] = "default:stone"}, {["x"] = 1, ["y"] = 0, ["param1"] = 93, ["z"] = 8, ["name"] = "default:stone"}, {["x"] = 1, ["y"] = 0, ["param1"] = 93, ["z"] = 9, ["name"] = "default:stone"}, {["x"] = 1, ["y"] = 0, ["param1"] = 93, ["z"] = 10, ["name"] = "default:stone"}, {["x"] = 1, ["y"] = 0, ["param1"] = 93, ["z"] = 11, ["name"] = "default:stone"}, {["x"] = 1, ["y"] = 0, ["param1"] = 93, ["z"] = 12, ["name"] = "default:stone"}, {["x"] = 1, ["y"] = 0, ["param1"] = 93, ["z"] = 13, ["name"] = "default:stone"}, {["x"] = 1, ["y"] = 0, ["param1"] = 93, ["z"] = 14, ["name"] = "default:stone"}, {["x"] = 1, ["y"] = 0, ["param1"] = 93, ["z"] = 15, ["name"] = "default:stone"}, {["x"] = 1, ["y"] = 0, ["param1"] = 93, ["z"] = 16, ["name"] = "default:stone"}, {["x"] = 1, ["y"] = 0, ["param1"] = 93, ["z"] = 17, ["name"] = "default:stone"}, {["x"] = 1, ["y"] = 0, ["param1"] = 93, ["z"] = 18, ["name"] = "default:stone"}, {["x"] = 1, ["y"] = 0, ["param1"] = 93, ["z"] = 19, ["name"] = "default:stone"}, {["x"] = 1, ["y"] = 0, ["param1"] = 93, ["z"] = 20, ["name"] = "default:stone"}, {["x"] = 1, ["y"] = 0, ["param1"] = 77, ["z"] = 21, ["name"] = "default:stone"}, {["x"] = 1, ["y"] = 0, ["param1"] = 62, ["z"] = 22, ["name"] = "default:stone"}, {["x"] = 1, ["y"] = 1, ["z"] = 0, ["name"] = "default:dirt_with_grass"}, {["x"] = 1, ["y"] = 1, ["z"] = 1, ["name"] = "default:dirt_with_grass"}, {["x"] = 1, ["y"] = 1, ["z"] = 2, ["name"] = "default:dirt_with_grass"}, {["x"] = 1, ["y"] = 1, ["z"] = 3, ["name"] = "default:dirt_with_grass"}, {["x"] = 1, ["y"] = 1, ["z"] = 4, ["name"] = "default:dirt_with_grass"}, {["x"] = 1, ["y"] = 1, ["z"] = 5, ["name"] = "default:dirt_with_grass"}, {["x"] = 1, ["y"] = 1, ["z"] = 6, ["name"] = "default:dirt_with_grass"}, {["x"] = 1, ["y"] = 1, ["z"] = 7, ["name"] = "default:dirt_with_grass"}, {["x"] = 1, ["y"] = 1, ["z"] = 8, ["name"] = "default:dirt_with_grass"}, {["x"] = 1, ["y"] = 1, ["z"] = 9, ["name"] = "default:silver_sandstone"}, {["x"] = 1, ["y"] = 1, ["z"] = 10, ["name"] = "default:stonebrick"}, {["x"] = 1, ["y"] = 1, ["z"] = 11, ["name"] = "default:stonebrick"}, {["x"] = 1, ["y"] = 1, ["z"] = 12, ["name"] = "default:silver_sandstone"}, {["x"] = 1, ["y"] = 1, ["z"] = 13, ["name"] = "default:dirt_with_grass"}, {["x"] = 1, ["y"] = 1, ["z"] = 14, ["name"] = "default:dirt_with_grass"}, {["x"] = 1, ["y"] = 1, ["z"] = 15, ["name"] = "default:dirt_with_grass"}, {["x"] = 1, ["y"] = 1, ["z"] = 16, ["name"] = "default:dirt_with_grass"}, {["x"] = 1, ["y"] = 1, ["z"] = 17, ["name"] = "default:dirt_with_grass"}, {["x"] = 1, ["y"] = 1, ["z"] = 18, ["name"] = "default:dirt_with_grass"}, {["x"] = 1, ["y"] = 1, ["z"] = 19, ["name"] = "default:dirt_with_grass"}, {["x"] = 1, ["y"] = 1, ["z"] = 20, ["name"] = "default:dirt_with_grass"}, {["x"] = 1, ["y"] = 1, ["z"] = 21, ["name"] = "default:dirt_with_grass"}, {["x"] = 1, ["y"] = 1, ["z"] = 22, ["name"] = "default:dirt_with_grass"}, {["x"] = 2, ["y"] = 0, ["param1"] = 46, ["z"] = 0, ["name"] = "default:stone"}, {["x"] = 2, ["y"] = 0, ["param1"] = 61, ["z"] = 1, ["name"] = "default:stone"}, {["x"] = 2, ["y"] = 0, ["param1"] = 76, ["z"] = 2, ["name"] = "default:stone"}, {["x"] = 2, ["y"] = 0, ["param1"] = 92, ["z"] = 3, ["name"] = "default:stone"}, {["x"] = 2, ["y"] = 0, ["param1"] = 108, ["z"] = 4, ["name"] = "default:stone"}, {["x"] = 2, ["y"] = 0, ["param1"] = 108, ["z"] = 5, ["name"] = "default:stone"}, {["x"] = 2, ["y"] = 0, ["param1"] = 108, ["z"] = 6, ["name"] = "default:stone"}, {["x"] = 2, ["y"] = 0, ["param1"] = 108, ["z"] = 7, ["name"] = "default:stone"}, {["x"] = 2, ["y"] = 0, ["param1"] = 108, ["z"] = 8, ["name"] = "default:stone"}, {["x"] = 2, ["y"] = 0, ["param1"] = 108, ["z"] = 9, ["name"] = "default:stone"}, {["x"] = 2, ["y"] = 0, ["param1"] = 108, ["z"] = 10, ["name"] = "default:stone"}, {["x"] = 2, ["y"] = 0, ["param1"] = 108, ["z"] = 11, ["name"] = "default:stone"}, {["x"] = 2, ["y"] = 0, ["param1"] = 108, ["z"] = 12, ["name"] = "default:stone"}, {["x"] = 2, ["y"] = 0, ["param1"] = 108, ["z"] = 13, ["name"] = "default:stone"}, {["x"] = 2, ["y"] = 0, ["param1"] = 108, ["z"] = 14, ["name"] = "default:stone"}, {["x"] = 2, ["y"] = 0, ["param1"] = 108, ["z"] = 15, ["name"] = "default:stone"}, {["x"] = 2, ["y"] = 0, ["param1"] = 108, ["z"] = 16, ["name"] = "default:stone"}, {["x"] = 2, ["y"] = 0, ["param1"] = 108, ["z"] = 17, ["name"] = "default:stone"}, {["x"] = 2, ["y"] = 0, ["param1"] = 108, ["z"] = 18, ["name"] = "default:stone"}, {["x"] = 2, ["y"] = 0, ["param1"] = 108, ["z"] = 19, ["name"] = "default:stone"}, {["x"] = 2, ["y"] = 0, ["param1"] = 108, ["z"] = 20, ["name"] = "default:stone"}, {["x"] = 2, ["y"] = 0, ["param1"] = 93, ["z"] = 21, ["name"] = "default:stone"}, {["x"] = 2, ["y"] = 0, ["param1"] = 78, ["z"] = 22, ["name"] = "default:stone"}, {["x"] = 2, ["y"] = 1, ["z"] = 0, ["name"] = "default:dirt_with_grass"}, {["x"] = 2, ["y"] = 1, ["z"] = 1, ["name"] = "default:dirt_with_grass"}, {["x"] = 2, ["y"] = 1, ["z"] = 2, ["name"] = "default:dirt_with_grass"}, {["x"] = 2, ["y"] = 1, ["z"] = 3, ["name"] = "default:dirt_with_grass"}, {["x"] = 2, ["y"] = 1, ["z"] = 4, ["name"] = "default:dirt_with_grass"}, {["x"] = 2, ["y"] = 1, ["z"] = 5, ["name"] = "default:dirt_with_grass"}, {["x"] = 2, ["y"] = 1, ["z"] = 6, ["name"] = "default:dirt_with_grass"}, {["x"] = 2, ["y"] = 1, ["z"] = 7, ["name"] = "default:dirt_with_grass"}, {["x"] = 2, ["y"] = 1, ["z"] = 8, ["name"] = "default:dirt_with_grass"}, {["x"] = 2, ["y"] = 1, ["z"] = 9, ["name"] = "default:silver_sandstone"}, {["x"] = 2, ["y"] = 1, ["z"] = 10, ["name"] = "default:stonebrick"}, {["x"] = 2, ["y"] = 1, ["z"] = 11, ["name"] = "default:stonebrick"}, {["x"] = 2, ["y"] = 1, ["z"] = 12, ["name"] = "default:silver_sandstone"}, {["x"] = 2, ["y"] = 1, ["z"] = 13, ["name"] = "default:dirt_with_grass"}, {["x"] = 2, ["y"] = 1, ["z"] = 14, ["name"] = "default:dirt_with_grass"}, {["x"] = 2, ["y"] = 1, ["z"] = 15, ["name"] = "default:dirt_with_grass"}, {["x"] = 2, ["y"] = 1, ["z"] = 16, ["name"] = "default:dirt_with_grass"}, {["x"] = 2, ["y"] = 1, ["z"] = 17, ["name"] = "default:dirt_with_grass"}, {["x"] = 2, ["y"] = 1, ["z"] = 18, ["name"] = "default:dirt_with_grass"}, {["x"] = 2, ["y"] = 1, ["z"] = 19, ["name"] = "default:dirt_with_grass"}, {["x"] = 2, ["y"] = 1, ["z"] = 20, ["name"] = "default:dirt_with_grass"}, {["x"] = 2, ["y"] = 1, ["z"] = 21, ["name"] = "default:dirt_with_grass"}, {["x"] = 2, ["y"] = 1, ["z"] = 22, ["name"] = "default:dirt_with_grass"}, {["x"] = 3, ["y"] = 0, ["param1"] = 62, ["z"] = 0, ["name"] = "default:stone"}, {["x"] = 3, ["y"] = 0, ["param1"] = 77, ["z"] = 1, ["name"] = "default:stone"}, {["x"] = 3, ["y"] = 0, ["param1"] = 92, ["z"] = 2, ["name"] = "default:stone"}, {["x"] = 3, ["y"] = 0, ["param1"] = 107, ["z"] = 3, ["name"] = "default:stone"}, {["x"] = 3, ["y"] = 0, ["param1"] = 123, ["z"] = 4, ["name"] = "default:stone"}, {["x"] = 3, ["y"] = 0, ["param1"] = 123, ["z"] = 5, ["name"] = "default:stone"}, {["x"] = 3, ["y"] = 0, ["param1"] = 123, ["z"] = 6, ["name"] = "default:stone"}, {["x"] = 3, ["y"] = 0, ["param1"] = 123, ["z"] = 7, ["name"] = "default:stone"}, {["x"] = 3, ["y"] = 0, ["param1"] = 123, ["z"] = 8, ["name"] = "default:stone"}, {["x"] = 3, ["y"] = 0, ["param1"] = 123, ["z"] = 9, ["name"] = "default:stone"}, {["x"] = 3, ["y"] = 0, ["param1"] = 123, ["z"] = 10, ["name"] = "default:stone"}, {["x"] = 3, ["y"] = 0, ["param1"] = 123, ["z"] = 11, ["name"] = "default:stone"}, {["x"] = 3, ["y"] = 0, ["param1"] = 123, ["z"] = 12, ["name"] = "default:stone"}, {["x"] = 3, ["y"] = 0, ["param1"] = 123, ["z"] = 13, ["name"] = "default:stone"}, {["x"] = 3, ["y"] = 0, ["param1"] = 123, ["z"] = 14, ["name"] = "default:stone"}, {["x"] = 3, ["y"] = 0, ["param1"] = 123, ["z"] = 15, ["name"] = "default:stone"}, {["x"] = 3, ["y"] = 0, ["param1"] = 123, ["z"] = 16, ["name"] = "default:stone"}, {["x"] = 3, ["y"] = 0, ["param1"] = 123, ["z"] = 17, ["name"] = "default:stone"}, {["x"] = 3, ["y"] = 0, ["param1"] = 123, ["z"] = 18, ["name"] = "default:stone"}, {["x"] = 3, ["y"] = 0, ["param1"] = 123, ["z"] = 19, ["name"] = "default:stone"}, {["x"] = 3, ["y"] = 0, ["param1"] = 124, ["z"] = 20, ["name"] = "default:stone"}, {["x"] = 3, ["y"] = 0, ["param1"] = 109, ["z"] = 21, ["name"] = "default:stone"}, {["x"] = 3, ["y"] = 0, ["param1"] = 94, ["z"] = 22, ["name"] = "default:stone"}, {["x"] = 3, ["y"] = 1, ["z"] = 0, ["name"] = "default:dirt_with_grass"}, {["x"] = 3, ["y"] = 1, ["z"] = 1, ["name"] = "default:dirt_with_grass"}, {["x"] = 3, ["y"] = 1, ["z"] = 2, ["name"] = "default:dirt_with_grass"}, {["x"] = 3, ["y"] = 1, ["z"] = 3, ["name"] = "default:dirt_with_grass"}, {["x"] = 3, ["y"] = 1, ["z"] = 4, ["name"] = "default:dirt_with_grass"}, {["x"] = 3, ["y"] = 1, ["z"] = 5, ["name"] = "default:dirt_with_grass"}, {["x"] = 3, ["y"] = 1, ["z"] = 6, ["name"] = "default:dirt_with_grass"}, {["x"] = 3, ["y"] = 1, ["z"] = 7, ["name"] = "default:dirt_with_grass"}, {["x"] = 3, ["y"] = 1, ["z"] = 8, ["name"] = "default:dirt_with_grass"}, {["x"] = 3, ["y"] = 1, ["z"] = 9, ["name"] = "default:silver_sandstone"}, {["x"] = 3, ["y"] = 1, ["z"] = 10, ["name"] = "default:stonebrick"}, {["x"] = 3, ["y"] = 1, ["z"] = 11, ["name"] = "default:stonebrick"}, {["x"] = 3, ["y"] = 1, ["z"] = 12, ["name"] = "default:silver_sandstone"}, {["x"] = 3, ["y"] = 1, ["z"] = 13, ["name"] = "default:dirt_with_grass"}, {["x"] = 3, ["y"] = 1, ["z"] = 14, ["name"] = "default:dirt_with_grass"}, {["x"] = 3, ["y"] = 1, ["z"] = 15, ["name"] = "default:dirt_with_grass"}, {["x"] = 3, ["y"] = 1, ["z"] = 16, ["name"] = "default:dirt_with_grass"}, {["x"] = 3, ["y"] = 1, ["z"] = 17, ["name"] = "default:dirt_with_grass"}, {["x"] = 3, ["y"] = 1, ["z"] = 18, ["name"] = "default:dirt_with_grass"}, {["x"] = 3, ["y"] = 1, ["z"] = 19, ["name"] = "default:dirt_with_grass"}, {["x"] = 3, ["y"] = 1, ["z"] = 20, ["name"] = "default:dirt_with_grass"}, {["x"] = 3, ["y"] = 1, ["z"] = 21, ["name"] = "default:dirt_with_grass"}, {["x"] = 3, ["y"] = 1, ["z"] = 22, ["name"] = "default:dirt_with_grass"}, {["x"] = 3, ["y"] = 2, ["param1"] = 78, ["z"] = 6, ["name"] = "stairs:slab_silver_sandstone"}, {["x"] = 3, ["y"] = 2, ["param1"] = 79, ["z"] = 7, ["name"] = "default:grass_2"}, {["x"] = 3, ["y"] = 2, ["param1"] = 63, ["z"] = 21, ["name"] = "default:grass_1"}, {["x"] = 4, ["y"] = 0, ["param1"] = 78, ["z"] = 0, ["name"] = "default:stone"}, {["x"] = 4, ["y"] = 0, ["param1"] = 93, ["z"] = 1, ["name"] = "default:stone"}, {["x"] = 4, ["y"] = 0, ["param1"] = 108, ["z"] = 2, ["name"] = "default:stone"}, {["x"] = 4, ["y"] = 0, ["param1"] = 123, ["z"] = 3, ["name"] = "default:stone"}, {["x"] = 4, ["y"] = 0, ["param1"] = 138, ["z"] = 4, ["name"] = "default:stone"}, {["x"] = 4, ["y"] = 0, ["param1"] = 138, ["z"] = 5, ["name"] = "default:stone"}, {["x"] = 4, ["y"] = 0, ["param1"] = 138, ["z"] = 6, ["name"] = "default:stone"}, {["x"] = 4, ["y"] = 0, ["param1"] = 138, ["z"] = 7, ["name"] = "default:stone"}, {["x"] = 4, ["y"] = 0, ["param1"] = 138, ["z"] = 8, ["name"] = "default:stone"}, {["x"] = 4, ["y"] = 0, ["param1"] = 138, ["z"] = 9, ["name"] = "default:stone"}, {["x"] = 4, ["y"] = 0, ["param1"] = 138, ["z"] = 10, ["name"] = "default:stone"}, {["x"] = 4, ["y"] = 0, ["param1"] = 138, ["z"] = 11, ["name"] = "default:stone"}, {["x"] = 4, ["y"] = 0, ["param1"] = 138, ["z"] = 12, ["name"] = "default:stone"}, {["x"] = 4, ["y"] = 0, ["param1"] = 138, ["z"] = 13, ["name"] = "default:stone"}, {["x"] = 4, ["y"] = 0, ["param1"] = 138, ["z"] = 14, ["name"] = "default:stone"}, {["x"] = 4, ["y"] = 0, ["param1"] = 138, ["z"] = 15, ["name"] = "default:stone"}, {["x"] = 4, ["y"] = 0, ["param1"] = 138, ["z"] = 16, ["name"] = "default:stone"}, {["x"] = 4, ["y"] = 0, ["param1"] = 138, ["z"] = 17, ["name"] = "default:stone"}, {["x"] = 4, ["y"] = 0, ["param1"] = 138, ["z"] = 18, ["name"] = "default:stone"}, {["x"] = 4, ["y"] = 0, ["param1"] = 139, ["z"] = 19, ["name"] = "default:stone"}, {["x"] = 4, ["y"] = 0, ["param1"] = 140, ["z"] = 20, ["name"] = "default:stone"}, {["x"] = 4, ["y"] = 0, ["param1"] = 125, ["z"] = 21, ["name"] = "default:stone"}, {["x"] = 4, ["y"] = 0, ["param1"] = 110, ["z"] = 22, ["name"] = "default:stone"}, {["x"] = 4, ["y"] = 1, ["z"] = 0, ["name"] = "default:dirt_with_grass"}, {["x"] = 4, ["y"] = 1, ["z"] = 1, ["name"] = "default:dirt_with_grass"}, {["x"] = 4, ["y"] = 1, ["z"] = 2, ["name"] = "default:dirt_with_grass"}, {["x"] = 4, ["y"] = 1, ["z"] = 3, ["name"] = "default:dirt_with_grass"}, {["x"] = 4, ["y"] = 1, ["z"] = 4, ["name"] = "default:dirt_with_grass"}, {["x"] = 4, ["y"] = 1, ["z"] = 5, ["name"] = "default:dirt_with_grass"}, {["x"] = 4, ["y"] = 1, ["z"] = 6, ["name"] = "default:dirt_with_grass"}, {["x"] = 4, ["y"] = 1, ["z"] = 7, ["name"] = "default:dirt_with_grass"}, {["x"] = 4, ["y"] = 1, ["z"] = 8, ["name"] = "default:dirt_with_grass"}, {["x"] = 4, ["y"] = 1, ["z"] = 9, ["name"] = "default:silver_sandstone"}, {["x"] = 4, ["y"] = 1, ["z"] = 10, ["name"] = "default:stonebrick"}, {["x"] = 4, ["y"] = 1, ["z"] = 11, ["name"] = "default:stonebrick"}, {["x"] = 4, ["y"] = 1, ["z"] = 12, ["name"] = "default:silver_sandstone"}, {["x"] = 4, ["y"] = 1, ["z"] = 13, ["name"] = "default:silver_sandstone"}, {["x"] = 4, ["y"] = 1, ["z"] = 14, ["name"] = "default:silver_sandstone"}, {["x"] = 4, ["y"] = 1, ["z"] = 15, ["name"] = "default:silver_sandstone"}, {["x"] = 4, ["y"] = 1, ["z"] = 16, ["name"] = "default:silver_sandstone"}, {["x"] = 4, ["y"] = 1, ["z"] = 17, ["name"] = "default:silver_sandstone"}, {["x"] = 4, ["y"] = 1, ["z"] = 18, ["name"] = "default:silver_sandstone"}, {["x"] = 4, ["y"] = 1, ["z"] = 19, ["name"] = "default:silver_sandstone"}, {["x"] = 4, ["y"] = 1, ["z"] = 20, ["name"] = "default:silver_sandstone"}, {["x"] = 4, ["y"] = 1, ["z"] = 21, ["name"] = "default:silver_sandstone"}, {["x"] = 4, ["y"] = 1, ["z"] = 22, ["name"] = "default:dirt_with_grass"}, {["x"] = 4, ["y"] = 2, ["param1"] = 95, ["z"] = 5, ["name"] = "default:grass_1"}, {["x"] = 5, ["y"] = 0, ["param1"] = 94, ["z"] = 0, ["name"] = "default:stone"}, {["x"] = 5, ["y"] = 0, ["param1"] = 109, ["z"] = 1, ["name"] = "default:stone"}, {["x"] = 5, ["y"] = 0, ["param1"] = 124, ["z"] = 2, ["name"] = "default:stone"}, {["x"] = 5, ["y"] = 0, ["param1"] = 139, ["z"] = 3, ["name"] = "default:stone"}, {["x"] = 5, ["y"] = 0, ["param1"] = 154, ["z"] = 4, ["name"] = "default:stone"}, {["x"] = 5, ["y"] = 0, ["param1"] = 153, ["z"] = 5, ["name"] = "default:stone"}, {["x"] = 5, ["y"] = 0, ["param1"] = 153, ["z"] = 6, ["name"] = "default:stone"}, {["x"] = 5, ["y"] = 0, ["param1"] = 153, ["z"] = 7, ["name"] = "default:stone"}, {["x"] = 5, ["y"] = 0, ["param1"] = 153, ["z"] = 8, ["name"] = "default:stone"}, {["x"] = 5, ["y"] = 0, ["param1"] = 153, ["z"] = 9, ["name"] = "default:stone"}, {["x"] = 5, ["y"] = 0, ["param1"] = 153, ["z"] = 10, ["name"] = "default:stone"}, {["x"] = 5, ["y"] = 0, ["param1"] = 153, ["z"] = 11, ["name"] = "default:stone"}, {["x"] = 5, ["y"] = 0, ["param1"] = 153, ["z"] = 12, ["name"] = "default:stone"}, {["x"] = 5, ["y"] = 0, ["param1"] = 153, ["z"] = 13, ["name"] = "default:stone"}, {["x"] = 5, ["y"] = 0, ["param1"] = 153, ["z"] = 14, ["name"] = "default:stone"}, {["x"] = 5, ["y"] = 0, ["param1"] = 153, ["z"] = 15, ["name"] = "default:stone"}, {["x"] = 5, ["y"] = 0, ["param1"] = 153, ["z"] = 16, ["name"] = "default:stone"}, {["x"] = 5, ["y"] = 0, ["param1"] = 153, ["z"] = 17, ["name"] = "default:stone"}, {["x"] = 5, ["y"] = 0, ["param1"] = 154, ["z"] = 18, ["name"] = "default:stone"}, {["x"] = 5, ["y"] = 0, ["param1"] = 155, ["z"] = 19, ["name"] = "default:stone"}, {["x"] = 5, ["y"] = 0, ["param1"] = 156, ["z"] = 20, ["name"] = "default:stone"}, {["x"] = 5, ["y"] = 0, ["param1"] = 141, ["z"] = 21, ["name"] = "default:stone"}, {["x"] = 5, ["y"] = 0, ["param1"] = 126, ["z"] = 22, ["name"] = "default:stone"}, {["x"] = 5, ["y"] = 1, ["z"] = 0, ["name"] = "default:dirt_with_grass"}, {["x"] = 5, ["y"] = 1, ["z"] = 1, ["name"] = "default:dirt_with_grass"}, {["x"] = 5, ["y"] = 1, ["z"] = 2, ["name"] = "default:dirt_with_grass"}, {["x"] = 5, ["y"] = 1, ["z"] = 3, ["name"] = "default:dirt_with_grass"}, {["x"] = 5, ["param2"] = 1, ["y"] = 1, ["z"] = 4, ["name"] = "default:silver_sandstone"}, {["x"] = 5, ["y"] = 1, ["z"] = 5, ["name"] = "default:dirt_with_grass"}, {["x"] = 5, ["y"] = 1, ["z"] = 6, ["name"] = "default:dirt_with_grass"}, {["x"] = 5, ["y"] = 1, ["z"] = 7, ["name"] = "default:dirt_with_grass"}, {["x"] = 5, ["y"] = 1, ["z"] = 8, ["name"] = "default:dirt_with_grass"}, {["x"] = 5, ["y"] = 1, ["z"] = 9, ["name"] = "default:silver_sandstone"}, {["x"] = 5, ["y"] = 1, ["z"] = 10, ["name"] = "default:stonebrick"}, {["x"] = 5, ["y"] = 1, ["z"] = 11, ["name"] = "default:stonebrick"}, {["x"] = 5, ["y"] = 1, ["z"] = 12, ["name"] = "default:stonebrick"}, {["x"] = 5, ["y"] = 1, ["z"] = 13, ["name"] = "default:stonebrick"}, {["x"] = 5, ["y"] = 1, ["z"] = 14, ["name"] = "default:stonebrick"}, {["x"] = 5, ["y"] = 1, ["z"] = 15, ["name"] = "default:stonebrick"}, {["x"] = 5, ["y"] = 1, ["z"] = 16, ["name"] = "default:stonebrick"}, {["x"] = 5, ["y"] = 1, ["z"] = 17, ["name"] = "default:stonebrick"}, {["x"] = 5, ["y"] = 1, ["z"] = 18, ["name"] = "default:stonebrick"}, {["x"] = 5, ["y"] = 1, ["z"] = 19, ["name"] = "default:stonebrick"}, {["x"] = 5, ["y"] = 1, ["z"] = 20, ["name"] = "default:stonebrick"}, {["x"] = 5, ["y"] = 1, ["z"] = 21, ["name"] = "default:silver_sandstone"}, {["x"] = 5, ["y"] = 1, ["z"] = 22, ["name"] = "default:dirt_with_grass"}, {["x"] = 5, ["param2"] = 1, ["y"] = 2, ["param1"] = 94, ["z"] = 4, ["name"] = "stairs:slab_silver_sandstone"}, {["x"] = 5, ["y"] = 2, ["param1"] = 111, ["z"] = 5, ["name"] = "default:grass_2"}, {["x"] = 5, ["y"] = 2, ["param1"] = 111, ["z"] = 7, ["name"] = "default:grass_2"}, {["x"] = 5, ["y"] = 2, ["param1"] = 111, ["z"] = 8, ["name"] = "default:grass_2"}, {["x"] = 6, ["y"] = 0, ["param1"] = 110, ["z"] = 0, ["name"] = "default:stone"}, {["x"] = 6, ["y"] = 0, ["param1"] = 125, ["z"] = 1, ["name"] = "default:stone"}, {["x"] = 6, ["y"] = 0, ["param1"] = 140, ["z"] = 2, ["name"] = "default:stone"}, {["x"] = 6, ["y"] = 0, ["param1"] = 155, ["z"] = 3, ["name"] = "default:stone"}, {["x"] = 6, ["y"] = 0, ["param1"] = 170, ["z"] = 4, ["name"] = "default:stone"}, {["x"] = 6, ["y"] = 0, ["param1"] = 170, ["z"] = 5, ["name"] = "default:stone"}, {["x"] = 6, ["y"] = 0, ["param1"] = 170, ["z"] = 6, ["name"] = "default:stone"}, {["x"] = 6, ["y"] = 0, ["param1"] = 170, ["z"] = 7, ["name"] = "default:stone"}, {["x"] = 6, ["y"] = 0, ["param1"] = 170, ["z"] = 8, ["name"] = "default:stone"}, {["x"] = 6, ["y"] = 0, ["param1"] = 170, ["z"] = 9, ["name"] = "default:stone"}, {["x"] = 6, ["y"] = 0, ["param1"] = 170, ["z"] = 10, ["name"] = "default:stone"}, {["x"] = 6, ["y"] = 0, ["param1"] = 170, ["z"] = 11, ["name"] = "default:stone"}, {["x"] = 6, ["y"] = 0, ["param1"] = 170, ["z"] = 12, ["name"] = "default:stone"}, {["x"] = 6, ["y"] = 0, ["param1"] = 170, ["z"] = 13, ["name"] = "default:stone"}, {["x"] = 6, ["y"] = 0, ["param1"] = 170, ["z"] = 14, ["name"] = "default:stone"}, {["x"] = 6, ["y"] = 0, ["param1"] = 170, ["z"] = 15, ["name"] = "default:stone"}, {["x"] = 6, ["y"] = 0, ["param1"] = 170, ["z"] = 16, ["name"] = "default:stone"}, {["x"] = 6, ["y"] = 0, ["param1"] = 170, ["z"] = 17, ["name"] = "default:stone"}, {["x"] = 6, ["y"] = 0, ["param1"] = 170, ["z"] = 18, ["name"] = "default:stone"}, {["x"] = 6, ["y"] = 0, ["param1"] = 171, ["z"] = 19, ["name"] = "default:stone"}, {["x"] = 6, ["y"] = 0, ["param1"] = 172, ["z"] = 20, ["name"] = "default:stone"}, {["x"] = 6, ["y"] = 0, ["param1"] = 157, ["z"] = 21, ["name"] = "default:stone"}, {["x"] = 6, ["y"] = 0, ["param1"] = 142, ["z"] = 22, ["name"] = "default:stone"}, {["x"] = 6, ["y"] = 1, ["z"] = 0, ["name"] = "default:dirt_with_grass"}, {["x"] = 6, ["y"] = 1, ["z"] = 1, ["name"] = "default:dirt_with_grass"}, {["x"] = 6, ["y"] = 1, ["z"] = 2, ["name"] = "default:dirt_with_grass"}, {["x"] = 6, ["y"] = 1, ["z"] = 3, ["name"] = "default:dirt_with_grass"}, {["x"] = 6, ["y"] = 1, ["z"] = 4, ["name"] = "default:dirt_with_grass"}, {["x"] = 6, ["y"] = 1, ["z"] = 5, ["name"] = "default:dirt_with_grass"}, {["x"] = 6, ["y"] = 1, ["z"] = 6, ["name"] = "default:dirt_with_grass"}, {["x"] = 6, ["y"] = 1, ["z"] = 7, ["name"] = "default:dirt_with_grass"}, {["x"] = 6, ["y"] = 1, ["z"] = 8, ["name"] = "default:dirt_with_grass"}, {["x"] = 6, ["y"] = 1, ["z"] = 9, ["name"] = "default:silver_sandstone"}, {["x"] = 6, ["y"] = 1, ["z"] = 10, ["name"] = "default:stonebrick"}, {["x"] = 6, ["y"] = 1, ["z"] = 11, ["name"] = "default:stonebrick"}, {["x"] = 6, ["y"] = 1, ["z"] = 12, ["name"] = "default:stonebrick"}, {["x"] = 6, ["y"] = 1, ["z"] = 13, ["name"] = "default:stonebrick"}, {["x"] = 6, ["y"] = 1, ["z"] = 14, ["name"] = "default:stonebrick"}, {["x"] = 6, ["y"] = 1, ["z"] = 15, ["name"] = "default:stonebrick"}, {["x"] = 6, ["y"] = 1, ["z"] = 16, ["name"] = "default:stonebrick"}, {["x"] = 6, ["y"] = 1, ["z"] = 17, ["name"] = "default:stonebrick"}, {["x"] = 6, ["y"] = 1, ["z"] = 18, ["name"] = "default:stonebrick"}, {["x"] = 6, ["y"] = 1, ["z"] = 19, ["name"] = "default:stonebrick"}, {["x"] = 6, ["y"] = 1, ["z"] = 20, ["name"] = "default:stonebrick"}, {["x"] = 6, ["y"] = 1, ["z"] = 21, ["name"] = "default:silver_sandstone"}, {["x"] = 6, ["y"] = 1, ["z"] = 22, ["name"] = "default:dirt_with_grass"}, {["x"] = 6, ["param2"] = 1, ["y"] = 2, ["param1"] = 126, ["z"] = 7, ["name"] = "stairs:slab_silver_sandstone"}, {["x"] = 7, ["y"] = 0, ["param1"] = 126, ["z"] = 0, ["name"] = "default:stone"}, {["x"] = 7, ["y"] = 0, ["param1"] = 141, ["z"] = 1, ["name"] = "default:stone"}, {["x"] = 7, ["y"] = 0, ["param1"] = 156, ["z"] = 2, ["name"] = "default:stone"}, {["x"] = 7, ["y"] = 0, ["param1"] = 171, ["z"] = 3, ["name"] = "default:stone"}, {["x"] = 7, ["y"] = 0, ["param1"] = 187, ["z"] = 4, ["name"] = "default:stone"}, {["x"] = 7, ["y"] = 0, ["param1"] = 187, ["z"] = 5, ["name"] = "default:stone"}, {["x"] = 7, ["y"] = 0, ["param1"] = 187, ["z"] = 6, ["name"] = "default:stone"}, {["x"] = 7, ["y"] = 0, ["param1"] = 187, ["z"] = 7, ["name"] = "default:stone"}, {["x"] = 7, ["y"] = 0, ["param1"] = 187, ["z"] = 8, ["name"] = "default:stone"}, {["x"] = 7, ["y"] = 0, ["param1"] = 187, ["z"] = 9, ["name"] = "default:stone"}, {["x"] = 7, ["y"] = 0, ["param1"] = 187, ["z"] = 10, ["name"] = "default:stone"}, {["x"] = 7, ["y"] = 0, ["param1"] = 187, ["z"] = 11, ["name"] = "default:stone"}, {["x"] = 7, ["y"] = 0, ["param1"] = 187, ["z"] = 12, ["name"] = "default:stone"}, {["x"] = 7, ["y"] = 0, ["param1"] = 187, ["z"] = 13, ["name"] = "default:stone"}, {["x"] = 7, ["y"] = 0, ["param1"] = 187, ["z"] = 14, ["name"] = "default:stone"}, {["x"] = 7, ["y"] = 0, ["param1"] = 187, ["z"] = 15, ["name"] = "default:stone"}, {["x"] = 7, ["y"] = 0, ["param1"] = 187, ["z"] = 16, ["name"] = "default:stone"}, {["x"] = 7, ["y"] = 0, ["param1"] = 187, ["z"] = 17, ["name"] = "default:stone"}, {["x"] = 7, ["y"] = 0, ["param1"] = 187, ["z"] = 18, ["name"] = "default:stone"}, {["x"] = 7, ["y"] = 0, ["param1"] = 187, ["z"] = 19, ["name"] = "default:stone"}, {["x"] = 7, ["y"] = 0, ["param1"] = 188, ["z"] = 20, ["name"] = "default:stone"}, {["x"] = 7, ["y"] = 0, ["param1"] = 173, ["z"] = 21, ["name"] = "default:stone"}, {["x"] = 7, ["y"] = 0, ["param1"] = 158, ["z"] = 22, ["name"] = "default:stone"}, {["x"] = 7, ["y"] = 1, ["z"] = 0, ["name"] = "default:dirt_with_grass"}, {["x"] = 7, ["y"] = 1, ["z"] = 1, ["name"] = "default:dirt_with_grass"}, {["x"] = 7, ["y"] = 1, ["z"] = 2, ["name"] = "default:dirt_with_grass"}, {["x"] = 7, ["y"] = 1, ["z"] = 3, ["name"] = "default:dirt_with_grass"}, {["x"] = 7, ["y"] = 1, ["z"] = 4, ["name"] = "default:dirt_with_grass"}, {["x"] = 7, ["y"] = 1, ["z"] = 5, ["name"] = "default:dirt_with_grass"}, {["x"] = 7, ["y"] = 1, ["z"] = 6, ["name"] = "default:dirt_with_grass"}, {["x"] = 7, ["y"] = 1, ["z"] = 7, ["name"] = "default:dirt_with_grass"}, {["x"] = 7, ["y"] = 1, ["z"] = 8, ["name"] = "default:dirt_with_grass"}, {["x"] = 7, ["y"] = 1, ["z"] = 9, ["name"] = "default:silver_sandstone"}, {["x"] = 7, ["y"] = 1, ["z"] = 10, ["name"] = "default:stonebrick"}, {["x"] = 7, ["y"] = 1, ["z"] = 11, ["name"] = "default:stonebrick"}, {["x"] = 7, ["y"] = 1, ["z"] = 12, ["name"] = "default:silver_sandstone"}, {["x"] = 7, ["y"] = 1, ["z"] = 13, ["name"] = "default:silver_sandstone"}, {["x"] = 7, ["y"] = 1, ["z"] = 14, ["name"] = "default:silver_sandstone"}, {["x"] = 7, ["y"] = 1, ["z"] = 15, ["name"] = "default:silver_sandstone"}, {["x"] = 7, ["y"] = 1, ["z"] = 16, ["name"] = "default:silver_sandstone"}, {["x"] = 7, ["y"] = 1, ["z"] = 17, ["name"] = "default:silver_sandstone"}, {["x"] = 7, ["y"] = 1, ["z"] = 18, ["name"] = "default:silver_sandstone"}, {["x"] = 7, ["y"] = 1, ["z"] = 19, ["name"] = "default:stonebrick"}, {["x"] = 7, ["y"] = 1, ["z"] = 20, ["name"] = "default:stonebrick"}, {["x"] = 7, ["y"] = 1, ["z"] = 21, ["name"] = "default:silver_sandstone"}, {["x"] = 7, ["y"] = 1, ["z"] = 22, ["name"] = "default:dirt_with_grass"}, {["x"] = 8, ["y"] = 0, ["param1"] = 142, ["z"] = 0, ["name"] = "default:stone"}, {["x"] = 8, ["y"] = 0, ["param1"] = 157, ["z"] = 1, ["name"] = "default:stone"}, {["x"] = 8, ["y"] = 0, ["param1"] = 172, ["z"] = 2, ["name"] = "default:stone"}, {["x"] = 8, ["y"] = 0, ["param1"] = 187, ["z"] = 3, ["name"] = "default:stone"}, {["x"] = 8, ["y"] = 0, ["param1"] = 204, ["z"] = 4, ["name"] = "default:stone"}, {["x"] = 8, ["y"] = 0, ["param1"] = 204, ["z"] = 5, ["name"] = "default:stone"}, {["x"] = 8, ["y"] = 0, ["param1"] = 204, ["z"] = 6, ["name"] = "default:stone"}, {["x"] = 8, ["y"] = 0, ["param1"] = 204, ["z"] = 7, ["name"] = "default:stone"}, {["x"] = 8, ["y"] = 0, ["param1"] = 204, ["z"] = 8, ["name"] = "default:stone"}, {["x"] = 8, ["y"] = 0, ["param1"] = 204, ["z"] = 9, ["name"] = "default:stone"}, {["x"] = 8, ["y"] = 0, ["param1"] = 204, ["z"] = 10, ["name"] = "default:stone"}, {["x"] = 8, ["y"] = 0, ["param1"] = 204, ["z"] = 11, ["name"] = "default:stone"}, {["x"] = 8, ["y"] = 0, ["param1"] = 204, ["z"] = 12, ["name"] = "default:stone"}, {["x"] = 8, ["y"] = 0, ["param1"] = 204, ["z"] = 13, ["name"] = "default:stone"}, {["x"] = 8, ["y"] = 0, ["param1"] = 204, ["z"] = 14, ["name"] = "default:stone"}, {["x"] = 8, ["y"] = 0, ["param1"] = 204, ["z"] = 15, ["name"] = "default:stone"}, {["x"] = 8, ["y"] = 0, ["param1"] = 204, ["z"] = 16, ["name"] = "default:stone"}, {["x"] = 8, ["y"] = 0, ["param1"] = 204, ["z"] = 17, ["name"] = "default:stone"}, {["x"] = 8, ["y"] = 0, ["param1"] = 204, ["z"] = 18, ["name"] = "default:stone"}, {["x"] = 8, ["y"] = 0, ["param1"] = 204, ["z"] = 19, ["name"] = "default:stone"}, {["x"] = 8, ["y"] = 0, ["param1"] = 204, ["z"] = 20, ["name"] = "default:stone"}, {["x"] = 8, ["y"] = 0, ["param1"] = 189, ["z"] = 21, ["name"] = "default:stone"}, {["x"] = 8, ["y"] = 0, ["param1"] = 174, ["z"] = 22, ["name"] = "default:stone"}, {["x"] = 8, ["y"] = 1, ["z"] = 0, ["name"] = "default:dirt_with_grass"}, {["x"] = 8, ["y"] = 1, ["z"] = 1, ["name"] = "default:dirt_with_grass"}, {["x"] = 8, ["y"] = 1, ["z"] = 2, ["name"] = "default:dirt_with_grass"}, {["x"] = 8, ["y"] = 1, ["z"] = 3, ["name"] = "default:dirt_with_grass"}, {["x"] = 8, ["y"] = 1, ["z"] = 4, ["name"] = "default:dirt_with_grass"}, {["x"] = 8, ["y"] = 1, ["z"] = 5, ["name"] = "default:dirt_with_grass"}, {["x"] = 8, ["y"] = 1, ["z"] = 6, ["name"] = "default:dirt_with_grass"}, {["x"] = 8, ["y"] = 1, ["z"] = 7, ["name"] = "default:dirt_with_grass"}, {["x"] = 8, ["y"] = 1, ["z"] = 8, ["name"] = "default:dirt_with_grass"}, {["x"] = 8, ["y"] = 1, ["z"] = 9, ["name"] = "default:silver_sandstone"}, {["x"] = 8, ["y"] = 1, ["z"] = 10, ["name"] = "default:stonebrick"}, {["x"] = 8, ["y"] = 1, ["z"] = 11, ["name"] = "default:stonebrick"}, {["x"] = 8, ["y"] = 1, ["z"] = 12, ["name"] = "default:silver_sandstone"}, {["x"] = 8, ["y"] = 1, ["z"] = 13, ["name"] = "default:dirt_with_grass"}, {["x"] = 8, ["y"] = 1, ["z"] = 14, ["name"] = "default:dirt_with_grass"}, {["x"] = 8, ["y"] = 1, ["z"] = 15, ["name"] = "default:dirt_with_grass"}, {["x"] = 8, ["y"] = 1, ["z"] = 16, ["name"] = "default:dirt_with_grass"}, {["x"] = 8, ["y"] = 1, ["z"] = 17, ["name"] = "default:dirt_with_grass"}, {["x"] = 8, ["y"] = 1, ["z"] = 18, ["name"] = "default:silver_sandstone"}, {["x"] = 8, ["y"] = 1, ["z"] = 19, ["name"] = "default:dirt_with_grass"}, {["x"] = 8, ["y"] = 1, ["z"] = 20, ["name"] = "default:silver_sandstone"}, {["x"] = 8, ["y"] = 1, ["z"] = 21, ["name"] = "default:silver_sandstone"}, {["x"] = 8, ["y"] = 1, ["z"] = 22, ["name"] = "default:dirt_with_grass"}, {["x"] = 8, ["param2"] = 1, ["y"] = 2, ["param1"] = 142, ["z"] = 19, ["name"] = "stairs:stair_silver_sandstone"}, {["x"] = 8, ["param2"] = 1, ["y"] = 2, ["param1"] = 158, ["z"] = 20, ["name"] = "stairs:stair_silver_sandstone"}, {["x"] = 9, ["y"] = 0, ["param1"] = 158, ["z"] = 0, ["name"] = "default:stone"}, {["x"] = 9, ["y"] = 0, ["param1"] = 173, ["z"] = 1, ["name"] = "default:stone"}, {["x"] = 9, ["y"] = 0, ["param1"] = 188, ["z"] = 2, ["name"] = "default:stone"}, {["x"] = 9, ["y"] = 0, ["param1"] = 204, ["z"] = 3, ["name"] = "default:stone"}, {["x"] = 9, ["y"] = 0, ["param1"] = 221, ["z"] = 4, ["name"] = "default:stone"}, {["x"] = 9, ["y"] = 0, ["param1"] = 221, ["z"] = 5, ["name"] = "default:stone"}, {["x"] = 9, ["y"] = 0, ["param1"] = 221, ["z"] = 6, ["name"] = "default:stone"}, {["x"] = 9, ["y"] = 0, ["param1"] = 221, ["z"] = 7, ["name"] = "default:stone"}, {["x"] = 9, ["y"] = 0, ["param1"] = 221, ["z"] = 8, ["name"] = "default:stone"}, {["x"] = 9, ["y"] = 0, ["param1"] = 221, ["z"] = 9, ["name"] = "default:stone"}, {["x"] = 9, ["y"] = 0, ["param1"] = 221, ["z"] = 10, ["name"] = "default:stone"}, {["x"] = 9, ["y"] = 0, ["param1"] = 221, ["z"] = 11, ["name"] = "default:stone"}, {["x"] = 9, ["y"] = 0, ["param1"] = 221, ["z"] = 12, ["name"] = "default:stone"}, {["x"] = 9, ["y"] = 0, ["param1"] = 221, ["z"] = 13, ["name"] = "default:stone"}, {["x"] = 9, ["y"] = 0, ["param1"] = 221, ["z"] = 14, ["name"] = "default:stone"}, {["x"] = 9, ["y"] = 0, ["param1"] = 221, ["z"] = 15, ["name"] = "default:stone"}, {["x"] = 9, ["y"] = 0, ["param1"] = 221, ["z"] = 16, ["name"] = "default:stone"}, {["x"] = 9, ["y"] = 0, ["param1"] = 221, ["z"] = 17, ["name"] = "default:stone"}, {["x"] = 9, ["y"] = 0, ["param1"] = 221, ["z"] = 18, ["name"] = "default:stone"}, {["x"] = 9, ["y"] = 0, ["param1"] = 221, ["z"] = 19, ["name"] = "default:stone"}, {["x"] = 9, ["y"] = 0, ["param1"] = 221, ["z"] = 20, ["name"] = "default:stone"}, {["x"] = 9, ["y"] = 0, ["param1"] = 205, ["z"] = 21, ["name"] = "default:stone"}, {["x"] = 9, ["y"] = 0, ["param1"] = 190, ["z"] = 22, ["name"] = "default:stone"}, {["x"] = 9, ["y"] = 1, ["z"] = 0, ["name"] = "default:dirt_with_grass"}, {["x"] = 9, ["y"] = 1, ["z"] = 1, ["name"] = "default:dirt_with_grass"}, {["x"] = 9, ["y"] = 1, ["z"] = 2, ["name"] = "default:dirt_with_grass"}, {["x"] = 9, ["y"] = 1, ["z"] = 3, ["name"] = "default:dirt"}, {["x"] = 9, ["y"] = 1, ["z"] = 4, ["name"] = "default:dirt_with_grass"}, {["x"] = 9, ["y"] = 1, ["z"] = 5, ["name"] = "default:dirt_with_grass"}, {["x"] = 9, ["y"] = 1, ["z"] = 6, ["name"] = "default:dirt_with_grass"}, {["x"] = 9, ["y"] = 1, ["z"] = 7, ["name"] = "default:dirt_with_grass"}, {["x"] = 9, ["y"] = 1, ["z"] = 8, ["name"] = "default:dirt_with_grass"}, {["x"] = 9, ["y"] = 1, ["z"] = 9, ["name"] = "default:silver_sandstone"}, {["x"] = 9, ["y"] = 1, ["z"] = 10, ["name"] = "default:stonebrick"}, {["x"] = 9, ["y"] = 1, ["z"] = 11, ["name"] = "default:stonebrick"}, {["x"] = 9, ["y"] = 1, ["z"] = 12, ["name"] = "default:silver_sandstone"}, {["x"] = 9, ["y"] = 1, ["z"] = 13, ["name"] = "default:dirt_with_grass"}, {["x"] = 9, ["y"] = 1, ["z"] = 14, ["name"] = "default:dirt_with_grass"}, {["x"] = 9, ["y"] = 1, ["z"] = 15, ["name"] = "default:dirt_with_grass"}, {["x"] = 9, ["y"] = 1, ["z"] = 16, ["name"] = "default:dirt_with_grass"}, {["x"] = 9, ["y"] = 1, ["z"] = 17, ["name"] = "default:dirt_with_grass"}, {["x"] = 9, ["param2"] = 3, ["y"] = 1, ["z"] = 19, ["name"] = "default:pine_wood"}, {["x"] = 9, ["y"] = 1, ["z"] = 20, ["name"] = "default:silver_sandstone"}, {["x"] = 9, ["y"] = 1, ["z"] = 21, ["name"] = "default:dirt"}, {["x"] = 9, ["y"] = 1, ["z"] = 22, ["name"] = "default:dirt_with_grass"}, {["x"] = 9, ["y"] = 2, ["z"] = 3, ["name"] = "default:silver_sandstone"}, {["x"] = 9, ["y"] = 2, ["param1"] = 174, ["z"] = 5, ["name"] = "default:junglegrass"}, {["x"] = 9, ["y"] = 2, ["param1"] = 174, ["z"] = 8, ["name"] = "default:junglegrass"}, {["x"] = 9, ["y"] = 2, ["param1"] = 174, ["z"] = 14, ["name"] = "default:junglegrass"}, {["x"] = 9, ["y"] = 2, ["param1"] = 158, ["z"] = 17, ["name"] = "default:junglegrass"}, {["x"] = 9, ["y"] = 2, ["z"] = 18, ["name"] = "default:silver_sandstone"}, {["x"] = 9, ["y"] = 2, ["z"] = 19, ["name"] = "default:silver_sandstone"}, {["x"] = 9, ["param2"] = 3, ["y"] = 2, ["param1"] = 173, ["z"] = 20, ["name"] = "stairs:slab_pine_wood"}, {["x"] = 9, ["y"] = 2, ["z"] = 21, ["name"] = "default:silver_sandstone"}, {["x"] = 9, ["y"] = 3, ["z"] = 3, ["name"] = "default:silver_sandstone"}, {["x"] = 9, ["y"] = 3, ["z"] = 18, ["name"] = "default:silver_sandstone"}, {["x"] = 9, ["param2"] = 1, ["y"] = 3, ["param1"] = 142, ["z"] = 19, ["name"] = "stairs:stair_silver_sandstone"}, {["x"] = 9, ["param2"] = 1, ["y"] = 3, ["param1"] = 158, ["z"] = 20, ["name"] = "stairs:stair_silver_sandstone"}, {["x"] = 9, ["y"] = 3, ["z"] = 21, ["name"] = "default:silver_sandstone"}, {["x"] = 9, ["y"] = 4, ["z"] = 3, ["name"] = "default:silver_sandstone"}, {["x"] = 9, ["y"] = 4, ["z"] = 18, ["name"] = "default:silver_sandstone"}, {["x"] = 9, ["y"] = 4, ["z"] = 21, ["name"] = "default:silver_sandstone"}, {["x"] = 9, ["y"] = 5, ["z"] = 3, ["name"] = "default:silver_sandstone"}, {["x"] = 9, ["y"] = 5, ["z"] = 4, ["name"] = "default:silver_sandstone"}, {["x"] = 9, ["y"] = 5, ["z"] = 5, ["name"] = "default:silver_sandstone"}, {["x"] = 9, ["y"] = 5, ["z"] = 6, ["name"] = "default:silver_sandstone"}, {["x"] = 9, ["y"] = 5, ["z"] = 7, ["name"] = "default:silver_sandstone"}, {["x"] = 9, ["y"] = 5, ["z"] = 8, ["name"] = "default:silver_sandstone"}, {["x"] = 9, ["y"] = 5, ["z"] = 9, ["name"] = "default:silver_sandstone"}, {["x"] = 9, ["y"] = 5, ["z"] = 10, ["name"] = "default:silver_sandstone"}, {["x"] = 9, ["y"] = 5, ["z"] = 11, ["name"] = "default:silver_sandstone"}, {["x"] = 9, ["y"] = 5, ["z"] = 12, ["name"] = "default:silver_sandstone"}, {["x"] = 9, ["y"] = 5, ["z"] = 13, ["name"] = "default:silver_sandstone"}, {["x"] = 9, ["y"] = 5, ["z"] = 14, ["name"] = "default:silver_sandstone"}, {["x"] = 9, ["y"] = 5, ["z"] = 15, ["name"] = "default:silver_sandstone"}, {["x"] = 9, ["y"] = 5, ["z"] = 16, ["name"] = "default:silver_sandstone"}, {["x"] = 9, ["y"] = 5, ["z"] = 17, ["name"] = "default:silver_sandstone"}, {["x"] = 9, ["y"] = 5, ["z"] = 18, ["name"] = "default:silver_sandstone"}, {["x"] = 9, ["y"] = 5, ["z"] = 21, ["name"] = "default:silver_sandstone"}, {["x"] = 9, ["y"] = 6, ["z"] = 12, ["name"] = "default:silver_sandstone"}, {["x"] = 9, ["param2"] = 1, ["y"] = 6, ["param1"] = 95, ["z"] = 13, ["name"] = "xpanes:pane_flat"}, {["x"] = 9, ["param2"] = 3, ["y"] = 6, ["param1"] = 111, ["z"] = 14, ["name"] = "xpanes:pane_flat"}, {["x"] = 9, ["param2"] = 3, ["y"] = 6, ["param1"] = 111, ["z"] = 15, ["name"] = "xpanes:pane_flat"}, {["x"] = 9, ["param2"] = 3, ["y"] = 6, ["param1"] = 111, ["z"] = 16, ["name"] = "xpanes:pane_flat"}, {["x"] = 9, ["param2"] = 3, ["y"] = 6, ["param1"] = 95, ["z"] = 17, ["name"] = "xpanes:pane_flat"}, {["x"] = 9, ["y"] = 6, ["param1"] = 95, ["z"] = 18, ["name"] = "xpanes:pane"}, {["x"] = 9, ["y"] = 7, ["z"] = 12, ["name"] = "default:silver_sandstone"}, {["x"] = 9, ["y"] = 8, ["z"] = 12, ["name"] = "default:silver_sandstone"}, {["x"] = 9, ["y"] = 9, ["z"] = 12, ["name"] = "default:silver_sandstone"}, {["x"] = 9, ["y"] = 10, ["z"] = 3, ["name"] = "default:silver_sandstone"}, {["x"] = 9, ["y"] = 10, ["z"] = 4, ["name"] = "default:silver_sandstone"}, {["x"] = 9, ["y"] = 10, ["z"] = 5, ["name"] = "default:silver_sandstone"}, {["x"] = 9, ["y"] = 10, ["z"] = 6, ["name"] = "default:silver_sandstone"}, {["x"] = 9, ["y"] = 10, ["z"] = 7, ["name"] = "default:silver_sandstone"}, {["x"] = 9, ["y"] = 10, ["z"] = 8, ["name"] = "default:silver_sandstone"}, {["x"] = 9, ["y"] = 10, ["z"] = 9, ["name"] = "default:silver_sandstone"}, {["x"] = 9, ["y"] = 10, ["z"] = 10, ["name"] = "default:silver_sandstone"}, {["x"] = 9, ["y"] = 10, ["z"] = 11, ["name"] = "default:silver_sandstone"}, {["x"] = 9, ["y"] = 10, ["z"] = 12, ["name"] = "default:silver_sandstone"}, {["x"] = 10, ["y"] = 0, ["param1"] = 174, ["z"] = 0, ["name"] = "default:stone"}, {["x"] = 10, ["y"] = 0, ["param1"] = 189, ["z"] = 1, ["name"] = "default:stone"}, {["x"] = 10, ["y"] = 0, ["param1"] = 204, ["z"] = 2, ["name"] = "default:stone"}, {["x"] = 10, ["y"] = 0, ["param1"] = 221, ["z"] = 3, ["name"] = "default:stone"}, {["x"] = 10, ["y"] = 0, ["param1"] = 238, ["z"] = 4, ["name"] = "default:meselamp"}, {["x"] = 10, ["y"] = 0, ["param1"] = 238, ["z"] = 5, ["name"] = "default:meselamp"}, {["x"] = 10, ["y"] = 0, ["param1"] = 238, ["z"] = 6, ["name"] = "default:meselamp"}, {["x"] = 10, ["y"] = 0, ["param1"] = 238, ["z"] = 7, ["name"] = "default:meselamp"}, {["x"] = 10, ["y"] = 0, ["param1"] = 238, ["z"] = 8, ["name"] = "default:meselamp"}, {["x"] = 10, ["y"] = 0, ["param1"] = 238, ["z"] = 9, ["name"] = "default:meselamp"}, {["x"] = 10, ["y"] = 0, ["param1"] = 238, ["z"] = 10, ["name"] = "default:meselamp"}, {["x"] = 10, ["y"] = 0, ["param1"] = 238, ["z"] = 11, ["name"] = "default:meselamp"}, {["x"] = 10, ["y"] = 0, ["param1"] = 238, ["z"] = 12, ["name"] = "default:meselamp"}, {["x"] = 10, ["y"] = 0, ["param1"] = 238, ["z"] = 13, ["name"] = "default:meselamp"}, {["x"] = 10, ["y"] = 0, ["param1"] = 238, ["z"] = 14, ["name"] = "default:meselamp"}, {["x"] = 10, ["y"] = 0, ["param1"] = 238, ["z"] = 15, ["name"] = "default:meselamp"}, {["x"] = 10, ["y"] = 0, ["param1"] = 238, ["z"] = 16, ["name"] = "default:meselamp"}, {["x"] = 10, ["y"] = 0, ["param1"] = 238, ["z"] = 17, ["name"] = "default:meselamp"}, {["x"] = 10, ["y"] = 0, ["param1"] = 238, ["z"] = 18, ["name"] = "default:meselamp"}, {["x"] = 10, ["y"] = 0, ["param1"] = 238, ["z"] = 19, ["name"] = "default:meselamp"}, {["x"] = 10, ["param2"] = 15, ["y"] = 0, ["param1"] = 238, ["z"] = 20, ["name"] = "default:meselamp"}, {["x"] = 10, ["y"] = 0, ["param1"] = 221, ["z"] = 21, ["name"] = "default:stone"}, {["x"] = 10, ["y"] = 0, ["param1"] = 206, ["z"] = 22, ["name"] = "default:stone"}, {["x"] = 10, ["y"] = 1, ["z"] = 0, ["name"] = "default:dirt_with_grass"}, {["x"] = 10, ["y"] = 1, ["z"] = 1, ["name"] = "default:dirt_with_grass"}, {["x"] = 10, ["y"] = 1, ["z"] = 2, ["name"] = "default:dirt_with_grass"}, {["x"] = 10, ["y"] = 1, ["z"] = 3, ["name"] = "default:silver_sandstone"}, {["x"] = 10, ["y"] = 1, ["z"] = 4, ["name"] = "default:dirt"}, {["x"] = 10, ["y"] = 1, ["z"] = 5, ["name"] = "default:silver_sandstone"}, {["x"] = 10, ["y"] = 1, ["z"] = 6, ["name"] = "default:silver_sandstone"}, {["x"] = 10, ["y"] = 1, ["z"] = 7, ["name"] = "default:silver_sandstone"}, {["x"] = 10, ["y"] = 1, ["z"] = 8, ["name"] = "default:silver_sandstone"}, {["x"] = 10, ["y"] = 1, ["z"] = 9, ["name"] = "default:dirt"}, {["x"] = 10, ["y"] = 1, ["z"] = 10, ["name"] = "default:silver_sandstone"}, {["x"] = 10, ["y"] = 1, ["z"] = 11, ["name"] = "default:silver_sandstone"}, {["x"] = 10, ["y"] = 1, ["z"] = 12, ["name"] = "default:silver_sandstone"}, {["x"] = 10, ["y"] = 1, ["z"] = 13, ["name"] = "default:silver_sandstone"}, {["x"] = 10, ["y"] = 1, ["z"] = 14, ["name"] = "default:silver_sandstone"}, {["x"] = 10, ["y"] = 1, ["z"] = 15, ["name"] = "default:silver_sandstone"}, {["x"] = 10, ["y"] = 1, ["z"] = 16, ["name"] = "default:silver_sandstone"}, {["x"] = 10, ["y"] = 1, ["z"] = 17, ["name"] = "default:silver_sandstone"}, {["x"] = 10, ["param2"] = 22, ["y"] = 1, ["param1"] = 221, ["z"] = 18, ["name"] = "stairs:slab_pine_wood"}, {["x"] = 10, ["param2"] = 21, ["y"] = 1, ["param1"] = 221, ["z"] = 19, ["name"] = "stairs:slab_pine_wood"}, {["x"] = 10, ["y"] = 1, ["z"] = 20, ["name"] = "default:pine_wood"}, {["x"] = 10, ["y"] = 1, ["z"] = 21, ["name"] = "default:dirt"}, {["x"] = 10, ["y"] = 1, ["z"] = 22, ["name"] = "default:dirt_with_grass"}, {["x"] = 10, ["y"] = 2, ["param1"] = 159, ["z"] = 2, ["name"] = "default:grass_2"}, {["x"] = 10, ["y"] = 2, ["z"] = 4, ["name"] = "default:pine_wood"}, {["x"] = 10, ["y"] = 2, ["param1"] = 189, ["z"] = 5, ["name"] = "default:obsidian_glass"}, {["x"] = 10, ["y"] = 2, ["param1"] = 189, ["z"] = 6, ["name"] = "default:obsidian_glass"}, {["x"] = 10, ["y"] = 2, ["param1"] = 189, ["z"] = 7, ["name"] = "default:obsidian_glass"}, {["x"] = 10, ["y"] = 2, ["param1"] = 189, ["z"] = 8, ["name"] = "default:obsidian_glass"}, {["x"] = 10, ["y"] = 2, ["z"] = 9, ["name"] = "default:pine_wood"}, {["x"] = 10, ["meta"] = {["fields"] = {["state"] = "2"}, ["inventory"] = {}}, ["param2"] = 1, ["y"] = 2, ["param1"] = 173, ["z"] = 10, ["name"] = "doors:door_wood_b"}, {["x"] = 10, ["meta"] = {["fields"] = {["state"] = "0"}, ["inventory"] = {}}, ["param2"] = 1, ["y"] = 2, ["param1"] = 189, ["z"] = 11, ["name"] = "doors:door_wood_a"}, {["x"] = 10, ["y"] = 2, ["z"] = 12, ["name"] = "default:pine_wood"}, {["x"] = 10, ["y"] = 2, ["param1"] = 189, ["z"] = 13, ["name"] = "default:obsidian_glass"}, {["x"] = 10, ["y"] = 2, ["param1"] = 189, ["z"] = 14, ["name"] = "default:obsidian_glass"}, {["x"] = 10, ["y"] = 2, ["param1"] = 189, ["z"] = 15, ["name"] = "default:obsidian_glass"}, {["x"] = 10, ["y"] = 2, ["param1"] = 189, ["z"] = 16, ["name"] = "default:obsidian_glass"}, {["x"] = 10, ["y"] = 2, ["z"] = 17, ["name"] = "default:pine_wood"}, {["x"] = 10, ["y"] = 2, ["z"] = 18, ["name"] = "default:pine_wood"}, {["x"] = 10, ["y"] = 2, ["z"] = 19, ["name"] = "default:silver_sandstone"}, {["x"] = 10, ["meta"] = {["fields"] = {["infotext"] = "\27(T@default)Chest\27E"}, ["inventory"] = {["main"] = {"", "", "", "", "", "", "", "", "", "", "", "", "", "", "", "", "", "", "", "", "", "", "", "", "", "", "", "", "", "", "", ""}}}, ["param2"] = 3, ["y"] = 2, ["param1"] = 188, ["z"] = 20, ["name"] = "default:chest"}, {["x"] = 10, ["y"] = 2, ["z"] = 21, ["name"] = "default:silver_sandstone"}, {["x"] = 10, ["y"] = 3, ["z"] = 4, ["name"] = "default:pine_wood"}, {["x"] = 10, ["y"] = 3, ["param1"] = 173, ["z"] = 5, ["name"] = "default:obsidian_glass"}, {["x"] = 10, ["y"] = 3, ["param1"] = 173, ["z"] = 6, ["name"] = "default:obsidian_glass"}, {["x"] = 10, ["y"] = 3, ["param1"] = 173, ["z"] = 7, ["name"] = "default:obsidian_glass"}, {["x"] = 10, ["y"] = 3, ["param1"] = 173, ["z"] = 8, ["name"] = "default:obsidian_glass"}, {["x"] = 10, ["y"] = 3, ["z"] = 9, ["name"] = "default:pine_wood"}, {["x"] = 10, ["y"] = 3, ["param1"] = 157, ["z"] = 10, ["name"] = "doors:hidden"}, {["x"] = 10, ["param2"] = 1, ["y"] = 3, ["param1"] = 173, ["z"] = 11, ["name"] = "doors:hidden"}, {["x"] = 10, ["y"] = 3, ["z"] = 12, ["name"] = "default:pine_wood"}, {["x"] = 10, ["y"] = 3, ["param1"] = 173, ["z"] = 13, ["name"] = "default:obsidian_glass"}, {["x"] = 10, ["y"] = 3, ["param1"] = 173, ["z"] = 14, ["name"] = "default:obsidian_glass"}, {["x"] = 10, ["y"] = 3, ["param1"] = 173, ["z"] = 15, ["name"] = "default:obsidian_glass"}, {["x"] = 10, ["y"] = 3, ["param1"] = 173, ["z"] = 16, ["name"] = "default:obsidian_glass"}, {["x"] = 10, ["y"] = 3, ["z"] = 17, ["name"] = "default:pine_wood"}, {["x"] = 10, ["y"] = 3, ["z"] = 18, ["name"] = "default:pine_wood"}, {["x"] = 10, ["y"] = 3, ["z"] = 19, ["name"] = "default:silver_sandstone"}, {["x"] = 10, ["param2"] = 3, ["y"] = 3, ["param1"] = 173, ["z"] = 20, ["name"] = "doors:trapdoor"}, {["x"] = 10, ["y"] = 3, ["z"] = 21, ["name"] = "default:silver_sandstone"}, {["x"] = 10, ["y"] = 4, ["z"] = 4, ["name"] = "default:pine_wood"}, {["x"] = 10, ["y"] = 4, ["param1"] = 157, ["z"] = 5, ["name"] = "default:obsidian_glass"}, {["x"] = 10, ["y"] = 4, ["param1"] = 157, ["z"] = 6, ["name"] = "default:obsidian_glass"}, {["x"] = 10, ["y"] = 4, ["param1"] = 157, ["z"] = 7, ["name"] = "default:obsidian_glass"}, {["x"] = 10, ["y"] = 4, ["param1"] = 157, ["z"] = 8, ["name"] = "default:obsidian_glass"}, {["x"] = 10, ["y"] = 4, ["z"] = 9, ["name"] = "default:pine_wood"}, {["x"] = 10, ["y"] = 4, ["z"] = 10, ["name"] = "default:pine_wood"}, {["x"] = 10, ["y"] = 4, ["z"] = 11, ["name"] = "default:pine_wood"}, {["x"] = 10, ["y"] = 4, ["z"] = 12, ["name"] = "default:pine_wood"}, {["x"] = 10, ["y"] = 4, ["param1"] = 157, ["z"] = 13, ["name"] = "default:obsidian_glass"}, {["x"] = 10, ["y"] = 4, ["param1"] = 157, ["z"] = 14, ["name"] = "default:obsidian_glass"}, {["x"] = 10, ["y"] = 4, ["param1"] = 157, ["z"] = 15, ["name"] = "default:obsidian_glass"}, {["x"] = 10, ["y"] = 4, ["param1"] = 157, ["z"] = 16, ["name"] = "default:obsidian_glass"}, {["x"] = 10, ["y"] = 4, ["z"] = 17, ["name"] = "default:pine_wood"}, {["x"] = 10, ["y"] = 4, ["z"] = 18, ["name"] = "default:silver_sandstone"}, {["x"] = 10, ["param2"] = 1, ["y"] = 4, ["param1"] = 142, ["z"] = 19, ["name"] = "stairs:stair_silver_sandstone"}, {["x"] = 10, ["param2"] = 1, ["y"] = 4, ["param1"] = 158, ["z"] = 20, ["name"] = "stairs:stair_silver_sandstone"}, {["x"] = 10, ["y"] = 4, ["z"] = 21, ["name"] = "default:silver_sandstone"}, {["x"] = 10, ["y"] = 5, ["z"] = 3, ["name"] = "default:silver_sandstone"}, {["x"] = 10, ["y"] = 5, ["z"] = 4, ["name"] = "default:pine_wood"}, {["x"] = 10, ["y"] = 5, ["z"] = 5, ["name"] = "default:pine_wood"}, {["x"] = 10, ["y"] = 5, ["z"] = 6, ["name"] = "default:pine_wood"}, {["x"] = 10, ["y"] = 5, ["z"] = 7, ["name"] = "default:pine_wood"}, {["x"] = 10, ["y"] = 5, ["z"] = 8, ["name"] = "default:pine_wood"}, {["x"] = 10, ["y"] = 5, ["z"] = 9, ["name"] = "default:pine_wood"}, {["x"] = 10, ["y"] = 5, ["z"] = 10, ["name"] = "default:pine_wood"}, {["x"] = 10, ["y"] = 5, ["z"] = 11, ["name"] = "default:silver_sandstone"}, {["x"] = 10, ["param2"] = 2, ["y"] = 5, ["z"] = 12, ["name"] = "default:silver_sandstone"}, {["x"] = 10, ["param2"] = 2, ["y"] = 5, ["z"] = 13, ["name"] = "default:silver_sandstone"}, {["x"] = 10, ["param2"] = 3, ["y"] = 5, ["param1"] = 142, ["z"] = 14, ["name"] = "stairs:slab_silver_sandstone"}, {["x"] = 10, ["param2"] = 3, ["y"] = 5, ["param1"] = 142, ["z"] = 15, ["name"] = "stairs:slab_silver_sandstone"}, {["x"] = 10, ["param2"] = 3, ["y"] = 5, ["param1"] = 142, ["z"] = 16, ["name"] = "stairs:slab_silver_sandstone"}, {["x"] = 10, ["y"] = 5, ["z"] = 17, ["name"] = "default:silver_sandstone"}, {["x"] = 10, ["y"] = 5, ["z"] = 18, ["name"] = "default:silver_sandstone"}, {["x"] = 10, ["y"] = 5, ["z"] = 21, ["name"] = "default:silver_sandstone"}, {["x"] = 10, ["y"] = 6, ["param1"] = 109, ["z"] = 4, ["name"] = "default:obsidian_glass"}, {["x"] = 10, ["y"] = 6, ["param1"] = 125, ["z"] = 5, ["name"] = "default:obsidian_glass"}, {["x"] = 10, ["y"] = 6, ["param1"] = 125, ["z"] = 6, ["name"] = "default:obsidian_glass"}, {["x"] = 10, ["y"] = 6, ["param1"] = 125, ["z"] = 7, ["name"] = "default:obsidian_glass"}, {["x"] = 10, ["y"] = 6, ["param1"] = 125, ["z"] = 8, ["name"] = "default:obsidian_glass"}, {["x"] = 10, ["y"] = 6, ["param1"] = 125, ["z"] = 9, ["name"] = "default:obsidian_glass"}, {["x"] = 10, ["y"] = 6, ["param1"] = 109, ["z"] = 10, ["name"] = "default:obsidian_glass"}, {["x"] = 10, ["y"] = 6, ["z"] = 11, ["name"] = "default:pine_wood"}, {["x"] = 10, ["y"] = 6, ["param1"] = 111, ["z"] = 18, ["name"] = "xpanes:pane_flat"}, {["x"] = 10, ["y"] = 7, ["param1"] = 93, ["z"] = 4, ["name"] = "default:obsidian_glass"}, {["x"] = 10, ["y"] = 7, ["param1"] = 109, ["z"] = 5, ["name"] = "default:obsidian_glass"}, {["x"] = 10, ["y"] = 7, ["param1"] = 109, ["z"] = 6, ["name"] = "default:obsidian_glass"}, {["x"] = 10, ["y"] = 7, ["param1"] = 109, ["z"] = 7, ["name"] = "default:obsidian_glass"}, {["x"] = 10, ["y"] = 7, ["param1"] = 109, ["z"] = 8, ["name"] = "default:obsidian_glass"}, {["x"] = 10, ["y"] = 7, ["param1"] = 109, ["z"] = 9, ["name"] = "default:obsidian_glass"}, {["x"] = 10, ["y"] = 7, ["param1"] = 93, ["z"] = 10, ["name"] = "default:obsidian_glass"}, {["x"] = 10, ["y"] = 7, ["z"] = 11, ["name"] = "default:pine_wood"}, {["x"] = 10, ["y"] = 8, ["param1"] = 77, ["z"] = 4, ["name"] = "default:obsidian_glass"}, {["x"] = 10, ["y"] = 8, ["param1"] = 93, ["z"] = 5, ["name"] = "default:obsidian_glass"}, {["x"] = 10, ["y"] = 8, ["param1"] = 93, ["z"] = 6, ["name"] = "default:obsidian_glass"}, {["x"] = 10, ["y"] = 8, ["param1"] = 93, ["z"] = 7, ["name"] = "default:obsidian_glass"}, {["x"] = 10, ["y"] = 8, ["param1"] = 93, ["z"] = 8, ["name"] = "default:obsidian_glass"}, {["x"] = 10, ["y"] = 8, ["param1"] = 93, ["z"] = 9, ["name"] = "default:obsidian_glass"}, {["x"] = 10, ["y"] = 8, ["param1"] = 77, ["z"] = 10, ["name"] = "default:obsidian_glass"}, {["x"] = 10, ["y"] = 8, ["z"] = 11, ["name"] = "default:pine_wood"}, {["x"] = 10, ["y"] = 9, ["param1"] = 61, ["z"] = 4, ["name"] = "default:obsidian_glass"}, {["x"] = 10, ["y"] = 9, ["param1"] = 77, ["z"] = 5, ["name"] = "default:obsidian_glass"}, {["x"] = 10, ["y"] = 9, ["param1"] = 77, ["z"] = 6, ["name"] = "default:obsidian_glass"}, {["x"] = 10, ["y"] = 9, ["param1"] = 77, ["z"] = 7, ["name"] = "default:obsidian_glass"}, {["x"] = 10, ["y"] = 9, ["param1"] = 77, ["z"] = 8, ["name"] = "default:obsidian_glass"}, {["x"] = 10, ["y"] = 9, ["param1"] = 77, ["z"] = 9, ["name"] = "default:obsidian_glass"}, {["x"] = 10, ["y"] = 9, ["param1"] = 61, ["z"] = 10, ["name"] = "default:obsidian_glass"}, {["x"] = 10, ["y"] = 9, ["z"] = 11, ["name"] = "default:pine_wood"}, {["x"] = 10, ["y"] = 10, ["z"] = 3, ["name"] = "default:silver_sandstone"}, {["x"] = 10, ["param2"] = 3, ["y"] = 10, ["param1"] = 46, ["z"] = 4, ["name"] = "stairs:slab_silver_sandstone"}, {["x"] = 10, ["param2"] = 3, ["y"] = 10, ["param1"] = 62, ["z"] = 5, ["name"] = "stairs:slab_silver_sandstone"}, {["x"] = 10, ["param2"] = 3, ["y"] = 10, ["param1"] = 62, ["z"] = 6, ["name"] = "stairs:slab_silver_sandstone"}, {["x"] = 10, ["param2"] = 3, ["y"] = 10, ["param1"] = 62, ["z"] = 7, ["name"] = "stairs:slab_silver_sandstone"}, {["x"] = 10, ["param2"] = 3, ["y"] = 10, ["param1"] = 62, ["z"] = 8, ["name"] = "stairs:slab_silver_sandstone"}, {["x"] = 10, ["param2"] = 3, ["y"] = 10, ["param1"] = 62, ["z"] = 9, ["name"] = "stairs:slab_silver_sandstone"}, {["x"] = 10, ["y"] = 10, ["param1"] = 46, ["z"] = 10, ["name"] = "stairs:slab_silver_sandstone"}, {["x"] = 10, ["y"] = 10, ["param1"] = 30, ["z"] = 11, ["name"] = "stairs:slab_silver_sandstone"}, {["x"] = 10, ["y"] = 10, ["z"] = 12, ["name"] = "default:silver_sandstone"}, {["x"] = 11, ["y"] = 0, ["param1"] = 174, ["z"] = 0, ["name"] = "default:stone"}, {["x"] = 11, ["y"] = 0, ["param1"] = 189, ["z"] = 1, ["name"] = "default:stone"}, {["x"] = 11, ["y"] = 0, ["param1"] = 204, ["z"] = 2, ["name"] = "default:stone"}, {["x"] = 11, ["y"] = 0, ["param1"] = 221, ["z"] = 3, ["name"] = "default:stone"}, {["x"] = 11, ["y"] = 0, ["param1"] = 238, ["z"] = 4, ["name"] = "default:meselamp"}, {["x"] = 11, ["param2"] = 15, ["y"] = 0, ["param1"] = 238, ["z"] = 5, ["name"] = "default:meselamp"}, {["x"] = 11, ["param2"] = 15, ["y"] = 0, ["param1"] = 238, ["z"] = 6, ["name"] = "default:meselamp"}, {["x"] = 11, ["param2"] = 15, ["y"] = 0, ["param1"] = 238, ["z"] = 7, ["name"] = "default:meselamp"}, {["x"] = 11, ["param2"] = 15, ["y"] = 0, ["param1"] = 238, ["z"] = 8, ["name"] = "default:meselamp"}, {["x"] = 11, ["param2"] = 15, ["y"] = 0, ["param1"] = 238, ["z"] = 9, ["name"] = "default:meselamp"}, {["x"] = 11, ["y"] = 0, ["param1"] = 238, ["z"] = 10, ["name"] = "default:meselamp"}, {["x"] = 11, ["y"] = 0, ["param1"] = 238, ["z"] = 11, ["name"] = "default:meselamp"}, {["x"] = 11, ["y"] = 0, ["param1"] = 238, ["z"] = 12, ["name"] = "default:meselamp"}, {["x"] = 11, ["param2"] = 15, ["y"] = 0, ["param1"] = 238, ["z"] = 13, ["name"] = "default:meselamp"}, {["x"] = 11, ["param2"] = 15, ["y"] = 0, ["param1"] = 238, ["z"] = 14, ["name"] = "default:meselamp"}, {["x"] = 11, ["param2"] = 15, ["y"] = 0, ["param1"] = 238, ["z"] = 15, ["name"] = "default:meselamp"}, {["x"] = 11, ["param2"] = 15, ["y"] = 0, ["param1"] = 238, ["z"] = 16, ["name"] = "default:meselamp"}, {["x"] = 11, ["y"] = 0, ["param1"] = 238, ["z"] = 17, ["name"] = "default:meselamp"}, {["x"] = 11, ["y"] = 0, ["param1"] = 238, ["z"] = 18, ["name"] = "default:meselamp"}, {["x"] = 11, ["y"] = 0, ["param1"] = 238, ["z"] = 19, ["name"] = "default:meselamp"}, {["x"] = 11, ["y"] = 0, ["param1"] = 238, ["z"] = 20, ["name"] = "default:meselamp"}, {["x"] = 11, ["y"] = 0, ["param1"] = 221, ["z"] = 21, ["name"] = "default:stone"}, {["x"] = 11, ["y"] = 0, ["param1"] = 206, ["z"] = 22, ["name"] = "default:stone"}, {["x"] = 11, ["y"] = 1, ["z"] = 0, ["name"] = "default:dirt_with_grass"}, {["x"] = 11, ["y"] = 1, ["z"] = 1, ["name"] = "default:dirt_with_grass"}, {["x"] = 11, ["y"] = 1, ["z"] = 2, ["name"] = "default:dirt_with_grass"}, {["x"] = 11, ["y"] = 1, ["z"] = 3, ["name"] = "default:silver_sandstone"}, {["x"] = 11, ["param2"] = 21, ["y"] = 1, ["param1"] = 221, ["z"] = 4, ["name"] = "stairs:slab_pine_wood"}, {["x"] = 11, ["param2"] = 7, ["y"] = 1, ["param1"] = 221, ["z"] = 5, ["name"] = "default:water_flowing"}, {["x"] = 11, ["param2"] = 7, ["y"] = 1, ["param1"] = 221, ["z"] = 6, ["name"] = "default:water_flowing"}, {["x"] = 11, ["param2"] = 7, ["y"] = 1, ["param1"] = 221, ["z"] = 7, ["name"] = "default:water_flowing"}, {["x"] = 11, ["param2"] = 7, ["y"] = 1, ["param1"] = 221, ["z"] = 8, ["name"] = "default:water_flowing"}, {["x"] = 11, ["param2"] = 7, ["y"] = 1, ["param1"] = 221, ["z"] = 9, ["name"] = "default:water_flowing"}, {["x"] = 11, ["y"] = 1, ["z"] = 10, ["name"] = "default:pine_wood"}, {["x"] = 11, ["param2"] = 21, ["y"] = 1, ["param1"] = 221, ["z"] = 11, ["name"] = "stairs:slab_pine_wood"}, {["x"] = 11, ["param2"] = 21, ["y"] = 1, ["param1"] = 221, ["z"] = 12, ["name"] = "stairs:slab_pine_wood"}, {["x"] = 11, ["param2"] = 15, ["y"] = 1, ["param1"] = 221, ["z"] = 13, ["name"] = "default:water_flowing"}, {["x"] = 11, ["param2"] = 15, ["y"] = 1, ["param1"] = 221, ["z"] = 14, ["name"] = "default:water_flowing"}, {["x"] = 11, ["param2"] = 15, ["y"] = 1, ["param1"] = 221, ["z"] = 15, ["name"] = "default:water_flowing"}, {["x"] = 11, ["param2"] = 15, ["y"] = 1, ["param1"] = 221, ["z"] = 16, ["name"] = "default:water_flowing"}, {["x"] = 11, ["param2"] = 21, ["y"] = 1, ["param1"] = 221, ["z"] = 17, ["name"] = "stairs:slab_pine_wood"}, {["x"] = 11, ["param2"] = 21, ["y"] = 1, ["param1"] = 221, ["z"] = 18, ["name"] = "stairs:slab_pine_wood"}, {["x"] = 11, ["param2"] = 21, ["y"] = 1, ["param1"] = 221, ["z"] = 19, ["name"] = "stairs:slab_pine_wood"}, {["x"] = 11, ["param2"] = 21, ["y"] = 1, ["param1"] = 221, ["z"] = 20, ["name"] = "stairs:slab_pine_wood"}, {["x"] = 11, ["y"] = 1, ["z"] = 21, ["name"] = "default:dirt"}, {["x"] = 11, ["y"] = 1, ["z"] = 22, ["name"] = "default:dirt_with_grass"}, {["x"] = 11, ["y"] = 2, ["param1"] = 205, ["z"] = 4, ["name"] = "default:obsidian_glass"}, {["x"] = 11, ["param2"] = 15, ["y"] = 2, ["param1"] = 204, ["z"] = 5, ["name"] = "default:water_flowing"}, {["x"] = 11, ["param2"] = 15, ["y"] = 2, ["param1"] = 204, ["z"] = 6, ["name"] = "default:water_flowing"}, {["x"] = 11, ["param2"] = 15, ["y"] = 2, ["param1"] = 204, ["z"] = 7, ["name"] = "default:water_flowing"}, {["x"] = 11, ["param2"] = 15, ["y"] = 2, ["param1"] = 204, ["z"] = 8, ["name"] = "default:water_flowing"}, {["x"] = 11, ["param2"] = 15, ["y"] = 2, ["param1"] = 204, ["z"] = 9, ["name"] = "default:water_flowing"}, {["x"] = 11, ["param2"] = 15, ["y"] = 2, ["param1"] = 204, ["z"] = 13, ["name"] = "default:water_flowing"}, {["x"] = 11, ["param2"] = 15, ["y"] = 2, ["param1"] = 204, ["z"] = 14, ["name"] = "default:water_flowing"}, {["x"] = 11, ["param2"] = 15, ["y"] = 2, ["param1"] = 204, ["z"] = 15, ["name"] = "default:water_flowing"}, {["x"] = 11, ["param2"] = 15, ["y"] = 2, ["param1"] = 204, ["z"] = 16, ["name"] = "default:water_flowing"}, {["x"] = 11, ["y"] = 2, ["z"] = 19, ["name"] = "default:silver_sandstone"}, {["x"] = 11, ["y"] = 2, ["z"] = 21, ["name"] = "default:silver_sandstone"}, {["x"] = 11, ["y"] = 3, ["param1"] = 189, ["z"] = 4, ["name"] = "default:obsidian_glass"}, {["x"] = 11, ["param2"] = 15, ["y"] = 3, ["param1"] = 188, ["z"] = 5, ["name"] = "default:water_flowing"}, {["x"] = 11, ["param2"] = 15, ["y"] = 3, ["param1"] = 188, ["z"] = 6, ["name"] = "default:water_flowing"}, {["x"] = 11, ["param2"] = 15, ["y"] = 3, ["param1"] = 188, ["z"] = 7, ["name"] = "default:water_flowing"}, {["x"] = 11, ["param2"] = 15, ["y"] = 3, ["param1"] = 188, ["z"] = 8, ["name"] = "default:water_flowing"}, {["x"] = 11, ["param2"] = 15, ["y"] = 3, ["param1"] = 187, ["z"] = 9, ["name"] = "default:water_flowing"}, {["x"] = 11, ["param2"] = 15, ["y"] = 3, ["param1"] = 188, ["z"] = 13, ["name"] = "default:water_flowing"}, {["x"] = 11, ["param2"] = 15, ["y"] = 3, ["param1"] = 188, ["z"] = 14, ["name"] = "default:water_flowing"}, {["x"] = 11, ["param2"] = 15, ["y"] = 3, ["param1"] = 188, ["z"] = 15, ["name"] = "default:water_flowing"}, {["x"] = 11, ["param2"] = 15, ["y"] = 3, ["param1"] = 188, ["z"] = 16, ["name"] = "default:water_flowing"}, {["x"] = 11, ["y"] = 3, ["z"] = 19, ["name"] = "default:silver_sandstone"}, {["x"] = 11, ["y"] = 3, ["z"] = 21, ["name"] = "default:silver_sandstone"}, {["x"] = 11, ["y"] = 4, ["param1"] = 173, ["z"] = 4, ["name"] = "default:obsidian_glass"}, {["x"] = 11, ["param2"] = 15, ["y"] = 4, ["param1"] = 172, ["z"] = 5, ["name"] = "default:water_flowing"}, {["x"] = 11, ["param2"] = 15, ["y"] = 4, ["param1"] = 172, ["z"] = 6, ["name"] = "default:water_flowing"}, {["x"] = 11, ["param2"] = 15, ["y"] = 4, ["param1"] = 172, ["z"] = 7, ["name"] = "default:water_flowing"}, {["x"] = 11, ["param2"] = 15, ["y"] = 4, ["param1"] = 172, ["z"] = 8, ["name"] = "default:water_flowing"}, {["x"] = 11, ["param2"] = 15, ["y"] = 4, ["param1"] = 171, ["z"] = 9, ["name"] = "default:water_flowing"}, {["x"] = 11, ["param2"] = 21, ["y"] = 4, ["z"] = 12, ["name"] = "default:silver_sandstone"}, {["x"] = 11, ["y"] = 4, ["param1"] = 172, ["z"] = 13, ["name"] = "default:water_source"}, {["x"] = 11, ["y"] = 4, ["param1"] = 172, ["z"] = 14, ["name"] = "default:water_source"}, {["x"] = 11, ["y"] = 4, ["param1"] = 172, ["z"] = 15, ["name"] = "default:water_source"}, {["x"] = 11, ["y"] = 4, ["param1"] = 172, ["z"] = 16, ["name"] = "default:water_source"}, {["x"] = 11, ["param2"] = 23, ["y"] = 4, ["z"] = 17, ["name"] = "default:silver_sandstone"}, {["x"] = 11, ["param2"] = 23, ["y"] = 4, ["param1"] = 173, ["z"] = 18, ["name"] = "stairs:slab_silver_sandstone"}, {["x"] = 11, ["y"] = 4, ["z"] = 19, ["name"] = "default:silver_sandstone"}, {["x"] = 11, ["param2"] = 23, ["y"] = 4, ["param1"] = 174, ["z"] = 20, ["name"] = "stairs:slab_silver_sandstone"}, {["x"] = 11, ["y"] = 4, ["z"] = 21, ["name"] = "default:silver_sandstone"}, {["x"] = 11, ["y"] = 5, ["z"] = 3, ["name"] = "default:silver_sandstone"}, {["x"] = 11, ["y"] = 5, ["z"] = 4, ["name"] = "default:pine_wood"}, {["x"] = 11, ["param2"] = 15, ["y"] = 5, ["param1"] = 155, ["z"] = 5, ["name"] = "default:water_flowing"}, {["x"] = 11, ["param2"] = 15, ["y"] = 5, ["param1"] = 155, ["z"] = 6, ["name"] = "default:water_flowing"}, {["x"] = 11, ["param2"] = 15, ["y"] = 5, ["param1"] = 155, ["z"] = 7, ["name"] = "default:water_flowing"}, {["x"] = 11, ["param2"] = 15, ["y"] = 5, ["param1"] = 155, ["z"] = 8, ["name"] = "default:water_flowing"}, {["x"] = 11, ["param2"] = 15, ["y"] = 5, ["param1"] = 155, ["z"] = 9, ["name"] = "default:water_flowing"}, {["x"] = 11, ["param2"] = 21, ["y"] = 5, ["param1"] = 139, ["z"] = 10, ["name"] = "stairs:slab_pine_wood"}, {["x"] = 11, ["param2"] = 21, ["y"] = 5, ["z"] = 11, ["name"] = "default:pine_wood"}, {["x"] = 11, ["y"] = 5, ["z"] = 12, ["name"] = "default:silver_sandstone"}, {["x"] = 11, ["y"] = 5, ["z"] = 13, ["name"] = "default:silver_sandstone"}, {["x"] = 11, ["y"] = 5, ["z"] = 14, ["name"] = "default:silver_sandstone"}, {["x"] = 11, ["y"] = 5, ["z"] = 15, ["name"] = "default:silver_sandstone"}, {["x"] = 11, ["y"] = 5, ["z"] = 16, ["name"] = "default:silver_sandstone"}, {["x"] = 11, ["y"] = 5, ["z"] = 17, ["name"] = "default:silver_sandstone"}, {["x"] = 11, ["y"] = 5, ["z"] = 18, ["name"] = "default:silver_sandstone"}, {["x"] = 11, ["y"] = 5, ["z"] = 21, ["name"] = "default:silver_sandstone"}, {["x"] = 11, ["y"] = 6, ["param1"] = 125, ["z"] = 4, ["name"] = "default:obsidian_glass"}, {["x"] = 11, ["param2"] = 15, ["y"] = 6, ["param1"] = 140, ["z"] = 5, ["name"] = "default:water_flowing"}, {["x"] = 11, ["param2"] = 15, ["y"] = 6, ["param1"] = 140, ["z"] = 6, ["name"] = "default:water_flowing"}, {["x"] = 11, ["param2"] = 15, ["y"] = 6, ["param1"] = 140, ["z"] = 7, ["name"] = "default:water_flowing"}, {["x"] = 11, ["param2"] = 15, ["y"] = 6, ["param1"] = 140, ["z"] = 8, ["name"] = "default:water_flowing"}, {["x"] = 11, ["param2"] = 15, ["y"] = 6, ["param1"] = 140, ["z"] = 9, ["name"] = "default:water_flowing"}, {["x"] = 11, ["y"] = 6, ["z"] = 11, ["name"] = "default:pine_wood"}, {["x"] = 11, ["y"] = 6, ["param1"] = 127, ["z"] = 18, ["name"] = "xpanes:pane_flat"}, {["x"] = 11, ["param2"] = 1, ["y"] = 6, ["param1"] = 126, ["z"] = 21, ["name"] = "default:aspen_leaves"}, {["x"] = 11, ["y"] = 7, ["param1"] = 109, ["z"] = 4, ["name"] = "default:obsidian_glass"}, {["x"] = 11, ["param2"] = 15, ["y"] = 7, ["param1"] = 124, ["z"] = 5, ["name"] = "default:water_flowing"}, {["x"] = 11, ["param2"] = 15, ["y"] = 7, ["param1"] = 124, ["z"] = 6, ["name"] = "default:water_flowing"}, {["x"] = 11, ["param2"] = 15, ["y"] = 7, ["param1"] = 124, ["z"] = 7, ["name"] = "default:water_flowing"}, {["x"] = 11, ["param2"] = 15, ["y"] = 7, ["param1"] = 124, ["z"] = 8, ["name"] = "default:water_flowing"}, {["x"] = 11, ["param2"] = 15, ["y"] = 7, ["param1"] = 124, ["z"] = 9, ["name"] = "default:water_flowing"}, {["x"] = 11, ["y"] = 7, ["z"] = 11, ["name"] = "default:pine_wood"}, {["x"] = 11, ["y"] = 8, ["param1"] = 93, ["z"] = 4, ["name"] = "default:obsidian_glass"}, {["x"] = 11, ["param2"] = 15, ["y"] = 8, ["param1"] = 108, ["z"] = 5, ["name"] = "default:water_flowing"}, {["x"] = 11, ["param2"] = 15, ["y"] = 8, ["param1"] = 108, ["z"] = 6, ["name"] = "default:water_flowing"}, {["x"] = 11, ["param2"] = 15, ["y"] = 8, ["param1"] = 108, ["z"] = 7, ["name"] = "default:water_flowing"}, {["x"] = 11, ["param2"] = 15, ["y"] = 8, ["param1"] = 108, ["z"] = 8, ["name"] = "default:water_flowing"}, {["x"] = 11, ["param2"] = 15, ["y"] = 8, ["param1"] = 108, ["z"] = 9, ["name"] = "default:water_flowing"}, {["x"] = 11, ["y"] = 8, ["z"] = 11, ["name"] = "default:pine_wood"}, {["x"] = 11, ["y"] = 9, ["param1"] = 77, ["z"] = 4, ["name"] = "default:obsidian_glass"}, {["x"] = 11, ["param2"] = 15, ["y"] = 9, ["param1"] = 93, ["z"] = 5, ["name"] = "default:water_flowing"}, {["x"] = 11, ["param2"] = 15, ["y"] = 9, ["param1"] = 93, ["z"] = 6, ["name"] = "default:water_flowing"}, {["x"] = 11, ["param2"] = 15, ["y"] = 9, ["param1"] = 93, ["z"] = 7, ["name"] = "default:water_flowing"}, {["x"] = 11, ["param2"] = 15, ["y"] = 9, ["param1"] = 93, ["z"] = 8, ["name"] = "default:water_flowing"}, {["x"] = 11, ["param2"] = 15, ["y"] = 9, ["param1"] = 93, ["z"] = 9, ["name"] = "default:water_flowing"}, {["x"] = 11, ["y"] = 9, ["z"] = 11, ["name"] = "default:pine_wood"}, {["x"] = 11, ["y"] = 10, ["z"] = 3, ["name"] = "default:silver_sandstone"}, {["x"] = 11, ["param2"] = 3, ["y"] = 10, ["param1"] = 62, ["z"] = 4, ["name"] = "stairs:slab_silver_sandstone"}, {["x"] = 11, ["y"] = 10, ["param1"] = 78, ["z"] = 5, ["name"] = "default:water_source"}, {["x"] = 11, ["y"] = 10, ["param1"] = 78, ["z"] = 6, ["name"] = "default:water_source"}, {["x"] = 11, ["y"] = 10, ["param1"] = 78, ["z"] = 7, ["name"] = "default:water_source"}, {["x"] = 11, ["y"] = 10, ["param1"] = 78, ["z"] = 8, ["name"] = "default:water_source"}, {["x"] = 11, ["y"] = 10, ["param1"] = 78, ["z"] = 9, ["name"] = "default:water_source"}, {["x"] = 11, ["y"] = 10, ["param1"] = 62, ["z"] = 10, ["name"] = "stairs:slab_silver_sandstone"}, {["x"] = 11, ["param2"] = 1, ["y"] = 10, ["param1"] = 46, ["z"] = 11, ["name"] = "stairs:slab_silver_sandstone"}, {["x"] = 11, ["y"] = 10, ["z"] = 12, ["name"] = "default:silver_sandstone"}, {["x"] = 12, ["y"] = 0, ["param1"] = 174, ["z"] = 0, ["name"] = "default:stone"}, {["x"] = 12, ["y"] = 0, ["param1"] = 189, ["z"] = 1, ["name"] = "default:stone"}, {["x"] = 12, ["y"] = 0, ["param1"] = 204, ["z"] = 2, ["name"] = "default:stone"}, {["x"] = 12, ["y"] = 0, ["param1"] = 221, ["z"] = 3, ["name"] = "default:stone"}, {["x"] = 12, ["y"] = 0, ["param1"] = 238, ["z"] = 4, ["name"] = "default:meselamp"}, {["x"] = 12, ["param2"] = 15, ["y"] = 0, ["param1"] = 238, ["z"] = 5, ["name"] = "default:meselamp"}, {["x"] = 12, ["y"] = 0, ["param1"] = 238, ["z"] = 6, ["name"] = "default:meselamp"}, {["x"] = 12, ["y"] = 0, ["param1"] = 238, ["z"] = 7, ["name"] = "default:meselamp"}, {["x"] = 12, ["y"] = 0, ["param1"] = 238, ["z"] = 8, ["name"] = "default:meselamp"}, {["x"] = 12, ["y"] = 0, ["param1"] = 238, ["z"] = 9, ["name"] = "default:meselamp"}, {["x"] = 12, ["y"] = 0, ["param1"] = 238, ["z"] = 10, ["name"] = "default:meselamp"}, {["x"] = 12, ["y"] = 0, ["param1"] = 238, ["z"] = 11, ["name"] = "default:meselamp"}, {["x"] = 12, ["y"] = 0, ["param1"] = 238, ["z"] = 12, ["name"] = "default:meselamp"}, {["x"] = 12, ["y"] = 0, ["param1"] = 238, ["z"] = 13, ["name"] = "default:meselamp"}, {["x"] = 12, ["y"] = 0, ["param1"] = 238, ["z"] = 14, ["name"] = "default:meselamp"}, {["x"] = 12, ["y"] = 0, ["param1"] = 238, ["z"] = 15, ["name"] = "default:meselamp"}, {["x"] = 12, ["y"] = 0, ["param1"] = 238, ["z"] = 16, ["name"] = "default:meselamp"}, {["x"] = 12, ["y"] = 0, ["param1"] = 238, ["z"] = 17, ["name"] = "default:meselamp"}, {["x"] = 12, ["y"] = 0, ["param1"] = 238, ["z"] = 18, ["name"] = "default:meselamp"}, {["x"] = 12, ["y"] = 0, ["param1"] = 238, ["z"] = 19, ["name"] = "default:meselamp"}, {["x"] = 12, ["y"] = 0, ["param1"] = 238, ["z"] = 20, ["name"] = "default:meselamp"}, {["x"] = 12, ["y"] = 0, ["param1"] = 221, ["z"] = 21, ["name"] = "default:stone"}, {["x"] = 12, ["y"] = 0, ["param1"] = 206, ["z"] = 22, ["name"] = "default:stone"}, {["x"] = 12, ["y"] = 1, ["z"] = 0, ["name"] = "default:dirt_with_grass"}, {["x"] = 12, ["y"] = 1, ["z"] = 1, ["name"] = "default:dirt_with_grass"}, {["x"] = 12, ["y"] = 1, ["z"] = 2, ["name"] = "default:dirt_with_grass"}, {["x"] = 12, ["y"] = 1, ["z"] = 3, ["name"] = "default:silver_sandstone"}, {["x"] = 12, ["param2"] = 21, ["y"] = 1, ["param1"] = 221, ["z"] = 4, ["name"] = "stairs:slab_pine_wood"}, {["x"] = 12, ["param2"] = 7, ["y"] = 1, ["param1"] = 221, ["z"] = 5, ["name"] = "default:water_flowing"}, {["x"] = 12, ["y"] = 1, ["z"] = 6, ["name"] = "default:pine_wood"}, {["x"] = 12, ["param2"] = 21, ["y"] = 1, ["param1"] = 221, ["z"] = 7, ["name"] = "stairs:slab_pine_wood"}, {["x"] = 12, ["param2"] = 21, ["y"] = 1, ["param1"] = 221, ["z"] = 8, ["name"] = "stairs:slab_pine_wood"}, {["x"] = 12, ["param2"] = 21, ["y"] = 1, ["param1"] = 221, ["z"] = 9, ["name"] = "stairs:slab_pine_wood"}, {["x"] = 12, ["param2"] = 21, ["y"] = 1, ["param1"] = 221, ["z"] = 10, ["name"] = "stairs:slab_pine_wood"}, {["x"] = 12, ["param2"] = 21, ["y"] = 1, ["param1"] = 221, ["z"] = 11, ["name"] = "stairs:slab_pine_wood"}, {["x"] = 12, ["param2"] = 23, ["y"] = 1, ["param1"] = 221, ["z"] = 12, ["name"] = "stairs:slab_pine_wood"}, {["x"] = 12, ["param2"] = 23, ["y"] = 1, ["param1"] = 221, ["z"] = 13, ["name"] = "stairs:slab_pine_wood"}, {["x"] = 12, ["param2"] = 23, ["y"] = 1, ["param1"] = 221, ["z"] = 14, ["name"] = "stairs:slab_pine_wood"}, {["x"] = 12, ["param2"] = 21, ["y"] = 1, ["param1"] = 221, ["z"] = 15, ["name"] = "stairs:slab_pine_wood"}, {["x"] = 12, ["param2"] = 21, ["y"] = 1, ["param1"] = 221, ["z"] = 16, ["name"] = "stairs:slab_pine_wood"}, {["x"] = 12, ["param2"] = 21, ["y"] = 1, ["param1"] = 221, ["z"] = 17, ["name"] = "stairs:slab_pine_wood"}, {["x"] = 12, ["param2"] = 21, ["y"] = 1, ["param1"] = 221, ["z"] = 18, ["name"] = "stairs:slab_pine_wood"}, {["x"] = 12, ["param2"] = 21, ["y"] = 1, ["param1"] = 221, ["z"] = 19, ["name"] = "stairs:slab_pine_wood"}, {["x"] = 12, ["param2"] = 23, ["y"] = 1, ["param1"] = 221, ["z"] = 20, ["name"] = "stairs:slab_pine_wood"}, {["x"] = 12, ["y"] = 1, ["z"] = 21, ["name"] = "default:dirt"}, {["x"] = 12, ["y"] = 1, ["z"] = 22, ["name"] = "default:dirt_with_grass"}, {["x"] = 12, ["y"] = 2, ["param1"] = 205, ["z"] = 4, ["name"] = "default:obsidian_glass"}, {["x"] = 12, ["param2"] = 15, ["y"] = 2, ["param1"] = 204, ["z"] = 5, ["name"] = "default:water_flowing"}, {["x"] = 12, ["y"] = 2, ["z"] = 19, ["name"] = "default:silver_sandstone"}, {["x"] = 12, ["meta"] = {["fields"] = {["state"] = "0"}, ["inventory"] = {}}, ["param2"] = 3, ["y"] = 2, ["param1"] = 204, ["z"] = 20, ["name"] = "doors:door_wood_a"}, {["x"] = 12, ["y"] = 2, ["z"] = 21, ["name"] = "default:silver_sandstone"}, {["x"] = 12, ["y"] = 3, ["param1"] = 189, ["z"] = 4, ["name"] = "default:obsidian_glass"}, {["x"] = 12, ["param2"] = 15, ["y"] = 3, ["param1"] = 188, ["z"] = 5, ["name"] = "default:water_flowing"}, {["x"] = 12, ["y"] = 3, ["z"] = 19, ["name"] = "default:silver_sandstone"}, {["x"] = 12, ["param2"] = 3, ["y"] = 3, ["param1"] = 188, ["z"] = 20, ["name"] = "doors:hidden"}, {["x"] = 12, ["y"] = 3, ["z"] = 21, ["name"] = "default:silver_sandstone"}, {["x"] = 12, ["y"] = 4, ["param1"] = 173, ["z"] = 4, ["name"] = "default:obsidian_glass"}, {["x"] = 12, ["param2"] = 15, ["y"] = 4, ["param1"] = 172, ["z"] = 5, ["name"] = "default:water_flowing"}, {["x"] = 12, ["param2"] = 21, ["y"] = 4, ["z"] = 12, ["name"] = "default:silver_sandstone"}, {["x"] = 12, ["y"] = 4, ["z"] = 13, ["name"] = "default:silver_sandstone"}, {["x"] = 12, ["y"] = 4, ["z"] = 14, ["name"] = "default:silver_sandstone"}, {["x"] = 12, ["y"] = 4, ["z"] = 15, ["name"] = "default:silver_sandstone"}, {["x"] = 12, ["y"] = 4, ["z"] = 16, ["name"] = "default:silver_sandstone"}, {["x"] = 12, ["param2"] = 23, ["y"] = 4, ["z"] = 17, ["name"] = "default:silver_sandstone"}, {["x"] = 12, ["param2"] = 20, ["y"] = 4, ["param1"] = 174, ["z"] = 18, ["name"] = "stairs:slab_silver_sandstone"}, {["x"] = 12, ["y"] = 4, ["z"] = 19, ["name"] = "default:silver_sandstone"}, {["x"] = 12, ["y"] = 4, ["z"] = 20, ["name"] = "default:silver_sandstone"}, {["x"] = 12, ["y"] = 4, ["z"] = 21, ["name"] = "default:silver_sandstone"}, {["x"] = 12, ["y"] = 5, ["z"] = 3, ["name"] = "default:silver_sandstone"}, {["x"] = 12, ["y"] = 5, ["z"] = 4, ["name"] = "default:pine_wood"}, {["x"] = 12, ["param2"] = 15, ["y"] = 5, ["param1"] = 155, ["z"] = 5, ["name"] = "default:water_flowing"}, {["x"] = 12, ["param2"] = 21, ["y"] = 5, ["z"] = 6, ["name"] = "default:pine_wood"}, {["x"] = 12, ["param2"] = 21, ["y"] = 5, ["z"] = 7, ["name"] = "default:pine_wood"}, {["x"] = 12, ["param2"] = 21, ["y"] = 5, ["z"] = 8, ["name"] = "default:pine_wood"}, {["x"] = 12, ["param2"] = 21, ["y"] = 5, ["z"] = 9, ["name"] = "default:pine_wood"}, {["x"] = 12, ["param2"] = 21, ["y"] = 5, ["param1"] = 155, ["z"] = 10, ["name"] = "stairs:slab_pine_wood"}, {["x"] = 12, ["y"] = 5, ["z"] = 11, ["name"] = "default:pine_wood"}, {["x"] = 12, ["param2"] = 2, ["y"] = 5, ["param1"] = 142, ["z"] = 12, ["name"] = "stairs:stair_silver_sandstone"}, {["x"] = 12, ["y"] = 5, ["z"] = 21, ["name"] = "default:silver_sandstone"}, {["x"] = 12, ["y"] = 6, ["param1"] = 125, ["z"] = 4, ["name"] = "default:obsidian_glass"}, {["x"] = 12, ["param2"] = 15, ["y"] = 6, ["param1"] = 140, ["z"] = 5, ["name"] = "default:water_flowing"}, {["x"] = 12, ["meta"] = {["fields"] = {["infotext"] = "\27(T@default)Chest\27E"}, ["inventory"] = {["main"] = {"", "", "", "", "", "", "", "", "", "", "", "", "", "", "", "", "", "", "", "", "", "", "", "", "", "", "", "", "", "", "", ""}}}, ["param2"] = 2, ["y"] = 6, ["param1"] = 123, ["z"] = 6, ["name"] = "default:chest"}, {["x"] = 12, ["param2"] = 1, ["y"] = 6, ["param1"] = 110, ["z"] = 21, ["name"] = "default:aspen_leaves"}, {["x"] = 12, ["y"] = 7, ["param1"] = 109, ["z"] = 4, ["name"] = "default:obsidian_glass"}, {["x"] = 12, ["param2"] = 15, ["y"] = 7, ["param1"] = 124, ["z"] = 5, ["name"] = "default:water_flowing"}, {["x"] = 12, ["y"] = 8, ["param1"] = 93, ["z"] = 4, ["name"] = "default:obsidian_glass"}, {["x"] = 12, ["param2"] = 15, ["y"] = 8, ["param1"] = 108, ["z"] = 5, ["name"] = "default:water_flowing"}, {["x"] = 12, ["y"] = 8, ["z"] = 11, ["name"] = "default:pine_wood"}, {["x"] = 12, ["y"] = 9, ["param1"] = 77, ["z"] = 4, ["name"] = "default:obsidian_glass"}, {["x"] = 12, ["param2"] = 15, ["y"] = 9, ["param1"] = 93, ["z"] = 5, ["name"] = "default:water_flowing"}, {["x"] = 12, ["y"] = 9, ["z"] = 11, ["name"] = "default:pine_wood"}, {["x"] = 12, ["y"] = 10, ["z"] = 3, ["name"] = "default:silver_sandstone"}, {["x"] = 12, ["param2"] = 2, ["y"] = 10, ["param1"] = 62, ["z"] = 4, ["name"] = "stairs:slab_silver_sandstone"}, {["x"] = 12, ["param2"] = 240, ["y"] = 10, ["param1"] = 78, ["z"] = 5, ["name"] = "default:water_source"}, {["x"] = 12, ["param2"] = 3, ["y"] = 10, ["param1"] = 62, ["z"] = 6, ["name"] = "stairs:slab_silver_sandstone"}, {["x"] = 12, ["y"] = 10, ["param1"] = 62, ["z"] = 7, ["name"] = "stairs:slab_silver_sandstone"}, {["x"] = 12, ["y"] = 10, ["param1"] = 62, ["z"] = 8, ["name"] = "stairs:slab_silver_sandstone"}, {["x"] = 12, ["y"] = 10, ["param1"] = 62, ["z"] = 9, ["name"] = "stairs:slab_silver_sandstone"}, {["x"] = 12, ["y"] = 10, ["param1"] = 78, ["z"] = 10, ["name"] = "stairs:slab_silver_sandstone"}, {["x"] = 12, ["y"] = 10, ["param1"] = 62, ["z"] = 11, ["name"] = "stairs:slab_silver_sandstone"}, {["x"] = 12, ["y"] = 10, ["z"] = 12, ["name"] = "default:silver_sandstone"}, {["x"] = 13, ["y"] = 0, ["param1"] = 174, ["z"] = 0, ["name"] = "default:stone"}, {["x"] = 13, ["y"] = 0, ["param1"] = 189, ["z"] = 1, ["name"] = "default:stone"}, {["x"] = 13, ["y"] = 0, ["param1"] = 204, ["z"] = 2, ["name"] = "default:stone"}, {["x"] = 13, ["y"] = 0, ["param1"] = 221, ["z"] = 3, ["name"] = "default:stone"}, {["x"] = 13, ["y"] = 0, ["param1"] = 238, ["z"] = 4, ["name"] = "default:meselamp"}, {["x"] = 13, ["param2"] = 15, ["y"] = 0, ["param1"] = 238, ["z"] = 5, ["name"] = "default:meselamp"}, {["x"] = 13, ["y"] = 0, ["param1"] = 238, ["z"] = 6, ["name"] = "default:meselamp"}, {["x"] = 13, ["y"] = 0, ["param1"] = 238, ["z"] = 7, ["name"] = "default:meselamp"}, {["x"] = 13, ["y"] = 0, ["param1"] = 238, ["z"] = 8, ["name"] = "default:meselamp"}, {["x"] = 13, ["y"] = 0, ["param1"] = 238, ["z"] = 9, ["name"] = "default:meselamp"}, {["x"] = 13, ["y"] = 0, ["param1"] = 238, ["z"] = 10, ["name"] = "default:meselamp"}, {["x"] = 13, ["y"] = 0, ["param1"] = 238, ["z"] = 11, ["name"] = "default:meselamp"}, {["x"] = 13, ["y"] = 0, ["param1"] = 238, ["z"] = 12, ["name"] = "default:meselamp"}, {["x"] = 13, ["y"] = 0, ["param1"] = 238, ["z"] = 13, ["name"] = "default:meselamp"}, {["x"] = 13, ["y"] = 0, ["param1"] = 238, ["z"] = 14, ["name"] = "default:meselamp"}, {["x"] = 13, ["y"] = 0, ["param1"] = 238, ["z"] = 15, ["name"] = "default:meselamp"}, {["x"] = 13, ["y"] = 0, ["param1"] = 238, ["z"] = 16, ["name"] = "default:meselamp"}, {["x"] = 13, ["y"] = 0, ["param1"] = 238, ["z"] = 17, ["name"] = "default:meselamp"}, {["x"] = 13, ["y"] = 0, ["param1"] = 238, ["z"] = 18, ["name"] = "default:meselamp"}, {["x"] = 13, ["y"] = 0, ["param1"] = 238, ["z"] = 19, ["name"] = "default:meselamp"}, {["x"] = 13, ["y"] = 0, ["param1"] = 238, ["z"] = 20, ["name"] = "default:meselamp"}, {["x"] = 13, ["y"] = 0, ["param1"] = 221, ["z"] = 21, ["name"] = "default:stone"}, {["x"] = 13, ["y"] = 0, ["param1"] = 206, ["z"] = 22, ["name"] = "default:stone"}, {["x"] = 13, ["y"] = 1, ["z"] = 0, ["name"] = "default:dirt_with_grass"}, {["x"] = 13, ["y"] = 1, ["z"] = 1, ["name"] = "default:dirt_with_grass"}, {["x"] = 13, ["y"] = 1, ["z"] = 2, ["name"] = "default:dirt_with_grass"}, {["x"] = 13, ["y"] = 1, ["z"] = 3, ["name"] = "default:silver_sandstone"}, {["x"] = 13, ["param2"] = 21, ["y"] = 1, ["param1"] = 221, ["z"] = 4, ["name"] = "stairs:slab_pine_wood"}, {["x"] = 13, ["param2"] = 7, ["y"] = 1, ["param1"] = 221, ["z"] = 5, ["name"] = "default:water_flowing"}, {["x"] = 13, ["param2"] = 21, ["y"] = 1, ["param1"] = 221, ["z"] = 6, ["name"] = "stairs:slab_pine_wood"}, {["x"] = 13, ["param2"] = 21, ["y"] = 1, ["param1"] = 221, ["z"] = 7, ["name"] = "stairs:slab_pine_wood"}, {["x"] = 13, ["param2"] = 21, ["y"] = 1, ["param1"] = 221, ["z"] = 8, ["name"] = "stairs:slab_pine_wood"}, {["x"] = 13, ["param2"] = 21, ["y"] = 1, ["param1"] = 221, ["z"] = 9, ["name"] = "stairs:slab_pine_wood"}, {["x"] = 13, ["param2"] = 21, ["y"] = 1, ["param1"] = 221, ["z"] = 10, ["name"] = "stairs:slab_pine_wood"}, {["x"] = 13, ["param2"] = 21, ["y"] = 1, ["param1"] = 221, ["z"] = 11, ["name"] = "stairs:slab_pine_wood"}, {["x"] = 13, ["param2"] = 23, ["y"] = 1, ["param1"] = 221, ["z"] = 12, ["name"] = "stairs:slab_pine_wood"}, {["x"] = 13, ["param2"] = 23, ["y"] = 1, ["param1"] = 221, ["z"] = 13, ["name"] = "stairs:slab_pine_wood"}, {["x"] = 13, ["param2"] = 23, ["y"] = 1, ["param1"] = 221, ["z"] = 14, ["name"] = "stairs:slab_pine_wood"}, {["x"] = 13, ["param2"] = 21, ["y"] = 1, ["param1"] = 221, ["z"] = 15, ["name"] = "stairs:slab_pine_wood"}, {["x"] = 13, ["param2"] = 21, ["y"] = 1, ["param1"] = 221, ["z"] = 16, ["name"] = "stairs:slab_pine_wood"}, {["x"] = 13, ["param2"] = 21, ["y"] = 1, ["param1"] = 221, ["z"] = 17, ["name"] = "stairs:slab_pine_wood"}, {["x"] = 13, ["param2"] = 21, ["y"] = 1, ["param1"] = 221, ["z"] = 18, ["name"] = "stairs:slab_pine_wood"}, {["x"] = 13, ["param2"] = 21, ["y"] = 1, ["param1"] = 221, ["z"] = 19, ["name"] = "stairs:slab_pine_wood"}, {["x"] = 13, ["param2"] = 23, ["y"] = 1, ["param1"] = 221, ["z"] = 20, ["name"] = "stairs:slab_pine_wood"}, {["x"] = 13, ["y"] = 1, ["z"] = 21, ["name"] = "default:dirt"}, {["x"] = 13, ["y"] = 1, ["z"] = 22, ["name"] = "default:dirt_with_grass"}, {["x"] = 13, ["y"] = 2, ["param1"] = 175, ["z"] = 2, ["name"] = "default:grass_1"}, {["x"] = 13, ["y"] = 2, ["param1"] = 205, ["z"] = 4, ["name"] = "default:obsidian_glass"}, {["x"] = 13, ["param2"] = 15, ["y"] = 2, ["param1"] = 204, ["z"] = 5, ["name"] = "default:water_flowing"}, {["x"] = 13, ["y"] = 2, ["z"] = 21, ["name"] = "default:silver_sandstone"}, {["x"] = 13, ["y"] = 3, ["param1"] = 189, ["z"] = 4, ["name"] = "default:obsidian_glass"}, {["x"] = 13, ["param2"] = 15, ["y"] = 3, ["param1"] = 188, ["z"] = 5, ["name"] = "default:water_flowing"}, {["x"] = 13, ["y"] = 3, ["z"] = 21, ["name"] = "default:silver_sandstone"}, {["x"] = 13, ["y"] = 4, ["param1"] = 173, ["z"] = 4, ["name"] = "default:obsidian_glass"}, {["x"] = 13, ["param2"] = 15, ["y"] = 4, ["param1"] = 172, ["z"] = 5, ["name"] = "default:water_flowing"}, {["x"] = 13, ["param2"] = 21, ["y"] = 4, ["param1"] = 173, ["z"] = 12, ["name"] = "stairs:slab_silver_sandstone"}, {["x"] = 13, ["param2"] = 23, ["y"] = 4, ["param1"] = 174, ["z"] = 13, ["name"] = "stairs:slab_silver_sandstone"}, {["x"] = 13, ["param2"] = 23, ["y"] = 4, ["param1"] = 174, ["z"] = 14, ["name"] = "stairs:slab_silver_sandstone"}, {["x"] = 13, ["param2"] = 23, ["y"] = 4, ["param1"] = 174, ["z"] = 15, ["name"] = "stairs:slab_silver_sandstone"}, {["x"] = 13, ["param2"] = 23, ["y"] = 4, ["param1"] = 174, ["z"] = 16, ["name"] = "stairs:slab_silver_sandstone"}, {["x"] = 13, ["param2"] = 23, ["y"] = 4, ["param1"] = 174, ["z"] = 17, ["name"] = "stairs:slab_silver_sandstone"}, {["x"] = 13, ["param2"] = 20, ["y"] = 4, ["param1"] = 174, ["z"] = 18, ["name"] = "stairs:slab_silver_sandstone"}, {["x"] = 13, ["param2"] = 20, ["y"] = 4, ["param1"] = 174, ["z"] = 19, ["name"] = "stairs:slab_silver_sandstone"}, {["x"] = 13, ["param2"] = 20, ["y"] = 4, ["param1"] = 174, ["z"] = 20, ["name"] = "stairs:slab_silver_sandstone"}, {["x"] = 13, ["y"] = 4, ["z"] = 21, ["name"] = "default:silver_sandstone"}, {["x"] = 13, ["y"] = 5, ["z"] = 3, ["name"] = "default:silver_sandstone"}, {["x"] = 13, ["y"] = 5, ["z"] = 4, ["name"] = "default:pine_wood"}, {["x"] = 13, ["param2"] = 15, ["y"] = 5, ["param1"] = 155, ["z"] = 5, ["name"] = "default:water_flowing"}, {["x"] = 13, ["param2"] = 21, ["y"] = 5, ["z"] = 6, ["name"] = "default:pine_wood"}, {["x"] = 13, ["param2"] = 21, ["y"] = 5, ["param1"] = 153, ["z"] = 7, ["name"] = "stairs:slab_pine_wood"}, {["x"] = 13, ["param2"] = 21, ["y"] = 5, ["param1"] = 153, ["z"] = 8, ["name"] = "stairs:slab_pine_wood"}, {["x"] = 13, ["param2"] = 21, ["y"] = 5, ["z"] = 9, ["name"] = "default:pine_wood"}, {["x"] = 13, ["param2"] = 21, ["y"] = 5, ["param1"] = 154, ["z"] = 10, ["name"] = "stairs:slab_pine_wood"}, {["x"] = 13, ["y"] = 5, ["z"] = 11, ["name"] = "default:pine_wood"}, {["x"] = 13, ["param2"] = 2, ["y"] = 5, ["param1"] = 158, ["z"] = 12, ["name"] = "stairs:stair_silver_sandstone"}, {["x"] = 13, ["y"] = 5, ["z"] = 21, ["name"] = "default:silver_sandstone"}, {["x"] = 13, ["y"] = 6, ["param1"] = 125, ["z"] = 4, ["name"] = "default:obsidian_glass"}, {["x"] = 13, ["param2"] = 15, ["y"] = 6, ["param1"] = 140, ["z"] = 5, ["name"] = "default:water_flowing"}, {["x"] = 13, ["meta"] = {["fields"] = {["formspec"] = "size[8,8.5]bgcolor[#080808BB;true]background[5,5;1,1;gui_formbg.png;true]listcolors[#00000069;#5A5A5A;#141318;#30434C;#FFF]list[current_name;src;2.75,0.5;1,1;]list[current_name;fuel;2.75,2.5;1,1;]image[2.75,1.5;1,1;default_furnace_fire_bg.png]image[3.75,1.5;1,1;gui_furnace_arrow_bg.png^[transformR270]list[current_name;dst;4.75,0.96;2,2;]list[current_player;main;0,4.25;8,1;]list[current_player;main;0,5.5;8,3;8]listring[current_name;dst]listring[current_player;main]listring[current_name;src]listring[current_player;main]listring[current_name;fuel]listring[current_player;main]image[0,4.25;1,1;gui_hb_bg.png]image[1,4.25;1,1;gui_hb_bg.png]image[2,4.25;1,1;gui_hb_bg.png]image[3,4.25;1,1;gui_hb_bg.png]image[4,4.25;1,1;gui_hb_bg.png]image[5,4.25;1,1;gui_hb_bg.png]image[6,4.25;1,1;gui_hb_bg.png]image[7,4.25;1,1;gui_hb_bg.png]"}, ["inventory"] = {["fuel"] = {""}, ["dst"] = {"", "", "", ""}, ["src"] = {""}}}, ["param2"] = 2, ["y"] = 6, ["z"] = 6, ["name"] = "default:furnace"}, {["x"] = 13, ["y"] = 6, ["z"] = 11, ["name"] = "default:pine_wood"}, {["x"] = 13, ["param2"] = 1, ["y"] = 6, ["param1"] = 126, ["z"] = 21, ["name"] = "default:aspen_leaves"}, {["x"] = 13, ["y"] = 7, ["param1"] = 109, ["z"] = 4, ["name"] = "default:obsidian_glass"}, {["x"] = 13, ["param2"] = 15, ["y"] = 7, ["param1"] = 124, ["z"] = 5, ["name"] = "default:water_flowing"}, {["x"] = 13, ["y"] = 7, ["z"] = 11, ["name"] = "default:pine_wood"}, {["x"] = 13, ["y"] = 8, ["param1"] = 93, ["z"] = 4, ["name"] = "default:obsidian_glass"}, {["x"] = 13, ["param2"] = 15, ["y"] = 8, ["param1"] = 108, ["z"] = 5, ["name"] = "default:water_flowing"}, {["x"] = 13, ["y"] = 8, ["z"] = 11, ["name"] = "default:pine_wood"}, {["x"] = 13, ["y"] = 9, ["param1"] = 77, ["z"] = 4, ["name"] = "default:obsidian_glass"}, {["x"] = 13, ["param2"] = 15, ["y"] = 9, ["param1"] = 93, ["z"] = 5, ["name"] = "default:water_flowing"}, {["x"] = 13, ["y"] = 9, ["z"] = 11, ["name"] = "default:pine_wood"}, {["x"] = 13, ["y"] = 10, ["z"] = 3, ["name"] = "default:silver_sandstone"}, {["x"] = 13, ["param2"] = 2, ["y"] = 10, ["param1"] = 62, ["z"] = 4, ["name"] = "stairs:slab_silver_sandstone"}, {["x"] = 13, ["y"] = 10, ["param1"] = 78, ["z"] = 5, ["name"] = "default:water_source"}, {["x"] = 13, ["param2"] = 3, ["y"] = 10, ["param1"] = 62, ["z"] = 6, ["name"] = "stairs:slab_silver_sandstone"}, {["x"] = 13, ["y"] = 10, ["param1"] = 78, ["z"] = 7, ["name"] = "stairs:slab_silver_sandstone"}, {["x"] = 13, ["y"] = 10, ["param1"] = 78, ["z"] = 8, ["name"] = "stairs:slab_silver_sandstone"}, {["x"] = 13, ["y"] = 10, ["param1"] = 62, ["z"] = 9, ["name"] = "stairs:slab_silver_sandstone"}, {["x"] = 13, ["y"] = 10, ["param1"] = 78, ["z"] = 10, ["name"] = "stairs:slab_silver_sandstone"}, {["x"] = 13, ["y"] = 10, ["param1"] = 62, ["z"] = 11, ["name"] = "stairs:slab_silver_sandstone"}, {["x"] = 13, ["y"] = 10, ["z"] = 12, ["name"] = "default:silver_sandstone"}, {["x"] = 14, ["y"] = 0, ["param1"] = 174, ["z"] = 0, ["name"] = "default:stone"}, {["x"] = 14, ["y"] = 0, ["param1"] = 189, ["z"] = 1, ["name"] = "default:stone"}, {["x"] = 14, ["y"] = 0, ["param1"] = 204, ["z"] = 2, ["name"] = "default:stone"}, {["x"] = 14, ["y"] = 0, ["param1"] = 221, ["z"] = 3, ["name"] = "default:stone"}, {["x"] = 14, ["y"] = 0, ["param1"] = 238, ["z"] = 4, ["name"] = "default:meselamp"}, {["x"] = 14, ["param2"] = 15, ["y"] = 0, ["param1"] = 238, ["z"] = 5, ["name"] = "default:meselamp"}, {["x"] = 14, ["y"] = 0, ["param1"] = 238, ["z"] = 6, ["name"] = "default:meselamp"}, {["x"] = 14, ["y"] = 0, ["param1"] = 238, ["z"] = 7, ["name"] = "default:meselamp"}, {["x"] = 14, ["y"] = 0, ["param1"] = 238, ["z"] = 8, ["name"] = "default:meselamp"}, {["x"] = 14, ["y"] = 0, ["param1"] = 238, ["z"] = 9, ["name"] = "default:meselamp"}, {["x"] = 14, ["y"] = 0, ["param1"] = 238, ["z"] = 10, ["name"] = "default:meselamp"}, {["x"] = 14, ["y"] = 0, ["param1"] = 238, ["z"] = 11, ["name"] = "default:meselamp"}, {["x"] = 14, ["y"] = 0, ["param1"] = 238, ["z"] = 12, ["name"] = "default:meselamp"}, {["x"] = 14, ["y"] = 0, ["param1"] = 238, ["z"] = 13, ["name"] = "default:meselamp"}, {["x"] = 14, ["y"] = 0, ["param1"] = 238, ["z"] = 14, ["name"] = "default:meselamp"}, {["x"] = 14, ["y"] = 0, ["param1"] = 238, ["z"] = 15, ["name"] = "default:meselamp"}, {["x"] = 14, ["y"] = 0, ["param1"] = 238, ["z"] = 16, ["name"] = "default:meselamp"}, {["x"] = 14, ["y"] = 0, ["param1"] = 238, ["z"] = 17, ["name"] = "default:meselamp"}, {["x"] = 14, ["y"] = 0, ["param1"] = 238, ["z"] = 18, ["name"] = "default:meselamp"}, {["x"] = 14, ["y"] = 0, ["param1"] = 238, ["z"] = 19, ["name"] = "default:meselamp"}, {["x"] = 14, ["y"] = 0, ["param1"] = 238, ["z"] = 20, ["name"] = "default:meselamp"}, {["x"] = 14, ["y"] = 0, ["param1"] = 221, ["z"] = 21, ["name"] = "default:stone"}, {["x"] = 14, ["y"] = 0, ["param1"] = 206, ["z"] = 22, ["name"] = "default:stone"}, {["x"] = 14, ["y"] = 1, ["z"] = 0, ["name"] = "default:dirt_with_grass"}, {["x"] = 14, ["y"] = 1, ["z"] = 1, ["name"] = "default:dirt_with_grass"}, {["x"] = 14, ["y"] = 1, ["z"] = 2, ["name"] = "default:dirt_with_grass"}, {["x"] = 14, ["y"] = 1, ["z"] = 3, ["name"] = "default:silver_sandstone"}, {["x"] = 14, ["param2"] = 22, ["y"] = 1, ["param1"] = 221, ["z"] = 4, ["name"] = "stairs:slab_pine_wood"}, {["x"] = 14, ["param2"] = 7, ["y"] = 1, ["param1"] = 221, ["z"] = 5, ["name"] = "default:water_flowing"}, {["x"] = 14, ["param2"] = 21, ["y"] = 1, ["param1"] = 221, ["z"] = 6, ["name"] = "stairs:slab_pine_wood"}, {["x"] = 14, ["param2"] = 21, ["y"] = 1, ["param1"] = 221, ["z"] = 7, ["name"] = "stairs:slab_pine_wood"}, {["x"] = 14, ["param2"] = 21, ["y"] = 1, ["param1"] = 221, ["z"] = 8, ["name"] = "stairs:slab_pine_wood"}, {["x"] = 14, ["param2"] = 21, ["y"] = 1, ["param1"] = 221, ["z"] = 9, ["name"] = "stairs:slab_pine_wood"}, {["x"] = 14, ["param2"] = 21, ["y"] = 1, ["param1"] = 221, ["z"] = 10, ["name"] = "stairs:slab_pine_wood"}, {["x"] = 14, ["param2"] = 21, ["y"] = 1, ["param1"] = 221, ["z"] = 11, ["name"] = "stairs:slab_pine_wood"}, {["x"] = 14, ["param2"] = 23, ["y"] = 1, ["param1"] = 221, ["z"] = 12, ["name"] = "stairs:slab_pine_wood"}, {["x"] = 14, ["param2"] = 23, ["y"] = 1, ["param1"] = 221, ["z"] = 13, ["name"] = "stairs:slab_pine_wood"}, {["x"] = 14, ["param2"] = 23, ["y"] = 1, ["param1"] = 221, ["z"] = 14, ["name"] = "stairs:slab_pine_wood"}, {["x"] = 14, ["param2"] = 21, ["y"] = 1, ["param1"] = 221, ["z"] = 15, ["name"] = "stairs:slab_pine_wood"}, {["x"] = 14, ["param2"] = 21, ["y"] = 1, ["param1"] = 221, ["z"] = 16, ["name"] = "stairs:slab_pine_wood"}, {["x"] = 14, ["param2"] = 21, ["y"] = 1, ["param1"] = 221, ["z"] = 17, ["name"] = "stairs:slab_pine_wood"}, {["x"] = 14, ["param2"] = 21, ["y"] = 1, ["param1"] = 221, ["z"] = 18, ["name"] = "stairs:slab_pine_wood"}, {["x"] = 14, ["param2"] = 21, ["y"] = 1, ["param1"] = 221, ["z"] = 19, ["name"] = "stairs:slab_pine_wood"}, {["x"] = 14, ["param2"] = 23, ["y"] = 1, ["param1"] = 221, ["z"] = 20, ["name"] = "stairs:slab_pine_wood"}, {["x"] = 14, ["y"] = 1, ["z"] = 21, ["name"] = "default:dirt"}, {["x"] = 14, ["y"] = 1, ["z"] = 22, ["name"] = "default:dirt_with_grass"}, {["x"] = 14, ["y"] = 2, ["param1"] = 159, ["z"] = 1, ["name"] = "default:grass_2"}, {["x"] = 14, ["y"] = 2, ["param1"] = 205, ["z"] = 4, ["name"] = "default:obsidian_glass"}, {["x"] = 14, ["param2"] = 15, ["y"] = 2, ["param1"] = 204, ["z"] = 5, ["name"] = "default:water_flowing"}, {["x"] = 14, ["y"] = 2, ["z"] = 21, ["name"] = "default:silver_sandstone"}, {["x"] = 14, ["y"] = 3, ["param1"] = 189, ["z"] = 4, ["name"] = "default:obsidian_glass"}, {["x"] = 14, ["param2"] = 15, ["y"] = 3, ["param1"] = 188, ["z"] = 5, ["name"] = "default:water_flowing"}, {["x"] = 14, ["y"] = 3, ["z"] = 21, ["name"] = "default:silver_sandstone"}, {["x"] = 14, ["y"] = 4, ["param1"] = 173, ["z"] = 4, ["name"] = "default:obsidian_glass"}, {["x"] = 14, ["param2"] = 15, ["y"] = 4, ["param1"] = 172, ["z"] = 5, ["name"] = "default:water_flowing"}, {["x"] = 14, ["param2"] = 21, ["y"] = 4, ["param1"] = 173, ["z"] = 12, ["name"] = "stairs:slab_silver_sandstone"}, {["x"] = 14, ["param2"] = 20, ["y"] = 4, ["param1"] = 174, ["z"] = 13, ["name"] = "stairs:slab_silver_sandstone"}, {["x"] = 14, ["param2"] = 20, ["y"] = 4, ["param1"] = 174, ["z"] = 14, ["name"] = "stairs:slab_silver_sandstone"}, {["x"] = 14, ["param2"] = 20, ["y"] = 4, ["param1"] = 174, ["z"] = 15, ["name"] = "stairs:slab_silver_sandstone"}, {["x"] = 14, ["param2"] = 20, ["y"] = 4, ["param1"] = 174, ["z"] = 16, ["name"] = "stairs:slab_silver_sandstone"}, {["x"] = 14, ["param2"] = 23, ["y"] = 4, ["param1"] = 174, ["z"] = 17, ["name"] = "stairs:slab_silver_sandstone"}, {["x"] = 14, ["param2"] = 20, ["y"] = 4, ["param1"] = 174, ["z"] = 18, ["name"] = "stairs:slab_silver_sandstone"}, {["x"] = 14, ["param2"] = 20, ["y"] = 4, ["param1"] = 174, ["z"] = 19, ["name"] = "stairs:slab_silver_sandstone"}, {["x"] = 14, ["param2"] = 20, ["y"] = 4, ["param1"] = 174, ["z"] = 20, ["name"] = "stairs:slab_silver_sandstone"}, {["x"] = 14, ["y"] = 4, ["z"] = 21, ["name"] = "default:silver_sandstone"}, {["x"] = 14, ["y"] = 5, ["z"] = 3, ["name"] = "default:silver_sandstone"}, {["x"] = 14, ["y"] = 5, ["z"] = 4, ["name"] = "default:pine_wood"}, {["x"] = 14, ["param2"] = 15, ["y"] = 5, ["param1"] = 155, ["z"] = 5, ["name"] = "default:water_flowing"}, {["x"] = 14, ["param2"] = 21, ["y"] = 5, ["z"] = 6, ["name"] = "default:pine_wood"}, {["x"] = 14, ["param2"] = 21, ["y"] = 5, ["param1"] = 153, ["z"] = 7, ["name"] = "stairs:slab_pine_wood"}, {["x"] = 14, ["param2"] = 21, ["y"] = 5, ["param1"] = 153, ["z"] = 8, ["name"] = "stairs:slab_pine_wood"}, {["x"] = 14, ["param2"] = 21, ["y"] = 5, ["z"] = 9, ["name"] = "default:pine_wood"}, {["x"] = 14, ["param2"] = 21, ["y"] = 5, ["param1"] = 154, ["z"] = 10, ["name"] = "stairs:slab_pine_wood"}, {["x"] = 14, ["y"] = 5, ["z"] = 11, ["name"] = "default:pine_wood"}, {["x"] = 14, ["param2"] = 2, ["y"] = 5, ["param1"] = 158, ["z"] = 12, ["name"] = "stairs:stair_silver_sandstone"}, {["x"] = 14, ["y"] = 5, ["z"] = 21, ["name"] = "default:silver_sandstone"}, {["x"] = 14, ["y"] = 6, ["param1"] = 125, ["z"] = 4, ["name"] = "default:obsidian_glass"}, {["x"] = 14, ["param2"] = 15, ["y"] = 6, ["param1"] = 140, ["z"] = 5, ["name"] = "default:water_flowing"}, {["x"] = 14, ["y"] = 6, ["z"] = 6, ["name"] = "default:silver_sandstone"}, {["x"] = 14, ["y"] = 6, ["z"] = 7, ["name"] = "default:silver_sandstone"}, {["x"] = 14, ["y"] = 6, ["z"] = 8, ["name"] = "default:silver_sandstone"}, {["x"] = 14, ["y"] = 6, ["z"] = 9, ["name"] = "default:silver_sandstone"}, {["x"] = 14, ["y"] = 6, ["z"] = 11, ["name"] = "default:pine_wood"}, {["x"] = 14, ["param2"] = 1, ["y"] = 6, ["param1"] = 126, ["z"] = 21, ["name"] = "default:aspen_leaves"}, {["x"] = 14, ["y"] = 7, ["param1"] = 109, ["z"] = 4, ["name"] = "default:obsidian_glass"}, {["x"] = 14, ["param2"] = 15, ["y"] = 7, ["param1"] = 124, ["z"] = 5, ["name"] = "default:water_flowing"}, {["x"] = 14, ["y"] = 7, ["z"] = 6, ["name"] = "default:silver_sandstone"}, {["x"] = 14, ["y"] = 7, ["z"] = 7, ["name"] = "default:silver_sandstone"}, {["x"] = 14, ["y"] = 7, ["z"] = 8, ["name"] = "default:silver_sandstone"}, {["x"] = 14, ["y"] = 7, ["z"] = 9, ["name"] = "default:silver_sandstone"}, {["x"] = 14, ["y"] = 7, ["z"] = 11, ["name"] = "default:pine_wood"}, {["x"] = 14, ["y"] = 8, ["param1"] = 93, ["z"] = 4, ["name"] = "default:obsidian_glass"}, {["x"] = 14, ["param2"] = 15, ["y"] = 8, ["param1"] = 108, ["z"] = 5, ["name"] = "default:water_flowing"}, {["x"] = 14, ["y"] = 8, ["z"] = 6, ["name"] = "default:silver_sandstone"}, {["x"] = 14, ["y"] = 8, ["z"] = 7, ["name"] = "default:silver_sandstone"}, {["x"] = 14, ["y"] = 8, ["z"] = 8, ["name"] = "default:silver_sandstone"}, {["x"] = 14, ["y"] = 8, ["z"] = 9, ["name"] = "default:silver_sandstone"}, {["x"] = 14, ["y"] = 8, ["z"] = 11, ["name"] = "default:pine_wood"}, {["x"] = 14, ["y"] = 9, ["param1"] = 77, ["z"] = 4, ["name"] = "default:obsidian_glass"}, {["x"] = 14, ["param2"] = 15, ["y"] = 9, ["param1"] = 93, ["z"] = 5, ["name"] = "default:water_flowing"}, {["x"] = 14, ["y"] = 9, ["z"] = 6, ["name"] = "default:silver_sandstone"}, {["x"] = 14, ["y"] = 9, ["z"] = 7, ["name"] = "default:silver_sandstone"}, {["x"] = 14, ["y"] = 9, ["z"] = 8, ["name"] = "default:silver_sandstone"}, {["x"] = 14, ["y"] = 9, ["z"] = 9, ["name"] = "default:silver_sandstone"}, {["x"] = 14, ["y"] = 9, ["z"] = 11, ["name"] = "default:pine_wood"}, {["x"] = 14, ["y"] = 10, ["z"] = 3, ["name"] = "default:silver_sandstone"}, {["x"] = 14, ["param2"] = 2, ["y"] = 10, ["param1"] = 62, ["z"] = 4, ["name"] = "stairs:slab_silver_sandstone"}, {["x"] = 14, ["param2"] = 240, ["y"] = 10, ["param1"] = 78, ["z"] = 5, ["name"] = "default:water_source"}, {["x"] = 14, ["param2"] = 3, ["y"] = 10, ["param1"] = 62, ["z"] = 6, ["name"] = "stairs:slab_silver_sandstone"}, {["x"] = 14, ["y"] = 10, ["param1"] = 62, ["z"] = 7, ["name"] = "stairs:slab_silver_sandstone"}, {["x"] = 14, ["y"] = 10, ["param1"] = 62, ["z"] = 8, ["name"] = "stairs:slab_silver_sandstone"}, {["x"] = 14, ["y"] = 10, ["param1"] = 62, ["z"] = 9, ["name"] = "stairs:slab_silver_sandstone"}, {["x"] = 14, ["y"] = 10, ["param1"] = 78, ["z"] = 10, ["name"] = "stairs:slab_silver_sandstone"}, {["x"] = 14, ["y"] = 10, ["param1"] = 62, ["z"] = 11, ["name"] = "stairs:slab_silver_sandstone"}, {["x"] = 14, ["y"] = 10, ["z"] = 12, ["name"] = "default:silver_sandstone"}, {["x"] = 15, ["y"] = 0, ["param1"] = 174, ["z"] = 0, ["name"] = "default:stone"}, {["x"] = 15, ["y"] = 0, ["param1"] = 189, ["z"] = 1, ["name"] = "default:stone"}, {["x"] = 15, ["y"] = 0, ["param1"] = 204, ["z"] = 2, ["name"] = "default:stone"}, {["x"] = 15, ["y"] = 0, ["param1"] = 221, ["z"] = 3, ["name"] = "default:stone"}, {["x"] = 15, ["y"] = 0, ["param1"] = 238, ["z"] = 4, ["name"] = "default:meselamp"}, {["x"] = 15, ["param2"] = 15, ["y"] = 0, ["param1"] = 238, ["z"] = 5, ["name"] = "default:meselamp"}, {["x"] = 15, ["y"] = 0, ["param1"] = 238, ["z"] = 6, ["name"] = "default:meselamp"}, {["x"] = 15, ["y"] = 0, ["param1"] = 238, ["z"] = 7, ["name"] = "default:meselamp"}, {["x"] = 15, ["y"] = 0, ["param1"] = 238, ["z"] = 8, ["name"] = "default:meselamp"}, {["x"] = 15, ["y"] = 0, ["param1"] = 238, ["z"] = 9, ["name"] = "default:meselamp"}, {["x"] = 15, ["y"] = 0, ["param1"] = 238, ["z"] = 10, ["name"] = "default:meselamp"}, {["x"] = 15, ["y"] = 0, ["param1"] = 238, ["z"] = 11, ["name"] = "default:meselamp"}, {["x"] = 15, ["y"] = 0, ["param1"] = 238, ["z"] = 12, ["name"] = "default:meselamp"},