5:return {{["x"] = 0, ["param2"] = 1, ["y"] = 0, ["param1"] = 174, ["z"] = 6, ["name"] = "stairs:stair_pine_wood"}, {["x"] = 1, ["y"] = 0, ["z"] = 0, ["name"] = "default:silver_sandstone"}, {["x"] = 1, ["y"] = 0, ["z"] = 1, ["name"] = "default:silver_sandstone"}, {["x"] = 1, ["y"] = 0, ["z"] = 2, ["name"] = "default:silver_sandstone"}, {["x"] = 1, ["y"] = 0, ["z"] = 3, ["name"] = "default:silver_sandstone"}, {["x"] = 1, ["y"] = 0, ["z"] = 4, ["name"] = "default:silver_sandstone"}, {["x"] = 1, ["y"] = 0, ["z"] = 5, ["name"] = "default:silver_sandstone"}, {["x"] = 1, ["y"] = 0, ["z"] = 6, ["name"] = "default:silver_sandstone"}, {["x"] = 1, ["y"] = 0, ["z"] = 7, ["name"] = "default:silver_sandstone"}, {["x"] = 1, ["y"] = 0, ["z"] = 8, ["name"] = "default:silver_sandstone"}, {["x"] = 1, ["y"] = 0, ["z"] = 9, ["name"] = "default:silver_sandstone"}, {["x"] = 1, ["y"] = 0, ["z"] = 10, ["name"] = "default:silver_sandstone"}, {["x"] = 1, ["y"] = 0, ["z"] = 11, ["name"] = "default:silver_sandstone"}, {["x"] = 1, ["y"] = 0, ["z"] = 12, ["name"] = "default:silver_sandstone"}, {["x"] = 1, ["y"] = 1, ["param1"] = 14, ["z"] = 0, ["name"] = "default:silver_sandstone"}, {["x"] = 1, ["meta"] = {["fields"] = {["infotext"] = "\27(T@default)Chest\27E"}, ["inventory"] = {["main"] = {"default:dirt", "stairs:stair_inner_pine_wood", "stairs:stair_pine_wood 2", "worldedit:wand", "stairs:slab_obsidian_glass", "default:bookshelf", "beds:bed_bottom", "default:obsidian_glass", "stairs:slab_pine_wood 3", "screwdriver:screwdriver", "default:water_source", "default:furnace", "default:tree", "default:chest", "xpanes:obsidian_pane_flat", "default:silver_sandstone", "", "doors:door_obsidian_glass", "default:brick", "default:pine_bush_needles", "stairs:slab_silver_sandstone", "doors:door_wood", "default:fence_pine_wood", "default:meselamp", "default:pine_wood", "", "", "", "", "", "", ""}}}, ["param2"] = 1, ["y"] = 1, ["param1"] = 14, ["z"] = 1, ["name"] = "default:silver_sandstone"}, {["x"] = 1, ["y"] = 1, ["param1"] = 15, ["z"] = 2, ["name"] = "default:silver_sandstone"}, {["x"] = 1, ["y"] = 1, ["param1"] = 15, ["z"] = 3, ["name"] = "default:silver_sandstone"}, {["x"] = 1, ["y"] = 1, ["param1"] = 15, ["z"] = 4, ["name"] = "default:silver_sandstone"}, {["x"] = 1, ["y"] = 1, ["param1"] = 15, ["z"] = 5, ["name"] = "default:silver_sandstone"}, {["x"] = 1, ["param2"] = 1, ["y"] = 1, ["param1"] = 206, ["z"] = 6, ["name"] = "stairs:stair_pine_wood"}, {["x"] = 1, ["y"] = 1, ["param1"] = 15, ["z"] = 7, ["name"] = "default:silver_sandstone"}, {["x"] = 1, ["y"] = 1, ["param1"] = 15, ["z"] = 8, ["name"] = "default:silver_sandstone"}, {["x"] = 1, ["y"] = 1, ["param1"] = 15, ["z"] = 9, ["name"] = "default:silver_sandstone"}, {["x"] = 1, ["y"] = 1, ["param1"] = 15, ["z"] = 10, ["name"] = "default:silver_sandstone"}, {["x"] = 1, ["y"] = 1, ["param1"] = 15, ["z"] = 11, ["name"] = "default:silver_sandstone"}, {["x"] = 1, ["y"] = 1, ["param1"] = 15, ["z"] = 12, ["name"] = "default:silver_sandstone"}, {["x"] = 2, ["y"] = 0, ["z"] = 0, ["name"] = "default:silver_sandstone"}, {["x"] = 2, ["y"] = 0, ["z"] = 1, ["name"] = "default:silver_sandstone"}, {["x"] = 2, ["y"] = 0, ["z"] = 2, ["name"] = "default:silver_sandstone"}, {["x"] = 2, ["y"] = 0, ["z"] = 3, ["name"] = "default:silver_sandstone"}, {["x"] = 2, ["y"] = 0, ["z"] = 4, ["name"] = "default:silver_sandstone"}, {["x"] = 2, ["y"] = 0, ["z"] = 5, ["name"] = "default:silver_sandstone"}, {["x"] = 2, ["y"] = 0, ["param1"] = 238, ["z"] = 6, ["name"] = "default:meselamp"}, {["x"] = 2, ["y"] = 0, ["z"] = 7, ["name"] = "default:silver_sandstone"}, {["x"] = 2, ["y"] = 0, ["z"] = 8, ["name"] = "default:silver_sandstone"}, {["x"] = 2, ["y"] = 0, ["z"] = 9, ["name"] = "default:silver_sandstone"}, {["x"] = 2, ["y"] = 0, ["z"] = 10, ["name"] = "default:silver_sandstone"}, {["x"] = 2, ["y"] = 0, ["z"] = 11, ["name"] = "default:silver_sandstone"}, {["x"] = 2, ["y"] = 0, ["z"] = 12, ["name"] = "default:silver_sandstone"}, {["x"] = 2, ["y"] = 1, ["param1"] = 14, ["z"] = 0, ["name"] = "default:silver_sandstone"}, {["x"] = 2, ["y"] = 1, ["param1"] = 141, ["z"] = 1, ["name"] = "default:water_source"}, {["x"] = 2, ["y"] = 1, ["param1"] = 158, ["z"] = 2, ["name"] = "default:water_source"}, {["x"] = 2, ["y"] = 1, ["param1"] = 174, ["z"] = 3, ["name"] = "default:water_source"}, {["x"] = 2, ["y"] = 1, ["param1"] = 190, ["z"] = 4, ["name"] = "default:water_source"}, {["x"] = 2, ["y"] = 1, ["param1"] = 206, ["z"] = 5, ["name"] = "default:water_source"}, {["x"] = 2, ["param2"] = 21, ["y"] = 1, ["param1"] = 222, ["z"] = 6, ["name"] = "stairs:slab_pine_wood"}, {["x"] = 2, ["y"] = 1, ["param1"] = 206, ["z"] = 7, ["name"] = "default:water_source"}, {["x"] = 2, ["y"] = 1, ["param1"] = 190, ["z"] = 8, ["name"] = "default:water_source"}, {["x"] = 2, ["y"] = 1, ["param1"] = 174, ["z"] = 9, ["name"] = "default:water_source"}, {["x"] = 2, ["y"] = 1, ["param1"] = 158, ["z"] = 10, ["name"] = "default:water_source"}, {["x"] = 2, ["y"] = 1, ["param1"] = 142, ["z"] = 11, ["name"] = "default:water_source"}, {["x"] = 2, ["y"] = 1, ["param1"] = 15, ["z"] = 12, ["name"] = "default:silver_sandstone"}, {["x"] = 3, ["y"] = 0, ["z"] = 0, ["name"] = "default:silver_sandstone"}, {["x"] = 3, ["y"] = 0, ["z"] = 1, ["name"] = "default:silver_sandstone"}, {["x"] = 3, ["y"] = 0, ["z"] = 2, ["name"] = "default:silver_sandstone"}, {["x"] = 3, ["y"] = 0, ["z"] = 3, ["name"] = "default:silver_sandstone"}, {["x"] = 3, ["y"] = 0, ["z"] = 4, ["name"] = "default:silver_sandstone"}, {["x"] = 3, ["y"] = 0, ["z"] = 5, ["name"] = "default:silver_sandstone"}, {["x"] = 3, ["y"] = 0, ["param1"] = 238, ["z"] = 6, ["name"] = "default:meselamp"}, {["x"] = 3, ["y"] = 0, ["z"] = 7, ["name"] = "default:silver_sandstone"}, {["x"] = 3, ["y"] = 0, ["z"] = 8, ["name"] = "default:silver_sandstone"}, {["x"] = 3, ["y"] = 0, ["z"] = 9, ["name"] = "default:silver_sandstone"}, {["x"] = 3, ["y"] = 0, ["z"] = 10, ["name"] = "default:silver_sandstone"}, {["x"] = 3, ["y"] = 0, ["z"] = 11, ["name"] = "default:silver_sandstone"}, {["x"] = 3, ["y"] = 0, ["z"] = 12, ["name"] = "default:silver_sandstone"}, {["x"] = 3, ["y"] = 1, ["param1"] = 14, ["z"] = 0, ["name"] = "default:silver_sandstone"}, {["x"] = 3, ["y"] = 1, ["param1"] = 141, ["z"] = 1, ["name"] = "default:water_source"}, {["x"] = 3, ["y"] = 1, ["param1"] = 158, ["z"] = 2, ["name"] = "default:water_source"}, {["x"] = 3, ["y"] = 1, ["param1"] = 174, ["z"] = 3, ["name"] = "default:water_source"}, {["x"] = 3, ["y"] = 1, ["param1"] = 190, ["z"] = 4, ["name"] = "default:water_source"}, {["x"] = 3, ["y"] = 1, ["param1"] = 206, ["z"] = 5, ["name"] = "default:water_source"}, {["x"] = 3, ["param2"] = 21, ["y"] = 1, ["param1"] = 222, ["z"] = 6, ["name"] = "stairs:slab_pine_wood"}, {["x"] = 3, ["y"] = 1, ["param1"] = 206, ["z"] = 7, ["name"] = "default:water_source"}, {["x"] = 3, ["y"] = 1, ["param1"] = 190, ["z"] = 8, ["name"] = "default:water_source"}, {["x"] = 3, ["y"] = 1, ["param1"] = 174, ["z"] = 9, ["name"] = "default:water_source"}, {["x"] = 3, ["y"] = 1, ["param1"] = 158, ["z"] = 10, ["name"] = "default:water_source"}, {["x"] = 3, ["y"] = 1, ["param1"] = 142, ["z"] = 11, ["name"] = "default:water_source"}, {["x"] = 3, ["y"] = 1, ["param1"] = 15, ["z"] = 12, ["name"] = "default:silver_sandstone"}, {["x"] = 4, ["y"] = 0, ["z"] = 0, ["name"] = "default:silver_sandstone"}, {["x"] = 4, ["y"] = 0, ["z"] = 1, ["name"] = "default:silver_sandstone"}, {["x"] = 4, ["y"] = 0, ["z"] = 2, ["name"] = "default:silver_sandstone"}, {["x"] = 4, ["y"] = 0, ["z"] = 3, ["name"] = "default:silver_sandstone"}, {["x"] = 4, ["y"] = 0, ["z"] = 4, ["name"] = "default:silver_sandstone"}, {["x"] = 4, ["y"] = 0, ["z"] = 5, ["name"] = "default:silver_sandstone"}, {["x"] = 4, ["y"] = 0, ["z"] = 6, ["name"] = "default:silver_sandstone"}, {["x"] = 4, ["y"] = 0, ["z"] = 7, ["name"] = "default:silver_sandstone"}, {["x"] = 4, ["y"] = 0, ["z"] = 8, ["name"] = "default:silver_sandstone"}, {["x"] = 4, ["y"] = 0, ["z"] = 9, ["name"] = "default:silver_sandstone"}, {["x"] = 4, ["y"] = 0, ["z"] = 10, ["name"] = "default:silver_sandstone"}, {["x"] = 4, ["y"] = 0, ["z"] = 11, ["name"] = "default:silver_sandstone"}, {["x"] = 4, ["y"] = 0, ["z"] = 12, ["name"] = "default:silver_sandstone"}, {["x"] = 4, ["y"] = 1, ["z"] = 0, ["name"] = "default:silver_sandstone"}, {["x"] = 4, ["y"] = 1, ["z"] = 1, ["name"] = "default:silver_sandstone"}, {["x"] = 4, ["y"] = 1, ["z"] = 2, ["name"] = "default:silver_sandstone"}, {["x"] = 4, ["y"] = 1, ["z"] = 3, ["name"] = "default:silver_sandstone"}, {["x"] = 4, ["y"] = 1, ["z"] = 4, ["name"] = "default:silver_sandstone"}, {["x"] = 4, ["y"] = 1, ["z"] = 5, ["name"] = "default:pine_wood"}, {["x"] = 4, ["y"] = 1, ["z"] = 6, ["name"] = "default:pine_wood"}, {["x"] = 4, ["y"] = 1, ["z"] = 7, ["name"] = "default:pine_wood"}, {["x"] = 4, ["y"] = 1, ["z"] = 8, ["name"] = "default:silver_sandstone"}, {["x"] = 4, ["y"] = 1, ["z"] = 9, ["name"] = "default:silver_sandstone"}, {["x"] = 4, ["y"] = 1, ["z"] = 10, ["name"] = "default:silver_sandstone"}, {["x"] = 4, ["y"] = 1, ["z"] = 11, ["name"] = "default:silver_sandstone"}, {["x"] = 4, ["y"] = 1, ["z"] = 12, ["name"] = "default:silver_sandstone"}, {["x"] = 4, ["y"] = 2, ["z"] = 0, ["name"] = "default:silver_sandstone"}, {["x"] = 4, ["param2"] = 1, ["y"] = 2, ["param1"] = 109, ["z"] = 1, ["name"] = "default:aspen_leaves"}, {["x"] = 4, ["param2"] = 1, ["y"] = 2, ["param1"] = 126, ["z"] = 2, ["name"] = "default:aspen_leaves"}, {["x"] = 4, ["param2"] = 1, ["y"] = 2, ["param1"] = 142, ["z"] = 3, ["name"] = "default:aspen_leaves"}, {["x"] = 4, ["y"] = 2, ["z"] = 4, ["name"] = "default:silver_sandstone"}, {["x"] = 4, ["y"] = 2, ["z"] = 8, ["name"] = "default:silver_sandstone"}, {["x"] = 4, ["param2"] = 1, ["y"] = 2, ["param1"] = 142, ["z"] = 9, ["name"] = "default:aspen_leaves"}, {["x"] = 4, ["param2"] = 1, ["y"] = 2, ["param1"] = 126, ["z"] = 10, ["name"] = "default:aspen_leaves"}, {["x"] = 4, ["param2"] = 1, ["y"] = 2, ["param1"] = 110, ["z"] = 11, ["name"] = "default:aspen_leaves"}, {["x"] = 4, ["y"] = 2, ["z"] = 12, ["name"] = "default:silver_sandstone"}, {["x"] = 4, ["y"] = 3, ["z"] = 0, ["name"] = "default:silver_sandstone"}, {["x"] = 4, ["y"] = 3, ["z"] = 4, ["name"] = "default:silver_sandstone"}, {["x"] = 4, ["y"] = 3, ["z"] = 8, ["name"] = "default:silver_sandstone"}, {["x"] = 4, ["y"] = 3, ["z"] = 12, ["name"] = "default:silver_sandstone"}, {["x"] = 4, ["y"] = 4, ["z"] = 0, ["name"] = "default:silver_sandstone"}, {["x"] = 4, ["y"] = 4, ["z"] = 4, ["name"] = "default:silver_sandstone"}, {["x"] = 4, ["y"] = 4, ["z"] = 8, ["name"] = "default:silver_sandstone"}, {["x"] = 4, ["y"] = 4, ["z"] = 12, ["name"] = "default:silver_sandstone"}, {["x"] = 4, ["y"] = 5, ["z"] = 0, ["name"] = "default:silver_sandstone"}, {["x"] = 4, ["y"] = 5, ["z"] = 1, ["name"] = "default:silver_sandstone"}, {["x"] = 4, ["y"] = 5, ["z"] = 2, ["name"] = "default:silver_sandstone"}, {["x"] = 4, ["y"] = 5, ["z"] = 3, ["name"] = "default:silver_sandstone"}, {["x"] = 4, ["y"] = 5, ["z"] = 4, ["name"] = "default:silver_sandstone"}, {["x"] = 4, ["y"] = 5, ["z"] = 5, ["name"] = "default:silver_sandstone"}, {["x"] = 4, ["y"] = 5, ["z"] = 6, ["name"] = "default:silver_sandstone"}, {["x"] = 4, ["y"] = 5, ["z"] = 7, ["name"] = "default:silver_sandstone"}, {["x"] = 4, ["y"] = 5, ["z"] = 8, ["name"] = "default:silver_sandstone"}, {["x"] = 4, ["y"] = 5, ["z"] = 9, ["name"] = "default:silver_sandstone"}, {["x"] = 4, ["y"] = 5, ["z"] = 10, ["name"] = "default:silver_sandstone"}, {["x"] = 4, ["y"] = 5, ["z"] = 11, ["name"] = "default:silver_sandstone"}, {["x"] = 4, ["y"] = 5, ["z"] = 12, ["name"] = "default:silver_sandstone"}, {["x"] = 4, ["y"] = 6, ["z"] = 0, ["name"] = "default:silver_sandstone"}, {["x"] = 4, ["param2"] = 1, ["y"] = 6, ["param1"] = 45, ["z"] = 1, ["name"] = "default:aspen_leaves"}, {["x"] = 4, ["param2"] = 1, ["y"] = 6, ["param1"] = 62, ["z"] = 2, ["name"] = "default:aspen_leaves"}, {["x"] = 4, ["param2"] = 1, ["y"] = 6, ["param1"] = 78, ["z"] = 3, ["name"] = "default:aspen_leaves"}, {["x"] = 4, ["y"] = 6, ["z"] = 4, ["name"] = "default:silver_sandstone"}, {["x"] = 4, ["y"] = 6, ["param1"] = 110, ["z"] = 5, ["name"] = "default:fence_pine_wood"}, {["x"] = 4, ["y"] = 6, ["param1"] = 30, ["z"] = 12, ["name"] = "default:fence_pine_wood"}, {["x"] = 4, ["y"] = 7, ["z"] = 0, ["name"] = "default:silver_sandstone"}, {["x"] = 4, ["y"] = 7, ["z"] = 4, ["name"] = "default:silver_sandstone"}, {["x"] = 4, ["y"] = 7, ["param1"] = 110, ["z"] = 5, ["name"] = "default:fence_pine_wood"}, {["x"] = 4, ["y"] = 7, ["param1"] = 14, ["z"] = 12, ["name"] = "default:fence_pine_wood"}, {["x"] = 4, ["y"] = 8, ["z"] = 0, ["name"] = "default:silver_sandstone"}, {["x"] = 4, ["y"] = 8, ["z"] = 4, ["name"] = "default:silver_sandstone"}, {["x"] = 4, ["y"] = 8, ["param1"] = 125, ["z"] = 5, ["name"] = "default:fence_pine_wood"}, {["x"] = 4, ["y"] = 8, ["param1"] = 14, ["z"] = 12, ["name"] = "default:fence_pine_wood"}, {["x"] = 4, ["y"] = 9, ["z"] = 0, ["name"] = "default:silver_sandstone"}, {["x"] = 4, ["y"] = 9, ["z"] = 1, ["name"] = "default:silver_sandstone"}, {["x"] = 4, ["y"] = 9, ["z"] = 2, ["name"] = "default:silver_sandstone"}, {["x"] = 4, ["y"] = 9, ["z"] = 3, ["name"] = "default:silver_sandstone"}, {["x"] = 4, ["y"] = 9, ["z"] = 4, ["name"] = "default:silver_sandstone"}, {["x"] = 4, ["y"] = 9, ["param1"] = 109, ["z"] = 5, ["name"] = "default:fence_pine_wood"}, {["x"] = 4, ["y"] = 9, ["param1"] = 13, ["z"] = 12, ["name"] = "default:fence_pine_wood"}, {["x"] = 4, ["y"] = 10, ["param1"] = 15, ["z"] = 0, ["name"] = "default:silver_sandstone"}, {["x"] = 4, ["y"] = 10, ["param1"] = 15, ["z"] = 1, ["name"] = "default:silver_sandstone"}, {["x"] = 4, ["y"] = 10, ["param1"] = 15, ["z"] = 2, ["name"] = "default:silver_sandstone"}, {["x"] = 4, ["y"] = 10, ["param1"] = 31, ["z"] = 3, ["name"] = "default:silver_sandstone"}, {["x"] = 4, ["y"] = 10, ["z"] = 4, ["name"] = "default:silver_sandstone"}, {["x"] = 4, ["y"] = 10, ["z"] = 5, ["name"] = "default:silver_sandstone"}, {["x"] = 4, ["y"] = 10, ["param1"] = 79, ["z"] = 6, ["name"] = "default:silver_sandstone"}, {["x"] = 4, ["y"] = 10, ["param1"] = 63, ["z"] = 7, ["name"] = "default:silver_sandstone"}, {["x"] = 4, ["y"] = 10, ["param1"] = 47, ["z"] = 8, ["name"] = "default:silver_sandstone"}, {["x"] = 4, ["y"] = 10, ["param1"] = 31, ["z"] = 9, ["name"] = "default:silver_sandstone"}, {["x"] = 4, ["y"] = 10, ["param1"] = 15, ["z"] = 10, ["name"] = "default:silver_sandstone"}, {["x"] = 4, ["y"] = 10, ["param1"] = 15, ["z"] = 11, ["name"] = "default:silver_sandstone"}, {["x"] = 4, ["y"] = 10, ["param1"] = 15, ["z"] = 12, ["name"] = "default:silver_sandstone"}, {["x"] = 5, ["y"] = 0, ["z"] = 0, ["name"] = "default:silver_sandstone"}, {["x"] = 5, ["y"] = 0, ["z"] = 1, ["name"] = "default:silver_sandstone"}, {["x"] = 5, ["y"] = 0, ["z"] = 2, ["name"] = "default:silver_sandstone"}, {["x"] = 5, ["y"] = 0, ["z"] = 3, ["name"] = "default:silver_sandstone"}, {["x"] = 5, ["y"] = 0, ["z"] = 4, ["name"] = "default:silver_sandstone"}, {["x"] = 5, ["y"] = 0, ["z"] = 5, ["name"] = "default:silver_sandstone"}, {["x"] = 5, ["y"] = 0, ["z"] = 6, ["name"] = "default:silver_sandstone"}, {["x"] = 5, ["y"] = 0, ["z"] = 7, ["name"] = "default:silver_sandstone"}, {["x"] = 5, ["y"] = 0, ["z"] = 8, ["name"] = "default:silver_sandstone"}, {["x"] = 5, ["y"] = 0, ["z"] = 9, ["name"] = "default:silver_sandstone"}, {["x"] = 5, ["y"] = 0, ["z"] = 10, ["name"] = "default:silver_sandstone"}, {["x"] = 5, ["y"] = 0, ["z"] = 11, ["name"] = "default:silver_sandstone"}, {["x"] = 5, ["y"] = 0, ["z"] = 12, ["name"] = "default:silver_sandstone"}, {["x"] = 5, ["y"] = 1, ["z"] = 0, ["name"] = "default:silver_sandstone"}, {["x"] = 5, ["y"] = 1, ["z"] = 1, ["name"] = "default:silver_sandstone"}, {["x"] = 5, ["y"] = 1, ["param1"] = 15, ["z"] = 2, ["name"] = "default:silver_sandstone"}, {["x"] = 5, ["y"] = 1, ["param1"] = 15, ["z"] = 3, ["name"] = "default:silver_sandstone"}, {["x"] = 5, ["y"] = 1, ["param1"] = 15, ["z"] = 4, ["name"] = "default:silver_sandstone"}, {["x"] = 5, ["y"] = 1, ["z"] = 5, ["name"] = "default:pine_wood"}, {["x"] = 5, ["y"] = 1, ["z"] = 6, ["name"] = "default:pine_wood"}, {["x"] = 5, ["y"] = 1, ["z"] = 7, ["name"] = "default:pine_wood"}, {["x"] = 5, ["y"] = 1, ["param1"] = 15, ["z"] = 8, ["name"] = "default:silver_sandstone"}, {["x"] = 5, ["y"] = 1, ["param1"] = 15, ["z"] = 9, ["name"] = "default:silver_sandstone"}, {["x"] = 5, ["y"] = 1, ["param1"] = 15, ["z"] = 10, ["name"] = "default:silver_sandstone"}, {["x"] = 5, ["y"] = 1, ["param1"] = 15, ["z"] = 11, ["name"] = "default:silver_sandstone"}, {["x"] = 5, ["y"] = 1, ["param1"] = 15, ["z"] = 12, ["name"] = "default:silver_sandstone"}, {["x"] = 5, ["param2"] = 1, ["y"] = 2, ["param1"] = 46, ["z"] = 0, ["name"] = "default:aspen_leaves"}, {["x"] = 5, ["y"] = 2, ["param1"] = 14, ["z"] = 1, ["name"] = "default:pine_wood"}, {["x"] = 5, ["y"] = 2, ["param1"] = 15, ["z"] = 2, ["name"] = "default:pine_wood"}, {["x"] = 5, ["y"] = 2, ["param1"] = 15, ["z"] = 3, ["name"] = "default:pine_wood"}, {["x"] = 5, ["y"] = 2, ["param1"] = 15, ["z"] = 4, ["name"] = "default:pine_wood"}, {["x"] = 5, ["y"] = 2, ["z"] = 5, ["name"] = "default:pine_wood"}, {["x"] = 5, ["meta"] = {["fields"] = {["state"] = "0"}, ["inventory"] = {}}, ["param2"] = 1, ["y"] = 2, ["param1"] = 174, ["z"] = 6, ["name"] = "doors:door_obsidian_glass_a"}, {["x"] = 5, ["y"] = 2, ["param1"] = 15, ["z"] = 7, ["name"] = "default:pine_wood"}, {["x"] = 5, ["y"] = 2, ["param1"] = 15, ["z"] = 8, ["name"] = "default:pine_wood"}, {["x"] = 5, ["y"] = 2, ["param1"] = 15, ["z"] = 9, ["name"] = "default:pine_wood"}, {["x"] = 5, ["y"] = 2, ["param1"] = 15, ["z"] = 10, ["name"] = "default:pine_wood"}, {["x"] = 5, ["y"] = 2, ["param1"] = 15, ["z"] = 11, ["name"] = "default:pine_wood"}, {["x"] = 5, ["y"] = 2, ["param1"] = 15, ["z"] = 12, ["name"] = "default:silver_sandstone"}, {["x"] = 5, ["y"] = 3, ["param1"] = 14, ["z"] = 1, ["name"] = "default:pine_wood"}, {["x"] = 5, ["y"] = 3, ["param1"] = 93, ["z"] = 2, ["name"] = "default:obsidian_glass"}, {["x"] = 5, ["y"] = 3, ["param1"] = 15, ["z"] = 3, ["name"] = "default:pine_wood"}, {["x"] = 5, ["y"] = 3, ["param1"] = 15, ["z"] = 4, ["name"] = "default:pine_wood"}, {["x"] = 5, ["y"] = 3, ["param1"] = 15, ["z"] = 5, ["name"] = "default:pine_wood"}, {["x"] = 5, ["param2"] = 1, ["y"] = 3, ["param1"] = 158, ["z"] = 6, ["name"] = "doors:hidden"}, {["x"] = 5, ["y"] = 3, ["param1"] = 15, ["z"] = 7, ["name"] = "default:pine_wood"}, {["x"] = 5, ["y"] = 3, ["param1"] = 15, ["z"] = 8, ["name"] = "default:pine_wood"}, {["x"] = 5, ["y"] = 3, ["param1"] = 15, ["z"] = 9, ["name"] = "default:pine_wood"}, {["x"] = 5, ["y"] = 3, ["z"] = 10, ["name"] = "default:pine_wood"}, {["x"] = 5, ["y"] = 3, ["param1"] = 15, ["z"] = 11, ["name"] = "default:pine_wood"}, {["x"] = 5, ["y"] = 3, ["param1"] = 15, ["z"] = 12, ["name"] = "default:silver_sandstone"}, {["x"] = 5, ["y"] = 4, ["z"] = 1, ["name"] = "default:pine_wood"}, {["x"] = 5, ["y"] = 4, ["param1"] = 77, ["z"] = 2, ["name"] = "default:obsidian_glass"}, {["x"] = 5, ["y"] = 4, ["param1"] = 15, ["z"] = 3, ["name"] = "default:pine_wood"}, {["x"] = 5, ["y"] = 4, ["param1"] = 15, ["z"] = 4, ["name"] = "default:pine_wood"}, {["x"] = 5, ["y"] = 4, ["param1"] = 15, ["z"] = 5, ["name"] = "default:pine_wood"}, {["x"] = 5, ["y"] = 4, ["param1"] = 15, ["z"] = 6, ["name"] = "default:pine_wood"}, {["x"] = 5, ["y"] = 4, ["param1"] = 15, ["z"] = 7, ["name"] = "default:pine_wood"}, {["x"] = 5, ["y"] = 4, ["param1"] = 15, ["z"] = 8, ["name"] = "default:pine_wood"}, {["x"] = 5, ["y"] = 4, ["param1"] = 15, ["z"] = 9, ["name"] = "default:pine_wood"}, {["x"] = 5, ["y"] = 4, ["z"] = 10, ["name"] = "default:pine_wood"}, {["x"] = 5, ["y"] = 4, ["param1"] = 15, ["z"] = 11, ["name"] = "default:pine_wood"}, {["x"] = 5, ["y"] = 4, ["param1"] = 15, ["z"] = 12, ["name"] = "default:silver_sandstone"}, {["x"] = 5, ["y"] = 5, ["param1"] = 14, ["z"] = 0, ["name"] = "default:silver_sandstone"}, {["x"] = 5, ["y"] = 5, ["z"] = 1, ["name"] = "default:pine_wood"}, {["x"] = 5, ["y"] = 5, ["z"] = 2, ["name"] = "default:pine_wood"}, {["x"] = 5, ["y"] = 5, ["z"] = 3, ["name"] = "default:pine_wood"}, {["x"] = 5, ["y"] = 5, ["z"] = 4, ["name"] = "default:silver_sandstone"}, {["x"] = 5, ["y"] = 5, ["param1"] = 15, ["z"] = 12, ["name"] = "default:silver_sandstone"}, {["x"] = 5, ["param2"] = 1, ["y"] = 6, ["param1"] = 30, ["z"] = 0, ["name"] = "default:aspen_leaves"}, {["x"] = 5, ["y"] = 6, ["z"] = 1, ["name"] = "default:pine_wood"}, {["x"] = 5, ["y"] = 6, ["z"] = 2, ["name"] = "default:pine_wood"}, {["x"] = 5, ["y"] = 6, ["z"] = 3, ["name"] = "default:pine_wood"}, {["x"] = 5, ["y"] = 6, ["z"] = 4, ["name"] = "default:silver_sandstone"}, {["x"] = 5, ["y"] = 7, ["z"] = 1, ["name"] = "default:pine_wood"}, {["x"] = 5, ["y"] = 7, ["param1"] = 78, ["z"] = 2, ["name"] = "default:obsidian_glass"}, {["x"] = 5, ["y"] = 7, ["z"] = 3, ["name"] = "default:pine_wood"}, {["x"] = 5, ["y"] = 7, ["z"] = 4, ["name"] = "default:silver_sandstone"}, {["x"] = 5, ["y"] = 8, ["z"] = 1, ["name"] = "default:pine_wood"}, {["x"] = 5, ["y"] = 8, ["param1"] = 61, ["z"] = 2, ["name"] = "default:obsidian_glass"}, {["x"] = 5, ["y"] = 8, ["z"] = 3, ["name"] = "default:pine_wood"}, {["x"] = 5, ["y"] = 8, ["z"] = 4, ["name"] = "default:silver_sandstone"}, {["x"] = 5, ["y"] = 9, ["z"] = 0, ["name"] = "default:silver_sandstone"}, {["x"] = 5, ["y"] = 9, ["z"] = 1, ["name"] = "default:pine_wood"}, {["x"] = 5, ["y"] = 9, ["z"] = 2, ["name"] = "default:pine_wood"}, {["x"] = 5, ["y"] = 9, ["z"] = 3, ["name"] = "default:pine_wood"}, {["x"] = 5, ["y"] = 9, ["z"] = 4, ["name"] = "default:silver_sandstone"}, {["x"] = 5, ["y"] = 10, ["param1"] = 15, ["z"] = 0, ["name"] = "default:silver_sandstone"}, {["x"] = 5, ["y"] = 10, ["param1"] = 15, ["z"] = 1, ["name"] = "default:silver_sandstone"}, {["x"] = 5, ["y"] = 10, ["param1"] = 31, ["z"] = 2, ["name"] = "default:silver_sandstone"}, {["x"] = 5, ["y"] = 10, ["param1"] = 47, ["z"] = 3, ["name"] = "default:silver_sandstone"}, {["x"] = 5, ["y"] = 10, ["param1"] = 63, ["z"] = 4, ["name"] = "default:silver_sandstone"}, {["x"] = 5, ["y"] = 10, ["param1"] = 111, ["z"] = 5, ["name"] = "default:silver_sandstone"}, {["x"] = 5, ["y"] = 10, ["param1"] = 95, ["z"] = 6, ["name"] = "default:silver_sandstone"}, {["x"] = 5, ["y"] = 10, ["param1"] = 79, ["z"] = 7, ["name"] = "default:silver_sandstone"}, {["x"] = 5, ["y"] = 10, ["param1"] = 63, ["z"] = 8, ["name"] = "default:silver_sandstone"}, {["x"] = 5, ["y"] = 10, ["param1"] = 47, ["z"] = 9, ["name"] = "default:silver_sandstone"}, {["x"] = 5, ["y"] = 10, ["param1"] = 31, ["z"] = 10, ["name"] = "default:silver_sandstone"}, {["x"] = 5, ["y"] = 10, ["param1"] = 15, ["z"] = 11, ["name"] = "default:silver_sandstone"}, {["x"] = 5, ["y"] = 10, ["param1"] = 15, ["z"] = 12, ["name"] = "default:silver_sandstone"}, {["x"] = 6, ["y"] = 0, ["z"] = 0, ["name"] = "default:silver_sandstone"}, {["x"] = 6, ["y"] = 0, ["z"] = 1, ["name"] = "default:silver_sandstone"}, {["x"] = 6, ["y"] = 0, ["z"] = 2, ["name"] = "default:silver_sandstone"}, {["x"] = 6, ["y"] = 0, ["z"] = 3, ["name"] = "default:silver_sandstone"}, {["x"] = 6, ["y"] = 0, ["z"] = 4, ["name"] = "default:silver_sandstone"}, {["x"] = 6, ["y"] = 0, ["z"] = 5, ["name"] = "default:silver_sandstone"}, {["x"] = 6, ["y"] = 0, ["z"] = 6, ["name"] = "default:silver_sandstone"}, {["x"] = 6, ["y"] = 0, ["z"] = 7, ["name"] = "default:silver_sandstone"}, {["x"] = 6, ["y"] = 0, ["z"] = 8, ["name"] = "default:silver_sandstone"}, {["x"] = 6, ["y"] = 0, ["z"] = 9, ["name"] = "default:silver_sandstone"}, {["x"] = 6, ["y"] = 0, ["z"] = 10, ["name"] = "default:silver_sandstone"}, {["x"] = 6, ["y"] = 0, ["z"] = 11, ["name"] = "default:silver_sandstone"}, {["x"] = 6, ["y"] = 0, ["z"] = 12, ["name"] = "default:silver_sandstone"}, {["x"] = 6, ["y"] = 1, ["z"] = 0, ["name"] = "default:silver_sandstone"}, {["x"] = 6, ["y"] = 1, ["z"] = 1, ["name"] = "default:silver_sandstone"}, {["x"] = 6, ["y"] = 1, ["param1"] = 15, ["z"] = 2, ["name"] = "default:silver_sandstone"}, {["x"] = 6, ["y"] = 1, ["param1"] = 15, ["z"] = 3, ["name"] = "default:silver_sandstone"}, {["x"] = 6, ["y"] = 1, ["param1"] = 15, ["z"] = 4, ["name"] = "default:silver_sandstone"}, {["x"] = 6, ["y"] = 1, ["param1"] = 15, ["z"] = 5, ["name"] = "default:silver_sandstone"}, {["x"] = 6, ["y"] = 1, ["param1"] = 15, ["z"] = 6, ["name"] = "default:silver_sandstone"}, {["x"] = 6, ["y"] = 1, ["param1"] = 15, ["z"] = 7, ["name"] = "default:silver_sandstone"}, {["x"] = 6, ["y"] = 1, ["param1"] = 15, ["z"] = 8, ["name"] = "default:silver_sandstone"}, {["x"] = 6, ["y"] = 1, ["param1"] = 15, ["z"] = 9, ["name"] = "default:silver_sandstone"}, {["x"] = 6, ["y"] = 1, ["param1"] = 15, ["z"] = 10, ["name"] = "default:silver_sandstone"}, {["x"] = 6, ["y"] = 1, ["param1"] = 15, ["z"] = 11, ["name"] = "default:silver_sandstone"}, {["x"] = 6, ["y"] = 1, ["param1"] = 15, ["z"] = 12, ["name"] = "default:silver_sandstone"}, {["x"] = 6, ["param2"] = 1, ["y"] = 2, ["param1"] = 30, ["z"] = 0, ["name"] = "default:aspen_leaves"}, {["x"] = 6, ["y"] = 2, ["z"] = 1, ["name"] = "default:pine_wood"}, {["x"] = 6, ["param2"] = 3, ["y"] = 2, ["param1"] = 142, ["z"] = 7, ["name"] = "stairs:stair_inner_pine_wood"}, {["x"] = 6, ["param2"] = 3, ["y"] = 2, ["param1"] = 126, ["z"] = 8, ["name"] = "stairs:stair_pine_wood"}, {["x"] = 6, ["y"] = 2, ["z"] = 10, ["name"] = "default:pine_wood"}, {["x"] = 6, ["y"] = 2, ["param1"] = 15, ["z"] = 11, ["name"] = "default:pine_wood"}, {["x"] = 6, ["y"] = 2, ["param1"] = 15, ["z"] = 12, ["name"] = "default:silver_sandstone"}, {["x"] = 6, ["y"] = 3, ["param1"] = 61, ["z"] = 1, ["name"] = "default:obsidian_glass"}, {["x"] = 6, ["y"] = 3, ["z"] = 11, ["name"] = "default:pine_wood"}, {["x"] = 6, ["y"] = 3, ["param1"] = 15, ["z"] = 12, ["name"] = "default:silver_sandstone"}, {["x"] = 6, ["y"] = 4, ["param1"] = 45, ["z"] = 1, ["name"] = "default:obsidian_glass"}, {["x"] = 6, ["y"] = 4, ["param1"] = 60, ["z"] = 2, ["name"] = "default:obsidian_glass"}, {["x"] = 6, ["y"] = 4, ["param1"] = 15, ["z"] = 3, ["name"] = "default:pine_wood"}, {["x"] = 6, ["param2"] = 21, ["y"] = 4, ["param1"] = 110, ["z"] = 4, ["name"] = "stairs:slab_pine_wood"}, {["x"] = 6, ["y"] = 4, ["param1"] = 15, ["z"] = 5, ["name"] = "default:pine_wood"}, {["x"] = 6, ["y"] = 4, ["param1"] = 15, ["z"] = 6, ["name"] = "default:pine_wood"}, {["x"] = 6, ["y"] = 4, ["param1"] = 15, ["z"] = 7, ["name"] = "default:pine_wood"}, {["x"] = 6, ["y"] = 4, ["param1"] = 15, ["z"] = 8, ["name"] = "default:pine_wood"}, {["x"] = 6, ["y"] = 4, ["param1"] = 15, ["z"] = 9, ["name"] = "default:pine_wood"}, {["x"] = 6, ["y"] = 4, ["param1"] = 15, ["z"] = 10, ["name"] = "default:pine_wood"}, {["x"] = 6, ["y"] = 4, ["param1"] = 15, ["z"] = 11, ["name"] = "default:pine_wood"}, {["x"] = 6, ["y"] = 4, ["param1"] = 15, ["z"] = 12, ["name"] = "default:silver_sandstone"}, {["x"] = 6, ["y"] = 5, ["param1"] = 14, ["z"] = 0, ["name"] = "default:silver_sandstone"}, {["x"] = 6, ["y"] = 5, ["z"] = 1, ["name"] = "default:pine_wood"}, {["x"] = 6, ["param2"] = 22, ["y"] = 5, ["param1"] = 61, ["z"] = 2, ["name"] = "stairs:slab_pine_wood"}, {["x"] = 6, ["y"] = 5, ["z"] = 3, ["name"] = "default:pine_wood"}, {["x"] = 6, ["y"] = 5, ["z"] = 4, ["name"] = "default:silver_sandstone"}, {["x"] = 6, ["y"] = 5, ["param1"] = 15, ["z"] = 12, ["name"] = "default:silver_sandstone"}, {["x"] = 6, ["param2"] = 1, ["y"] = 6, ["param1"] = 46, ["z"] = 0, ["name"] = "default:aspen_leaves"}, {["x"] = 6, ["y"] = 6, ["z"] = 1, ["name"] = "default:pine_wood"}, {["x"] = 6, ["param2"] = 2, ["y"] = 6, ["param1"] = 78, ["z"] = 2, ["name"] = "stairs:slab_pine_wood"}, {["x"] = 6, ["y"] = 6, ["z"] = 4, ["name"] = "default:silver_sandstone"}, {["x"] = 6, ["y"] = 7, ["param1"] = 78, ["z"] = 1, ["name"] = "default:obsidian_glass"}, {["x"] = 6, ["y"] = 7, ["z"] = 4, ["name"] = "default:silver_sandstone"}, {["x"] = 6, ["y"] = 8, ["param1"] = 61, ["z"] = 1, ["name"] = "default:obsidian_glass"}, {["x"] = 6, ["y"] = 8, ["z"] = 4, ["name"] = "default:silver_sandstone"}, {["x"] = 6, ["y"] = 9, ["z"] = 0, ["name"] = "default:silver_sandstone"}, {["x"] = 6, ["y"] = 9, ["z"] = 1, ["name"] = "default:pine_wood"}, {["x"] = 6, ["y"] = 9, ["z"] = 2, ["name"] = "default:pine_wood"}, {["x"] = 6, ["y"] = 9, ["z"] = 3, ["name"] = "default:pine_wood"}, {["x"] = 6, ["y"] = 9, ["z"] = 4, ["name"] = "default:silver_sandstone"}, {["x"] = 6, ["y"] = 10, ["param1"] = 15, ["z"] = 0, ["name"] = "default:silver_sandstone"}, {["x"] = 6, ["y"] = 10, ["param1"] = 31, ["z"] = 1, ["name"] = "default:silver_sandstone"}, {["x"] = 6, ["y"] = 10, ["param1"] = 47, ["z"] = 2, ["name"] = "default:silver_sandstone"}, {["x"] = 6, ["y"] = 10, ["param1"] = 63, ["z"] = 3, ["name"] = "default:silver_sandstone"}, {["x"] = 6, ["y"] = 10, ["param1"] = 79, ["z"] = 4, ["name"] = "default:silver_sandstone"}, {["x"] = 6, ["y"] = 10, ["param1"] = 127, ["z"] = 5, ["name"] = "default:silver_sandstone"}, {["x"] = 6, ["y"] = 10, ["param1"] = 111, ["z"] = 6, ["name"] = "default:silver_sandstone"}, {["x"] = 6, ["y"] = 10, ["param1"] = 95, ["z"] = 7, ["name"] = "default:silver_sandstone"}, {["x"] = 6, ["y"] = 10, ["param1"] = 79, ["z"] = 8, ["name"] = "default:silver_sandstone"}, {["x"] = 6, ["y"] = 10, ["param1"] = 63, ["z"] = 9, ["name"] = "default:silver_sandstone"}, {["x"] = 6, ["y"] = 10, ["param1"] = 47, ["z"] = 10, ["name"] = "default:silver_sandstone"}, {["x"] = 6, ["y"] = 10, ["param1"] = 31, ["z"] = 11, ["name"] = "default:silver_sandstone"}, {["x"] = 6, ["y"] = 10, ["param1"] = 15, ["z"] = 12, ["name"] = "default:silver_sandstone"}, {["x"] = 7, ["y"] = 0, ["z"] = 0, ["name"] = "default:silver_sandstone"}, {["x"] = 7, ["y"] = 0, ["z"] = 1, ["name"] = "default:silver_sandstone"}, {["x"] = 7, ["y"] = 0, ["z"] = 2, ["name"] = "default:silver_sandstone"}, {["x"] = 7, ["y"] = 0, ["z"] = 3, ["name"] = "default:silver_sandstone"}, {["x"] = 7, ["y"] = 0, ["z"] = 4, ["name"] = "default:silver_sandstone"}, {["x"] = 7, ["y"] = 0, ["z"] = 5, ["name"] = "default:silver_sandstone"}, {["x"] = 7, ["y"] = 0, ["z"] = 6, ["name"] = "default:silver_sandstone"}, {["x"] = 7, ["y"] = 0, ["z"] = 7, ["name"] = "default:silver_sandstone"}, {["x"] = 7, ["y"] = 0, ["z"] = 8, ["name"] = "default:silver_sandstone"}, {["x"] = 7, ["y"] = 0, ["z"] = 9, ["name"] = "default:silver_sandstone"}, {["x"] = 7, ["y"] = 0, ["z"] = 10, ["name"] = "default:silver_sandstone"}, {["x"] = 7, ["y"] = 0, ["z"] = 11, ["name"] = "default:silver_sandstone"}, {["x"] = 7, ["y"] = 0, ["z"] = 12, ["name"] = "default:silver_sandstone"}, {["x"] = 7, ["y"] = 1, ["z"] = 0, ["name"] = "default:silver_sandstone"}, {["x"] = 7, ["y"] = 1, ["param1"] = 15, ["z"] = 1, ["name"] = "default:silver_sandstone"}, {["x"] = 7, ["y"] = 1, ["param1"] = 15, ["z"] = 2, ["name"] = "default:silver_sandstone"}, {["x"] = 7, ["y"] = 1, ["param1"] = 15, ["z"] = 3, ["name"] = "default:silver_sandstone"}, {["x"] = 7, ["y"] = 1, ["param1"] = 15, ["z"] = 4, ["name"] = "default:silver_sandstone"}, {["x"] = 7, ["y"] = 1, ["param1"] = 15, ["z"] = 5, ["name"] = "default:silver_sandstone"}, {["x"] = 7, ["y"] = 1, ["param1"] = 15, ["z"] = 6, ["name"] = "default:silver_sandstone"}, {["x"] = 7, ["y"] = 1, ["param1"] = 15, ["z"] = 7, ["name"] = "default:silver_sandstone"}, {["x"] = 7, ["y"] = 1, ["param1"] = 15, ["z"] = 8, ["name"] = "default:silver_sandstone"}, {["x"] = 7, ["y"] = 1, ["param1"] = 15, ["z"] = 9, ["name"] = "default:silver_sandstone"}, {["x"] = 7, ["y"] = 1, ["param1"] = 15, ["z"] = 10, ["name"] = "default:silver_sandstone"}, {["x"] = 7, ["y"] = 1, ["param1"] = 15, ["z"] = 11, ["name"] = "default:silver_sandstone"}, {["x"] = 7, ["y"] = 1, ["param1"] = 15, ["z"] = 12, ["name"] = "default:silver_sandstone"}, {["x"] = 7, ["param2"] = 1, ["y"] = 2, ["param1"] = 13, ["z"] = 0, ["name"] = "default:aspen_leaves"}, {["x"] = 7, ["y"] = 2, ["param1"] = 13, ["z"] = 1, ["name"] = "default:pine_wood"}, {["x"] = 7, ["meta"] = {["fields"] = {["infotext"] = "\27(T@default)Empty Bookshelf\27E", ["formspec"] = "size[8,7;]list[context;books;0,0.3;8,2;]list[current_player;main;0,2.85;8,1;]list[current_player;main;0,4.08;8,3;8]listring[context;books]listring[current_player;main]image[0,2.85;1,1;gui_hb_bg.png]image[1,2.85;1,1;gui_hb_bg.png]image[2,2.85;1,1;gui_hb_bg.png]image[3,2.85;1,1;gui_hb_bg.png]image[4,2.85;1,1;gui_hb_bg.png]image[5,2.85;1,1;gui_hb_bg.png]image[6,2.85;1,1;gui_hb_bg.png]image[7,2.85;1,1;gui_hb_bg.png]image[0,0.3;1,1;default_bookshelf_slot.png]image[1,0.3;1,1;default_bookshelf_slot.png]image[2,0.3;1,1;default_bookshelf_slot.png]image[3,0.3;1,1;default_bookshelf_slot.png]image[4,0.3;1,1;default_bookshelf_slot.png]image[5,0.3;1,1;default_bookshelf_slot.png]image[6,0.3;1,1;default_bookshelf_slot.png]image[7,0.3;1,1;default_bookshelf_slot.png]image[0,1.3;1,1;default_bookshelf_slot.png]image[1,1.3;1,1;default_bookshelf_slot.png]image[2,1.3;1,1;default_bookshelf_slot.png]image[3,1.3;1,1;default_bookshelf_slot.png]image[4,1.3;1,1;default_bookshelf_slot.png]image[5,1.3;1,1;default_bookshelf_slot.png]image[6,1.3;1,1;default_bookshelf_slot.png]image[7,1.3;1,1;default_bookshelf_slot.png]"}, ["inventory"] = {["books"] = {"", "", "", "", "", "", "", "", "", "", "", "", "", "", "", ""}}}, ["param2"] = 2, ["y"] = 2, ["z"] = 2, ["name"] = "default:bookshelf"}, {["x"] = 7, ["param2"] = 2, ["y"] = 2, ["param1"] = 125, ["z"] = 7, ["name"] = "stairs:stair_pine_wood"}, {["x"] = 7, ["param2"] = 20, ["y"] = 2, ["param1"] = 77, ["z"] = 10, ["name"] = "stairs:slab_pine_wood"}, {["x"] = 7, ["y"] = 2, ["param1"] = 14, ["z"] = 11, ["name"] = "default:pine_wood"}, {["x"] = 7, ["y"] = 2, ["param1"] = 14, ["z"] = 12, ["name"] = "default:silver_sandstone"}, {["x"] = 7, ["y"] = 3, ["param1"] = 14, ["z"] = 1, ["name"] = "default:pine_wood"}, {["x"] = 7, ["meta"] = {["fields"] = {["infotext"] = "\27(T@default)Empty Bookshelf\27E", ["formspec"] = "size[8,7;]list[context;books;0,0.3;8,2;]list[current_player;main;0,2.85;8,1;]list[current_player;main;0,4.08;8,3;8]listring[context;books]listring[current_player;main]image[0,2.85;1,1;gui_hb_bg.png]image[1,2.85;1,1;gui_hb_bg.png]image[2,2.85;1,1;gui_hb_bg.png]image[3,2.85;1,1;gui_hb_bg.png]image[4,2.85;1,1;gui_hb_bg.png]image[5,2.85;1,1;gui_hb_bg.png]image[6,2.85;1,1;gui_hb_bg.png]image[7,2.85;1,1;gui_hb_bg.png]image[0,0.3;1,1;default_bookshelf_slot.png]image[1,0.3;1,1;default_bookshelf_slot.png]image[2,0.3;1,1;default_bookshelf_slot.png]image[3,0.3;1,1;default_bookshelf_slot.png]image[4,0.3;1,1;default_bookshelf_slot.png]image[5,0.3;1,1;default_bookshelf_slot.png]image[6,0.3;1,1;default_bookshelf_slot.png]image[7,0.3;1,1;default_bookshelf_slot.png]image[0,1.3;1,1;default_bookshelf_slot.png]image[1,1.3;1,1;default_bookshelf_slot.png]image[2,1.3;1,1;default_bookshelf_slot.png]image[3,1.3;1,1;default_bookshelf_slot.png]image[4,1.3;1,1;default_bookshelf_slot.png]image[5,1.3;1,1;default_bookshelf_slot.png]image[6,1.3;1,1;default_bookshelf_slot.png]image[7,1.3;1,1;default_bookshelf_slot.png]"}, ["inventory"] = {["books"] = {"", "", "", "", "", "", "", "", "", "", "", "", "", "", "", ""}}}, ["param2"] = 2, ["y"] = 3, ["z"] = 2, ["name"] = "default:bookshelf"}, {["x"] = 7, ["y"] = 3, ["z"] = 10, ["name"] = "default:obsidianbrick"}, {["x"] = 7, ["y"] = 3, ["z"] = 11, ["name"] = "default:pine_wood"}, {["x"] = 7, ["y"] = 3, ["param1"] = 14, ["z"] = 12, ["name"] = "default:silver_sandstone"}, {["x"] = 7, ["y"] = 4, ["param1"] = 14, ["z"] = 1, ["name"] = "default:pine_wood"}, {["x"] = 7, ["y"] = 4, ["param1"] = 59, ["z"] = 2, ["name"] = "default:obsidian_glass"}, {["x"] = 7, ["y"] = 4, ["param1"] = 14, ["z"] = 3, ["name"] = "default:pine_wood"}, {["x"] = 7, ["param2"] = 21, ["y"] = 4, ["param1"] = 125, ["z"] = 4, ["name"] = "stairs:slab_pine_wood"}, {["x"] = 7, ["y"] = 4, ["param1"] = 14, ["z"] = 5, ["name"] = "default:pine_wood"}, {["x"] = 7, ["y"] = 4, ["param1"] = 14, ["z"] = 6, ["name"] = "default:pine_wood"}, {["x"] = 7, ["y"] = 4, ["param1"] = 14, ["z"] = 7, ["name"] = "default:pine_wood"}, {["x"] = 7, ["y"] = 4, ["param1"] = 14, ["z"] = 8, ["name"] = "default:pine_wood"}, {["x"] = 7, ["y"] = 4, ["param1"] = 14, ["z"] = 9, ["name"] = "default:pine_wood"}, {["x"] = 7, ["y"] = 4, ["param1"] = 14, ["z"] = 10, ["name"] = "default:pine_wood"}, {["x"] = 7, ["y"] = 4, ["param1"] = 14, ["z"] = 11, ["name"] = "default:pine_wood"}, {["x"] = 7, ["y"] = 4, ["param1"] = 14, ["z"] = 12, ["name"] = "default:silver_sandstone"}, {["x"] = 7, ["y"] = 5, ["param1"] = 14, ["z"] = 0, ["name"] = "default:silver_sandstone"}, {["x"] = 7, ["y"] = 5, ["z"] = 1, ["name"] = "default:pine_wood"}, {["x"] = 7, ["param2"] = 22, ["y"] = 5, ["param1"] = 76, ["z"] = 2, ["name"] = "stairs:slab_pine_wood"}, {["x"] = 7, ["param2"] = 1, ["y"] = 5, ["param1"] = 93, ["z"] = 3, ["name"] = "stairs:slab_pine_wood"}, {["x"] = 7, ["param2"] = 1, ["y"] = 5, ["param1"] = 109, ["z"] = 4, ["name"] = "stairs:slab_pine_wood"}, {["x"] = 7, ["meta"] = {["fields"] = {["state"] = "0"}, ["inventory"] = {}}, ["y"] = 5, ["param1"] = 126, ["z"] = 5, ["name"] = "doors:door_wood_a"}, {["x"] = 7, ["y"] = 5, ["param1"] = 14, ["z"] = 12, ["name"] = "default:silver_sandstone"}, {["x"] = 7, ["param2"] = 1, ["y"] = 6, ["param1"] = 29, ["z"] = 0, ["name"] = "default:aspen_leaves"}, {["x"] = 7, ["y"] = 6, ["z"] = 1, ["name"] = "default:pine_wood"}, {["x"] = 7, ["y"] = 6, ["param1"] = 142, ["z"] = 5, ["name"] = "doors:hidden"}, {["x"] = 7, ["y"] = 7, ["z"] = 1, ["name"] = "default:pine_wood"}, {["x"] = 7, ["param2"] = 22, ["y"] = 7, ["param1"] = 141, ["z"] = 4, ["name"] = "stairs:slab_silver_sandstone"}, {["x"] = 7, ["y"] = 8, ["z"] = 1, ["name"] = "default:pine_wood"}, {["x"] = 7, ["y"] = 8, ["z"] = 4, ["name"] = "default:silver_sandstone"}, {["x"] = 7, ["y"] = 9, ["z"] = 0, ["name"] = "default:silver_sandstone"}, {["x"] = 7, ["y"] = 9, ["z"] = 1, ["name"] = "default:pine_wood"}, {["x"] = 7, ["y"] = 9, ["z"] = 2, ["name"] = "default:pine_wood"}, {["x"] = 7, ["y"] = 9, ["z"] = 3, ["name"] = "default:pine_wood"}, {["x"] = 7, ["y"] = 9, ["z"] = 4, ["name"] = "default:silver_sandstone"}, {["x"] = 7, ["y"] = 10, ["param1"] = 31, ["z"] = 0, ["name"] = "default:silver_sandstone"}, {["x"] = 7, ["y"] = 10, ["param1"] = 47, ["z"] = 1, ["name"] = "default:silver_sandstone"}, {["x"] = 7, ["y"] = 10, ["param1"] = 63, ["z"] = 2, ["name"] = "default:silver_sandstone"}, {["x"] = 7, ["y"] = 10, ["param1"] = 79, ["z"] = 3, ["name"] = "default:silver_sandstone"}, {["x"] = 7, ["y"] = 10, ["param1"] = 95, ["z"] = 4, ["name"] = "default:silver_sandstone"}, {["x"] = 7, ["y"] = 10, ["param1"] = 142, ["z"] = 5, ["name"] = "default:silver_sandstone"}, {["x"] = 7, ["y"] = 10, ["param1"] = 126, ["z"] = 6, ["name"] = "default:silver_sandstone"}, {["x"] = 7, ["y"] = 10, ["param1"] = 110, ["z"] = 7, ["name"] = "default:silver_sandstone"}, {["x"] = 7, ["y"] = 10, ["param1"] = 94, ["z"] = 8, ["name"] = "default:silver_sandstone"}, {["x"] = 7, ["y"] = 10, ["param1"] = 78, ["z"] = 9, ["name"] = "default:silver_sandstone"}, {["x"] = 7, ["y"] = 10, ["param1"] = 62, ["z"] = 10, ["name"] = "default:silver_sandstone"}, {["x"] = 7, ["y"] = 10, ["param1"] = 46, ["z"] = 11, ["name"] = "default:silver_sandstone"}, {["x"] = 7, ["y"] = 10, ["param1"] = 30, ["z"] = 12, ["name"] = "default:silver_sandstone"}, {["x"] = 8, ["y"] = 0, ["z"] = 0, ["name"] = "default:silver_sandstone"}, {["x"] = 8, ["y"] = 0, ["z"] = 1, ["name"] = "default:silver_sandstone"}, {["x"] = 8, ["y"] = 0, ["z"] = 2, ["name"] = "default:silver_sandstone"}, {["x"] = 8, ["y"] = 0, ["z"] = 3, ["name"] = "default:silver_sandstone"}, {["x"] = 8, ["y"] = 0, ["z"] = 4, ["name"] = "default:silver_sandstone"}, {["x"] = 8, ["y"] = 0, ["z"] = 5, ["name"] = "default:silver_sandstone"}, {["x"] = 8, ["y"] = 0, ["z"] = 6, ["name"] = "default:silver_sandstone"}, {["x"] = 8, ["y"] = 0, ["z"] = 7, ["name"] = "default:silver_sandstone"}, {["x"] = 8, ["y"] = 0, ["z"] = 8, ["name"] = "default:silver_sandstone"}, {["x"] = 8, ["y"] = 0, ["z"] = 9, ["name"] = "default:silver_sandstone"}, {["x"] = 8, ["y"] = 0, ["z"] = 10, ["name"] = "default:silver_sandstone"}, {["x"] = 8, ["y"] = 0, ["z"] = 11, ["name"] = "default:silver_sandstone"}, {["x"] = 8, ["y"] = 0, ["z"] = 12, ["name"] = "default:silver_sandstone"}, {["x"] = 8, ["y"] = 1, ["z"] = 0, ["name"] = "default:silver_sandstone"}, {["x"] = 8, ["y"] = 1, ["param1"] = 15, ["z"] = 1, ["name"] = "default:silver_sandstone"}, {["x"] = 8, ["y"] = 1, ["param1"] = 15, ["z"] = 2, ["name"] = "default:silver_sandstone"}, {["x"] = 8, ["y"] = 1, ["param1"] = 15, ["z"] = 3, ["name"] = "default:silver_sandstone"}, {["x"] = 8, ["y"] = 1, ["param1"] = 15, ["z"] = 4, ["name"] = "default:silver_sandstone"}, {["x"] = 8, ["y"] = 1, ["param1"] = 15, ["z"] = 5, ["name"] = "default:silver_sandstone"}, {["x"] = 8, ["y"] = 1, ["param1"] = 15, ["z"] = 6, ["name"] = "default:silver_sandstone"}, {["x"] = 8, ["y"] = 1, ["z"] = 7, ["name"] = "default:silver_sandstone"}, {["x"] = 8, ["y"] = 1, ["param1"] = 15, ["z"] = 8, ["name"] = "default:silver_sandstone"}, {["x"] = 8, ["y"] = 1, ["param1"] = 15, ["z"] = 9, ["name"] = "default:silver_sandstone"}, {["x"] = 8, ["y"] = 1, ["param1"] = 15, ["z"] = 10, ["name"] = "default:silver_sandstone"}, {["x"] = 8, ["y"] = 1, ["param1"] = 15, ["z"] = 11, ["name"] = "default:silver_sandstone"}, {["x"] = 8, ["y"] = 1, ["param1"] = 15, ["z"] = 12, ["name"] = "default:silver_sandstone"}, {["x"] = 8, ["y"] = 2, ["param1"] = 14, ["z"] = 0, ["name"] = "default:silver_sandstone"}, {["x"] = 8, ["y"] = 2, ["param1"] = 13, ["z"] = 1, ["name"] = "default:pine_wood"}, {["x"] = 8, ["y"] = 2, ["z"] = 2, ["name"] = "default:pine_wood"}, {["x"] = 8, ["meta"] = {["fields"] = {["infotext"] = "\27(T@default)Empty Bookshelf\27E", ["formspec"] = "size[8,7;]list[context;books;0,0.3;8,2;]list[current_player;main;0,2.85;8,1;]list[current_player;main;0,4.08;8,3;8]listring[context;books]listring[current_player;main]image[0,2.85;1,1;gui_hb_bg.png]image[1,2.85;1,1;gui_hb_bg.png]image[2,2.85;1,1;gui_hb_bg.png]image[3,2.85;1,1;gui_hb_bg.png]image[4,2.85;1,1;gui_hb_bg.png]image[5,2.85;1,1;gui_hb_bg.png]image[6,2.85;1,1;gui_hb_bg.png]image[7,2.85;1,1;gui_hb_bg.png]image[0,0.3;1,1;default_bookshelf_slot.png]image[1,0.3;1,1;default_bookshelf_slot.png]image[2,0.3;1,1;default_bookshelf_slot.png]image[3,0.3;1,1;default_bookshelf_slot.png]image[4,0.3;1,1;default_bookshelf_slot.png]image[5,0.3;1,1;default_bookshelf_slot.png]image[6,0.3;1,1;default_bookshelf_slot.png]image[7,0.3;1,1;default_bookshelf_slot.png]image[0,1.3;1,1;default_bookshelf_slot.png]image[1,1.3;1,1;default_bookshelf_slot.png]image[2,1.3;1,1;default_bookshelf_slot.png]image[3,1.3;1,1;default_bookshelf_slot.png]image[4,1.3;1,1;default_bookshelf_slot.png]image[5,1.3;1,1;default_bookshelf_slot.png]image[6,1.3;1,1;default_bookshelf_slot.png]image[7,1.3;1,1;default_bookshelf_slot.png]"}, ["inventory"] = {["books"] = {"", "", "", "", "", "", "", "", "", "", "", "", "", "", "", ""}}}, ["param2"] = 3, ["y"] = 2, ["z"] = 3, ["name"] = "default:bookshelf"}, {["x"] = 8, ["param2"] = 2, ["y"] = 2, ["param1"] = 109, ["z"] = 7, ["name"] = "stairs:stair_inner_pine_wood"}, {["x"] = 8, ["param2"] = 1, ["y"] = 2, ["param1"] = 94, ["z"] = 8, ["name"] = "stairs:stair_pine_wood"}, {["x"] = 8, ["y"] = 2, ["z"] = 10, ["name"] = "default:pine_wood"}, {["x"] = 8, ["y"] = 2, ["param1"] = 14, ["z"] = 11, ["name"] = "default:pine_wood"}, {["x"] = 8, ["y"] = 2, ["param1"] = 14, ["z"] = 12, ["name"] = "default:silver_sandstone"}, {["x"] = 8, ["y"] = 3, ["param1"] = 14, ["z"] = 0, ["name"] = "default:silver_sandstone"}, {["x"] = 8, ["y"] = 3, ["z"] = 1, ["name"] = "default:pine_wood"}, {["x"] = 8, ["y"] = 3, ["z"] = 2, ["name"] = "default:pine_wood"}, {["x"] = 8, ["meta"] = {["fields"] = {["infotext"] = "\27(T@default)Empty Bookshelf\27E", ["formspec"] = "size[8,7;]list[context;books;0,0.3;8,2;]list[current_player;main;0,2.85;8,1;]list[current_player;main;0,4.08;8,3;8]listring[context;books]listring[current_player;main]image[0,2.85;1,1;gui_hb_bg.png]image[1,2.85;1,1;gui_hb_bg.png]image[2,2.85;1,1;gui_hb_bg.png]image[3,2.85;1,1;gui_hb_bg.png]image[4,2.85;1,1;gui_hb_bg.png]image[5,2.85;1,1;gui_hb_bg.png]image[6,2.85;1,1;gui_hb_bg.png]image[7,2.85;1,1;gui_hb_bg.png]image[0,0.3;1,1;default_bookshelf_slot.png]image[1,0.3;1,1;default_bookshelf_slot.png]image[2,0.3;1,1;default_bookshelf_slot.png]image[3,0.3;1,1;default_bookshelf_slot.png]image[4,0.3;1,1;default_bookshelf_slot.png]image[5,0.3;1,1;default_bookshelf_slot.png]image[6,0.3;1,1;default_bookshelf_slot.png]image[7,0.3;1,1;default_bookshelf_slot.png]image[0,1.3;1,1;default_bookshelf_slot.png]image[1,1.3;1,1;default_bookshelf_slot.png]image[2,1.3;1,1;default_bookshelf_slot.png]image[3,1.3;1,1;default_bookshelf_slot.png]image[4,1.3;1,1;default_bookshelf_slot.png]image[5,1.3;1,1;default_bookshelf_slot.png]image[6,1.3;1,1;default_bookshelf_slot.png]image[7,1.3;1,1;default_bookshelf_slot.png]"}, ["inventory"] = {["books"] = {"", "", "", "", "", "", "", "", "", "", "", "", "", "", "", ""}}}, ["param2"] = 3, ["y"] = 3, ["z"] = 3, ["name"] = "default:bookshelf"}, {["x"] = 8, ["y"] = 3, ["param1"] = 14, ["z"] = 11, ["name"] = "default:pine_wood"}, {["x"] = 8, ["y"] = 3, ["param1"] = 14, ["z"] = 12, ["name"] = "default:silver_sandstone"}, {["x"] = 8, ["y"] = 4, ["param1"] = 14, ["z"] = 0, ["name"] = "default:silver_sandstone"}, {["x"] = 8, ["y"] = 4, ["param1"] = 13, ["z"] = 1, ["name"] = "default:pine_wood"}, {["x"] = 8, ["y"] = 4, ["param1"] = 14, ["z"] = 2, ["name"] = "default:pine_wood"}, {["x"] = 8, ["y"] = 4, ["param1"] = 14, ["z"] = 3, ["name"] = "default:pine_wood"}, {["x"] = 8, ["param2"] = 21, ["y"] = 4, ["param1"] = 140, ["z"] = 4, ["name"] = "stairs:slab_pine_wood"}, {["x"] = 8, ["y"] = 4, ["param1"] = 14, ["z"] = 5, ["name"] = "default:pine_wood"}, {["x"] = 8, ["y"] = 4, ["param1"] = 14, ["z"] = 6, ["name"] = "default:pine_wood"}, {["x"] = 8, ["y"] = 4, ["param1"] = 14, ["z"] = 7, ["name"] = "default:pine_wood"}, {["x"] = 8, ["y"] = 4, ["param1"] = 14, ["z"] = 8, ["name"] = "default:pine_wood"}, {["x"] = 8, ["y"] = 4, ["param1"] = 14, ["z"] = 9, ["name"] = "default:pine_wood"}, {["x"] = 8, ["y"] = 4, ["param1"] = 14, ["z"] = 10, ["name"] = "default:pine_wood"}, {["x"] = 8, ["y"] = 4, ["param1"] = 14, ["z"] = 11, ["name"] = "default:pine_wood"}, {["x"] = 8, ["y"] = 4, ["param1"] = 14, ["z"] = 12, ["name"] = "default:silver_sandstone"}, {["x"] = 8, ["y"] = 5, ["param1"] = 14, ["z"] = 0, ["name"] = "default:silver_sandstone"}, {["x"] = 8, ["y"] = 5, ["z"] = 1, ["name"] = "default:pine_wood"}, {["x"] = 8, ["y"] = 5, ["z"] = 2, ["name"] = "default:pine_wood"}, {["x"] = 8, ["y"] = 5, ["z"] = 3, ["name"] = "default:pine_wood"}, {["x"] = 8, ["y"] = 5, ["z"] = 4, ["name"] = "default:silver_sandstone"}, {["x"] = 8, ["y"] = 5, ["param1"] = 14, ["z"] = 12, ["name"] = "default:silver_sandstone"}, {["x"] = 8, ["y"] = 6, ["z"] = 0, ["name"] = "default:silver_sandstone"}, {["x"] = 8, ["y"] = 6, ["z"] = 1, ["name"] = "default:pine_wood"}, {["x"] = 8, ["y"] = 6, ["z"] = 2, ["name"] = "default:pine_wood"}, {["x"] = 8, ["y"] = 6, ["z"] = 3, ["name"] = "default:pine_wood"}, {["x"] = 8, ["y"] = 6, ["z"] = 4, ["name"] = "default:silver_sandstone"}, {["x"] = 8, ["y"] = 7, ["z"] = 0, ["name"] = "default:silver_sandstone"}, {["x"] = 8, ["y"] = 7, ["z"] = 1, ["name"] = "default:pine_wood"}, {["x"] = 8, ["y"] = 7, ["z"] = 2, ["name"] = "default:pine_wood"}, {["x"] = 8, ["y"] = 7, ["z"] = 3, ["name"] = "default:pine_wood"}, {["x"] = 8, ["y"] = 7, ["z"] = 4, ["name"] = "default:silver_sandstone"}, {["x"] = 8, ["y"] = 8, ["z"] = 0, ["name"] = "default:silver_sandstone"}, {["x"] = 8, ["y"] = 8, ["z"] = 1, ["name"] = "default:pine_wood"}, {["x"] = 8, ["y"] = 8, ["z"] = 2, ["name"] = "default:pine_wood"}, {["x"] = 8, ["y"] = 8, ["z"] = 3, ["name"] = "default:pine_wood"}, {["x"] = 8, ["y"] = 8, ["z"] = 4, ["name"] = "default:silver_sandstone"}, {["x"] = 8, ["y"] = 9, ["z"] = 0, ["name"] = "default:silver_sandstone"}, {["x"] = 8, ["y"] = 9, ["z"] = 1, ["name"] = "default:pine_wood"}, {["x"] = 8, ["y"] = 9, ["z"] = 2, ["name"] = "default:pine_wood"}, {["x"] = 8, ["y"] = 9, ["z"] = 3, ["name"] = "default:pine_wood"}, {["x"] = 8, ["y"] = 9, ["z"] = 4, ["name"] = "default:silver_sandstone"}, {["x"] = 8, ["y"] = 10, ["param1"] = 46, ["z"] = 0, ["name"] = "default:silver_sandstone"}, {["x"] = 8, ["y"] = 10, ["param1"] = 62, ["z"] = 1, ["name"] = "default:silver_sandstone"}, {["x"] = 8, ["y"] = 10, ["param1"] = 78, ["z"] = 2, ["name"] = "default:silver_sandstone"}, {["x"] = 8, ["y"] = 10, ["param1"] = 94, ["z"] = 3, ["name"] = "default:silver_sandstone"}, {["x"] = 8, ["y"] = 10, ["param1"] = 110, ["z"] = 4, ["name"] = "default:silver_sandstone"}, {["x"] = 8, ["y"] = 10, ["param1"] = 158, ["z"] = 5, ["name"] = "default:silver_sandstone"}, {["x"] = 8, ["y"] = 10, ["param1"] = 142, ["z"] = 6, ["name"] = "default:silver_sandstone"}, {["x"] = 8, ["y"] = 10, ["param1"] = 126, ["z"] = 7, ["name"] = "default:silver_sandstone"}, {["x"] = 8, ["y"] = 10, ["param1"] = 110, ["z"] = 8, ["name"] = "default:silver_sandstone"}, {["x"] = 8, ["y"] = 10, ["param1"] = 94, ["z"] = 9, ["name"] = "default:silver_sandstone"}, {["x"] = 8, ["y"] = 10, ["param1"] = 78, ["z"] = 10, ["name"] = "default:silver_sandstone"}, {["x"] = 8, ["y"] = 10, ["param1"] = 62, ["z"] = 11, ["name"] = "default:silver_sandstone"}, {["x"] = 8, ["y"] = 10, ["param1"] = 46, ["z"] = 12, ["name"] = "default:silver_sandstone"}, {["x"] = 9, ["y"] = 0, ["z"] = 0, ["name"] = "default:silver_sandstone"}, {["x"] = 9, ["y"] = 0, ["z"] = 1, ["name"] = "default:silver_sandstone"}, {["x"] = 9, ["y"] = 0, ["z"] = 2, ["name"] = "default:silver_sandstone"}, {["x"] = 9, ["y"] = 0, ["z"] = 3, ["name"] = "default:silver_sandstone"}, {["x"] = 9, ["y"] = 0, ["z"] = 4, ["name"] = "default:silver_sandstone"}, {["x"] = 9, ["y"] = 0, ["z"] = 5, ["name"] = "default:silver_sandstone"}, {["x"] = 9, ["y"] = 0, ["z"] = 6, ["name"] = "default:silver_sandstone"}, {["x"] = 9, ["y"] = 0, ["z"] = 7, ["name"] = "default:silver_sandstone"}, {["x"] = 9, ["y"] = 0, ["z"] = 8, ["name"] = "default:silver_sandstone"}, {["x"] = 9, ["y"] = 0, ["z"] = 9, ["name"] = "default:silver_sandstone"}, {["x"] = 9, ["y"] = 0, ["z"] = 10, ["name"] = "default:silver_sandstone"}, {["x"] = 9, ["y"] = 0, ["z"] = 11, ["name"] = "default:silver_sandstone"}, {["x"] = 9, ["y"] = 0, ["z"] = 12, ["name"] = "default:silver_sandstone"}, {["x"] = 9, ["y"] = 1, ["z"] = 0, ["name"] = "default:silver_sandstone"}, {["x"] = 9, ["y"] = 1, ["param1"] = 15, ["z"] = 1, ["name"] = "default:silver_sandstone"}, {["x"] = 9, ["y"] = 1, ["param1"] = 15, ["z"] = 2, ["name"] = "default:silver_sandstone"}, {["x"] = 9, ["y"] = 1, ["param1"] = 15, ["z"] = 3, ["name"] = "default:silver_sandstone"}, {["x"] = 9, ["y"] = 1, ["param1"] = 15, ["z"] = 4, ["name"] = "default:silver_sandstone"}, {["x"] = 9, ["y"] = 1, ["param1"] = 15, ["z"] = 5, ["name"] = "default:silver_sandstone"}, {["x"] = 9, ["y"] = 1, ["param1"] = 15, ["z"] = 6, ["name"] = "default:silver_sandstone"}, {["x"] = 9, ["y"] = 1, ["param1"] = 15, ["z"] = 7, ["name"] = "default:silver_sandstone"}, {["x"] = 9, ["y"] = 1, ["param1"] = 15, ["z"] = 8, ["name"] = "default:silver_sandstone"}, {["x"] = 9, ["y"] = 1, ["param1"] = 15, ["z"] = 9, ["name"] = "default:silver_sandstone"}, {["x"] = 9, ["y"] = 1, ["param1"] = 15, ["z"] = 10, ["name"] = "default:silver_sandstone"}, {["x"] = 9, ["y"] = 1, ["param1"] = 15, ["z"] = 11, ["name"] = "default:silver_sandstone"}, {["x"] = 9, ["y"] = 1, ["param1"] = 15, ["z"] = 12, ["name"] = "default:silver_sandstone"}, {["x"] = 9, ["y"] = 2, ["param1"] = 14, ["z"] = 0, ["name"] = "default:silver_sandstone"}, {["x"] = 9, ["y"] = 2, ["param1"] = 14, ["z"] = 1, ["name"] = "default:pine_wood"}, {["x"] = 9, ["param2"] = 2, ["y"] = 2, ["param1"] = 124, ["z"] = 2, ["name"] = "beds:bed_top"}, {["x"] = 9, ["param2"] = 2, ["y"] = 2, ["param1"] = 141, ["z"] = 3, ["name"] = "beds:bed_bottom"}, {["x"] = 9, ["meta"] = {["fields"] = {["state"] = "0"}, ["inventory"] = {}}, ["y"] = 2, ["param1"] = 126, ["z"] = 4, ["name"] = "doors:door_wood_a"}, {["x"] = 9, ["y"] = 2, ["param1"] = 15, ["z"] = 11, ["name"] = "default:pine_wood"}, {["x"] = 9, ["y"] = 2, ["param1"] = 15, ["z"] = 12, ["name"] = "default:silver_sandstone"}, {["x"] = 9, ["y"] = 3, ["param1"] = 14, ["z"] = 0, ["name"] = "default:silver_sandstone"}, {["x"] = 9, ["y"] = 3, ["param1"] = 14, ["z"] = 1, ["name"] = "default:pine_wood"}, {["x"] = 9, ["y"] = 3, ["param1"] = 142, ["z"] = 4, ["name"] = "doors:hidden"}, {["x"] = 9, ["y"] = 3, ["param1"] = 15, ["z"] = 11, ["name"] = "default:pine_wood"}, {["x"] = 9, ["y"] = 3, ["param1"] = 15, ["z"] = 12, ["name"] = "default:silver_sandstone"}, {["x"] = 9, ["y"] = 4, ["param1"] = 14, ["z"] = 0, ["name"] = "default:silver_sandstone"}, {["x"] = 9, ["y"] = 4, ["param1"] = 14, ["z"] = 1, ["name"] = "default:pine_wood"}, {["x"] = 9, ["param2"] = 22, ["y"] = 4, ["param1"] = 155, ["z"] = 2, ["name"] = "stairs:slab_pine_wood"}, {["x"] = 9, ["param2"] = 22, ["y"] = 4, ["param1"] = 172, ["z"] = 3, ["name"] = "stairs:slab_pine_wood"}, {["x"] = 9, ["param2"] = 22, ["y"] = 4, ["param1"] = 157, ["z"] = 4, ["name"] = "stairs:slab_pine_wood"}, {["x"] = 9, ["y"] = 4, ["param1"] = 15, ["z"] = 5, ["name"] = "default:pine_wood"}, {["x"] = 9, ["y"] = 4, ["param1"] = 15, ["z"] = 6, ["name"] = "default:pine_wood"}, {["x"] = 9, ["y"] = 4, ["param1"] = 15, ["z"] = 7, ["name"] = "default:pine_wood"}, {["x"] = 9, ["y"] = 4, ["param1"] = 15, ["z"] = 8, ["name"] = "default:pine_wood"}, {["x"] = 9, ["y"] = 4, ["param1"] = 15, ["z"] = 9, ["name"] = "default:pine_wood"}, {["x"] = 9, ["y"] = 4, ["param1"] = 15, ["z"] = 10, ["name"] = "default:pine_wood"}, {["x"] = 9, ["y"] = 4, ["param1"] = 15, ["z"] = 11, ["name"] = "default:pine_wood"}, {["x"] = 9, ["y"] = 4, ["param1"] = 15, ["z"] = 12, ["name"] = "default:silver_sandstone"}, {["x"] = 9, ["y"] = 5, ["param1"] = 14, ["z"] = 0, ["name"] = "default:silver_sandstone"}, {["x"] = 9, ["y"] = 5, ["param1"] = 15, ["z"] = 12, ["name"] = "default:silver_sandstone"}, {["x"] = 9, ["y"] = 6, ["param1"] = 14, ["z"] = 0, ["name"] = "default:silver_sandstone"}, {["x"] = 9, ["y"] = 7, ["param1"] = 14, ["z"] = 0, ["name"] = "default:silver_sandstone"}, {["x"] = 9, ["param2"] = 21, ["y"] = 7, ["param1"] = 222, ["z"] = 1, ["name"] = "stairs:slab_pine_wood"}, {["x"] = 9, ["param2"] = 21, ["y"] = 7, ["param1"] = 205, ["z"] = 2, ["name"] = "stairs:slab_obsidian_glass"}, {["x"] = 9, ["param2"] = 21, ["y"] = 7, ["param1"] = 222, ["z"] = 3, ["name"] = "stairs:slab_pine_wood"}, {["x"] = 9, ["param2"] = 8, ["y"] = 7, ["param1"] = 206, ["z"] = 4, ["name"] = "stairs:stair_pine_wood"}, {["x"] = 9, ["y"] = 8, ["param1"] = 14, ["z"] = 0, ["name"] = "default:silver_sandstone"}, {["x"] = 9, ["y"] = 8, ["param1"] = 239, ["z"] = 1, ["name"] = "default:meselamp"}, {["x"] = 9, ["y"] = 8, ["param1"] = 222, ["z"] = 2, ["name"] = "default:water_source"}, {["x"] = 9, ["y"] = 8, ["param1"] = 239, ["z"] = 3, ["name"] = "default:meselamp"}, {["x"] = 9, ["param2"] = 4, ["y"] = 8, ["param1"] = 222, ["z"] = 4, ["name"] = "stairs:slab_pine_wood"}, {["x"] = 9, ["y"] = 9, ["param1"] = 15, ["z"] = 0, ["name"] = "default:silver_sandstone"}, {["x"] = 9, ["y"] = 9, ["param1"] = 14, ["z"] = 1, ["name"] = "default:pine_wood"}, {["x"] = 9, ["y"] = 9, ["param1"] = 14, ["z"] = 2, ["name"] = "default:pine_wood"}, {["x"] = 9, ["y"] = 9, ["param1"] = 14, ["z"] = 3, ["name"] = "default:pine_wood"}, {["x"] = 9, ["y"] = 9, ["z"] = 4, ["name"] = "default:pine_wood"}, {["x"] = 9, ["y"] = 10, ["param1"] = 62, ["z"] = 0, ["name"] = "default:silver_sandstone"}, {["x"] = 9, ["y"] = 10, ["param1"] = 78, ["z"] = 1, ["name"] = "default:silver_sandstone"}, {["x"] = 9, ["y"] = 10, ["param1"] = 95, ["z"] = 2, ["name"] = "default:silver_sandstone"}, {["x"] = 9, ["y"] = 10, ["param1"] = 111, ["z"] = 3, ["name"] = "default:silver_sandstone"}, {["x"] = 9, ["y"] = 10, ["param1"] = 127, ["z"] = 4, ["name"] = "default:silver_sandstone"}, {["x"] = 9, ["y"] = 10, ["param1"] = 175, ["z"] = 5, ["name"] = "default:silver_sandstone"}, {["x"] = 9, ["y"] = 10, ["param1"] = 159, ["z"] = 6, ["name"] = "default:silver_sandstone"}, {["x"] = 9, ["y"] = 10, ["param1"] = 143, ["z"] = 7, ["name"] = "default:silver_sandstone"}, {["x"] = 9, ["y"] = 10, ["param1"] = 127, ["z"] = 8, ["name"] = "default:silver_sandstone"}, {["x"] = 9, ["y"] = 10, ["param1"] = 111, ["z"] = 9, ["name"] = "default:silver_sandstone"}, {["x"] = 9, ["y"] = 10, ["param1"] = 95, ["z"] = 10, ["name"] = "default:silver_sandstone"}, {["x"] = 9, ["y"] = 10, ["param1"] = 79, ["z"] = 11, ["name"] = "default:silver_sandstone"}, {["x"] = 9, ["y"] = 10, ["param1"] = 63, ["z"] = 12, ["name"] = "default:silver_sandstone"}, {["x"] = 10, ["y"] = 0, ["z"] = 0, ["name"] = "default:silver_sandstone"}, {["x"] = 10, ["y"] = 0, ["z"] = 1, ["name"] = "default:silver_sandstone"}, {["x"] = 10, ["y"] = 0, ["z"] = 2, ["name"] = "default:silver_sandstone"}, {["x"] = 10, ["y"] = 0, ["z"] = 3, ["name"] = "default:silver_sandstone"}, {["x"] = 10, ["y"] = 0, ["z"] = 4, ["name"] = "default:silver_sandstone"}, {["x"] = 10, ["y"] = 0, ["z"] = 5, ["name"] = "default:silver_sandstone"}, {["x"] = 10, ["y"] = 0, ["z"] = 6, ["name"] = "default:silver_sandstone"}, {["x"] = 10, ["y"] = 0, ["z"] = 7, ["name"] = "default:silver_sandstone"}, {["x"] = 10, ["y"] = 0, ["z"] = 8, ["name"] = "default:silver_sandstone"}, {["x"] = 10, ["y"] = 0, ["z"] = 9, ["name"] = "default:silver_sandstone"}, {["x"] = 10, ["y"] = 0, ["z"] = 10, ["name"] = "default:silver_sandstone"}, {["x"] = 10, ["y"] = 0, ["z"] = 11, ["name"] = "default:silver_sandstone"}, {["x"] = 10, ["y"] = 0, ["z"] = 12, ["name"] = "default:silver_sandstone"}, {["x"] = 10, ["y"] = 1, ["z"] = 0, ["name"] = "default:silver_sandstone"}, {["x"] = 10, ["y"] = 1, ["param1"] = 15, ["z"] = 1, ["name"] = "default:silver_sandstone"}, {["x"] = 10, ["y"] = 1, ["param1"] = 15, ["z"] = 2, ["name"] = "default:silver_sandstone"}, {["x"] = 10, ["y"] = 1, ["param1"] = 15, ["z"] = 3, ["name"] = "default:silver_sandstone"}, {["x"] = 10, ["y"] = 1, ["param1"] = 15, ["z"] = 4, ["name"] = "default:silver_sandstone"}, {["x"] = 10, ["y"] = 1, ["param1"] = 15, ["z"] = 5, ["name"] = "default:silver_sandstone"}, {["x"] = 10, ["y"] = 1, ["param1"] = 15, ["z"] = 6, ["name"] = "default:silver_sandstone"}, {["x"] = 10, ["y"] = 1, ["param1"] = 15, ["z"] = 7, ["name"] = "default:silver_sandstone"}, {["x"] = 10, ["y"] = 1, ["param1"] = 15, ["z"] = 8, ["name"] = "default:silver_sandstone"}, {["x"] = 10, ["y"] = 1, ["param1"] = 15, ["z"] = 9, ["name"] = "default:silver_sandstone"}, {["x"] = 10, ["y"] = 1, ["param1"] = 15, ["z"] = 10, ["name"] = "default:silver_sandstone"}, {["x"] = 10, ["y"] = 1, ["param1"] = 15, ["z"] = 11, ["name"] = "default:silver_sandstone"}, {["x"] = 10, ["y"] = 1, ["param1"] = 15, ["z"] = 12, ["name"] = "default:silver_sandstone"}, {["x"] = 10, ["y"] = 2, ["param1"] = 14, ["z"] = 0, ["name"] = "default:silver_sandstone"}, {["x"] = 10, ["y"] = 2, ["param1"] = 14, ["z"] = 1, ["name"] = "default:pine_wood"}, {["x"] = 10, ["y"] = 2, ["z"] = 2, ["name"] = "default:pine_wood"}, {["x"] = 10, ["y"] = 2, ["z"] = 3, ["name"] = "default:pine_wood"}, {["x"] = 10, ["y"] = 2, ["z"] = 6, ["name"] = "default:pine_wood"}, {["x"] = 10, ["y"] = 2, ["z"] = 7, ["name"] = "default:pine_wood"}, {["x"] = 10, ["meta"] = {["fields"] = {["state"] = "0"}, ["inventory"] = {}}, ["param2"] = 1, ["y"] = 2, ["param1"] = 62, ["z"] = 8, ["name"] = "doors:door_wood_a"}, {["x"] = 10, ["y"] = 2, ["z"] = 9, ["name"] = "default:pine_wood"}, {["x"] = 10, ["y"] = 2, ["z"] = 10, ["name"] = "default:pine_wood"}, {["x"] = 10, ["y"] = 2, ["param1"] = 15, ["z"] = 11, ["name"] = "default:pine_wood"}, {["x"] = 10, ["y"] = 2, ["param1"] = 15, ["z"] = 12, ["name"] = "default:silver_sandstone"}, {["x"] = 10, ["y"] = 3, ["param1"] = 14, ["z"] = 0, ["name"] = "default:silver_sandstone"}, {["x"] = 10, ["y"] = 3, ["param1"] = 14, ["z"] = 1, ["name"] = "default:pine_wood"}, {["x"] = 10, ["y"] = 3, ["z"] = 2, ["name"] = "default:pine_wood"}, {["x"] = 10, ["y"] = 3, ["z"] = 3, ["name"] = "default:pine_wood"}, {["x"] = 10, ["y"] = 3, ["z"] = 6, ["name"] = "default:pine_wood"}, {["x"] = 10, ["y"] = 3, ["z"] = 7, ["name"] = "default:pine_wood"}, {["x"] = 10, ["param2"] = 1, ["y"] = 3, ["param1"] = 62, ["z"] = 8, ["name"] = "doors:hidden"}, {["x"] = 10, ["y"] = 3, ["z"] = 9, ["name"] = "default:pine_wood"}, {["x"] = 10, ["y"] = 3, ["z"] = 10, ["name"] = "default:pine_wood"}, {["x"] = 10, ["y"] = 3, ["param1"] = 15, ["z"] = 11, ["name"] = "default:pine_wood"}, {["x"] = 10, ["y"] = 3, ["param1"] = 15, ["z"] = 12, ["name"] = "default:silver_sandstone"}, {["x"] = 10, ["y"] = 4, ["param1"] = 14, ["z"] = 0, ["name"] = "default:silver_sandstone"}, {["x"] = 10, ["y"] = 4, ["param1"] = 14, ["z"] = 1, ["name"] = "default:pine_wood"}, {["x"] = 10, ["y"] = 4, ["z"] = 2, ["name"] = "default:pine_wood"}, {["x"] = 10, ["y"] = 4, ["z"] = 3, ["name"] = "default:pine_wood"}, {["x"] = 10, ["param2"] = 22, ["y"] = 4, ["param1"] = 157, ["z"] = 4, ["name"] = "stairs:slab_pine_wood"}, {["x"] = 10, ["y"] = 4, ["param1"] = 15, ["z"] = 5, ["name"] = "default:pine_wood"}, {["x"] = 10, ["y"] = 4, ["param1"] = 15, ["z"] = 6, ["name"] = "default:pine_wood"}, {["x"] = 10, ["y"] = 4, ["param1"] = 15, ["z"] = 7, ["name"] = "default:pine_wood"}, {["x"] = 10, ["y"] = 4, ["param1"] = 15, ["z"] = 8, ["name"] = "default:pine_wood"}, {["x"] = 10, ["y"] = 4, ["param1"] = 15, ["z"] = 9, ["name"] = "default:pine_wood"}, {["x"] = 10, ["y"] = 4, ["param1"] = 15, ["z"] = 10, ["name"] = "default:pine_wood"}, {["x"] = 10, ["y"] = 4, ["param1"] = 15, ["z"] = 11, ["name"] = "default:pine_wood"}, {["x"] = 10, ["y"] = 4, ["param1"] = 15, ["z"] = 12, ["name"] = "default:silver_sandstone"}, {["x"] = 10, ["y"] = 5, ["param1"] = 14, ["z"] = 0, ["name"] = "default:silver_sandstone"}, {["x"] = 10, ["param2"] = 16, ["y"] = 5, ["param1"] = 172, ["z"] = 2, ["name"] = "stairs:slab_pine_wood"}, {["x"] = 10, ["param2"] = 16, ["y"] = 5, ["param1"] = 189, ["z"] = 3, ["name"] = "stairs:slab_pine_wood"}, {["x"] = 10, ["y"] = 5, ["param1"] = 15, ["z"] = 12, ["name"] = "default:silver_sandstone"}, {["x"] = 10, ["y"] = 6, ["param1"] = 14, ["z"] = 0, ["name"] = "default:silver_sandstone"}, {["x"] = 10, ["y"] = 7, ["param1"] = 14, ["z"] = 0, ["name"] = "default:silver_sandstone"}, {["x"] = 10, ["param2"] = 21, ["y"] = 7, ["param1"] = 222, ["z"] = 1, ["name"] = "stairs:slab_pine_wood"}, {["x"] = 10, ["param2"] = 21, ["y"] = 7, ["param1"] = 205, ["z"] = 2, ["name"] = "stairs:slab_obsidian_glass"}, {["x"] = 10, ["param2"] = 21, ["y"] = 7, ["param1"] = 222, ["z"] = 3, ["name"] = "stairs:slab_pine_wood"}, {["x"] = 10, ["param2"] = 8, ["y"] = 7, ["param1"] = 206, ["z"] = 4, ["name"] = "stairs:stair_pine_wood"}, {["x"] = 10, ["y"] = 8, ["z"] = 0, ["name"] = "default:silver_sandstone"}, {["x"] = 10, ["y"] = 8, ["param1"] = 239, ["z"] = 1, ["name"] = "default:meselamp"}, {["x"] = 10, ["y"] = 8, ["param1"] = 222, ["z"] = 2, ["name"] = "default:water_source"}, {["x"] = 10, ["y"] = 8, ["param1"] = 239, ["z"] = 3, ["name"] = "default:meselamp"}, {["x"] = 10, ["param2"] = 4, ["y"] = 8, ["param1"] = 222, ["z"] = 4, ["name"] = "stairs:slab_pine_wood"}, {["x"] = 10, ["y"] = 9, ["param1"] = 15, ["z"] = 0, ["name"] = "default:silver_sandstone"}, {["x"] = 10, ["y"] = 9, ["param1"] = 14, ["z"] = 1, ["name"] = "default:pine_wood"}, {["x"] = 10, ["y"] = 9, ["param1"] = 14, ["z"] = 2, ["name"] = "default:pine_wood"}, {["x"] = 10, ["y"] = 9, ["param1"] = 14, ["z"] = 3, ["name"] = "default:pine_wood"}, {["x"] = 10, ["y"] = 9, ["z"] = 4, ["name"] = "default:pine_wood"}, {["x"] = 10, ["y"] = 10, ["param1"] = 62, ["z"] = 0, ["name"] = "default:silver_sandstone"}, {["x"] = 10, ["y"] = 10, ["param1"] = 78, ["z"] = 1, ["name"] = "default:silver_sandstone"}, {["x"] = 10, ["y"] = 10, ["param1"] = 95, ["z"] = 2, ["name"] = "default:silver_sandstone"}, {["x"] = 10, ["y"] = 10, ["param1"] = 111, ["z"] = 3, ["name"] = "default:silver_sandstone"}, {["x"] = 10, ["y"] = 10, ["param1"] = 127, ["z"] = 4, ["name"] = "default:silver_sandstone"}, {["x"] = 10, ["y"] = 10, ["param1"] = 175, ["z"] = 5, ["name"] = "default:silver_sandstone"}, {["x"] = 10, ["y"] = 10, ["param1"] = 159, ["z"] = 6, ["name"] = "default:silver_sandstone"}, {["x"] = 10, ["y"] = 10, ["param1"] = 143, ["z"] = 7, ["name"] = "default:silver_sandstone"}, {["x"] = 10, ["y"] = 10, ["param1"] = 127, ["z"] = 8, ["name"] = "default:silver_sandstone"}, {["x"] = 10, ["y"] = 10, ["param1"] = 111, ["z"] = 9, ["name"] = "default:silver_sandstone"}, {["x"] = 10, ["y"] = 10, ["param1"] = 95, ["z"] = 10, ["name"] = "default:silver_sandstone"}, {["x"] = 10, ["y"] = 10, ["param1"] = 79, ["z"] = 11, ["name"] = "default:silver_sandstone"}, {["x"] = 10, ["y"] = 10, ["param1"] = 63, ["z"] = 12, ["name"] = "default:silver_sandstone"}, {["x"] = 11, ["y"] = 0, ["z"] = 0, ["name"] = "default:silver_sandstone"}, {["x"] = 11, ["y"] = 0, ["z"] = 1, ["name"] = "default:silver_sandstone"}, {["x"] = 11, ["y"] = 0, ["z"] = 2, ["name"] = "default:silver_sandstone"}, {["x"] = 11, ["y"] = 0, ["z"] = 3, ["name"] = "default:silver_sandstone"}, {["x"] = 11, ["y"] = 0, ["z"] = 4, ["name"] = "default:silver_sandstone"}, {["x"] = 11, ["y"] = 0, ["z"] = 5, ["name"] = "default:silver_sandstone"}, {["x"] = 11, ["y"] = 0, ["z"] = 6, ["name"] = "default:silver_sandstone"}, {["x"] = 11, ["y"] = 0, ["z"] = 7, ["name"] = "default:silver_sandstone"}, {["x"] = 11, ["y"] = 0, ["z"] = 8, ["name"] = "default:silver_sandstone"}, {["x"] = 11, ["y"] = 0, ["z"] = 9, ["name"] = "default:silver_sandstone"}, {["x"] = 11, ["y"] = 0, ["z"] = 10, ["name"] = "default:silver_sandstone"}, {["x"] = 11, ["y"] = 0, ["z"] = 11, ["name"] = "default:silver_sandstone"}, {["x"] = 11, ["y"] = 0, ["z"] = 12, ["name"] = "default:silver_sandstone"}, {["x"] = 11, ["y"] = 1, ["z"] = 0, ["name"] = "default:silver_sandstone"}, {["x"] = 11, ["y"] = 1, ["param1"] = 15, ["z"] = 1, ["name"] = "default:silver_sandstone"}, {["x"] = 11, ["y"] = 1, ["param1"] = 15, ["z"] = 2, ["name"] = "default:silver_sandstone"}, {["x"] = 11, ["y"] = 1, ["param1"] = 15, ["z"] = 3, ["name"] = "default:silver_sandstone"}, {["x"] = 11, ["y"] = 1, ["param1"] = 15, ["z"] = 4, ["name"] = "default:silver_sandstone"}, {["x"] = 11, ["y"] = 1, ["param1"] = 15, ["z"] = 5, ["name"] = "default:silver_sandstone"}, {["x"] = 11, ["y"] = 1, ["param1"] = 15, ["z"] = 6, ["name"] = "default:silver_sandstone"}, {["x"] = 11, ["y"] = 1, ["param1"] = 15, ["z"] = 7, ["name"] = "default:silver_sandstone"}, {["x"] = 11, ["y"] = 1, ["param1"] = 15, ["z"] = 8, ["name"] = "default:silver_sandstone"}, {["x"] = 11, ["y"] = 1, ["param1"] = 15, ["z"] = 9, ["name"] = "default:silver_sandstone"}, {["x"] = 11, ["y"] = 1, ["param1"] = 15, ["z"] = 10, ["name"] = "default:silver_sandstone"}, {["x"] = 11, ["y"] = 1, ["param1"] = 15, ["z"] = 11, ["name"] = "default:silver_sandstone"}, {["x"] = 11, ["y"] = 1, ["param1"] = 15, ["z"] = 12, ["name"] = "default:silver_sandstone"}, {["x"] = 11, ["y"] = 2, ["param1"] = 14, ["z"] = 0, ["name"] = "default:silver_sandstone"}, {["x"] = 11, ["y"] = 2, ["param1"] = 14, ["z"] = 1, ["name"] = "default:pine_wood"}, {["x"] = 11, ["y"] = 2, ["z"] = 2, ["name"] = "default:pine_wood"}, {["x"] = 11, ["y"] = 2, ["z"] = 3, ["name"] = "default:pine_wood"}, {["x"] = 11, ["param2"] = 2, ["y"] = 2, ["param1"] = 126, ["z"] = 4, ["name"] = "doors:trapdoor_open"}, {["x"] = 11, ["y"] = 2, ["z"] = 6, ["name"] = "default:pine_wood"}, {["x"] = 11, ["y"] = 2, ["z"] = 7, ["name"] = "default:brick"}, {["x"] = 11, ["y"] = 2, ["z"] = 9, ["name"] = "default:brick"}, {["x"] = 11, ["y"] = 2, ["z"] = 10, ["name"] = "default:brick"}, {["x"] = 11, ["y"] = 2, ["param1"] = 15, ["z"] = 11, ["name"] = "default:pine_wood"}, {["x"] = 11, ["y"] = 2, ["param1"] = 15, ["z"] = 12, ["name"] = "default:silver_sandstone"}, {["x"] = 11, ["y"] = 3, ["param1"] = 14, ["z"] = 0, ["name"] = "default:silver_sandstone"}, {["x"] = 11, ["y"] = 3, ["param1"] = 14, ["z"] = 1, ["name"] = "default:pine_wood"}, {["x"] = 11, ["y"] = 3, ["z"] = 2, ["name"] = "default:pine_wood"}, {["x"] = 11, ["param2"] = 2, ["y"] = 3, ["param1"] = 157, ["z"] = 3, ["name"] = "stairs:slab_pine_wood"}, {["x"] = 11, ["param2"] = 2, ["y"] = 3, ["param1"] = 142, ["z"] = 4, ["name"] = "doors:trapdoor_open"}, {["x"] = 11, ["y"] = 3, ["z"] = 6, ["name"] = "default:pine_wood"}, {["x"] = 11, ["y"] = 3, ["z"] = 7, ["name"] = "default:brick"}, {["x"] = 11, ["y"] = 3, ["z"] = 9, ["name"] = "default:brick"}, {["x"] = 11, ["y"] = 3, ["z"] = 10, ["name"] = "default:brick"}, {["x"] = 11, ["y"] = 3, ["param1"] = 15, ["z"] = 11, ["name"] = "default:pine_wood"}, {["x"] = 11, ["y"] = 3, ["param1"] = 15, ["z"] = 12, ["name"] = "default:silver_sandstone"}, {["x"] = 11, ["y"] = 4, ["param1"] = 14, ["z"] = 0, ["name"] = "default:silver_sandstone"}, {["x"] = 11, ["y"] = 4, ["param1"] = 14, ["z"] = 1, ["name"] = "default:pine_wood"}, {["x"] = 11, ["param2"] = 21, ["y"] = 4, ["param1"] = 157, ["z"] = 4, ["name"] = "stairs:slab_pine_wood"}, {["x"] = 11, ["y"] = 4, ["param1"] = 15, ["z"] = 5, ["name"] = "default:pine_wood"}, {["x"] = 11, ["y"] = 4, ["param1"] = 15, ["z"] = 6, ["name"] = "default:pine_wood"}, {["x"] = 11, ["y"] = 4, ["param1"] = 15, ["z"] = 7, ["name"] = "default:pine_wood"}, {["x"] = 11, ["y"] = 4, ["param1"] = 15, ["z"] = 8, ["name"] = "default:pine_wood"}, {["x"] = 11, ["y"] = 4, ["param1"] = 15, ["z"] = 9, ["name"] = "default:pine_wood"}, {["x"] = 11, ["y"] = 4, ["param1"] = 15, ["z"] = 10, ["name"] = "default:pine_wood"}, {["x"] = 11, ["y"] = 4, ["param1"] = 15, ["z"] = 11, ["name"] = "default:pine_wood"}, {["x"] = 11, ["y"] = 4, ["param1"] = 15, ["z"] = 12, ["name"] = "default:silver_sandstone"}, {["x"] = 11, ["y"] = 5, ["param1"] = 14, ["z"] = 0, ["name"] = "default:silver_sandstone"}, {["x"] = 11, ["param2"] = 3, ["y"] = 5, ["param1"] = 188, ["z"] = 1, ["name"] = "doors:trapdoor_open"}, {["x"] = 11, ["param2"] = 4, ["y"] = 5, ["param1"] = 174, ["z"] = 4, ["name"] = "stairs:slab_pine_wood"}, {["x"] = 11, ["y"] = 5, ["param1"] = 15, ["z"] = 12, ["name"] = "default:silver_sandstone"}, {["x"] = 11, ["y"] = 6, ["param1"] = 14, ["z"] = 0, ["name"] = "default:silver_sandstone"}, {["x"] = 11, ["y"] = 7, ["param1"] = 14, ["z"] = 0, ["name"] = "default:silver_sandstone"}, {["x"] = 11, ["param2"] = 21, ["y"] = 7, ["param1"] = 222, ["z"] = 1, ["name"] = "stairs:slab_pine_wood"}, {["x"] = 11, ["param2"] = 21, ["y"] = 7, ["param1"] = 205, ["z"] = 2, ["name"] = "stairs:slab_obsidian_glass"}, {["x"] = 11, ["param2"] = 21, ["y"] = 7, ["param1"] = 222, ["z"] = 3, ["name"] = "stairs:slab_pine_wood"}, {["x"] = 11, ["param2"] = 8, ["y"] = 7, ["param1"] = 206, ["z"] = 4, ["name"] = "stairs:stair_pine_wood"}, {["x"] = 11, ["y"] = 8, ["param1"] = 14, ["z"] = 0, ["name"] = "default:silver_sandstone"}, {["x"] = 11, ["y"] = 8, ["param1"] = 239, ["z"] = 1, ["name"] = "default:meselamp"}, {["x"] = 11, ["y"] = 8, ["param1"] = 222, ["z"] = 2, ["name"] = "default:water_source"}, {["x"] = 11, ["y"] = 8, ["param1"] = 239, ["z"] = 3, ["name"] = "default:meselamp"}, {["x"] = 11, ["param2"] = 4, ["y"] = 8, ["param1"] = 222, ["z"] = 4, ["name"] = "stairs:slab_pine_wood"}, {["x"] = 11, ["y"] = 9, ["param1"] = 15, ["z"] = 0, ["name"] = "default:silver_sandstone"}, {["x"] = 11, ["y"] = 9, ["param1"] = 14, ["z"] = 1, ["name"] = "default:pine_wood"}, {["x"] = 11, ["y"] = 9, ["param1"] = 14, ["z"] = 2, ["name"] = "default:pine_wood"}, {["x"] = 11, ["y"] = 9, ["param1"] = 14, ["z"] = 3, ["name"] = "default:pine_wood"}, {["x"] = 11, ["y"] = 9, ["z"] = 4, ["name"] = "default:pine_wood"}, {["x"] = 11, ["y"] = 10, ["param1"] = 62, ["z"] = 0, ["name"] = "default:silver_sandstone"}, {["x"] = 11, ["y"] = 10, ["param1"] = 78, ["z"] = 1, ["name"] = "default:silver_sandstone"}, {["x"] = 11, ["y"] = 10, ["param1"] = 95, ["z"] = 2, ["name"] = "default:silver_sandstone"}, {["x"] = 11, ["y"] = 10, ["param1"] = 111, ["z"] = 3, ["name"] = "default:silver_sandstone"}, {["x"] = 11, ["y"] = 10, ["param1"] = 127, ["z"] = 4, ["name"] = "default:silver_sandstone"}, {["x"] = 11, ["y"] = 10, ["param1"] = 175, ["z"] = 5, ["name"] = "default:silver_sandstone"}, {["x"] = 11, ["y"] = 10, ["param1"] = 159, ["z"] = 6, ["name"] = "default:silver_sandstone"}, {["x"] = 11, ["y"] = 10, ["param1"] = 143, ["z"] = 7, ["name"] = "default:silver_sandstone"}, {["x"] = 11, ["y"] = 10, ["param1"] = 127, ["z"] = 8, ["name"] = "default:silver_sandstone"}, {["x"] = 11, ["y"] = 10, ["param1"] = 111, ["z"] = 9, ["name"] = "default:silver_sandstone"}, {["x"] = 11, ["y"] = 10, ["param1"] = 95, ["z"] = 10, ["name"] = "default:silver_sandstone"}, {["x"] = 11, ["y"] = 10, ["param1"] = 79, ["z"] = 11, ["name"] = "default:silver_sandstone"}, {["x"] = 11, ["y"] = 10, ["param1"] = 63, ["z"] = 12, ["name"] = "default:silver_sandstone"}, {["x"] = 12, ["y"] = 0, ["z"] = 0, ["name"] = "default:silver_sandstone"}, {["x"] = 12, ["y"] = 0, ["z"] = 1, ["name"] = "default:silver_sandstone"}, {["x"] = 12, ["y"] = 0, ["z"] = 2, ["name"] = "default:silver_sandstone"}, {["x"] = 12, ["y"] = 0, ["z"] = 3, ["name"] = "default:silver_sandstone"}, {["x"] = 12, ["y"] = 0, ["z"] = 4, ["name"] = "default:silver_sandstone"}, {["x"] = 12, ["y"] = 0, ["z"] = 5, ["name"] = "default:silver_sandstone"}, {["x"] = 12, ["y"] = 0, ["z"] = 6, ["name"] = "default:silver_sandstone"}, {["x"] = 12, ["y"] = 0, ["z"] = 7, ["name"] = "default:silver_sandstone"}, {["x"] = 12, ["y"] = 0, ["z"] = 8, ["name"] = "default:silver_sandstone"}, {["x"] = 12, ["y"] = 0, ["z"] = 9, ["name"] = "default:silver_sandstone"}, {["x"] = 12, ["y"] = 0, ["z"] = 10, ["name"] = "default:silver_sandstone"}, {["x"] = 12, ["y"] = 0, ["z"] = 11, ["name"] = "default:silver_sandstone"}, {["x"] = 12, ["y"] = 0, ["z"] = 12, ["name"] = "default:silver_sandstone"}, {["x"] = 12, ["y"] = 1, ["z"] = 0, ["name"] = "default:silver_sandstone"}, {["x"] = 12, ["y"] = 1, ["param1"] = 15, ["z"] = 1, ["name"] = "default:silver_sandstone"}, {["x"] = 12, ["y"] = 1, ["param1"] = 15, ["z"] = 2, ["name"] = "default:silver_sandstone"}, {["x"] = 12, ["y"] = 1, ["z"] = 3, ["name"] = "default:silver_sandstone"}, {["x"] = 12, ["y"] = 1, ["param1"] = 15, ["z"] = 4, ["name"] = "default:silver_sandstone"}, {["x"] = 12, ["y"] = 1, ["param1"] = 15, ["z"] = 5, ["name"] = "default:silver_sandstone"}, {["x"] = 12, ["y"] = 1, ["param1"] = 15, ["z"] = 6, ["name"] = "default:silver_sandstone"}, {["x"] = 12, ["y"] = 1, ["param1"] = 15, ["z"] = 7, ["name"] = "default:silver_sandstone"}, {["x"] = 12, ["y"] = 1, ["param1"] = 15, ["z"] = 8, ["name"] = "default:silver_sandstone"}, {["x"] = 12, ["y"] = 1, ["param1"] = 15, ["z"] = 9, ["name"] = "default:silver_sandstone"}, {["x"] = 12, ["y"] = 1, ["param1"] = 15, ["z"] = 10, ["name"] = "default:silver_sandstone"}, {["x"] = 12, ["y"] = 1, ["param1"] = 15, ["z"] = 11, ["name"] = "default:silver_sandstone"}, {["x"] = 12, ["y"] = 1, ["param1"] = 15, ["z"] = 12, ["name"] = "default:silver_sandstone"}, {["x"] = 12, ["y"] = 2, ["param1"] = 14, ["z"] = 0, ["name"] = "default:silver_sandstone"}, {["x"] = 12, ["y"] = 2, ["param1"] = 14, ["z"] = 1, ["name"] = "default:pine_wood"}, {["x"] = 12, ["y"] = 2, ["z"] = 2, ["name"] = "default:pine_wood"}, {["x"] = 12, ["y"] = 2, ["z"] = 3, ["name"] = "default:pine_wood"}, {["x"] = 12, ["param2"] = 2, ["y"] = 2, ["param1"] = 126, ["z"] = 4, ["name"] = "doors:trapdoor_open"}, {["x"] = 12, ["y"] = 2, ["z"] = 6, ["name"] = "default:pine_wood"}, {["x"] = 12, ["y"] = 2, ["z"] = 7, ["name"] = "default:brick"}, {["x"] = 12, ["y"] = 2, ["z"] = 10, ["name"] = "default:brick"}, {["x"] = 12, ["y"] = 2, ["param1"] = 15, ["z"] = 11, ["name"] = "default:pine_wood"}, {["x"] = 12, ["y"] = 2, ["param1"] = 15, ["z"] = 12, ["name"] = "default:silver_sandstone"}, {["x"] = 12, ["y"] = 3, ["param1"] = 14, ["z"] = 0, ["name"] = "default:silver_sandstone"}, {["x"] = 12, ["y"] = 3, ["param1"] = 14, ["z"] = 1, ["name"] = "default:pine_wood"}, {["x"] = 12, ["y"] = 3, ["z"] = 2, ["name"] = "default:pine_wood"}, {["x"] = 12, ["param2"] = 2, ["y"] = 3, ["param1"] = 142, ["z"] = 4, ["name"] = "doors:trapdoor_open"}, {["x"] = 12, ["y"] = 3, ["z"] = 6, ["name"] = "default:pine_wood"}, {["x"] = 12, ["y"] = 3, ["z"] = 7, ["name"] = "default:brick"}, {["x"] = 12, ["y"] = 3, ["z"] = 10, ["name"] = "default:brick"}, {["x"] = 12, ["y"] = 3, ["param1"] = 15, ["z"] = 11, ["name"] = "default:pine_wood"}, {["x"] = 12, ["y"] = 3, ["param1"] = 15, ["z"] = 12, ["name"] = "default:silver_sandstone"}, {["x"] = 12, ["y"] = 4, ["param1"] = 14, ["z"] = 0, ["name"] = "default:silver_sandstone"}, {["x"] = 12, ["y"] = 4, ["param1"] = 14, ["z"] = 1, ["name"] = "default:pine_wood"}, {["x"] = 12, ["param2"] = 1, ["y"] = 4, ["param1"] = 155, ["z"] = 2, ["name"] = "stairs:slab_pine_wood"}, {["x"] = 12, ["param2"] = 21, ["y"] = 4, ["param1"] = 157, ["z"] = 4, ["name"] = "stairs:slab_pine_wood"}, {["x"] = 12, ["y"] = 4, ["param1"] = 15, ["z"] = 5, ["name"] = "default:pine_wood"}, {["x"] = 12, ["y"] = 4, ["param1"] = 15, ["z"] = 6, ["name"] = "default:pine_wood"}, {["x"] = 12, ["y"] = 4, ["param1"] = 15, ["z"] = 7, ["name"] = "default:pine_wood"}, {["x"] = 12, ["y"] = 4, ["param1"] = 15, ["z"] = 8, ["name"] = "default:pine_wood"}, {["x"] = 12, ["y"] = 4, ["param1"] = 15, ["z"] = 9, ["name"] = "default:pine_wood"}, {["x"] = 12, ["y"] = 4, ["param1"] = 15, ["z"] = 10, ["name"] = "default:pine_wood"}, {["x"] = 12, ["y"] = 4, ["param1"] = 15, ["z"] = 11, ["name"] = "default:pine_wood"}, {["x"] = 12, ["y"] = 4, ["param1"] = 15, ["z"] = 12, ["name"] = "default:silver_sandstone"}, {["x"] = 12, ["y"] = 5, ["param1"] = 14, ["z"] = 0, ["name"] = "default:silver_sandstone"}, {["x"] = 12, ["param2"] = 4, ["y"] = 5, ["param1"] = 174, ["z"] = 4, ["name"] = "stairs:slab_pine_wood"}, {["x"] = 12, ["y"] = 5, ["param1"] = 15, ["z"] = 12, ["name"] = "default:silver_sandstone"}, {["x"] = 12, ["y"] = 6, ["param1"] = 14, ["z"] = 0, ["name"] = "default:silver_sandstone"}, {["x"] = 12, ["y"] = 7, ["param1"] = 14, ["z"] = 0, ["name"] = "default:silver_sandstone"}, {["x"] = 12, ["param2"] = 21, ["y"] = 7, ["param1"] = 222, ["z"] = 1, ["name"] = "stairs:slab_pine_wood"}, {["x"] = 12, ["param2"] = 21, ["y"] = 7, ["param1"] = 205, ["z"] = 2, ["name"] = "stairs:slab_obsidian_glass"}, {["x"] = 12, ["param2"] = 21, ["y"] = 7, ["param1"] = 222, ["z"] = 3, ["name"] = "stairs:slab_pine_wood"}, {["x"] = 12, ["param2"] = 8, ["y"] = 7, ["param1"] = 206, ["z"] = 4, ["name"] = "stairs:stair_pine_wood"}, {["x"] = 12, ["y"] = 8, ["param1"] = 14, ["z"] = 0, ["name"] = "default:silver_sandstone"}, {["x"] = 12, ["y"] = 8, ["param1"] = 239, ["z"] = 1, ["name"] = "default:meselamp"}, {["x"] = 12, ["y"] = 8, ["param1"] = 222, ["z"] = 2, ["name"] = "default:water_source"}, {["x"] = 12, ["y"] = 8, ["param1"] = 239, ["z"] = 3, ["name"] = "default:meselamp"}, {["x"] = 12, ["param2"] = 4, ["y"] = 8, ["param1"] = 222, ["z"] = 4, ["name"] = "stairs:slab_pine_wood"}, {["x"] = 12, ["y"] = 9, ["param1"] = 15, ["z"] = 0, ["name"] = "default:silver_sandstone"}, {["x"] = 12, ["y"] = 9, ["param1"] = 14, ["z"] = 1, ["name"] = "default:pine_wood"}, {["x"] = 12, ["y"] = 9, ["param1"] = 14, ["z"] = 2, ["name"] = "default:pine_wood"}, {["x"] = 12, ["y"] = 9, ["param1"] = 14, ["z"] = 3, ["name"] = "default:pine_wood"}, {["x"] = 12, ["y"] = 9, ["z"] = 4, ["name"] = "default:pine_wood"}, {["x"] = 12, ["y"] = 10, ["param1"] = 62, ["z"] = 0, ["name"] = "default:silver_sandstone"}, {["x"] = 12, ["y"] = 10, ["param1"] = 78, ["z"] = 1, ["name"] = "default:silver_sandstone"}, {["x"] = 12, ["y"] = 10, ["param1"] = 95, ["z"] = 2, ["name"] = "default:silver_sandstone"}, {["x"] = 12, ["y"] = 10, ["param1"] = 111, ["z"] = 3, ["name"] = "default:silver_sandstone"}, {["x"] = 12, ["y"] = 10, ["param1"] = 127, ["z"] = 4, ["name"] = "default:silver_sandstone"}, {["x"] = 12, ["y"] = 10, ["param1"] = 175, ["z"] = 5, ["name"] = "default:silver_sandstone"}, {["x"] = 12, ["y"] = 10, ["param1"] = 159, ["z"] = 6, ["name"] = "default:silver_sandstone"}, {["x"] = 12, ["y"] = 10, ["param1"] = 143, ["z"] = 7, ["name"] = "default:silver_sandstone"}, {["x"] = 12, ["y"] = 10, ["param1"] = 127, ["z"] = 8, ["name"] = "default:silver_sandstone"}, {["x"] = 12, ["y"] = 10, ["param1"] = 111, ["z"] = 9, ["name"] = "default:silver_sandstone"}, {["x"] = 12, ["y"] = 10, ["param1"] = 95, ["z"] = 10, ["name"] = "default:silver_sandstone"}, {["x"] = 12, ["y"] = 10, ["param1"] = 79, ["z"] = 11, ["name"] = "default:silver_sandstone"}, {["x"] = 12, ["y"] = 10, ["param1"] = 63, ["z"] = 12, ["name"] = "default:silver_sandstone"}, {["x"] = 13, ["y"] = 0, ["z"] = 0, ["name"] = "default:silver_sandstone"}, {["x"] = 13, ["y"] = 0, ["z"] = 1, ["name"] = "default:silver_sandstone"}, {["x"] = 13, ["y"] = 0, ["z"] = 2, ["name"] = "default:silver_sandstone"}, {["x"] = 13, ["y"] = 0, ["z"] = 3, ["name"] = "default:silver_sandstone"}, {["x"] = 13, ["y"] = 0, ["z"] = 4, ["name"] = "default:silver_sandstone"}, {["x"] = 13, ["y"] = 0, ["z"] = 5, ["name"] = "default:silver_sandstone"}, {["x"] = 13, ["y"] = 0, ["z"] = 6, ["name"] = "default:silver_sandstone"}, {["x"] = 13, ["y"] = 0, ["z"] = 7, ["name"] = "default:silver_sandstone"}, {["x"] = 13, ["y"] = 0, ["z"] = 8, ["name"] = "default:silver_sandstone"}, {["x"] = 13, ["y"] = 0, ["z"] = 9, ["name"] = "default:silver_sandstone"}, {["x"] = 13, ["y"] = 0, ["z"] = 10, ["name"] = "default:silver_sandstone"}, {["x"] = 13, ["y"] = 0, ["z"] = 11, ["name"] = "default:silver_sandstone"}, {["x"] = 13, ["y"] = 0, ["z"] = 12, ["name"] = "default:silver_sandstone"}, {["x"] = 13, ["y"] = 1, ["z"] = 0, ["name"] = "default:silver_sandstone"}, {["x"] = 13, ["y"] = 1, ["param1"] = 15, ["z"] = 1, ["name"] = "default:silver_sandstone"}, {["x"] = 13, ["y"] = 1, ["param1"] = 15, ["z"] = 2, ["name"] = "default:silver_sandstone"}, {["x"] = 13, ["y"] = 1, ["param1"] = 15, ["z"] = 3, ["name"] = "default:silver_sandstone"}, {["x"] = 13, ["y"] = 1, ["param1"] = 15, ["z"] = 4, ["name"] = "default:silver_sandstone"}, {["x"] = 13, ["y"] = 1, ["param1"] = 15, ["z"] = 5, ["name"] = "default:silver_sandstone"}, {["x"] = 13, ["y"] = 1, ["param1"] = 15, ["z"] = 6, ["name"] = "default:silver_sandstone"}, {["x"] = 13, ["y"] = 1, ["param1"] = 15, ["z"] = 7, ["name"] = "default:silver_sandstone"}, {["x"] = 13, ["y"] = 1, ["param1"] = 15, ["z"] = 8, ["name"] = "default:silver_sandstone"}, {["x"] = 13, ["y"] = 1, ["param1"] = 15, ["z"] = 9, ["name"] = "default:silver_sandstone"}, {["x"] = 13, ["y"] = 1, ["param1"] = 15, ["z"] = 10, ["name"] = "default:silver_sandstone"}, {["x"] = 13, ["y"] = 1, ["param1"] = 15, ["z"] = 11, ["name"] = "default:silver_sandstone"}, {["x"] = 13, ["y"] = 1, ["param1"] = 15, ["z"] = 12, ["name"] = "default:silver_sandstone"}, {["x"] = 13, ["y"] = 2, ["param1"] = 14, ["z"] = 0, ["name"] = "default:silver_sandstone"}, {["x"] = 13, ["y"] = 2, ["param1"] = 14, ["z"] = 1, ["name"] = "default:pine_wood"}, {["x"] = 13, ["y"] = 2, ["z"] = 2, ["name"] = "default:pine_wood"}, {["x"] = 13, ["param2"] = 2, ["y"] = 2, ["param1"] = 141, ["z"] = 3, ["name"] = "stairs:slab_pine_wood"}, {["x"] = 13, ["param2"] = 2, ["y"] = 2, ["param1"] = 126, ["z"] = 4, ["name"] = "doors:trapdoor_open"}, {["x"] = 13, ["y"] = 2, ["z"] = 6, ["name"] = "default:pine_wood"}, {["x"] = 13, ["y"] = 2, ["z"] = 7, ["name"] = "default:brick"}, {["x"] = 13, ["y"] = 2, ["z"] = 10, ["name"] = "default:brick"}, {["x"] = 13, ["y"] = 2, ["param1"] = 15, ["z"] = 11, ["name"] = "default:pine_wood"}, {["x"] = 13, ["y"] = 2, ["param1"] = 15, ["z"] = 12, ["name"] = "default:silver_sandstone"}, {["x"] = 13, ["y"] = 3, ["param1"] = 14, ["z"] = 0, ["name"] = "default:silver_sandstone"}, {["x"] = 13, ["y"] = 3, ["param1"] = 14, ["z"] = 1, ["name"] = "default:pine_wood"}, {["x"] = 13, ["y"] = 3, ["z"] = 2, ["name"] = "default:pine_wood"}, {["x"] = 13, ["param2"] = 2, ["y"] = 3, ["param1"] = 142, ["z"] = 4, ["name"] = "doors:trapdoor_open"}, {["x"] = 13, ["y"] = 3, ["z"] = 6, ["name"] = "default:pine_wood"}, {["x"] = 13, ["y"] = 3, ["z"] = 7, ["name"] = "default:brick"}, {["x"] = 13, ["y"] = 3, ["z"] = 10, ["name"] = "default:brick"}, {["x"] = 13, ["y"] = 3, ["param1"] = 15, ["z"] = 11, ["name"] = "default:pine_wood"}, {["x"] = 13, ["y"] = 3, ["param1"] = 15, ["z"] = 12, ["name"] = "default:silver_sandstone"}, {["x"] = 13, ["y"] = 4, ["param1"] = 14, ["z"] = 0, ["name"] = "default:silver_sandstone"}, {["x"] = 13, ["y"] = 4, ["param1"] = 14, ["z"] = 1, ["name"] = "default:pine_wood"}, {["x"] = 13, ["y"] = 4, ["z"] = 2, ["name"] = "default:pine_wood"}, {["x"] = 13, ["param2"] = 20, ["y"] = 4, ["param1"] = 157, ["z"] = 4, ["name"] = "stairs:slab_pine_wood"}, {["x"] = 13, ["param2"] = 4, ["y"] = 4, ["param1"] = 15, ["z"] = 5, ["name"] = "default:pine_wood"}, {["x"] = 13, ["y"] = 4, ["param1"] = 15, ["z"] = 6, ["name"] = "default:pine_wood"}, {["x"] = 13, ["y"] = 4, ["param1"] = 15, ["z"] = 7, ["name"] = "default:pine_wood"}, {["x"] = 13, ["y"] = 4, ["param1"] = 15, ["z"] = 8, ["name"] = "default:pine_wood"}, {["x"] = 13, ["y"] = 4, ["param1"] = 15, ["z"] = 9, ["name"] = "default:pine_wood"}, {["x"] = 13, ["y"] = 4, ["param1"] = 15, ["z"] = 10, ["name"] = "default:pine_wood"}, {["x"] = 13, ["y"] = 4, ["param1"] = 15, ["z"] = 11, ["name"] = "default:pine_wood"}, {["x"] = 13, ["y"] = 4, ["param1"] = 15, ["z"] = 12, ["name"] = "default:silver_sandstone"}, {["x"] = 13, ["y"] = 5, ["param1"] = 14, ["z"] = 0, ["name"] = "default:silver_sandstone"}, {["x"] = 13, ["param2"] = 16, ["y"] = 5, ["param1"] = 172, ["z"] = 2, ["name"] = "stairs:slab_pine_wood"}, {["x"] = 13, ["param2"] = 16, ["y"] = 5, ["param1"] = 189, ["z"] = 3, ["name"] = "stairs:slab_pine_wood"}, {["x"] = 13, ["param2"] = 4, ["y"] = 5, ["param1"] = 174, ["z"] = 4, ["name"] = "stairs:slab_pine_wood"}, {["x"] = 13, ["y"] = 5, ["param1"] = 15, ["z"] = 12, ["name"] = "default:silver_sandstone"}, {["x"] = 13, ["y"] = 6, ["param1"] = 14, ["z"] = 0, ["name"] = "default:silver_sandstone"}, {["x"] = 13, ["y"] = 7, ["param1"] = 14, ["z"] = 0, ["name"] = "default:silver_sandstone"}, {["x"] = 13, ["param2"] = 21, ["y"] = 7, ["param1"] = 222, ["z"] = 1, ["name"] = "stairs:slab_pine_wood"}, {["x"] = 13, ["param2"] = 21, ["y"] = 7, ["param1"] = 205, ["z"] = 2, ["name"] = "stairs:slab_obsidian_glass"}, {["x"] = 13, ["param2"] = 20, ["y"] = 7, ["param1"] = 222, ["z"] = 3, ["name"] = "stairs:slab_pine_wood"}, {["x"] = 13, ["param2"] = 8, ["y"] = 7, ["param1"] = 206, ["z"] = 4, ["name"] = "stairs:stair_pine_wood"}, {["x"] = 13, ["y"] = 8, ["param1"] = 14, ["z"] = 0, ["name"] = "default:silver_sandstone"}, {["x"] = 13, ["y"] = 8, ["param1"] = 239, ["z"] = 1, ["name"] = "default:meselamp"}, {["x"] = 13, ["y"] = 8, ["param1"] = 222, ["z"] = 2, ["name"] = "default:water_source"}, {["x"] = 13, ["y"] = 8, ["param1"] = 239, ["z"] = 3, ["name"] = "default:meselamp"}, {["x"] = 13, ["param2"] = 4, ["y"] = 8, ["param1"] = 222, ["z"] = 4, ["name"] = "stairs:slab_pine_wood"}, {["x"] = 13, ["y"] = 9, ["param1"] = 15, ["z"] = 0, ["name"] = "default:silver_sandstone"}, {["x"] = 13, ["y"] = 9, ["param1"] = 14, ["z"] = 1, ["name"] = "default:pine_wood"}, {["x"] = 13, ["y"] = 9, ["param1"] = 14, ["z"] = 2, ["name"] = "default:pine_wood"}, {["x"] = 13, ["y"] = 9, ["param1"] = 14, ["z"] = 3, ["name"] = "default:pine_wood"}, {["x"] = 13, ["y"] = 9, ["z"] = 4, ["name"] = "default:pine_wood"}, {["x"] = 13, ["y"] = 10, ["param1"] = 62, ["z"] = 0, ["name"] = "default:silver_sandstone"}, {["x"] = 13, ["y"] = 10, ["param1"] = 78, ["z"] = 1, ["name"] = "default:silver_sandstone"}, {["x"] = 13, ["y"] = 10, ["param1"] = 95, ["z"] = 2, ["name"] = "default:silver_sandstone"}, {["x"] = 13, ["y"] = 10, ["param1"] = 111, ["z"] = 3, ["name"] = "default:silver_sandstone"}, {["x"] = 13, ["y"] = 10, ["param1"] = 127, ["z"] = 4, ["name"] = "default:silver_sandstone"}, {["x"] = 13, ["y"] = 10, ["param1"] = 175, ["z"] = 5, ["name"] = "default:silver_sandstone"}, {["x"] = 13, ["y"] = 10, ["param1"] = 159, ["z"] = 6, ["name"] = "default:silver_sandstone"}, {["x"] = 13, ["y"] = 10, ["param1"] = 143, ["z"] = 7, ["name"] = "default:silver_sandstone"}, {["x"] = 13, ["y"] = 10, ["param1"] = 127, ["z"] = 8, ["name"] = "default:silver_sandstone"}, {["x"] = 13, ["y"] = 10, ["param1"] = 111, ["z"] = 9, ["name"] = "default:silver_sandstone"}, {["x"] = 13, ["y"] = 10, ["param1"] = 95, ["z"] = 10, ["name"] = "default:silver_sandstone"}, {["x"] = 13, ["y"] = 10, ["param1"] = 79, ["z"] = 11, ["name"] = "default:silver_sandstone"}, {["x"] = 13, ["y"] = 10, ["param1"] = 63, ["z"] = 12, ["name"] = "default:silver_sandstone"}, {["x"] = 14, ["y"] = 0, ["z"] = 0, ["name"] = "default:silver_sandstone"}, {["x"] = 14, ["y"] = 0, ["z"] = 1, ["name"] = "default:silver_sandstone"}, {["x"] = 14, ["y"] = 0, ["z"] = 2, ["name"] = "default:silver_sandstone"}, {["x"] = 14, ["y"] = 0, ["z"] = 3, ["name"] = "default:silver_sandstone"}, {["x"] = 14, ["y"] = 0, ["z"] = 4, ["name"] = "default:silver_sandstone"}, {["x"] = 14, ["y"] = 0, ["z"] = 5, ["name"] = "default:silver_sandstone"}, {["x"] = 14, ["y"] = 0, ["z"] = 6, ["name"] = "default:silver_sandstone"}, {["x"] = 14, ["y"] = 0, ["z"] = 7, ["name"] = "default:silver_sandstone"}, {["x"] = 14, ["y"] = 0, ["z"] = 8, ["name"] = "default:silver_sandstone"}, {["x"] = 14, ["y"] = 0, ["z"] = 9, ["name"] = "default:silver_sandstone"}, {["x"] = 14, ["y"] = 0, ["z"] = 10, ["name"] = "default:silver_sandstone"}, {["x"] = 14, ["y"] = 0, ["z"] = 11, ["name"] = "default:silver_sandstone"}, {["x"] = 14, ["y"] = 0, ["z"] = 12, ["name"] = "default:silver_sandstone"}, {["x"] = 14, ["y"] = 1, ["z"] = 0, ["name"] = "default:silver_sandstone"}, {["x"] = 14, ["y"] = 1, ["param1"] = 15, ["z"] = 1, ["name"] = "default:silver_sandstone"}, {["x"] = 14, ["y"] = 1, ["param1"] = 15, ["z"] = 2, ["name"] = "default:silver_sandstone"}, {["x"] = 14, ["y"] = 1, ["param1"] = 15, ["z"] = 3, ["name"] = "default:silver_sandstone"}, {["x"] = 14, ["y"] = 1, ["param1"] = 15, ["z"] = 4, ["name"] = "default:silver_sandstone"}, {["x"] = 14, ["y"] = 1, ["param1"] = 15, ["z"] = 5, ["name"] = "default:silver_sandstone"}, {["x"] = 14, ["y"] = 1, ["param1"] = 15, ["z"] = 6, ["name"] = "default:silver_sandstone"}, {["x"] = 14, ["y"] = 1, ["param1"] = 15, ["z"] = 7, ["name"] = "default:silver_sandstone"}, {["x"] = 14, ["y"] = 1, ["param1"] = 15, ["z"] = 8, ["name"] = "default:silver_sandstone"}, {["x"] = 14, ["y"] = 1, ["param1"] = 15, ["z"] = 9, ["name"] = "default:silver_sandstone"}, {["x"] = 14, ["y"] = 1, ["param1"] = 15, ["z"] = 10, ["name"] = "default:silver_sandstone"}, {["x"] = 14, ["y"] = 1, ["param1"] = 15, ["z"] = 11, ["name"] = "default:silver_sandstone"}, {["x"] = 14, ["y"] = 1, ["param1"] = 15, ["z"] = 12, ["name"] = "default:silver_sandstone"}, {["x"] = 14, ["y"] = 2, ["param1"] = 14, ["z"] = 0, ["name"] = "default:silver_sandstone"}, {["x"] = 14, ["y"] = 2, ["param1"] = 14, ["z"] = 1, ["name"] = "default:pine_wood"}, {["x"] = 14, ["y"] = 2, ["z"] = 6, ["name"] = "default:pine_wood"}, {["x"] = 14, ["y"] = 2, ["z"] = 7, ["name"] = "default:brick"}, {["x"] = 14, ["y"] = 2, ["z"] = 8, ["name"] = "default:brick"}, {["x"] = 14, ["meta"] = {["fields"] = {["timer_elapsed"] = "0", ["formspec"] = "size[8,8.5]list[context;src;2.75,0.5;1,1;]list[context;fuel;2.75,2.5;1,1;]image[2.75,1.5;1,1;default_furnace_fire_bg.png]image[3.75,1.5;1,1;gui_furnace_arrow_bg.png^[transformR270]list[context;dst;4.75,0.96;2,2;]list[current_player;main;0,4.25;8,1;]list[current_player;main;0,5.5;8,3;8]listring[context;dst]listring[current_player;main]listring[context;src]listring[current_player;main]listring[context;fuel]listring[current_player;main]image[0,4.25;1,1;gui_hb_bg.png]image[1,4.25;1,1;gui_hb_bg.png]image[2,4.25;1,1;gui_hb_bg.png]image[3,4.25;1,1;gui_hb_bg.png]image[4,4.25;1,1;gui_hb_bg.png]image[5,4.25;1,1;gui_hb_bg.png]image[6,4.25;1,1;gui_hb_bg.png]image[7,4.25;1,1;gui_hb_bg.png]", ["infotext"] = "\27(T@default)Furnace inactive\27E\
