5:return {{["x"] = 0, ["y"] = 0, ["z"] = 0, ["name"] = "default:dirt_with_grass"}, {["x"] = 0, ["y"] = 0, ["z"] = 1, ["name"] = "default:dirt_with_grass"}, {["x"] = 0, ["y"] = 0, ["z"] = 2, ["name"] = "default:dirt_with_grass"}, {["x"] = 0, ["y"] = 0, ["z"] = 3, ["name"] = "default:dirt_with_grass"}, {["x"] = 0, ["y"] = 0, ["z"] = 4, ["name"] = "default:dirt_with_grass"}, {["x"] = 0, ["y"] = 0, ["z"] = 5, ["name"] = "default:dirt_with_grass"}, {["x"] = 0, ["y"] = 0, ["z"] = 6, ["name"] = "default:dirt_with_grass"}, {["x"] = 0, ["y"] = 0, ["z"] = 7, ["name"] = "default:dirt_with_grass"}, {["x"] = 0, ["y"] = 0, ["z"] = 8, ["name"] = "default:dirt_with_grass"}, {["x"] = 0, ["y"] = 0, ["z"] = 9, ["name"] = "default:dirt_with_grass"}, {["x"] = 0, ["y"] = 0, ["z"] = 10, ["name"] = "default:dirt_with_grass"}, {["x"] = 0, ["y"] = 0, ["z"] = 11, ["name"] = "default:dirt_with_grass"}, {["x"] = 0, ["y"] = 0, ["z"] = 12, ["name"] = "default:dirt_with_grass"}, {["x"] = 0, ["y"] = 0, ["z"] = 13, ["name"] = "default:dirt_with_grass"}, {["x"] = 0, ["y"] = 0, ["z"] = 14, ["name"] = "default:dirt_with_grass"}, {["x"] = 0, ["y"] = 0, ["z"] = 15, ["name"] = "default:dirt_with_grass"}, {["x"] = 0, ["y"] = 0, ["z"] = 16, ["name"] = "default:dirt_with_grass"}, {["x"] = 0, ["y"] = 0, ["z"] = 17, ["name"] = "default:dirt_with_grass"}, {["x"] = 0, ["y"] = 0, ["z"] = 18, ["name"] = "default:dirt_with_grass"}, {["x"] = 0, ["y"] = 0, ["z"] = 19, ["name"] = "default:dirt_with_grass"}, {["x"] = 0, ["y"] = 0, ["z"] = 20, ["name"] = "default:dirt_with_grass"}, {["x"] = 0, ["y"] = 0, ["z"] = 21, ["name"] = "default:dirt_with_grass"}, {["x"] = 0, ["y"] = 0, ["z"] = 22, ["name"] = "default:dirt_with_grass"}, {["x"] = 0, ["y"] = 0, ["z"] = 23, ["name"] = "default:dirt_with_grass"}, {["x"] = 0, ["y"] = 0, ["z"] = 24, ["name"] = "default:dirt_with_grass"}, {["x"] = 0, ["y"] = 0, ["z"] = 25, ["name"] = "default:dirt_with_grass"}, {["x"] = 0, ["y"] = 0, ["z"] = 26, ["name"] = "default:dirt_with_grass"}, {["x"] = 0, ["y"] = 0, ["z"] = 27, ["name"] = "the_build_spawner:white"}, {["x"] = 0, ["y"] = 0, ["z"] = 28, ["name"] = "the_build_spawner:white"}, {["x"] = 0, ["y"] = 0, ["z"] = 29, ["name"] = "the_build_spawner:white"}, {["x"] = 0, ["y"] = 0, ["z"] = 30, ["name"] = "the_build_spawner:white"}, {["x"] = 0, ["y"] = 0, ["z"] = 31, ["name"] = "the_build_spawner:white"}, {["x"] = 0, ["y"] = 0, ["z"] = 32, ["name"] = "the_build_spawner:white"}, {["x"] = 0, ["y"] = 0, ["z"] = 33, ["name"] = "the_build_spawner:white"}, {["x"] = 0, ["y"] = 0, ["z"] = 34, ["name"] = "the_build_spawner:black"}, {["x"] = 0, ["y"] = 0, ["z"] = 35, ["name"] = "the_build_spawner:black"}, {["x"] = 0, ["y"] = 0, ["z"] = 36, ["name"] = "the_build_spawner:black"}, {["x"] = 0, ["y"] = 0, ["z"] = 37, ["name"] = "the_build_spawner:black"}, {["x"] = 0, ["y"] = 0, ["z"] = 38, ["name"] = "the_build_spawner:white"}, {["x"] = 0, ["y"] = 0, ["z"] = 39, ["name"] = "the_build_spawner:white"}, {["x"] = 0, ["y"] = 0, ["z"] = 40, ["name"] = "the_build_spawner:white"}, {["x"] = 0, ["y"] = 0, ["z"] = 41, ["name"] = "the_build_spawner:white"}, {["x"] = 0, ["y"] = 1, ["param1"] = 15, ["z"] = 0, ["name"] = "default:fence_wood"}, {["x"] = 0, ["y"] = 1, ["param1"] = 15, ["z"] = 1, ["name"] = "default:fence_wood"}, {["x"] = 0, ["y"] = 1, ["param1"] = 15, ["z"] = 2, ["name"] = "default:fence_wood"}, {["x"] = 0, ["y"] = 1, ["param1"] = 15, ["z"] = 3, ["name"] = "default:fence_wood"}, {["x"] = 0, ["y"] = 1, ["param1"] = 14, ["z"] = 4, ["name"] = "default:fence_wood"}, {["x"] = 0, ["y"] = 1, ["param1"] = 14, ["z"] = 5, ["name"] = "default:fence_wood"}, {["x"] = 0, ["y"] = 1, ["param1"] = 15, ["z"] = 6, ["name"] = "default:fence_wood"}, {["x"] = 0, ["y"] = 1, ["param1"] = 15, ["z"] = 7, ["name"] = "default:fence_wood"}, {["x"] = 0, ["y"] = 1, ["param1"] = 15, ["z"] = 8, ["name"] = "default:fence_wood"}, {["x"] = 0, ["y"] = 1, ["param1"] = 15, ["z"] = 9, ["name"] = "default:fence_wood"}, {["x"] = 0, ["y"] = 1, ["param1"] = 15, ["z"] = 10, ["name"] = "default:fence_wood"}, {["x"] = 0, ["y"] = 1, ["param1"] = 15, ["z"] = 11, ["name"] = "default:fence_wood"}, {["x"] = 0, ["y"] = 1, ["param1"] = 15, ["z"] = 12, ["name"] = "default:fence_wood"}, {["x"] = 0, ["y"] = 1, ["param1"] = 15, ["z"] = 13, ["name"] = "default:fence_wood"}, {["x"] = 0, ["y"] = 1, ["param1"] = 15, ["z"] = 14, ["name"] = "default:fence_wood"}, {["x"] = 0, ["y"] = 1, ["param1"] = 31, ["z"] = 15, ["name"] = "default:fence_wood"}, {["x"] = 0, ["y"] = 1, ["param1"] = 47, ["z"] = 16, ["name"] = "default:fence_wood"}, {["x"] = 0, ["y"] = 1, ["param1"] = 63, ["z"] = 17, ["name"] = "default:fence_wood"}, {["x"] = 0, ["y"] = 1, ["param1"] = 79, ["z"] = 18, ["name"] = "default:fence_wood"}, {["x"] = 0, ["y"] = 1, ["param1"] = 95, ["z"] = 19, ["name"] = "default:fence_wood"}, {["x"] = 0, ["y"] = 1, ["param1"] = 110, ["z"] = 20, ["name"] = "default:fence_wood"}, {["x"] = 0, ["y"] = 1, ["param1"] = 126, ["z"] = 21, ["name"] = "default:fence_wood"}, {["x"] = 0, ["y"] = 1, ["param1"] = 143, ["z"] = 22, ["name"] = "default:fence_wood"}, {["x"] = 0, ["y"] = 1, ["param1"] = 159, ["z"] = 23, ["name"] = "default:fence_wood"}, {["x"] = 0, ["y"] = 1, ["param1"] = 175, ["z"] = 24, ["name"] = "default:fence_wood"}, {["x"] = 0, ["y"] = 1, ["param1"] = 191, ["z"] = 25, ["name"] = "default:fence_wood"}, {["x"] = 0, ["y"] = 1, ["param1"] = 207, ["z"] = 26, ["name"] = "default:fence_wood"}, {["x"] = 0, ["y"] = 1, ["param1"] = 191, ["z"] = 27, ["name"] = "default:fence_wood"}, {["x"] = 0, ["y"] = 1, ["param1"] = 175, ["z"] = 28, ["name"] = "default:fence_wood"}, {["x"] = 0, ["y"] = 1, ["param1"] = 159, ["z"] = 29, ["name"] = "default:fence_wood"}, {["x"] = 0, ["y"] = 1, ["param1"] = 143, ["z"] = 30, ["name"] = "default:fence_wood"}, {["x"] = 0, ["y"] = 1, ["param1"] = 127, ["z"] = 31, ["name"] = "default:fence_wood"}, {["x"] = 0, ["y"] = 1, ["param1"] = 111, ["z"] = 32, ["name"] = "default:fence_wood"}, {["x"] = 0, ["y"] = 1, ["param1"] = 95, ["z"] = 33, ["name"] = "default:fence_wood"}, {["x"] = 0, ["y"] = 1, ["param1"] = 15, ["z"] = 41, ["name"] = "default:fence_wood"}, {["x"] = 1, ["y"] = 0, ["z"] = 0, ["name"] = "default:dirt_with_grass"}, {["x"] = 1, ["y"] = 0, ["z"] = 1, ["name"] = "default:dirt_with_grass"}, {["x"] = 1, ["y"] = 0, ["z"] = 2, ["name"] = "default:dirt_with_grass"}, {["x"] = 1, ["y"] = 0, ["z"] = 3, ["name"] = "default:dirt_with_grass"}, {["x"] = 1, ["y"] = 0, ["z"] = 4, ["name"] = "default:dirt_with_grass"}, {["x"] = 1, ["y"] = 0, ["z"] = 5, ["name"] = "default:dirt_with_grass"}, {["x"] = 1, ["y"] = 0, ["z"] = 6, ["name"] = "default:dirt_with_grass"}, {["x"] = 1, ["y"] = 0, ["z"] = 7, ["name"] = "default:dirt_with_grass"}, {["x"] = 1, ["y"] = 0, ["z"] = 8, ["name"] = "default:dirt_with_grass"}, {["x"] = 1, ["y"] = 0, ["z"] = 9, ["name"] = "default:dirt_with_grass"}, {["x"] = 1, ["y"] = 0, ["z"] = 10, ["name"] = "default:dirt_with_grass"}, {["x"] = 1, ["y"] = 0, ["z"] = 11, ["name"] = "default:dirt_with_grass"}, {["x"] = 1, ["y"] = 0, ["z"] = 12, ["name"] = "default:dirt_with_grass"}, {["x"] = 1, ["y"] = 0, ["z"] = 13, ["name"] = "default:dirt_with_grass"}, {["x"] = 1, ["y"] = 0, ["z"] = 14, ["name"] = "default:dirt_with_grass"}, {["x"] = 1, ["y"] = 0, ["z"] = 15, ["name"] = "default:dirt_with_grass"}, {["x"] = 1, ["y"] = 0, ["z"] = 16, ["name"] = "default:dirt_with_grass"}, {["x"] = 1, ["y"] = 0, ["z"] = 17, ["name"] = "default:dirt_with_grass"}, {["x"] = 1, ["y"] = 0, ["z"] = 18, ["name"] = "default:dirt_with_grass"}, {["x"] = 1, ["y"] = 0, ["z"] = 19, ["name"] = "default:dirt_with_grass"}, {["x"] = 1, ["y"] = 0, ["z"] = 20, ["name"] = "default:dirt_with_grass"}, {["x"] = 1, ["y"] = 0, ["z"] = 21, ["name"] = "default:dirt_with_grass"}, {["x"] = 1, ["y"] = 0, ["z"] = 22, ["name"] = "default:dirt_with_grass"}, {["x"] = 1, ["y"] = 0, ["z"] = 23, ["name"] = "default:dirt_with_grass"}, {["x"] = 1, ["y"] = 0, ["z"] = 24, ["name"] = "default:dirt_with_grass"}, {["x"] = 1, ["y"] = 0, ["z"] = 25, ["name"] = "default:dirt_with_grass"}, {["x"] = 1, ["y"] = 0, ["z"] = 26, ["name"] = "default:dirt_with_grass"}, {["x"] = 1, ["y"] = 0, ["z"] = 27, ["name"] = "the_build_spawner:white"}, {["x"] = 1, ["y"] = 0, ["z"] = 28, ["name"] = "the_build_spawner:black"}, {["x"] = 1, ["y"] = 0, ["z"] = 29, ["name"] = "the_build_spawner:white"}, {["x"] = 1, ["y"] = 0, ["z"] = 30, ["name"] = "the_build_spawner:black"}, {["x"] = 1, ["y"] = 0, ["z"] = 31, ["name"] = "the_build_spawner:black"}, {["x"] = 1, ["y"] = 0, ["z"] = 32, ["name"] = "the_build_spawner:black"}, {["x"] = 1, ["y"] = 0, ["z"] = 33, ["name"] = "the_build_spawner:white"}, {["x"] = 1, ["y"] = 0, ["z"] = 34, ["name"] = "the_build_spawner:black"}, {["x"] = 1, ["y"] = 0, ["z"] = 35, ["name"] = "the_build_spawner:black"}, {["x"] = 1, ["y"] = 0, ["z"] = 36, ["name"] = "the_build_spawner:black"}, {["x"] = 1, ["y"] = 0, ["z"] = 37, ["name"] = "the_build_spawner:black"}, {["x"] = 1, ["y"] = 0, ["z"] = 38, ["name"] = "the_build_spawner:black"}, {["x"] = 1, ["y"] = 0, ["z"] = 39, ["name"] = "the_build_spawner:black"}, {["x"] = 1, ["y"] = 0, ["z"] = 40, ["name"] = "the_build_spawner:black"}, {["x"] = 1, ["y"] = 0, ["z"] = 41, ["name"] = "the_build_spawner:white"}, {["x"] = 1, ["y"] = 1, ["param1"] = 15, ["z"] = 0, ["name"] = "default:fence_wood"}, {["x"] = 1, ["y"] = 1, ["param1"] = 223, ["z"] = 26, ["name"] = "default:fence_wood"}, {["x"] = 1, ["y"] = 1, ["param1"] = 15, ["z"] = 41, ["name"] = "default:fence_wood"}, {["x"] = 1, ["y"] = 2, ["param1"] = 239, ["z"] = 26, ["name"] = "default:mese_post_light"}, {["x"] = 2, ["y"] = 0, ["z"] = 0, ["name"] = "default:dirt_with_grass"}, {["x"] = 2, ["y"] = 0, ["z"] = 1, ["name"] = "default:dirt_with_grass"}, {["x"] = 2, ["y"] = 0, ["z"] = 2, ["name"] = "default:dirt_with_grass"}, {["x"] = 2, ["y"] = 0, ["z"] = 3, ["name"] = "default:dirt_with_grass"}, {["x"] = 2, ["y"] = 0, ["z"] = 4, ["name"] = "default:dirt_with_grass"}, {["x"] = 2, ["y"] = 0, ["z"] = 5, ["name"] = "default:dirt_with_grass"}, {["x"] = 2, ["y"] = 0, ["z"] = 6, ["name"] = "default:dirt_with_grass"}, {["x"] = 2, ["y"] = 0, ["z"] = 7, ["name"] = "default:dirt_with_grass"}, {["x"] = 2, ["y"] = 0, ["z"] = 8, ["name"] = "default:dirt_with_grass"}, {["x"] = 2, ["y"] = 0, ["z"] = 9, ["name"] = "default:dirt_with_grass"}, {["x"] = 2, ["y"] = 0, ["z"] = 10, ["name"] = "default:dirt_with_grass"}, {["x"] = 2, ["y"] = 0, ["z"] = 11, ["name"] = "default:dirt_with_grass"}, {["x"] = 2, ["y"] = 0, ["z"] = 12, ["name"] = "default:dirt_with_grass"}, {["x"] = 2, ["y"] = 0, ["z"] = 13, ["name"] = "default:dirt_with_grass"}, {["x"] = 2, ["y"] = 0, ["z"] = 14, ["name"] = "default:dirt_with_grass"}, {["x"] = 2, ["y"] = 0, ["z"] = 15, ["name"] = "default:dirt_with_grass"}, {["x"] = 2, ["y"] = 0, ["z"] = 16, ["name"] = "default:dirt_with_grass"}, {["x"] = 2, ["y"] = 0, ["z"] = 17, ["name"] = "default:dirt_with_grass"}, {["x"] = 2, ["y"] = 0, ["z"] = 18, ["name"] = "default:dirt_with_grass"}, {["x"] = 2, ["y"] = 0, ["z"] = 19, ["name"] = "default:dirt_with_grass"}, {["x"] = 2, ["y"] = 0, ["param1"] = 12, ["z"] = 20, ["name"] = "default:dirt_with_grass"}, {["x"] = 2, ["y"] = 0, ["z"] = 21, ["name"] = "default:dirt_with_grass"}, {["x"] = 2, ["y"] = 0, ["z"] = 22, ["name"] = "default:dirt_with_grass"}, {["x"] = 2, ["y"] = 0, ["z"] = 23, ["name"] = "default:dirt_with_grass"}, {["x"] = 2, ["y"] = 0, ["z"] = 24, ["name"] = "default:dirt_with_grass"}, {["x"] = 2, ["y"] = 0, ["z"] = 25, ["name"] = "default:dirt_with_grass"}, {["x"] = 2, ["y"] = 0, ["z"] = 26, ["name"] = "default:dirt_with_grass"}, {["x"] = 2, ["y"] = 0, ["z"] = 27, ["name"] = "the_build_spawner:white"}, {["x"] = 2, ["y"] = 0, ["z"] = 28, ["name"] = "the_build_spawner:white"}, {["x"] = 2, ["y"] = 0, ["z"] = 29, ["name"] = "the_build_spawner:white"}, {["x"] = 2, ["y"] = 0, ["z"] = 30, ["name"] = "the_build_spawner:black"}, {["x"] = 2, ["y"] = 0, ["z"] = 31, ["name"] = "the_build_spawner:black"}, {["x"] = 2, ["y"] = 0, ["z"] = 32, ["name"] = "the_build_spawner:black"}, {["x"] = 2, ["y"] = 0, ["z"] = 33, ["name"] = "the_build_spawner:white"}, {["x"] = 2, ["y"] = 0, ["z"] = 34, ["name"] = "the_build_spawner:black"}, {["x"] = 2, ["y"] = 0, ["z"] = 35, ["name"] = "the_build_spawner:black"}, {["x"] = 2, ["y"] = 0, ["z"] = 36, ["name"] = "the_build_spawner:black"}, {["x"] = 2, ["y"] = 0, ["z"] = 37, ["name"] = "the_build_spawner:black"}, {["x"] = 2, ["y"] = 0, ["z"] = 38, ["name"] = "the_build_spawner:black"}, {["x"] = 2, ["y"] = 0, ["z"] = 39, ["name"] = "the_build_spawner:black"}, {["x"] = 2, ["y"] = 0, ["z"] = 40, ["name"] = "the_build_spawner:black"}, {["x"] = 2, ["y"] = 0, ["z"] = 41, ["name"] = "the_build_spawner:white"}, {["x"] = 2, ["y"] = 1, ["param1"] = 15, ["z"] = 0, ["name"] = "default:fence_wood"}, {["x"] = 2, ["y"] = 1, ["param1"] = 207, ["z"] = 26, ["name"] = "default:fence_wood"}, {["x"] = 2, ["y"] = 1, ["param1"] = 15, ["z"] = 41, ["name"] = "default:fence_wood"}, {["x"] = 2, ["param2"] = 23, ["y"] = 5, ["param1"] = 14, ["z"] = 4, ["name"] = "stairs:slab_silver_sandstone"}, {["x"] = 2, ["param2"] = 23, ["y"] = 5, ["param1"] = 13, ["z"] = 5, ["name"] = "stairs:slab_silver_sandstone"}, {["x"] = 2, ["param2"] = 23, ["y"] = 5, ["param1"] = 14, ["z"] = 6, ["name"] = "stairs:slab_silver_sandstone"}, {["x"] = 2, ["param2"] = 23, ["y"] = 5, ["param1"] = 14, ["z"] = 7, ["name"] = "stairs:slab_silver_sandstone"}, {["x"] = 2, ["param2"] = 23, ["y"] = 5, ["param1"] = 14, ["z"] = 8, ["name"] = "stairs:slab_silver_sandstone"}, {["x"] = 2, ["param2"] = 23, ["y"] = 5, ["param1"] = 14, ["z"] = 9, ["name"] = "stairs:slab_silver_sandstone"}, {["x"] = 2, ["param2"] = 23, ["y"] = 5, ["param1"] = 14, ["z"] = 10, ["name"] = "stairs:slab_silver_sandstone"}, {["x"] = 2, ["param2"] = 23, ["y"] = 5, ["param1"] = 14, ["z"] = 11, ["name"] = "stairs:slab_silver_sandstone"}, {["x"] = 2, ["param2"] = 23, ["y"] = 5, ["param1"] = 14, ["z"] = 12, ["name"] = "stairs:slab_silver_sandstone"}, {["x"] = 2, ["param2"] = 23, ["y"] = 5, ["param1"] = 14, ["z"] = 13, ["name"] = "stairs:slab_silver_sandstone"}, {["x"] = 2, ["param2"] = 23, ["y"] = 5, ["param1"] = 14, ["z"] = 14, ["name"] = "stairs:slab_silver_sandstone"}, {["x"] = 2, ["param2"] = 23, ["y"] = 5, ["param1"] = 14, ["z"] = 15, ["name"] = "stairs:slab_silver_sandstone"}, {["x"] = 2, ["param2"] = 23, ["y"] = 5, ["param1"] = 14, ["z"] = 16, ["name"] = "stairs:slab_silver_sandstone"}, {["x"] = 2, ["param2"] = 23, ["y"] = 5, ["param1"] = 30, ["z"] = 17, ["name"] = "stairs:slab_silver_sandstone"}, {["x"] = 2, ["param2"] = 23, ["y"] = 5, ["param1"] = 46, ["z"] = 18, ["name"] = "stairs:slab_silver_sandstone"}, {["x"] = 2, ["param2"] = 23, ["y"] = 5, ["param1"] = 62, ["z"] = 19, ["name"] = "stairs:slab_silver_sandstone"}, {["x"] = 2, ["param2"] = 23, ["y"] = 5, ["param1"] = 77, ["z"] = 20, ["name"] = "stairs:slab_silver_sandstone"}, {["x"] = 2, ["param2"] = 23, ["y"] = 5, ["param1"] = 93, ["z"] = 21, ["name"] = "stairs:slab_silver_sandstone"}, {["x"] = 2, ["param2"] = 22, ["y"] = 5, ["param1"] = 110, ["z"] = 22, ["name"] = "stairs:slab_silver_sandstone"}, {["x"] = 2, ["y"] = 6, ["param1"] = 14, ["z"] = 12, ["name"] = "xpanes:pane"}, {["x"] = 2, ["param2"] = 3, ["y"] = 6, ["param1"] = 14, ["z"] = 13, ["name"] = "xpanes:pane_flat"}, {["x"] = 2, ["param2"] = 3, ["y"] = 6, ["param1"] = 14, ["z"] = 14, ["name"] = "xpanes:pane_flat"}, {["x"] = 2, ["param2"] = 3, ["y"] = 6, ["param1"] = 14, ["z"] = 15, ["name"] = "xpanes:pane_flat"}, {["x"] = 2, ["param2"] = 3, ["y"] = 6, ["param1"] = 14, ["z"] = 16, ["name"] = "xpanes:pane_flat"}, {["x"] = 2, ["param2"] = 3, ["y"] = 6, ["param1"] = 14, ["z"] = 17, ["name"] = "xpanes:pane_flat"}, {["x"] = 2, ["param2"] = 3, ["y"] = 6, ["param1"] = 30, ["z"] = 18, ["name"] = "xpanes:pane_flat"}, {["x"] = 2, ["param2"] = 3, ["y"] = 6, ["param1"] = 46, ["z"] = 19, ["name"] = "xpanes:pane_flat"}, {["x"] = 2, ["param2"] = 3, ["y"] = 6, ["param1"] = 61, ["z"] = 20, ["name"] = "xpanes:pane_flat"}, {["x"] = 2, ["param2"] = 3, ["y"] = 6, ["param1"] = 77, ["z"] = 21, ["name"] = "xpanes:pane_flat"}, {["x"] = 2, ["y"] = 6, ["param1"] = 94, ["z"] = 22, ["name"] = "xpanes:pane"}, {["x"] = 3, ["y"] = 0, ["z"] = 0, ["name"] = "default:dirt_with_grass"}, {["x"] = 3, ["y"] = 0, ["z"] = 1, ["name"] = "default:dirt_with_grass"}, {["x"] = 3, ["y"] = 0, ["z"] = 2, ["name"] = "default:dirt_with_grass"}, {["x"] = 3, ["y"] = 0, ["z"] = 3, ["name"] = "default:dirt_with_grass"}, {["x"] = 3, ["y"] = 0, ["z"] = 4, ["name"] = "default:dirt_with_grass"}, {["x"] = 3, ["y"] = 0, ["z"] = 5, ["name"] = "default:wood"}, {["x"] = 3, ["y"] = 0, ["z"] = 6, ["name"] = "default:wood"}, {["x"] = 3, ["y"] = 0, ["z"] = 7, ["name"] = "default:wood"}, {["x"] = 3, ["y"] = 0, ["z"] = 8, ["name"] = "default:wood"}, {["x"] = 3, ["y"] = 0, ["z"] = 9, ["name"] = "default:wood"}, {["x"] = 3, ["y"] = 0, ["z"] = 10, ["name"] = "default:wood"}, {["x"] = 3, ["y"] = 0, ["z"] = 11, ["name"] = "default:wood"}, {["x"] = 3, ["y"] = 0, ["z"] = 12, ["name"] = "default:wood"}, {["x"] = 3, ["y"] = 0, ["z"] = 13, ["name"] = "default:wood"}, {["x"] = 3, ["y"] = 0, ["z"] = 14, ["name"] = "default:wood"}, {["x"] = 3, ["y"] = 0, ["z"] = 15, ["name"] = "default:wood"}, {["x"] = 3, ["y"] = 0, ["z"] = 16, ["name"] = "default:wood"}, {["x"] = 3, ["y"] = 0, ["z"] = 17, ["name"] = "default:wood"}, {["x"] = 3, ["y"] = 0, ["z"] = 18, ["name"] = "default:wood"}, {["x"] = 3, ["y"] = 0, ["z"] = 19, ["name"] = "default:wood"}, {["x"] = 3, ["y"] = 0, ["z"] = 20, ["name"] = "default:wood"}, {["x"] = 3, ["y"] = 0, ["z"] = 21, ["name"] = "default:wood"}, {["x"] = 3, ["y"] = 0, ["z"] = 22, ["name"] = "default:dirt_with_grass"}, {["x"] = 3, ["y"] = 0, ["z"] = 23, ["name"] = "default:dirt_with_grass"}, {["x"] = 3, ["y"] = 0, ["z"] = 24, ["name"] = "default:dirt_with_grass"}, {["x"] = 3, ["y"] = 0, ["z"] = 25, ["name"] = "default:dirt_with_grass"}, {["x"] = 3, ["y"] = 0, ["z"] = 26, ["name"] = "default:dirt_with_grass"}, {["x"] = 3, ["y"] = 0, ["z"] = 27, ["name"] = "the_build_spawner:white"}, {["x"] = 3, ["y"] = 0, ["z"] = 28, ["name"] = "the_build_spawner:black"}, {["x"] = 3, ["y"] = 0, ["z"] = 29, ["name"] = "the_build_spawner:white"}, {["x"] = 3, ["y"] = 0, ["z"] = 30, ["name"] = "the_build_spawner:black"}, {["x"] = 3, ["y"] = 0, ["z"] = 31, ["name"] = "the_build_spawner:black"}, {["x"] = 3, ["y"] = 0, ["z"] = 32, ["name"] = "the_build_spawner:black"}, {["x"] = 3, ["y"] = 0, ["z"] = 33, ["name"] = "the_build_spawner:white"}, {["x"] = 3, ["y"] = 0, ["z"] = 34, ["name"] = "the_build_spawner:black"}, {["x"] = 3, ["y"] = 0, ["z"] = 35, ["name"] = "the_build_spawner:black"}, {["x"] = 3, ["y"] = 0, ["z"] = 36, ["name"] = "the_build_spawner:black"}, {["x"] = 3, ["y"] = 0, ["z"] = 37, ["name"] = "the_build_spawner:black"}, {["x"] = 3, ["y"] = 0, ["z"] = 38, ["name"] = "the_build_spawner:black"}, {["x"] = 3, ["y"] = 0, ["z"] = 39, ["name"] = "the_build_spawner:black"}, {["x"] = 3, ["y"] = 0, ["z"] = 40, ["name"] = "the_build_spawner:black"}, {["x"] = 3, ["y"] = 0, ["z"] = 41, ["name"] = "the_build_spawner:white"}, {["x"] = 3, ["y"] = 1, ["param1"] = 14, ["z"] = 0, ["name"] = "default:fence_wood"}, {["x"] = 3, ["y"] = 1, ["z"] = 5, ["name"] = "default:stonebrick"}, {["x"] = 3, ["y"] = 1, ["z"] = 6, ["name"] = "default:stonebrick"}, {["x"] = 3, ["y"] = 1, ["z"] = 7, ["name"] = "default:stonebrick"}, {["x"] = 3, ["y"] = 1, ["z"] = 8, ["name"] = "default:stonebrick"}, {["x"] = 3, ["y"] = 1, ["z"] = 9, ["name"] = "default:stonebrick"}, {["x"] = 3, ["y"] = 1, ["z"] = 10, ["name"] = "default:stonebrick"}, {["x"] = 3, ["y"] = 1, ["z"] = 11, ["name"] = "default:stonebrick"}, {["x"] = 3, ["y"] = 1, ["z"] = 12, ["name"] = "default:stonebrick"}, {["x"] = 3, ["y"] = 1, ["z"] = 13, ["name"] = "default:stonebrick"}, {["x"] = 3, ["y"] = 1, ["z"] = 14, ["name"] = "default:stonebrick"}, {["x"] = 3, ["y"] = 1, ["z"] = 15, ["name"] = "default:stonebrick"}, {["x"] = 3, ["y"] = 1, ["z"] = 16, ["name"] = "default:stonebrick"}, {["x"] = 3, ["y"] = 1, ["z"] = 17, ["name"] = "default:stonebrick"}, {["x"] = 3, ["y"] = 1, ["z"] = 18, ["name"] = "default:stonebrick"}, {["x"] = 3, ["y"] = 1, ["z"] = 19, ["name"] = "default:stonebrick"}, {["x"] = 3, ["y"] = 1, ["z"] = 20, ["name"] = "default:stonebrick"}, {["x"] = 3, ["y"] = 1, ["z"] = 21, ["name"] = "default:stonebrick"}, {["x"] = 3, ["y"] = 1, ["z"] = 22, ["name"] = "default:obsidian"}, {["x"] = 3, ["y"] = 1, ["param1"] = 206, ["z"] = 26, ["name"] = "default:fence_wood"}, {["x"] = 3, ["y"] = 1, ["param1"] = 14, ["z"] = 41, ["name"] = "default:fence_wood"}, {["x"] = 3, ["y"] = 2, ["param1"] = 45, ["z"] = 15, ["name"] = "xpanes:pane"}, {["x"] = 3, ["param2"] = 3, ["y"] = 2, ["param1"] = 61, ["z"] = 16, ["name"] = "xpanes:pane_flat"}, {["x"] = 3, ["param2"] = 3, ["y"] = 2, ["param1"] = 77, ["z"] = 17, ["name"] = "xpanes:pane_flat"}, {["x"] = 3, ["param2"] = 3, ["y"] = 2, ["param1"] = 93, ["z"] = 18, ["name"] = "xpanes:pane_flat"}, {["x"] = 3, ["param2"] = 3, ["y"] = 2, ["param1"] = 109, ["z"] = 19, ["name"] = "xpanes:pane_flat"}, {["x"] = 3, ["param2"] = 3, ["y"] = 2, ["param1"] = 125, ["z"] = 20, ["name"] = "xpanes:pane_flat"}, {["x"] = 3, ["y"] = 2, ["z"] = 21, ["name"] = "default:stonebrick"}, {["x"] = 3, ["param2"] = 1, ["y"] = 2, ["param1"] = 157, ["z"] = 22, ["name"] = "default:aspen_leaves"}, {["x"] = 3, ["param2"] = 1, ["y"] = 3, ["param1"] = 29, ["z"] = 15, ["name"] = "stairs:slab_silver_sandstone"}, {["x"] = 3, ["y"] = 3, ["param1"] = 45, ["z"] = 16, ["name"] = "stairs:slab_silver_sandstone"}, {["x"] = 3, ["y"] = 3, ["param1"] = 61, ["z"] = 17, ["name"] = "stairs:slab_silver_sandstone"}, {["x"] = 3, ["y"] = 3, ["param1"] = 77, ["z"] = 18, ["name"] = "stairs:slab_silver_sandstone"}, {["x"] = 3, ["y"] = 3, ["param1"] = 93, ["z"] = 19, ["name"] = "stairs:slab_silver_sandstone"}, {["x"] = 3, ["y"] = 3, ["param1"] = 109, ["z"] = 20, ["name"] = "stairs:slab_silver_sandstone"}, {["x"] = 3, ["y"] = 3, ["z"] = 21, ["name"] = "default:stonebrick"}, {["x"] = 3, ["param2"] = 1, ["y"] = 3, ["param1"] = 141, ["z"] = 22, ["name"] = "default:aspen_leaves"}, {["x"] = 3, ["y"] = 4, ["z"] = 21, ["name"] = "default:stonebrick"}, {["x"] = 3, ["param2"] = 23, ["y"] = 5, ["param1"] = 13, ["z"] = 4, ["name"] = "stairs:slab_silver_sandstone"}, {["x"] = 3, ["param2"] = 20, ["y"] = 5, ["param1"] = 13, ["z"] = 12, ["name"] = "stairs:slab_silver_sandstone"}, {["x"] = 3, ["param2"] = 20, ["y"] = 5, ["param1"] = 13, ["z"] = 13, ["name"] = "stairs:slab_silver_sandstone"}, {["x"] = 3, ["param2"] = 20, ["y"] = 5, ["param1"] = 13, ["z"] = 14, ["name"] = "stairs:slab_silver_sandstone"}, {["x"] = 3, ["y"] = 5, ["z"] = 15, ["name"] = "default:stonebrick"}, {["x"] = 3, ["y"] = 5, ["z"] = 16, ["name"] = "default:stonebrick"}, {["x"] = 3, ["y"] = 5, ["z"] = 17, ["name"] = "default:stonebrick"}, {["x"] = 3, ["y"] = 5, ["z"] = 18, ["name"] = "default:stonebrick"}, {["x"] = 3, ["y"] = 5, ["z"] = 19, ["name"] = "default:stonebrick"}, {["x"] = 3, ["y"] = 5, ["z"] = 20, ["name"] = "default:stonebrick"}, {["x"] = 3, ["y"] = 5, ["z"] = 21, ["name"] = "default:stonebrick"}, {["x"] = 3, ["param2"] = 22, ["y"] = 5, ["param1"] = 109, ["z"] = 22, ["name"] = "stairs:slab_silver_sandstone"}, {["x"] = 3, ["y"] = 6, ["param1"] = 13, ["z"] = 12, ["name"] = "xpanes:pane_flat"}, {["x"] = 3, ["y"] = 6, ["param1"] = 93, ["z"] = 22, ["name"] = "xpanes:pane_flat"}, {["x"] = 4, ["y"] = 0, ["z"] = 0, ["name"] = "default:dirt_with_grass"}, {["x"] = 4, ["y"] = 0, ["z"] = 1, ["name"] = "default:dirt_with_grass"}, {["x"] = 4, ["y"] = 0, ["z"] = 2, ["name"] = "default:dirt_with_grass"}, {["x"] = 4, ["y"] = 0, ["z"] = 3, ["name"] = "default:dirt_with_grass"}, {["x"] = 4, ["y"] = 0, ["z"] = 4, ["name"] = "default:dirt_with_grass"}, {["x"] = 4, ["y"] = 0, ["z"] = 5, ["name"] = "default:wood"}, {["x"] = 4, ["y"] = 0, ["z"] = 6, ["name"] = "default:wood"}, {["x"] = 4, ["y"] = 0, ["z"] = 7, ["name"] = "default:wood"}, {["x"] = 4, ["y"] = 0, ["z"] = 8, ["name"] = "default:wood"}, {["x"] = 4, ["y"] = 0, ["z"] = 9, ["name"] = "default:wood"}, {["x"] = 4, ["y"] = 0, ["z"] = 10, ["name"] = "default:wood"}, {["x"] = 4, ["y"] = 0, ["z"] = 11, ["name"] = "default:wood"}, {["x"] = 4, ["y"] = 0, ["z"] = 12, ["name"] = "default:wood"}, {["x"] = 4, ["y"] = 0, ["z"] = 13, ["name"] = "default:wood"}, {["x"] = 4, ["y"] = 0, ["z"] = 14, ["name"] = "default:wood"}, {["x"] = 4, ["y"] = 0, ["z"] = 15, ["name"] = "default:wood"}, {["x"] = 4, ["y"] = 0, ["z"] = 16, ["name"] = "default:wood"}, {["x"] = 4, ["y"] = 0, ["z"] = 17, ["name"] = "default:wood"}, {["x"] = 4, ["y"] = 0, ["z"] = 18, ["name"] = "default:wood"}, {["x"] = 4, ["y"] = 0, ["z"] = 19, ["name"] = "default:wood"}, {["x"] = 4, ["y"] = 0, ["z"] = 20, ["name"] = "default:wood"}, {["x"] = 4, ["y"] = 0, ["z"] = 21, ["name"] = "default:wood"}, {["x"] = 4, ["y"] = 0, ["z"] = 22, ["name"] = "default:dirt_with_grass"}, {["x"] = 4, ["y"] = 0, ["z"] = 23, ["name"] = "default:dirt_with_grass"}, {["x"] = 4, ["y"] = 0, ["z"] = 24, ["name"] = "default:dirt_with_grass"}, {["x"] = 4, ["y"] = 0, ["z"] = 25, ["name"] = "default:dirt_with_grass"}, {["x"] = 4, ["y"] = 0, ["z"] = 26, ["name"] = "default:dirt_with_grass"}, {["x"] = 4, ["y"] = 0, ["z"] = 27, ["name"] = "the_build_spawner:white"}, {["x"] = 4, ["y"] = 0, ["z"] = 28, ["name"] = "the_build_spawner:black"}, {["x"] = 4, ["y"] = 0, ["z"] = 29, ["name"] = "the_build_spawner:black"}, {["x"] = 4, ["y"] = 0, ["z"] = 30, ["name"] = "the_build_spawner:black"}, {["x"] = 4, ["y"] = 0, ["z"] = 31, ["name"] = "the_build_spawner:black"}, {["x"] = 4, ["y"] = 0, ["z"] = 32, ["name"] = "the_build_spawner:black"}, {["x"] = 4, ["y"] = 0, ["z"] = 33, ["name"] = "the_build_spawner:black"}, {["x"] = 4, ["y"] = 0, ["z"] = 34, ["name"] = "the_build_spawner:black"}, {["x"] = 4, ["y"] = 0, ["z"] = 35, ["name"] = "the_build_spawner:black"}, {["x"] = 4, ["y"] = 0, ["z"] = 36, ["name"] = "the_build_spawner:black"}, {["x"] = 4, ["y"] = 0, ["z"] = 37, ["name"] = "the_build_spawner:black"}, {["x"] = 4, ["y"] = 0, ["z"] = 38, ["name"] = "the_build_spawner:white"}, {["x"] = 4, ["y"] = 0, ["z"] = 39, ["name"] = "the_build_spawner:white"}, {["x"] = 4, ["y"] = 0, ["z"] = 40, ["name"] = "the_build_spawner:white"}, {["x"] = 4, ["y"] = 0, ["z"] = 41, ["name"] = "the_build_spawner:white"}, {["x"] = 4, ["y"] = 1, ["param1"] = 14, ["z"] = 0, ["name"] = "default:fence_wood"}, {["x"] = 4, ["y"] = 1, ["z"] = 5, ["name"] = "default:stonebrick"}, {["x"] = 4, ["param2"] = 2, ["y"] = 1, ["param1"] = 14, ["z"] = 6, ["name"] = "stairs:stair_wood"}, {["x"] = 4, ["y"] = 1, ["param1"] = 14, ["z"] = 7, ["name"] = "default:fence_wood"}, {["x"] = 4, ["y"] = 1, ["param1"] = 14, ["z"] = 8, ["name"] = "stairs:stair_wood"}, {["x"] = 4, ["param2"] = 2, ["y"] = 1, ["param1"] = 14, ["z"] = 10, ["name"] = "stairs:stair_wood"}, {["x"] = 4, ["y"] = 1, ["param1"] = 14, ["z"] = 11, ["name"] = "default:fence_wood"}, {["x"] = 4, ["y"] = 1, ["param1"] = 13, ["z"] = 12, ["name"] = "stairs:stair_wood"}, {["x"] = 4, ["y"] = 1, ["z"] = 15, ["name"] = "default:stonebrick"}, {["x"] = 4, ["y"] = 1, ["param1"] = 222, ["z"] = 26, ["name"] = "default:fence_wood"}, {["x"] = 4, ["y"] = 1, ["param1"] = 14, ["z"] = 41, ["name"] = "default:fence_wood"}, {["x"] = 4, ["param2"] = 3, ["y"] = 2, ["param1"] = 14, ["z"] = 7, ["name"] = "doors:trapdoor"}, {["x"] = 4, ["param2"] = 3, ["y"] = 2, ["param1"] = 14, ["z"] = 11, ["name"] = "doors:trapdoor"}, {["x"] = 4, ["y"] = 2, ["param1"] = 60, ["z"] = 15, ["name"] = "xpanes:pane_flat"}, {["x"] = 4, ["param2"] = 3, ["y"] = 2, ["param1"] = 157, ["z"] = 21, ["name"] = "doors:trapdoor"}, {["x"] = 4, ["y"] = 2, ["param1"] = 238, ["z"] = 26, ["name"] = "default:mese_post_light"}, {["x"] = 4, ["param2"] = 1, ["y"] = 3, ["param1"] = 44, ["z"] = 15, ["name"] = "stairs:slab_silver_sandstone"}, {["x"] = 4, ["param2"] = 3, ["y"] = 3, ["param1"] = 141, ["z"] = 21, ["name"] = "stairs:slab_silver_sandstone"}, {["x"] = 4, ["param2"] = 23, ["y"] = 5, ["param1"] = 13, ["z"] = 4, ["name"] = "stairs:slab_silver_sandstone"}, {["x"] = 4, ["param2"] = 20, ["y"] = 5, ["param1"] = 13, ["z"] = 12, ["name"] = "stairs:slab_silver_sandstone"}, {["x"] = 4, ["param2"] = 20, ["y"] = 5, ["param1"] = 13, ["z"] = 13, ["name"] = "stairs:slab_silver_sandstone"}, {["x"] = 4, ["param2"] = 20, ["y"] = 5, ["param1"] = 13, ["z"] = 14, ["name"] = "stairs:slab_silver_sandstone"}, {["x"] = 4, ["y"] = 5, ["z"] = 15, ["name"] = "default:stonebrick"}, {["x"] = 4, ["y"] = 5, ["z"] = 16, ["name"] = "default:stonebrick"}, {["x"] = 4, ["y"] = 5, ["z"] = 17, ["name"] = "default:stonebrick"}, {["x"] = 4, ["y"] = 5, ["z"] = 18, ["name"] = "default:stonebrick"}, {["x"] = 4, ["y"] = 5, ["z"] = 19, ["name"] = "default:stonebrick"}, {["x"] = 4, ["y"] = 5, ["z"] = 20, ["name"] = "default:stonebrick"}, {["x"] = 4, ["y"] = 5, ["z"] = 21, ["name"] = "default:stonebrick"}, {["x"] = 4, ["param2"] = 22, ["y"] = 5, ["param1"] = 125, ["z"] = 22, ["name"] = "stairs:slab_silver_sandstone"}, {["x"] = 4, ["y"] = 6, ["param1"] = 13, ["z"] = 12, ["name"] = "xpanes:pane_flat"}, {["x"] = 4, ["y"] = 6, ["param1"] = 109, ["z"] = 22, ["name"] = "xpanes:pane_flat"}, {["x"] = 5, ["y"] = 0, ["z"] = 0, ["name"] = "default:dirt_with_grass"}, {["x"] = 5, ["y"] = 0, ["z"] = 1, ["name"] = "default:dirt_with_grass"}, {["x"] = 5, ["y"] = 0, ["z"] = 2, ["name"] = "default:dirt_with_grass"}, {["x"] = 5, ["y"] = 0, ["z"] = 3, ["name"] = "default:dirt_with_grass"}, {["x"] = 5, ["y"] = 0, ["z"] = 4, ["name"] = "default:dirt_with_grass"}, {["x"] = 5, ["y"] = 0, ["z"] = 5, ["name"] = "default:wood"}, {["x"] = 5, ["y"] = 0, ["z"] = 6, ["name"] = "default:wood"}, {["x"] = 5, ["y"] = 0, ["z"] = 7, ["name"] = "default:wood"}, {["x"] = 5, ["y"] = 0, ["z"] = 8, ["name"] = "default:wood"}, {["x"] = 5, ["y"] = 0, ["z"] = 9, ["name"] = "default:wood"}, {["x"] = 5, ["y"] = 0, ["z"] = 10, ["name"] = "default:wood"}, {["x"] = 5, ["y"] = 0, ["z"] = 11, ["name"] = "default:wood"}, {["x"] = 5, ["y"] = 0, ["z"] = 12, ["name"] = "default:wood"}, {["x"] = 5, ["y"] = 0, ["z"] = 13, ["name"] = "default:wood"}, {["x"] = 5, ["y"] = 0, ["z"] = 14, ["name"] = "default:wood"}, {["x"] = 5, ["y"] = 0, ["z"] = 15, ["name"] = "default:wood"}, {["x"] = 5, ["y"] = 0, ["z"] = 16, ["name"] = "default:wood"}, {["x"] = 5, ["y"] = 0, ["z"] = 17, ["name"] = "default:wood"}, {["x"] = 5, ["y"] = 0, ["z"] = 18, ["name"] = "default:wood"}, {["x"] = 5, ["y"] = 0, ["z"] = 19, ["name"] = "default:wood"}, {["x"] = 5, ["y"] = 0, ["z"] = 20, ["name"] = "default:wood"}, {["x"] = 5, ["y"] = 0, ["z"] = 21, ["name"] = "default:wood"}, {["x"] = 5, ["y"] = 0, ["z"] = 22, ["name"] = "default:dirt_with_grass"}, {["x"] = 5, ["y"] = 0, ["z"] = 23, ["name"] = "default:dirt_with_grass"}, {["x"] = 5, ["y"] = 0, ["z"] = 24, ["name"] = "default:dirt_with_grass"}, {["x"] = 5, ["y"] = 0, ["z"] = 25, ["name"] = "default:dirt_with_grass"}, {["x"] = 5, ["y"] = 0, ["z"] = 26, ["name"] = "default:dirt_with_grass"}, {["x"] = 5, ["y"] = 0, ["z"] = 27, ["name"] = "the_build_spawner:white"}, {["x"] = 5, ["y"] = 0, ["z"] = 28, ["name"] = "the_build_spawner:black"}, {["x"] = 5, ["y"] = 0, ["z"] = 29, ["name"] = "the_build_spawner:black"}, {["x"] = 5, ["y"] = 0, ["z"] = 30, ["name"] = "the_build_spawner:black"}, {["x"] = 5, ["y"] = 0, ["z"] = 31, ["name"] = "the_build_spawner:black"}, {["x"] = 5, ["y"] = 0, ["z"] = 32, ["name"] = "the_build_spawner:black"}, {["x"] = 5, ["y"] = 0, ["z"] = 33, ["name"] = "the_build_spawner:black"}, {["x"] = 5, ["y"] = 0, ["z"] = 34, ["name"] = "the_build_spawner:black"}, {["x"] = 5, ["y"] = 0, ["z"] = 35, ["name"] = "the_build_spawner:black"}, {["x"] = 5, ["y"] = 0, ["z"] = 36, ["name"] = "the_build_spawner:black"}, {["x"] = 5, ["y"] = 0, ["z"] = 37, ["name"] = "the_build_spawner:black"}, {["x"] = 5, ["y"] = 0, ["z"] = 38, ["name"] = "the_build_spawner:black"}, {["x"] = 5, ["y"] = 0, ["z"] = 39, ["name"] = "the_build_spawner:black"}, {["x"] = 5, ["y"] = 0, ["z"] = 40, ["name"] = "the_build_spawner:black"}, {["x"] = 5, ["y"] = 0, ["z"] = 41, ["name"] = "the_build_spawner:white"}, {["x"] = 5, ["y"] = 1, ["param1"] = 15, ["z"] = 0, ["name"] = "default:fence_wood"}, {["x"] = 5, ["y"] = 1, ["z"] = 5, ["name"] = "default:stonebrick"}, {["x"] = 5, ["y"] = 1, ["z"] = 15, ["name"] = "default:stonebrick"}, {["x"] = 5, ["param2"] = 23, ["y"] = 1, ["param1"] = 125, ["z"] = 21, ["name"] = "stairs:slab_silver_sandstone"}, {["x"] = 5, ["y"] = 1, ["param1"] = 207, ["z"] = 26, ["name"] = "default:fence_wood"}, {["x"] = 5, ["y"] = 1, ["param1"] = 15, ["z"] = 41, ["name"] = "default:fence_wood"}, {["x"] = 5, ["y"] = 2, ["param1"] = 43, ["z"] = 15, ["name"] = "xpanes:pane_flat"}, {["x"] = 5, ["param2"] = 1, ["y"] = 3, ["param1"] = 27, ["z"] = 15, ["name"] = "stairs:slab_silver_sandstone"}, {["x"] = 5, ["param2"] = 3, ["y"] = 3, ["param1"] = 125, ["z"] = 21, ["name"] = "stairs:slab_silver_sandstone"}, {["x"] = 5, ["param2"] = 23, ["y"] = 5, ["param1"] = 14, ["z"] = 4, ["name"] = "stairs:slab_silver_sandstone"}, {["x"] = 5, ["param2"] = 20, ["y"] = 5, ["param1"] = 14, ["z"] = 12, ["name"] = "stairs:slab_silver_sandstone"}, {["x"] = 5, ["param2"] = 20, ["y"] = 5, ["param1"] = 14, ["z"] = 13, ["name"] = "stairs:slab_silver_sandstone"}, {["x"] = 5, ["param2"] = 20, ["y"] = 5, ["param1"] = 14, ["z"] = 14, ["name"] = "stairs:slab_silver_sandstone"}, {["x"] = 5, ["y"] = 5, ["z"] = 15, ["name"] = "default:stonebrick"}, {["x"] = 5, ["y"] = 5, ["z"] = 16, ["name"] = "default:stonebrick"}, {["x"] = 5, ["y"] = 5, ["z"] = 17, ["name"] = "default:stonebrick"}, {["x"] = 5, ["y"] = 5, ["z"] = 18, ["name"] = "default:stonebrick"}, {["x"] = 5, ["y"] = 5, ["z"] = 19, ["name"] = "default:stonebrick"}, {["x"] = 5, ["y"] = 5, ["z"] = 20, ["name"] = "default:stonebrick"}, {["x"] = 5, ["y"] = 5, ["z"] = 21, ["name"] = "default:stonebrick"}, {["x"] = 5, ["param2"] = 22, ["y"] = 5, ["param1"] = 110, ["z"] = 22, ["name"] = "stairs:slab_silver_sandstone"}, {["x"] = 5, ["y"] = 6, ["param1"] = 14, ["z"] = 12, ["name"] = "xpanes:pane_flat"}, {["x"] = 5, ["y"] = 6, ["param1"] = 94, ["z"] = 22, ["name"] = "xpanes:pane_flat"}, {["x"] = 6, ["y"] = 0, ["z"] = 0, ["name"] = "default:dirt_with_grass"}, {["x"] = 6, ["y"] = 0, ["z"] = 1, ["name"] = "default:dirt_with_grass"}, {["x"] = 6, ["y"] = 0, ["z"] = 2, ["name"] = "default:dirt_with_grass"}, {["x"] = 6, ["y"] = 0, ["z"] = 3, ["name"] = "default:dirt_with_grass"}, {["x"] = 6, ["y"] = 0, ["z"] = 4, ["name"] = "default:dirt_with_grass"}, {["x"] = 6, ["y"] = 0, ["z"] = 5, ["name"] = "default:wood"}, {["x"] = 6, ["y"] = 0, ["z"] = 6, ["name"] = "default:wood"}, {["x"] = 6, ["y"] = 0, ["z"] = 7, ["name"] = "default:wood"}, {["x"] = 6, ["y"] = 0, ["z"] = 8, ["name"] = "default:wood"}, {["x"] = 6, ["y"] = 0, ["z"] = 9, ["name"] = "default:wood"}, {["x"] = 6, ["y"] = 0, ["z"] = 10, ["name"] = "default:wood"}, {["x"] = 6, ["y"] = 0, ["z"] = 11, ["name"] = "default:wood"}, {["x"] = 6, ["y"] = 0, ["z"] = 12, ["name"] = "default:wood"}, {["x"] = 6, ["y"] = 0, ["z"] = 13, ["name"] = "default:wood"}, {["x"] = 6, ["y"] = 0, ["z"] = 14, ["name"] = "default:wood"}, {["x"] = 6, ["y"] = 0, ["z"] = 15, ["name"] = "default:wood"}, {["x"] = 6, ["y"] = 0, ["z"] = 16, ["name"] = "default:wood"}, {["x"] = 6, ["y"] = 0, ["z"] = 17, ["name"] = "default:wood"}, {["x"] = 6, ["y"] = 0, ["z"] = 18, ["name"] = "default:wood"}, {["x"] = 6, ["y"] = 0, ["z"] = 19, ["name"] = "default:wood"}, {["x"] = 6, ["y"] = 0, ["z"] = 20, ["name"] = "default:wood"}, {["x"] = 6, ["y"] = 0, ["z"] = 21, ["name"] = "default:wood"}, {["x"] = 6, ["y"] = 0, ["z"] = 22, ["name"] = "default:dirt_with_grass"}, {["x"] = 6, ["y"] = 0, ["z"] = 23, ["name"] = "default:dirt_with_grass"}, {["x"] = 6, ["y"] = 0, ["z"] = 24, ["name"] = "default:dirt_with_grass"}, {["x"] = 6, ["y"] = 0, ["z"] = 25, ["name"] = "default:dirt_with_grass"}, {["x"] = 6, ["y"] = 0, ["z"] = 26, ["name"] = "default:dirt_with_grass"}, {["x"] = 6, ["y"] = 0, ["z"] = 27, ["name"] = "the_build_spawner:white"}, {["x"] = 6, ["y"] = 0, ["z"] = 28, ["name"] = "the_build_spawner:white"}, {["x"] = 6, ["y"] = 0, ["z"] = 29, ["name"] = "the_build_spawner:white"}, {["x"] = 6, ["y"] = 0, ["z"] = 30, ["name"] = "the_build_spawner:black"}, {["x"] = 6, ["y"] = 0, ["z"] = 31, ["name"] = "the_build_spawner:black"}, {["x"] = 6, ["y"] = 0, ["z"] = 32, ["name"] = "the_build_spawner:black"}, {["x"] = 6, ["y"] = 0, ["z"] = 33, ["name"] = "the_build_spawner:black"}, {["x"] = 6, ["y"] = 0, ["z"] = 34, ["name"] = "the_build_spawner:black"}, {["x"] = 6, ["y"] = 0, ["z"] = 35, ["name"] = "the_build_spawner:black"}, {["x"] = 6, ["y"] = 0, ["z"] = 36, ["name"] = "the_build_spawner:black"}, {["x"] = 6, ["y"] = 0, ["z"] = 37, ["name"] = "the_build_spawner:black"}, {["x"] = 6, ["y"] = 0, ["z"] = 38, ["name"] = "the_build_spawner:black"}, {["x"] = 6, ["y"] = 0, ["z"] = 39, ["name"] = "the_build_spawner:black"}, {["x"] = 6, ["y"] = 0, ["z"] = 40, ["name"] = "the_build_spawner:black"}, {["x"] = 6, ["y"] = 0, ["z"] = 41, ["name"] = "the_build_spawner:white"}, {["x"] = 6, ["y"] = 1, ["param1"] = 15, ["z"] = 0, ["name"] = "default:fence_wood"}, {["x"] = 6, ["y"] = 1, ["z"] = 5, ["name"] = "default:stonebrick"}, {["x"] = 6, ["param2"] = 2, ["y"] = 1, ["param1"] = 14, ["z"] = 6, ["name"] = "stairs:stair_wood"}, {["x"] = 6, ["y"] = 1, ["param1"] = 14, ["z"] = 7, ["name"] = "default:fence_wood"}, {["x"] = 6, ["y"] = 1, ["param1"] = 14, ["z"] = 8, ["name"] = "stairs:stair_wood"}, {["x"] = 6, ["param2"] = 2, ["y"] = 1, ["param1"] = 14, ["z"] = 10, ["name"] = "stairs:stair_wood"}, {["x"] = 6, ["y"] = 1, ["param1"] = 14, ["z"] = 11, ["name"] = "default:fence_wood"}, {["x"] = 6, ["y"] = 1, ["param1"] = 14, ["z"] = 12, ["name"] = "stairs:stair_wood"}, {["x"] = 6, ["y"] = 1, ["z"] = 15, ["name"] = "default:stonebrick"}, {["x"] = 6, ["param2"] = 23, ["y"] = 1, ["param1"] = 109, ["z"] = 21, ["name"] = "stairs:slab_silver_sandstone"}, {["x"] = 6, ["y"] = 1, ["param1"] = 191, ["z"] = 26, ["name"] = "default:fence_wood"}, {["x"] = 6, ["y"] = 1, ["param1"] = 15, ["z"] = 41, ["name"] = "default:fence_wood"}, {["x"] = 6, ["param2"] = 3, ["y"] = 2, ["param1"] = 14, ["z"] = 7, ["name"] = "doors:trapdoor"}, {["x"] = 6, ["param2"] = 3, ["y"] = 2, ["param1"] = 14, ["z"] = 11, ["name"] = "doors:trapdoor"}, {["x"] = 6, ["y"] = 2, ["param1"] = 27, ["z"] = 15, ["name"] = "xpanes:pane_flat"}, {["x"] = 6, ["param2"] = 1, ["y"] = 3, ["param1"] = 11, ["z"] = 15, ["name"] = "stairs:slab_silver_sandstone"}, {["x"] = 6, ["param2"] = 3, ["y"] = 3, ["param1"] = 109, ["z"] = 21, ["name"] = "stairs:slab_silver_sandstone"}, {["x"] = 6, ["param2"] = 23, ["y"] = 4, ["param1"] = 13, ["z"] = 13, ["name"] = "stairs:stair_wood"}, {["x"] = 6, ["param2"] = 23, ["y"] = 4, ["param1"] = 13, ["z"] = 14, ["name"] = "stairs:stair_wood"}, {["x"] = 6, ["param2"] = 23, ["y"] = 5, ["param1"] = 14, ["z"] = 4, ["name"] = "stairs:slab_silver_sandstone"}, {["x"] = 6, ["param2"] = 20, ["y"] = 5, ["param1"] = 14, ["z"] = 12, ["name"] = "stairs:slab_silver_sandstone"}, {["x"] = 6, ["param2"] = 3, ["y"] = 5, ["param1"] = 14, ["z"] = 13, ["name"] = "stairs:stair_wood"}, {["x"] = 6, ["param2"] = 3, ["y"] = 5, ["param1"] = 14, ["z"] = 14, ["name"] = "stairs:stair_wood"}, {["x"] = 6, ["y"] = 5, ["z"] = 15, ["name"] = "default:stonebrick"}, {["x"] = 6, ["y"] = 5, ["z"] = 16, ["name"] = "default:stonebrick"}, {["x"] = 6, ["y"] = 5, ["z"] = 17, ["name"] = "default:stonebrick"}, {["x"] = 6, ["y"] = 5, ["z"] = 18, ["name"] = "default:stonebrick"}, {["x"] = 6, ["y"] = 5, ["z"] = 19, ["name"] = "default:stonebrick"}, {["x"] = 6, ["y"] = 5, ["z"] = 20, ["name"] = "default:stonebrick"}, {["x"] = 6, ["y"] = 5, ["z"] = 21, ["name"] = "default:stonebrick"}, {["x"] = 6, ["param2"] = 22, ["y"] = 5, ["param1"] = 94, ["z"] = 22, ["name"] = "stairs:slab_silver_sandstone"}, {["x"] = 6, ["y"] = 6, ["param1"] = 14, ["z"] = 12, ["name"] = "xpanes:pane_flat"}, {["x"] = 6, ["param2"] = 2, ["y"] = 6, ["param1"] = 14, ["z"] = 15, ["name"] = "xpanes:pane_flat"}, {["x"] = 6, ["y"] = 6, ["param1"] = 78, ["z"] = 22, ["name"] = "xpanes:pane_flat"}, {["x"] = 7, ["y"] = 0, ["z"] = 0, ["name"] = "default:dirt_with_grass"}, {["x"] = 7, ["y"] = 0, ["z"] = 1, ["name"] = "default:dirt_with_grass"}, {["x"] = 7, ["y"] = 0, ["z"] = 2, ["name"] = "default:dirt_with_grass"}, {["x"] = 7, ["y"] = 0, ["z"] = 3, ["name"] = "default:dirt_with_grass"}, {["x"] = 7, ["y"] = 0, ["z"] = 4, ["name"] = "default:dirt_with_grass"}, {["x"] = 7, ["y"] = 0, ["z"] = 5, ["name"] = "default:wood"}, {["x"] = 7, ["y"] = 0, ["z"] = 6, ["name"] = "default:wood"}, {["x"] = 7, ["y"] = 0, ["z"] = 7, ["name"] = "default:wood"}, {["x"] = 7, ["y"] = 0, ["z"] = 8, ["name"] = "default:wood"}, {["x"] = 7, ["y"] = 0, ["z"] = 9, ["name"] = "default:wood"}, {["x"] = 7, ["y"] = 0, ["z"] = 10, ["name"] = "default:wood"}, {["x"] = 7, ["y"] = 0, ["z"] = 11, ["name"] = "default:wood"}, {["x"] = 7, ["y"] = 0, ["z"] = 12, ["name"] = "default:wood"}, {["x"] = 7, ["y"] = 0, ["z"] = 13, ["name"] = "default:wood"}, {["x"] = 7, ["y"] = 0, ["z"] = 14, ["name"] = "default:wood"}, {["x"] = 7, ["y"] = 0, ["z"] = 15, ["name"] = "default:wood"}, {["x"] = 7, ["y"] = 0, ["z"] = 16, ["name"] = "default:wood"}, {["x"] = 7, ["y"] = 0, ["z"] = 17, ["name"] = "default:wood"}, {["x"] = 7, ["y"] = 0, ["z"] = 18, ["name"] = "default:wood"}, {["x"] = 7, ["y"] = 0, ["z"] = 19, ["name"] = "default:wood"}, {["x"] = 7, ["y"] = 0, ["z"] = 20, ["name"] = "default:wood"}, {["x"] = 7, ["y"] = 0, ["z"] = 21, ["name"] = "default:wood"}, {["x"] = 7, ["y"] = 0, ["z"] = 22, ["name"] = "default:dirt_with_grass"}, {["x"] = 7, ["y"] = 0, ["z"] = 23, ["name"] = "default:dirt_with_grass"}, {["x"] = 7, ["y"] = 0, ["z"] = 24, ["name"] = "default:dirt_with_grass"}, {["x"] = 7, ["y"] = 0, ["z"] = 25, ["name"] = "default:dirt_with_grass"}, {["x"] = 7, ["y"] = 0, ["z"] = 26, ["name"] = "default:dirt_with_grass"}, {["x"] = 7, ["y"] = 0, ["z"] = 27, ["name"] = "the_build_spawner:white"}, {["x"] = 7, ["y"] = 0, ["z"] = 28, ["name"] = "the_build_spawner:black"}, {["x"] = 7, ["y"] = 0, ["z"] = 29, ["name"] = "the_build_spawner:black"}, {["x"] = 7, ["y"] = 0, ["z"] = 30, ["name"] = "the_build_spawner:black"}, {["x"] = 7, ["y"] = 0, ["z"] = 31, ["name"] = "the_build_spawner:black"}, {["x"] = 7, ["y"] = 0, ["z"] = 32, ["name"] = "the_build_spawner:black"}, {["x"] = 7, ["y"] = 0, ["z"] = 33, ["name"] = "the_build_spawner:black"}, {["x"] = 7, ["y"] = 0, ["z"] = 34, ["name"] = "the_build_spawner:black"}, {["x"] = 7, ["y"] = 0, ["z"] = 35, ["name"] = "the_build_spawner:black"}, {["x"] = 7, ["y"] = 0, ["z"] = 36, ["name"] = "the_build_spawner:black"}, {["x"] = 7, ["y"] = 0, ["z"] = 37, ["name"] = "the_build_spawner:black"}, {["x"] = 7, ["y"] = 0, ["z"] = 38, ["name"] = "the_build_spawner:black"}, {["x"] = 7, ["y"] = 0, ["z"] = 39, ["name"] = "the_build_spawner:black"}, {["x"] = 7, ["y"] = 0, ["z"] = 40, ["name"] = "the_build_spawner:black"}, {["x"] = 7, ["y"] = 0, ["z"] = 41, ["name"] = "the_build_spawner:white"}, {["x"] = 7, ["y"] = 1, ["param1"] = 15, ["z"] = 0, ["name"] = "default:fence_wood"}, {["x"] = 7, ["y"] = 1, ["z"] = 5, ["name"] = "default:stonebrick"}, {["x"] = 7, ["y"] = 1, ["z"] = 15, ["name"] = "default:stonebrick"}, {["x"] = 7, ["param2"] = 23, ["y"] = 1, ["param1"] = 125, ["z"] = 21, ["name"] = "stairs:slab_silver_sandstone"}, {["x"] = 7, ["y"] = 1, ["param1"] = 207, ["z"] = 26, ["name"] = "default:fence_wood"}, {["x"] = 7, ["y"] = 1, ["param1"] = 15, ["z"] = 41, ["name"] = "default:fence_wood"}, {["x"] = 7, ["y"] = 2, ["param1"] = 44, ["z"] = 15, ["name"] = "xpanes:pane_flat"}, {["x"] = 7, ["param2"] = 23, ["y"] = 3, ["param1"] = 14, ["z"] = 13, ["name"] = "stairs:stair_wood"}, {["x"] = 7, ["param2"] = 23, ["y"] = 3, ["param1"] = 13, ["z"] = 14, ["name"] = "stairs:stair_wood"}, {["x"] = 7, ["param2"] = 1, ["y"] = 3, ["param1"] = 28, ["z"] = 15, ["name"] = "stairs:slab_silver_sandstone"}, {["x"] = 7, ["param2"] = 3, ["y"] = 3, ["param1"] = 125, ["z"] = 21, ["name"] = "stairs:slab_silver_sandstone"}, {["x"] = 7, ["param2"] = 3, ["y"] = 4, ["param1"] = 14, ["z"] = 13, ["name"] = "stairs:stair_wood"}, {["x"] = 7, ["param2"] = 3, ["y"] = 4, ["param1"] = 14, ["z"] = 14, ["name"] = "stairs:stair_wood"}, {["x"] = 7, ["param2"] = 23, ["y"] = 5, ["param1"] = 14, ["z"] = 4, ["name"] = "stairs:slab_silver_sandstone"}, {["x"] = 7, ["y"] = 5, ["z"] = 15, ["name"] = "default:stonebrick"}, {["x"] = 7, ["y"] = 5, ["z"] = 16, ["name"] = "default:stonebrick"}, {["x"] = 7, ["y"] = 5, ["z"] = 17, ["name"] = "default:stonebrick"}, {["x"] = 7, ["y"] = 5, ["z"] = 18, ["name"] = "default:stonebrick"}, {["x"] = 7, ["y"] = 5, ["z"] = 19, ["name"] = "default:stonebrick"}, {["x"] = 7, ["y"] = 5, ["z"] = 20, ["name"] = "default:stonebrick"}, {["x"] = 7, ["y"] = 5, ["z"] = 21, ["name"] = "default:stonebrick"}, {["x"] = 7, ["param2"] = 22, ["y"] = 5, ["param1"] = 110, ["z"] = 22, ["name"] = "stairs:slab_silver_sandstone"}, {["x"] = 7, ["y"] = 6, ["param1"] = 14, ["z"] = 15, ["name"] = "xpanes:pane_flat"}, {["x"] = 7, ["y"] = 6, ["param1"] = 94, ["z"] = 22, ["name"] = "xpanes:pane_flat"}, {["x"] = 8, ["y"] = 0, ["z"] = 0, ["name"] = "default:dirt_with_grass"}, {["x"] = 8, ["y"] = 0, ["z"] = 1, ["name"] = "default:dirt_with_grass"}, {["x"] = 8, ["y"] = 0, ["z"] = 2, ["name"] = "default:dirt_with_grass"}, {["x"] = 8, ["y"] = 0, ["z"] = 3, ["name"] = "default:dirt_with_grass"}, {["x"] = 8, ["y"] = 0, ["z"] = 4, ["name"] = "default:dirt_with_grass"}, {["x"] = 8, ["y"] = 0, ["z"] = 5, ["name"] = "default:wood"}, {["x"] = 8, ["y"] = 0, ["z"] = 6, ["name"] = "default:wood"}, {["x"] = 8, ["y"] = 0, ["z"] = 7, ["name"] = "default:wood"}, {["x"] = 8, ["y"] = 0, ["z"] = 8, ["name"] = "default:wood"}, {["x"] = 8, ["y"] = 0, ["z"] = 9, ["name"] = "default:wood"}, {["x"] = 8, ["y"] = 0, ["z"] = 10, ["name"] = "default:wood"}, {["x"] = 8, ["y"] = 0, ["z"] = 11, ["name"] = "default:wood"}, {["x"] = 8, ["y"] = 0, ["z"] = 12, ["name"] = "default:wood"}, {["x"] = 8, ["y"] = 0, ["z"] = 13, ["name"] = "default:wood"}, {["x"] = 8, ["y"] = 0, ["z"] = 14, ["name"] = "default:wood"}, {["x"] = 8, ["y"] = 0, ["z"] = 15, ["name"] = "default:wood"}, {["x"] = 8, ["y"] = 0, ["z"] = 16, ["name"] = "default:wood"}, {["x"] = 8, ["y"] = 0, ["z"] = 17, ["name"] = "default:wood"}, {["x"] = 8, ["y"] = 0, ["z"] = 18, ["name"] = "default:wood"}, {["x"] = 8, ["y"] = 0, ["z"] = 19, ["name"] = "default:wood"}, {["x"] = 8, ["y"] = 0, ["z"] = 20, ["name"] = "default:wood"}, {["x"] = 8, ["y"] = 0, ["z"] = 21, ["name"] = "default:wood"}, {["x"] = 8, ["y"] = 0, ["z"] = 22, ["name"] = "default:dirt_with_grass"}, {["x"] = 8, ["y"] = 0, ["z"] = 23, ["name"] = "default:dirt_with_grass"}, {["x"] = 8, ["y"] = 0, ["z"] = 24, ["name"] = "default:dirt_with_grass"}, {["x"] = 8, ["y"] = 0, ["z"] = 25, ["name"] = "default:dirt_with_grass"}, {["x"] = 8, ["y"] = 0, ["z"] = 26, ["name"] = "default:dirt_with_grass"}, {["x"] = 8, ["y"] = 0, ["z"] = 27, ["name"] = "the_build_spawner:white"}, {["x"] = 8, ["y"] = 0, ["z"] = 28, ["name"] = "the_build_spawner:black"}, {["x"] = 8, ["y"] = 0, ["z"] = 29, ["name"] = "the_build_spawner:black"}, {["x"] = 8, ["y"] = 0, ["z"] = 30, ["name"] = "the_build_spawner:black"}, {["x"] = 8, ["y"] = 0, ["z"] = 31, ["name"] = "the_build_spawner:black"}, {["x"] = 8, ["y"] = 0, ["z"] = 32, ["name"] = "the_build_spawner:black"}, {["x"] = 8, ["y"] = 0, ["z"] = 33, ["name"] = "the_build_spawner:black"}, {["x"] = 8, ["y"] = 0, ["z"] = 34, ["name"] = "the_build_spawner:black"}, {["x"] = 8, ["y"] = 0, ["z"] = 35, ["name"] = "the_build_spawner:black"}, {["x"] = 8, ["y"] = 0, ["z"] = 36, ["name"] = "the_build_spawner:black"}, {["x"] = 8, ["y"] = 0, ["z"] = 37, ["name"] = "the_build_spawner:black"}, {["x"] = 8, ["y"] = 0, ["z"] = 38, ["name"] = "the_build_spawner:white"}, {["x"] = 8, ["y"] = 0, ["z"] = 39, ["name"] = "the_build_spawner:white"}, {["x"] = 8, ["y"] = 0, ["z"] = 40, ["name"] = "the_build_spawner:white"}, {["x"] = 8, ["y"] = 0, ["z"] = 41, ["name"] = "the_build_spawner:white"}, {["x"] = 8, ["y"] = 1, ["param1"] = 15, ["z"] = 0, ["name"] = "default:fence_wood"}, {["x"] = 8, ["y"] = 1, ["z"] = 5, ["name"] = "default:stonebrick"}, {["x"] = 8, ["param2"] = 2, ["y"] = 1, ["param1"] = 14, ["z"] = 6, ["name"] = "stairs:stair_wood"}, {["x"] = 8, ["y"] = 1, ["param1"] = 14, ["z"] = 7, ["name"] = "default:fence_wood"}, {["x"] = 8, ["y"] = 1, ["param1"] = 14, ["z"] = 8, ["name"] = "stairs:stair_wood"}, {["x"] = 8, ["param2"] = 2, ["y"] = 1, ["param1"] = 14, ["z"] = 10, ["name"] = "stairs:stair_wood"}, {["x"] = 8, ["y"] = 1, ["param1"] = 14, ["z"] = 11, ["name"] = "default:fence_wood"}, {["x"] = 8, ["y"] = 1, ["param1"] = 14, ["z"] = 12, ["name"] = "stairs:stair_wood"}, {["x"] = 8, ["y"] = 1, ["z"] = 15, ["name"] = "default:stonebrick"}, {["x"] = 8, ["param2"] = 23, ["y"] = 1, ["param1"] = 141, ["z"] = 21, ["name"] = "stairs:slab_silver_sandstone"}, {["x"] = 8, ["y"] = 1, ["param1"] = 223, ["z"] = 26, ["name"] = "default:fence_wood"}, {["x"] = 8, ["y"] = 1, ["param1"] = 15, ["z"] = 41, ["name"] = "default:fence_wood"}, {["x"] = 8, ["param2"] = 3, ["y"] = 2, ["param1"] = 14, ["z"] = 7, ["name"] = "doors:trapdoor"}, {["x"] = 8, ["param2"] = 3, ["y"] = 2, ["param1"] = 14, ["z"] = 11, ["name"] = "doors:trapdoor"}, {["x"] = 8, ["param2"] = 23, ["y"] = 2, ["param1"] = 14, ["z"] = 13, ["name"] = "stairs:stair_wood"}, {["x"] = 8, ["param2"] = 23, ["y"] = 2, ["param1"] = 13, ["z"] = 14, ["name"] = "stairs:stair_wood"}, {["x"] = 8, ["y"] = 2, ["z"] = 15, ["name"] = "default:stonebrick"}, {["x"] = 8, ["y"] = 2, ["param1"] = 239, ["z"] = 26, ["name"] = "default:mese_post_light"}, {["x"] = 8, ["param2"] = 3, ["y"] = 3, ["param1"] = 14, ["z"] = 13, ["name"] = "stairs:stair_wood"}, {["x"] = 8, ["param2"] = 3, ["y"] = 3, ["param1"] = 14, ["z"] = 14, ["name"] = "stairs:stair_wood"}, {["x"] = 8, ["y"] = 3, ["z"] = 15, ["name"] = "default:stonebrick"}, {["x"] = 8, ["param2"] = 3, ["y"] = 3, ["param1"] = 141, ["z"] = 21, ["name"] = "stairs:slab_silver_sandstone"}, {["x"] = 8, ["y"] = 4, ["z"] = 15, ["name"] = "default:stonebrick"}, {["x"] = 8, ["param2"] = 23, ["y"] = 5, ["param1"] = 14, ["z"] = 4, ["name"] = "stairs:slab_silver_sandstone"}, {["x"] = 8, ["y"] = 5, ["z"] = 15, ["name"] = "default:stonebrick"}, {["x"] = 8, ["y"] = 5, ["z"] = 16, ["name"] = "default:stonebrick"}, {["x"] = 8, ["y"] = 5, ["z"] = 17, ["name"] = "default:stonebrick"}, {["x"] = 8, ["y"] = 5, ["z"] = 18, ["name"] = "default:stonebrick"}, {["x"] = 8, ["y"] = 5, ["z"] = 19, ["name"] = "default:stonebrick"}, {["x"] = 8, ["y"] = 5, ["z"] = 20, ["name"] = "default:stonebrick"}, {["x"] = 8, ["y"] = 5, ["z"] = 21, ["name"] = "default:stonebrick"}, {["x"] = 8, ["param2"] = 22, ["y"] = 5, ["param1"] = 126, ["z"] = 22, ["name"] = "stairs:slab_silver_sandstone"}, {["x"] = 8, ["y"] = 6, ["param1"] = 14, ["z"] = 15, ["name"] = "xpanes:pane_flat"}, {["x"] = 8, ["y"] = 6, ["param1"] = 110, ["z"] = 22, ["name"] = "xpanes:pane_flat"}, {["x"] = 9, ["y"] = 0, ["z"] = 0, ["name"] = "default:dirt_with_grass"}, {["x"] = 9, ["y"] = 0, ["z"] = 1, ["name"] = "default:dirt_with_grass"}, {["x"] = 9, ["y"] = 0, ["z"] = 2, ["name"] = "default:dirt_with_grass"}, {["x"] = 9, ["y"] = 0, ["z"] = 3, ["name"] = "default:dirt_with_grass"}, {["x"] = 9, ["y"] = 0, ["z"] = 4, ["name"] = "default:dirt_with_grass"}, {["x"] = 9, ["y"] = 0, ["z"] = 5, ["name"] = "default:wood"}, {["x"] = 9, ["y"] = 0, ["z"] = 6, ["name"] = "default:wood"}, {["x"] = 9, ["y"] = 0, ["z"] = 7, ["name"] = "default:wood"}, {["x"] = 9, ["y"] = 0, ["z"] = 8, ["name"] = "default:wood"}, {["x"] = 9, ["y"] = 0, ["z"] = 9, ["name"] = "default:wood"}, {["x"] = 9, ["y"] = 0, ["z"] = 10, ["name"] = "default:wood"}, {["x"] = 9, ["y"] = 0, ["z"] = 11, ["name"] = "default:wood"}, {["x"] = 9, ["y"] = 0, ["z"] = 12, ["name"] = "default:wood"}, {["x"] = 9, ["y"] = 0, ["z"] = 13, ["name"] = "default:wood"}, {["x"] = 9, ["y"] = 0, ["z"] = 14, ["name"] = "default:wood"}, {["x"] = 9, ["y"] = 0, ["z"] = 15, ["name"] = "default:wood"}, {["x"] = 9, ["y"] = 0, ["z"] = 16, ["name"] = "default:wood"}, {["x"] = 9, ["y"] = 0, ["z"] = 17, ["name"] = "default:wood"}, {["x"] = 9, ["y"] = 0, ["z"] = 18, ["name"] = "default:wood"}, {["x"] = 9, ["y"] = 0, ["z"] = 19, ["name"] = "default:wood"}, {["x"] = 9, ["y"] = 0, ["z"] = 20, ["name"] = "default:wood"}, {["x"] = 9, ["y"] = 0, ["z"] = 21, ["name"] = "default:wood"}, {["x"] = 9, ["y"] = 0, ["z"] = 22, ["name"] = "default:dirt_with_grass"}, {["x"] = 9, ["y"] = 0, ["z"] = 23, ["name"] = "default:dirt_with_grass"}, {["x"] = 9, ["y"] = 0, ["z"] = 24, ["name"] = "default:dirt_with_grass"}, {["x"] = 9, ["y"] = 0, ["z"] = 25, ["name"] = "default:dirt_with_grass"}, {["x"] = 9, ["y"] = 0, ["z"] = 26, ["name"] = "default:dirt_with_grass"}, {["x"] = 9, ["y"] = 0, ["z"] = 27, ["name"] = "the_build_spawner:white"}, {["x"] = 9, ["y"] = 0, ["z"] = 28, ["name"] = "the_build_spawner:black"}, {["x"] = 9, ["y"] = 0, ["z"] = 29, ["name"] = "the_build_spawner:black"}, {["x"] = 9, ["y"] = 0, ["z"] = 30, ["name"] = "the_build_spawner:black"}, {["x"] = 9, ["y"] = 0, ["z"] = 31, ["name"] = "the_build_spawner:black"}, {["x"] = 9, ["y"] = 0, ["z"] = 32, ["name"] = "the_build_spawner:black"}, {["x"] = 9, ["y"] = 0, ["z"] = 33, ["name"] = "the_build_spawner:black"}, {["x"] = 9, ["y"] = 0, ["z"] = 34, ["name"] = "the_build_spawner:black"}, {["x"] = 9, ["y"] = 0, ["z"] = 35, ["name"] = "the_build_spawner:black"}, {["x"] = 9, ["y"] = 0, ["z"] = 36, ["name"] = "the_build_spawner:black"}, {["x"] = 9, ["y"] = 0, ["z"] = 37, ["name"] = "the_build_spawner:black"}, {["x"] = 9, ["y"] = 0, ["z"] = 38, ["name"] = "the_build_spawner:black"}, {["x"] = 9, ["y"] = 0, ["z"] = 39, ["name"] = "the_build_spawner:black"}, {["x"] = 9, ["y"] = 0, ["z"] = 40, ["name"] = "the_build_spawner:black"}, {["x"] = 9, ["y"] = 0, ["z"] = 41, ["name"] = "the_build_spawner:white"}, {["x"] = 9, ["y"] = 1, ["param1"] = 15, ["z"] = 0, ["name"] = "default:fence_wood"}, {["x"] = 9, ["y"] = 1, ["z"] = 5, ["name"] = "default:stonebrick"}, {["x"] = 9, ["param2"] = 23, ["y"] = 1, ["param1"] = 14, ["z"] = 13, ["name"] = "stairs:stair_wood"}, {["x"] = 9, ["param2"] = 23, ["y"] = 1, ["param1"] = 13, ["z"] = 14, ["name"] = "stairs:stair_wood"}, {["x"] = 9, ["y"] = 1, ["z"] = 15, ["name"] = "default:stonebrick"}, {["x"] = 9, ["param2"] = 23, ["y"] = 1, ["param1"] = 125, ["z"] = 21, ["name"] = "stairs:slab_silver_sandstone"}, {["x"] = 9, ["y"] = 1, ["param1"] = 207, ["z"] = 26, ["name"] = "default:fence_wood"}, {["x"] = 9, ["y"] = 1, ["param1"] = 15, ["z"] = 41, ["name"] = "default:fence_wood"}, {["x"] = 9, ["param2"] = 3, ["y"] = 2, ["param1"] = 14, ["z"] = 13, ["name"] = "stairs:stair_wood"}, {["x"] = 9, ["param2"] = 3, ["y"] = 2, ["param1"] = 14, ["z"] = 14, ["name"] = "stairs:stair_wood"}, {["x"] = 9, ["y"] = 2, ["z"] = 15, ["name"] = "default:stonebrick"}, {["x"] = 9, ["param2"] = 3, ["y"] = 3, ["param1"] = 30, ["z"] = 15, ["name"] = "stairs:slab_silver_sandstone"}, {["x"] = 9, ["param2"] = 3, ["y"] = 3, ["param1"] = 125, ["z"] = 21, ["name"] = "stairs:slab_silver_sandstone"}, {["x"] = 9, ["param2"] = 23, ["y"] = 5, ["param1"] = 14, ["z"] = 4, ["name"] = "stairs:slab_silver_sandstone"}, {["x"] = 9, ["y"] = 5, ["z"] = 15, ["name"] = "default:stonebrick"}, {["x"] = 9, ["y"] = 5, ["z"] = 16, ["name"] = "default:stonebrick"}, {["x"] = 9, ["y"] = 5, ["z"] = 17, ["name"] = "default:stonebrick"}, {["x"] = 9, ["y"] = 5, ["z"] = 18, ["name"] = "default:stonebrick"}, {["x"] = 9, ["y"] = 5, ["z"] = 19, ["name"] = "default:stonebrick"}, {["x"] = 9, ["y"] = 5, ["z"] = 20, ["name"] = "default:stonebrick"}, {["x"] = 9, ["y"] = 5, ["z"] = 21, ["name"] = "default:stonebrick"}, {["x"] = 9, ["param2"] = 22, ["y"] = 5, ["param1"] = 110, ["z"] = 22, ["name"] = "stairs:slab_silver_sandstone"}, {["x"] = 9, ["y"] = 6, ["param1"] = 14, ["z"] = 15, ["name"] = "xpanes:pane_flat"}, {["x"] = 9, ["y"] = 6, ["param1"] = 94, ["z"] = 22, ["name"] = "xpanes:pane_flat"}, {["x"] = 10, ["y"] = 0, ["z"] = 0, ["name"] = "default:dirt_with_grass"}, {["x"] = 10, ["y"] = 0, ["z"] = 1, ["name"] = "default:dirt_with_grass"}, {["x"] = 10, ["y"] = 0, ["z"] = 2, ["name"] = "default:dirt_with_grass"}, {["x"] = 10, ["y"] = 0, ["z"] = 3, ["name"] = "default:dirt_with_grass"}, {["x"] = 10, ["y"] = 0, ["z"] = 4, ["name"] = "default:dirt_with_grass"}, {["x"] = 10, ["y"] = 0, ["z"] = 5, ["name"] = "default:wood"}, {["x"] = 10, ["y"] = 0, ["z"] = 6, ["name"] = "default:wood"}, {["x"] = 10, ["y"] = 0, ["z"] = 7, ["name"] = "default:wood"}, {["x"] = 10, ["y"] = 0, ["z"] = 8, ["name"] = "default:wood"}, {["x"] = 10, ["y"] = 0, ["z"] = 9, ["name"] = "default:wood"}, {["x"] = 10, ["y"] = 0, ["z"] = 10, ["name"] = "default:wood"}, {["x"] = 10, ["y"] = 0, ["z"] = 11, ["name"] = "default:wood"}, {["x"] = 10, ["y"] = 0, ["z"] = 12, ["name"] = "default:wood"}, {["x"] = 10, ["y"] = 0, ["z"] = 13, ["name"] = "default:wood"}, {["x"] = 10, ["y"] = 0, ["z"] = 14, ["name"] = "default:wood"}, {["x"] = 10, ["y"] = 0, ["z"] = 15, ["name"] = "default:wood"}, {["x"] = 10, ["y"] = 0, ["z"] = 16, ["name"] = "default:wood"}, {["x"] = 10, ["y"] = 0, ["z"] = 17, ["name"] = "default:wood"}, {["x"] = 10, ["y"] = 0, ["z"] = 18, ["name"] = "default:wood"}, {["x"] = 10, ["y"] = 0, ["z"] = 19, ["name"] = "default:wood"}, {["x"] = 10, ["y"] = 0, ["z"] = 20, ["name"] = "default:wood"}, {["x"] = 10, ["y"] = 0, ["z"] = 21, ["name"] = "default:wood"}, {["x"] = 10, ["y"] = 0, ["z"] = 22, ["name"] = "default:dirt_with_grass"}, {["x"] = 10, ["y"] = 0, ["z"] = 23, ["name"] = "default:dirt_with_grass"}, {["x"] = 10, ["y"] = 0, ["z"] = 24, ["name"] = "default:dirt_with_grass"}, {["x"] = 10, ["y"] = 0, ["z"] = 25, ["name"] = "default:dirt_with_grass"}, {["x"] = 10, ["y"] = 0, ["z"] = 26, ["name"] = "default:dirt_with_grass"}, {["x"] = 10, ["y"] = 0, ["z"] = 27, ["name"] = "the_build_spawner:white"}, {["x"] = 10, ["y"] = 0, ["z"] = 28, ["name"] = "the_build_spawner:white"}, {["x"] = 10, ["y"] = 0, ["z"] = 29, ["name"] = "the_build_spawner:white"}, {["x"] = 10, ["y"] = 0, ["z"] = 30, ["name"] = "the_build_spawner:black"}, {["x"] = 10, ["y"] = 0, ["z"] = 31, ["name"] = "the_build_spawner:black"}, {["x"] = 10, ["y"] = 0, ["z"] = 32, ["name"] = "the_build_spawner:black"}, {["x"] = 10, ["y"] = 0, ["z"] = 33, ["name"] = "the_build_spawner:black"}, {["x"] = 10, ["y"] = 0, ["z"] = 34, ["name"] = "the_build_spawner:black"}, {["x"] = 10, ["y"] = 0, ["z"] = 35, ["name"] = "the_build_spawner:black"}, {["x"] = 10, ["y"] = 0, ["z"] = 36, ["name"] = "the_build_spawner:black"}, {["x"] = 10, ["y"] = 0, ["z"] = 37, ["name"] = "the_build_spawner:black"}, {["x"] = 10, ["y"] = 0, ["z"] = 38, ["name"] = "the_build_spawner:black"}, {["x"] = 10, ["y"] = 0, ["z"] = 39, ["name"] = "the_build_spawner:black"}, {["x"] = 10, ["y"] = 0, ["z"] = 40, ["name"] = "the_build_spawner:black"}, {["x"] = 10, ["y"] = 0, ["z"] = 41, ["name"] = "the_build_spawner:white"}, {["x"] = 10, ["y"] = 1, ["param1"] = 15, ["z"] = 0, ["name"] = "default:fence_wood"}, {["x"] = 10, ["y"] = 1, ["z"] = 5, ["name"] = "default:stonebrick"}, {["x"] = 10, ["param2"] = 2, ["y"] = 1, ["param1"] = 14, ["z"] = 6, ["name"] = "stairs:stair_wood"}, {["x"] = 10, ["y"] = 1, ["param1"] = 14, ["z"] = 7, ["name"] = "default:fence_wood"}, {["x"] = 10, ["y"] = 1, ["param1"] = 14, ["z"] = 8, ["name"] = "stairs:stair_wood"}, {["x"] = 10, ["param2"] = 2, ["y"] = 1, ["param1"] = 14, ["z"] = 10, ["name"] = "stairs:stair_wood"}, {["x"] = 10, ["y"] = 1, ["param1"] = 14, ["z"] = 11, ["name"] = "default:fence_wood"}, {["x"] = 10, ["y"] = 1, ["param1"] = 14, ["z"] = 12, ["name"] = "stairs:stair_wood"}, {["x"] = 10, ["param2"] = 3, ["y"] = 1, ["param1"] = 14, ["z"] = 13, ["name"] = "stairs:stair_wood"}, {["x"] = 10, ["param2"] = 3, ["y"] = 1, ["param1"] = 14, ["z"] = 14, ["name"] = "stairs:stair_wood"}, {["x"] = 10, ["y"] = 1, ["z"] = 15, ["name"] = "default:stonebrick"}, {["x"] = 10, ["y"] = 1, ["z"] = 16, ["name"] = "default:stonebrick"}, {["x"] = 10, ["y"] = 1, ["z"] = 17, ["name"] = "default:stonebrick"}, {["x"] = 10, ["y"] = 1, ["z"] = 18, ["name"] = "default:stonebrick"}, {["x"] = 10, ["y"] = 1, ["z"] = 19, ["name"] = "default:stonebrick"}, {["x"] = 10, ["y"] = 1, ["z"] = 20, ["name"] = "default:stonebrick"}, {["x"] = 10, ["y"] = 1, ["z"] = 21, ["name"] = "default:stonebrick"}, {["x"] = 10, ["y"] = 1, ["param1"] = 191, ["z"] = 26, ["name"] = "default:fence_wood"}, {["x"] = 10, ["y"] = 1, ["param1"] = 15, ["z"] = 41, ["name"] = "default:fence_wood"}, {["x"] = 10, ["param2"] = 3, ["y"] = 2, ["param1"] = 14, ["z"] = 7, ["name"] = "doors:trapdoor"}, {["x"] = 10, ["param2"] = 3, ["y"] = 2, ["param1"] = 14, ["z"] = 11, ["name"] = "doors:trapdoor"}, {["x"] = 10, ["y"] = 2, ["z"] = 15, ["name"] = "default:stonebrick"}, {["x"] = 10, ["param2"] = 3, ["y"] = 3, ["param1"] = 14, ["z"] = 15, ["name"] = "stairs:slab_silver_sandstone"}, {["x"] = 10, ["param2"] = 3, ["y"] = 3, ["param1"] = 29, ["z"] = 16, ["name"] = "stairs:slab_silver_sandstone"}, {["x"] = 10, ["param2"] = 3, ["y"] = 3, ["param1"] = 45, ["z"] = 17, ["name"] = "stairs:slab_silver_sandstone"}, {["x"] = 10, ["param2"] = 3, ["y"] = 3, ["param1"] = 61, ["z"] = 18, ["name"] = "stairs:slab_silver_sandstone"}, {["x"] = 10, ["param2"] = 3, ["y"] = 3, ["param1"] = 77, ["z"] = 19, ["name"] = "stairs:slab_silver_sandstone"}, {["x"] = 10, ["param2"] = 3, ["y"] = 3, ["param1"] = 92, ["z"] = 20, ["name"] = "stairs:slab_silver_sandstone"}, {["x"] = 10, ["param2"] = 3, ["y"] = 3, ["param1"] = 109, ["z"] = 21, ["name"] = "stairs:slab_silver_sandstone"}, {["x"] = 10, ["param2"] = 23, ["y"] = 5, ["param1"] = 14, ["z"] = 4, ["name"] = "stairs:slab_silver_sandstone"}, {["x"] = 10, ["y"] = 5, ["z"] = 15, ["name"] = "default:stonebrick"}, {["x"] = 10, ["y"] = 5, ["z"] = 16, ["name"] = "default:stonebrick"}, {["x"] = 10, ["y"] = 5, ["z"] = 17, ["name"] = "default:stonebrick"}, {["x"] = 10, ["y"] = 5, ["z"] = 18, ["name"] = "default:stonebrick"}, {["x"] = 10, ["y"] = 5, ["z"] = 19, ["name"] = "default:stonebrick"}, {["x"] = 10, ["y"] = 5, ["z"] = 20, ["name"] = "default:stonebrick"}, {["x"] = 10, ["y"] = 5, ["z"] = 21, ["name"] = "default:stonebrick"}, {["x"] = 10, ["param2"] = 22, ["y"] = 5, ["param1"] = 94, ["z"] = 22, ["name"] = "stairs:slab_silver_sandstone"}, {["x"] = 10, ["y"] = 6, ["param1"] = 14, ["z"] = 15, ["name"] = "xpanes:pane_flat"}, {["x"] = 10, ["y"] = 6, ["param1"] = 78, ["z"] = 22, ["name"] = "xpanes:pane_flat"}, {["x"] = 11, ["y"] = 0, ["z"] = 0, ["name"] = "default:dirt_with_grass"}, {["x"] = 11, ["y"] = 0, ["z"] = 1, ["name"] = "default:dirt_with_grass"}, {["x"] = 11, ["y"] = 0, ["z"] = 2, ["name"] = "default:dirt_with_grass"}, {["x"] = 11, ["y"] = 0, ["z"] = 3, ["name"] = "default:dirt_with_grass"}, {["x"] = 11, ["y"] = 0, ["z"] = 4, ["name"] = "default:dirt_with_grass"}, {["x"] = 11, ["y"] = 0, ["z"] = 5, ["name"] = "default:wood"}, {["x"] = 11, ["y"] = 0, ["z"] = 6, ["name"] = "default:wood"}, {["x"] = 11, ["y"] = 0, ["z"] = 7, ["name"] = "default:wood"}, {["x"] = 11, ["y"] = 0, ["z"] = 8, ["name"] = "default:wood"}, {["x"] = 11, ["y"] = 0, ["z"] = 9, ["name"] = "default:wood"}, {["x"] = 11, ["y"] = 0, ["z"] = 10, ["name"] = "default:wood"}, {["x"] = 11, ["y"] = 0, ["z"] = 11, ["name"] = "default:wood"}, {["x"] = 11, ["y"] = 0, ["z"] = 12, ["name"] = "default:wood"}, {["x"] = 11, ["y"] = 0, ["z"] = 13, ["name"] = "default:wood"}, {["x"] = 11, ["y"] = 0, ["z"] = 14, ["name"] = "default:wood"}, {["x"] = 11, ["y"] = 0, ["z"] = 15, ["name"] = "default:wood"}, {["x"] = 11, ["y"] = 0, ["z"] = 16, ["name"] = "default:wood"}, {["x"] = 11, ["y"] = 0, ["z"] = 17, ["name"] = "default:wood"}, {["x"] = 11, ["y"] = 0, ["z"] = 18, ["name"] = "default:wood"}, {["x"] = 11, ["y"] = 0, ["z"] = 19, ["name"] = "default:wood"}, {["x"] = 11, ["y"] = 0, ["z"] = 20, ["name"] = "default:wood"}, {["x"] = 11, ["y"] = 0, ["z"] = 21, ["name"] = "default:wood"}, {["x"] = 11, ["y"] = 0, ["z"] = 22, ["name"] = "default:dirt_with_grass"}, {["x"] = 11, ["y"] = 0, ["z"] = 23, ["name"] = "default:dirt_with_grass"}, {["x"] = 11, ["y"] = 0, ["z"] = 24, ["name"] = "default:dirt_with_grass"}, {["x"] = 11, ["y"] = 0, ["z"] = 25, ["name"] = "default:dirt_with_grass"}, {["x"] = 11, ["y"] = 0, ["z"] = 26, ["name"] = "default:dirt_with_grass"}, {["x"] = 11, ["y"] = 0, ["z"] = 27, ["name"] = "the_build_spawner:white"}, {["x"] = 11, ["y"] = 0, ["z"] = 28, ["name"] = "the_build_spawner:black"}, {["x"] = 11, ["y"] = 0, ["z"] = 29, ["name"] = "the_build_spawner:black"}, {["x"] = 11, ["y"] = 0, ["z"] = 30, ["name"] = "the_build_spawner:black"}, {["x"] = 11, ["y"] = 0, ["z"] = 31, ["name"] = "the_build_spawner:black"}, {["x"] = 11, ["y"] = 0, ["z"] = 32, ["name"] = "the_build_spawner:black"}, {["x"] = 11, ["y"] = 0, ["z"] = 33, ["name"] = "the_build_spawner:black"}, {["x"] = 11, ["y"] = 0, ["z"] = 34, ["name"] = "the_build_spawner:black"}, {["x"] = 11, ["y"] = 0, ["z"] = 35, ["name"] = "the_build_spawner:black"}, {["x"] = 11, ["y"] = 0, ["z"] = 36, ["name"] = "the_build_spawner:black"}, {["x"] = 11, ["y"] = 0, ["z"] = 37, ["name"] = "the_build_spawner:black"}, {["x"] = 11, ["y"] = 0, ["z"] = 38, ["name"] = "the_build_spawner:black"}, {["x"] = 11, ["y"] = 0, ["z"] = 39, ["name"] = "the_build_spawner:black"}, {["x"] = 11, ["y"] = 0, ["z"] = 40, ["name"] = "the_build_spawner:black"}, {["x"] = 11, ["y"] = 0, ["z"] = 41, ["name"] = "the_build_spawner:white"}, {["x"] = 11, ["y"] = 1, ["param1"] = 15, ["z"] = 0, ["name"] = "default:fence_wood"}, {["x"] = 11, ["y"] = 1, ["z"] = 5, ["name"] = "default:stonebrick"}, {["x"] = 11, ["y"] = 1, ["param1"] = 207, ["z"] = 26, ["name"] = "default:fence_wood"}, {["x"] = 11, ["y"] = 1, ["param1"] = 15, ["z"] = 41, ["name"] = "default:fence_wood"}, {["x"] = 11, ["param2"] = 3, ["y"] = 2, ["param1"] = 141, ["z"] = 21, ["name"] = "doors:trapdoor"}, {["x"] = 11, ["param2"] = 23, ["y"] = 5, ["param1"] = 14, ["z"] = 4, ["name"] = "stairs:slab_silver_sandstone"}, {["x"] = 11, ["param2"] = 21, ["y"] = 5, ["param1"] = 14, ["z"] = 15, ["name"] = "stairs:slab_silver_sandstone"}, {["x"] = 11, ["param2"] = 21, ["y"] = 5, ["param1"] = 14, ["z"] = 16, ["name"] = "stairs:slab_silver_sandstone"}, {["x"] = 11, ["param2"] = 21, ["y"] = 5, ["param1"] = 30, ["z"] = 17, ["name"] = "stairs:slab_silver_sandstone"}, {["x"] = 11, ["param2"] = 21, ["y"] = 5, ["param1"] = 46, ["z"] = 18, ["name"] = "stairs:slab_silver_sandstone"}, {["x"] = 11, ["param2"] = 21, ["y"] = 5, ["param1"] = 62, ["z"] = 19, ["name"] = "stairs:slab_silver_sandstone"}, {["x"] = 11, ["param2"] = 21, ["y"] = 5, ["param1"] = 77, ["z"] = 20, ["name"] = "stairs:slab_silver_sandstone"}, {["x"] = 11, ["param2"] = 21, ["y"] = 5, ["param1"] = 93, ["z"] = 21, ["name"] = "stairs:slab_silver_sandstone"}, {["x"] = 11, ["param2"] = 21, ["y"] = 5, ["param1"] = 110, ["z"] = 22, ["name"] = "stairs:slab_silver_sandstone"}, {["x"] = 11, ["y"] = 6, ["param1"] = 14, ["z"] = 15, ["name"] = "xpanes:pane"}, {["x"] = 11, ["param2"] = 3, ["y"] = 6, ["param1"] = 14, ["z"] = 16, ["name"] = "xpanes:pane_flat"}, {["x"] = 11, ["param2"] = 3, ["y"] = 6, ["param1"] = 14, ["z"] = 17, ["name"] = "xpanes:pane_flat"}, {["x"] = 11, ["param2"] = 3, ["y"] = 6, ["param1"] = 30, ["z"] = 18, ["name"] = "xpanes:pane_flat"}, {["x"] = 11, ["param2"] = 3, ["y"] = 6, ["param1"] = 46, ["z"] = 19, ["name"] = "xpanes:pane_flat"}, {["x"] = 11, ["param2"] = 3, ["y"] = 6, ["param1"] = 61, ["z"] = 20, ["name"] = "xpanes:pane_flat"}, {["x"] = 11, ["param2"] = 3, ["y"] = 6, ["param1"] = 77, ["z"] = 21, ["name"] = "xpanes:pane_flat"}, {["x"] = 11, ["y"] = 6, ["param1"] = 94, ["z"] = 22, ["name"] = "xpanes:pane"}, {["x"] = 12, ["y"] = 0, ["z"] = 0, ["name"] = "default:dirt_with_grass"}, {["x"] = 12, ["y"] = 0, ["z"] = 1, ["name"] = "default:dirt_with_grass"}, {["x"] = 12, ["y"] = 0, ["z"] = 2, ["name"] = "default:dirt_with_grass"}, {["x"] = 12, ["y"] = 0, ["z"] = 3, ["name"] = "default:dirt_with_grass"}, {["x"] = 12, ["y"] = 0, ["z"] = 4, ["name"] = "default:dirt_with_grass"}, {["x"] = 12, ["y"] = 0, ["z"] = 5, ["name"] = "default:wood"}, {["x"] = 12, ["y"] = 0, ["z"] = 6, ["name"] = "default:wood"}, {["x"] = 12, ["y"] = 0, ["z"] = 7, ["name"] = "default:wood"}, {["x"] = 12, ["y"] = 0, ["z"] = 8, ["name"] = "default:wood"}, {["x"] = 12, ["y"] = 0, ["z"] = 9, ["name"] = "default:wood"}, {["x"] = 12, ["y"] = 0, ["z"] = 10, ["name"] = "default:wood"}, {["x"] = 12, ["y"] = 0, ["z"] = 11, ["name"] = "default:wood"}, {["x"] = 12, ["y"] = 0, ["z"] = 12, ["name"] = "default:wood"}, {["x"] = 12, ["y"] = 0, ["z"] = 13, ["name"] = "default:wood"}, {["x"] = 12, ["y"] = 0, ["z"] = 14, ["name"] = "default:wood"}, {["x"] = 12, ["y"] = 0, ["z"] = 15, ["name"] = "default:wood"}, {["x"] = 12, ["y"] = 0, ["z"] = 16, ["name"] = "default:wood"}, {["x"] = 12, ["y"] = 0, ["z"] = 17, ["name"] = "default:wood"}, {["x"] = 12, ["y"] = 0, ["z"] = 18, ["name"] = "default:wood"}, {["x"] = 12, ["y"] = 0, ["z"] = 19, ["name"] = "default:wood"}, {["x"] = 12, ["y"] = 0, ["z"] = 20, ["name"] = "default:wood"}, {["x"] = 12, ["y"] = 0, ["z"] = 21, ["name"] = "default:wood"}, {["x"] = 12, ["y"] = 0, ["z"] = 22, ["name"] = "default:dirt_with_grass"}, {["x"] = 12, ["y"] = 0, ["z"] = 23, ["name"] = "default:dirt_with_grass"}, {["x"] = 12, ["y"] = 0, ["z"] = 24, ["name"] = "default:dirt_with_grass"}, {["x"] = 12, ["y"] = 0, ["z"] = 25, ["name"] = "default:dirt_with_grass"}, {["x"] = 12, ["y"] = 0, ["z"] = 26, ["name"] = "default:dirt_with_grass"}, {["x"] = 12, ["y"] = 0, ["z"] = 27, ["name"] = "the_build_spawner:white"}, {["x"] = 12, ["y"] = 0, ["z"] = 28, ["name"] = "the_build_spawner:black"}, {["x"] = 12, ["y"] = 0, ["z"] = 29, ["name"] = "the_build_spawner:black"}, {["x"] = 12, ["y"] = 0, ["z"] = 30, ["name"] = "the_build_spawner:black"}, {["x"] = 12, ["y"] = 0, ["z"] = 31, ["name"] = "the_build_spawner:black"}, {["x"] = 12, ["y"] = 0, ["z"] = 32, ["name"] = "the_build_spawner:black"}, {["x"] = 12, ["y"] = 0, ["z"] = 33, ["name"] = "the_build_spawner:black"}, {["x"] = 12, ["y"] = 0, ["z"] = 34, ["name"] = "the_build_spawner:black"}, {["x"] = 12, ["y"] = 0, ["z"] = 35, ["name"] = "the_build_spawner:black"}, {["x"] = 12, ["y"] = 0, ["z"] = 36, ["name"] = "the_build_spawner:black"}, {["x"] = 12, ["y"] = 0, ["z"] = 37, ["name"] = "the_build_spawner:black"}, {["x"] = 12, ["y"] = 0, ["z"] = 38, ["name"] = "the_build_spawner:white"}, {["x"] = 12, ["y"] = 0, ["z"] = 39, ["name"] = "the_build_spawner:white"}, {["x"] = 12, ["y"] = 0, ["z"] = 40, ["name"] = "the_build_spawner:white"}, {["x"] = 12, ["y"] = 0, ["z"] = 41, ["name"] = "the_build_spawner:white"}, {["x"] = 12, ["y"] = 1, ["param1"] = 15, ["z"] = 0, ["name"] = "default:fence_wood"}, {["x"] = 12, ["y"] = 1, ["z"] = 5, ["name"] = "default:stonebrick"}, {["x"] = 12, ["param2"] = 2, ["y"] = 1, ["param1"] = 14, ["z"] = 6, ["name"] = "stairs:stair_wood"}, {["x"] = 12, ["y"] = 1, ["param1"] = 14, ["z"] = 7, ["name"] = "default:fence_wood"}, {["x"] = 12, ["y"] = 1, ["param1"] = 14, ["z"] = 8, ["name"] = "stairs:stair_wood"}, {["x"] = 12, ["param2"] = 2, ["y"] = 1, ["param1"] = 14, ["z"] = 10, ["name"] = "stairs:stair_wood"}, {["x"] = 12, ["y"] = 1, ["param1"] = 14, ["z"] = 11, ["name"] = "default:fence_wood"}, {["x"] = 12, ["y"] = 1, ["param1"] = 14, ["z"] = 12, ["name"] = "stairs:stair_wood"}, {["x"] = 12, ["param2"] = 2, ["y"] = 1, ["param1"] = 30, ["z"] = 14, ["name"] = "stairs:stair_wood"}, {["x"] = 12, ["y"] = 1, ["param1"] = 46, ["z"] = 15, ["name"] = "default:fence_wood"}, {["x"] = 12, ["y"] = 1, ["param1"] = 62, ["z"] = 16, ["name"] = "stairs:stair_wood"}, {["x"] = 12, ["param2"] = 2, ["y"] = 1, ["param1"] = 94, ["z"] = 18, ["name"] = "stairs:stair_wood"}, {["x"] = 12, ["y"] = 1, ["param1"] = 110, ["z"] = 19, ["name"] = "default:fence_wood"}, {["x"] = 12, ["y"] = 1, ["param1"] = 125, ["z"] = 20, ["name"] = "stairs:stair_wood"}, {["x"] = 12, ["y"] = 1, ["z"] = 21, ["name"] = "default:stonebrick"}, {["x"] = 12, ["y"] = 1, ["param1"] = 223, ["z"] = 26, ["name"] = "default:fence_wood"}, {["x"] = 12, ["y"] = 1, ["param1"] = 31, ["z"] = 41, ["name"] = "default:fence_wood"}, {["x"] = 12, ["param2"] = 3, ["y"] = 2, ["param1"] = 14, ["z"] = 7, ["name"] = "doors:trapdoor"}, {["x"] = 12, ["param2"] = 3, ["y"] = 2, ["param1"] = 14, ["z"] = 11, ["name"] = "doors:trapdoor"}, {["x"] = 12, ["param2"] = 3, ["y"] = 2, ["param1"] = 62, ["z"] = 15, ["name"] = "doors:trapdoor"}, {["x"] = 12, ["param2"] = 3, ["y"] = 2, ["param1"] = 126, ["z"] = 19, ["name"] = "doors:trapdoor"}, {["x"] = 12, ["y"] = 2, ["param1"] = 239, ["z"] = 26, ["name"] = "default:mese_post_light"}, {["x"] = 12, ["param2"] = 23, ["y"] = 5, ["param1"] = 14, ["z"] = 4, ["name"] = "stairs:slab_silver_sandstone"}, {["x"] = 12, ["param2"] = 21, ["y"] = 5, ["param1"] = 126, ["z"] = 22, ["name"] = "stairs:slab_silver_sandstone"}, {["x"] = 13, ["y"] = 0, ["z"] = 0, ["name"] = "default:dirt_with_grass"}, {["x"] = 13, ["y"] = 0, ["z"] = 1, ["name"] = "default:dirt_with_grass"}, {["x"] = 13, ["y"] = 0, ["z"] = 2, ["name"] = "default:dirt_with_grass"}, {["x"] = 13, ["y"] = 0, ["z"] = 3, ["name"] = "default:dirt_with_grass"}, {["x"] = 13, ["y"] = 0, ["z"] = 4, ["name"] = "default:dirt_with_grass"}, {["x"] = 13, ["y"] = 0, ["z"] = 5, ["name"] = "default:wood"}, {["x"] = 13, ["y"] = 0, ["z"] = 6, ["name"] = "default:wood"}, {["x"] = 13, ["y"] = 0, ["z"] = 7, ["name"] = "default:wood"}, {["x"] = 13, ["y"] = 0, ["z"] = 8, ["name"] = "default:wood"}, {["x"] = 13, ["y"] = 0, ["z"] = 9, ["name"] = "default:wood"}, {["x"] = 13, ["y"] = 0, ["z"] = 10, ["name"] = "default:wood"}, {["x"] = 13, ["y"] = 0, ["z"] = 11, ["name"] = "default:wood"}, {["x"] = 13, ["y"] = 0, ["z"] = 12, ["name"] = "default:wood"}, {["x"] = 13, ["y"] = 0, ["z"] = 13, ["name"] = "default:wood"}, {["x"] = 13, ["y"] = 0, ["z"] = 14, ["name"] = "default:wood"}, {["x"] = 13, ["y"] = 0, ["z"] = 15, ["name"] = "default:wood"}, {["x"] = 13, ["y"] = 0, ["z"] = 16, ["name"] = "default:wood"}, {["x"] = 13, ["y"] = 0, ["z"] = 17, ["name"] = "default:wood"}, {["x"] = 13, ["y"] = 0, ["z"] = 18, ["name"] = "default:wood"}, {["x"] = 13, ["y"] = 0, ["z"] = 19, ["name"] = "default:wood"}, {["x"] = 13, ["y"] = 0, ["z"] = 20, ["name"] = "default:wood"}, {["x"] = 13, ["y"] = 0, ["z"] = 21, ["name"] = "default:wood"}, {["x"] = 13, ["y"] = 0, ["z"] = 22, ["name"] = "default:dirt_with_grass"}, {["x"] = 13, ["y"] = 0, ["z"] = 23, ["name"] = "default:dirt_with_grass"}, {["x"] = 13, ["y"] = 0, ["z"] = 24, ["name"] = "default:dirt_with_grass"}, {["x"] = 13, ["y"] = 0, ["z"] = 25, ["name"] = "default:dirt_with_grass"}, {["x"] = 13, ["y"] = 0, ["z"] = 26, ["name"] = "default:dirt_with_grass"}, {["x"] = 13, ["y"] = 0, ["z"] = 27, ["name"] = "the_build_spawner:white"}, {["x"] = 13, ["y"] = 0, ["z"] = 28, ["name"] = "the_build_spawner:black"}, {["x"] = 13, ["y"] = 0, ["z"] = 29, ["name"] = "the_build_spawner:black"}, {["x"] = 13, ["y"] = 0, ["z"] = 30, ["name"] = "the_build_spawner:black"}, {["x"] = 13, ["y"] = 0, ["z"] = 31, ["name"] = "the_build_spawner:black"}, {["x"] = 13, ["y"] = 0, ["z"] = 32, ["name"] = "the_build_spawner:black"}, {["x"] = 13, ["y"] = 0, ["z"] = 33, ["name"] = "the_build_spawner:black"}, {["x"] = 13, ["y"] = 0, ["z"] = 34, ["name"] = "the_build_spawner:black"}, {["x"] = 13, ["y"] = 0, ["z"] = 35, ["name"] = "the_build_spawner:black"}, {["x"] = 13, ["y"] = 0, ["z"] = 36, ["name"] = "the_build_spawner:black"}, {["x"] = 13, ["y"] = 0, ["z"] = 37, ["name"] = "the_build_spawner:black"}, {["x"] = 13, ["y"] = 0, ["z"] = 38, ["name"] = "the_build_spawner:black"}, {["x"] = 13, ["y"] = 0, ["z"] = 39, ["name"] = "the_build_spawner:black"}, {["x"] = 13, ["y"] = 0, ["z"] = 40, ["name"] = "the_build_spawner:black"}, {["x"] = 13, ["y"] = 0, ["z"] = 41, ["name"] = "the_build_spawner:white"}, {["x"] = 13, ["y"] = 1, ["param1"] = 15, ["z"] = 0, ["name"] = "default:fence_wood"}, {["x"] = 13, ["y"] = 1, ["z"] = 5, ["name"] = "default:stonebrick"}, {["x"] = 13, ["y"] = 1, ["z"] = 21, ["name"] = "default:stonebrick"}, {["x"] = 13, ["y"] = 1, ["param1"] = 207, ["z"] = 26, ["name"] = "default:fence_wood"}, {["x"] = 13, ["y"] = 1, ["param1"] = 47, ["z"] = 41, ["name"] = "default:fence_wood"}, {["x"] = 13, ["param2"] = 23, ["y"] = 5, ["param1"] = 14, ["z"] = 4, ["name"] = "stairs:slab_silver_sandstone"}, {["x"] = 13, ["param2"] = 21, ["y"] = 5, ["param1"] = 110, ["z"] = 22, ["name"] = "stairs:slab_silver_sandstone"}, {["x"] = 14, ["y"] = 0, ["z"] = 0, ["name"] = "default:dirt_with_grass"}, {["x"] = 14, ["y"] = 0, ["z"] = 1, ["name"] = "default:dirt_with_grass"}, {["x"] = 14, ["y"] = 0, ["z"] = 2, ["name"] = "default:dirt_with_grass"}, {["x"] = 14, ["y"] = 0, ["z"] = 3, ["name"] = "default:dirt_with_grass"}, {["x"] = 14, ["y"] = 0, ["z"] = 4, ["name"] = "default:dirt_with_grass"}, {["x"] = 14, ["y"] = 0, ["z"] = 5, ["name"] = "default:wood"}, {["x"] = 14, ["y"] = 0, ["z"] = 6, ["name"] = "default:wood"}, {["x"] = 14, ["y"] = 0, ["z"] = 7, ["name"] = "default:wood"}, {["x"] = 14, ["y"] = 0, ["z"] = 8, ["name"] = "default:wood"}, {["x"] = 14, ["y"] = 0, ["z"] = 9, ["name"] = "default:wood"}, {["x"] = 14, ["y"] = 0, ["z"] = 10, ["name"] = "default:wood"}, {["x"] = 14, ["y"] = 0, ["z"] = 11, ["name"] = "default:wood"}, {["x"] = 14, ["y"] = 0, ["z"] = 12, ["name"] = "default:wood"}, {["x"] = 14, ["y"] = 0, ["z"] = 13, ["name"] = "default:wood"}, {["x"] = 14, ["y"] = 0, ["z"] = 14, ["name"] = "default:wood"}, {["x"] = 14, ["y"] = 0, ["z"] = 15, ["name"] = "default:wood"}, {["x"] = 14, ["y"] = 0, ["z"] = 16, ["name"] = "default:wood"}, {["x"] = 14, ["y"] = 0, ["z"] = 17, ["name"] = "default:wood"}, {["x"] = 14, ["y"] = 0, ["z"] = 18, ["name"] = "default:wood"}, {["x"] = 14, ["y"] = 0, ["z"] = 19, ["name"] = "default:wood"}, {["x"] = 14, ["y"] = 0, ["z"] = 20, ["name"] = "default:wood"}, {["x"] = 14, ["y"] = 0, ["z"] = 21, ["name"] = "default:wood"}, {["x"] = 14, ["y"] = 0, ["z"] = 22, ["name"] = "default:dirt_with_grass"}, {["x"] = 14, ["y"] = 0, ["z"] = 23, ["name"] = "default:dirt_with_grass"}, {["x"] = 14, ["y"] = 0, ["z"] = 24, ["name"] = "default:dirt_with_grass"}, {["x"] = 14, ["y"] = 0, ["z"] = 25, ["name"] = "default:dirt_with_grass"}, {["x"] = 14, ["y"] = 0, ["z"] = 26, ["name"] = "default:dirt_with_grass"}, {["x"] = 14, ["y"] = 0, ["z"] = 27, ["name"] = "the_build_spawner:white"}, {["x"] = 14, ["y"] = 0, ["z"] = 28, ["name"] = "the_build_spawner:white"}, {["x"] = 14, ["y"] = 0, ["z"] = 29, ["name"] = "the_build_spawner:white"}, {["x"] = 14, ["y"] = 0, ["z"] = 30, ["name"] = "the_build_spawner:black"}, {["x"] = 14, ["y"] = 0, ["z"] = 31, ["name"] = "the_build_spawner:black"}, {["x"] = 14, ["y"] = 0, ["z"] = 32, ["name"] = "the_build_spawner:black"}, {["x"] = 14, ["y"] = 0, ["z"] = 33, ["name"] = "the_build_spawner:black"}, {["x"] = 14, ["y"] = 0, ["z"] = 34, ["name"] = "the_build_spawner:black"}, {["x"] = 14, ["y"] = 0, ["z"] = 35, ["name"] = "the_build_spawner:black"}, {["x"] = 14, ["y"] = 0, ["z"] = 36, ["name"] = "the_build_spawner:black"}, {["x"] = 14, ["y"] = 0, ["z"] = 37, ["name"] = "the_build_spawner:black"}, {["x"] = 14, ["y"] = 0, ["z"] = 38, ["name"] = "the_build_spawner:black"}, {["x"] = 14, ["y"] = 0, ["z"] = 39, ["name"] = "the_build_spawner:black"}, {["x"] = 14, ["y"] = 0, ["z"] = 40, ["name"] = "the_build_spawner:black"}, {["x"] = 14, ["y"] = 0, ["z"] = 41, ["name"] = "the_build_spawner:white"}, {["x"] = 14, ["y"] = 1, ["param1"] = 15, ["z"] = 0, ["name"] = "default:fence_wood"}, {["x"] = 14, ["y"] = 1, ["z"] = 5, ["name"] = "default:stonebrick"}, {["x"] = 14, ["param2"] = 2, ["y"] = 1, ["param1"] = 14, ["z"] = 6, ["name"] = "stairs:stair_wood"}, {["x"] = 14, ["y"] = 1, ["param1"] = 14, ["z"] = 7, ["name"] = "default:fence_wood"}, {["x"] = 14, ["y"] = 1, ["param1"] = 14, ["z"] = 8, ["name"] = "stairs:stair_wood"}, {["x"] = 14, ["param2"] = 2, ["y"] = 1, ["param1"] = 14, ["z"] = 10, ["name"] = "stairs:stair_wood"}, {["x"] = 14, ["y"] = 1, ["param1"] = 14, ["z"] = 11, ["name"] = "default:fence_wood"}, {["x"] = 14, ["y"] = 1, ["param1"] = 14, ["z"] = 12, ["name"] = "stairs:stair_wood"}, {["x"] = 14, ["param2"] = 2, ["y"] = 1, ["param1"] = 14, ["z"] = 14, ["name"] = "stairs:stair_wood"}, {["x"] = 14, ["y"] = 1, ["param1"] = 14, ["z"] = 15, ["name"] = "default:fence_wood"}, {["x"] = 14, ["y"] = 1, ["param1"] = 30, ["z"] = 16, ["name"] = "stairs:stair_wood"}, {["x"] = 14, ["param2"] = 2, ["y"] = 1, ["param1"] = 62, ["z"] = 18, ["name"] = "stairs:stair_wood"}, {["x"] = 14, ["y"] = 1, ["param1"] = 78, ["z"] = 19, ["name"] = "default:fence_wood"}, {["x"] = 14, ["y"] = 1, ["param1"] = 93, ["z"] = 20, ["name"] = "stairs:stair_wood"}, {["x"] = 14, ["y"] = 1, ["z"] = 21, ["name"] = "default:stonebrick"}, {["x"] = 14, ["y"] = 1, ["param1"] = 191, ["z"] = 26, ["name"] = "default:fence_wood"}, {["x"] = 14, ["y"] = 1, ["param1"] = 63, ["z"] = 41, ["name"] = "default:fence_wood"}, {["x"] = 14, ["param2"] = 3, ["y"] = 2, ["param1"] = 14, ["z"] = 7, ["name"] = "doors:trapdoor"}, {["x"] = 14, ["param2"] = 3, ["y"] = 2, ["param1"] = 14, ["z"] = 11, ["name"] = "doors:trapdoor"}, {["x"] = 14, ["param2"] = 3, ["y"] = 2, ["param1"] = 30, ["z"] = 15, ["name"] = "doors:trapdoor"}, {["x"] = 14, ["param2"] = 3, ["y"] = 2, ["param1"] = 94, ["z"] = 19, ["name"] = "doors:trapdoor"}, {["x"] = 14, ["param2"] = 23, ["y"] = 5, ["param1"] = 14, ["z"] = 4, ["name"] = "stairs:slab_silver_sandstone"}, {["x"] = 14, ["param2"] = 21, ["y"] = 5, ["param1"] = 94, ["z"] = 22, ["name"] = "stairs:slab_silver_sandstone"}, {["x"] = 15, ["y"] = 0, ["z"] = 0, ["name"] = "default:dirt_with_grass"}, {["x"] = 15, ["y"] = 0, ["z"] = 1, ["name"] = "default:dirt_with_grass"}, {["x"] = 15, ["y"] = 0, ["z"] = 2, ["name"] = "default:dirt_with_grass"}, {["x"] = 15, ["y"] = 0, ["z"] = 3, ["name"] = "default:dirt_with_grass"}, {["x"] = 15, ["y"] = 0, ["z"] = 4, ["name"] = "default:dirt_with_grass"}, {["x"] = 15, ["y"] = 0, ["z"] = 5, ["name"] = "default:wood"}, {["x"] = 15, ["y"] = 0, ["z"] = 6, ["name"] = "default:wood"}, {["x"] = 15, ["y"] = 0, ["z"] = 7, ["name"] = "default:wood"}, {["x"] = 15, ["y"] = 0, ["z"] = 8, ["name"] = "default:wood"}, {["x"] = 15, ["y"] = 0, ["z"] = 9, ["name"] = "default:wood"}, {["x"] = 15, ["y"] = 0, ["z"] = 10, ["name"] = "default:wood"}, {["x"] = 15, ["y"] = 0, ["z"] = 11, ["name"] = "default:wood"}, {["x"] = 15, ["y"] = 0, ["z"] = 12, ["name"] = "default:wood"}, {["x"] = 15, ["y"] = 0, ["z"] = 13, ["name"] = "default:wood"}, {["x"] = 15, ["y"] = 0, ["z"] = 14, ["name"] = "default:wood"}, {["x"] = 15, ["y"] = 0, ["z"] = 15, ["name"] = "default:wood"}, {["x"] = 15, ["y"] = 0, ["z"] = 16, ["name"] = "default:wood"}, {["x"] = 15, ["y"] = 0, ["z"] = 17, ["name"] = "default:wood"}, {["x"] = 15, ["y"] = 0, ["z"] = 18, ["name"] = "default:wood"}, {["x"] = 15, ["y"] = 0, ["z"] = 19, ["name"] = "default:wood"}, {["x"] = 15, ["y"] = 0, ["z"] = 20, ["name"] = "default:wood"}, {["x"] = 15, ["y"] = 0, ["z"] = 21, ["name"] = "default:wood"}, {["x"] = 15, ["y"] = 0, ["z"] = 22, ["name"] = "default:dirt_with_grass"}, {["x"] = 15, ["y"] = 0, ["z"] = 23, ["name"] = "default:dirt_with_grass"}, {["x"] = 15, ["y"] = 0, ["z"] = 24, ["name"] = "default:dirt_with_grass"}, {["x"] = 15, ["y"] = 0, ["z"] = 25, ["name"] = "default:dirt_with_grass"}, {["x"] = 15, ["y"] = 0, ["z"] = 26, ["name"] = "default:dirt_with_grass"}, {["x"] = 15, ["y"] = 0, ["z"] = 27, ["name"] = "the_build_spawner:white"}, {["x"] = 15, ["y"] = 0, ["z"] = 28, ["name"] = "the_build_spawner:black"}, {["x"] = 15, ["y"] = 0, ["z"] = 29, ["name"] = "the_build_spawner:black"}, {["x"] = 15, ["y"] = 0, ["z"] = 30, ["name"] = "the_build_spawner:black"}, {["x"] = 15, ["y"] = 0, ["z"] = 31, ["name"] = "the_build_spawner:black"}, {["x"] = 15, ["y"] = 0, ["z"] = 32, ["name"] = "the_build_spawner:black"}, {["x"] = 15, ["y"] = 0, ["z"] = 33, ["name"] = "the_build_spawner:black"}, {["x"] = 15, ["y"] = 0, ["z"] = 34, ["name"] = "the_build_spawner:black"}, {["x"] = 15, ["y"] = 0, ["z"] = 35, ["name"] = "the_build_spawner:black"}, {["x"] = 15, ["y"] = 0, ["z"] = 36, ["name"] = "the_build_spawner:black"}, {["x"] = 15, ["y"] = 0, ["z"] = 37, ["name"] = "the_build_spawner:black"}, {["x"] = 15, ["y"] = 0, ["z"] = 38, ["name"] = "the_build_spawner:black"}, {["x"] = 15, ["y"] = 0, ["z"] = 39, ["name"] = "the_build_spawner:black"}, {["x"] = 15, ["y"] = 0, ["z"] = 40, ["name"] = "the_build_spawner:black"}, {["x"] = 15, ["y"] = 0, ["z"] = 41, ["name"] = "the_build_spawner:white"}, {["x"] = 15, ["y"] = 1, ["param1"] = 15, ["z"] = 0, ["name"] = "default:fence_wood"}, {["x"] = 15, ["y"] = 1, ["z"] = 5, ["name"] = "default:stonebrick"}, {["x"] = 15, ["y"] = 1, ["z"] = 21, ["name"] = "default:stonebrick"}, {["x"] = 15, ["y"] = 1, ["param1"] = 207, ["z"] = 26, ["name"] = "default:fence_wood"}, {["x"] = 15, ["y"] = 1, ["param1"] = 79, ["z"] = 41, ["name"] = "default:fence_wood"}, {["x"] = 15, ["param2"] = 23, ["y"] = 5, ["param1"] = 14, ["z"] = 4, ["name"] = "stairs:slab_silver_sandstone"}, {["x"] = 15, ["param2"] = 21, ["y"] = 5, ["param1"] = 110, ["z"] = 22, ["name"] = "stairs:slab_silver_sandstone"}, {["x"] = 16, ["y"] = 0, ["z"] = 0, ["name"] = "default:dirt"}, {["x"] = 16, ["y"] = 0, ["z"] = 1, ["name"] = "default:dirt_with_grass"}, {["x"] = 16, ["y"] = 0, ["z"] = 2, ["name"] = "default:dirt_with_grass"}, {["x"] = 16, ["y"] = 0, ["z"] = 3, ["name"] = "default:dirt_with_grass"}, {["x"] = 16, ["y"] = 0, ["z"] = 4, ["name"] = "default:dirt_with_grass"}, {["x"] = 16, ["y"] = 0, ["z"] = 5, ["name"] = "default:wood"}, {["x"] = 16, ["y"] = 0, ["z"] = 6, ["name"] = "default:wood"}, {["x"] = 16, ["y"] = 0, ["z"] = 7, ["name"] = "default:wood"}, {["x"] = 16, ["y"] = 0, ["z"] = 8, ["name"] = "default:wood"}, {["x"] = 16, ["y"] = 0, ["z"] = 9, ["name"] = "default:wood"}, {["x"] = 16, ["y"] = 0, ["z"] = 10, ["name"] = "default:wood"}, {["x"] = 16, ["y"] = 0, ["z"] = 11, ["name"] = "default:wood"}, {["x"] = 16, ["y"] = 0, ["z"] = 12, ["name"] = "default:wood"}, {["x"] = 16, ["y"] = 0, ["z"] = 13, ["name"] = "default:wood"}, {["x"] = 16, ["y"] = 0, ["z"] = 14, ["name"] = "default:wood"}, {["x"] = 16, ["y"] = 0, ["z"] = 15, ["name"] = "default:wood"}, {["x"] = 16, ["y"] = 0, ["z"] = 16, ["name"] = "default:wood"}, {["x"] = 16, ["y"] = 0, ["z"] = 17, ["name"] = "default:wood"}, {["x"] = 16, ["y"] = 0, ["z"] = 18, ["name"] = "default:wood"}, {["x"] = 16, ["y"] = 0, ["z"] = 19, ["name"] = "default:wood"}, {["x"] = 16, ["y"] = 0, ["z"] = 20, ["name"] = "default:wood"}, {["x"] = 16, ["y"] = 0, ["z"] = 21, ["name"] = "default:wood"}, {["x"] = 16, ["y"] = 0, ["z"] = 22, ["name"] = "default:dirt_with_grass"}, {["x"] = 16, ["y"] = 0, ["z"] = 23, ["name"] = "default:dirt_with_grass"}, {["x"] = 16, ["y"] = 0, ["z"] = 24, ["name"] = "default:dirt_with_grass"}, {["x"] = 16, ["y"] = 0, ["z"] = 25, ["name"] = "default:dirt_with_grass"}, {["x"] = 16, ["y"] = 0, ["z"] = 26, ["name"] = "default:dirt_with_grass"}, {["x"] = 16, ["y"] = 0, ["z"] = 27, ["name"] = "the_build_spawner:white"}, {["x"] = 16, ["y"] = 0, ["z"] = 28, ["name"] = "the_build_spawner:black"}, {["x"] = 16, ["y"] = 0, ["z"] = 29, ["name"] = "the_build_spawner:black"}, {["x"] = 16, ["y"] = 0, ["z"] = 30, ["name"] = "the_build_spawner:black"}, {["x"] = 16, ["y"] = 0, ["z"] = 31, ["name"] = "the_build_spawner:black"}, {["x"] = 16, ["y"] = 0, ["z"] = 32, ["name"] = "the_build_spawner:black"}, {["x"] = 16, ["y"] = 0, ["z"] = 33, ["name"] = "the_build_spawner:black"}, {["x"] = 16, ["y"] = 0, ["z"] = 34, ["name"] = "the_build_spawner:black"}, {["x"] = 16, ["y"] = 0, ["z"] = 35, ["name"] = "the_build_spawner:black"}, {["x"] = 16, ["y"] = 0, ["z"] = 36, ["name"] = "the_build_spawner:black"}, {["x"] = 16, ["y"] = 0, ["z"] = 37, ["name"] = "the_build_spawner:black"}, {["x"] = 16, ["y"] = 0, ["z"] = 38, ["name"] = "the_build_spawner:white"}, {["x"] = 16, ["y"] = 0, ["z"] = 39, ["name"] = "the_build_spawner:white"}, {["x"] = 16, ["y"] = 0, ["z"] = 40, ["name"] = "the_build_spawner:white"}, {["x"] = 16, ["y"] = 0, ["z"] = 41, ["name"] = "the_build_spawner:white"}, {["x"] = 16, ["y"] = 1, ["z"] = 0, ["name"] = "default:obsidian"}, {["x"] = 16, ["y"] = 1, ["z"] = 5, ["name"] = "default:stonebrick"}, {["x"] = 16, ["y"] = 1, ["z"] = 6, ["name"] = "default:stonebrick"}, {["x"] = 16, ["y"] = 1, ["z"] = 7, ["name"] = "default:stonebrick"}, {["x"] = 16, ["y"] = 1, ["z"] = 8, ["name"] = "default:stonebrick"}, {["x"] = 16, ["y"] = 1, ["z"] = 9, ["name"] = "default:stonebrick"}, {["x"] = 16, ["y"] = 1, ["z"] = 10, ["name"] = "default:stonebrick"}, {["x"] = 16, ["y"] = 1, ["z"] = 11, ["name"] = "default:stonebrick"}, {["x"] = 16, ["y"] = 1, ["z"] = 12, ["name"] = "default:stonebrick"}, {["x"] = 16, ["y"] = 1, ["z"] = 13, ["name"] = "default:stonebrick"}, {["x"] = 16, ["y"] = 1, ["z"] = 14, ["name"] = "default:stonebrick"}, {["x"] = 16, ["y"] = 1, ["z"] = 15, ["name"] = "default:stonebrick"}, {["x"] = 16, ["y"] = 1, ["z"] = 16, ["name"] = "default:stonebrick"}, {["x"] = 16, ["y"] = 1, ["z"] = 17, ["name"] = "default:stonebrick"}, {["x"] = 16, ["y"] = 1, ["z"] = 18, ["name"] = "default:stonebrick"}, {["x"] = 16, ["y"] = 1, ["z"] = 19, ["name"] = "default:stonebrick"}, {["x"] = 16, ["y"] = 1, ["z"] = 20, ["name"] = "default:stonebrick"}, {["x"] = 16, ["y"] = 1, ["z"] = 21, ["name"] = "default:stonebrick"}, {["x"] = 16, ["y"] = 1, ["param1"] = 223, ["z"] = 26, ["name"] = "default:fence_wood"}, {["x"] = 16, ["y"] = 1, ["param1"] = 95, ["z"] = 41, ["name"] = "default:fence_wood"}, {["x"] = 16, ["param2"] = 1, ["y"] = 2, ["param1"] = 14, ["z"] = 0, ["name"] = "default:aspen_leaves"}, {["x"] = 16, ["y"] = 2, ["param1"] = 239, ["z"] = 26, ["name"] = "default:mese_post_light"}, {["x"] = 16, ["param2"] = 1, ["y"] = 3, ["param1"] = 14, ["z"] = 0, ["name"] = "default:aspen_leaves"}, {["x"] = 16, ["param2"] = 23, ["y"] = 5, ["param1"] = 14, ["z"] = 4, ["name"] = "stairs:slab_silver_sandstone"}, {["x"] = 16, ["param2"] = 21, ["y"] = 5, ["param1"] = 126, ["z"] = 22, ["name"] = "stairs:slab_silver_sandstone"}, {["x"] = 17, ["y"] = 0, ["z"] = 0, ["name"] = "default:dirt_with_grass"}, {["x"] = 17, ["y"] = 0, ["z"] = 1, ["name"] = "default:dirt_with_grass"}, {["x"] = 17, ["y"] = 0, ["z"] = 2, ["name"] = "default:dirt_with_grass"}, {["x"] = 17, ["y"] = 0, ["z"] = 3, ["name"] = "default:dirt_with_grass"}, {["x"] = 17, ["y"] = 0, ["z"] = 4, ["name"] = "default:dirt_with_grass"}, {["x"] = 17, ["y"] = 0, ["z"] = 5, ["name"] = "default:dirt_with_grass"}, {["x"] = 17, ["y"] = 0, ["z"] = 6, ["name"] = "default:dirt_with_grass"}, {["x"] = 17, ["y"] = 0, ["z"] = 7, ["name"] = "default:dirt_with_grass"}, {["x"] = 17, ["y"] = 0, ["z"] = 8, ["name"] = "default:dirt_with_grass"}, {["x"] = 17, ["y"] = 0, ["z"] = 9, ["name"] = "default:dirt_with_grass"}, {["x"] = 17, ["y"] = 0, ["z"] = 10, ["name"] = "default:dirt_with_grass"}, {["x"] = 17, ["y"] = 0, ["z"] = 11, ["name"] = "default:dirt_with_grass"}, {["x"] = 17, ["y"] = 0, ["z"] = 12, ["name"] = "default:dirt_with_grass"}, {["x"] = 17, ["y"] = 0, ["z"] = 13, ["name"] = "default:dirt_with_grass"}, {["x"] = 17, ["y"] = 0, ["z"] = 14, ["name"] = "default:dirt_with_grass"}, {["x"] = 17, ["y"] = 0, ["z"] = 15, ["name"] = "default:dirt_with_grass"}, {["x"] = 17, ["y"] = 0, ["z"] = 16, ["name"] = "default:dirt_with_grass"}, {["x"] = 17, ["y"] = 0, ["z"] = 17, ["name"] = "default:dirt_with_grass"}, {["x"] = 17, ["y"] = 0, ["z"] = 18, ["name"] = "default:dirt_with_grass"}, {["x"] = 17, ["y"] = 0, ["z"] = 19, ["name"] = "default:dirt_with_grass"}, {["x"] = 17, ["y"] = 0, ["z"] = 20, ["name"] = "default:dirt_with_grass"}, {["x"] = 17, ["y"] = 0, ["z"] = 21, ["name"] = "default:dirt_with_grass"}, {["x"] = 17, ["y"] = 0, ["z"] = 22, ["name"] = "default:dirt_with_grass"}, {["x"] = 17, ["y"] = 0, ["z"] = 23, ["name"] = "default:dirt_with_grass"}, {["x"] = 17, ["y"] = 0, ["z"] = 24, ["name"] = "default:dirt_with_grass"}, {["x"] = 17, ["y"] = 0, ["z"] = 25, ["name"] = "default:dirt_with_grass"}, {["x"] = 17, ["y"] = 0, ["z"] = 26, ["name"] = "default:dirt_with_grass"}, {["x"] = 17, ["y"] = 0, ["z"] = 27, ["name"] = "the_build_spawner:white"}, {["x"] = 17, ["y"] = 0, ["z"] = 28, ["name"] = "the_build_spawner:black"}, {["x"] = 17, ["y"] = 0, ["z"] = 29, ["name"] = "the_build_spawner:black"}, {["x"] = 17, ["y"] = 0, ["z"] = 30, ["name"] = "the_build_spawner:black"}, {["x"] = 17, ["y"] = 0, ["z"] = 31, ["name"] = "the_build_spawner:black"}, {["x"] = 17, ["y"] = 0, ["z"] = 32, ["name"] = "the_build_spawner:black"}, {["x"] = 17, ["y"] = 0, ["z"] = 33, ["name"] = "the_build_spawner:black"}, {["x"] = 17, ["y"] = 0, ["z"] = 34, ["name"] = "the_build_spawner:black"}, {["x"] = 17, ["y"] = 0, ["z"] = 35, ["name"] = "the_build_spawner:black"}, {["x"] = 17, ["y"] = 0, ["z"] = 36, ["name"] = "the_build_spawner:black"}, {["x"] = 17, ["y"] = 0, ["z"] = 37, ["name"] = "the_build_spawner:white"}, {["x"] = 17, ["y"] = 0, ["z"] = 38, ["name"] = "the_build_spawner:black"}, {["x"] = 17, ["y"] = 0, ["z"] = 39, ["name"] = "the_build_spawner:black"}, {["x"] = 17, ["y"] = 0, ["z"] = 40, ["name"] = "the_build_spawner:black"}, {["x"] = 17, ["y"] = 0, ["z"] = 41, ["name"] = "the_build_spawner:white"}, {["x"] = 17, ["y"] = 1, ["param1"] = 207, ["z"] = 26, ["name"] = "default:fence_wood"}, {["x"] = 17, ["y"] = 1, ["param1"] = 111, ["z"] = 41, ["name"] = "default:fence_wood"}, {["x"] = 17, ["param2"] = 23, ["y"] = 5, ["param1"] = 14, ["z"] = 4, ["name"] = "stairs:slab_silver_sandstone"}, {["x"] = 17, ["param2"] = 23, ["y"] = 5, ["param1"] = 13, ["z"] = 5, ["name"] = "stairs:slab_silver_sandstone"}, {["x"] = 17, ["param2"] = 23, ["y"] = 5, ["param1"] = 14, ["z"] = 6, ["name"] = "stairs:slab_silver_sandstone"}, {["x"] = 17, ["param2"] = 23, ["y"] = 5, ["param1"] = 14, ["z"] = 7, ["name"] = "stairs:slab_silver_sandstone"}, {["x"] = 17, ["param2"] = 23, ["y"] = 5, ["param1"] = 14, ["z"] = 8, ["name"] = "stairs:slab_silver_sandstone"}, {["x"] = 17, ["param2"] = 23, ["y"] = 5, ["param1"] = 14, ["z"] = 9, ["name"] = "stairs:slab_silver_sandstone"}, {["x"] = 17, ["param2"] = 23, ["y"] = 5, ["param1"] = 14, ["z"] = 10, ["name"] = "stairs:slab_silver_sandstone"}, {["x"] = 17, ["param2"] = 23, ["y"] = 5, ["param1"] = 14, ["z"] = 11, ["name"] = "stairs:slab_silver_sandstone"}, {["x"] = 17, ["param2"] = 23, ["y"] = 5, ["param1"] = 14, ["z"] = 12, ["name"] = "stairs:slab_silver_sandstone"}, {["x"] = 17, ["param2"] = 23, ["y"] = 5, ["param1"] = 14, ["z"] = 13, ["name"] = "stairs:slab_silver_sandstone"}, {["x"] = 17, ["param2"] = 23, ["y"] = 5, ["param1"] = 14, ["z"] = 14, ["name"] = "stairs:slab_silver_sandstone"}, {["x"] = 17, ["param2"] = 23, ["y"] = 5, ["param1"] = 14, ["z"] = 15, ["name"] = "stairs:slab_silver_sandstone"}, {["x"] = 17, ["param2"] = 23, ["y"] = 5, ["param1"] = 14, ["z"] = 16, ["name"] = "stairs:slab_silver_sandstone"}, {["x"] = 17, ["param2"] = 23, ["y"] = 5, ["param1"] = 30, ["z"] = 17, ["name"] = "stairs:slab_silver_sandstone"}, {["x"] = 17, ["param2"] = 23, ["y"] = 5, ["param1"] = 46, ["z"] = 18, ["name"] = "stairs:slab_silver_sandstone"}, {["x"] = 17, ["param2"] = 23, ["y"] = 5, ["param1"] = 62, ["z"] = 19, ["name"] = "stairs:slab_silver_sandstone"}, {["x"] = 17, ["param2"] = 23, ["y"] = 5, ["param1"] = 77, ["z"] = 20, ["name"] = "stairs:slab_silver_sandstone"}, {["x"] = 17, ["param2"] = 23, ["y"] = 5, ["param1"] = 93, ["z"] = 21, ["name"] = "stairs:slab_silver_sandstone"}, {["x"] = 17, ["param2"] = 23, ["y"] = 5, ["param1"] = 110, ["z"] = 22, ["name"] = "stairs:slab_silver_sandstone"}, {["x"] = 18, ["y"] = 0, ["z"] = 0, ["name"] = "default:dirt_with_grass"}, {["x"] = 18, ["y"] = 0, ["z"] = 1, ["name"] = "default:dirt_with_grass"}, {["x"] = 18, ["y"] = 0, ["z"] = 2, ["name"] = "default:dirt_with_grass"}, {["x"] = 18, ["y"] = 0, ["z"] = 3, ["name"] = "default:dirt_with_grass"}, {["x"] = 18, ["y"] = 0, ["z"] = 4, ["name"] = "default:dirt_with_grass"}, {["x"] = 18, ["y"] = 0, ["z"] = 5, ["name"] = "default:dirt_with_grass"}, {["x"] = 18, ["y"] = 0, ["z"] = 6, ["name"] = "default:dirt_with_grass"}, {["x"] = 18, ["y"] = 0, ["z"] = 7, ["name"] = "default:dirt_with_grass"}, {["x"] = 18, ["y"] = 0, ["z"] = 8, ["name"] = "default:dirt_with_grass"}, {["x"] = 18, ["y"] = 0, ["z"] = 9, ["name"] = "default:dirt_with_grass"}, {["x"] = 18, ["y"] = 0, ["z"] = 10, ["name"] = "default:dirt_with_grass"}, {["x"] = 18, ["y"] = 0, ["z"] = 11, ["name"] = "default:dirt_with_grass"}, {["x"] = 18, ["y"] = 0, ["z"] = 12, ["name"] = "default:dirt_with_grass"}, {["x"] = 18, ["y"] = 0, ["z"] = 13, ["name"] = "default:dirt_with_grass"}, {["x"] = 18, ["y"] = 0, ["z"] = 14, ["name"] = "default:dirt_with_grass"}, {["x"] = 18, ["y"] = 0, ["z"] = 15, ["name"] = "default:dirt_with_grass"}, {["x"] = 18, ["y"] = 0, ["z"] = 16, ["name"] = "default:dirt_with_grass"}, {["x"] = 18, ["y"] = 0, ["z"] = 17, ["name"] = "default:dirt_with_grass"}, {["x"] = 18, ["y"] = 0, ["z"] = 18, ["name"] = "default:dirt_with_grass"}, {["x"] = 18, ["y"] = 0, ["z"] = 19, ["name"] = "default:dirt_with_grass"}, {["x"] = 18, ["y"] = 0, ["z"] = 20, ["name"] = "default:dirt_with_grass"}, {["x"] = 18, ["y"] = 0, ["z"] = 21, ["name"] = "default:dirt_with_grass"}, {["x"] = 18, ["y"] = 0, ["z"] = 22, ["name"] = "default:dirt_with_grass"}, {["x"] = 18, ["y"] = 0, ["z"] = 23, ["name"] = "default:dirt_with_grass"}, {["x"] = 18, ["y"] = 0, ["z"] = 24, ["name"] = "default:dirt_with_grass"}, {["x"] = 18, ["y"] = 0, ["z"] = 25, ["name"] = "default:dirt_with_grass"}, {["x"] = 18, ["y"] = 0, ["z"] = 26, ["name"] = "default:dirt_with_grass"}, {["x"] = 18, ["y"] = 0, ["z"] = 27, ["name"] = "the_build_spawner:white"}, {["x"] = 18, ["y"] = 0, ["z"] = 28, ["name"] = "the_build_spawner:white"}, {["x"] = 18, ["y"] = 0, ["z"] = 29, ["name"] = "the_build_spawner:white"}, {["x"] = 18, ["y"] = 0, ["z"] = 30, ["name"] = "the_build_spawner:black"}, {["x"] = 18, ["y"] = 0, ["z"] = 31, ["name"] = "the_build_spawner:black"}, {["x"] = 18, ["y"] = 0, ["z"] = 32, ["name"] = "the_build_spawner:black"}, {["x"] = 18, ["y"] = 0, ["z"] = 33, ["name"] = "the_build_spawner:white"}, {["x"] = 18, ["y"] = 0, ["z"] = 34, ["name"] = "the_build_spawner:black"}, {["x"] = 18, ["y"] = 0, ["z"] = 35, ["name"] = "the_build_spawner:black"}, {["x"] = 18, ["y"] = 0, ["z"] = 36, ["name"] = "the_build_spawner:black"}, {["x"] = 18, ["y"] = 0, ["z"] = 37, ["name"] = "the_build_spawner:white"}, {["x"] = 18, ["y"] = 0, ["z"] = 38, ["name"] = "the_build_spawner:black"}, {["x"] = 18, ["y"] = 0, ["z"] = 39, ["name"] = "the_build_spawner:black"}, {["x"] = 18, ["y"] = 0, ["z"] = 40, ["name"] = "the_build_spawner:black"}, {["x"] = 18, ["y"] = 0, ["z"] = 41, ["name"] = "the_build_spawner:white"}, {["x"] = 18, ["y"] = 1, ["param1"] = 191, ["z"] = 26, ["name"] = "default:fence_wood"}, {["x"] = 18, ["y"] = 1, ["param1"] = 127, ["z"] = 41, ["name"] = "default:fence_wood"}, {["x"] = 19, ["y"] = 0, ["z"] = 0, ["name"] = "default:dirt_with_grass"}, {["x"] = 19, ["y"] = 0, ["z"] = 1, ["name"] = "default:dirt_with_grass"}, {["x"] = 19, ["y"] = 0, ["z"] = 2, ["name"] = "default:dirt_with_grass"}, {["x"] = 19, ["y"] = 0, ["z"] = 3, ["name"] = "default:dirt_with_grass"}, {["x"] = 19, ["y"] = 0, ["z"] = 4, ["name"] = "default:dirt_with_grass"}, {["x"] = 19, ["y"] = 0, ["z"] = 5, ["name"] = "default:dirt_with_grass"}, {["x"] = 19, ["y"] = 0, ["z"] = 6, ["name"] = "default:dirt_with_grass"}, {["x"] = 19, ["y"] = 0, ["z"] = 7, ["name"] = "default:dirt_with_grass"}, {["x"] = 19, ["y"] = 0, ["z"] = 8, ["name"] = "default:dirt_with_grass"}, {["x"] = 19, ["y"] = 0, ["z"] = 9, ["name"] = "default:dirt_with_grass"}, {["x"] = 19, ["y"] = 0, ["z"] = 10, ["name"] = "default:dirt_with_grass"}, {["x"] = 19, ["y"] = 0, ["z"] = 11, ["name"] = "default:dirt_with_grass"}, {["x"] = 19, ["y"] = 0, ["z"] = 12, ["name"] = "default:dirt_with_grass"}, {["x"] = 19, ["y"] = 0, ["z"] = 13, ["name"] = "default:dirt_with_grass"}, {["x"] = 19, ["y"] = 0, ["z"] = 14, ["name"] = "default:dirt_with_grass"}, {["x"] = 19, ["y"] = 0, ["z"] = 15, ["name"] = "default:dirt_with_grass"}, {["x"] = 19, ["y"] = 0, ["z"] = 16, ["name"] = "default:dirt_with_grass"}, {["x"] = 19, ["y"] = 0, ["z"] = 17, ["name"] = "default:dirt_with_grass"},