5:return {{["x"] = 0, ["y"] = 0, ["z"] = 0, ["name"] = "default:cobble"}, {["x"] = 0, ["y"] = 0, ["z"] = 1, ["name"] = "default:cobble"}, {["x"] = 0, ["y"] = 0, ["z"] = 2, ["name"] = "default:cobble"}, {["x"] = 0, ["y"] = 0, ["z"] = 3, ["name"] = "default:cobble"}, {["x"] = 0, ["y"] = 0, ["z"] = 4, ["name"] = "default:cobble"}, {["x"] = 0, ["y"] = 0, ["z"] = 5, ["name"] = "default:cobble"}, {["x"] = 0, ["y"] = 0, ["z"] = 6, ["name"] = "default:cobble"}, {["x"] = 0, ["y"] = 0, ["z"] = 7, ["name"] = "default:cobble"}, {["x"] = 0, ["y"] = 0, ["z"] = 8, ["name"] = "default:cobble"}, {["x"] = 0, ["y"] = 0, ["z"] = 9, ["name"] = "default:cobble"}, {["x"] = 0, ["y"] = 0, ["z"] = 10, ["name"] = "default:cobble"}, {["x"] = 0, ["y"] = 0, ["param1"] = 3, ["z"] = 11, ["name"] = "default:cobble"}, {["x"] = 0, ["y"] = 0, ["param1"] = 3, ["z"] = 12, ["name"] = "default:cobble"}, {["x"] = 0, ["y"] = 0, ["param1"] = 3, ["z"] = 13, ["name"] = "default:cobble"}, {["x"] = 0, ["y"] = 0, ["param1"] = 3, ["z"] = 14, ["name"] = "default:cobble"}, {["x"] = 0, ["y"] = 0, ["param1"] = 3, ["z"] = 15, ["name"] = "default:cobble"}, {["x"] = 0, ["y"] = 0, ["param1"] = 3, ["z"] = 16, ["name"] = "default:cobble"}, {["x"] = 0, ["y"] = 0, ["param1"] = 3, ["z"] = 17, ["name"] = "default:cobble"}, {["x"] = 0, ["y"] = 0, ["param1"] = 3, ["z"] = 18, ["name"] = "default:cobble"}, {["x"] = 0, ["y"] = 0, ["param1"] = 3, ["z"] = 19, ["name"] = "default:cobble"}, {["x"] = 0, ["y"] = 0, ["param1"] = 3, ["z"] = 20, ["name"] = "default:cobble"}, {["x"] = 0, ["y"] = 0, ["param1"] = 3, ["z"] = 21, ["name"] = "default:cobble"}, {["x"] = 0, ["y"] = 0, ["param1"] = 3, ["z"] = 22, ["name"] = "default:cobble"}, {["x"] = 0, ["y"] = 0, ["param1"] = 3, ["z"] = 23, ["name"] = "default:cobble"}, {["x"] = 1, ["y"] = 0, ["z"] = 0, ["name"] = "default:cobble"}, {["x"] = 1, ["y"] = 0, ["z"] = 1, ["name"] = "default:cobble"}, {["x"] = 1, ["y"] = 0, ["z"] = 2, ["name"] = "default:cobble"}, {["x"] = 1, ["y"] = 0, ["z"] = 3, ["name"] = "default:cobble"}, {["x"] = 1, ["y"] = 0, ["z"] = 4, ["name"] = "default:cobble"}, {["x"] = 1, ["y"] = 0, ["z"] = 5, ["name"] = "default:cobble"}, {["x"] = 1, ["y"] = 0, ["z"] = 6, ["name"] = "default:cobble"}, {["x"] = 1, ["y"] = 0, ["z"] = 7, ["name"] = "default:cobble"}, {["x"] = 1, ["y"] = 0, ["z"] = 8, ["name"] = "default:cobble"}, {["x"] = 1, ["y"] = 0, ["z"] = 9, ["name"] = "default:cobble"}, {["x"] = 1, ["y"] = 0, ["z"] = 10, ["name"] = "default:cobble"}, {["x"] = 1, ["y"] = 0, ["param1"] = 3, ["z"] = 11, ["name"] = "default:cobble"}, {["x"] = 1, ["y"] = 0, ["param1"] = 3, ["z"] = 12, ["name"] = "default:cobble"}, {["x"] = 1, ["y"] = 0, ["param1"] = 3, ["z"] = 13, ["name"] = "default:cobble"}, {["x"] = 1, ["y"] = 0, ["param1"] = 3, ["z"] = 14, ["name"] = "default:cobble"}, {["x"] = 1, ["y"] = 0, ["param1"] = 3, ["z"] = 15, ["name"] = "default:cobble"}, {["x"] = 1, ["y"] = 0, ["param1"] = 3, ["z"] = 16, ["name"] = "default:cobble"}, {["x"] = 1, ["y"] = 0, ["param1"] = 3, ["z"] = 17, ["name"] = "default:cobble"}, {["x"] = 1, ["y"] = 0, ["param1"] = 3, ["z"] = 18, ["name"] = "default:cobble"}, {["x"] = 1, ["y"] = 0, ["param1"] = 3, ["z"] = 19, ["name"] = "default:cobble"}, {["x"] = 1, ["y"] = 0, ["param1"] = 3, ["z"] = 20, ["name"] = "default:cobble"}, {["x"] = 1, ["y"] = 0, ["param1"] = 3, ["z"] = 21, ["name"] = "default:cobble"}, {["x"] = 1, ["y"] = 0, ["param1"] = 3, ["z"] = 22, ["name"] = "default:cobble"}, {["x"] = 1, ["y"] = 0, ["param1"] = 3, ["z"] = 23, ["name"] = "default:cobble"}, {["x"] = 1, ["y"] = 4, ["param1"] = 134, ["z"] = 13, ["name"] = "wool:white"}, {["x"] = 1, ["y"] = 4, ["param1"] = 134, ["z"] = 14, ["name"] = "wool:white"}, {["x"] = 1, ["y"] = 4, ["param1"] = 134, ["z"] = 15, ["name"] = "wool:white"}, {["x"] = 1, ["y"] = 4, ["param1"] = 134, ["z"] = 16, ["name"] = "wool:white"}, {["x"] = 1, ["y"] = 4, ["param1"] = 134, ["z"] = 17, ["name"] = "wool:white"}, {["x"] = 2, ["y"] = 0, ["z"] = 0, ["name"] = "default:cobble"}, {["x"] = 2, ["y"] = 0, ["z"] = 1, ["name"] = "default:cobble"}, {["x"] = 2, ["y"] = 0, ["z"] = 2, ["name"] = "default:cobble"}, {["x"] = 2, ["y"] = 0, ["z"] = 3, ["name"] = "default:cobble"}, {["x"] = 2, ["y"] = 0, ["z"] = 4, ["name"] = "default:cobble"}, {["x"] = 2, ["y"] = 0, ["z"] = 5, ["name"] = "default:cobble"}, {["x"] = 2, ["y"] = 0, ["z"] = 6, ["name"] = "default:cobble"}, {["x"] = 2, ["y"] = 0, ["z"] = 7, ["name"] = "default:cobble"}, {["x"] = 2, ["y"] = 0, ["z"] = 8, ["name"] = "default:cobble"}, {["x"] = 2, ["y"] = 0, ["z"] = 9, ["name"] = "default:cobble"}, {["x"] = 2, ["y"] = 0, ["z"] = 10, ["name"] = "default:cobble"}, {["x"] = 2, ["y"] = 0, ["param1"] = 3, ["z"] = 11, ["name"] = "default:cobble"}, {["x"] = 2, ["y"] = 0, ["param1"] = 3, ["z"] = 12, ["name"] = "default:cobble"}, {["x"] = 2, ["y"] = 0, ["param1"] = 3, ["z"] = 13, ["name"] = "default:cobble"}, {["x"] = 2, ["y"] = 0, ["param1"] = 3, ["z"] = 14, ["name"] = "default:cobble"}, {["x"] = 2, ["y"] = 0, ["param1"] = 3, ["z"] = 15, ["name"] = "default:cobble"}, {["x"] = 2, ["y"] = 0, ["param1"] = 3, ["z"] = 16, ["name"] = "default:cobble"}, {["x"] = 2, ["y"] = 0, ["param1"] = 3, ["z"] = 17, ["name"] = "default:cobble"}, {["x"] = 2, ["y"] = 0, ["param1"] = 3, ["z"] = 18, ["name"] = "default:cobble"}, {["x"] = 2, ["y"] = 0, ["param1"] = 3, ["z"] = 19, ["name"] = "default:cobble"}, {["x"] = 2, ["y"] = 0, ["param1"] = 3, ["z"] = 20, ["name"] = "default:cobble"}, {["x"] = 2, ["y"] = 0, ["param1"] = 3, ["z"] = 21, ["name"] = "default:cobble"}, {["x"] = 2, ["y"] = 0, ["param1"] = 3, ["z"] = 22, ["name"] = "default:cobble"}, {["x"] = 2, ["y"] = 0, ["param1"] = 3, ["z"] = 23, ["name"] = "default:cobble"}, {["x"] = 2, ["y"] = 4, ["param1"] = 134, ["z"] = 13, ["name"] = "wool:white"}, {["x"] = 2, ["y"] = 4, ["param1"] = 134, ["z"] = 14, ["name"] = "wool:white"}, {["x"] = 2, ["y"] = 4, ["param1"] = 134, ["z"] = 15, ["name"] = "wool:white"}, {["x"] = 2, ["y"] = 4, ["param1"] = 134, ["z"] = 16, ["name"] = "wool:white"}, {["x"] = 2, ["y"] = 4, ["param1"] = 134, ["z"] = 17, ["name"] = "wool:white"}, {["x"] = 3, ["y"] = 0, ["z"] = 0, ["name"] = "default:cobble"}, {["x"] = 3, ["y"] = 0, ["z"] = 1, ["name"] = "default:dirt"}, {["x"] = 3, ["y"] = 0, ["z"] = 2, ["name"] = "default:dirt_with_snow"}, {["x"] = 3, ["y"] = 0, ["z"] = 3, ["name"] = "default:dirt_with_snow"}, {["x"] = 3, ["y"] = 0, ["z"] = 4, ["name"] = "default:dirt_with_snow"}, {["x"] = 3, ["y"] = 0, ["z"] = 5, ["name"] = "default:dirt_with_snow"}, {["x"] = 3, ["y"] = 0, ["z"] = 6, ["name"] = "default:dirt_with_snow"}, {["x"] = 3, ["y"] = 0, ["z"] = 7, ["name"] = "default:dirt_with_snow"}, {["x"] = 3, ["y"] = 0, ["z"] = 8, ["name"] = "default:dirt_with_snow"}, {["x"] = 3, ["y"] = 0, ["z"] = 9, ["name"] = "default:dirt_with_snow"}, {["x"] = 3, ["y"] = 0, ["z"] = 10, ["name"] = "default:dirt_with_snow"}, {["x"] = 3, ["y"] = 0, ["param1"] = 27, ["z"] = 11, ["name"] = "default:dirt_with_snow"}, {["x"] = 3, ["y"] = 0, ["param1"] = 27, ["z"] = 12, ["name"] = "default:dirt_with_snow"}, {["x"] = 3, ["y"] = 0, ["param1"] = 23, ["z"] = 13, ["name"] = "default:dirt"}, {["x"] = 3, ["y"] = 0, ["param1"] = 195, ["z"] = 14, ["name"] = "the_build_spawner:white"}, {["x"] = 3, ["y"] = 0, ["param1"] = 195, ["z"] = 15, ["name"] = "the_build_spawner:white"}, {["x"] = 3, ["y"] = 0, ["param1"] = 195, ["z"] = 16, ["name"] = "the_build_spawner:white"}, {["x"] = 3, ["y"] = 0, ["param1"] = 195, ["z"] = 17, ["name"] = "the_build_spawner:white"}, {["x"] = 3, ["y"] = 0, ["z"] = 18, ["name"] = "the_build_spawner:white"}, {["x"] = 3, ["y"] = 0, ["z"] = 19, ["name"] = "the_build_spawner:white"}, {["x"] = 3, ["y"] = 0, ["z"] = 20, ["name"] = "the_build_spawner:white"}, {["x"] = 3, ["y"] = 0, ["z"] = 21, ["name"] = "the_build_spawner:white"}, {["x"] = 3, ["y"] = 0, ["z"] = 22, ["name"] = "the_build_spawner:white"}, {["x"] = 3, ["y"] = 0, ["param1"] = 3, ["z"] = 23, ["name"] = "default:cobble"}, {["x"] = 3, ["y"] = 1, ["z"] = 1, ["name"] = "the_build_spawner:dark_blue"}, {["x"] = 3, ["param2"] = 1, ["y"] = 1, ["param1"] = 78, ["z"] = 2, ["name"] = "default:aspen_leaves"}, {["x"] = 3, ["param2"] = 1, ["y"] = 1, ["param1"] = 94, ["z"] = 3, ["name"] = "default:aspen_leaves"}, {["x"] = 3, ["param2"] = 1, ["y"] = 1, ["param1"] = 110, ["z"] = 4, ["name"] = "default:aspen_leaves"}, {["x"] = 3, ["param2"] = 1, ["y"] = 1, ["param1"] = 126, ["z"] = 5, ["name"] = "default:aspen_leaves"}, {["x"] = 3, ["param2"] = 1, ["y"] = 1, ["param1"] = 142, ["z"] = 6, ["name"] = "default:aspen_leaves"}, {["x"] = 3, ["param2"] = 1, ["y"] = 1, ["param1"] = 126, ["z"] = 7, ["name"] = "default:aspen_leaves"}, {["x"] = 3, ["param2"] = 1, ["y"] = 1, ["param1"] = 110, ["z"] = 8, ["name"] = "default:aspen_leaves"}, {["x"] = 3, ["param2"] = 1, ["y"] = 1, ["param1"] = 94, ["z"] = 9, ["name"] = "default:aspen_leaves"}, {["x"] = 3, ["param2"] = 1, ["y"] = 1, ["param1"] = 94, ["z"] = 10, ["name"] = "default:aspen_leaves"}, {["x"] = 3, ["param2"] = 1, ["y"] = 1, ["param1"] = 110, ["z"] = 11, ["name"] = "default:aspen_leaves"}, {["x"] = 3, ["param2"] = 1, ["y"] = 1, ["param1"] = 126, ["z"] = 12, ["name"] = "default:aspen_leaves"}, {["x"] = 3, ["y"] = 1, ["param1"] = 198, ["z"] = 13, ["name"] = "the_build_spawner:dark_blue"}, {["x"] = 3, ["y"] = 1, ["param1"] = 172, ["z"] = 14, ["name"] = "default:glass"}, {["x"] = 3, ["meta"] = {["fields"] = {["state"] = "0"}, ["inventory"] = {}}, ["param2"] = 3, ["y"] = 1, ["param1"] = 156, ["z"] = 15, ["name"] = "doors:door_wood_a"}, {["x"] = 3, ["y"] = 1, ["param1"] = 172, ["z"] = 16, ["name"] = "default:glass"}, {["x"] = 3, ["y"] = 1, ["param1"] = 198, ["z"] = 17, ["name"] = "the_build_spawner:dark_blue"}, {["x"] = 3, ["y"] = 2, ["z"] = 1, ["name"] = "the_build_spawner:dark_blue"}, {["x"] = 3, ["y"] = 2, ["param1"] = 198, ["z"] = 13, ["name"] = "the_build_spawner:dark_blue"}, {["x"] = 3, ["y"] = 2, ["param1"] = 188, ["z"] = 14, ["name"] = "default:glass"}, {["x"] = 3, ["param2"] = 3, ["y"] = 2, ["param1"] = 172, ["z"] = 15, ["name"] = "doors:hidden"}, {["x"] = 3, ["y"] = 2, ["param1"] = 188, ["z"] = 16, ["name"] = "default:glass"}, {["x"] = 3, ["y"] = 2, ["param1"] = 198, ["z"] = 17, ["name"] = "the_build_spawner:dark_blue"}, {["x"] = 3, ["y"] = 3, ["z"] = 1, ["name"] = "the_build_spawner:dark_blue"}, {["x"] = 3, ["y"] = 3, ["param1"] = 198, ["z"] = 13, ["name"] = "the_build_spawner:dark_blue"}, {["x"] = 3, ["y"] = 3, ["param1"] = 204, ["z"] = 14, ["name"] = "default:glass"}, {["x"] = 3, ["y"] = 3, ["param1"] = 188, ["z"] = 15, ["name"] = "default:glass"}, {["x"] = 3, ["y"] = 3, ["param1"] = 204, ["z"] = 16, ["name"] = "default:glass"}, {["x"] = 3, ["y"] = 3, ["param1"] = 198, ["z"] = 17, ["name"] = "the_build_spawner:dark_blue"}, {["x"] = 3, ["y"] = 4, ["z"] = 1, ["name"] = "the_build_spawner:dark_blue"}, {["x"] = 3, ["y"] = 4, ["param1"] = 198, ["z"] = 13, ["name"] = "the_build_spawner:dark_blue"}, {["x"] = 3, ["y"] = 4, ["param1"] = 198, ["z"] = 14, ["name"] = "the_build_spawner:dark_blue"}, {["x"] = 3, ["y"] = 4, ["param1"] = 198, ["z"] = 15, ["name"] = "the_build_spawner:dark_blue"}, {["x"] = 3, ["y"] = 4, ["param1"] = 198, ["z"] = 16, ["name"] = "the_build_spawner:dark_blue"}, {["x"] = 3, ["y"] = 4, ["param1"] = 198, ["z"] = 17, ["name"] = "the_build_spawner:dark_blue"}, {["x"] = 3, ["y"] = 5, ["z"] = 1, ["name"] = "the_build_spawner:dark_blue"}, {["x"] = 3, ["y"] = 5, ["z"] = 2, ["name"] = "the_build_spawner:dark_blue"}, {["x"] = 3, ["y"] = 5, ["z"] = 3, ["name"] = "the_build_spawner:dark_blue"}, {["x"] = 3, ["y"] = 5, ["z"] = 4, ["name"] = "the_build_spawner:dark_blue"}, {["x"] = 3, ["y"] = 5, ["z"] = 5, ["name"] = "the_build_spawner:dark_blue"}, {["x"] = 3, ["y"] = 5, ["z"] = 6, ["name"] = "the_build_spawner:dark_blue"}, {["x"] = 3, ["y"] = 5, ["z"] = 7, ["name"] = "the_build_spawner:dark_blue"}, {["x"] = 3, ["y"] = 5, ["z"] = 8, ["name"] = "the_build_spawner:dark_blue"}, {["x"] = 3, ["y"] = 5, ["z"] = 9, ["name"] = "the_build_spawner:dark_blue"}, {["x"] = 3, ["y"] = 5, ["z"] = 10, ["name"] = "the_build_spawner:dark_blue"}, {["x"] = 3, ["y"] = 5, ["param1"] = 198, ["z"] = 11, ["name"] = "the_build_spawner:dark_blue"}, {["x"] = 3, ["y"] = 5, ["param1"] = 198, ["z"] = 12, ["name"] = "the_build_spawner:dark_blue"}, {["x"] = 3, ["y"] = 5, ["param1"] = 198, ["z"] = 13, ["name"] = "the_build_spawner:dark_blue"}, {["x"] = 3, ["y"] = 5, ["param1"] = 198, ["z"] = 14, ["name"] = "the_build_spawner:dark_blue"}, {["x"] = 3, ["y"] = 5, ["param1"] = 198, ["z"] = 15, ["name"] = "the_build_spawner:dark_blue"}, {["x"] = 3, ["y"] = 5, ["param1"] = 198, ["z"] = 16, ["name"] = "the_build_spawner:dark_blue"}, {["x"] = 3, ["y"] = 5, ["param1"] = 198, ["z"] = 17, ["name"] = "the_build_spawner:dark_blue"}, {["x"] = 3, ["y"] = 6, ["z"] = 1, ["name"] = "the_build_spawner:white"}, {["x"] = 3, ["y"] = 6, ["z"] = 2, ["name"] = "the_build_spawner:white"}, {["x"] = 3, ["y"] = 6, ["z"] = 3, ["name"] = "the_build_spawner:white"}, {["x"] = 3, ["y"] = 6, ["z"] = 4, ["name"] = "the_build_spawner:white"}, {["x"] = 3, ["y"] = 6, ["z"] = 5, ["name"] = "the_build_spawner:white"}, {["x"] = 3, ["y"] = 6, ["z"] = 6, ["name"] = "the_build_spawner:white"}, {["x"] = 3, ["y"] = 6, ["z"] = 7, ["name"] = "the_build_spawner:white"}, {["x"] = 3, ["y"] = 6, ["z"] = 8, ["name"] = "the_build_spawner:white"}, {["x"] = 3, ["y"] = 6, ["z"] = 9, ["name"] = "the_build_spawner:white"}, {["x"] = 3, ["y"] = 6, ["z"] = 10, ["name"] = "the_build_spawner:white"}, {["x"] = 3, ["y"] = 6, ["param1"] = 195, ["z"] = 11, ["name"] = "the_build_spawner:white"}, {["x"] = 3, ["y"] = 6, ["param1"] = 195, ["z"] = 12, ["name"] = "the_build_spawner:white"}, {["x"] = 3, ["y"] = 6, ["param1"] = 195, ["z"] = 13, ["name"] = "the_build_spawner:white"}, {["x"] = 3, ["y"] = 6, ["param1"] = 195, ["z"] = 14, ["name"] = "the_build_spawner:white"}, {["x"] = 3, ["y"] = 6, ["param1"] = 195, ["z"] = 15, ["name"] = "the_build_spawner:white"}, {["x"] = 3, ["y"] = 6, ["param1"] = 195, ["z"] = 16, ["name"] = "the_build_spawner:white"}, {["x"] = 3, ["y"] = 6, ["param1"] = 195, ["z"] = 17, ["name"] = "the_build_spawner:white"}, {["x"] = 3, ["y"] = 7, ["z"] = 1, ["name"] = "the_build_spawner:white"}, {["x"] = 3, ["y"] = 7, ["z"] = 2, ["name"] = "the_build_spawner:white"}, {["x"] = 3, ["y"] = 7, ["z"] = 3, ["name"] = "the_build_spawner:white"}, {["x"] = 3, ["y"] = 7, ["z"] = 4, ["name"] = "the_build_spawner:white"}, {["x"] = 3, ["y"] = 7, ["z"] = 5, ["name"] = "the_build_spawner:white"}, {["x"] = 3, ["y"] = 7, ["z"] = 6, ["name"] = "the_build_spawner:white"}, {["x"] = 3, ["y"] = 7, ["z"] = 7, ["name"] = "the_build_spawner:white"}, {["x"] = 3, ["y"] = 7, ["z"] = 8, ["name"] = "the_build_spawner:white"}, {["x"] = 3, ["y"] = 7, ["z"] = 9, ["name"] = "the_build_spawner:white"}, {["x"] = 3, ["y"] = 7, ["z"] = 10, ["name"] = "the_build_spawner:white"}, {["x"] = 3, ["y"] = 7, ["param1"] = 195, ["z"] = 11, ["name"] = "the_build_spawner:white"}, {["x"] = 3, ["y"] = 7, ["param1"] = 195, ["z"] = 12, ["name"] = "the_build_spawner:white"}, {["x"] = 3, ["y"] = 7, ["param1"] = 195, ["z"] = 13, ["name"] = "the_build_spawner:white"}, {["x"] = 3, ["y"] = 7, ["param1"] = 195, ["z"] = 14, ["name"] = "the_build_spawner:white"}, {["x"] = 3, ["y"] = 7, ["param1"] = 195, ["z"] = 15, ["name"] = "the_build_spawner:white"}, {["x"] = 3, ["y"] = 7, ["param1"] = 195, ["z"] = 16, ["name"] = "the_build_spawner:white"}, {["x"] = 3, ["y"] = 7, ["param1"] = 195, ["z"] = 17, ["name"] = "the_build_spawner:white"}, {["x"] = 4, ["y"] = 0, ["z"] = 0, ["name"] = "default:cobble"}, {["x"] = 4, ["y"] = 0, ["z"] = 1, ["name"] = "the_build_spawner:white"}, {["x"] = 4, ["y"] = 0, ["z"] = 2, ["name"] = "the_build_spawner:white"}, {["x"] = 4, ["y"] = 0, ["z"] = 3, ["name"] = "the_build_spawner:white"}, {["x"] = 4, ["y"] = 0, ["z"] = 4, ["name"] = "the_build_spawner:white"}, {["x"] = 4, ["y"] = 0, ["z"] = 5, ["name"] = "the_build_spawner:white"}, {["x"] = 4, ["y"] = 0, ["z"] = 6, ["name"] = "the_build_spawner:white"}, {["x"] = 4, ["y"] = 0, ["z"] = 7, ["name"] = "the_build_spawner:white"}, {["x"] = 4, ["y"] = 0, ["z"] = 8, ["name"] = "the_build_spawner:white"}, {["x"] = 4, ["y"] = 0, ["z"] = 9, ["name"] = "the_build_spawner:white"}, {["x"] = 4, ["y"] = 0, ["z"] = 10, ["name"] = "the_build_spawner:white"}, {["x"] = 4, ["y"] = 0, ["param1"] = 195, ["z"] = 11, ["name"] = "the_build_spawner:white"}, {["x"] = 4, ["y"] = 0, ["param1"] = 195, ["z"] = 12, ["name"] = "the_build_spawner:white"}, {["x"] = 4, ["y"] = 0, ["param1"] = 195, ["z"] = 13, ["name"] = "the_build_spawner:white"}, {["x"] = 4, ["y"] = 0, ["param1"] = 195, ["z"] = 14, ["name"] = "the_build_spawner:white"}, {["x"] = 4, ["y"] = 0, ["param1"] = 183, ["z"] = 15, ["name"] = "the_build_spawner:black"}, {["x"] = 4, ["y"] = 0, ["param1"] = 195, ["z"] = 16, ["name"] = "the_build_spawner:white"}, {["x"] = 4, ["y"] = 0, ["param1"] = 195, ["z"] = 17, ["name"] = "the_build_spawner:white"}, {["x"] = 4, ["y"] = 0, ["z"] = 18, ["name"] = "the_build_spawner:black"}, {["x"] = 4, ["y"] = 0, ["param1"] = 183, ["z"] = 19, ["name"] = "the_build_spawner:black"}, {["x"] = 4, ["y"] = 0, ["param1"] = 183, ["z"] = 20, ["name"] = "the_build_spawner:black"}, {["x"] = 4, ["y"] = 0, ["param1"] = 183, ["z"] = 21, ["name"] = "the_build_spawner:black"}, {["x"] = 4, ["y"] = 0, ["param1"] = 183, ["z"] = 22, ["name"] = "the_build_spawner:black"}, {["x"] = 4, ["y"] = 0, ["param1"] = 3, ["z"] = 23, ["name"] = "default:cobble"}, {["x"] = 4, ["y"] = 1, ["z"] = 1, ["name"] = "the_build_spawner:white"}, {["x"] = 4, ["param2"] = 3, ["y"] = 1, ["param1"] = 93, ["z"] = 2, ["name"] = "xpanes:pane_flat"}, {["x"] = 4, ["param2"] = 3, ["y"] = 1, ["param1"] = 109, ["z"] = 3, ["name"] = "xpanes:pane_flat"}, {["x"] = 4, ["param2"] = 3, ["y"] = 1, ["param1"] = 125, ["z"] = 4, ["name"] = "xpanes:pane_flat"}, {["x"] = 4, ["param2"] = 3, ["y"] = 1, ["param1"] = 141, ["z"] = 5, ["name"] = "xpanes:pane_flat"}, {["x"] = 4, ["param2"] = 3, ["y"] = 1, ["param1"] = 157, ["z"] = 6, ["name"] = "xpanes:pane_flat"}, {["x"] = 4, ["y"] = 1, ["z"] = 7, ["name"] = "the_build_spawner:white"}, {["x"] = 4, ["param2"] = 3, ["y"] = 1, ["param1"] = 125, ["z"] = 8, ["name"] = "xpanes:pane_flat"}, {["x"] = 4, ["param2"] = 3, ["y"] = 1, ["param1"] = 109, ["z"] = 9, ["name"] = "xpanes:pane_flat"}, {["x"] = 4, ["param2"] = 3, ["y"] = 1, ["param1"] = 109, ["z"] = 10, ["name"] = "xpanes:pane_flat"}, {["x"] = 4, ["param2"] = 3, ["y"] = 1, ["param1"] = 125, ["z"] = 11, ["name"] = "xpanes:pane_flat"}, {["x"] = 4, ["param2"] = 3, ["y"] = 1, ["param1"] = 141, ["z"] = 12, ["name"] = "xpanes:pane_flat"}, {["x"] = 4, ["y"] = 1, ["param1"] = 195, ["z"] = 13, ["name"] = "the_build_spawner:white"}, {["x"] = 4, ["y"] = 1, ["param1"] = 195, ["z"] = 17, ["name"] = "the_build_spawner:white"}, {["x"] = 4, ["y"] = 2, ["z"] = 1, ["name"] = "the_build_spawner:white"}, {["x"] = 4, ["param2"] = 3, ["y"] = 2, ["param1"] = 109, ["z"] = 2, ["name"] = "xpanes:pane_flat"}, {["x"] = 4, ["param2"] = 3, ["y"] = 2, ["param1"] = 125, ["z"] = 3, ["name"] = "xpanes:pane_flat"}, {["x"] = 4, ["param2"] = 3, ["y"] = 2, ["param1"] = 141, ["z"] = 4, ["name"] = "xpanes:pane_flat"}, {["x"] = 4, ["param2"] = 3, ["y"] = 2, ["param1"] = 157, ["z"] = 5, ["name"] = "xpanes:pane_flat"}, {["x"] = 4, ["param2"] = 3, ["y"] = 2, ["param1"] = 173, ["z"] = 6, ["name"] = "xpanes:pane_flat"}, {["x"] = 4, ["y"] = 2, ["z"] = 7, ["name"] = "the_build_spawner:white"}, {["x"] = 4, ["param2"] = 3, ["y"] = 2, ["param1"] = 141, ["z"] = 8, ["name"] = "xpanes:pane_flat"}, {["x"] = 4, ["param2"] = 3, ["y"] = 2, ["param1"] = 125, ["z"] = 9, ["name"] = "xpanes:pane_flat"}, {["x"] = 4, ["param2"] = 3, ["y"] = 2, ["param1"] = 125, ["z"] = 10, ["name"] = "xpanes:pane_flat"}, {["x"] = 4, ["param2"] = 3, ["y"] = 2, ["param1"] = 141, ["z"] = 11, ["name"] = "xpanes:pane_flat"}, {["x"] = 4, ["param2"] = 3, ["y"] = 2, ["param1"] = 157, ["z"] = 12, ["name"] = "xpanes:pane_flat"}, {["x"] = 4, ["y"] = 2, ["param1"] = 195, ["z"] = 13, ["name"] = "the_build_spawner:white"}, {["x"] = 4, ["y"] = 2, ["param1"] = 195, ["z"] = 17, ["name"] = "the_build_spawner:white"}, {["x"] = 4, ["y"] = 3, ["z"] = 1, ["name"] = "the_build_spawner:white"}, {["x"] = 4, ["param2"] = 3, ["y"] = 3, ["param1"] = 125, ["z"] = 2, ["name"] = "xpanes:pane_flat"}, {["x"] = 4, ["param2"] = 3, ["y"] = 3, ["param1"] = 141, ["z"] = 3, ["name"] = "xpanes:pane_flat"}, {["x"] = 4, ["param2"] = 3, ["y"] = 3, ["param1"] = 157, ["z"] = 4, ["name"] = "xpanes:pane_flat"}, {["x"] = 4, ["param2"] = 3, ["y"] = 3, ["param1"] = 173, ["z"] = 5, ["name"] = "xpanes:pane_flat"}, {["x"] = 4, ["param2"] = 3, ["y"] = 3, ["param1"] = 189, ["z"] = 6, ["name"] = "xpanes:pane_flat"}, {["x"] = 4, ["y"] = 3, ["z"] = 7, ["name"] = "the_build_spawner:white"}, {["x"] = 4, ["param2"] = 3, ["y"] = 3, ["param1"] = 157, ["z"] = 8, ["name"] = "xpanes:pane_flat"}, {["x"] = 4, ["param2"] = 3, ["y"] = 3, ["param1"] = 141, ["z"] = 9, ["name"] = "xpanes:pane_flat"}, {["x"] = 4, ["param2"] = 3, ["y"] = 3, ["param1"] = 141, ["z"] = 10, ["name"] = "xpanes:pane_flat"}, {["x"] = 4, ["param2"] = 3, ["y"] = 3, ["param1"] = 157, ["z"] = 11, ["name"] = "xpanes:pane_flat"}, {["x"] = 4, ["param2"] = 3, ["y"] = 3, ["param1"] = 173, ["z"] = 12, ["name"] = "xpanes:pane_flat"}, {["x"] = 4, ["y"] = 3, ["param1"] = 195, ["z"] = 13, ["name"] = "the_build_spawner:white"}, {["x"] = 4, ["y"] = 3, ["param1"] = 195, ["z"] = 17, ["name"] = "the_build_spawner:white"}, {["x"] = 4, ["y"] = 4, ["z"] = 1, ["name"] = "the_build_spawner:white"}, {["x"] = 4, ["param2"] = 3, ["y"] = 4, ["param1"] = 141, ["z"] = 2, ["name"] = "xpanes:pane_flat"}, {["x"] = 4, ["param2"] = 3, ["y"] = 4, ["param1"] = 157, ["z"] = 3, ["name"] = "xpanes:pane_flat"}, {["x"] = 4, ["param2"] = 3, ["y"] = 4, ["param1"] = 173, ["z"] = 4, ["name"] = "xpanes:pane_flat"}, {["x"] = 4, ["param2"] = 3, ["y"] = 4, ["param1"] = 189, ["z"] = 5, ["name"] = "xpanes:pane_flat"}, {["x"] = 4, ["param2"] = 3, ["y"] = 4, ["param1"] = 205, ["z"] = 6, ["name"] = "xpanes:pane_flat"}, {["x"] = 4, ["y"] = 4, ["z"] = 7, ["name"] = "the_build_spawner:white"}, {["x"] = 4, ["param2"] = 3, ["y"] = 4, ["param1"] = 173, ["z"] = 8, ["name"] = "xpanes:pane_flat"}, {["x"] = 4, ["param2"] = 3, ["y"] = 4, ["param1"] = 157, ["z"] = 9, ["name"] = "xpanes:pane_flat"}, {["x"] = 4, ["param2"] = 3, ["y"] = 4, ["param1"] = 157, ["z"] = 10, ["name"] = "xpanes:pane_flat"}, {["x"] = 4, ["param2"] = 3, ["y"] = 4, ["param1"] = 173, ["z"] = 11, ["name"] = "xpanes:pane_flat"}, {["x"] = 4, ["param2"] = 3, ["y"] = 4, ["param1"] = 189, ["z"] = 12, ["name"] = "xpanes:pane_flat"}, {["x"] = 4, ["y"] = 4, ["param1"] = 195, ["z"] = 13, ["name"] = "the_build_spawner:white"}, {["x"] = 4, ["y"] = 4, ["param1"] = 238, ["z"] = 14, ["name"] = "default:meselamp"}, {["x"] = 4, ["y"] = 4, ["param1"] = 238, ["z"] = 16, ["name"] = "default:meselamp"}, {["x"] = 4, ["y"] = 4, ["param1"] = 195, ["z"] = 17, ["name"] = "the_build_spawner:white"}, {["x"] = 4, ["y"] = 5, ["z"] = 1, ["name"] = "the_build_spawner:dark_blue"}, {["x"] = 4, ["y"] = 5, ["z"] = 2, ["name"] = "the_build_spawner:dark_blue"}, {["x"] = 4, ["y"] = 5, ["z"] = 3, ["name"] = "the_build_spawner:dark_blue"}, {["x"] = 4, ["y"] = 5, ["z"] = 4, ["name"] = "the_build_spawner:dark_blue"}, {["x"] = 4, ["y"] = 5, ["z"] = 5, ["name"] = "the_build_spawner:dark_blue"}, {["x"] = 4, ["y"] = 5, ["z"] = 6, ["name"] = "the_build_spawner:dark_blue"}, {["x"] = 4, ["y"] = 5, ["z"] = 7, ["name"] = "the_build_spawner:dark_blue"}, {["x"] = 4, ["y"] = 5, ["z"] = 8, ["name"] = "the_build_spawner:dark_blue"}, {["x"] = 4, ["y"] = 5, ["z"] = 9, ["name"] = "the_build_spawner:dark_blue"}, {["x"] = 4, ["y"] = 5, ["z"] = 10, ["name"] = "the_build_spawner:dark_blue"}, {["x"] = 4, ["y"] = 5, ["param1"] = 198, ["z"] = 11, ["name"] = "the_build_spawner:dark_blue"}, {["x"] = 4, ["y"] = 5, ["param1"] = 198, ["z"] = 12, ["name"] = "the_build_spawner:dark_blue"}, {["x"] = 4, ["y"] = 5, ["param1"] = 198, ["z"] = 13, ["name"] = "the_build_spawner:dark_blue"}, {["x"] = 4, ["y"] = 5, ["param1"] = 198, ["z"] = 14, ["name"] = "the_build_spawner:dark_blue"}, {["x"] = 4, ["y"] = 5, ["param1"] = 198, ["z"] = 15, ["name"] = "the_build_spawner:dark_blue"}, {["x"] = 4, ["y"] = 5, ["param1"] = 198, ["z"] = 16, ["name"] = "the_build_spawner:dark_blue"}, {["x"] = 4, ["y"] = 5, ["param1"] = 198, ["z"] = 17, ["name"] = "the_build_spawner:dark_blue"}, {["x"] = 5, ["y"] = 0, ["z"] = 0, ["name"] = "default:cobble"}, {["x"] = 5, ["y"] = 0, ["z"] = 1, ["name"] = "the_build_spawner:white"}, {["x"] = 5, ["y"] = 0, ["z"] = 2, ["name"] = "the_build_spawner:black"}, {["x"] = 5, ["y"] = 0, ["z"] = 3, ["name"] = "the_build_spawner:white"}, {["x"] = 5, ["y"] = 0, ["z"] = 4, ["name"] = "the_build_spawner:black"}, {["x"] = 5, ["y"] = 0, ["z"] = 5, ["name"] = "the_build_spawner:white"}, {["x"] = 5, ["y"] = 0, ["z"] = 6, ["name"] = "the_build_spawner:black"}, {["x"] = 5, ["y"] = 0, ["z"] = 7, ["name"] = "the_build_spawner:white"}, {["x"] = 5, ["y"] = 0, ["z"] = 8, ["name"] = "the_build_spawner:black"}, {["x"] = 5, ["y"] = 0, ["z"] = 9, ["name"] = "the_build_spawner:white"}, {["x"] = 5, ["y"] = 0, ["z"] = 10, ["name"] = "the_build_spawner:black"}, {["x"] = 5, ["y"] = 0, ["param1"] = 195, ["z"] = 11, ["name"] = "the_build_spawner:white"}, {["x"] = 5, ["y"] = 0, ["param1"] = 183, ["z"] = 12, ["name"] = "the_build_spawner:black"}, {["x"] = 5, ["y"] = 0, ["param1"] = 195, ["z"] = 13, ["name"] = "the_build_spawner:white"}, {["x"] = 5, ["y"] = 0, ["param1"] = 183, ["z"] = 14, ["name"] = "the_build_spawner:black"}, {["x"] = 5, ["y"] = 0, ["param1"] = 195, ["z"] = 15, ["name"] = "the_build_spawner:white"}, {["x"] = 5, ["y"] = 0, ["param1"] = 183, ["z"] = 16, ["name"] = "the_build_spawner:black"}, {["x"] = 5, ["y"] = 0, ["param1"] = 195, ["z"] = 17, ["name"] = "the_build_spawner:white"}, {["x"] = 5, ["y"] = 0, ["z"] = 18, ["name"] = "the_build_spawner:black"}, {["x"] = 5, ["y"] = 0, ["param1"] = 183, ["z"] = 19, ["name"] = "the_build_spawner:black"}, {["x"] = 5, ["y"] = 0, ["param1"] = 183, ["z"] = 20, ["name"] = "the_build_spawner:black"}, {["x"] = 5, ["y"] = 0, ["param1"] = 183, ["z"] = 21, ["name"] = "the_build_spawner:black"}, {["x"] = 5, ["y"] = 0, ["param1"] = 183, ["z"] = 22, ["name"] = "the_build_spawner:black"}, {["x"] = 5, ["y"] = 0, ["param1"] = 3, ["z"] = 23, ["name"] = "default:cobble"}, {["x"] = 5, ["y"] = 1, ["z"] = 1, ["name"] = "the_build_spawner:white"}, {["x"] = 5, ["y"] = 1, ["param1"] = 195, ["z"] = 17, ["name"] = "the_build_spawner:white"}, {["x"] = 5, ["y"] = 2, ["z"] = 1, ["name"] = "the_build_spawner:white"}, {["x"] = 5, ["y"] = 2, ["param1"] = 195, ["z"] = 17, ["name"] = "the_build_spawner:white"}, {["x"] = 5, ["y"] = 3, ["z"] = 1, ["name"] = "the_build_spawner:white"}, {["x"] = 5, ["y"] = 3, ["param1"] = 195, ["z"] = 17, ["name"] = "the_build_spawner:white"}, {["x"] = 5, ["y"] = 4, ["z"] = 1, ["name"] = "the_build_spawner:white"}, {["x"] = 5, ["y"] = 4, ["param1"] = 195, ["z"] = 17, ["name"] = "the_build_spawner:white"}, {["x"] = 5, ["y"] = 5, ["z"] = 1, ["name"] = "the_build_spawner:dark_blue"}, {["x"] = 5, ["y"] = 5, ["z"] = 2, ["name"] = "the_build_spawner:dark_blue"}, {["x"] = 5, ["y"] = 5, ["z"] = 3, ["name"] = "the_build_spawner:dark_blue"}, {["x"] = 5, ["y"] = 5, ["z"] = 4, ["name"] = "the_build_spawner:dark_blue"}, {["x"] = 5, ["y"] = 5, ["param1"] = 15, ["z"] = 5, ["name"] = "the_build_spawner:dark_blue"}, {["x"] = 5, ["y"] = 5, ["z"] = 6, ["name"] = "the_build_spawner:dark_blue"}, {["x"] = 5, ["y"] = 5, ["z"] = 7, ["name"] = "the_build_spawner:dark_blue"}, {["x"] = 5, ["y"] = 5, ["z"] = 8, ["name"] = "the_build_spawner:dark_blue"}, {["x"] = 5, ["y"] = 5, ["z"] = 9, ["name"] = "the_build_spawner:dark_blue"}, {["x"] = 5, ["y"] = 5, ["z"] = 10, ["name"] = "the_build_spawner:dark_blue"}, {["x"] = 5, ["y"] = 5, ["param1"] = 198, ["z"] = 11, ["name"] = "the_build_spawner:dark_blue"}, {["x"] = 5, ["y"] = 5, ["param1"] = 198, ["z"] = 12, ["name"] = "the_build_spawner:dark_blue"}, {["x"] = 5, ["y"] = 5, ["param1"] = 198, ["z"] = 13, ["name"] = "the_build_spawner:dark_blue"}, {["x"] = 5, ["y"] = 5, ["param1"] = 198, ["z"] = 14, ["name"] = "the_build_spawner:dark_blue"}, {["x"] = 5, ["y"] = 5, ["param1"] = 198, ["z"] = 15, ["name"] = "the_build_spawner:dark_blue"}, {["x"] = 5, ["y"] = 5, ["param1"] = 198, ["z"] = 16, ["name"] = "the_build_spawner:dark_blue"}, {["x"] = 5, ["y"] = 5, ["param1"] = 198, ["z"] = 17, ["name"] = "the_build_spawner:dark_blue"}, {["x"] = 6, ["y"] = 0, ["z"] = 0, ["name"] = "default:cobble"}, {["x"] = 6, ["y"] = 0, ["z"] = 1, ["name"] = "the_build_spawner:black"}, {["x"] = 6, ["y"] = 0, ["z"] = 2, ["name"] = "the_build_spawner:white"}, {["x"] = 6, ["y"] = 0, ["z"] = 3, ["name"] = "the_build_spawner:black"}, {["x"] = 6, ["y"] = 0, ["z"] = 4, ["name"] = "the_build_spawner:white"}, {["x"] = 6, ["y"] = 0, ["z"] = 5, ["name"] = "the_build_spawner:black"}, {["x"] = 6, ["y"] = 0, ["z"] = 6, ["name"] = "the_build_spawner:white"}, {["x"] = 6, ["y"] = 0, ["z"] = 7, ["name"] = "the_build_spawner:black"}, {["x"] = 6, ["y"] = 0, ["z"] = 8, ["name"] = "the_build_spawner:white"}, {["x"] = 6, ["y"] = 0, ["z"] = 9, ["name"] = "the_build_spawner:black"}, {["x"] = 6, ["y"] = 0, ["z"] = 10, ["name"] = "the_build_spawner:white"}, {["x"] = 6, ["y"] = 0, ["param1"] = 183, ["z"] = 11, ["name"] = "the_build_spawner:black"}, {["x"] = 6, ["y"] = 0, ["param1"] = 195, ["z"] = 12, ["name"] = "the_build_spawner:white"}, {["x"] = 6, ["y"] = 0, ["param1"] = 183, ["z"] = 13, ["name"] = "the_build_spawner:black"}, {["x"] = 6, ["y"] = 0, ["param1"] = 195, ["z"] = 14, ["name"] = "the_build_spawner:white"}, {["x"] = 6, ["y"] = 0, ["param1"] = 183, ["z"] = 15, ["name"] = "the_build_spawner:black"}, {["x"] = 6, ["y"] = 0, ["param1"] = 195, ["z"] = 16, ["name"] = "the_build_spawner:white"}, {["x"] = 6, ["y"] = 0, ["param1"] = 195, ["z"] = 17, ["name"] = "the_build_spawner:white"}, {["x"] = 6, ["y"] = 0, ["z"] = 18, ["name"] = "the_build_spawner:black"}, {["x"] = 6, ["y"] = 0, ["param1"] = 183, ["z"] = 19, ["name"] = "the_build_spawner:black"}, {["x"] = 6, ["y"] = 0, ["param1"] = 183, ["z"] = 20, ["name"] = "the_build_spawner:black"}, {["x"] = 6, ["y"] = 0, ["param1"] = 183, ["z"] = 21, ["name"] = "the_build_spawner:black"}, {["x"] = 6, ["y"] = 0, ["param1"] = 183, ["z"] = 22, ["name"] = "the_build_spawner:black"}, {["x"] = 6, ["y"] = 0, ["param1"] = 3, ["z"] = 23, ["name"] = "default:cobble"}, {["x"] = 6, ["y"] = 1, ["z"] = 1, ["name"] = "the_build_spawner:white"}, {["x"] = 6, ["y"] = 1, ["param1"] = 195, ["z"] = 17, ["name"] = "the_build_spawner:white"}, {["x"] = 6, ["y"] = 2, ["z"] = 1, ["name"] = "the_build_spawner:white"}, {["x"] = 6, ["y"] = 2, ["param1"] = 195, ["z"] = 17, ["name"] = "the_build_spawner:white"}, {["x"] = 6, ["y"] = 3, ["z"] = 1, ["name"] = "the_build_spawner:white"}, {["x"] = 6, ["y"] = 3, ["param1"] = 195, ["z"] = 17, ["name"] = "the_build_spawner:white"}, {["x"] = 6, ["y"] = 4, ["z"] = 1, ["name"] = "the_build_spawner:white"}, {["x"] = 6, ["y"] = 4, ["param1"] = 238, ["z"] = 6, ["name"] = "default:meselamp"}, {["x"] = 6, ["y"] = 4, ["param1"] = 238, ["z"] = 13, ["name"] = "default:meselamp"}, {["x"] = 6, ["y"] = 4, ["param1"] = 195, ["z"] = 17, ["name"] = "the_build_spawner:white"}, {["x"] = 6, ["y"] = 5, ["z"] = 1, ["name"] = "the_build_spawner:dark_blue"}, {["x"] = 6, ["y"] = 5, ["z"] = 2, ["name"] = "the_build_spawner:dark_blue"}, {["x"] = 6, ["y"] = 5, ["param1"] = 15, ["z"] = 3, ["name"] = "the_build_spawner:dark_blue"}, {["x"] = 6, ["y"] = 5, ["z"] = 4, ["name"] = "the_build_spawner:dark_blue"}, {["x"] = 6, ["y"] = 5, ["param1"] = 15, ["z"] = 5, ["name"] = "the_build_spawner:dark_blue"}, {["x"] = 6, ["y"] = 5, ["param1"] = 15, ["z"] = 6, ["name"] = "the_build_spawner:dark_blue"}, {["x"] = 6, ["y"] = 5, ["param1"] = 15, ["z"] = 7, ["name"] = "the_build_spawner:dark_blue"}, {["x"] = 6, ["y"] = 5, ["z"] = 8, ["name"] = "the_build_spawner:dark_blue"}, {["x"] = 6, ["y"] = 5, ["param1"] = 15, ["z"] = 9, ["name"] = "the_build_spawner:dark_blue"}, {["x"] = 6, ["y"] = 5, ["param1"] = 14, ["z"] = 10, ["name"] = "the_build_spawner:dark_blue"}, {["x"] = 6, ["y"] = 5, ["param1"] = 198, ["z"] = 11, ["name"] = "the_build_spawner:dark_blue"}, {["x"] = 6, ["y"] = 5, ["param1"] = 198, ["z"] = 12, ["name"] = "the_build_spawner:dark_blue"}, {["x"] = 6, ["y"] = 5, ["param1"] = 198, ["z"] = 13, ["name"] = "the_build_spawner:dark_blue"}, {["x"] = 6, ["y"] = 5, ["param1"] = 198, ["z"] = 14, ["name"] = "the_build_spawner:dark_blue"}, {["x"] = 6, ["y"] = 5, ["param1"] = 198, ["z"] = 15, ["name"] = "the_build_spawner:dark_blue"}, {["x"] = 6, ["y"] = 5, ["param1"] = 198, ["z"] = 16, ["name"] = "the_build_spawner:dark_blue"}, {["x"] = 6, ["y"] = 5, ["param1"] = 198, ["z"] = 17, ["name"] = "the_build_spawner:dark_blue"}, {["x"] = 7, ["y"] = 0, ["z"] = 0, ["name"] = "default:cobble"}, {["x"] = 7, ["y"] = 0, ["z"] = 1, ["name"] = "the_build_spawner:white"}, {["x"] = 7, ["y"] = 0, ["z"] = 2, ["name"] = "the_build_spawner:black"}, {["x"] = 7, ["y"] = 0, ["z"] = 3, ["name"] = "the_build_spawner:white"}, {["x"] = 7, ["y"] = 0, ["z"] = 4, ["name"] = "the_build_spawner:black"}, {["x"] = 7, ["y"] = 0, ["z"] = 5, ["name"] = "the_build_spawner:white"}, {["x"] = 7, ["y"] = 0, ["z"] = 6, ["name"] = "the_build_spawner:black"}, {["x"] = 7, ["y"] = 0, ["z"] = 7, ["name"] = "the_build_spawner:white"}, {["x"] = 7, ["y"] = 0, ["z"] = 8, ["name"] = "the_build_spawner:black"}, {["x"] = 7, ["y"] = 0, ["z"] = 9, ["name"] = "the_build_spawner:white"}, {["x"] = 7, ["y"] = 0, ["z"] = 10, ["name"] = "the_build_spawner:black"}, {["x"] = 7, ["y"] = 0, ["param1"] = 195, ["z"] = 11, ["name"] = "the_build_spawner:white"}, {["x"] = 7, ["y"] = 0, ["param1"] = 183, ["z"] = 12, ["name"] = "the_build_spawner:black"}, {["x"] = 7, ["y"] = 0, ["param1"] = 195, ["z"] = 13, ["name"] = "the_build_spawner:white"}, {["x"] = 7, ["y"] = 0, ["param1"] = 183, ["z"] = 14, ["name"] = "the_build_spawner:black"}, {["x"] = 7, ["y"] = 0, ["param1"] = 195, ["z"] = 15, ["name"] = "the_build_spawner:white"}, {["x"] = 7, ["y"] = 0, ["param1"] = 183, ["z"] = 16, ["name"] = "the_build_spawner:black"}, {["x"] = 7, ["y"] = 0, ["param1"] = 195, ["z"] = 17, ["name"] = "the_build_spawner:white"}, {["x"] = 7, ["y"] = 0, ["z"] = 18, ["name"] = "the_build_spawner:black"}, {["x"] = 7, ["y"] = 0, ["param1"] = 183, ["z"] = 19, ["name"] = "the_build_spawner:black"}, {["x"] = 7, ["y"] = 0, ["param1"] = 183, ["z"] = 20, ["name"] = "the_build_spawner:black"}, {["x"] = 7, ["y"] = 0, ["param1"] = 183, ["z"] = 21, ["name"] = "the_build_spawner:black"}, {["x"] = 7, ["y"] = 0, ["param1"] = 183, ["z"] = 22, ["name"] = "the_build_spawner:black"}, {["x"] = 7, ["y"] = 0, ["param1"] = 3, ["z"] = 23, ["name"] = "default:cobble"}, {["x"] = 7, ["y"] = 1, ["z"] = 1, ["name"] = "the_build_spawner:white"}, {["x"] = 7, ["y"] = 1, ["param1"] = 195, ["z"] = 17, ["name"] = "the_build_spawner:white"}, {["x"] = 7, ["y"] = 2, ["z"] = 1, ["name"] = "the_build_spawner:white"}, {["x"] = 7, ["y"] = 2, ["param1"] = 195, ["z"] = 17, ["name"] = "the_build_spawner:white"}, {["x"] = 7, ["y"] = 3, ["z"] = 1, ["name"] = "the_build_spawner:white"}, {["x"] = 7, ["y"] = 3, ["param1"] = 195, ["z"] = 17, ["name"] = "the_build_spawner:white"}, {["x"] = 7, ["y"] = 4, ["z"] = 1, ["name"] = "the_build_spawner:white"}, {["x"] = 7, ["y"] = 4, ["param1"] = 195, ["z"] = 17, ["name"] = "the_build_spawner:white"}, {["x"] = 7, ["y"] = 5, ["z"] = 1, ["name"] = "the_build_spawner:dark_blue"}, {["x"] = 7, ["y"] = 5, ["z"] = 2, ["name"] = "the_build_spawner:dark_blue"}, {["x"] = 7, ["y"] = 5, ["param1"] = 15, ["z"] = 3, ["name"] = "the_build_spawner:dark_blue"}, {["x"] = 7, ["y"] = 5, ["param1"] = 15, ["z"] = 4, ["name"] = "the_build_spawner:dark_blue"}, {["x"] = 7, ["y"] = 5, ["param1"] = 15, ["z"] = 5, ["name"] = "the_build_spawner:dark_blue"}, {["x"] = 7, ["y"] = 5, ["param1"] = 15, ["z"] = 6, ["name"] = "the_build_spawner:dark_blue"}, {["x"] = 7, ["y"] = 5, ["param1"] = 15, ["z"] = 7, ["name"] = "the_build_spawner:dark_blue"}, {["x"] = 7, ["y"] = 5, ["param1"] = 15, ["z"] = 8, ["name"] = "the_build_spawner:dark_blue"}, {["x"] = 7, ["y"] = 5, ["param1"] = 15, ["z"] = 9, ["name"] = "the_build_spawner:dark_blue"}, {["x"] = 7, ["y"] = 5, ["param1"] = 14, ["z"] = 10, ["name"] = "the_build_spawner:dark_blue"}, {["x"] = 7, ["y"] = 5, ["param1"] = 198, ["z"] = 11, ["name"] = "the_build_spawner:dark_blue"}, {["x"] = 7, ["y"] = 5, ["param1"] = 198, ["z"] = 12, ["name"] = "the_build_spawner:dark_blue"}, {["x"] = 7, ["y"] = 5, ["param1"] = 198, ["z"] = 13, ["name"] = "the_build_spawner:dark_blue"}, {["x"] = 7, ["y"] = 5, ["param1"] = 198, ["z"] = 14, ["name"] = "the_build_spawner:dark_blue"}, {["x"] = 7, ["y"] = 5, ["param1"] = 198, ["z"] = 15, ["name"] = "the_build_spawner:dark_blue"}, {["x"] = 7, ["y"] = 5, ["param1"] = 198, ["z"] = 16, ["name"] = "the_build_spawner:dark_blue"}, {["x"] = 7, ["y"] = 5, ["param1"] = 198, ["z"] = 17, ["name"] = "the_build_spawner:dark_blue"}, {["x"] = 8, ["y"] = 0, ["z"] = 0, ["name"] = "default:cobble"}, {["x"] = 8, ["y"] = 0, ["z"] = 1, ["name"] = "the_build_spawner:white"}, {["x"] = 8, ["y"] = 0, ["z"] = 2, ["name"] = "the_build_spawner:white"}, {["x"] = 8, ["y"] = 0, ["z"] = 3, ["name"] = "the_build_spawner:white"}, {["x"] = 8, ["y"] = 0, ["z"] = 4, ["name"] = "the_build_spawner:white"}, {["x"] = 8, ["y"] = 0, ["z"] = 5, ["name"] = "the_build_spawner:white"}, {["x"] = 8, ["y"] = 0, ["z"] = 6, ["name"] = "the_build_spawner:white"}, {["x"] = 8, ["y"] = 0, ["z"] = 7, ["name"] = "the_build_spawner:white"}, {["x"] = 8, ["y"] = 0, ["z"] = 8, ["name"] = "the_build_spawner:white"}, {["x"] = 8, ["y"] = 0, ["z"] = 9, ["name"] = "the_build_spawner:white"}, {["x"] = 8, ["y"] = 0, ["z"] = 10, ["name"] = "the_build_spawner:white"}, {["x"] = 8, ["y"] = 0, ["param1"] = 195, ["z"] = 11, ["name"] = "the_build_spawner:white"}, {["x"] = 8, ["y"] = 0, ["param1"] = 195, ["z"] = 12, ["name"] = "the_build_spawner:white"}, {["x"] = 8, ["y"] = 0, ["param1"] = 195, ["z"] = 13, ["name"] = "the_build_spawner:white"}, {["x"] = 8, ["y"] = 0, ["param1"] = 195, ["z"] = 14, ["name"] = "the_build_spawner:white"}, {["x"] = 8, ["y"] = 0, ["param1"] = 183, ["z"] = 15, ["name"] = "the_build_spawner:black"}, {["x"] = 8, ["y"] = 0, ["param1"] = 195, ["z"] = 16, ["name"] = "the_build_spawner:white"}, {["x"] = 8, ["y"] = 0, ["param1"] = 195, ["z"] = 17, ["name"] = "the_build_spawner:white"}, {["x"] = 8, ["y"] = 0, ["z"] = 18, ["name"] = "the_build_spawner:white"}, {["x"] = 8, ["y"] = 0, ["z"] = 19, ["name"] = "the_build_spawner:white"}, {["x"] = 8, ["y"] = 0, ["z"] = 20, ["name"] = "the_build_spawner:white"}, {["x"] = 8, ["y"] = 0, ["z"] = 21, ["name"] = "the_build_spawner:white"}, {["x"] = 8, ["y"] = 0, ["z"] = 22, ["name"] = "the_build_spawner:white"}, {["x"] = 8, ["y"] = 0, ["param1"] = 3, ["z"] = 23, ["name"] = "default:cobble"}, {["x"] = 8, ["y"] = 1, ["z"] = 1, ["name"] = "default:cobble"}, {["x"] = 8, ["param2"] = 3, ["y"] = 1, ["param1"] = 137, ["z"] = 2, ["name"] = "xpanes:bar_flat"}, {["x"] = 8, ["param2"] = 3, ["y"] = 1, ["param1"] = 153, ["z"] = 3, ["name"] = "xpanes:bar_flat"}, {["x"] = 8, ["param2"] = 3, ["y"] = 1, ["param1"] = 137, ["z"] = 4, ["name"] = "xpanes:bar_flat"}, {["x"] = 8, ["y"] = 1, ["z"] = 5, ["name"] = "default:cobble"}, {["x"] = 8, ["meta"] = {["fields"] = {["state"] = "0"}, ["inventory"] = {}}, ["param2"] = 1, ["y"] = 1, ["param1"] = 153, ["z"] = 6, ["name"] = "doors:door_wood_a"}, {["x"] = 8, ["y"] = 1, ["z"] = 7, ["name"] = "default:cobble"}, {["x"] = 8, ["param2"] = 3, ["y"] = 1, ["param1"] = 137, ["z"] = 8, ["name"] = "xpanes:bar_flat"}, {["x"] = 8, ["param2"] = 3, ["y"] = 1, ["param1"] = 153, ["z"] = 9, ["name"] = "xpanes:bar_flat"}, {["x"] = 8, ["param2"] = 3, ["y"] = 1, ["param1"] = 137, ["z"] = 10, ["name"] = "xpanes:bar_flat"}, {["x"] = 8, ["y"] = 1, ["param1"] = 3, ["z"] = 11, ["name"] = "default:cobble"}, {["x"] = 8, ["meta"] = {["fields"] = {["state"] = "0"}, ["inventory"] = {}}, ["param2"] = 1, ["y"] = 1, ["param1"] = 137, ["z"] = 12, ["name"] = "doors:door_wood_a"}, {["x"] = 8, ["y"] = 1, ["param1"] = 3, ["z"] = 13, ["name"] = "default:cobble"}, {["x"] = 8, ["param2"] = 23, ["y"] = 1, ["param1"] = 119, ["z"] = 15, ["name"] = "stairs:stair_silver_sandstone"}, {["x"] = 8, ["param2"] = 23, ["y"] = 1, ["param1"] = 136, ["z"] = 16, ["name"] = "stairs:stair_silver_sandstone"}, {["x"] = 8, ["y"] = 1, ["param1"] = 195, ["z"] = 17, ["name"] = "the_build_spawner:white"}, {["x"] = 8, ["y"] = 2, ["z"] = 1, ["name"] = "default:cobble"}, {["x"] = 8, ["param2"] = 3, ["y"] = 2, ["param1"] = 153, ["z"] = 2, ["name"] = "xpanes:bar_flat"}, {["x"] = 8, ["param2"] = 3, ["y"] = 2, ["param1"] = 170, ["z"] = 3, ["name"] = "xpanes:bar_flat"}, {["x"] = 8, ["param2"] = 3, ["y"] = 2, ["param1"] = 153, ["z"] = 4, ["name"] = "xpanes:bar_flat"}, {["x"] = 8, ["y"] = 2, ["z"] = 5, ["name"] = "default:cobble"}, {["x"] = 8, ["param2"] = 1, ["y"] = 2, ["param1"] = 170, ["z"] = 6, ["name"] = "doors:hidden"}, {["x"] = 8, ["y"] = 2, ["z"] = 7, ["name"] = "default:cobble"}, {["x"] = 8, ["param2"] = 3, ["y"] = 2, ["param1"] = 153, ["z"] = 8, ["name"] = "xpanes:bar_flat"}, {["x"] = 8, ["param2"] = 3, ["y"] = 2, ["param1"] = 170, ["z"] = 9, ["name"] = "xpanes:bar_flat"}, {["x"] = 8, ["param2"] = 3, ["y"] = 2, ["param1"] = 153, ["z"] = 10, ["name"] = "xpanes:bar_flat"}, {["x"] = 8, ["y"] = 2, ["param1"] = 3, ["z"] = 11, ["name"] = "default:cobble"}, {["x"] = 8, ["param2"] = 1, ["y"] = 2, ["param1"] = 153, ["z"] = 12, ["name"] = "doors:hidden"}, {["x"] = 8, ["y"] = 2, ["param1"] = 3, ["z"] = 13, ["name"] = "default:cobble"}, {["x"] = 8, ["y"] = 2, ["param1"] = 195, ["z"] = 17, ["name"] = "the_build_spawner:white"}, {["x"] = 8, ["y"] = 3, ["z"] = 1, ["name"] = "default:cobble"}, {["x"] = 8, ["param2"] = 3, ["y"] = 3, ["param1"] = 170, ["z"] = 2, ["name"] = "xpanes:bar_flat"}, {["x"] = 8, ["param2"] = 3, ["y"] = 3, ["param1"] = 187, ["z"] = 3, ["name"] = "xpanes:bar_flat"}, {["x"] = 8, ["param2"] = 3, ["y"] = 3, ["param1"] = 170, ["z"] = 4, ["name"] = "xpanes:bar_flat"}, {["x"] = 8, ["y"] = 3, ["z"] = 5, ["name"] = "default:cobble"}, {["x"] = 8, ["y"] = 3, ["z"] = 6, ["name"] = "default:cobble"}, {["x"] = 8, ["y"] = 3, ["z"] = 7, ["name"] = "default:cobble"}, {["x"] = 8, ["param2"] = 3, ["y"] = 3, ["param1"] = 170, ["z"] = 8, ["name"] = "xpanes:bar_flat"}, {["x"] = 8, ["param2"] = 3, ["y"] = 3, ["param1"] = 187, ["z"] = 9, ["name"] = "xpanes:bar_flat"}, {["x"] = 8, ["param2"] = 3, ["y"] = 3, ["param1"] = 170, ["z"] = 10, ["name"] = "xpanes:bar_flat"}, {["x"] = 8, ["y"] = 3, ["param1"] = 3, ["z"] = 11, ["name"] = "default:cobble"}, {["x"] = 8, ["y"] = 3, ["param1"] = 3, ["z"] = 12, ["name"] = "default:cobble"}, {["x"] = 8, ["y"] = 3, ["param1"] = 3, ["z"] = 13, ["name"] = "default:cobble"}, {["x"] = 8, ["y"] = 3, ["param1"] = 195, ["z"] = 17, ["name"] = "the_build_spawner:white"}, {["x"] = 8, ["y"] = 4, ["z"] = 1, ["name"] = "default:cobble"}, {["x"] = 8, ["param2"] = 3, ["y"] = 4, ["param1"] = 187, ["z"] = 2, ["name"] = "xpanes:bar_flat"}, {["x"] = 8, ["param2"] = 3, ["y"] = 4, ["param1"] = 204, ["z"] = 3, ["name"] = "xpanes:bar_flat"}, {["x"] = 8, ["param2"] = 3, ["y"] = 4, ["param1"] = 187, ["z"] = 4, ["name"] = "xpanes:bar_flat"}, {["x"] = 8, ["y"] = 4, ["z"] = 5, ["name"] = "default:cobble"}, {["x"] = 8, ["y"] = 4, ["z"] = 6, ["name"] = "default:cobble"}, {["x"] = 8, ["y"] = 4, ["z"] = 7, ["name"] = "default:cobble"}, {["x"] = 8, ["param2"] = 3, ["y"] = 4, ["param1"] = 187, ["z"] = 8, ["name"] = "xpanes:bar_flat"}, {["x"] = 8, ["param2"] = 3, ["y"] = 4, ["param1"] = 204, ["z"] = 9, ["name"] = "xpanes:bar_flat"}, {["x"] = 8, ["param2"] = 3, ["y"] = 4, ["param1"] = 187, ["z"] = 10, ["name"] = "xpanes:bar_flat"}, {["x"] = 8, ["y"] = 4, ["param1"] = 3, ["z"] = 11, ["name"] = "default:cobble"}, {["x"] = 8, ["y"] = 4, ["param1"] = 3, ["z"] = 12, ["name"] = "default:cobble"}, {["x"] = 8, ["y"] = 4, ["param1"] = 3, ["z"] = 13, ["name"] = "default:cobble"}, {["x"] = 8, ["y"] = 4, ["param1"] = 195, ["z"] = 17, ["name"] = "the_build_spawner:white"}, {["x"] = 8, ["y"] = 5, ["z"] = 1, ["name"] = "the_build_spawner:dark_blue"}, {["x"] = 8, ["y"] = 5, ["z"] = 2, ["name"] = "the_build_spawner:dark_blue"}, {["x"] = 8, ["y"] = 5, ["param1"] = 15, ["z"] = 3, ["name"] = "the_build_spawner:dark_blue"}, {["x"] = 8, ["y"] = 5, ["param1"] = 15, ["z"] = 4, ["name"] = "the_build_spawner:dark_blue"}, {["x"] = 8, ["y"] = 5, ["param1"] = 15, ["z"] = 5, ["name"] = "the_build_spawner:dark_blue"}, {["x"] = 8, ["y"] = 5, ["param1"] = 15, ["z"] = 6, ["name"] = "the_build_spawner:dark_blue"}, {["x"] = 8, ["y"] = 5, ["param1"] = 15, ["z"] = 7, ["name"] = "the_build_spawner:dark_blue"}, {["x"] = 8, ["y"] = 5, ["param1"] = 15, ["z"] = 8, ["name"] = "the_build_spawner:dark_blue"}, {["x"] = 8, ["y"] = 5, ["param1"] = 15, ["z"] = 9, ["name"] = "the_build_spawner:dark_blue"}, {["x"] = 8, ["y"] = 5, ["param1"] = 14, ["z"] = 10, ["name"] = "the_build_spawner:dark_blue"}, {["x"] = 8, ["y"] = 5, ["param1"] = 198, ["z"] = 11, ["name"] = "the_build_spawner:dark_blue"}, {["x"] = 8, ["y"] = 5, ["param1"] = 198, ["z"] = 12, ["name"] = "the_build_spawner:dark_blue"}, {["x"] = 8, ["y"] = 5, ["param1"] = 198, ["z"] = 13, ["name"] = "the_build_spawner:dark_blue"}, {["x"] = 8, ["y"] = 5, ["param1"] = 198, ["z"] = 14, ["name"] = "the_build_spawner:dark_blue"}, {["x"] = 8, ["y"] = 5, ["param1"] = 198, ["z"] = 15, ["name"] = "the_build_spawner:dark_blue"}, {["x"] = 8, ["y"] = 5, ["param1"] = 198, ["z"] = 16, ["name"] = "the_build_spawner:dark_blue"}, {["x"] = 8, ["y"] = 5, ["param1"] = 198, ["z"] = 17, ["name"] = "the_build_spawner:dark_blue"}, {["x"] = 9, ["y"] = 0, ["param1"] = 14, ["z"] = 0, ["name"] = "default:cobble"}, {["x"] = 9, ["y"] = 0, ["z"] = 1, ["name"] = "the_build_spawner:white"}, {["x"] = 9, ["y"] = 0, ["z"] = 2, ["name"] = "the_build_spawner:white"}, {["x"] = 9, ["y"] = 0, ["z"] = 3, ["name"] = "the_build_spawner:white"}, {["x"] = 9, ["y"] = 0, ["z"] = 4, ["name"] = "the_build_spawner:white"}, {["x"] = 9, ["y"] = 0, ["z"] = 5, ["name"] = "the_build_spawner:white"}, {["x"] = 9, ["y"] = 0, ["z"] = 6, ["name"] = "the_build_spawner:white"}, {["x"] = 9, ["y"] = 0, ["z"] = 7, ["name"] = "the_build_spawner:white"}, {["x"] = 9, ["y"] = 0, ["z"] = 8, ["name"] = "the_build_spawner:white"}, {["x"] = 9, ["y"] = 0, ["z"] = 9, ["name"] = "the_build_spawner:white"}, {["x"] = 9, ["y"] = 0, ["z"] = 10, ["name"] = "the_build_spawner:white"}, {["x"] = 9, ["y"] = 0, ["param1"] = 195, ["z"] = 11, ["name"] = "the_build_spawner:white"}, {["x"] = 9, ["y"] = 0, ["param1"] = 195, ["z"] = 12, ["name"] = "the_build_spawner:white"}, {["x"] = 9, ["y"] = 0, ["param1"] = 195, ["z"] = 13, ["name"] = "the_build_spawner:white"}, {["x"] = 9, ["y"] = 0, ["param1"] = 183, ["z"] = 14, ["name"] = "the_build_spawner:black"}, {["x"] = 9, ["y"] = 0, ["param1"] = 195, ["z"] = 15, ["name"] = "the_build_spawner:white"}, {["x"] = 9, ["y"] = 0, ["param1"] = 183, ["z"] = 16, ["name"] = "the_build_spawner:black"}, {["x"] = 9, ["y"] = 0, ["param1"] = 195, ["z"] = 17, ["name"] = "the_build_spawner:white"}, {["x"] = 9, ["y"] = 0, ["z"] = 18, ["name"] = "the_build_spawner:black"}, {["x"] = 9, ["y"] = 0, ["param1"] = 183, ["z"] = 19, ["name"] = "the_build_spawner:black"}, {["x"] = 9, ["y"] = 0, ["param1"] = 183, ["z"] = 20, ["name"] = "the_build_spawner:black"}, {["x"] = 9, ["y"] = 0, ["param1"] = 183, ["z"] = 21, ["name"] = "the_build_spawner:black"}, {["x"] = 9, ["y"] = 0, ["param1"] = 183, ["z"] = 22, ["name"] = "the_build_spawner:black"}, {["x"] = 9, ["y"] = 0, ["param1"] = 3, ["z"] = 23, ["name"] = "default:cobble"}, {["x"] = 9, ["y"] = 1, ["z"] = 1, ["name"] = "default:cobble"}, {["x"] = 9, ["y"] = 1, ["param1"] = 153, ["z"] = 7, ["name"] = "xpanes:bar_flat"}, {["x"] = 9, ["y"] = 1, ["param1"] = 3, ["z"] = 13, ["name"] = "default:cobble"}, {["x"] = 9, ["y"] = 1, ["param1"] = 195, ["z"] = 17, ["name"] = "the_build_spawner:white"}, {["x"] = 9, ["y"] = 2, ["z"] = 1, ["name"] = "default:cobble"}, {["x"] = 9, ["y"] = 2, ["param1"] = 170, ["z"] = 7, ["name"] = "xpanes:bar_flat"}, {["x"] = 9, ["y"] = 2, ["param1"] = 3, ["z"] = 13, ["name"] = "default:cobble"}, {["x"] = 9, ["y"] = 2, ["z"] = 17, ["name"] = "the_build_spawner:white"}, {["x"] = 9, ["y"] = 3, ["z"] = 1, ["name"] = "default:cobble"}, {["x"] = 9, ["y"] = 3, ["param1"] = 187, ["z"] = 7, ["name"] = "xpanes:bar_flat"}, {["x"] = 9, ["y"] = 3, ["param1"] = 3, ["z"] = 13, ["name"] = "default:cobble"}, {["x"] = 9, ["y"] = 3, ["param1"] = 195, ["z"] = 17, ["name"] = "the_build_spawner:white"}, {["x"] = 9, ["y"] = 4, ["z"] = 1, ["name"] = "default:cobble"}, {["x"] = 9, ["y"] = 4, ["param1"] = 204, ["z"] = 7, ["name"] = "xpanes:bar_flat"}, {["x"] = 9, ["y"] = 4, ["param1"] = 3, ["z"] = 13, ["name"] = "default:cobble"}, {["x"] = 9, ["y"] = 4, ["param1"] = 195, ["z"] = 17, ["name"] = "the_build_spawner:white"}, {["x"] = 9, ["y"] = 5, ["z"] = 1, ["name"] = "the_build_spawner:dark_blue"}, {["x"] = 9, ["y"] = 5, ["z"] = 2, ["name"] = "the_build_spawner:dark_blue"}, {["x"] = 9, ["y"] = 5, ["param1"] = 15, ["z"] = 3, ["name"] = "the_build_spawner:dark_blue"}, {["x"] = 9, ["y"] = 5, ["param1"] = 15, ["z"] = 4, ["name"] = "the_build_spawner:dark_blue"}, {["x"] = 9, ["y"] = 5, ["param1"] = 15, ["z"] = 5, ["name"] = "the_build_spawner:dark_blue"}, {["x"] = 9, ["y"] = 5, ["param1"] = 15, ["z"] = 6, ["name"] = "the_build_spawner:dark_blue"}, {["x"] = 9, ["y"] = 5, ["param1"] = 15, ["z"] = 7, ["name"] = "the_build_spawner:dark_blue"}, {["x"] = 9, ["y"] = 5, ["param1"] = 15, ["z"] = 8, ["name"] = "the_build_spawner:dark_blue"}, {["x"] = 9, ["y"] = 5, ["param1"] = 15, ["z"] = 9, ["name"] = "the_build_spawner:dark_blue"}, {["x"] = 9, ["y"] = 5, ["param1"] = 14, ["z"] = 10, ["name"] = "the_build_spawner:dark_blue"}, {["x"] = 9, ["y"] = 5, ["param1"] = 198, ["z"] = 11, ["name"] = "the_build_spawner:dark_blue"}, {["x"] = 9, ["y"] = 5, ["param1"] = 198, ["z"] = 12, ["name"] = "the_build_spawner:dark_blue"}, {["x"] = 9, ["y"] = 5, ["param1"] = 198, ["z"] = 13, ["name"] = "the_build_spawner:dark_blue"}, {["x"] = 9, ["y"] = 5, ["param1"] = 198, ["z"] = 14, ["name"] = "the_build_spawner:dark_blue"}, {["x"] = 9, ["y"] = 5, ["param1"] = 198, ["z"] = 15, ["name"] = "the_build_spawner:dark_blue"}, {["x"] = 9, ["y"] = 5, ["param1"] = 198, ["z"] = 16, ["name"] = "the_build_spawner:dark_blue"}, {["x"] = 9, ["y"] = 5, ["param1"] = 198, ["z"] = 17, ["name"] = "the_build_spawner:dark_blue"}, {["x"] = 10, ["y"] = 0, ["z"] = 0, ["name"] = "default:cobble"}, {["x"] = 10, ["y"] = 0, ["z"] = 1, ["name"] = "the_build_spawner:white"}, {["x"] = 10, ["y"] = 0, ["z"] = 2, ["name"] = "the_build_spawner:white"}, {["x"] = 10, ["y"] = 0, ["z"] = 3, ["name"] = "the_build_spawner:white"}, {["x"] = 10, ["y"] = 0, ["z"] = 4, ["name"] = "the_build_spawner:white"}, {["x"] = 10, ["y"] = 0, ["z"] = 5, ["name"] = "the_build_spawner:white"}, {["x"] = 10, ["y"] = 0, ["z"] = 6, ["name"] = "the_build_spawner:white"}, {["x"] = 10, ["y"] = 0, ["z"] = 7, ["name"] = "the_build_spawner:white"}, {["x"] = 10, ["y"] = 0, ["z"] = 8, ["name"] = "the_build_spawner:white"}, {["x"] = 10, ["y"] = 0, ["z"] = 9, ["name"] = "the_build_spawner:white"}, {["x"] = 10, ["y"] = 0, ["z"] = 10, ["name"] = "the_build_spawner:white"}, {["x"] = 10, ["y"] = 0, ["param1"] = 195, ["z"] = 11, ["name"] = "the_build_spawner:white"}, {["x"] = 10, ["y"] = 0, ["param1"] = 195, ["z"] = 12, ["name"] = "the_build_spawner:white"}, {["x"] = 10, ["y"] = 0, ["param1"] = 195, ["z"] = 13, ["name"] = "the_build_spawner:white"}, {["x"] = 10, ["y"] = 0, ["param1"] = 195, ["z"] = 14, ["name"] = "the_build_spawner:white"}, {["x"] = 10, ["y"] = 0, ["param1"] = 183, ["z"] = 15, ["name"] = "the_build_spawner:black"}, {["x"] = 10, ["y"] = 0, ["param1"] = 195, ["z"] = 16, ["name"] = "the_build_spawner:white"}, {["x"] = 10, ["y"] = 0, ["param1"] = 195, ["z"] = 17, ["name"] = "the_build_spawner:white"}, {["x"] = 10, ["y"] = 0, ["z"] = 18, ["name"] = "the_build_spawner:black"}, {["x"] = 10, ["y"] = 0, ["param1"] = 183, ["z"] = 19, ["name"] = "the_build_spawner:black"}, {["x"] = 10, ["y"] = 0, ["param1"] = 183, ["z"] = 20, ["name"] = "the_build_spawner:black"}, {["x"] = 10, ["y"] = 0, ["param1"] = 183, ["z"] = 21, ["name"] = "the_build_spawner:black"}, {["x"] = 10, ["y"] = 0, ["param1"] = 183, ["z"] = 22, ["name"] = "the_build_spawner:black"}, {["x"] = 10, ["y"] = 0, ["param1"] = 3, ["z"] = 23, ["name"] = "default:cobble"}, {["x"] = 10, ["y"] = 1, ["z"] = 1, ["name"] = "default:cobble"}, {["x"] = 10, ["param2"] = 2, ["y"] = 1, ["param1"] = 187, ["z"] = 6, ["name"] = "default:ladder_wood"}, {["x"] = 10, ["y"] = 1, ["param1"] = 170, ["z"] = 7, ["name"] = "xpanes:bar_flat"}, {["x"] = 10, ["param2"] = 2, ["y"] = 1, ["param1"] = 170, ["z"] = 12, ["name"] = "default:ladder_wood"}, {["x"] = 10, ["y"] = 1, ["param1"] = 3, ["z"] = 13, ["name"] = "default:cobble"}, {["x"] = 10, ["y"] = 1, ["param1"] = 195, ["z"] = 17, ["name"] = "the_build_spawner:white"}, {["x"] = 10, ["y"] = 2, ["z"] = 1, ["name"] = "default:cobble"}, {["x"] = 10, ["param2"] = 2, ["y"] = 2, ["param1"] = 204, ["z"] = 6, ["name"] = "default:ladder_wood"}, {["x"] = 10, ["y"] = 2, ["param1"] = 187, ["z"] = 7, ["name"] = "xpanes:bar_flat"}, {["x"] = 10, ["param2"] = 2, ["y"] = 2, ["param1"] = 187, ["z"] = 12, ["name"] = "default:ladder_wood"}, {["x"] = 10, ["y"] = 2, ["param1"] = 3, ["z"] = 13, ["name"] = "default:cobble"}, {["x"] = 10, ["y"] = 2, ["param1"] = 195, ["z"] = 17, ["name"] = "the_build_spawner:white"}, {["x"] = 10, ["y"] = 3, ["z"] = 1, ["name"] = "default:cobble"}, {["x"] = 10, ["param2"] = 2, ["y"] = 3, ["param1"] = 221, ["z"] = 6, ["name"] = "default:ladder_wood"}, {["x"] = 10, ["y"] = 3, ["param1"] = 204, ["z"] = 7, ["name"] = "xpanes:bar_flat"}, {["x"] = 10, ["param2"] = 2, ["y"] = 3, ["param1"] = 204, ["z"] = 12, ["name"] = "default:ladder_wood"}, {["x"] = 10, ["y"] = 3, ["param1"] = 3, ["z"] = 13, ["name"] = "default:cobble"}, {["x"] = 10, ["y"] = 3, ["param1"] = 195, ["z"] = 17, ["name"] = "the_build_spawner:white"}, {["x"] = 10, ["y"] = 4, ["z"] = 1, ["name"] = "default:cobble"}, {["x"] = 10, ["y"] = 4, ["param1"] = 238, ["z"] = 3, ["name"] = "default:meselamp"}, {["x"] = 10, ["y"] = 4, ["param1"] = 238, ["z"] = 6, ["name"] = "default:meselamp"}, {["x"] = 10, ["y"] = 4, ["param1"] = 221, ["z"] = 7, ["name"] = "xpanes:bar_flat"}, {["x"] = 10, ["y"] = 4, ["param1"] = 238, ["z"] = 9, ["name"] = "default:meselamp"}, {["x"] = 10, ["y"] = 4, ["param1"] = 238, ["z"] = 11, ["name"] = "default:meselamp"}, {["x"] = 10, ["y"] = 4, ["param1"] = 3, ["z"] = 13, ["name"] = "default:cobble"}, {["x"] = 10, ["y"] = 4, ["param1"] = 195, ["z"] = 17, ["name"] = "the_build_spawner:white"}, {["x"] = 10, ["y"] = 5, ["z"] = 1, ["name"] = "the_build_spawner:dark_blue"}, {["x"] = 10, ["y"] = 5, ["z"] = 2, ["name"] = "the_build_spawner:dark_blue"}, {["x"] = 10, ["y"] = 5, ["param1"] = 15, ["z"] = 3, ["name"] = "the_build_spawner:dark_blue"}, {["x"] = 10, ["y"] = 5, ["param1"] = 15, ["z"] = 4, ["name"] = "the_build_spawner:dark_blue"}, {["x"] = 10, ["y"] = 5, ["param1"] = 15, ["z"] = 5, ["name"] = "the_build_spawner:dark_blue"}, {["x"] = 10, ["y"] = 5, ["param1"] = 15, ["z"] = 6, ["name"] = "the_build_spawner:dark_blue"}, {["x"] = 10, ["y"] = 5, ["param1"] = 15, ["z"] = 7, ["name"] = "the_build_spawner:dark_blue"}, {["x"] = 10, ["y"] = 5, ["param1"] = 15, ["z"] = 8, ["name"] = "the_build_spawner:dark_blue"}, {["x"] = 10, ["y"] = 5, ["param1"] = 15, ["z"] = 9, ["name"] = "the_build_spawner:dark_blue"}, {["x"] = 10, ["y"] = 5, ["param1"] = 14, ["z"] = 10, ["name"] = "the_build_spawner:dark_blue"}, {["x"] = 10, ["y"] = 5, ["param1"] = 198, ["z"] = 11, ["name"] = "the_build_spawner:dark_blue"}, {["x"] = 10, ["y"] = 5, ["param1"] = 198, ["z"] = 12, ["name"] = "the_build_spawner:dark_blue"}, {["x"] = 10, ["y"] = 5, ["param1"] = 198, ["z"] = 13, ["name"] = "the_build_spawner:dark_blue"}, {["x"] = 10, ["y"] = 5, ["param1"] = 198, ["z"] = 14, ["name"] = "the_build_spawner:dark_blue"}, {["x"] = 10, ["y"] = 5, ["param1"] = 198, ["z"] = 15, ["name"] = "the_build_spawner:dark_blue"}, {["x"] = 10, ["y"] = 5, ["param1"] = 198, ["z"] = 16, ["name"] = "the_build_spawner:dark_blue"}, {["x"] = 10, ["y"] = 5, ["param1"] = 198, ["z"] = 17, ["name"] = "the_build_spawner:dark_blue"}, {["x"] = 11, ["y"] = 0, ["z"] = 0, ["name"] = "default:cobble"}, {["x"] = 11, ["y"] = 0, ["z"] = 1, ["name"] = "the_build_spawner:white"}, {["x"] = 11, ["y"] = 0, ["z"] = 2, ["name"] = "the_build_spawner:white"}, {["x"] = 11, ["y"] = 0, ["z"] = 3, ["name"] = "the_build_spawner:white"}, {["x"] = 11, ["y"] = 0, ["z"] = 4, ["name"] = "the_build_spawner:white"}, {["x"] = 11, ["y"] = 0, ["z"] = 5, ["name"] = "the_build_spawner:white"}, {["x"] = 11, ["y"] = 0, ["z"] = 6, ["name"] = "the_build_spawner:white"}, {["x"] = 11, ["y"] = 0, ["z"] = 7, ["name"] = "the_build_spawner:white"}, {["x"] = 11, ["y"] = 0, ["z"] = 8, ["name"] = "the_build_spawner:white"}, {["x"] = 11, ["y"] = 0, ["z"] = 9, ["name"] = "the_build_spawner:white"}, {["x"] = 11, ["y"] = 0, ["z"] = 10, ["name"] = "the_build_spawner:white"}, {["x"] = 11, ["y"] = 0, ["param1"] = 195, ["z"] = 11, ["name"] = "the_build_spawner:white"}, {["x"] = 11, ["y"] = 0, ["param1"] = 195, ["z"] = 12, ["name"] = "the_build_spawner:white"}, {["x"] = 11, ["y"] = 0, ["param1"] = 195, ["z"] = 13, ["name"] = "the_build_spawner:white"}, {["x"] = 11, ["y"] = 0, ["param1"] = 183, ["z"] = 14, ["name"] = "the_build_spawner:black"}, {["x"] = 11, ["y"] = 0, ["param1"] = 195, ["z"] = 15, ["name"] = "the_build_spawner:white"}, {["x"] = 11, ["y"] = 0, ["param1"] = 183, ["z"] = 16, ["name"] = "the_build_spawner:black"}, {["x"] = 11, ["y"] = 0, ["param1"] = 195, ["z"] = 17, ["name"] = "the_build_spawner:white"}, {["x"] = 11, ["y"] = 0, ["z"] = 18, ["name"] = "the_build_spawner:black"}, {["x"] = 11, ["y"] = 0, ["param1"] = 183, ["z"] = 19, ["name"] = "the_build_spawner:black"}, {["x"] = 11, ["y"] = 0, ["param1"] = 183, ["z"] = 20, ["name"] = "the_build_spawner:black"}, {["x"] = 11, ["y"] = 0, ["param1"] = 183, ["z"] = 21, ["name"] = "the_build_spawner:black"}, {["x"] = 11, ["y"] = 0, ["param1"] = 183, ["z"] = 22, ["name"] = "the_build_spawner:black"}, {["x"] = 11, ["y"] = 0, ["param1"] = 3, ["z"] = 23, ["name"] = "default:cobble"}, {["x"] = 11, ["y"] = 1, ["z"] = 1, ["name"] = "default:cobble"}, {["x"] = 11, ["param2"] = 23, ["y"] = 1, ["param1"] = 153, ["z"] = 2, ["name"] = "stairs:slab_steelblock"}, {["x"] = 11, ["y"] = 1, ["param1"] = 170, ["z"] = 3, ["name"] = "doors:trapdoor_open"}, {["x"] = 11, ["param2"] = 2, ["y"] = 1, ["param1"] = 153, ["z"] = 4, ["name"] = "beds:bed_top"}, {["x"] = 11, ["param2"] = 2, ["y"] = 1, ["param1"] = 153, ["z"] = 5, ["name"] = "beds:bed_bottom"}, {["x"] = 11, ["y"] = 1, ["z"] = 6, ["name"] = "default:steelblock"}, {["x"] = 11, ["y"] = 1, ["param1"] = 153, ["z"] = 7, ["name"] = "xpanes:bar_flat"}, {["x"] = 11, ["param2"] = 23, ["y"] = 1, ["param1"] = 153, ["z"] = 8, ["name"] = "stairs:slab_steelblock"}, {["x"] = 11, ["y"] = 1, ["param1"] = 170, ["z"] = 9, ["name"] = "doors:trapdoor_open"}, {["x"] = 11, ["param2"] = 2, ["y"] = 1, ["param1"] = 153, ["z"] = 10, ["name"] = "beds:bed_top"}, {["x"] = 11, ["param2"] = 2, ["y"] = 1, ["param1"] = 170, ["z"] = 11, ["name"] = "beds:bed_bottom"}, {["x"] = 11, ["y"] = 1, ["param1"] = 70, ["z"] = 12, ["name"] = "default:steelblock"}, {["x"] = 11, ["y"] = 1, ["param1"] = 3, ["z"] = 13, ["name"] = "default:cobble"}, {["x"] = 11, ["meta"] = {["fields"] = {["infotext"] = "\27(T@default)Chest\27E"}, ["inventory"] = {["main"] = {"", "", "", "", "", "", "", "", "", "", "", "", "", "", "", "", "", "", "", "", "", "", "", "", "", "", "", "", "", "", "", ""}}}, ["param2"] = 1, ["y"] = 1, ["param1"] = 187, ["z"] = 14, ["name"] = "default:chest"}, {["x"] = 11, ["meta"] = {["fields"] = {["infotext"] = "\27(T@default)Empty Bookshelf\27E", ["formspec"] = "size[8,7;]list[context;books;0,0.3;8,2;]list[current_player;main;0,2.85;8,1;]list[current_player;main;0,4.08;8,3;8]listring[context;books]listring[current_player;main]image[0,2.85;1,1;gui_hb_bg.png]image[1,2.85;1,1;gui_hb_bg.png]image[2,2.85;1,1;gui_hb_bg.png]image[3,2.85;1,1;gui_hb_bg.png]image[4,2.85;1,1;gui_hb_bg.png]image[5,2.85;1,1;gui_hb_bg.png]image[6,2.85;1,1;gui_hb_bg.png]image[7,2.85;1,1;gui_hb_bg.png]image[0,0.3;1,1;default_bookshelf_slot.png]image[1,0.3;1,1;default_bookshelf_slot.png]image[2,0.3;1,1;default_bookshelf_slot.png]image[3,0.3;1,1;default_bookshelf_slot.png]image[4,0.3;1,1;default_bookshelf_slot.png]image[5,0.3;1,1;default_bookshelf_slot.png]image[6,0.3;1,1;default_bookshelf_slot.png]image[7,0.3;1,1;default_bookshelf_slot.png]image[0,1.3;1,1;default_bookshelf_slot.png]image[1,1.3;1,1;default_bookshelf_slot.png]image[2,1.3;1,1;default_bookshelf_slot.png]image[3,1.3;1,1;default_bookshelf_slot.png]image[4,1.3;1,1;default_bookshelf_slot.png]image[5,1.3;1,1;default_bookshelf_slot.png]image[6,1.3;1,1;default_bookshelf_slot.png]image[7,1.3;1,1;default_bookshelf_slot.png]"}, ["inventory"] = {["books"] = {"", "", "", "", "", "", "", "", "", "", "", "", "", "", "", ""}}}, ["param2"] = 1, ["y"] = 1, ["z"] = 15, ["name"] = "default:bookshelf"}, {["x"] = 11, ["meta"] = {["fields"] = {["infotext"] = "\27(T@default)Empty Bookshelf\27E", ["formspec"] = "size[8,7;]list[context;books;0,0.3;8,2;]list[current_player;main;0,2.85;8,1;]list[current_player;main;0,4.08;8,3;8]listring[context;books]listring[current_player;main]image[0,2.85;1,1;gui_hb_bg.png]image[1,2.85;1,1;gui_hb_bg.png]image[2,2.85;1,1;gui_hb_bg.png]image[3,2.85;1,1;gui_hb_bg.png]image[4,2.85;1,1;gui_hb_bg.png]image[5,2.85;1,1;gui_hb_bg.png]image[6,2.85;1,1;gui_hb_bg.png]image[7,2.85;1,1;gui_hb_bg.png]image[0,0.3;1,1;default_bookshelf_slot.png]image[1,0.3;1,1;default_bookshelf_slot.png]image[2,0.3;1,1;default_bookshelf_slot.png]image[3,0.3;1,1;default_bookshelf_slot.png]image[4,0.3;1,1;default_bookshelf_slot.png]image[5,0.3;1,1;default_bookshelf_slot.png]image[6,0.3;1,1;default_bookshelf_slot.png]image[7,0.3;1,1;default_bookshelf_slot.png]image[0,1.3;1,1;default_bookshelf_slot.png]image[1,1.3;1,1;default_bookshelf_slot.png]image[2,1.3;1,1;default_bookshelf_slot.png]image[3,1.3;1,1;default_bookshelf_slot.png]image[4,1.3;1,1;default_bookshelf_slot.png]image[5,1.3;1,1;default_bookshelf_slot.png]image[6,1.3;1,1;default_bookshelf_slot.png]image[7,1.3;1,1;default_bookshelf_slot.png]"}, ["inventory"] = {["books"] = {"", "", "", "", "", "", "", "", "", "", "", "", "", "", "", ""}}}, ["param2"] = 1, ["y"] = 1, ["z"] = 16, ["name"] = "default:bookshelf"}, {["x"] = 11, ["y"] = 1, ["param1"] = 195, ["z"] = 17, ["name"] = "the_build_spawner:white"}, {["x"] = 11, ["y"] = 2, ["z"] = 1, ["name"] = "default:cobble"}, {["x"] = 11, ["y"] = 2, ["param1"] = 170, ["z"] = 2, ["name"] = "vessels:steel_bottle"}, {["x"] = 11, ["y"] = 2, ["param1"] = 187, ["z"] = 3, ["name"] = "doors:trapdoor_open"}, {["x"] = 11, ["y"] = 2, ["z"] = 6, ["name"] = "default:steelblock"}, {["x"] = 11, ["y"] = 2, ["param1"] = 170, ["z"] = 7, ["name"] = "xpanes:bar_flat"}, {["x"] = 11, ["y"] = 2, ["param1"] = 170, ["z"] = 8, ["name"] = "vessels:steel_bottle"}, {["x"] = 11, ["y"] = 2, ["param1"] = 187, ["z"] = 9, ["name"] = "doors:trapdoor_open"}, {["x"] = 11, ["param2"] = 23, ["y"] = 2, ["param1"] = 170, ["z"] = 10, ["name"] = "stairs:slab_wood"}, {["x"] = 11, ["param2"] = 23, ["y"] = 2, ["param1"] = 187, ["z"] = 11, ["name"] = "stairs:slab_wood"}, {["x"] = 11, ["y"] = 2, ["param1"] = 70, ["z"] = 12, ["name"] = "default:steelblock"}, {["x"] = 11, ["y"] = 2, ["param1"] = 3, ["z"] = 13, ["name"] = "default:cobble"}, {["x"] = 11, ["param2"] = 23, ["y"] = 2, ["param1"] = 204, ["z"] = 14, ["name"] = "stairs:slab_wood"}, {["x"] = 11, ["param2"] = 23, ["y"] = 2, ["param1"] = 187, ["z"] = 15, ["name"] = "stairs:slab_wood"}, {["x"] = 11, ["param2"] = 20, ["y"] = 2, ["param1"] = 204, ["z"] = 16, ["name"] = "stairs:stair_wood"}, {["x"] = 11, ["y"] = 2, ["param1"] = 195, ["z"] = 17, ["name"] = "the_build_spawner:white"}, {["x"] = 11, ["y"] = 3, ["z"] = 1, ["name"] = "default:cobble"}, {["x"] = 11, ["y"] = 3, ["param1"] = 204, ["z"] = 3, ["name"] = "doors:trapdoor_open"}, {["x"] = 11, ["param2"] = 2, ["y"] = 3, ["param1"] = 187, ["z"] = 4, ["name"] = "beds:bed_top"}, {["x"] = 11, ["param2"] = 2, ["y"] = 3, ["param1"] = 187, ["z"] = 5, ["name"] = "beds:bed_bottom"}, {["x"] = 11, ["y"] = 3, ["z"] = 6, ["name"] = "default:steelblock"}, {["x"] = 11, ["y"] = 3, ["param1"] = 187, ["z"] = 7, ["name"] = "xpanes:bar_flat"}, {["x"] = 11, ["y"] = 3, ["param1"] = 204, ["z"] = 9, ["name"] = "doors:trapdoor_open"}, {["x"] = 11, ["param2"] = 2, ["y"] = 3, ["param1"] = 187, ["z"] = 10, ["name"] = "beds:bed_top"}, {["x"] = 11, ["param2"] = 2, ["y"] = 3, ["param1"] = 204, ["z"] = 11, ["name"] = "beds:bed_bottom"}, {["x"] = 11, ["y"] = 3, ["param1"] = 70, ["z"] = 12, ["name"] = "default:steelblock"}, {["x"] = 11, ["y"] = 3, ["param1"] = 3, ["z"] = 13, ["name"] = "default:cobble"}, {["x"] = 11, ["param2"] = 22, ["y"] = 3, ["param1"] = 221, ["z"] = 14, ["name"] = "stairs:stair_wood"}, {["x"] = 11, ["param2"] = 23, ["y"] = 3, ["param1"] = 204, ["z"] = 15, ["name"] = "stairs:slab_wood"}, {["x"] = 11, ["param2"] = 23, ["y"] = 3, ["param1"] = 221, ["z"] = 16, ["name"] = "stairs:slab_wood"}, {["x"] = 11, ["y"] = 3, ["param1"] = 195, ["z"] = 17, ["name"] = "the_build_spawner:white"}, {["x"] = 11, ["y"] = 4, ["z"] = 1, ["name"] = "default:cobble"}, {["x"] = 11, ["y"] = 4, ["param1"] = 204, ["z"] = 7, ["name"] = "xpanes:bar_flat"}, {["x"] = 11, ["y"] = 4, ["param1"] = 3, ["z"] = 13, ["name"] = "default:cobble"}, {["x"] = 11, ["y"] = 4, ["param1"] = 238, ["z"] = 14, ["name"] = "default:meselamp"}, {["x"] = 11, ["y"] = 4, ["param1"] = 238, ["z"] = 16, ["name"] = "default:meselamp"}, {["x"] = 11, ["y"] = 4, ["param1"] = 195, ["z"] = 17, ["name"] = "the_build_spawner:white"}, {["x"] = 11, ["y"] = 5, ["z"] = 1, ["name"] = "the_build_spawner:dark_blue"}, {["x"] = 11, ["y"] = 5, ["z"] = 2, ["name"] = "the_build_spawner:dark_blue"}, {["x"] = 11, ["y"] = 5, ["param1"] = 15, ["z"] = 3, ["name"] = "the_build_spawner:dark_blue"}, {["x"] = 11, ["y"] = 5, ["param1"] = 15, ["z"] = 4, ["name"] = "the_build_spawner:dark_blue"}, {["x"] = 11, ["y"] = 5, ["param1"] = 15, ["z"] = 5, ["name"] = "the_build_spawner:dark_blue"}, {["x"] = 11, ["y"] = 5, ["param1"] = 15, ["z"] = 6, ["name"] = "the_build_spawner:dark_blue"}, {["x"] = 11, ["y"] = 5, ["param1"] = 15, ["z"] = 7, ["name"] = "the_build_spawner:dark_blue"}, {["x"] = 11, ["y"] = 5, ["param1"] = 15, ["z"] = 8, ["name"] = "the_build_spawner:dark_blue"}, {["x"] = 11, ["y"] = 5, ["param1"] = 15, ["z"] = 9, ["name"] = "the_build_spawner:dark_blue"}, {["x"] = 11, ["y"] = 5, ["param1"] = 14, ["z"] = 10, ["name"] = "the_build_spawner:dark_blue"}, {["x"] = 11, ["y"] = 5, ["param1"] = 198, ["z"] = 11, ["name"] = "the_build_spawner:dark_blue"}, {["x"] = 11, ["y"] = 5, ["param1"] = 198, ["z"] = 12, ["name"] = "the_build_spawner:dark_blue"}, {["x"] = 11, ["y"] = 5, ["param1"] = 198, ["z"] = 13, ["name"] = "the_build_spawner:dark_blue"}, {["x"] = 11, ["y"] = 5, ["param1"] = 198, ["z"] = 14, ["name"] = "the_build_spawner:dark_blue"}, {["x"] = 11, ["y"] = 5, ["param1"] = 198, ["z"] = 15, ["name"] = "the_build_spawner:dark_blue"}, {["x"] = 11, ["y"] = 5, ["param1"] = 198, ["z"] = 16, ["name"] = "the_build_spawner:dark_blue"}, {["x"] = 11, ["y"] = 5, ["param1"] = 198, ["z"] = 17, ["name"] = "the_build_spawner:dark_blue"}, {["x"] = 12, ["y"] = 0, ["z"] = 0, ["name"] = "default:cobble"}, {["x"] = 12, ["y"] = 0, ["z"] = 1, ["name"] = "the_build_spawner:white"}, {["x"] = 12, ["y"] = 0, ["z"] = 2, ["name"] = "the_build_spawner:white"}, {["x"] = 12, ["y"] = 0, ["z"] = 3, ["name"] = "the_build_spawner:white"}, {["x"] = 12, ["y"] = 0, ["z"] = 4, ["name"] = "the_build_spawner:white"}, {["x"] = 12, ["y"] = 0, ["z"] = 5, ["name"] = "the_build_spawner:white"}, {["x"] = 12, ["y"] = 0, ["z"] = 6, ["name"] = "the_build_spawner:white"}, {["x"] = 12, ["y"] = 0, ["z"] = 7, ["name"] = "the_build_spawner:white"}, {["x"] = 12, ["y"] = 0, ["z"] = 8, ["name"] = "the_build_spawner:white"}, {["x"] = 12, ["y"] = 0, ["z"] = 9, ["name"] = "the_build_spawner:white"}, {["x"] = 12, ["y"] = 0, ["z"] = 10, ["name"] = "the_build_spawner:white"}, {["x"] = 12, ["y"] = 0, ["param1"] = 195, ["z"] = 11, ["name"] = "the_build_spawner:white"}, {["x"] = 12, ["y"] = 0, ["param1"] = 195, ["z"] = 12, ["name"] = "the_build_spawner:white"}, {["x"] = 12, ["y"] = 0, ["param1"] = 195, ["z"] = 13, ["name"] = "the_build_spawner:white"}, {["x"] = 12, ["y"] = 0, ["param1"] = 195, ["z"] = 14, ["name"] = "the_build_spawner:white"}, {["x"] = 12, ["y"] = 0, ["param1"] = 195, ["z"] = 15, ["name"] = "the_build_spawner:white"}, {["x"] = 12, ["y"] = 0, ["param1"] = 195, ["z"] = 16, ["name"] = "the_build_spawner:white"}, {["x"] = 12, ["y"] = 0, ["param1"] = 195, ["z"] = 17, ["name"] = "the_build_spawner:white"}, {["x"] = 12, ["y"] = 0, ["z"] = 18, ["name"] = "the_build_spawner:black"}, {["x"] = 12, ["y"] = 0, ["param1"] = 183, ["z"] = 19, ["name"] = "the_build_spawner:black"}, {["x"] = 12, ["y"] = 0, ["param1"] = 183, ["z"] = 20, ["name"] = "the_build_spawner:black"}, {["x"] = 12, ["y"] = 0, ["param1"] = 183, ["z"] = 21, ["name"] = "the_build_spawner:black"}, {["x"] = 12, ["y"] = 0, ["param1"] = 183, ["z"] = 22, ["name"] = "the_build_spawner:black"}, {["x"] = 12, ["y"] = 0, ["param1"] = 3, ["z"] = 23, ["name"] = "default:cobble"}, {["x"] = 12, ["y"] = 1, ["z"] = 1, ["name"] = "default:cobble"}, {["x"] = 12, ["y"] = 1, ["z"] = 2, ["name"] = "default:cobble"}, {["x"] = 12, ["y"] = 1, ["z"] = 3, ["name"] = "default:cobble"}, {["x"] = 12, ["y"] = 1, ["z"] = 4, ["name"] = "default:cobble"}, {["x"] = 12, ["y"] = 1, ["z"] = 5, ["name"] = "default:cobble"}, {["x"] = 12, ["y"] = 1, ["z"] = 6, ["name"] = "default:cobble"}, {["x"] = 12, ["y"] = 1, ["z"] = 7, ["name"] = "default:cobble"}, {["x"] = 12, ["y"] = 1, ["z"] = 8, ["name"] = "default:cobble"}, {["x"] = 12, ["y"] = 1, ["z"] = 9, ["name"] = "default:cobble"}, {["x"] = 12, ["y"] = 1, ["z"] = 10, ["name"] = "default:cobble"}, {["x"] = 12, ["y"] = 1, ["param1"] = 3, ["z"] = 11, ["name"] = "default:cobble"}, {["x"] = 12, ["y"] = 1, ["param1"] = 3, ["z"] = 12, ["name"] = "default:cobble"}, {["x"] = 12, ["y"] = 1, ["param1"] = 3, ["z"] = 13, ["name"] = "default:cobble"}, {["x"] = 12, ["y"] = 1, ["param1"] = 195, ["z"] = 14, ["name"] = "the_build_spawner:white"}, {["x"] = 12, ["y"] = 1, ["param1"] = 195, ["z"] = 15, ["name"] = "the_build_spawner:white"}, {["x"] = 12, ["y"] = 1, ["param1"] = 195, ["z"] = 16, ["name"] = "the_build_spawner:white"}, {["x"] = 12, ["y"] = 1, ["param1"] = 195, ["z"] = 17, ["name"] = "the_build_spawner:white"}, {["x"] = 12, ["y"] = 2, ["z"] = 1, ["name"] = "default:cobble"}, {["x"] = 12, ["y"] = 2, ["z"] = 2, ["name"] = "default:cobble"}, {["x"] = 12, ["y"] = 2, ["z"] = 3, ["name"] = "default:cobble"}, {["x"] = 12, ["y"] = 2, ["z"] = 4, ["name"] = "default:cobble"}, {["x"] = 12, ["y"] = 2, ["z"] = 5, ["name"] = "default:cobble"}, {["x"] = 12, ["y"] = 2, ["z"] = 6, ["name"] = "default:cobble"}, {["x"] = 12, ["y"] = 2, ["z"] = 7, ["name"] = "default:cobble"}, {["x"] = 12, ["y"] = 2, ["z"] = 8, ["name"] = "default:cobble"}, {["x"] = 12, ["y"] = 2, ["z"] = 9, ["name"] = "default:cobble"}, {["x"] = 12, ["y"] = 2, ["z"] = 10, ["name"] = "default:cobble"}, {["x"] = 12, ["y"] = 2, ["param1"] = 3, ["z"] = 11, ["name"] = "default:cobble"}, {["x"] = 12, ["y"] = 2, ["param1"] = 3, ["z"] = 12, ["name"] = "default:cobble"}, {["x"] = 12, ["y"] = 2, ["param1"] = 3, ["z"] = 13, ["name"] = "default:cobble"}, {["x"] = 12, ["y"] = 2, ["param1"] = 195, ["z"] = 14, ["name"] = "the_build_spawner:white"}, {["x"] = 12, ["y"] = 2, ["param1"] = 195, ["z"] = 15, ["name"] = "the_build_spawner:white"}, {["x"] = 12, ["y"] = 2, ["param1"] = 195, ["z"] = 16, ["name"] = "the_build_spawner:white"}, {["x"] = 12, ["y"] = 2, ["param1"] = 195, ["z"] = 17, ["name"] = "the_build_spawner:white"}, {["x"] = 12, ["y"] = 3, ["z"] = 1, ["name"] = "default:cobble"}, {["x"] = 12, ["y"] = 3, ["z"] = 2, ["name"] = "default:cobble"}, {["x"] = 12, ["y"] = 3, ["z"] = 3, ["name"] = "default:cobble"}, {["x"] = 12, ["y"] = 3, ["z"] = 4, ["name"] = "default:cobble"}, {["x"] = 12, ["y"] = 3, ["z"] = 5, ["name"] = "default:cobble"}, {["x"] = 12, ["y"] = 3, ["z"] = 6, ["name"] = "default:cobble"}, {["x"] = 12, ["y"] = 3, ["z"] = 7, ["name"] = "default:cobble"}, {["x"] = 12, ["y"] = 3, ["z"] = 8, ["name"] = "default:cobble"}, {["x"] = 12, ["y"] = 3, ["z"] = 9, ["name"] = "default:cobble"}, {["x"] = 12, ["y"] = 3, ["z"] = 10, ["name"] = "default:cobble"}, {["x"] = 12, ["y"] = 3, ["param1"] = 3, ["z"] = 11, ["name"] = "default:cobble"}, {["x"] = 12, ["y"] = 3, ["param1"] = 3, ["z"] = 12, ["name"] = "default:cobble"}, {["x"] = 12, ["y"] = 3, ["param1"] = 3, ["z"] = 13, ["name"] = "default:cobble"}, {["x"] = 12, ["y"] = 3, ["param1"] = 195, ["z"] = 14, ["name"] = "the_build_spawner:white"}, {["x"] = 12, ["y"] = 3, ["param1"] = 195, ["z"] = 15, ["name"] = "the_build_spawner:white"}, {["x"] = 12, ["y"] = 3, ["param1"] = 195, ["z"] = 16, ["name"] = "the_build_spawner:white"}, {["x"] = 12, ["y"] = 3, ["param1"] = 195, ["z"] = 17, ["name"] = "the_build_spawner:white"}, {["x"] = 12, ["y"] = 4, ["z"] = 1, ["name"] = "default:cobble"}, {["x"] = 12, ["y"] = 4, ["z"] = 2, ["name"] = "default:cobble"}, {["x"] = 12, ["y"] = 4, ["z"] = 3, ["name"] = "default:cobble"}, {["x"] = 12, ["y"] = 4, ["z"] = 4, ["name"] = "default:cobble"}, {["x"] = 12, ["y"] = 4, ["z"] = 5, ["name"] = "default:cobble"}, {["x"] = 12, ["y"] = 4, ["z"] = 6, ["name"] = "default:cobble"}, {["x"] = 12, ["y"] = 4, ["z"] = 7, ["name"] = "default:cobble"}, {["x"] = 12, ["y"] = 4, ["z"] = 8, ["name"] = "default:cobble"}, {["x"] = 12, ["y"] = 4, ["z"] = 9, ["name"] = "default:cobble"}, {["x"] = 12, ["y"] = 4, ["z"] = 10, ["name"] = "default:cobble"}, {["x"] = 12, ["y"] = 4, ["param1"] = 3, ["z"] = 11, ["name"] = "default:cobble"}, {["x"] = 12, ["y"] = 4, ["param1"] = 3, ["z"] = 12, ["name"] = "default:cobble"}, {["x"] = 12, ["y"] = 4, ["param1"] = 3, ["z"] = 13, ["name"] = "default:cobble"}, {["x"] = 12, ["y"] = 4, ["param1"] = 195, ["z"] = 14, ["name"] = "the_build_spawner:white"}, {["x"] = 12, ["y"] = 4, ["param1"] = 195, ["z"] = 15, ["name"] = "the_build_spawner:white"}, {["x"] = 12, ["y"] = 4, ["param1"] = 195, ["z"] = 16, ["name"] = "the_build_spawner:white"}, {["x"] = 12, ["y"] = 4, ["param1"] = 195, ["z"] = 17, ["name"] = "the_build_spawner:white"}, {["x"] = 12, ["y"] = 5, ["z"] = 1, ["name"] = "the_build_spawner:dark_blue"}, {["x"] = 12, ["y"] = 5, ["z"] = 2, ["name"] = "the_build_spawner:dark_blue"}, {["x"] = 12, ["y"] = 5, ["z"] = 3, ["name"] = "the_build_spawner:dark_blue"}, {["x"] = 12, ["y"] = 5, ["z"] = 4, ["name"] = "the_build_spawner:dark_blue"}, {["x"] = 12, ["y"] = 5, ["z"] = 5, ["name"] = "the_build_spawner:dark_blue"}, {["x"] = 12, ["y"] = 5, ["z"] = 6, ["name"] = "the_build_spawner:dark_blue"}, {["x"] = 12, ["y"] = 5, ["z"] = 7, ["name"] = "the_build_spawner:dark_blue"}, {["x"] = 12, ["y"] = 5, ["z"] = 8, ["name"] = "the_build_spawner:dark_blue"}, {["x"] = 12, ["y"] = 5, ["z"] = 9, ["name"] = "the_build_spawner:dark_blue"}, {["x"] = 12, ["y"] = 5, ["z"] = 10, ["name"] = "the_build_spawner:dark_blue"}, {["x"] = 12, ["y"] = 5, ["param1"] = 198, ["z"] = 11, ["name"] = "the_build_spawner:dark_blue"}, {["x"] = 12, ["y"] = 5, ["param1"] = 198, ["z"] = 12, ["name"] = "the_build_spawner:dark_blue"}, {["x"] = 12, ["y"] = 5, ["param1"] = 198, ["z"] = 13, ["name"] = "the_build_spawner:dark_blue"}, {["x"] = 12, ["y"] = 5, ["param1"] = 198, ["z"] = 14, ["name"] = "the_build_spawner:dark_blue"}, {["x"] = 12, ["y"] = 5, ["param1"] = 198, ["z"] = 15, ["name"] = "the_build_spawner:dark_blue"}, {["x"] = 12, ["y"] = 5, ["param1"] = 198, ["z"] = 16, ["name"] = "the_build_spawner:dark_blue"}, {["x"] = 12, ["y"] = 5, ["param1"] = 198, ["z"] = 17, ["name"] = "the_build_spawner:dark_blue"}, {["x"] = 13, ["y"] = 0, ["z"] = 0, ["name"] = "default:cobble"}, {["x"] = 13, ["y"] = 0, ["z"] = 1, ["name"] = "default:cobble"}, {["x"] = 13, ["y"] = 0, ["z"] = 2, ["name"] = "default:cobble"}, {["x"] = 13, ["y"] = 0, ["z"] = 3, ["name"] = "default:cobble"}, {["x"] = 13, ["y"] = 0, ["z"] = 4, ["name"] = "default:cobble"}, {["x"] = 13, ["y"] = 0, ["z"] = 5, ["name"] = "default:cobble"}, {["x"] = 13, ["y"] = 0, ["z"] = 6, ["name"] = "default:cobble"}, {["x"] = 13, ["y"] = 0, ["z"] = 7, ["name"] = "default:cobble"}, {["x"] = 13, ["y"] = 0, ["z"] = 8, ["name"] = "default:cobble"}, {["x"] = 13, ["y"] = 0, ["z"] = 9, ["name"] = "default:cobble"}, {["x"] = 13, ["y"] = 0, ["z"] = 10, ["name"] = "default:cobble"}, {["x"] = 13, ["y"] = 0, ["param1"] = 3, ["z"] = 11, ["name"] = "default:cobble"}, {["x"] = 13, ["y"] = 0, ["param1"] = 3, ["z"] = 12, ["name"] = "default:cobble"}, {["x"] = 13, ["y"] = 0, ["param1"] = 3, ["z"] = 13, ["name"] = "default:cobble"}, {["x"] = 13, ["y"] = 0, ["param1"] = 3, ["z"] = 14, ["name"] = "default:cobble"}, {["x"] = 13, ["y"] = 0, ["param1"] = 3, ["z"] = 15, ["name"] = "default:cobble"}, {["x"] = 13, ["y"] = 0, ["param1"] = 3, ["z"] = 16, ["name"] = "default:cobble"}, {["x"] = 13, ["y"] = 0, ["param1"] = 3, ["z"] = 17, ["name"] = "default:cobble"}, {["x"] = 13, ["y"] = 0, ["param1"] = 3, ["z"] = 18, ["name"] = "default:cobble"}, {["x"] = 13, ["y"] = 0, ["param1"] = 3, ["z"] = 19, ["name"] = "default:cobble"}, {["x"] = 13, ["y"] = 0, ["param1"] = 3, ["z"] = 20, ["name"] = "default:cobble"}, {["x"] = 13, ["y"] = 0, ["param1"] = 3, ["z"] = 21, ["name"] = "default:cobble"}, {["x"] = 13, ["y"] = 0, ["param1"] = 3, ["z"] = 22, ["name"] = "default:cobble"}, {["x"] = 13, ["y"] = 0, ["param1"] = 3, ["z"] = 23, ["name"] = "default:cobble"}}