5:return {{["x"] = 0, ["y"] = 0, ["z"] = 1, ["name"] = "the_build_spawner:yellow"}, {["x"] = 0, ["y"] = 0, ["z"] = 2, ["name"] = "the_build_spawner:yellow"}, {["x"] = 0, ["y"] = 0, ["z"] = 3, ["name"] = "the_build_spawner:yellow"}, {["x"] = 0, ["y"] = 0, ["z"] = 4, ["name"] = "the_build_spawner:yellow"}, {["x"] = 0, ["y"] = 0, ["z"] = 5, ["name"] = "the_build_spawner:yellow"}, {["x"] = 0, ["y"] = 0, ["z"] = 6, ["name"] = "the_build_spawner:yellow"}, {["x"] = 0, ["y"] = 0, ["z"] = 7, ["name"] = "the_build_spawner:yellow"}, {["x"] = 0, ["y"] = 0, ["param1"] = 15, ["z"] = 8, ["name"] = "default:junglewood"}, {["x"] = 0, ["y"] = 0, ["param1"] = 15, ["z"] = 9, ["name"] = "default:junglewood"}, {["x"] = 0, ["y"] = 0, ["param1"] = 15, ["z"] = 10, ["name"] = "default:junglewood"}, {["x"] = 0, ["y"] = 0, ["param1"] = 15, ["z"] = 11, ["name"] = "default:junglewood"}, {["x"] = 0, ["y"] = 0, ["z"] = 12, ["name"] = "default:junglewood"}, {["x"] = 0, ["y"] = 0, ["z"] = 13, ["name"] = "default:junglewood"}, {["x"] = 0, ["y"] = 1, ["z"] = 1, ["name"] = "the_build_spawner:yellow"}, {["x"] = 0, ["y"] = 1, ["z"] = 2, ["name"] = "the_build_spawner:yellow"}, {["x"] = 0, ["y"] = 1, ["z"] = 3, ["name"] = "the_build_spawner:yellow"}, {["x"] = 0, ["y"] = 1, ["z"] = 4, ["name"] = "the_build_spawner:yellow"}, {["x"] = 0, ["y"] = 1, ["z"] = 5, ["name"] = "the_build_spawner:yellow"}, {["x"] = 0, ["y"] = 1, ["z"] = 6, ["name"] = "the_build_spawner:yellow"}, {["x"] = 0, ["y"] = 1, ["z"] = 7, ["name"] = "the_build_spawner:yellow"}, {["x"] = 0, ["y"] = 1, ["param1"] = 126, ["z"] = 8, ["name"] = "default:fence_wood"}, {["x"] = 0, ["y"] = 1, ["param1"] = 109, ["z"] = 9, ["name"] = "default:fence_wood"}, {["x"] = 0, ["y"] = 1, ["param1"] = 94, ["z"] = 10, ["name"] = "default:fence_wood"}, {["x"] = 0, ["y"] = 1, ["param1"] = 79, ["z"] = 11, ["name"] = "default:fence_wood"}, {["x"] = 0, ["y"] = 1, ["param1"] = 63, ["z"] = 12, ["name"] = "default:fence_wood"}, {["x"] = 0, ["y"] = 1, ["param1"] = 47, ["z"] = 13, ["name"] = "default:fence_wood"}, {["x"] = 0, ["y"] = 2, ["z"] = 1, ["name"] = "the_build_spawner:yellow"}, {["x"] = 0, ["y"] = 2, ["z"] = 2, ["name"] = "the_build_spawner:yellow"}, {["x"] = 0, ["y"] = 2, ["z"] = 3, ["name"] = "the_build_spawner:yellow"}, {["x"] = 0, ["y"] = 2, ["z"] = 4, ["name"] = "the_build_spawner:yellow"}, {["x"] = 0, ["y"] = 2, ["z"] = 5, ["name"] = "the_build_spawner:yellow"}, {["x"] = 0, ["y"] = 2, ["z"] = 6, ["name"] = "the_build_spawner:yellow"}, {["x"] = 0, ["y"] = 2, ["z"] = 7, ["name"] = "the_build_spawner:yellow"}, {["x"] = 0, ["y"] = 3, ["z"] = 1, ["name"] = "the_build_spawner:yellow"}, {["x"] = 0, ["y"] = 3, ["z"] = 2, ["name"] = "the_build_spawner:yellow"}, {["x"] = 0, ["y"] = 3, ["z"] = 3, ["name"] = "the_build_spawner:yellow"}, {["x"] = 0, ["y"] = 3, ["z"] = 4, ["name"] = "the_build_spawner:yellow"}, {["x"] = 0, ["y"] = 3, ["z"] = 5, ["name"] = "the_build_spawner:yellow"}, {["x"] = 0, ["y"] = 3, ["z"] = 6, ["name"] = "the_build_spawner:yellow"}, {["x"] = 0, ["y"] = 3, ["z"] = 7, ["name"] = "the_build_spawner:yellow"}, {["x"] = 0, ["y"] = 4, ["z"] = 1, ["name"] = "the_build_spawner:yellow"}, {["x"] = 0, ["y"] = 4, ["z"] = 2, ["name"] = "the_build_spawner:yellow"}, {["x"] = 0, ["y"] = 4, ["z"] = 3, ["name"] = "the_build_spawner:yellow"}, {["x"] = 0, ["y"] = 4, ["z"] = 4, ["name"] = "the_build_spawner:yellow"}, {["x"] = 0, ["y"] = 4, ["z"] = 5, ["name"] = "the_build_spawner:yellow"}, {["x"] = 0, ["y"] = 4, ["z"] = 6, ["name"] = "the_build_spawner:yellow"}, {["x"] = 0, ["y"] = 4, ["z"] = 7, ["name"] = "the_build_spawner:yellow"}, {["x"] = 0, ["y"] = 4, ["z"] = 8, ["name"] = "wool:black"}, {["x"] = 0, ["y"] = 4, ["z"] = 9, ["name"] = "wool:black"}, {["x"] = 0, ["y"] = 5, ["param1"] = 190, ["z"] = 1, ["name"] = "default:fence_wood"}, {["x"] = 0, ["y"] = 5, ["param1"] = 174, ["z"] = 2, ["name"] = "default:fence_wood"}, {["x"] = 0, ["y"] = 5, ["param1"] = 158, ["z"] = 3, ["name"] = "default:fence_wood"}, {["x"] = 0, ["y"] = 5, ["param1"] = 142, ["z"] = 4, ["name"] = "default:fence_wood"}, {["x"] = 0, ["y"] = 5, ["param1"] = 158, ["z"] = 5, ["name"] = "default:fence_wood"}, {["x"] = 0, ["y"] = 5, ["param1"] = 174, ["z"] = 6, ["name"] = "default:fence_wood"}, {["x"] = 0, ["y"] = 5, ["param1"] = 190, ["z"] = 7, ["name"] = "default:fence_wood"}, {["x"] = 1, ["y"] = 0, ["z"] = 1, ["name"] = "the_build_spawner:yellow"}, {["x"] = 1, ["y"] = 0, ["z"] = 2, ["name"] = "default:junglewood"}, {["x"] = 1, ["y"] = 0, ["param1"] = 15, ["z"] = 3, ["name"] = "default:junglewood"}, {["x"] = 1, ["y"] = 0, ["param1"] = 15, ["z"] = 4, ["name"] = "default:junglewood"}, {["x"] = 1, ["y"] = 0, ["param1"] = 15, ["z"] = 5, ["name"] = "default:junglewood"}, {["x"] = 1, ["y"] = 0, ["param1"] = 15, ["z"] = 6, ["name"] = "default:junglewood"}, {["x"] = 1, ["y"] = 0, ["z"] = 7, ["name"] = "the_build_spawner:yellow"}, {["x"] = 1, ["y"] = 0, ["param1"] = 15, ["z"] = 8, ["name"] = "default:junglewood"}, {["x"] = 1, ["y"] = 0, ["param1"] = 15, ["z"] = 9, ["name"] = "default:junglewood"}, {["x"] = 1, ["y"] = 0, ["param1"] = 15, ["z"] = 10, ["name"] = "default:junglewood"}, {["x"] = 1, ["y"] = 0, ["param1"] = 15, ["z"] = 11, ["name"] = "default:junglewood"}, {["x"] = 1, ["y"] = 0, ["param1"] = 15, ["z"] = 12, ["name"] = "default:junglewood"}, {["x"] = 1, ["param2"] = 2, ["y"] = 0, ["param1"] = 46, ["z"] = 13, ["name"] = "stairs:stair_junglewood"}, {["x"] = 1, ["y"] = 1, ["z"] = 1, ["name"] = "the_build_spawner:yellow"}, {["x"] = 1, ["meta"] = {["fields"] = {["timer_elapsed"] = "0", ["formspec"] = "size[8,8.5]list[context;src;2.75,0.5;1,1;]list[context;fuel;2.75,2.5;1,1;]image[2.75,1.5;1,1;default_furnace_fire_bg.png]image[3.75,1.5;1,1;gui_furnace_arrow_bg.png^[transformR270]list[context;dst;4.75,0.96;2,2;]list[current_player;main;0,4.25;8,1;]list[current_player;main;0,5.5;8,3;8]listring[context;dst]listring[current_player;main]listring[context;src]listring[current_player;main]listring[context;fuel]listring[current_player;main]image[0,4.25;1,1;gui_hb_bg.png]image[1,4.25;1,1;gui_hb_bg.png]image[2,4.25;1,1;gui_hb_bg.png]image[3,4.25;1,1;gui_hb_bg.png]image[4,4.25;1,1;gui_hb_bg.png]image[5,4.25;1,1;gui_hb_bg.png]image[6,4.25;1,1;gui_hb_bg.png]image[7,4.25;1,1;gui_hb_bg.png]", ["fuel_time"] = "0", ["fuel_totaltime"] = "0", ["src_time"] = "0", ["infotext"] = "\27(T@default)Furnace inactive\27E\
\27(T@default)(Item: \27F\27(T@default)Empty\27E\27E; Fuel: \27F\27(T@default)Empty\27E\27E)\27E"}, ["inventory"] = {["fuel"] = {""}, ["dst"] = {"", "", "", ""}, ["src"] = {""}}}, ["param2"] = 2, ["y"] = 1, ["z"] = 2, ["name"] = "default:furnace"}, {["x"] = 1, ["meta"] = {["fields"] = {["infotext"] = "\27(T@default)Chest\27E"}, ["inventory"] = {["main"] = {"", "", "", "", "", "", "", "", "", "", "", "", "", "", "", "", "", "", "", "", "", "", "", "", "", "", "", "", "", "", "", ""}}}, ["y"] = 1, ["param1"] = 142, ["z"] = 4, ["name"] = "default:chest"}, {["x"] = 1, ["meta"] = {["fields"] = {["state"] = "0"}, ["inventory"] = {}}, ["y"] = 1, ["param1"] = 158, ["z"] = 7, ["name"] = "doors:door_wood_a"}, {["x"] = 1, ["y"] = 2, ["z"] = 1, ["name"] = "the_build_spawner:yellow"}, {["x"] = 1, ["param2"] = 22, ["y"] = 2, ["param1"] = 190, ["z"] = 2, ["name"] = "stairs:slab_wood"}, {["x"] = 1, ["param2"] = 2, ["y"] = 2, ["param1"] = 158, ["z"] = 4, ["name"] = "doors:trapdoor"}, {["x"] = 1, ["y"] = 2, ["param1"] = 174, ["z"] = 7, ["name"] = "doors:hidden"}, {["x"] = 1, ["y"] = 3, ["z"] = 1, ["name"] = "the_build_spawner:yellow"}, {["x"] = 1, ["y"] = 3, ["param1"] = 206, ["z"] = 2, ["name"] = "flowers:dandelion_white"}, {["x"] = 1, ["param2"] = 2, ["y"] = 3, ["param1"] = 190, ["z"] = 7, ["name"] = "doors:trapdoor_open"}, {["x"] = 1, ["y"] = 4, ["z"] = 1, ["name"] = "the_build_spawner:yellow"}, {["x"] = 1, ["y"] = 4, ["z"] = 2, ["name"] = "default:junglewood"}, {["x"] = 1, ["y"] = 4, ["param1"] = 15, ["z"] = 3, ["name"] = "default:junglewood"}, {["x"] = 1, ["y"] = 4, ["param1"] = 15, ["z"] = 4, ["name"] = "default:junglewood"}, {["x"] = 1, ["y"] = 4, ["param1"] = 15, ["z"] = 5, ["name"] = "default:junglewood"}, {["x"] = 1, ["y"] = 4, ["param1"] = 15, ["z"] = 6, ["name"] = "default:junglewood"}, {["x"] = 1, ["y"] = 4, ["z"] = 7, ["name"] = "the_build_spawner:yellow"}, {["x"] = 1, ["y"] = 4, ["z"] = 8, ["name"] = "wool:white"}, {["x"] = 1, ["y"] = 4, ["z"] = 9, ["name"] = "wool:white"}, {["x"] = 1, ["y"] = 5, ["param1"] = 206, ["z"] = 1, ["name"] = "default:fence_wood"}, {["x"] = 1, ["param2"] = 3, ["y"] = 5, ["param1"] = 189, ["z"] = 2, ["name"] = "stairs:stair_junglewood"}, {["x"] = 1, ["param2"] = 3, ["y"] = 5, ["param1"] = 174, ["z"] = 5, ["name"] = "stairs:stair_junglewood"}, {["x"] = 1, ["param2"] = 3, ["y"] = 5, ["param1"] = 189, ["z"] = 6, ["name"] = "stairs:stair_junglewood"}, {["x"] = 1, ["y"] = 5, ["param1"] = 206, ["z"] = 7, ["name"] = "default:fence_wood"}, {["x"] = 2, ["y"] = 0, ["z"] = 1, ["name"] = "the_build_spawner:yellow"}, {["x"] = 2, ["y"] = 0, ["param1"] = 15, ["z"] = 2, ["name"] = "default:junglewood"}, {["x"] = 2, ["y"] = 0, ["param1"] = 15, ["z"] = 3, ["name"] = "default:junglewood"}, {["x"] = 2, ["y"] = 0, ["param1"] = 15, ["z"] = 4, ["name"] = "default:junglewood"}, {["x"] = 2, ["y"] = 0, ["param1"] = 15, ["z"] = 5, ["name"] = "default:junglewood"}, {["x"] = 2, ["y"] = 0, ["param1"] = 15, ["z"] = 6, ["name"] = "default:junglewood"}, {["x"] = 2, ["y"] = 0, ["z"] = 7, ["name"] = "the_build_spawner:yellow"}, {["x"] = 2, ["y"] = 0, ["param1"] = 15, ["z"] = 8, ["name"] = "default:junglewood"}, {["x"] = 2, ["y"] = 0, ["param1"] = 15, ["z"] = 9, ["name"] = "default:junglewood"}, {["x"] = 2, ["y"] = 0, ["param1"] = 15, ["z"] = 10, ["name"] = "default:junglewood"}, {["x"] = 2, ["y"] = 0, ["param1"] = 15, ["z"] = 11, ["name"] = "default:junglewood"}, {["x"] = 2, ["y"] = 0, ["param1"] = 15, ["z"] = 12, ["name"] = "default:junglewood"}, {["x"] = 2, ["param2"] = 2, ["y"] = 0, ["param1"] = 62, ["z"] = 13, ["name"] = "stairs:stair_junglewood"}, {["x"] = 2, ["y"] = 1, ["z"] = 1, ["name"] = "the_build_spawner:yellow"}, {["x"] = 2, ["meta"] = {["fields"] = {["timer_elapsed"] = "0", ["formspec"] = "size[8,8.5]list[context;src;2.75,0.5;1,1;]list[context;fuel;2.75,2.5;1,1;]image[2.75,1.5;1,1;default_furnace_fire_bg.png]image[3.75,1.5;1,1;gui_furnace_arrow_bg.png^[transformR270]list[context;dst;4.75,0.96;2,2;]list[current_player;main;0,4.25;8,1;]list[current_player;main;0,5.5;8,3;8]listring[context;dst]listring[current_player;main]listring[context;src]listring[current_player;main]listring[context;fuel]listring[current_player;main]image[0,4.25;1,1;gui_hb_bg.png]image[1,4.25;1,1;gui_hb_bg.png]image[2,4.25;1,1;gui_hb_bg.png]image[3,4.25;1,1;gui_hb_bg.png]image[4,4.25;1,1;gui_hb_bg.png]image[5,4.25;1,1;gui_hb_bg.png]image[6,4.25;1,1;gui_hb_bg.png]image[7,4.25;1,1;gui_hb_bg.png]", ["fuel_time"] = "0", ["fuel_totaltime"] = "0", ["src_time"] = "0", ["infotext"] = "\27(T@default)Furnace inactive\27E\
\27(T@default)(Item: \27F\27(T@default)Empty\27E\27E; Fuel: \27F\27(T@default)Empty\27E\27E)\27E"}, ["inventory"] = {["fuel"] = {""}, ["dst"] = {"", "", "", ""}, ["src"] = {""}}}, ["param2"] = 2, ["y"] = 1, ["z"] = 2, ["name"] = "default:furnace"}, {["x"] = 2, ["meta"] = {["fields"] = {["infotext"] = "\27(T@default)Chest\27E"}, ["inventory"] = {["main"] = {"", "", "", "", "", "", "", "", "", "", "", "", "", "", "", "", "", "", "", "", "", "", "", "", "", "", "", "", "", "", "", ""}}}, ["y"] = 1, ["param1"] = 158, ["z"] = 4, ["name"] = "default:chest"}, {["x"] = 2, ["meta"] = {["fields"] = {["state"] = "2"}, ["inventory"] = {}}, ["y"] = 1, ["param1"] = 174, ["z"] = 7, ["name"] = "doors:door_wood_b"}, {["x"] = 2, ["y"] = 2, ["z"] = 1, ["name"] = "the_build_spawner:yellow"}, {["x"] = 2, ["param2"] = 22, ["y"] = 2, ["param1"] = 206, ["z"] = 2, ["name"] = "stairs:slab_wood"}, {["x"] = 2, ["param2"] = 2, ["y"] = 2, ["param1"] = 174, ["z"] = 4, ["name"] = "doors:trapdoor"}, {["x"] = 2, ["param2"] = 3, ["y"] = 2, ["param1"] = 190, ["z"] = 7, ["name"] = "doors:hidden"}, {["x"] = 2, ["y"] = 3, ["z"] = 1, ["name"] = "the_build_spawner:yellow"}, {["x"] = 2, ["param2"] = 2, ["y"] = 3, ["param1"] = 206, ["z"] = 7, ["name"] = "doors:trapdoor_open"}, {["x"] = 2, ["y"] = 4, ["z"] = 1, ["name"] = "the_build_spawner:yellow"}, {["x"] = 2, ["y"] = 4, ["param1"] = 15, ["z"] = 2, ["name"] = "default:junglewood"}, {["x"] = 2, ["y"] = 4, ["param1"] = 15, ["z"] = 3, ["name"] = "default:junglewood"}, {["x"] = 2, ["y"] = 4, ["param1"] = 15, ["z"] = 4, ["name"] = "default:junglewood"}, {["x"] = 2, ["y"] = 4, ["param1"] = 15, ["z"] = 5, ["name"] = "default:junglewood"}, {["x"] = 2, ["y"] = 4, ["param1"] = 15, ["z"] = 6, ["name"] = "default:junglewood"}, {["x"] = 2, ["y"] = 4, ["z"] = 7, ["name"] = "the_build_spawner:yellow"}, {["x"] = 2, ["y"] = 4, ["z"] = 8, ["name"] = "wool:black"}, {["x"] = 2, ["y"] = 4, ["z"] = 9, ["name"] = "wool:black"}, {["x"] = 2, ["y"] = 5, ["param1"] = 223, ["z"] = 1, ["name"] = "default:fence_wood"}, {["x"] = 2, ["y"] = 5, ["param1"] = 206, ["z"] = 2, ["name"] = "default:fence_wood"}, {["x"] = 2, ["y"] = 5, ["param1"] = 190, ["z"] = 5, ["name"] = "default:fence_wood"}, {["x"] = 2, ["y"] = 5, ["param1"] = 206, ["z"] = 6, ["name"] = "default:fence_wood"}, {["x"] = 2, ["y"] = 5, ["param1"] = 223, ["z"] = 7, ["name"] = "default:fence_wood"}, {["x"] = 2, ["y"] = 6, ["param1"] = 239, ["z"] = 1, ["name"] = "default:mese_post_light_junglewood"}, {["x"] = 2, ["param2"] = 2, ["y"] = 6, ["param1"] = 222, ["z"] = 2, ["name"] = "doors:trapdoor"}, {["x"] = 2, ["param2"] = 2, ["y"] = 6, ["param1"] = 206, ["z"] = 5, ["name"] = "doors:trapdoor"}, {["x"] = 2, ["y"] = 6, ["param1"] = 222, ["z"] = 6, ["name"] = "doors:trapdoor"}, {["x"] = 2, ["y"] = 6, ["param1"] = 239, ["z"] = 7, ["name"] = "default:mese_post_light_junglewood"}, {["x"] = 3, ["y"] = 0, ["z"] = 1, ["name"] = "the_build_spawner:yellow"}, {["x"] = 3, ["y"] = 0, ["param1"] = 15, ["z"] = 2, ["name"] = "default:junglewood"}, {["x"] = 3, ["y"] = 0, ["param1"] = 15, ["z"] = 3, ["name"] = "default:junglewood"}, {["x"] = 3, ["y"] = 0, ["param1"] = 15, ["z"] = 4, ["name"] = "default:junglewood"}, {["x"] = 3, ["y"] = 0, ["param1"] = 15, ["z"] = 5, ["name"] = "default:junglewood"}, {["x"] = 3, ["y"] = 0, ["param1"] = 15, ["z"] = 6, ["name"] = "default:junglewood"}, {["x"] = 3, ["y"] = 0, ["z"] = 7, ["name"] = "the_build_spawner:yellow"}, {["x"] = 3, ["y"] = 0, ["param1"] = 15, ["z"] = 8, ["name"] = "default:junglewood"}, {["x"] = 3, ["y"] = 0, ["param1"] = 15, ["z"] = 9, ["name"] = "default:junglewood"}, {["x"] = 3, ["y"] = 0, ["param1"] = 15, ["z"] = 10, ["name"] = "default:junglewood"}, {["x"] = 3, ["y"] = 0, ["param1"] = 15, ["z"] = 11, ["name"] = "default:junglewood"}, {["x"] = 3, ["y"] = 0, ["param1"] = 15, ["z"] = 12, ["name"] = "default:junglewood"}, {["x"] = 3, ["param2"] = 2, ["y"] = 0, ["param1"] = 46, ["z"] = 13, ["name"] = "stairs:stair_junglewood"}, {["x"] = 3, ["y"] = 1, ["z"] = 1, ["name"] = "the_build_spawner:yellow"}, {["x"] = 3, ["meta"] = {["fields"] = {["infotext"] = "\27(T@default)Chest\27E"}, ["inventory"] = {["main"] = {"", "", "", "", "", "", "", "", "", "", "", "", "", "", "", "", "", "", "", "", "", "", "", "", "", "", "", "", "", "", "", ""}}}, ["y"] = 1, ["param1"] = 174, ["z"] = 4, ["name"] = "default:chest"}, {["x"] = 3, ["y"] = 1, ["z"] = 7, ["name"] = "the_build_spawner:yellow"}, {["x"] = 3, ["y"] = 1, ["z"] = 8, ["name"] = "the_build_spawner:dark_grey"}, {["x"] = 3, ["y"] = 2, ["z"] = 1, ["name"] = "the_build_spawner:yellow"}, {["x"] = 3, ["param2"] = 2, ["y"] = 2, ["param1"] = 190, ["z"] = 4, ["name"] = "doors:trapdoor"}, {["x"] = 3, ["y"] = 2, ["z"] = 7, ["name"] = "the_build_spawner:yellow"}, {["x"] = 3, ["y"] = 3, ["z"] = 1, ["name"] = "the_build_spawner:yellow"}, {["x"] = 3, ["y"] = 3, ["param1"] = 238, ["z"] = 2, ["name"] = "default:mese_post_light_junglewood"}, {["x"] = 3, ["y"] = 3, ["param1"] = 238, ["z"] = 6, ["name"] = "default:mese_post_light_junglewood"}, {["x"] = 3, ["y"] = 3, ["z"] = 7, ["name"] = "the_build_spawner:yellow"}, {["x"] = 3, ["y"] = 4, ["z"] = 1, ["name"] = "the_build_spawner:yellow"}, {["x"] = 3, ["y"] = 4, ["param1"] = 15, ["z"] = 2, ["name"] = "default:junglewood"}, {["x"] = 3, ["y"] = 4, ["param1"] = 15, ["z"] = 3, ["name"] = "default:junglewood"}, {["x"] = 3, ["y"] = 4, ["param1"] = 15, ["z"] = 4, ["name"] = "default:junglewood"}, {["x"] = 3, ["y"] = 4, ["param1"] = 15, ["z"] = 5, ["name"] = "default:junglewood"}, {["x"] = 3, ["y"] = 4, ["param1"] = 15, ["z"] = 6, ["name"] = "default:junglewood"}, {["x"] = 3, ["y"] = 4, ["z"] = 7, ["name"] = "the_build_spawner:yellow"}, {["x"] = 3, ["y"] = 4, ["z"] = 8, ["name"] = "wool:white"}, {["x"] = 3, ["y"] = 4, ["z"] = 9, ["name"] = "wool:white"}, {["x"] = 3, ["y"] = 5, ["param1"] = 206, ["z"] = 1, ["name"] = "default:fence_wood"}, {["x"] = 3, ["param2"] = 1, ["y"] = 5, ["param1"] = 190, ["z"] = 2, ["name"] = "stairs:stair_junglewood"}, {["x"] = 3, ["param2"] = 1, ["y"] = 5, ["param1"] = 174, ["z"] = 5, ["name"] = "stairs:stair_junglewood"}, {["x"] = 3, ["param2"] = 1, ["y"] = 5, ["param1"] = 190, ["z"] = 6, ["name"] = "stairs:stair_junglewood"}, {["x"] = 3, ["y"] = 5, ["param1"] = 206, ["z"] = 7, ["name"] = "default:fence_wood"}, {["x"] = 4, ["y"] = 0, ["z"] = 1, ["name"] = "the_build_spawner:yellow"}, {["x"] = 4, ["y"] = 0, ["param1"] = 15, ["z"] = 2, ["name"] = "default:junglewood"}, {["x"] = 4, ["y"] = 0, ["param1"] = 15, ["z"] = 3, ["name"] = "default:junglewood"}, {["x"] = 4, ["y"] = 0, ["param1"] = 15, ["z"] = 4, ["name"] = "default:junglewood"}, {["x"] = 4, ["y"] = 0, ["param1"] = 15, ["z"] = 5, ["name"] = "default:junglewood"}, {["x"] = 4, ["y"] = 0, ["param1"] = 15, ["z"] = 6, ["name"] = "default:junglewood"}, {["x"] = 4, ["y"] = 0, ["z"] = 7, ["name"] = "the_build_spawner:yellow"}, {["x"] = 4, ["y"] = 0, ["param1"] = 15, ["z"] = 8, ["name"] = "default:junglewood"}, {["x"] = 4, ["y"] = 0, ["param1"] = 15, ["z"] = 9, ["name"] = "default:junglewood"}, {["x"] = 4, ["y"] = 0, ["param1"] = 15, ["z"] = 10, ["name"] = "default:junglewood"}, {["x"] = 4, ["y"] = 0, ["param1"] = 15, ["z"] = 11, ["name"] = "default:junglewood"}, {["x"] = 4, ["y"] = 0, ["param1"] = 15, ["z"] = 12, ["name"] = "default:junglewood"}, {["x"] = 4, ["param2"] = 2, ["y"] = 0, ["param1"] = 62, ["z"] = 13, ["name"] = "stairs:stair_junglewood"}, {["x"] = 4, ["y"] = 1, ["z"] = 1, ["name"] = "the_build_spawner:yellow"}, {["x"] = 4, ["meta"] = {["fields"] = {["infotext"] = "\27(T@default)Chest\27E"}, ["inventory"] = {["main"] = {"", "", "", "", "", "", "", "", "", "", "", "", "", "", "", "", "", "", "", "", "", "", "", "", "", "", "", "", "", "", "", ""}}}, ["param2"] = 1, ["y"] = 1, ["param1"] = 174, ["z"] = 3, ["name"] = "default:chest"}, {["x"] = 4, ["y"] = 1, ["z"] = 4, ["name"] = "default:junglewood"}, {["x"] = 4, ["y"] = 1, ["z"] = 7, ["name"] = "the_build_spawner:yellow"}, {["x"] = 4, ["param2"] = 1, ["y"] = 1, ["param1"] = 156, ["z"] = 8, ["name"] = "default:blueberry_bush_leaves"}, {["x"] = 4, ["y"] = 2, ["z"] = 1, ["name"] = "the_build_spawner:yellow"}, {["x"] = 4, ["param2"] = 1, ["y"] = 2, ["param1"] = 190, ["z"] = 3, ["name"] = "doors:trapdoor"}, {["x"] = 4, ["param2"] = 2, ["y"] = 2, ["param1"] = 174, ["z"] = 4, ["name"] = "doors:trapdoor"}, {["x"] = 4, ["y"] = 2, ["param1"] = 190, ["z"] = 7, ["name"] = "xpanes:pane_flat"}, {["x"] = 4, ["y"] = 3, ["z"] = 1, ["name"] = "the_build_spawner:yellow"}, {["x"] = 4, ["y"] = 3, ["param1"] = 206, ["z"] = 7, ["name"] = "xpanes:pane_flat"}, {["x"] = 4, ["y"] = 4, ["z"] = 1, ["name"] = "the_build_spawner:yellow"}, {["x"] = 4, ["y"] = 4, ["param1"] = 15, ["z"] = 2, ["name"] = "default:junglewood"}, {["x"] = 4, ["y"] = 4, ["param1"] = 15, ["z"] = 3, ["name"] = "default:junglewood"}, {["x"] = 4, ["y"] = 4, ["param1"] = 15, ["z"] = 4, ["name"] = "default:junglewood"}, {["x"] = 4, ["y"] = 4, ["param1"] = 15, ["z"] = 5, ["name"] = "default:junglewood"}, {["x"] = 4, ["y"] = 4, ["param1"] = 15, ["z"] = 6, ["name"] = "default:junglewood"}, {["x"] = 4, ["y"] = 4, ["z"] = 7, ["name"] = "the_build_spawner:yellow"}, {["x"] = 4, ["y"] = 4, ["z"] = 8, ["name"] = "wool:black"}, {["x"] = 4, ["y"] = 4, ["z"] = 9, ["name"] = "wool:black"}, {["x"] = 4, ["y"] = 5, ["param1"] = 190, ["z"] = 1, ["name"] = "default:fence_wood"}, {["x"] = 4, ["y"] = 5, ["param1"] = 190, ["z"] = 7, ["name"] = "default:fence_wood"}, {["x"] = 5, ["y"] = 0, ["z"] = 1, ["name"] = "the_build_spawner:yellow"}, {["x"] = 5, ["y"] = 0, ["param1"] = 15, ["z"] = 2, ["name"] = "default:junglewood"}, {["x"] = 5, ["y"] = 0, ["param1"] = 15, ["z"] = 3, ["name"] = "default:junglewood"}, {["x"] = 5, ["y"] = 0, ["param1"] = 15, ["z"] = 4, ["name"] = "default:junglewood"}, {["x"] = 5, ["y"] = 0, ["param1"] = 15, ["z"] = 5, ["name"] = "default:junglewood"}, {["x"] = 5, ["y"] = 0, ["param1"] = 15, ["z"] = 6, ["name"] = "default:junglewood"}, {["x"] = 5, ["y"] = 0, ["z"] = 7, ["name"] = "the_build_spawner:yellow"}, {["x"] = 5, ["y"] = 0, ["param1"] = 15, ["z"] = 8, ["name"] = "default:junglewood"}, {["x"] = 5, ["y"] = 0, ["param1"] = 15, ["z"] = 9, ["name"] = "default:junglewood"}, {["x"] = 5, ["y"] = 0, ["param1"] = 15, ["z"] = 10, ["name"] = "default:junglewood"}, {["x"] = 5, ["y"] = 0, ["param1"] = 15, ["z"] = 11, ["name"] = "default:junglewood"}, {["x"] = 5, ["y"] = 0, ["param1"] = 15, ["z"] = 12, ["name"] = "default:junglewood"}, {["x"] = 5, ["param2"] = 2, ["y"] = 0, ["param1"] = 62, ["z"] = 13, ["name"] = "stairs:stair_junglewood"}, {["x"] = 5, ["y"] = 1, ["z"] = 1, ["name"] = "the_build_spawner:yellow"}, {["x"] = 5, ["y"] = 1, ["z"] = 7, ["name"] = "the_build_spawner:yellow"}, {["x"] = 5, ["param2"] = 1, ["y"] = 1, ["param1"] = 156, ["z"] = 8, ["name"] = "default:blueberry_bush_leaves"}, {["x"] = 5, ["y"] = 2, ["z"] = 1, ["name"] = "the_build_spawner:yellow"}, {["x"] = 5, ["y"] = 2, ["param1"] = 190, ["z"] = 7, ["name"] = "xpanes:pane_flat"}, {["x"] = 5, ["y"] = 3, ["z"] = 1, ["name"] = "the_build_spawner:yellow"}, {["x"] = 5, ["y"] = 3, ["param1"] = 206, ["z"] = 7, ["name"] = "xpanes:pane_flat"}, {["x"] = 5, ["y"] = 4, ["z"] = 1, ["name"] = "the_build_spawner:yellow"}, {["x"] = 5, ["y"] = 4, ["param1"] = 15, ["z"] = 2, ["name"] = "default:junglewood"}, {["x"] = 5, ["y"] = 4, ["param1"] = 15, ["z"] = 3, ["name"] = "default:junglewood"}, {["x"] = 5, ["y"] = 4, ["param1"] = 15, ["z"] = 4, ["name"] = "default:junglewood"}, {["x"] = 5, ["y"] = 4, ["param1"] = 15, ["z"] = 5, ["name"] = "default:junglewood"}, {["x"] = 5, ["y"] = 4, ["param1"] = 15, ["z"] = 6, ["name"] = "default:junglewood"}, {["x"] = 5, ["y"] = 4, ["z"] = 7, ["name"] = "the_build_spawner:yellow"}, {["x"] = 5, ["y"] = 4, ["z"] = 8, ["name"] = "wool:white"}, {["x"] = 5, ["y"] = 4, ["z"] = 9, ["name"] = "wool:white"}, {["x"] = 5, ["y"] = 5, ["param1"] = 206, ["z"] = 1, ["name"] = "default:fence_wood"}, {["x"] = 5, ["param2"] = 3, ["y"] = 5, ["param1"] = 190, ["z"] = 2, ["name"] = "stairs:stair_junglewood"}, {["x"] = 5, ["param2"] = 3, ["y"] = 5, ["param1"] = 174, ["z"] = 5, ["name"] = "stairs:stair_junglewood"}, {["x"] = 5, ["param2"] = 3, ["y"] = 5, ["param1"] = 190, ["z"] = 6, ["name"] = "stairs:stair_junglewood"}, {["x"] = 5, ["y"] = 5, ["param1"] = 206, ["z"] = 7, ["name"] = "default:fence_wood"}, {["x"] = 6, ["y"] = 0, ["z"] = 1, ["name"] = "the_build_spawner:yellow"}, {["x"] = 6, ["y"] = 0, ["param1"] = 15, ["z"] = 2, ["name"] = "default:junglewood"}, {["x"] = 6, ["y"] = 0, ["param1"] = 15, ["z"] = 3, ["name"] = "default:junglewood"}, {["x"] = 6, ["y"] = 0, ["param1"] = 15, ["z"] = 4, ["name"] = "default:junglewood"}, {["x"] = 6, ["y"] = 0, ["param1"] = 15, ["z"] = 5, ["name"] = "default:junglewood"}, {["x"] = 6, ["y"] = 0, ["param1"] = 15, ["z"] = 6, ["name"] = "default:junglewood"}, {["x"] = 6, ["y"] = 0, ["z"] = 7, ["name"] = "the_build_spawner:yellow"}, {["x"] = 6, ["y"] = 0, ["param1"] = 15, ["z"] = 8, ["name"] = "default:junglewood"}, {["x"] = 6, ["y"] = 0, ["param1"] = 15, ["z"] = 9, ["name"] = "default:junglewood"}, {["x"] = 6, ["y"] = 0, ["param1"] = 15, ["z"] = 10, ["name"] = "default:junglewood"}, {["x"] = 6, ["y"] = 0, ["param1"] = 15, ["z"] = 11, ["name"] = "default:junglewood"}, {["x"] = 6, ["y"] = 0, ["param1"] = 15, ["z"] = 12, ["name"] = "default:junglewood"}, {["x"] = 6, ["param2"] = 2, ["y"] = 0, ["param1"] = 46, ["z"] = 13, ["name"] = "stairs:stair_junglewood"}, {["x"] = 6, ["y"] = 1, ["z"] = 1, ["name"] = "the_build_spawner:yellow"}, {["x"] = 6, ["param2"] = 3, ["y"] = 1, ["param1"] = 206, ["z"] = 2, ["name"] = "stairs:stair_junglewood"}, {["x"] = 6, ["param2"] = 3, ["y"] = 1, ["param1"] = 190, ["z"] = 5, ["name"] = "stairs:stair_junglewood"}, {["x"] = 6, ["param2"] = 3, ["y"] = 1, ["param1"] = 206, ["z"] = 6, ["name"] = "stairs:stair_junglewood"}, {["x"] = 6, ["y"] = 1, ["z"] = 7, ["name"] = "the_build_spawner:yellow"}, {["x"] = 6, ["y"] = 1, ["z"] = 8, ["name"] = "the_build_spawner:dark_grey"}, {["x"] = 6, ["y"] = 2, ["z"] = 1, ["name"] = "the_build_spawner:yellow"}, {["x"] = 6, ["y"] = 2, ["z"] = 7, ["name"] = "the_build_spawner:yellow"}, {["x"] = 6, ["y"] = 3, ["z"] = 1, ["name"] = "the_build_spawner:yellow"}, {["x"] = 6, ["y"] = 3, ["param1"] = 238, ["z"] = 2, ["name"] = "default:mese_post_light_junglewood"}, {["x"] = 6, ["y"] = 3, ["param1"] = 238, ["z"] = 6, ["name"] = "default:mese_post_light_junglewood"}, {["x"] = 6, ["y"] = 3, ["z"] = 7, ["name"] = "the_build_spawner:yellow"}, {["x"] = 6, ["y"] = 4, ["z"] = 1, ["name"] = "the_build_spawner:yellow"}, {["x"] = 6, ["y"] = 4, ["param1"] = 15, ["z"] = 2, ["name"] = "default:junglewood"}, {["x"] = 6, ["y"] = 4, ["param1"] = 15, ["z"] = 3, ["name"] = "default:junglewood"}, {["x"] = 6, ["y"] = 4, ["param1"] = 15, ["z"] = 4, ["name"] = "default:junglewood"}, {["x"] = 6, ["y"] = 4, ["param1"] = 15, ["z"] = 5, ["name"] = "default:junglewood"}, {["x"] = 6, ["y"] = 4, ["param1"] = 15, ["z"] = 6, ["name"] = "default:junglewood"}, {["x"] = 6, ["y"] = 4, ["z"] = 7, ["name"] = "the_build_spawner:yellow"}, {["x"] = 6, ["y"] = 4, ["z"] = 8, ["name"] = "wool:black"}, {["x"] = 6, ["y"] = 4, ["z"] = 9, ["name"] = "wool:black"}, {["x"] = 6, ["y"] = 5, ["param1"] = 223, ["z"] = 1, ["name"] = "default:fence_wood"}, {["x"] = 6, ["y"] = 5, ["param1"] = 206, ["z"] = 2, ["name"] = "default:fence_wood"}, {["x"] = 6, ["y"] = 5, ["param1"] = 190, ["z"] = 5, ["name"] = "default:fence_wood"}, {["x"] = 6, ["y"] = 5, ["param1"] = 206, ["z"] = 6, ["name"] = "default:fence_wood"}, {["x"] = 6, ["y"] = 5, ["param1"] = 223, ["z"] = 7, ["name"] = "default:fence_wood"}, {["x"] = 6, ["y"] = 6, ["param1"] = 239, ["z"] = 1, ["name"] = "default:mese_post_light_junglewood"}, {["x"] = 6, ["param2"] = 2, ["y"] = 6, ["param1"] = 222, ["z"] = 2, ["name"] = "doors:trapdoor"}, {["x"] = 6, ["param2"] = 2, ["y"] = 6, ["param1"] = 206, ["z"] = 5, ["name"] = "doors:trapdoor"}, {["x"] = 6, ["y"] = 6, ["param1"] = 222, ["z"] = 6, ["name"] = "doors:trapdoor"}, {["x"] = 6, ["y"] = 6, ["param1"] = 239, ["z"] = 7, ["name"] = "default:mese_post_light_junglewood"}, {["x"] = 7, ["y"] = 0, ["z"] = 1, ["name"] = "the_build_spawner:yellow"}, {["x"] = 7, ["y"] = 0, ["param1"] = 15, ["z"] = 2, ["name"] = "default:junglewood"}, {["x"] = 7, ["y"] = 0, ["param1"] = 15, ["z"] = 3, ["name"] = "default:junglewood"}, {["x"] = 7, ["y"] = 0, ["param1"] = 15, ["z"] = 4, ["name"] = "default:junglewood"}, {["x"] = 7, ["y"] = 0, ["param1"] = 15, ["z"] = 5, ["name"] = "default:junglewood"}, {["x"] = 7, ["y"] = 0, ["param1"] = 15, ["z"] = 6, ["name"] = "default:junglewood"}, {["x"] = 7, ["y"] = 0, ["z"] = 7, ["name"] = "the_build_spawner:yellow"}, {["x"] = 7, ["y"] = 0, ["param1"] = 15, ["z"] = 8, ["name"] = "default:junglewood"}, {["x"] = 7, ["y"] = 0, ["param1"] = 15, ["z"] = 9, ["name"] = "default:junglewood"}, {["x"] = 7, ["y"] = 0, ["param1"] = 15, ["z"] = 10, ["name"] = "default:junglewood"}, {["x"] = 7, ["y"] = 0, ["param1"] = 15, ["z"] = 11, ["name"] = "default:junglewood"}, {["x"] = 7, ["y"] = 0, ["param1"] = 15, ["z"] = 12, ["name"] = "default:junglewood"}, {["x"] = 7, ["param2"] = 2, ["y"] = 0, ["param1"] = 61, ["z"] = 13, ["name"] = "stairs:stair_junglewood"}, {["x"] = 7, ["y"] = 1, ["z"] = 1, ["name"] = "the_build_spawner:yellow"}, {["x"] = 7, ["y"] = 1, ["param1"] = 189, ["z"] = 2, ["name"] = "default:fence_wood"}, {["x"] = 7, ["y"] = 1, ["param1"] = 173, ["z"] = 5, ["name"] = "default:fence_wood"}, {["x"] = 7, ["y"] = 1, ["param1"] = 189, ["z"] = 6, ["name"] = "default:fence_wood"}, {["x"] = 7, ["y"] = 1, ["z"] = 7, ["name"] = "the_build_spawner:yellow"}, {["x"] = 7, ["param2"] = 1, ["y"] = 1, ["param1"] = 156, ["z"] = 8, ["name"] = "default:blueberry_bush_leaves"}, {["x"] = 7, ["y"] = 2, ["z"] = 1, ["name"] = "the_build_spawner:yellow"}, {["x"] = 7, ["param2"] = 2, ["y"] = 2, ["param1"] = 205, ["z"] = 2, ["name"] = "doors:trapdoor"}, {["x"] = 7, ["param2"] = 2, ["y"] = 2, ["param1"] = 190, ["z"] = 5, ["name"] = "doors:trapdoor"}, {["x"] = 7, ["y"] = 2, ["param1"] = 205, ["z"] = 6, ["name"] = "doors:trapdoor"}, {["x"] = 7, ["y"] = 2, ["param1"] = 188, ["z"] = 7, ["name"] = "xpanes:pane_flat"}, {["x"] = 7, ["y"] = 3, ["z"] = 1, ["name"] = "the_build_spawner:yellow"}, {["x"] = 7, ["y"] = 3, ["param1"] = 204, ["z"] = 7, ["name"] = "xpanes:pane_flat"}, {["x"] = 7, ["y"] = 4, ["z"] = 1, ["name"] = "the_build_spawner:yellow"}, {["x"] = 7, ["y"] = 4, ["param1"] = 14, ["z"] = 2, ["name"] = "default:junglewood"}, {["x"] = 7, ["y"] = 4, ["param1"] = 14, ["z"] = 3, ["name"] = "default:junglewood"}, {["x"] = 7, ["y"] = 4, ["param1"] = 14, ["z"] = 4, ["name"] = "default:junglewood"}, {["x"] = 7, ["y"] = 4, ["param1"] = 14, ["z"] = 5, ["name"] = "default:junglewood"}, {["x"] = 7, ["y"] = 4, ["param1"] = 14, ["z"] = 6, ["name"] = "default:junglewood"}, {["x"] = 7, ["y"] = 4, ["z"] = 7, ["name"] = "the_build_spawner:yellow"}, {["x"] = 7, ["y"] = 4, ["z"] = 8, ["name"] = "wool:white"}, {["x"] = 7, ["y"] = 4, ["z"] = 9, ["name"] = "wool:white"}, {["x"] = 7, ["y"] = 5, ["param1"] = 206, ["z"] = 1, ["name"] = "default:fence_wood"}, {["x"] = 7, ["param2"] = 1, ["y"] = 5, ["param1"] = 189, ["z"] = 2, ["name"] = "stairs:stair_junglewood"}, {["x"] = 7, ["param2"] = 1, ["y"] = 5, ["param1"] = 173, ["z"] = 5, ["name"] = "stairs:stair_junglewood"}, {["x"] = 7, ["param2"] = 1, ["y"] = 5, ["param1"] = 189, ["z"] = 6, ["name"] = "stairs:stair_junglewood"}, {["x"] = 7, ["y"] = 5, ["param1"] = 206, ["z"] = 7, ["name"] = "default:fence_wood"}, {["x"] = 8, ["y"] = 0, ["z"] = 1, ["name"] = "the_build_spawner:yellow"}, {["x"] = 8, ["y"] = 0, ["param1"] = 14, ["z"] = 2, ["name"] = "default:junglewood"}, {["x"] = 8, ["y"] = 0, ["param1"] = 14, ["z"] = 3, ["name"] = "default:junglewood"}, {["x"] = 8, ["y"] = 0, ["param1"] = 14, ["z"] = 4, ["name"] = "default:junglewood"}, {["x"] = 8, ["y"] = 0, ["param1"] = 14, ["z"] = 5, ["name"] = "default:junglewood"}, {["x"] = 8, ["y"] = 0, ["param1"] = 14, ["z"] = 6, ["name"] = "default:junglewood"}, {["x"] = 8, ["y"] = 0, ["z"] = 7, ["name"] = "the_build_spawner:yellow"}, {["x"] = 8, ["y"] = 0, ["param1"] = 15, ["z"] = 8, ["name"] = "default:junglewood"}, {["x"] = 8, ["y"] = 0, ["param1"] = 15, ["z"] = 9, ["name"] = "default:junglewood"}, {["x"] = 8, ["y"] = 0, ["param1"] = 15, ["z"] = 10, ["name"] = "default:junglewood"}, {["x"] = 8, ["y"] = 0, ["param1"] = 15, ["z"] = 11, ["name"] = "default:junglewood"}, {["x"] = 8, ["y"] = 0, ["param1"] = 15, ["z"] = 12, ["name"] = "default:junglewood"}, {["x"] = 8, ["param2"] = 2, ["y"] = 0, ["param1"] = 61, ["z"] = 13, ["name"] = "stairs:stair_junglewood"}, {["x"] = 8, ["y"] = 1, ["z"] = 1, ["name"] = "the_build_spawner:yellow"}, {["x"] = 8, ["param2"] = 1, ["y"] = 1, ["param1"] = 189, ["z"] = 2, ["name"] = "stairs:stair_junglewood"}, {["x"] = 8, ["param2"] = 1, ["y"] = 1, ["param1"] = 173, ["z"] = 5, ["name"] = "stairs:stair_junglewood"}, {["x"] = 8, ["param2"] = 1, ["y"] = 1, ["param1"] = 188, ["z"] = 6, ["name"] = "stairs:stair_junglewood"}, {["x"] = 8, ["y"] = 1, ["z"] = 7, ["name"] = "the_build_spawner:yellow"}, {["x"] = 8, ["param2"] = 1, ["y"] = 1, ["param1"] = 156, ["z"] = 8, ["name"] = "default:blueberry_bush_leaves"}, {["x"] = 8, ["y"] = 2, ["z"] = 1, ["name"] = "the_build_spawner:yellow"}, {["x"] = 8, ["y"] = 2, ["param1"] = 188, ["z"] = 7, ["name"] = "xpanes:pane_flat"}, {["x"] = 8, ["y"] = 3, ["z"] = 1, ["name"] = "the_build_spawner:yellow"}, {["x"] = 8, ["y"] = 3, ["param1"] = 204, ["z"] = 7, ["name"] = "xpanes:pane_flat"}, {["x"] = 8, ["y"] = 4, ["z"] = 1, ["name"] = "the_build_spawner:yellow"}, {["x"] = 8, ["y"] = 4, ["param1"] = 14, ["z"] = 2, ["name"] = "default:junglewood"}, {["x"] = 8, ["y"] = 4, ["param1"] = 14, ["z"] = 3, ["name"] = "default:junglewood"}, {["x"] = 8, ["y"] = 4, ["param1"] = 14, ["z"] = 4, ["name"] = "default:junglewood"}, {["x"] = 8, ["y"] = 4, ["param1"] = 14, ["z"] = 5, ["name"] = "default:junglewood"}, {["x"] = 8, ["y"] = 4, ["param1"] = 14, ["z"] = 6, ["name"] = "default:junglewood"}, {["x"] = 8, ["y"] = 4, ["z"] = 7, ["name"] = "the_build_spawner:yellow"}, {["x"] = 8, ["y"] = 4, ["z"] = 8, ["name"] = "wool:black"}, {["x"] = 8, ["y"] = 4, ["z"] = 9, ["name"] = "wool:black"}, {["x"] = 8, ["y"] = 5, ["param1"] = 189, ["z"] = 1, ["name"] = "default:fence_wood"}, {["x"] = 8, ["y"] = 5, ["param1"] = 189, ["z"] = 7, ["name"] = "default:fence_wood"}, {["x"] = 9, ["y"] = 0, ["z"] = 1, ["name"] = "the_build_spawner:yellow"}, {["x"] = 9, ["y"] = 0, ["param1"] = 15, ["z"] = 2, ["name"] = "default:junglewood"}, {["x"] = 9, ["y"] = 0, ["param1"] = 15, ["z"] = 3, ["name"] = "default:junglewood"}, {["x"] = 9, ["y"] = 0, ["param1"] = 15, ["z"] = 4, ["name"] = "default:junglewood"}, {["x"] = 9, ["y"] = 0, ["param1"] = 15, ["z"] = 5, ["name"] = "default:junglewood"}, {["x"] = 9, ["y"] = 0, ["param1"] = 15, ["z"] = 6, ["name"] = "default:junglewood"}, {["x"] = 9, ["y"] = 0, ["z"] = 7, ["name"] = "the_build_spawner:yellow"}, {["x"] = 9, ["y"] = 0, ["param1"] = 15, ["z"] = 8, ["name"] = "default:junglewood"}, {["x"] = 9, ["y"] = 0, ["param1"] = 15, ["z"] = 9, ["name"] = "default:junglewood"}, {["x"] = 9, ["y"] = 0, ["param1"] = 15, ["z"] = 10, ["name"] = "default:junglewood"}, {["x"] = 9, ["y"] = 0, ["param1"] = 15, ["z"] = 11, ["name"] = "default:junglewood"}, {["x"] = 9, ["y"] = 0, ["param1"] = 15, ["z"] = 12, ["name"] = "default:junglewood"}, {["x"] = 9, ["param2"] = 2, ["y"] = 0, ["param1"] = 78, ["z"] = 13, ["name"] = "stairs:stair_junglewood"}, {["x"] = 9, ["y"] = 1, ["z"] = 1, ["name"] = "the_build_spawner:yellow"}, {["x"] = 9, ["param2"] = 3, ["y"] = 1, ["param1"] = 206, ["z"] = 2, ["name"] = "stairs:stair_junglewood"}, {["x"] = 9, ["param2"] = 3, ["y"] = 1, ["param1"] = 190, ["z"] = 5, ["name"] = "stairs:stair_junglewood"}, {["x"] = 9, ["param2"] = 3, ["y"] = 1, ["param1"] = 205, ["z"] = 6, ["name"] = "stairs:stair_junglewood"}, {["x"] = 9, ["y"] = 1, ["z"] = 7, ["name"] = "the_build_spawner:yellow"}, {["x"] = 9, ["y"] = 1, ["z"] = 8, ["name"] = "the_build_spawner:dark_grey"}, {["x"] = 9, ["y"] = 2, ["z"] = 1, ["name"] = "the_build_spawner:yellow"}, {["x"] = 9, ["y"] = 2, ["z"] = 7, ["name"] = "the_build_spawner:yellow"}, {["x"] = 9, ["y"] = 3, ["z"] = 1, ["name"] = "the_build_spawner:yellow"}, {["x"] = 9, ["y"] = 3, ["param1"] = 238, ["z"] = 2, ["name"] = "default:mese_post_light_junglewood"}, {["x"] = 9, ["y"] = 3, ["param1"] = 238, ["z"] = 6, ["name"] = "default:mese_post_light_junglewood"}, {["x"] = 9, ["y"] = 3, ["z"] = 7, ["name"] = "the_build_spawner:yellow"}, {["x"] = 9, ["y"] = 4, ["z"] = 1, ["name"] = "the_build_spawner:yellow"}, {["x"] = 9, ["y"] = 4, ["param1"] = 15, ["z"] = 2, ["name"] = "default:junglewood"}, {["x"] = 9, ["y"] = 4, ["param1"] = 15, ["z"] = 3, ["name"] = "default:junglewood"}, {["x"] = 9, ["y"] = 4, ["param1"] = 15, ["z"] = 4, ["name"] = "default:junglewood"}, {["x"] = 9, ["y"] = 4, ["param1"] = 15, ["z"] = 5, ["name"] = "default:junglewood"}, {["x"] = 9, ["y"] = 4, ["param1"] = 15, ["z"] = 6, ["name"] = "default:junglewood"}, {["x"] = 9, ["y"] = 4, ["z"] = 7, ["name"] = "the_build_spawner:yellow"}, {["x"] = 9, ["y"] = 4, ["z"] = 8, ["name"] = "wool:white"}, {["x"] = 9, ["y"] = 4, ["z"] = 9, ["name"] = "wool:white"}, {["x"] = 9, ["y"] = 5, ["param1"] = 206, ["z"] = 1, ["name"] = "default:fence_wood"}, {["x"] = 9, ["param2"] = 3, ["y"] = 5, ["param1"] = 190, ["z"] = 2, ["name"] = "stairs:stair_junglewood"}, {["x"] = 9, ["param2"] = 3, ["y"] = 5, ["param1"] = 174, ["z"] = 5, ["name"] = "stairs:stair_junglewood"}, {["x"] = 9, ["param2"] = 3, ["y"] = 5, ["param1"] = 189, ["z"] = 6, ["name"] = "stairs:stair_junglewood"}, {["x"] = 9, ["y"] = 5, ["param1"] = 206, ["z"] = 7, ["name"] = "default:fence_wood"}, {["x"] = 10, ["y"] = 0, ["z"] = 1, ["name"] = "the_build_spawner:yellow"}, {["x"] = 10, ["y"] = 0, ["param1"] = 15, ["z"] = 2, ["name"] = "default:junglewood"}, {["x"] = 10, ["y"] = 0, ["param1"] = 15, ["z"] = 3, ["name"] = "default:junglewood"}, {["x"] = 10, ["y"] = 0, ["param1"] = 15, ["z"] = 4, ["name"] = "default:junglewood"}, {["x"] = 10, ["y"] = 0, ["param1"] = 15, ["z"] = 5, ["name"] = "default:junglewood"}, {["x"] = 10, ["y"] = 0, ["z"] = 6, ["name"] = "default:junglewood"}, {["x"] = 10, ["y"] = 0, ["z"] = 7, ["name"] = "the_build_spawner:yellow"}, {["x"] = 10, ["y"] = 0, ["param1"] = 15, ["z"] = 8, ["name"] = "default:junglewood"}, {["x"] = 10, ["y"] = 0, ["param1"] = 15, ["z"] = 9, ["name"] = "default:junglewood"}, {["x"] = 10, ["y"] = 0, ["param1"] = 15, ["z"] = 10, ["name"] = "default:junglewood"}, {["x"] = 10, ["y"] = 0, ["param1"] = 15, ["z"] = 11, ["name"] = "default:junglewood"}, {["x"] = 10, ["y"] = 0, ["z"] = 12, ["name"] = "default:junglewood"}, {["x"] = 10, ["param2"] = 2, ["y"] = 0, ["param1"] = 94, ["z"] = 13, ["name"] = "stairs:stair_junglewood"}, {["x"] = 10, ["y"] = 1, ["z"] = 1, ["name"] = "the_build_spawner:yellow"}, {["x"] = 10, ["y"] = 1, ["param1"] = 190, ["z"] = 2, ["name"] = "default:fence_wood"}, {["x"] = 10, ["y"] = 1, ["param1"] = 174, ["z"] = 5, ["name"] = "default:fence_wood"}, {["x"] = 10, ["y"] = 1, ["param1"] = 189, ["z"] = 6, ["name"] = "default:fence_wood"}, {["x"] = 10, ["y"] = 1, ["z"] = 7, ["name"] = "the_build_spawner:yellow"}, {["x"] = 10, ["param2"] = 1, ["y"] = 1, ["param1"] = 156, ["z"] = 8, ["name"] = "default:blueberry_bush_leaves"}, {["x"] = 10, ["y"] = 2, ["z"] = 1, ["name"] = "the_build_spawner:yellow"}, {["x"] = 10, ["param2"] = 2, ["y"] = 2, ["param1"] = 206, ["z"] = 2, ["name"] = "doors:trapdoor"}, {["x"] = 10, ["param2"] = 2, ["y"] = 2, ["param1"] = 190, ["z"] = 5, ["name"] = "doors:trapdoor"}, {["x"] = 10, ["y"] = 2, ["param1"] = 206, ["z"] = 6, ["name"] = "doors:trapdoor"}, {["x"] = 10, ["y"] = 2, ["param1"] = 189, ["z"] = 7, ["name"] = "xpanes:pane_flat"}, {["x"] = 10, ["y"] = 3, ["z"] = 1, ["name"] = "the_build_spawner:yellow"}, {["x"] = 10, ["y"] = 3, ["param1"] = 206, ["z"] = 7, ["name"] = "xpanes:pane_flat"}, {["x"] = 10, ["y"] = 4, ["z"] = 1, ["name"] = "the_build_spawner:yellow"}, {["x"] = 10, ["y"] = 4, ["param1"] = 15, ["z"] = 2, ["name"] = "default:junglewood"}, {["x"] = 10, ["y"] = 4, ["param1"] = 15, ["z"] = 3, ["name"] = "default:junglewood"}, {["x"] = 10, ["y"] = 4, ["param1"] = 15, ["z"] = 4, ["name"] = "default:junglewood"}, {["x"] = 10, ["y"] = 4, ["param1"] = 15, ["z"] = 5, ["name"] = "default:junglewood"}, {["x"] = 10, ["y"] = 4, ["param1"] = 15, ["z"] = 6, ["name"] = "default:junglewood"}, {["x"] = 10, ["y"] = 4, ["z"] = 7, ["name"] = "the_build_spawner:yellow"}, {["x"] = 10, ["y"] = 4, ["z"] = 8, ["name"] = "wool:black"}, {["x"] = 10, ["y"] = 4, ["z"] = 9, ["name"] = "wool:black"}, {["x"] = 10, ["y"] = 5, ["param1"] = 223, ["z"] = 1, ["name"] = "default:fence_wood"}, {["x"] = 10, ["y"] = 5, ["param1"] = 206, ["z"] = 2, ["name"] = "default:fence_wood"}, {["x"] = 10, ["y"] = 5, ["param1"] = 190, ["z"] = 5, ["name"] = "default:fence_wood"}, {["x"] = 10, ["y"] = 5, ["param1"] = 206, ["z"] = 6, ["name"] = "default:fence_wood"}, {["x"] = 10, ["y"] = 5, ["param1"] = 223, ["z"] = 7, ["name"] = "default:fence_wood"}, {["x"] = 10, ["y"] = 6, ["param1"] = 239, ["z"] = 1, ["name"] = "default:mese_post_light_junglewood"}, {["x"] = 10, ["param2"] = 2, ["y"] = 6, ["param1"] = 222, ["z"] = 2, ["name"] = "doors:trapdoor"}, {["x"] = 10, ["param2"] = 2, ["y"] = 6, ["param1"] = 206, ["z"] = 5, ["name"] = "doors:trapdoor"}, {["x"] = 10, ["y"] = 6, ["param1"] = 222, ["z"] = 6, ["name"] = "doors:trapdoor"}, {["x"] = 10, ["y"] = 6, ["param1"] = 239, ["z"] = 7, ["name"] = "default:mese_post_light_junglewood"}, {["x"] = 11, ["y"] = 0, ["z"] = 1, ["name"] = "the_build_spawner:yellow"}, {["x"] = 11, ["y"] = 0, ["param1"] = 15, ["z"] = 2, ["name"] = "default:junglewood"}, {["x"] = 11, ["y"] = 0, ["param1"] = 15, ["z"] = 3, ["name"] = "default:junglewood"}, {["x"] = 11, ["y"] = 0, ["z"] = 4, ["name"] = "default:junglewood"}, {["x"] = 11, ["y"] = 0, ["param1"] = 15, ["z"] = 5, ["name"] = "default:junglewood"}, {["x"] = 11, ["y"] = 0, ["z"] = 6, ["name"] = "default:junglewood"}, {["x"] = 11, ["y"] = 0, ["z"] = 7, ["name"] = "the_build_spawner:yellow"}, {["x"] = 11, ["y"] = 0, ["param1"] = 15, ["z"] = 8, ["name"] = "default:junglewood"}, {["x"] = 11, ["y"] = 0, ["param1"] = 15, ["z"] = 9, ["name"] = "default:junglewood"}, {["x"] = 11, ["y"] = 0, ["param1"] = 15, ["z"] = 10, ["name"] = "default:junglewood"}, {["x"] = 11, ["y"] = 0, ["param1"] = 15, ["z"] = 11, ["name"] = "default:junglewood"}, {["x"] = 11, ["y"] = 0, ["z"] = 12, ["name"] = "default:junglewood"}, {["x"] = 11, ["param2"] = 2, ["y"] = 0, ["param1"] = 110, ["z"] = 13, ["name"] = "stairs:stair_junglewood"}, {["x"] = 11, ["y"] = 1, ["z"] = 1, ["name"] = "the_build_spawner:yellow"}, {["x"] = 11, ["param2"] = 1, ["y"] = 1, ["param1"] = 174, ["z"] = 2, ["name"] = "stairs:stair_junglewood"}, {["x"] = 11, ["param2"] = 1, ["y"] = 1, ["param1"] = 158, ["z"] = 5, ["name"] = "stairs:stair_junglewood"}, {["x"] = 11, ["param2"] = 1, ["y"] = 1, ["param1"] = 173, ["z"] = 6, ["name"] = "stairs:stair_junglewood"}, {["x"] = 11, ["y"] = 1, ["z"] = 7, ["name"] = "the_build_spawner:yellow"}, {["x"] = 11, ["param2"] = 1, ["y"] = 1, ["param1"] = 140, ["z"] = 8, ["name"] = "default:blueberry_bush_leaves"}, {["x"] = 11, ["y"] = 2, ["z"] = 1, ["name"] = "the_build_spawner:yellow"}, {["x"] = 11, ["y"] = 2, ["param1"] = 173, ["z"] = 7, ["name"] = "xpanes:pane_flat"}, {["x"] = 11, ["y"] = 3, ["z"] = 1, ["name"] = "the_build_spawner:yellow"}, {["x"] = 11, ["y"] = 3, ["param1"] = 189, ["z"] = 7, ["name"] = "xpanes:pane_flat"}, {["x"] = 11, ["y"] = 4, ["z"] = 1, ["name"] = "the_build_spawner:yellow"}, {["x"] = 11, ["y"] = 4, ["param1"] = 15, ["z"] = 2, ["name"] = "default:junglewood"}, {["x"] = 11, ["y"] = 4, ["param1"] = 15, ["z"] = 3, ["name"] = "default:junglewood"}, {["x"] = 11, ["y"] = 4, ["param1"] = 15, ["z"] = 4, ["name"] = "default:junglewood"}, {["x"] = 11, ["y"] = 4, ["param1"] = 15, ["z"] = 5, ["name"] = "default:junglewood"}, {["x"] = 11, ["y"] = 4, ["z"] = 6, ["name"] = "default:junglewood"}, {["x"] = 11, ["y"] = 4, ["z"] = 7, ["name"] = "the_build_spawner:yellow"}, {["x"] = 11, ["y"] = 4, ["z"] = 8, ["name"] = "wool:white"}, {["x"] = 11, ["y"] = 4, ["z"] = 9, ["name"] = "wool:white"}, {["x"] = 11, ["y"] = 5, ["param1"] = 206, ["z"] = 1, ["name"] = "default:fence_wood"}, {["x"] = 11, ["param2"] = 1, ["y"] = 5, ["param1"] = 190, ["z"] = 2, ["name"] = "stairs:stair_junglewood"}, {["x"] = 11, ["param2"] = 1, ["y"] = 5, ["param1"] = 174, ["z"] = 5, ["name"] = "stairs:stair_junglewood"}, {["x"] = 11, ["param2"] = 1, ["y"] = 5, ["param1"] = 189, ["z"] = 6, ["name"] = "stairs:stair_junglewood"}, {["x"] = 11, ["y"] = 5, ["param1"] = 206, ["z"] = 7, ["name"] = "default:fence_wood"}, {["x"] = 12, ["y"] = 0, ["z"] = 1, ["name"] = "the_build_spawner:yellow"}, {["x"] = 12, ["y"] = 0, ["z"] = 2, ["name"] = "default:junglewood"}, {["x"] = 12, ["y"] = 0, ["z"] = 3, ["name"] = "default:junglewood"}, {["x"] = 12, ["y"] = 0, ["z"] = 4, ["name"] = "default:junglewood"}, {["x"] = 12, ["y"] = 0, ["z"] = 5, ["name"] = "default:junglewood"}, {["x"] = 12, ["y"] = 0, ["z"] = 6, ["name"] = "the_build_spawner:yellow"}, {["x"] = 12, ["y"] = 0, ["z"] = 7, ["name"] = "the_build_spawner:yellow"}, {["x"] = 12, ["y"] = 0, ["z"] = 8, ["name"] = "default:junglewood"}, {["x"] = 12, ["y"] = 0, ["param1"] = 15, ["z"] = 9, ["name"] = "default:junglewood"}, {["x"] = 12, ["y"] = 0, ["param1"] = 15, ["z"] = 10, ["name"] = "default:junglewood"}, {["x"] = 12, ["y"] = 0, ["param1"] = 15, ["z"] = 11, ["name"] = "default:junglewood"}, {["x"] = 12, ["y"] = 0, ["z"] = 12, ["name"] = "default:junglewood"}, {["x"] = 12, ["param2"] = 2, ["y"] = 0, ["param1"] = 126, ["z"] = 13, ["name"] = "stairs:stair_junglewood"}, {["x"] = 12, ["y"] = 1, ["z"] = 1, ["name"] = "the_build_spawner:yellow"}, {["x"] = 12, ["meta"] = {["fields"] = {["infotext"] = "\27(T@default)Empty Bookshelf\27E", ["formspec"] = "size[8,7;]list[context;books;0,0.3;8,2;]list[current_player;main;0,2.85;8,1;]list[current_player;main;0,4.08;8,3;8]listring[context;books]listring[current_player;main]image[0,2.85;1,1;gui_hb_bg.png]image[1,2.85;1,1;gui_hb_bg.png]image[2,2.85;1,1;gui_hb_bg.png]image[3,2.85;1,1;gui_hb_bg.png]image[4,2.85;1,1;gui_hb_bg.png]image[5,2.85;1,1;gui_hb_bg.png]image[6,2.85;1,1;gui_hb_bg.png]image[7,2.85;1,1;gui_hb_bg.png]image[0,0.3;1,1;default_bookshelf_slot.png]image[1,0.3;1,1;default_bookshelf_slot.png]image[2,0.3;1,1;default_bookshelf_slot.png]image[3,0.3;1,1;default_bookshelf_slot.png]image[4,0.3;1,1;default_bookshelf_slot.png]image[5,0.3;1,1;default_bookshelf_slot.png]image[6,0.3;1,1;default_bookshelf_slot.png]image[7,0.3;1,1;default_bookshelf_slot.png]image[0,1.3;1,1;default_bookshelf_slot.png]image[1,1.3;1,1;default_bookshelf_slot.png]image[2,1.3;1,1;default_bookshelf_slot.png]image[3,1.3;1,1;default_bookshelf_slot.png]image[4,1.3;1,1;default_bookshelf_slot.png]image[5,1.3;1,1;default_bookshelf_slot.png]image[6,1.3;1,1;default_bookshelf_slot.png]image[7,1.3;1,1;default_bookshelf_slot.png]"}, ["inventory"] = {["books"] = {"", "", "", "", "", "", "", "", "", "", "", "", "", "", "", ""}}}, ["param2"] = 3, ["y"] = 1, ["z"] = 4, ["name"] = "default:bookshelf"}, {["x"] = 12, ["meta"] = {["fields"] = {["infotext"] = "\27(T@default)Empty Bookshelf\27E", ["formspec"] = "size[8,7;]list[context;books;0,0.3;8,2;]list[current_player;main;0,2.85;8,1;]list[current_player;main;0,4.08;8,3;8]listring[context;books]listring[current_player;main]image[0,2.85;1,1;gui_hb_bg.png]image[1,2.85;1,1;gui_hb_bg.png]image[2,2.85;1,1;gui_hb_bg.png]image[3,2.85;1,1;gui_hb_bg.png]image[4,2.85;1,1;gui_hb_bg.png]image[5,2.85;1,1;gui_hb_bg.png]image[6,2.85;1,1;gui_hb_bg.png]image[7,2.85;1,1;gui_hb_bg.png]image[0,0.3;1,1;default_bookshelf_slot.png]image[1,0.3;1,1;default_bookshelf_slot.png]image[2,0.3;1,1;default_bookshelf_slot.png]image[3,0.3;1,1;default_bookshelf_slot.png]image[4,0.3;1,1;default_bookshelf_slot.png]image[5,0.3;1,1;default_bookshelf_slot.png]image[6,0.3;1,1;default_bookshelf_slot.png]image[7,0.3;1,1;default_bookshelf_slot.png]image[0,1.3;1,1;default_bookshelf_slot.png]image[1,1.3;1,1;default_bookshelf_slot.png]image[2,1.3;1,1;default_bookshelf_slot.png]image[3,1.3;1,1;default_bookshelf_slot.png]image[4,1.3;1,1;default_bookshelf_slot.png]image[5,1.3;1,1;default_bookshelf_slot.png]image[6,1.3;1,1;default_bookshelf_slot.png]image[7,1.3;1,1;default_bookshelf_slot.png]"}, ["inventory"] = {["books"] = {"", "", "", "", "", "", "", "", "", "", "", "", "", "", "", ""}}}, ["param2"] = 3, ["y"] = 1, ["z"] = 5, ["name"] = "default:bookshelf"}, {["x"] = 12, ["y"] = 1, ["z"] = 6, ["name"] = "the_build_spawner:yellow"}, {["x"] = 12, ["y"] = 1, ["z"] = 7, ["name"] = "the_build_spawner:yellow"}, {["x"] = 12, ["y"] = 1, ["z"] = 8, ["name"] = "the_build_spawner:dark_grey"}, {["x"] = 12, ["y"] = 2, ["z"] = 1, ["name"] = "the_build_spawner:yellow"}, {["x"] = 12, ["meta"] = {["fields"] = {["infotext"] = "\27(T@default)Empty Bookshelf\27E", ["formspec"] = "size[8,7;]list[context;books;0,0.3;8,2;]list[current_player;main;0,2.85;8,1;]list[current_player;main;0,4.08;8,3;8]listring[context;books]listring[current_player;main]image[0,2.85;1,1;gui_hb_bg.png]image[1,2.85;1,1;gui_hb_bg.png]image[2,2.85;1,1;gui_hb_bg.png]image[3,2.85;1,1;gui_hb_bg.png]image[4,2.85;1,1;gui_hb_bg.png]image[5,2.85;1,1;gui_hb_bg.png]image[6,2.85;1,1;gui_hb_bg.png]image[7,2.85;1,1;gui_hb_bg.png]image[0,0.3;1,1;default_bookshelf_slot.png]image[1,0.3;1,1;default_bookshelf_slot.png]image[2,0.3;1,1;default_bookshelf_slot.png]image[3,0.3;1,1;default_bookshelf_slot.png]image[4,0.3;1,1;default_bookshelf_slot.png]image[5,0.3;1,1;default_bookshelf_slot.png]image[6,0.3;1,1;default_bookshelf_slot.png]image[7,0.3;1,1;default_bookshelf_slot.png]image[0,1.3;1,1;default_bookshelf_slot.png]image[1,1.3;1,1;default_bookshelf_slot.png]image[2,1.3;1,1;default_bookshelf_slot.png]image[3,1.3;1,1;default_bookshelf_slot.png]image[4,1.3;1,1;default_bookshelf_slot.png]image[5,1.3;1,1;default_bookshelf_slot.png]image[6,1.3;1,1;default_bookshelf_slot.png]image[7,1.3;1,1;default_bookshelf_slot.png]"}, ["inventory"] = {["books"] = {"", "", "", "", "", "", "", "", "", "", "", "", "", "", "", ""}}}, ["param2"] = 3, ["y"] = 2, ["z"] = 4, ["name"] = "default:bookshelf"}, {["x"] = 12, ["meta"] = {["fields"] = {["infotext"] = "\27(T@default)Empty Bookshelf\27E", ["formspec"] = "size[8,7;]list[context;books;0,0.3;8,2;]list[current_player;main;0,2.85;8,1;]list[current_player;main;0,4.08;8,3;8]listring[context;books]listring[current_player;main]image[0,2.85;1,1;gui_hb_bg.png]image[1,2.85;1,1;gui_hb_bg.png]image[2,2.85;1,1;gui_hb_bg.png]image[3,2.85;1,1;gui_hb_bg.png]image[4,2.85;1,1;gui_hb_bg.png]image[5,2.85;1,1;gui_hb_bg.png]image[6,2.85;1,1;gui_hb_bg.png]image[7,2.85;1,1;gui_hb_bg.png]image[0,0.3;1,1;default_bookshelf_slot.png]image[1,0.3;1,1;default_bookshelf_slot.png]image[2,0.3;1,1;default_bookshelf_slot.png]image[3,0.3;1,1;default_bookshelf_slot.png]image[4,0.3;1,1;default_bookshelf_slot.png]image[5,0.3;1,1;default_bookshelf_slot.png]image[6,0.3;1,1;default_bookshelf_slot.png]image[7,0.3;1,1;default_bookshelf_slot.png]image[0,1.3;1,1;default_bookshelf_slot.png]image[1,1.3;1,1;default_bookshelf_slot.png]image[2,1.3;1,1;default_bookshelf_slot.png]image[3,1.3;1,1;default_bookshelf_slot.png]image[4,1.3;1,1;default_bookshelf_slot.png]image[5,1.3;1,1;default_bookshelf_slot.png]image[6,1.3;1,1;default_bookshelf_slot.png]image[7,1.3;1,1;default_bookshelf_slot.png]"}, ["inventory"] = {["books"] = {"", "", "", "", "", "", "", "", "", "", "", "", "", "", "", ""}}}, ["param2"] = 3, ["y"] = 2, ["z"] = 5, ["name"] = "default:bookshelf"}, {["x"] = 12, ["y"] = 2, ["z"] = 6, ["name"] = "the_build_spawner:yellow"}, {["x"] = 12, ["y"] = 2, ["z"] = 7, ["name"] = "the_build_spawner:yellow"}, {["x"] = 12, ["y"] = 3, ["z"] = 1, ["name"] = "the_build_spawner:yellow"}, {["x"] = 12, ["meta"] = {["fields"] = {["infotext"] = "\27(T@default)Empty Bookshelf\27E", ["formspec"] = "size[8,7;]list[context;books;0,0.3;8,2;]list[current_player;main;0,2.85;8,1;]list[current_player;main;0,4.08;8,3;8]listring[context;books]listring[current_player;main]image[0,2.85;1,1;gui_hb_bg.png]image[1,2.85;1,1;gui_hb_bg.png]image[2,2.85;1,1;gui_hb_bg.png]image[3,2.85;1,1;gui_hb_bg.png]image[4,2.85;1,1;gui_hb_bg.png]image[5,2.85;1,1;gui_hb_bg.png]image[6,2.85;1,1;gui_hb_bg.png]image[7,2.85;1,1;gui_hb_bg.png]image[0,0.3;1,1;default_bookshelf_slot.png]image[1,0.3;1,1;default_bookshelf_slot.png]image[2,0.3;1,1;default_bookshelf_slot.png]image[3,0.3;1,1;default_bookshelf_slot.png]image[4,0.3;1,1;default_bookshelf_slot.png]image[5,0.3;1,1;default_bookshelf_slot.png]image[6,0.3;1,1;default_bookshelf_slot.png]image[7,0.3;1,1;default_bookshelf_slot.png]image[0,1.3;1,1;default_bookshelf_slot.png]image[1,1.3;1,1;default_bookshelf_slot.png]image[2,1.3;1,1;default_bookshelf_slot.png]image[3,1.3;1,1;default_bookshelf_slot.png]image[4,1.3;1,1;default_bookshelf_slot.png]image[5,1.3;1,1;default_bookshelf_slot.png]image[6,1.3;1,1;default_bookshelf_slot.png]image[7,1.3;1,1;default_bookshelf_slot.png]"}, ["inventory"] = {["books"] = {"", "", "", "", "", "", "", "", "", "", "", "", "", "", "", ""}}}, ["param2"] = 3, ["y"] = 3, ["z"] = 4, ["name"] = "default:bookshelf"}, {["x"] = 12, ["meta"] = {["fields"] = {["infotext"] = "\27(T@default)Empty Bookshelf\27E", ["formspec"] = "size[8,7;]list[context;books;0,0.3;8,2;]list[current_player;main;0,2.85;8,1;]list[current_player;main;0,4.08;8,3;8]listring[context;books]listring[current_player;main]image[0,2.85;1,1;gui_hb_bg.png]image[1,2.85;1,1;gui_hb_bg.png]image[2,2.85;1,1;gui_hb_bg.png]image[3,2.85;1,1;gui_hb_bg.png]image[4,2.85;1,1;gui_hb_bg.png]image[5,2.85;1,1;gui_hb_bg.png]image[6,2.85;1,1;gui_hb_bg.png]image[7,2.85;1,1;gui_hb_bg.png]image[0,0.3;1,1;default_bookshelf_slot.png]image[1,0.3;1,1;default_bookshelf_slot.png]image[2,0.3;1,1;default_bookshelf_slot.png]image[3,0.3;1,1;default_bookshelf_slot.png]image[4,0.3;1,1;default_bookshelf_slot.png]image[5,0.3;1,1;default_bookshelf_slot.png]image[6,0.3;1,1;default_bookshelf_slot.png]image[7,0.3;1,1;default_bookshelf_slot.png]image[0,1.3;1,1;default_bookshelf_slot.png]image[1,1.3;1,1;default_bookshelf_slot.png]image[2,1.3;1,1;default_bookshelf_slot.png]image[3,1.3;1,1;default_bookshelf_slot.png]image[4,1.3;1,1;default_bookshelf_slot.png]image[5,1.3;1,1;default_bookshelf_slot.png]image[6,1.3;1,1;default_bookshelf_slot.png]image[7,1.3;1,1;default_bookshelf_slot.png]"}, ["inventory"] = {["books"] = {"", "", "", "", "", "", "", "", "", "", "", "", "", "", "", ""}}}, ["param2"] = 3, ["y"] = 3, ["z"] = 5, ["name"] = "default:bookshelf"}, {["x"] = 12, ["y"] = 3, ["z"] = 6, ["name"] = "the_build_spawner:yellow"}, {["x"] = 12, ["y"] = 3, ["z"] = 7, ["name"] = "the_build_spawner:yellow"}, {["x"] = 12, ["y"] = 4, ["z"] = 1, ["name"] = "the_build_spawner:yellow"}, {["x"] = 12, ["y"] = 4, ["z"] = 2, ["name"] = "the_build_spawner:yellow"}, {["x"] = 12, ["y"] = 4, ["z"] = 3, ["name"] = "the_build_spawner:yellow"}, {["x"] = 12, ["y"] = 4, ["z"] = 4, ["name"] = "the_build_spawner:yellow"}, {["x"] = 12, ["y"] = 4, ["z"] = 5, ["name"] = "the_build_spawner:yellow"}, {["x"] = 12, ["y"] = 4, ["z"] = 6, ["name"] = "the_build_spawner:yellow"}, {["x"] = 12, ["y"] = 4, ["z"] = 7, ["name"] = "the_build_spawner:yellow"}, {["x"] = 12, ["y"] = 4, ["z"] = 8, ["name"] = "wool:black"}, {["x"] = 12, ["y"] = 4, ["z"] = 9, ["name"] = "wool:black"}, {["x"] = 12, ["y"] = 5, ["param1"] = 190, ["z"] = 1, ["name"] = "default:fence_wood"}, {["x"] = 12, ["meta"] = {["fields"] = {["infotext"] = "\27(T@default)Chest\27E"}, ["inventory"] = {["main"] = {"", "", "", "", "", "", "", "", "", "", "", "", "", "", "", "", "", "", "", "", "", "", "", "", "", "", "", "", "", "", "", ""}}}, ["param2"] = 1, ["y"] = 5, ["param1"] = 173, ["z"] = 2, ["name"] = "default:chest"}, {["x"] = 12, ["meta"] = {["fields"] = {["timer_elapsed"] = "0", ["formspec"] = "size[8,8.5]list[context;src;2.75,0.5;1,1;]list[context;fuel;2.75,2.5;1,1;]image[2.75,1.5;1,1;default_furnace_fire_bg.png]image[3.75,1.5;1,1;gui_furnace_arrow_bg.png^[transformR270]list[context;dst;4.75,0.96;2,2;]list[current_player;main;0,4.25;8,1;]list[current_player;main;0,5.5;8,3;8]listring[context;dst]listring[current_player;main]listring[context;src]listring[current_player;main]listring[context;fuel]listring[current_player;main]image[0,4.25;1,1;gui_hb_bg.png]image[1,4.25;1,1;gui_hb_bg.png]image[2,4.25;1,1;gui_hb_bg.png]image[3,4.25;1,1;gui_hb_bg.png]image[4,4.25;1,1;gui_hb_bg.png]image[5,4.25;1,1;gui_hb_bg.png]image[6,4.25;1,1;gui_hb_bg.png]image[7,4.25;1,1;gui_hb_bg.png]", ["fuel_time"] = "0", ["fuel_totaltime"] = "0", ["src_time"] = "0", ["infotext"] = "\27(T@default)Furnace inactive\27E\
\27(T@default)(Item: \27F\27(T@default)Empty\27E\27E; Fuel: \27F\27(T@default)Empty\27E\27E)\27E"}, ["inventory"] = {["fuel"] = {""}, ["dst"] = {"", "", "", ""}, ["src"] = {""}}}, ["param2"] = 1, ["y"] = 5, ["z"] = 3, ["name"] = "default:furnace"}, {["x"] = 12, ["y"] = 5, ["param1"] = 206, ["z"] = 7, ["name"] = "default:fence_wood"}, {["x"] = 12, ["y"] = 6, ["param1"] = 189, ["z"] = 2, ["name"] = "flowers:dandelion_white"}, {["x"] = 12, ["param2"] = 1, ["y"] = 6, ["param1"] = 173, ["z"] = 3, ["name"] = "doors:trapdoor"}, {["x"] = 12, ["y"] = 7, ["param1"] = 238, ["z"] = 0, ["name"] = "default:mese_post_light_junglewood"}, {["x"] = 12, ["y"] = 7, ["param1"] = 238, ["z"] = 7, ["name"] = "default:mese_post_light_junglewood"}, {["x"] = 12, ["param2"] = 3, ["y"] = 8, ["param1"] = 222, ["z"] = 0, ["name"] = "stairs:slab_silver_sandstone"}, {["x"] = 12, ["param2"] = 3, ["y"] = 8, ["param1"] = 206, ["z"] = 1, ["name"] = "stairs:slab_silver_sandstone"}, {["x"] = 12, ["param2"] = 3, ["y"] = 8, ["param1"] = 190, ["z"] = 2, ["name"] = "stairs:slab_silver_sandstone"}, {["x"] = 12, ["param2"] = 3, ["y"] = 8, ["param1"] = 174, ["z"] = 3, ["name"] = "stairs:slab_silver_sandstone"}, {["x"] = 12, ["param2"] = 3, ["y"] = 8, ["param1"] = 174, ["z"] = 4, ["name"] = "stairs:slab_silver_sandstone"}, {["x"] = 12, ["param2"] = 3, ["y"] = 8, ["param1"] = 190, ["z"] = 5, ["name"] = "stairs:slab_silver_sandstone"}, {["x"] = 12, ["param2"] = 3, ["y"] = 8, ["param1"] = 206, ["z"] = 6, ["name"] = "stairs:slab_silver_sandstone"}, {["x"] = 12, ["param2"] = 3, ["y"] = 8, ["param1"] = 222, ["z"] = 7, ["name"] = "stairs:slab_silver_sandstone"}, {["x"] = 13, ["y"] = 0, ["z"] = 1, ["name"] = "the_build_spawner:dark_grey"}, {["x"] = 13, ["y"] = 0, ["z"] = 2, ["name"] = "default:junglewood"}, {["x"] = 13, ["y"] = 0, ["z"] = 3, ["name"] = "default:junglewood"}, {["x"] = 13, ["y"] = 0, ["z"] = 4, ["name"] = "default:junglewood"}, {["x"] = 13, ["y"] = 0, ["z"] = 5, ["name"] = "default:junglewood"}, {["x"] = 13, ["y"] = 0, ["z"] = 6, ["name"] = "the_build_spawner:dark_grey"}, {["x"] = 13, ["y"] = 0, ["z"] = 7, ["name"] = "default:junglewood"}, {["x"] = 13, ["y"] = 0, ["z"] = 8, ["name"] = "default:junglewood"}, {["x"] = 13, ["y"] = 0, ["param1"] = 13, ["z"] = 9, ["name"] = "default:junglewood"}, {["x"] = 13, ["y"] = 0, ["param1"] = 14, ["z"] = 10, ["name"] = "default:junglewood"}, {["x"] = 13, ["y"] = 0, ["param1"] = 15, ["z"] = 11, ["name"] = "default:junglewood"}, {["x"] = 13, ["y"] = 0, ["param1"] = 15, ["z"] = 12, ["name"] = "default:junglewood"}, {["x"] = 13, ["y"] = 0, ["z"] = 13, ["name"] = "default:junglewood"}, {["x"] = 13, ["y"] = 1, ["z"] = 1, ["name"] = "the_build_spawner:dark_grey"}, {["x"] = 13, ["meta"] = {["fields"] = {["infotext"] = "\27(T@default)Empty Bookshelf\27E", ["formspec"] = "size[8,7;]list[context;books;0,0.3;8,2;]list[current_player;main;0,2.85;8,1;]list[current_player;main;0,4.08;8,3;8]listring[context;books]listring[current_player;main]image[0,2.85;1,1;gui_hb_bg.png]image[1,2.85;1,1;gui_hb_bg.png]image[2,2.85;1,1;gui_hb_bg.png]image[3,2.85;1,1;gui_hb_bg.png]image[4,2.85;1,1;gui_hb_bg.png]image[5,2.85;1,1;gui_hb_bg.png]image[6,2.85;1,1;gui_hb_bg.png]image[7,2.85;1,1;gui_hb_bg.png]image[0,0.3;1,1;default_bookshelf_slot.png]image[1,0.3;1,1;default_bookshelf_slot.png]image[2,0.3;1,1;default_bookshelf_slot.png]image[3,0.3;1,1;default_bookshelf_slot.png]image[4,0.3;1,1;default_bookshelf_slot.png]image[5,0.3;1,1;default_bookshelf_slot.png]image[6,0.3;1,1;default_bookshelf_slot.png]image[7,0.3;1,1;default_bookshelf_slot.png]image[0,1.3;1,1;default_bookshelf_slot.png]image[1,1.3;1,1;default_bookshelf_slot.png]image[2,1.3;1,1;default_bookshelf_slot.png]image[3,1.3;1,1;default_bookshelf_slot.png]image[4,1.3;1,1;default_bookshelf_slot.png]image[5,1.3;1,1;default_bookshelf_slot.png]image[6,1.3;1,1;default_bookshelf_slot.png]image[7,1.3;1,1;default_bookshelf_slot.png]"}, ["inventory"] = {["books"] = {"", "", "", "", "", "", "", "", "", "", "", "", "", "", "", ""}}}, ["param2"] = 3, ["y"] = 1, ["z"] = 4, ["name"] = "default:bookshelf"}, {["x"] = 13, ["meta"] = {["fields"] = {["infotext"] = "\27(T@default)Empty Bookshelf\27E", ["formspec"] = "size[8,7;]list[context;books;0,0.3;8,2;]list[current_player;main;0,2.85;8,1;]list[current_player;main;0,4.08;8,3;8]listring[context;books]listring[current_player;main]image[0,2.85;1,1;gui_hb_bg.png]image[1,2.85;1,1;gui_hb_bg.png]image[2,2.85;1,1;gui_hb_bg.png]image[3,2.85;1,1;gui_hb_bg.png]image[4,2.85;1,1;gui_hb_bg.png]image[5,2.85;1,1;gui_hb_bg.png]image[6,2.85;1,1;gui_hb_bg.png]image[7,2.85;1,1;gui_hb_bg.png]image[0,0.3;1,1;default_bookshelf_slot.png]image[1,0.3;1,1;default_bookshelf_slot.png]image[2,0.3;1,1;default_bookshelf_slot.png]image[3,0.3;1,1;default_bookshelf_slot.png]image[4,0.3;1,1;default_bookshelf_slot.png]image[5,0.3;1,1;default_bookshelf_slot.png]image[6,0.3;1,1;default_bookshelf_slot.png]image[7,0.3;1,1;default_bookshelf_slot.png]image[0,1.3;1,1;default_bookshelf_slot.png]image[1,1.3;1,1;default_bookshelf_slot.png]image[2,1.3;1,1;default_bookshelf_slot.png]image[3,1.3;1,1;default_bookshelf_slot.png]image[4,1.3;1,1;default_bookshelf_slot.png]image[5,1.3;1,1;default_bookshelf_slot.png]image[6,1.3;1,1;default_bookshelf_slot.png]image[7,1.3;1,1;default_bookshelf_slot.png]"}, ["inventory"] = {["books"] = {"", "", "", "", "", "", "", "", "", "", "", "", "", "", "", ""}}}, ["param2"] = 3, ["y"] = 1, ["z"] = 5, ["name"] = "default:bookshelf"}, {["x"] = 13, ["y"] = 1, ["z"] = 6, ["name"] = "the_build_spawner:dark_grey"}, {["x"] = 13, ["y"] = 1, ["param1"] = 159, ["z"] = 13, ["name"] = "default:fence_wood"}, {["x"] = 13, ["y"] = 2, ["z"] = 1, ["name"] = "the_build_spawner:dark_grey"}, {["x"] = 13, ["meta"] = {["fields"] = {["infotext"] = "\27(T@default)Empty Bookshelf\27E", ["formspec"] = "size[8,7;]list[context;books;0,0.3;8,2;]list[current_player;main;0,2.85;8,1;]list[current_player;main;0,4.08;8,3;8]listring[context;books]listring[current_player;main]image[0,2.85;1,1;gui_hb_bg.png]image[1,2.85;1,1;gui_hb_bg.png]image[2,2.85;1,1;gui_hb_bg.png]image[3,2.85;1,1;gui_hb_bg.png]image[4,2.85;1,1;gui_hb_bg.png]image[5,2.85;1,1;gui_hb_bg.png]image[6,2.85;1,1;gui_hb_bg.png]image[7,2.85;1,1;gui_hb_bg.png]image[0,0.3;1,1;default_bookshelf_slot.png]image[1,0.3;1,1;default_bookshelf_slot.png]image[2,0.3;1,1;default_bookshelf_slot.png]image[3,0.3;1,1;default_bookshelf_slot.png]image[4,0.3;1,1;default_bookshelf_slot.png]image[5,0.3;1,1;default_bookshelf_slot.png]image[6,0.3;1,1;default_bookshelf_slot.png]image[7,0.3;1,1;default_bookshelf_slot.png]image[0,1.3;1,1;default_bookshelf_slot.png]image[1,1.3;1,1;default_bookshelf_slot.png]image[2,1.3;1,1;default_bookshelf_slot.png]image[3,1.3;1,1;default_bookshelf_slot.png]image[4,1.3;1,1;default_bookshelf_slot.png]image[5,1.3;1,1;default_bookshelf_slot.png]image[6,1.3;1,1;default_bookshelf_slot.png]image[7,1.3;1,1;default_bookshelf_slot.png]"}, ["inventory"] = {["books"] = {"", "", "", "", "", "", "", "", "", "", "", "", "", "", "", ""}}}, ["param2"] = 3, ["y"] = 2, ["z"] = 4, ["name"] = "default:bookshelf"}, {["x"] = 13, ["meta"] = {["fields"] = {["infotext"] = "\27(T@default)Empty Bookshelf\27E", ["formspec"] = "size[8,7;]list[context;books;0,0.3;8,2;]list[current_player;main;0,2.85;8,1;]list[current_player;main;0,4.08;8,3;8]listring[context;books]listring[current_player;main]image[0,2.85;1,1;gui_hb_bg.png]image[1,2.85;1,1;gui_hb_bg.png]image[2,2.85;1,1;gui_hb_bg.png]image[3,2.85;1,1;gui_hb_bg.png]image[4,2.85;1,1;gui_hb_bg.png]image[5,2.85;1,1;gui_hb_bg.png]image[6,2.85;1,1;gui_hb_bg.png]image[7,2.85;1,1;gui_hb_bg.png]image[0,0.3;1,1;default_bookshelf_slot.png]image[1,0.3;1,1;default_bookshelf_slot.png]image[2,0.3;1,1;default_bookshelf_slot.png]image[3,0.3;1,1;default_bookshelf_slot.png]image[4,0.3;1,1;default_bookshelf_slot.png]image[5,0.3;1,1;default_bookshelf_slot.png]image[6,0.3;1,1;default_bookshelf_slot.png]image[7,0.3;1,1;default_bookshelf_slot.png]image[0,1.3;1,1;default_bookshelf_slot.png]image[1,1.3;1,1;default_bookshelf_slot.png]image[2,1.3;1,1;default_bookshelf_slot.png]image[3,1.3;1,1;default_bookshelf_slot.png]image[4,1.3;1,1;default_bookshelf_slot.png]image[5,1.3;1,1;default_bookshelf_slot.png]image[6,1.3;1,1;default_bookshelf_slot.png]image[7,1.3;1,1;default_bookshelf_slot.png]"}, ["inventory"] = {["books"] = {"", "", "", "", "", "", "", "", "", "", "", "", "", "", "", ""}}}, ["param2"] = 3, ["y"] = 2, ["z"] = 5, ["name"] = "default:bookshelf"}, {["x"] = 13, ["y"] = 2, ["z"] = 6, ["name"] = "the_build_spawner:dark_grey"}, {["x"] = 13, ["y"] = 3, ["z"] = 1, ["name"] = "the_build_spawner:dark_grey"}, {["x"] = 13, ["meta"] = {["fields"] = {["infotext"] = "\27(T@default)Empty Bookshelf\27E", ["formspec"] = "size[8,7;]list[context;books;0,0.3;8,2;]list[current_player;main;0,2.85;8,1;]list[current_player;main;0,4.08;8,3;8]listring[context;books]listring[current_player;main]image[0,2.85;1,1;gui_hb_bg.png]image[1,2.85;1,1;gui_hb_bg.png]image[2,2.85;1,1;gui_hb_bg.png]image[3,2.85;1,1;gui_hb_bg.png]image[4,2.85;1,1;gui_hb_bg.png]image[5,2.85;1,1;gui_hb_bg.png]image[6,2.85;1,1;gui_hb_bg.png]image[7,2.85;1,1;gui_hb_bg.png]image[0,0.3;1,1;default_bookshelf_slot.png]image[1,0.3;1,1;default_bookshelf_slot.png]image[2,0.3;1,1;default_bookshelf_slot.png]image[3,0.3;1,1;default_bookshelf_slot.png]image[4,0.3;1,1;default_bookshelf_slot.png]image[5,0.3;1,1;default_bookshelf_slot.png]image[6,0.3;1,1;default_bookshelf_slot.png]image[7,0.3;1,1;default_bookshelf_slot.png]image[0,1.3;1,1;default_bookshelf_slot.png]image[1,1.3;1,1;default_bookshelf_slot.png]image[2,1.3;1,1;default_bookshelf_slot.png]image[3,1.3;1,1;default_bookshelf_slot.png]image[4,1.3;1,1;default_bookshelf_slot.png]image[5,1.3;1,1;default_bookshelf_slot.png]image[6,1.3;1,1;default_bookshelf_slot.png]image[7,1.3;1,1;default_bookshelf_slot.png]"}, ["inventory"] = {["books"] = {"", "", "", "", "", "", "", "", "", "", "", "", "", "", "", ""}}}, ["param2"] = 3, ["y"] = 3, ["z"] = 4, ["name"] = "default:bookshelf"}, {["x"] = 13, ["meta"] = {["fields"] = {["infotext"] = "\27(T@default)Empty Bookshelf\27E", ["formspec"] = "size[8,7;]list[context;books;0,0.3;8,2;]list[current_player;main;0,2.85;8,1;]list[current_player;main;0,4.08;8,3;8]listring[context;books]listring[current_player;main]image[0,2.85;1,1;gui_hb_bg.png]image[1,2.85;1,1;gui_hb_bg.png]image[2,2.85;1,1;gui_hb_bg.png]image[3,2.85;1,1;gui_hb_bg.png]image[4,2.85;1,1;gui_hb_bg.png]image[5,2.85;1,1;gui_hb_bg.png]image[6,2.85;1,1;gui_hb_bg.png]image[7,2.85;1,1;gui_hb_bg.png]image[0,0.3;1,1;default_bookshelf_slot.png]image[1,0.3;1,1;default_bookshelf_slot.png]image[2,0.3;1,1;default_bookshelf_slot.png]image[3,0.3;1,1;default_bookshelf_slot.png]image[4,0.3;1,1;default_bookshelf_slot.png]image[5,0.3;1,1;default_bookshelf_slot.png]image[6,0.3;1,1;default_bookshelf_slot.png]image[7,0.3;1,1;default_bookshelf_slot.png]image[0,1.3;1,1;default_bookshelf_slot.png]image[1,1.3;1,1;default_bookshelf_slot.png]image[2,1.3;1,1;default_bookshelf_slot.png]image[3,1.3;1,1;default_bookshelf_slot.png]image[4,1.3;1,1;default_bookshelf_slot.png]image[5,1.3;1,1;default_bookshelf_slot.png]image[6,1.3;1,1;default_bookshelf_slot.png]image[7,1.3;1,1;default_bookshelf_slot.png]"}, ["inventory"] = {["books"] = {"", "", "", "", "", "", "", "", "", "", "", "", "", "", "", ""}}}, ["param2"] = 3, ["y"] = 3, ["z"] = 5, ["name"] = "default:bookshelf"}, {["x"] = 13, ["y"] = 3, ["z"] = 6, ["name"] = "the_build_spawner:dark_grey"}, {["x"] = 13, ["y"] = 4, ["z"] = 1, ["name"] = "the_build_spawner:dark_grey"}, {["x"] = 13, ["param2"] = 3, ["y"] = 4, ["param1"] = 158, ["z"] = 4, ["name"] = "stairs:stair_junglewood"}, {["x"] = 13, ["param2"] = 3, ["y"] = 4, ["param1"] = 174, ["z"] = 5, ["name"] = "stairs:stair_junglewood"}, {["x"] = 13, ["y"] = 4, ["z"] = 6, ["name"] = "the_build_spawner:dark_grey"}, {["x"] = 13, ["y"] = 5, ["z"] = 1, ["name"] = "the_build_spawner:dark_grey"}, {["x"] = 13, ["y"] = 5, ["z"] = 6, ["name"] = "the_build_spawner:dark_grey"}, {["x"] = 13, ["y"] = 6, ["z"] = 1, ["name"] = "the_build_spawner:dark_grey"}, {["x"] = 13, ["y"] = 6, ["z"] = 6, ["name"] = "the_build_spawner:dark_grey"}, {["x"] = 13, ["y"] = 7, ["z"] = 1, ["name"] = "the_build_spawner:dark_grey"}, {["x"] = 13, ["y"] = 7, ["z"] = 2, ["name"] = "the_build_spawner:dark_grey"}, {["x"] = 13, ["y"] = 7, ["z"] = 3, ["name"] = "the_build_spawner:dark_grey"}, {["x"] = 13, ["y"] = 7, ["z"] = 4, ["name"] = "the_build_spawner:dark_grey"}, {["x"] = 13, ["y"] = 7, ["z"] = 5, ["name"] = "the_build_spawner:dark_grey"}, {["x"] = 13, ["y"] = 7, ["z"] = 6, ["name"] = "the_build_spawner:dark_grey"}, {["x"] = 13, ["param2"] = 3, ["y"] = 8, ["param1"] = 206, ["z"] = 0, ["name"] = "stairs:slab_silver_sandstone"}, {["x"] = 13, ["param2"] = 1, ["y"] = 8, ["param1"] = 190, ["z"] = 1, ["name"] = "stairs:slab_silver_sandstone"}, {["x"] = 13, ["param2"] = 1, ["y"] = 8, ["param1"] = 206, ["z"] = 2, ["name"] = "stairs:slab_silver_sandstone"}, {["x"] = 13, ["param2"] = 1, ["y"] = 8, ["param1"] = 190, ["z"] = 3, ["name"] = "stairs:slab_silver_sandstone"}, {["x"] = 13, ["param2"] = 1, ["y"] = 8, ["param1"] = 190, ["z"] = 4, ["name"] = "stairs:slab_silver_sandstone"}, {["x"] = 13, ["param2"] = 1, ["y"] = 8, ["param1"] = 206, ["z"] = 5, ["name"] = "stairs:slab_silver_sandstone"}, {["x"] = 13, ["param2"] = 1, ["y"] = 8, ["param1"] = 190, ["z"] = 6, ["name"] = "stairs:slab_silver_sandstone"}, {["x"] = 13, ["param2"] = 1, ["y"] = 8, ["param1"] = 206, ["z"] = 7, ["name"] = "stairs:slab_silver_sandstone"}, {["x"] = 14, ["y"] = 0, ["z"] = 1, ["name"] = "the_build_spawner:dark_grey"}, {["x"] = 14, ["y"] = 0, ["z"] = 2, ["name"] = "default:junglewood"}, {["x"] = 14, ["y"] = 0, ["z"] = 3, ["name"] = "default:junglewood"}, {["x"] = 14, ["y"] = 0, ["z"] = 4, ["name"] = "default:junglewood"}, {["x"] = 14, ["y"] = 0, ["z"] = 5, ["name"] = "default:junglewood"}, {["x"] = 14, ["y"] = 0, ["z"] = 6, ["name"] = "the_build_spawner:dark_grey"}, {["x"] = 14, ["y"] = 0, ["z"] = 7, ["name"] = "default:junglewood"}, {["x"] = 14, ["y"] = 0, ["z"] = 8, ["name"] = "default:junglewood"}, {["x"] = 14, ["y"] = 0, ["param1"] = 13, ["z"] = 9, ["name"] = "default:junglewood"}, {["x"] = 14, ["y"] = 0, ["param1"] = 14, ["z"] = 10, ["name"] = "default:junglewood"}, {["x"] = 14, ["y"] = 0, ["param1"] = 15, ["z"] = 11, ["name"] = "default:junglewood"}, {["x"] = 14, ["y"] = 0, ["param1"] = 15, ["z"] = 12, ["name"] = "default:junglewood"}, {["x"] = 14, ["y"] = 0, ["z"] = 13, ["name"] = "default:junglewood"}, {["x"] = 14, ["y"] = 1, ["z"] = 1, ["name"] = "the_build_spawner:dark_grey"}, {["x"] = 14, ["param2"] = 1, ["y"] = 1, ["param1"] = 142, ["z"] = 2, ["name"] = "stairs:stair_junglewood"}, {["x"] = 14, ["param2"] = 1, ["y"] = 1, ["param1"] = 126, ["z"] = 3, ["name"] = "stairs:stair_junglewood"}, {["x"] = 14, ["meta"] = {["fields"] = {["infotext"] = "\27(T@default)Empty Bookshelf\27E", ["formspec"] = "size[8,7;]list[context;books;0,0.3;8,2;]list[current_player;main;0,2.85;8,1;]list[current_player;main;0,4.08;8,3;8]listring[context;books]listring[current_player;main]image[0,2.85;1,1;gui_hb_bg.png]image[1,2.85;1,1;gui_hb_bg.png]image[2,2.85;1,1;gui_hb_bg.png]image[3,2.85;1,1;gui_hb_bg.png]image[4,2.85;1,1;gui_hb_bg.png]image[5,2.85;1,1;gui_hb_bg.png]image[6,2.85;1,1;gui_hb_bg.png]image[7,2.85;1,1;gui_hb_bg.png]image[0,0.3;1,1;default_bookshelf_slot.png]image[1,0.3;1,1;default_bookshelf_slot.png]image[2,0.3;1,1;default_bookshelf_slot.png]image[3,0.3;1,1;default_bookshelf_slot.png]image[4,0.3;1,1;default_bookshelf_slot.png]image[5,0.3;1,1;default_bookshelf_slot.png]image[6,0.3;1,1;default_bookshelf_slot.png]image[7,0.3;1,1;default_bookshelf_slot.png]image[0,1.3;1,1;default_bookshelf_slot.png]image[1,1.3;1,1;default_bookshelf_slot.png]image[2,1.3;1,1;default_bookshelf_slot.png]image[3,1.3;1,1;default_bookshelf_slot.png]image[4,1.3;1,1;default_bookshelf_slot.png]image[5,1.3;1,1;default_bookshelf_slot.png]image[6,1.3;1,1;default_bookshelf_slot.png]image[7,1.3;1,1;default_bookshelf_slot.png]"}, ["inventory"] = {["books"] = {"", "", "", "", "", "", "", "", "", "", "", "", "", "", "", ""}}}, ["param2"] = 3, ["y"] = 1, ["z"] = 4, ["name"] = "default:bookshelf"}, {["x"] = 14, ["meta"] = {["fields"] = {["infotext"] = "\27(T@default)Empty Bookshelf\27E", ["formspec"] = "size[8,7;]list[context;books;0,0.3;8,2;]list[current_player;main;0,2.85;8,1;]list[current_player;main;0,4.08;8,3;8]listring[context;books]listring[current_player;main]image[0,2.85;1,1;gui_hb_bg.png]image[1,2.85;1,1;gui_hb_bg.png]image[2,2.85;1,1;gui_hb_bg.png]image[3,2.85;1,1;gui_hb_bg.png]image[4,2.85;1,1;gui_hb_bg.png]image[5,2.85;1,1;gui_hb_bg.png]image[6,2.85;1,1;gui_hb_bg.png]image[7,2.85;1,1;gui_hb_bg.png]image[0,0.3;1,1;default_bookshelf_slot.png]image[1,0.3;1,1;default_bookshelf_slot.png]image[2,0.3;1,1;default_bookshelf_slot.png]image[3,0.3;1,1;default_bookshelf_slot.png]image[4,0.3;1,1;default_bookshelf_slot.png]image[5,0.3;1,1;default_bookshelf_slot.png]image[6,0.3;1,1;default_bookshelf_slot.png]image[7,0.3;1,1;default_bookshelf_slot.png]image[0,1.3;1,1;default_bookshelf_slot.png]image[1,1.3;1,1;default_bookshelf_slot.png]image[2,1.3;1,1;default_bookshelf_slot.png]image[3,1.3;1,1;default_bookshelf_slot.png]image[4,1.3;1,1;default_bookshelf_slot.png]image[5,1.3;1,1;default_bookshelf_slot.png]image[6,1.3;1,1;default_bookshelf_slot.png]image[7,1.3;1,1;default_bookshelf_slot.png]"}, ["inventory"] = {["books"] = {"", "", "", "", "", "", "", "", "", "", "", "", "", "", "", ""}}}, ["param2"] = 3, ["y"] = 1, ["z"] = 5, ["name"] = "default:bookshelf"}, {["x"] = 14, ["y"] = 1, ["z"] = 6, ["name"] = "the_build_spawner:dark_grey"}, {["x"] = 14, ["y"] = 1, ["param1"] = 174, ["z"] = 13, ["name"] = "default:fence_wood"}, {["x"] = 14, ["y"] = 2, ["z"] = 1, ["name"] = "the_build_spawner:dark_grey"}, {["x"] = 14, ["meta"] = {["fields"] = {["infotext"] = "\27(T@default)Empty Bookshelf\27E", ["formspec"] = "size[8,7;]list[context;books;0,0.3;8,2;]list[current_player;main;0,2.85;8,1;]list[current_player;main;0,4.08;8,3;8]listring[context;books]listring[current_player;main]image[0,2.85;1,1;gui_hb_bg.png]image[1,2.85;1,1;gui_hb_bg.png]image[2,2.85;1,1;gui_hb_bg.png]image[3,2.85;1,1;gui_hb_bg.png]image[4,2.85;1,1;gui_hb_bg.png]image[5,2.85;1,1;gui_hb_bg.png]image[6,2.85;1,1;gui_hb_bg.png]image[7,2.85;1,1;gui_hb_bg.png]image[0,0.3;1,1;default_bookshelf_slot.png]image[1,0.3;1,1;default_bookshelf_slot.png]image[2,0.3;1,1;default_bookshelf_slot.png]image[3,0.3;1,1;default_bookshelf_slot.png]image[4,0.3;1,1;default_bookshelf_slot.png]image[5,0.3;1,1;default_bookshelf_slot.png]image[6,0.3;1,1;default_bookshelf_slot.png]image[7,0.3;1,1;default_bookshelf_slot.png]image[0,1.3;1,1;default_bookshelf_slot.png]image[1,1.3;1,1;default_bookshelf_slot.png]image[2,1.3;1,1;default_bookshelf_slot.png]image[3,1.3;1,1;default_bookshelf_slot.png]image[4,1.3;1,1;default_bookshelf_slot.png]image[5,1.3;1,1;default_bookshelf_slot.png]image[6,1.3;1,1;default_bookshelf_slot.png]image[7,1.3;1,1;default_bookshelf_slot.png]"}, ["inventory"] = {["books"] = {"", "", "", "", "", "", "", "", "", "", "", "", "", "", "", ""}}}, ["param2"] = 3, ["y"] = 2, ["z"] = 4, ["name"] = "default:bookshelf"}, {["x"] = 14, ["meta"] = {["fields"] = {["infotext"] = "\27(T@default)Empty Bookshelf\27E", ["formspec"] = "size[8,7;]list[context;books;0,0.3;8,2;]list[current_player;main;0,2.85;8,1;]list[current_player;main;0,4.08;8,3;8]listring[context;books]listring[current_player;main]image[0,2.85;1,1;gui_hb_bg.png]image[1,2.85;1,1;gui_hb_bg.png]image[2,2.85;1,1;gui_hb_bg.png]image[3,2.85;1,1;gui_hb_bg.png]image[4,2.85;1,1;gui_hb_bg.png]image[5,2.85;1,1;gui_hb_bg.png]image[6,2.85;1,1;gui_hb_bg.png]image[7,2.85;1,1;gui_hb_bg.png]image[0,0.3;1,1;default_bookshelf_slot.png]image[1,0.3;1,1;default_bookshelf_slot.png]image[2,0.3;1,1;default_bookshelf_slot.png]image[3,0.3;1,1;default_bookshelf_slot.png]image[4,0.3;1,1;default_bookshelf_slot.png]image[5,0.3;1,1;default_bookshelf_slot.png]image[6,0.3;1,1;default_bookshelf_slot.png]image[7,0.3;1,1;default_bookshelf_slot.png]image[0,1.3;1,1;default_bookshelf_slot.png]image[1,1.3;1,1;default_bookshelf_slot.png]image[2,1.3;1,1;default_bookshelf_slot.png]image[3,1.3;1,1;default_bookshelf_slot.png]image[4,1.3;1,1;default_bookshelf_slot.png]image[5,1.3;1,1;default_bookshelf_slot.png]image[6,1.3;1,1;default_bookshelf_slot.png]image[7,1.3;1,1;default_bookshelf_slot.png]"}, ["inventory"] = {["books"] = {"", "", "", "", "", "", "", "", "", "", "", "", "", "", "", ""}}}, ["param2"] = 3, ["y"] = 2, ["z"] = 5, ["name"] = "default:bookshelf"}, {["x"] = 14, ["y"] = 2, ["z"] = 6, ["name"] = "the_build_spawner:dark_grey"}, {["x"] = 14, ["y"] = 2, ["param1"] = 190, ["z"] = 13, ["name"] = "default:fence_wood"}, {["x"] = 14, ["y"] = 3, ["z"] = 1, ["name"] = "the_build_spawner:dark_grey"}, {["x"] = 14, ["param2"] = 3, ["y"] = 3, ["param1"] = 158, ["z"] = 4, ["name"] = "stairs:stair_junglewood"}, {["x"] = 14, ["param2"] = 3, ["y"] = 3, ["param1"] = 174, ["z"] = 5, ["name"] = "stairs:stair_junglewood"}, {["x"] = 14, ["y"] = 3, ["z"] = 6, ["name"] = "the_build_spawner:dark_grey"}, {["x"] = 14, ["y"] = 3, ["param1"] = 206, ["z"] = 13, ["name"] = "default:fence_wood"}, {["x"] = 14, ["y"] = 4, ["z"] = 1, ["name"] = "the_build_spawner:dark_grey"}, {["x"] = 14, ["y"] = 4, ["z"] = 6, ["name"] = "the_build_spawner:dark_grey"}, {["x"] = 14, ["y"] = 4, ["param1"] = 238, ["z"] = 12, ["name"] = "default:mese_post_light_junglewood"}, {["x"] = 14, ["y"] = 4, ["param1"] = 222, ["z"] = 13, ["name"] = "default:fence_wood"}, {["x"] = 14, ["y"] = 5, ["z"] = 1, ["name"] = "the_build_spawner:dark_grey"}, {["x"] = 14, ["y"] = 5, ["z"] = 6, ["name"] = "the_build_spawner:dark_grey"}, {["x"] = 14, ["y"] = 5, ["param1"] = 174, ["z"] = 7, ["name"] = "stairs:slab_wood"}, {["x"] = 14, ["y"] = 5, ["param1"] = 158, ["z"] = 8, ["name"] = "stairs:slab_wood"}, {["x"] = 14, ["y"] = 5, ["param1"] = 173, ["z"] = 9, ["name"] = "stairs:slab_wood"}, {["x"] = 14, ["y"] = 5, ["param1"] = 189, ["z"] = 10, ["name"] = "stairs:slab_wood"}, {["x"] = 14, ["y"] = 5, ["param1"] = 206, ["z"] = 11, ["name"] = "stairs:slab_wood"}, {["x"] = 14, ["y"] = 5, ["param1"] = 222, ["z"] = 12, ["name"] = "stairs:slab_wood"}, {["x"] = 14, ["param2"] = 3, ["y"] = 5, ["param1"] = 206, ["z"] = 13, ["name"] = "stairs:slab_wood"}, {["x"] = 14, ["y"] = 6, ["z"] = 1, ["name"] = "the_build_spawner:dark_grey"}, {["x"] = 14, ["y"] = 6, ["z"] = 6, ["name"] = "the_build_spawner:dark_grey"}, {["x"] = 14, ["y"] = 7, ["z"] = 1, ["name"] = "the_build_spawner:dark_grey"}, {["x"] = 14, ["y"] = 7, ["param1"] = 238, ["z"] = 2, ["name"] = "default:mese_post_light_junglewood"}, {["x"] = 14, ["y"] = 7, ["param1"] = 238, ["z"] = 5, ["name"] = "default:mese_post_light_junglewood"}, {["x"] = 14, ["y"] = 7, ["z"] = 6, ["name"] = "the_build_spawner:dark_grey"}, {["x"] = 14, ["param2"] = 3, ["y"] = 8, ["param1"] = 190, ["z"] = 0, ["name"] = "stairs:slab_silver_sandstone"}, {["x"] = 14, ["y"] = 8, ["param1"] = 206, ["z"] = 1, ["name"] = "stairs:slab_silver_sandstone"}, {["x"] = 14, ["y"] = 8, ["param1"] = 222, ["z"] = 2, ["name"] = "stairs:slab_silver_sandstone"}, {["x"] = 14, ["y"] = 8, ["param1"] = 206, ["z"] = 3, ["name"] = "stairs:slab_silver_sandstone"}, {["x"] = 14, ["y"] = 8, ["param1"] = 206, ["z"] = 4, ["name"] = "stairs:slab_silver_sandstone"}, {["x"] = 14, ["y"] = 8, ["param1"] = 222, ["z"] = 5, ["name"] = "stairs:slab_silver_sandstone"}, {["x"] = 14, ["param2"] = 2, ["y"] = 8, ["param1"] = 206, ["z"] = 6, ["name"] = "stairs:slab_silver_sandstone"}, {["x"] = 14, ["param2"] = 1, ["y"] = 8, ["param1"] = 190, ["z"] = 7, ["name"] = "stairs:slab_silver_sandstone"}, {["x"] = 15, ["y"] = 0, ["z"] = 1, ["name"] = "the_build_spawner:dark_grey"}, {["x"] = 15, ["y"] = 0, ["z"] = 2, ["name"] = "default:junglewood"}, {["x"] = 15, ["y"] = 0, ["z"] = 3, ["name"] = "default:junglewood"}, {["x"] = 15, ["y"] = 0, ["z"] = 4, ["name"] = "default:junglewood"}, {["x"] = 15, ["y"] = 0, ["z"] = 5, ["name"] = "default:junglewood"}, {["x"] = 15, ["y"] = 0, ["z"] = 6, ["name"] = "the_build_spawner:dark_grey"}, {["x"] = 15, ["y"] = 0, ["z"] = 7, ["name"] = "default:junglewood"}, {["x"] = 15, ["y"] = 0, ["z"] = 8, ["name"] = "default:junglewood"}, {["x"] = 15, ["y"] = 0, ["param1"] = 13, ["z"] = 9, ["name"] = "default:junglewood"}, {["x"] = 15, ["y"] = 0, ["param1"] = 14, ["z"] = 10, ["name"] = "default:junglewood"}, {["x"] = 15, ["y"] = 0, ["param1"] = 15, ["z"] = 11, ["name"] = "default:junglewood"}, {["x"] = 15, ["y"] = 0, ["param1"] = 15, ["z"] = 12, ["name"] = "default:junglewood"}, {["x"] = 15, ["y"] = 0, ["z"] = 13, ["name"] = "default:junglewood"}, {["x"] = 15, ["y"] = 1, ["z"] = 1, ["name"] = "the_build_spawner:dark_grey"}, {["x"] = 15, ["meta"] = {["fields"] = {["infotext"] = "\27(T@default)Empty Bookshelf\27E", ["formspec"] = "size[8,7;]list[context;books;0,0.3;8,2;]list[current_player;main;0,2.85;8,1;]list[current_player;main;0,4.08;8,3;8]listring[context;books]listring[current_player;main]image[0,2.85;1,1;gui_hb_bg.png]image[1,2.85;1,1;gui_hb_bg.png]image[2,2.85;1,1;gui_hb_bg.png]image[3,2.85;1,1;gui_hb_bg.png]image[4,2.85;1,1;gui_hb_bg.png]image[5,2.85;1,1;gui_hb_bg.png]image[6,2.85;1,1;gui_hb_bg.png]image[7,2.85;1,1;gui_hb_bg.png]image[0,0.3;1,1;default_bookshelf_slot.png]image[1,0.3;1,1;default_bookshelf_slot.png]image[2,0.3;1,1;default_bookshelf_slot.png]image[3,0.3;1,1;default_bookshelf_slot.png]image[4,0.3;1,1;default_bookshelf_slot.png]image[5,0.3;1,1;default_bookshelf_slot.png]image[6,0.3;1,1;default_bookshelf_slot.png]image[7,0.3;1,1;default_bookshelf_slot.png]image[0,1.3;1,1;default_bookshelf_slot.png]image[1,1.3;1,1;default_bookshelf_slot.png]image[2,1.3;1,1;default_bookshelf_slot.png]image[3,1.3;1,1;default_bookshelf_slot.png]image[4,1.3;1,1;default_bookshelf_slot.png]image[5,1.3;1,1;default_bookshelf_slot.png]image[6,1.3;1,1;default_bookshelf_slot.png]image[7,1.3;1,1;default_bookshelf_slot.png]"}, ["inventory"] = {["books"] = {"", "", "", "", "", "", "", "", "", "", "", "", "", "", "", ""}}}, ["param2"] = 3, ["y"] = 1, ["z"] = 4, ["name"] = "default:bookshelf"}, {["x"] = 15, ["meta"] = {["fields"] = {["infotext"] = "\27(T@default)Empty Bookshelf\27E", ["formspec"] = "size[8,7;]list[context;books;0,0.3;8,2;]list[current_player;main;0,2.85;8,1;]list[current_player;main;0,4.08;8,3;8]listring[context;books]listring[current_player;main]image[0,2.85;1,1;gui_hb_bg.png]image[1,2.85;1,1;gui_hb_bg.png]image[2,2.85;1,1;gui_hb_bg.png]image[3,2.85;1,1;gui_hb_bg.png]image[4,2.85;1,1;gui_hb_bg.png]image[5,2.85;1,1;gui_hb_bg.png]image[6,2.85;1,1;gui_hb_bg.png]image[7,2.85;1,1;gui_hb_bg.png]image[0,0.3;1,1;default_bookshelf_slot.png]image[1,0.3;1,1;default_bookshelf_slot.png]image[2,0.3;1,1;default_bookshelf_slot.png]image[3,0.3;1,1;default_bookshelf_slot.png]image[4,0.3;1,1;default_bookshelf_slot.png]image[5,0.3;1,1;default_bookshelf_slot.png]image[6,0.3;1,1;default_bookshelf_slot.png]image[7,0.3;1,1;default_bookshelf_slot.png]image[0,1.3;1,1;default_bookshelf_slot.png]image[1,1.3;1,1;default_bookshelf_slot.png]image[2,1.3;1,1;default_bookshelf_slot.png]image[3,1.3;1,1;default_bookshelf_slot.png]image[4,1.3;1,1;default_bookshelf_slot.png]image[5,1.3;1,1;default_bookshelf_slot.png]image[6,1.3;1,1;default_bookshelf_slot.png]image[7,1.3;1,1;default_bookshelf_slot.png]"}, ["inventory"] = {["books"] = {"", "", "", "", "", "", "", "", "", "", "", "", "", "", "", ""}}}, ["param2"] = 3, ["y"] = 1, ["z"] = 5, ["name"] = "default:bookshelf"}, {["x"] = 15, ["y"] = 1, ["z"] = 6, ["name"] = "the_build_spawner:dark_grey"}, {["x"] = 15, ["param2"] = 2, ["y"] = 1, ["param1"] = 141, ["z"] = 10, ["name"] = "stairs:stair_junglewood"}, {["x"] = 15, ["y"] = 1, ["param1"] = 158, ["z"] = 11, ["name"] = "default:fence_wood"}, {["x"] = 15, ["y"] = 1, ["param1"] = 174, ["z"] = 12, ["name"] = "stairs:stair_junglewood"}, {["x"] = 15, ["y"] = 1, ["param1"] = 190, ["z"] = 13, ["name"] = "default:fence_wood"}, {["x"] = 15, ["y"] = 2, ["z"] = 1, ["name"] = "the_build_spawner:dark_grey"}, {["x"] = 15, ["param2"] = 1, ["y"] = 2, ["param1"] = 142, ["z"] = 2, ["name"] = "stairs:stair_junglewood"}, {["x"] = 15, ["param2"] = 1, ["y"] = 2, ["param1"] = 126, ["z"] = 3, ["name"] = "stairs:stair_junglewood"}, {["x"] = 15, ["meta"] = {["fields"] = {["infotext"] = "\27(T@default)Empty Bookshelf\27E", ["formspec"] = "size[8,7;]list[context;books;0,0.3;8,2;]list[current_player;main;0,2.85;8,1;]list[current_player;main;0,4.08;8,3;8]listring[context;books]listring[current_player;main]image[0,2.85;1,1;gui_hb_bg.png]image[1,2.85;1,1;gui_hb_bg.png]image[2,2.85;1,1;gui_hb_bg.png]image[3,2.85;1,1;gui_hb_bg.png]image[4,2.85;1,1;gui_hb_bg.png]image[5,2.85;1,1;gui_hb_bg.png]image[6,2.85;1,1;gui_hb_bg.png]image[7,2.85;1,1;gui_hb_bg.png]image[0,0.3;1,1;default_bookshelf_slot.png]image[1,0.3;1,1;default_bookshelf_slot.png]image[2,0.3;1,1;default_bookshelf_slot.png]image[3,0.3;1,1;default_bookshelf_slot.png]image[4,0.3;1,1;default_bookshelf_slot.png]image[5,0.3;1,1;default_bookshelf_slot.png]image[6,0.3;1,1;default_bookshelf_slot.png]image[7,0.3;1,1;default_bookshelf_slot.png]image[0,1.3;1,1;default_bookshelf_slot.png]image[1,1.3;1,1;default_bookshelf_slot.png]image[2,1.3;1,1;default_bookshelf_slot.png]image[3,1.3;1,1;default_bookshelf_slot.png]image[4,1.3;1,1;default_bookshelf_slot.png]image[5,1.3;1,1;default_bookshelf_slot.png]image[6,1.3;1,1;default_bookshelf_slot.png]image[7,1.3;1,1;default_bookshelf_slot.png]"}, ["inventory"] = {["books"] = {"", "", "", "", "", "", "", "", "", "", "", "", "", "", "", ""}}}, ["param2"] = 3, ["y"] = 2, ["z"] = 4, ["name"] = "default:bookshelf"}, {["x"] = 15, ["meta"] = {["fields"] = {["infotext"] = "\27(T@default)Empty Bookshelf\27E", ["formspec"] = "size[8,7;]list[context;books;0,0.3;8,2;]list[current_player;main;0,2.85;8,1;]list[current_player;main;0,4.08;8,3;8]listring[context;books]listring[current_player;main]image[0,2.85;1,1;gui_hb_bg.png]image[1,2.85;1,1;gui_hb_bg.png]image[2,2.85;1,1;gui_hb_bg.png]image[3,2.85;1,1;gui_hb_bg.png]image[4,2.85;1,1;gui_hb_bg.png]image[5,2.85;1,1;gui_hb_bg.png]image[6,2.85;1,1;gui_hb_bg.png]image[7,2.85;1,1;gui_hb_bg.png]image[0,0.3;1,1;default_bookshelf_slot.png]image[1,0.3;1,1;default_bookshelf_slot.png]image[2,0.3;1,1;default_bookshelf_slot.png]image[3,0.3;1,1;default_bookshelf_slot.png]image[4,0.3;1,1;default_bookshelf_slot.png]image[5,0.3;1,1;default_bookshelf_slot.png]image[6,0.3;1,1;default_bookshelf_slot.png]image[7,0.3;1,1;default_bookshelf_slot.png]image[0,1.3;1,1;default_bookshelf_slot.png]image[1,1.3;1,1;default_bookshelf_slot.png]image[2,1.3;1,1;default_bookshelf_slot.png]image[3,1.3;1,1;default_bookshelf_slot.png]image[4,1.3;1,1;default_bookshelf_slot.png]image[5,1.3;1,1;default_bookshelf_slot.png]image[6,1.3;1,1;default_bookshelf_slot.png]image[7,1.3;1,1;default_bookshelf_slot.png]"}, ["inventory"] = {["books"] = {"", "", "", "", "", "", "", "", "", "", "", "", "", "", "", ""}}}, ["param2"] = 3, ["y"] = 2, ["z"] = 5, ["name"] = "default:bookshelf"}, {["x"] = 15, ["y"] = 2, ["z"] = 6, ["name"] = "the_build_spawner:dark_grey"}, {["x"] = 15, ["param2"] = 3, ["y"] = 2, ["param1"] = 174, ["z"] = 11, ["name"] = "doors:trapdoor"}, {["x"] = 15, ["y"] = 3, ["z"] = 1, ["name"] = "the_build_spawner:dark_grey"}, {["x"] = 15, ["y"] = 3, ["z"] = 6, ["name"] = "the_build_spawner:dark_grey"}, {["x"] = 15, ["y"] = 4, ["z"] = 1, ["name"] = "the_build_spawner:dark_grey"}, {["x"] = 15, ["y"] = 4, ["z"] = 6, ["name"] = "the_build_spawner:dark_grey"}, {["x"] = 15, ["y"] = 4, ["param1"] = 238, ["z"] = 13, ["name"] = "default:mese_post_light_junglewood"}, {["x"] = 15, ["y"] = 5, ["z"] = 1, ["name"] = "the_build_spawner:dark_grey"}, {["x"] = 15, ["y"] = 5, ["z"] = 6, ["name"] = "the_build_spawner:dark_grey"}, {["x"] = 15, ["y"] = 5, ["param1"] = 158, ["z"] = 7, ["name"] = "stairs:slab_wood"}, {["x"] = 15, ["y"] = 5, ["param1"] = 142, ["z"] = 8, ["name"] = "stairs:slab_wood"}, {["x"] = 15, ["y"] = 5, ["param1"] = 157, ["z"] = 9, ["name"] = "stairs:slab_wood"}, {["x"] = 15, ["y"] = 5, ["param1"] = 173, ["z"] = 10, ["name"] = "stairs:slab_wood"}, {["x"] = 15, ["y"] = 5, ["param1"] = 190, ["z"] = 11, ["name"] = "stairs:slab_wood"}, {["x"] = 15, ["y"] = 5, ["param1"] = 206, ["z"] = 12, ["name"] = "stairs:slab_wood"}, {["x"] = 15, ["param2"] = 3, ["y"] = 5, ["param1"] = 222, ["z"] = 13, ["name"] = "stairs:slab_wood"}, {["x"] = 15, ["y"] = 6, ["z"] = 1, ["name"] = "the_build_spawner:dark_grey"}, {["x"] = 15, ["y"] = 6, ["z"] = 6, ["name"] = "the_build_spawner:dark_grey"}, {["x"] = 15, ["y"] = 7, ["z"] = 1, ["name"] = "the_build_spawner:dark_grey"}, {["x"] = 15, ["y"] = 7, ["z"] = 6, ["name"] = "the_build_spawner:dark_grey"}, {["x"] = 15, ["param2"] = 3, ["y"] = 8, ["param1"] = 174, ["z"] = 0, ["name"] = "stairs:slab_silver_sandstone"}, {["x"] = 15, ["y"] = 8, ["param1"] = 190, ["z"] = 1, ["name"] = "stairs:slab_silver_sandstone"}, {["x"] = 15, ["y"] = 8, ["param1"] = 206, ["z"] = 2, ["name"] = "stairs:slab_silver_sandstone"}, {["x"] = 15, ["y"] = 8, ["param1"] = 190, ["z"] = 3, ["name"] = "stairs:slab_silver_sandstone"}, {["x"] = 15, ["y"] = 8, ["param1"] = 190, ["z"] = 4, ["name"] = "stairs:slab_silver_sandstone"}, {["x"] = 15, ["y"] = 8, ["param1"] = 206, ["z"] = 5, ["name"] = "stairs:slab_silver_sandstone"}, {["x"] = 15, ["param2"] = 2, ["y"] = 8, ["param1"] = 190, ["z"] = 6, ["name"] = "stairs:slab_silver_sandstone"}, {["x"] = 15, ["param2"] = 1, ["y"] = 8, ["param1"] = 174, ["z"] = 7, ["name"] = "stairs:slab_silver_sandstone"}, {["x"] = 16, ["y"] = 0, ["z"] = 1, ["name"] = "the_build_spawner:dark_grey"}, {["x"] = 16, ["y"] = 0, ["z"] = 2, ["name"] = "default:junglewood"}, {["x"] = 16, ["y"] = 0, ["z"] = 3, ["name"] = "default:junglewood"}, {["x"] = 16, ["y"] = 0, ["z"] = 4, ["name"] = "default:junglewood"}, {["x"] = 16, ["y"] = 0, ["z"] = 5, ["name"] = "default:junglewood"}, {["x"] = 16, ["y"] = 0, ["z"] = 6, ["name"] = "the_build_spawner:dark_grey"}, {["x"] = 16, ["y"] = 0, ["z"] = 7, ["name"] = "default:junglewood"}, {["x"] = 16, ["y"] = 0, ["z"] = 8, ["name"] = "default:junglewood"}, {["x"] = 16, ["y"] = 0, ["param1"] = 13, ["z"] = 9, ["name"] = "default:junglewood"}, {["x"] = 16, ["y"] = 0, ["param1"] = 14, ["z"] = 10, ["name"] = "default:junglewood"}, {["x"] = 16, ["y"] = 0, ["param1"] = 15, ["z"] = 11, ["name"] = "default:junglewood"}, {["x"] = 16, ["y"] = 0, ["param1"] = 15, ["z"] = 12, ["name"] = "default:junglewood"}, {["x"] = 16, ["y"] = 0, ["z"] = 13, ["name"] = "default:junglewood"}, {["x"] = 16, ["y"] = 1, ["z"] = 1, ["name"] = "the_build_spawner:dark_grey"}, {["x"] = 16, ["meta"] = {["fields"] = {["infotext"] = "\27(T@default)Empty Bookshelf\27E", ["formspec"] = "size[8,7;]list[context;books;0,0.3;8,2;]list[current_player;main;0,2.85;8,1;]list[current_player;main;0,4.08;8,3;8]listring[context;books]listring[current_player;main]image[0,2.85;1,1;gui_hb_bg.png]image[1,2.85;1,1;gui_hb_bg.png]image[2,2.85;1,1;gui_hb_bg.png]image[3,2.85;1,1;gui_hb_bg.png]image[4,2.85;1,1;gui_hb_bg.png]image[5,2.85;1,1;gui_hb_bg.png]image[6,2.85;1,1;gui_hb_bg.png]image[7,2.85;1,1;gui_hb_bg.png]image[0,0.3;1,1;default_bookshelf_slot.png]image[1,0.3;1,1;default_bookshelf_slot.png]image[2,0.3;1,1;default_bookshelf_slot.png]image[3,0.3;1,1;default_bookshelf_slot.png]image[4,0.3;1,1;default_bookshelf_slot.png]image[5,0.3;1,1;default_bookshelf_slot.png]image[6,0.3;1,1;default_bookshelf_slot.png]image[7,0.3;1,1;default_bookshelf_slot.png]image[0,1.3;1,1;default_bookshelf_slot.png]image[1,1.3;1,1;default_bookshelf_slot.png]image[2,1.3;1,1;default_bookshelf_slot.png]image[3,1.3;1,1;default_bookshelf_slot.png]image[4,1.3;1,1;default_bookshelf_slot.png]image[5,1.3;1,1;default_bookshelf_slot.png]image[6,1.3;1,1;default_bookshelf_slot.png]image[7,1.3;1,1;default_bookshelf_slot.png]"}, ["inventory"] = {["books"] = {"", "", "", "", "", "", "", "", "", "", "", "", "", "", "", ""}}}, ["param2"] = 3, ["y"] = 1, ["z"] = 4, ["name"] = "default:bookshelf"}, {["x"] = 16, ["meta"] = {["fields"] = {["infotext"] = "\27(T@default)Empty Bookshelf\27E", ["formspec"] = "size[8,7;]list[context;books;0,0.3;8,2;]list[current_player;main;0,2.85;8,1;]list[current_player;main;0,4.08;8,3;8]listring[context;books]listring[current_player;main]image[0,2.85;1,1;gui_hb_bg.png]image[1,2.85;1,1;gui_hb_bg.png]image[2,2.85;1,1;gui_hb_bg.png]image[3,2.85;1,1;gui_hb_bg.png]image[4,2.85;1,1;gui_hb_bg.png]image[5,2.85;1,1;gui_hb_bg.png]image[6,2.85;1,1;gui_hb_bg.png]image[7,2.85;1,1;gui_hb_bg.png]image[0,0.3;1,1;default_bookshelf_slot.png]image[1,0.3;1,1;default_bookshelf_slot.png]image[2,0.3;1,1;default_bookshelf_slot.png]image[3,0.3;1,1;default_bookshelf_slot.png]image[4,0.3;1,1;default_bookshelf_slot.png]image[5,0.3;1,1;default_bookshelf_slot.png]image[6,0.3;1,1;default_bookshelf_slot.png]image[7,0.3;1,1;default_bookshelf_slot.png]image[0,1.3;1,1;default_bookshelf_slot.png]image[1,1.3;1,1;default_bookshelf_slot.png]image[2,1.3;1,1;default_bookshelf_slot.png]image[3,1.3;1,1;default_bookshelf_slot.png]image[4,1.3;1,1;default_bookshelf_slot.png]image[5,1.3;1,1;default_bookshelf_slot.png]image[6,1.3;1,1;default_bookshelf_slot.png]image[7,1.3;1,1;default_bookshelf_slot.png]"}, ["inventory"] = {["books"] = {"", "", "", "", "", "", "", "", "", "", "", "", "", "", "", ""}}}, ["param2"] = 3, ["y"] = 1, ["z"] = 5, ["name"] = "default:bookshelf"}, {["x"] = 16, ["y"] = 1, ["z"] = 6, ["name"] = "the_build_spawner:dark_grey"}, {["x"] = 16, ["param2"] = 2, ["y"] = 1, ["param1"] = 141, ["z"] = 10, ["name"] = "stairs:stair_junglewood"}, {["x"] = 16, ["y"] = 1, ["param1"] = 158, ["z"] = 11, ["name"] = "default:fence_wood"}, {["x"] = 16, ["y"] = 1, ["param1"] = 174, ["z"] = 12, ["name"] = "stairs:stair_junglewood"}, {["x"] = 16, ["y"] = 1, ["param1"] = 174, ["z"] = 13, ["name"] = "default:fence_wood"}, {["x"] = 16, ["y"] = 2, ["z"] = 1, ["name"] = "the_build_spawner:dark_grey"}, {["x"] = 16, ["meta"] = {["fields"] = {["infotext"] = "\27(T@default)Empty Bookshelf\27E", ["formspec"] = "size[8,7;]list[context;books;0,0.3;8,2;]list[current_player;main;0,2.85;8,1;]list[current_player;main;0,4.08;8,3;8]listring[context;books]listring[current_player;main]image[0,2.85;1,1;gui_hb_bg.png]image[1,2.85;1,1;gui_hb_bg.png]image[2,2.85;1,1;gui_hb_bg.png]image[3,2.85;1,1;gui_hb_bg.png]image[4,2.85;1,1;gui_hb_bg.png]image[5,2.85;1,1;gui_hb_bg.png]image[6,2.85;1,1;gui_hb_bg.png]image[7,2.85;1,1;gui_hb_bg.png]image[0,0.3;1,1;default_bookshelf_slot.png]image[1,0.3;1,1;default_bookshelf_slot.png]image[2,0.3;1,1;default_bookshelf_slot.png]image[3,0.3;1,1;default_bookshelf_slot.png]image[4,0.3;1,1;default_bookshelf_slot.png]image[5,0.3;1,1;default_bookshelf_slot.png]image[6,0.3;1,1;default_bookshelf_slot.png]image[7,0.3;1,1;default_bookshelf_slot.png]image[0,1.3;1,1;default_bookshelf_slot.png]image[1,1.3;1,1;default_bookshelf_slot.png]image[2,1.3;1,1;default_bookshelf_slot.png]image[3,1.3;1,1;default_bookshelf_slot.png]image[4,1.3;1,1;default_bookshelf_slot.png]image[5,1.3;1,1;default_bookshelf_slot.png]image[6,1.3;1,1;default_bookshelf_slot.png]image[7,1.3;1,1;default_bookshelf_slot.png]"}, ["inventory"] = {["books"] = {"", "", "", "", "", "", "", "", "", "", "", "", "", "", "", ""}}}, ["param2"] = 1, ["y"] = 2, ["z"] = 2, ["name"] = "default:bookshelf"}, {["x"] = 16, ["meta"] = {["fields"] = {["infotext"] = "\27(T@default)Empty Bookshelf\27E", ["formspec"] = "size[8,7;]list[context;books;0,0.3;8,2;]list[current_player;main;0,2.85;8,1;]list[current_player;main;0,4.08;8,3;8]listring[context;books]listring[current_player;main]image[0,2.85;1,1;gui_hb_bg.png]image[1,2.85;1,1;gui_hb_bg.png]image[2,2.85;1,1;gui_hb_bg.png]image[3,2.85;1,1;gui_hb_bg.png]image[4,2.85;1,1;gui_hb_bg.png]image[5,2.85;1,1;gui_hb_bg.png]image[6,2.85;1,1;gui_hb_bg.png]image[7,2.85;1,1;gui_hb_bg.png]image[0,0.3;1,1;default_bookshelf_slot.png]image[1,0.3;1,1;default_bookshelf_slot.png]image[2,0.3;1,1;default_bookshelf_slot.png]image[3,0.3;1,1;default_bookshelf_slot.png]image[4,0.3;1,1;default_bookshelf_slot.png]image[5,0.3;1,1;default_bookshelf_slot.png]image[6,0.3;1,1;default_bookshelf_slot.png]image[7,0.3;1,1;default_bookshelf_slot.png]image[0,1.3;1,1;default_bookshelf_slot.png]image[1,1.3;1,1;default_bookshelf_slot.png]image[2,1.3;1,1;default_bookshelf_slot.png]image[3,1.3;1,1;default_bookshelf_slot.png]image[4,1.3;1,1;default_bookshelf_slot.png]image[5,1.3;1,1;default_bookshelf_slot.png]image[6,1.3;1,1;default_bookshelf_slot.png]image[7,1.3;1,1;default_bookshelf_slot.png]"}, ["inventory"] = {["books"] = {"", "", "", "", "", "", "", "", "", "", "", "", "", "", "", ""}}}, ["param2"] = 1, ["y"] = 2, ["z"] = 3, ["name"] = "default:bookshelf"}, {["x"] = 16, ["meta"] = {["fields"] = {["infotext"] = "\27(T@default)Empty Bookshelf\27E", ["formspec"] = "size[8,7;]list[context;books;0,0.3;8,2;]list[current_player;main;0,2.85;8,1;]list[current_player;main;0,4.08;8,3;8]listring[context;books]listring[current_player;main]image[0,2.85;1,1;gui_hb_bg.png]image[1,2.85;1,1;gui_hb_bg.png]image[2,2.85;1,1;gui_hb_bg.png]image[3,2.85;1,1;gui_hb_bg.png]image[4,2.85;1,1;gui_hb_bg.png]image[5,2.85;1,1;gui_hb_bg.png]image[6,2.85;1,1;gui_hb_bg.png]image[7,2.85;1,1;gui_hb_bg.png]image[0,0.3;1,1;default_bookshelf_slot.png]image[1,0.3;1,1;default_bookshelf_slot.png]image[2,0.3;1,1;default_bookshelf_slot.png]image[3,0.3;1,1;default_bookshelf_slot.png]image[4,0.3;1,1;default_bookshelf_slot.png]image[5,0.3;1,1;default_bookshelf_slot.png]image[6,0.3;1,1;default_bookshelf_slot.png]image[7,0.3;1,1;default_bookshelf_slot.png]image[0,1.3;1,1;default_bookshelf_slot.png]image[1,1.3;1,1;default_bookshelf_slot.png]image[2,1.3;1,1;default_bookshelf_slot.png]image[3,1.3;1,1;default_bookshelf_slot.png]image[4,1.3;1,1;default_bookshelf_slot.png]image[5,1.3;1,1;default_bookshelf_slot.png]image[6,1.3;1,1;default_bookshelf_slot.png]image[7,1.3;1,1;default_bookshelf_slot.png]"}, ["inventory"] = {["books"] = {"", "", "", "", "", "", "", "", "", "", "", "", "", "", "", ""}}}, ["param2"] = 3, ["y"] = 2, ["z"] = 4, ["name"] = "default:bookshelf"}, {["x"] = 16, ["meta"] = {["fields"] = {["infotext"] = "\27(T@default)Empty Bookshelf\27E", ["formspec"] = "size[8,7;]list[context;books;0,0.3;8,2;]list[current_player;main;0,2.85;8,1;]list[current_player;main;0,4.08;8,3;8]listring[context;books]listring[current_player;main]image[0,2.85;1,1;gui_hb_bg.png]image[1,2.85;1,1;gui_hb_bg.png]image[2,2.85;1,1;gui_hb_bg.png]image[3,2.85;1,1;gui_hb_bg.png]image[4,2.85;1,1;gui_hb_bg.png]image[5,2.85;1,1;gui_hb_bg.png]image[6,2.85;1,1;gui_hb_bg.png]image[7,2.85;1,1;gui_hb_bg.png]image[0,0.3;1,1;default_bookshelf_slot.png]image[1,0.3;1,1;default_bookshelf_slot.png]image[2,0.3;1,1;default_bookshelf_slot.png]image[3,0.3;1,1;default_bookshelf_slot.png]image[4,0.3;1,1;default_bookshelf_slot.png]image[5,0.3;1,1;default_bookshelf_slot.png]image[6,0.3;1,1;default_bookshelf_slot.png]image[7,0.3;1,1;default_bookshelf_slot.png]image[0,1.3;1,1;default_bookshelf_slot.png]image[1,1.3;1,1;default_bookshelf_slot.png]image[2,1.3;1,1;default_bookshelf_slot.png]image[3,1.3;1,1;default_bookshelf_slot.png]image[4,1.3;1,1;default_bookshelf_slot.png]image[5,1.3;1,1;default_bookshelf_slot.png]image[6,1.3;1,1;default_bookshelf_slot.png]image[7,1.3;1,1;default_bookshelf_slot.png]"}, ["inventory"] = {["books"] = {"", "", "", "", "", "", "", "", "", "", "", "", "", "", "", ""}}}, ["param2"] = 3, ["y"] = 2, ["z"] = 5, ["name"] = "default:bookshelf"}, {["x"] = 16, ["y"] = 2, ["z"] = 6, ["name"] = "the_build_spawner:dark_grey"}, {["x"] = 16, ["param2"] = 1, ["y"] = 2, ["param1"] = 174, ["z"] = 11, ["name"] = "doors:trapdoor"}, {["x"] = 16, ["y"] = 3, ["z"] = 1, ["name"] = "the_build_spawner:dark_grey"}, {["x"] = 16, ["y"] = 3, ["z"] = 6, ["name"] = "the_build_spawner:dark_grey"}, {["x"] = 16, ["y"] = 4, ["z"] = 1, ["name"] = "the_build_spawner:dark_grey"}, {["x"] = 16, ["y"] = 4, ["z"] = 6, ["name"] = "the_build_spawner:dark_grey"}, {["x"] = 16, ["y"] = 5, ["z"] = 1, ["name"] = "the_build_spawner:dark_grey"}, {["x"] = 16, ["y"] = 5, ["z"] = 6, ["name"] = "the_build_spawner:dark_grey"}, {["x"] = 16, ["y"] = 5, ["param1"] = 158, ["z"] = 7, ["name"] = "stairs:slab_wood"}, {["x"] = 16, ["y"] = 5, ["param1"] = 142, ["z"] = 8, ["name"] = "stairs:slab_wood"}, {["x"] = 16, ["y"] = 5, ["param1"] = 157, ["z"] = 9, ["name"] = "stairs:slab_wood"},