5:return {{["x"] = 0, ["meta"] = {["fields"] = {}, ["inventory"] = {}}, ["y"] = 0, ["param1"] = 8, ["z"] = 0, ["name"] = "default:stonebrick"}, {["x"] = 0, ["meta"] = {["fields"] = {}, ["inventory"] = {}}, ["y"] = 0, ["param1"] = 8, ["z"] = 1, ["name"] = "default:stonebrick"}, {["x"] = 0, ["meta"] = {["fields"] = {}, ["inventory"] = {}}, ["y"] = 0, ["param1"] = 8, ["z"] = 2, ["name"] = "default:stonebrick"}, {["x"] = 0, ["meta"] = {["fields"] = {}, ["inventory"] = {}}, ["y"] = 0, ["param1"] = 8, ["z"] = 3, ["name"] = "default:stonebrick"}, {["x"] = 0, ["meta"] = {["fields"] = {}, ["inventory"] = {}}, ["y"] = 0, ["param1"] = 8, ["z"] = 4, ["name"] = "default:stonebrick"}, {["x"] = 0, ["meta"] = {["fields"] = {}, ["inventory"] = {}}, ["y"] = 0, ["param1"] = 8, ["z"] = 5, ["name"] = "default:stonebrick"}, {["x"] = 0, ["meta"] = {["fields"] = {}, ["inventory"] = {}}, ["y"] = 0, ["param1"] = 8, ["z"] = 6, ["name"] = "default:stonebrick"}, {["x"] = 0, ["meta"] = {["fields"] = {}, ["inventory"] = {}}, ["y"] = 0, ["param1"] = 6, ["z"] = 7, ["name"] = "default:stone"}, {["x"] = 0, ["meta"] = {["fields"] = {}, ["inventory"] = {}}, ["y"] = 0, ["param1"] = 6, ["z"] = 8, ["name"] = "default:stone"}, {["x"] = 0, ["meta"] = {["fields"] = {}, ["inventory"] = {}}, ["y"] = 0, ["param1"] = 6, ["z"] = 9, ["name"] = "default:stone"}, {["x"] = 0, ["meta"] = {["fields"] = {}, ["inventory"] = {}}, ["y"] = 0, ["param1"] = 6, ["z"] = 10, ["name"] = "default:stone"}, {["x"] = 0, ["meta"] = {["fields"] = {}, ["inventory"] = {}}, ["y"] = 0, ["param1"] = 6, ["z"] = 11, ["name"] = "default:stone_block"}, {["x"] = 0, ["meta"] = {["fields"] = {}, ["inventory"] = {}}, ["y"] = 0, ["param1"] = 6, ["z"] = 12, ["name"] = "default:stone_block"}, {["x"] = 0, ["meta"] = {["fields"] = {}, ["inventory"] = {}}, ["y"] = 0, ["param1"] = 6, ["z"] = 13, ["name"] = "default:stone_block"}, {["x"] = 0, ["meta"] = {["fields"] = {}, ["inventory"] = {}}, ["y"] = 0, ["param1"] = 6, ["z"] = 14, ["name"] = "default:stone_block"}, {["x"] = 0, ["meta"] = {["fields"] = {}, ["inventory"] = {}}, ["y"] = 0, ["param1"] = 6, ["z"] = 15, ["name"] = "default:stone_block"}, {["x"] = 0, ["meta"] = {["fields"] = {}, ["inventory"] = {}}, ["y"] = 0, ["param1"] = 6, ["z"] = 16, ["name"] = "default:stone_block"}, {["x"] = 0, ["meta"] = {["fields"] = {}, ["inventory"] = {}}, ["y"] = 0, ["param1"] = 6, ["z"] = 17, ["name"] = "default:stone_block"}, {["x"] = 0, ["meta"] = {["fields"] = {}, ["inventory"] = {}}, ["y"] = 0, ["param1"] = 6, ["z"] = 18, ["name"] = "default:stone_block"}, {["x"] = 0, ["meta"] = {["fields"] = {}, ["inventory"] = {}}, ["y"] = 0, ["param1"] = 6, ["z"] = 19, ["name"] = "default:stone_block"}, {["x"] = 0, ["meta"] = {["fields"] = {}, ["inventory"] = {}}, ["y"] = 0, ["param1"] = 6, ["z"] = 20, ["name"] = "default:stone"}, {["x"] = 0, ["meta"] = {["fields"] = {}, ["inventory"] = {}}, ["y"] = 0, ["param1"] = 6, ["z"] = 21, ["name"] = "default:stone"}, {["x"] = 0, ["meta"] = {["fields"] = {}, ["inventory"] = {}}, ["y"] = 0, ["param1"] = 6, ["z"] = 22, ["name"] = "default:stone"}, {["x"] = 0, ["meta"] = {["fields"] = {}, ["inventory"] = {}}, ["y"] = 0, ["param1"] = 6, ["z"] = 23, ["name"] = "default:stone"}, {["x"] = 0, ["meta"] = {["fields"] = {}, ["inventory"] = {}}, ["y"] = 0, ["param1"] = 8, ["z"] = 24, ["name"] = "default:stonebrick"}, {["x"] = 0, ["meta"] = {["fields"] = {}, ["inventory"] = {}}, ["y"] = 0, ["param1"] = 8, ["z"] = 25, ["name"] = "default:stonebrick"}, {["x"] = 0, ["meta"] = {["fields"] = {}, ["inventory"] = {}}, ["y"] = 0, ["param1"] = 8, ["z"] = 26, ["name"] = "default:stonebrick"}, {["x"] = 0, ["meta"] = {["fields"] = {}, ["inventory"] = {}}, ["y"] = 0, ["param1"] = 8, ["z"] = 27, ["name"] = "default:stonebrick"}, {["x"] = 0, ["meta"] = {["fields"] = {}, ["inventory"] = {}}, ["y"] = 0, ["param1"] = 8, ["z"] = 28, ["name"] = "default:stonebrick"}, {["x"] = 0, ["meta"] = {["fields"] = {}, ["inventory"] = {}}, ["y"] = 0, ["param1"] = 8, ["z"] = 29, ["name"] = "default:stonebrick"}, {["x"] = 0, ["meta"] = {["fields"] = {}, ["inventory"] = {}}, ["y"] = 0, ["param1"] = 8, ["z"] = 30, ["name"] = "default:stonebrick"}, {["x"] = 0, ["meta"] = {["fields"] = {}, ["inventory"] = {}}, ["y"] = 1, ["param1"] = 8, ["z"] = 0, ["name"] = "default:stonebrick"}, {["x"] = 0, ["meta"] = {["fields"] = {}, ["inventory"] = {}}, ["y"] = 1, ["param1"] = 8, ["z"] = 1, ["name"] = "default:stonebrick"}, {["x"] = 0, ["meta"] = {["fields"] = {}, ["inventory"] = {}}, ["y"] = 1, ["param1"] = 8, ["z"] = 2, ["name"] = "default:stonebrick"}, {["x"] = 0, ["meta"] = {["fields"] = {}, ["inventory"] = {}}, ["y"] = 1, ["param1"] = 8, ["z"] = 3, ["name"] = "default:stonebrick"}, {["x"] = 0, ["meta"] = {["fields"] = {}, ["inventory"] = {}}, ["y"] = 1, ["param1"] = 8, ["z"] = 4, ["name"] = "default:stonebrick"}, {["x"] = 0, ["meta"] = {["fields"] = {}, ["inventory"] = {}}, ["y"] = 1, ["param1"] = 8, ["z"] = 5, ["name"] = "default:stonebrick"}, {["x"] = 0, ["meta"] = {["fields"] = {}, ["inventory"] = {}}, ["y"] = 1, ["param1"] = 8, ["z"] = 6, ["name"] = "default:stonebrick"}, {["x"] = 0, ["meta"] = {["fields"] = {}, ["inventory"] = {}}, ["y"] = 1, ["param1"] = 8, ["z"] = 24, ["name"] = "default:stonebrick"}, {["x"] = 0, ["meta"] = {["fields"] = {}, ["inventory"] = {}}, ["y"] = 1, ["param1"] = 8, ["z"] = 25, ["name"] = "default:stonebrick"}, {["x"] = 0, ["meta"] = {["fields"] = {}, ["inventory"] = {}}, ["y"] = 1, ["param1"] = 8, ["z"] = 26, ["name"] = "default:stonebrick"}, {["x"] = 0, ["meta"] = {["fields"] = {}, ["inventory"] = {}}, ["y"] = 1, ["param1"] = 8, ["z"] = 27, ["name"] = "default:stonebrick"}, {["x"] = 0, ["meta"] = {["fields"] = {}, ["inventory"] = {}}, ["y"] = 1, ["param1"] = 8, ["z"] = 28, ["name"] = "default:stonebrick"}, {["x"] = 0, ["meta"] = {["fields"] = {}, ["inventory"] = {}}, ["y"] = 1, ["param1"] = 8, ["z"] = 29, ["name"] = "default:stonebrick"}, {["x"] = 0, ["meta"] = {["fields"] = {}, ["inventory"] = {}}, ["y"] = 1, ["param1"] = 8, ["z"] = 30, ["name"] = "default:stonebrick"}, {["x"] = 0, ["meta"] = {["fields"] = {}, ["inventory"] = {}}, ["y"] = 2, ["param1"] = 152, ["z"] = 0, ["name"] = "default:brick"}, {["x"] = 0, ["meta"] = {["fields"] = {}, ["inventory"] = {}}, ["y"] = 2, ["param1"] = 152, ["z"] = 1, ["name"] = "default:brick"}, {["x"] = 0, ["meta"] = {["fields"] = {}, ["inventory"] = {}}, ["y"] = 2, ["param1"] = 152, ["z"] = 2, ["name"] = "default:brick"}, {["x"] = 0, ["meta"] = {["fields"] = {}, ["inventory"] = {}}, ["y"] = 2, ["param1"] = 152, ["z"] = 3, ["name"] = "default:brick"}, {["x"] = 0, ["meta"] = {["fields"] = {}, ["inventory"] = {}}, ["y"] = 2, ["param1"] = 152, ["z"] = 4, ["name"] = "default:brick"}, {["x"] = 0, ["y"] = 2, ["z"] = 5, ["name"] = "default:brick"}, {["x"] = 0, ["meta"] = {["fields"] = {}, ["inventory"] = {}}, ["y"] = 2, ["param1"] = 152, ["z"] = 6, ["name"] = "default:brick"}, {["x"] = 0, ["meta"] = {["fields"] = {}, ["inventory"] = {}}, ["y"] = 2, ["param1"] = 152, ["z"] = 24, ["name"] = "default:brick"}, {["x"] = 0, ["meta"] = {["fields"] = {}, ["inventory"] = {}}, ["y"] = 2, ["param1"] = 152, ["z"] = 25, ["name"] = "default:brick"}, {["x"] = 0, ["meta"] = {["fields"] = {}, ["inventory"] = {}}, ["y"] = 2, ["param1"] = 152, ["z"] = 26, ["name"] = "default:brick"}, {["x"] = 0, ["meta"] = {["fields"] = {}, ["inventory"] = {}}, ["y"] = 2, ["param1"] = 152, ["z"] = 27, ["name"] = "default:brick"}, {["x"] = 0, ["meta"] = {["fields"] = {}, ["inventory"] = {}}, ["y"] = 2, ["param1"] = 152, ["z"] = 28, ["name"] = "default:brick"}, {["x"] = 0, ["meta"] = {["fields"] = {}, ["inventory"] = {}}, ["y"] = 2, ["param1"] = 152, ["z"] = 29, ["name"] = "default:brick"}, {["x"] = 0, ["meta"] = {["fields"] = {}, ["inventory"] = {}}, ["y"] = 2, ["param1"] = 152, ["z"] = 30, ["name"] = "default:brick"}, {["x"] = 0, ["meta"] = {["fields"] = {}, ["inventory"] = {}}, ["y"] = 3, ["param1"] = 152, ["z"] = 0, ["name"] = "default:brick"}, {["x"] = 0, ["y"] = 3, ["param1"] = 142, ["z"] = 1, ["name"] = "default:glass"}, {["x"] = 0, ["y"] = 3, ["param1"] = 126, ["z"] = 2, ["name"] = "default:glass"}, {["x"] = 0, ["meta"] = {["fields"] = {}, ["inventory"] = {}}, ["y"] = 3, ["param1"] = 152, ["z"] = 3, ["name"] = "default:brick"}, {["x"] = 0, ["y"] = 3, ["param1"] = 126, ["z"] = 4, ["name"] = "default:glass"}, {["x"] = 0, ["y"] = 3, ["param1"] = 141, ["z"] = 5, ["name"] = "default:glass"}, {["x"] = 0, ["meta"] = {["fields"] = {}, ["inventory"] = {}}, ["y"] = 3, ["param1"] = 152, ["z"] = 6, ["name"] = "default:brick"}, {["x"] = 0, ["meta"] = {["fields"] = {}, ["inventory"] = {}}, ["y"] = 3, ["param1"] = 152, ["z"] = 24, ["name"] = "default:brick"}, {["x"] = 0, ["y"] = 3, ["param1"] = 174, ["z"] = 25, ["name"] = "default:glass"}, {["x"] = 0, ["y"] = 3, ["param1"] = 158, ["z"] = 26, ["name"] = "default:glass"}, {["x"] = 0, ["meta"] = {["fields"] = {}, ["inventory"] = {}}, ["y"] = 3, ["param1"] = 152, ["z"] = 27, ["name"] = "default:brick"}, {["x"] = 0, ["y"] = 3, ["param1"] = 158, ["z"] = 28, ["name"] = "default:glass"}, {["x"] = 0, ["y"] = 3, ["param1"] = 174, ["z"] = 29, ["name"] = "default:glass"}, {["x"] = 0, ["meta"] = {["fields"] = {}, ["inventory"] = {}}, ["y"] = 3, ["param1"] = 152, ["z"] = 30, ["name"] = "default:brick"}, {["x"] = 0, ["meta"] = {["fields"] = {}, ["inventory"] = {}}, ["y"] = 4, ["param1"] = 152, ["z"] = 0, ["name"] = "default:brick"}, {["x"] = 0, ["y"] = 4, ["param1"] = 158, ["z"] = 1, ["name"] = "default:glass"}, {["x"] = 0, ["y"] = 4, ["param1"] = 142, ["z"] = 2, ["name"] = "default:glass"}, {["x"] = 0, ["meta"] = {["fields"] = {}, ["inventory"] = {}}, ["y"] = 4, ["param1"] = 152, ["z"] = 3, ["name"] = "default:brick"}, {["x"] = 0, ["y"] = 4, ["param1"] = 142, ["z"] = 4, ["name"] = "default:glass"}, {["x"] = 0, ["y"] = 4, ["param1"] = 157, ["z"] = 5, ["name"] = "default:glass"}, {["x"] = 0, ["meta"] = {["fields"] = {}, ["inventory"] = {}}, ["y"] = 4, ["param1"] = 152, ["z"] = 6, ["name"] = "default:brick"}, {["x"] = 0, ["meta"] = {["fields"] = {}, ["inventory"] = {}}, ["y"] = 4, ["param1"] = 152, ["z"] = 24, ["name"] = "default:brick"}, {["x"] = 0, ["y"] = 4, ["param1"] = 190, ["z"] = 25, ["name"] = "default:glass"}, {["x"] = 0, ["y"] = 4, ["param1"] = 174, ["z"] = 26, ["name"] = "default:glass"}, {["x"] = 0, ["meta"] = {["fields"] = {}, ["inventory"] = {}}, ["y"] = 4, ["param1"] = 152, ["z"] = 27, ["name"] = "default:brick"}, {["x"] = 0, ["y"] = 4, ["param1"] = 174, ["z"] = 28, ["name"] = "default:glass"}, {["x"] = 0, ["y"] = 4, ["param1"] = 190, ["z"] = 29, ["name"] = "default:glass"}, {["x"] = 0, ["meta"] = {["fields"] = {}, ["inventory"] = {}}, ["y"] = 4, ["param1"] = 152, ["z"] = 30, ["name"] = "default:brick"}, {["x"] = 0, ["meta"] = {["fields"] = {}, ["inventory"] = {}}, ["y"] = 5, ["param1"] = 152, ["z"] = 0, ["name"] = "default:brick"}, {["x"] = 0, ["y"] = 5, ["param1"] = 174, ["z"] = 1, ["name"] = "default:glass"}, {["x"] = 0, ["y"] = 5, ["param1"] = 158, ["z"] = 2, ["name"] = "default:glass"}, {["x"] = 0, ["meta"] = {["fields"] = {}, ["inventory"] = {}}, ["y"] = 5, ["param1"] = 152, ["z"] = 3, ["name"] = "default:brick"}, {["x"] = 0, ["y"] = 5, ["param1"] = 158, ["z"] = 4, ["name"] = "default:glass"}, {["x"] = 0, ["y"] = 5, ["param1"] = 173, ["z"] = 5, ["name"] = "default:glass"}, {["x"] = 0, ["meta"] = {["fields"] = {}, ["inventory"] = {}}, ["y"] = 5, ["param1"] = 152, ["z"] = 6, ["name"] = "default:brick"}, {["x"] = 0, ["meta"] = {["fields"] = {}, ["inventory"] = {}}, ["y"] = 5, ["param1"] = 152, ["z"] = 24, ["name"] = "default:brick"}, {["x"] = 0, ["y"] = 5, ["param1"] = 206, ["z"] = 25, ["name"] = "default:glass"}, {["x"] = 0, ["y"] = 5, ["param1"] = 190, ["z"] = 26, ["name"] = "default:glass"}, {["x"] = 0, ["meta"] = {["fields"] = {}, ["inventory"] = {}}, ["y"] = 5, ["param1"] = 152, ["z"] = 27, ["name"] = "default:brick"}, {["x"] = 0, ["y"] = 5, ["param1"] = 190, ["z"] = 28, ["name"] = "default:glass"}, {["x"] = 0, ["y"] = 5, ["param1"] = 206, ["z"] = 29, ["name"] = "default:glass"}, {["x"] = 0, ["meta"] = {["fields"] = {}, ["inventory"] = {}}, ["y"] = 5, ["param1"] = 152, ["z"] = 30, ["name"] = "default:brick"}, {["x"] = 0, ["meta"] = {["fields"] = {}, ["inventory"] = {}}, ["y"] = 6, ["param1"] = 152, ["z"] = 0, ["name"] = "default:brick"}, {["x"] = 0, ["meta"] = {["fields"] = {}, ["inventory"] = {}}, ["y"] = 6, ["param1"] = 152, ["z"] = 1, ["name"] = "default:brick"}, {["x"] = 0, ["meta"] = {["fields"] = {}, ["inventory"] = {}}, ["y"] = 6, ["param1"] = 152, ["z"] = 2, ["name"] = "default:brick"}, {["x"] = 0, ["meta"] = {["fields"] = {}, ["inventory"] = {}}, ["y"] = 6, ["param1"] = 152, ["z"] = 3, ["name"] = "default:brick"}, {["x"] = 0, ["meta"] = {["fields"] = {}, ["inventory"] = {}}, ["y"] = 6, ["param1"] = 152, ["z"] = 4, ["name"] = "default:brick"}, {["x"] = 0, ["meta"] = {["fields"] = {}, ["inventory"] = {}}, ["y"] = 6, ["param1"] = 152, ["z"] = 5, ["name"] = "default:brick"}, {["x"] = 0, ["meta"] = {["fields"] = {}, ["inventory"] = {}}, ["y"] = 6, ["param1"] = 152, ["z"] = 6, ["name"] = "default:brick"}, {["x"] = 0, ["meta"] = {["fields"] = {}, ["inventory"] = {}}, ["y"] = 6, ["param1"] = 152, ["z"] = 24, ["name"] = "default:brick"}, {["x"] = 0, ["meta"] = {["fields"] = {}, ["inventory"] = {}}, ["y"] = 6, ["param1"] = 152, ["z"] = 25, ["name"] = "default:brick"}, {["x"] = 0, ["meta"] = {["fields"] = {}, ["inventory"] = {}}, ["y"] = 6, ["param1"] = 152, ["z"] = 26, ["name"] = "default:brick"}, {["x"] = 0, ["meta"] = {["fields"] = {}, ["inventory"] = {}}, ["y"] = 6, ["param1"] = 152, ["z"] = 27, ["name"] = "default:brick"}, {["x"] = 0, ["meta"] = {["fields"] = {}, ["inventory"] = {}}, ["y"] = 6, ["param1"] = 152, ["z"] = 28, ["name"] = "default:brick"}, {["x"] = 0, ["meta"] = {["fields"] = {}, ["inventory"] = {}}, ["y"] = 6, ["param1"] = 152, ["z"] = 29, ["name"] = "default:brick"}, {["x"] = 0, ["meta"] = {["fields"] = {}, ["inventory"] = {}}, ["y"] = 6, ["param1"] = 152, ["z"] = 30, ["name"] = "default:brick"}, {["x"] = 0, ["y"] = 7, ["z"] = 0, ["name"] = "default:stonebrick"}, {["x"] = 0, ["y"] = 7, ["z"] = 1, ["name"] = "default:stonebrick"}, {["x"] = 0, ["y"] = 7, ["z"] = 2, ["name"] = "default:stonebrick"}, {["x"] = 0, ["y"] = 7, ["z"] = 3, ["name"] = "default:stonebrick"}, {["x"] = 0, ["y"] = 7, ["z"] = 4, ["name"] = "default:stonebrick"}, {["x"] = 0, ["y"] = 7, ["z"] = 5, ["name"] = "default:stonebrick"}, {["x"] = 0, ["y"] = 7, ["z"] = 6, ["name"] = "default:stonebrick"}, {["x"] = 0, ["y"] = 7, ["z"] = 24, ["name"] = "default:stonebrick"}, {["x"] = 0, ["y"] = 7, ["z"] = 25, ["name"] = "default:stonebrick"}, {["x"] = 0, ["y"] = 7, ["z"] = 26, ["name"] = "default:stonebrick"}, {["x"] = 0, ["y"] = 7, ["z"] = 27, ["name"] = "default:stonebrick"}, {["x"] = 0, ["y"] = 7, ["z"] = 28, ["name"] = "default:stonebrick"}, {["x"] = 0, ["y"] = 7, ["z"] = 29, ["name"] = "default:stonebrick"}, {["x"] = 0, ["y"] = 7, ["z"] = 30, ["name"] = "default:stonebrick"}, {["x"] = 0, ["meta"] = {["fields"] = {}, ["inventory"] = {}}, ["y"] = 8, ["param1"] = 152, ["z"] = 0, ["name"] = "default:brick"}, {["x"] = 0, ["meta"] = {["fields"] = {}, ["inventory"] = {}}, ["y"] = 8, ["param1"] = 152, ["z"] = 1, ["name"] = "default:brick"}, {["x"] = 0, ["meta"] = {["fields"] = {}, ["inventory"] = {}}, ["y"] = 8, ["param1"] = 152, ["z"] = 2, ["name"] = "default:brick"}, {["x"] = 0, ["meta"] = {["fields"] = {}, ["inventory"] = {}}, ["y"] = 8, ["param1"] = 152, ["z"] = 3, ["name"] = "default:brick"}, {["x"] = 0, ["meta"] = {["fields"] = {}, ["inventory"] = {}}, ["y"] = 8, ["param1"] = 152, ["z"] = 4, ["name"] = "default:brick"}, {["x"] = 0, ["meta"] = {["fields"] = {}, ["inventory"] = {}}, ["y"] = 8, ["param1"] = 152, ["z"] = 5, ["name"] = "default:brick"}, {["x"] = 0, ["meta"] = {["fields"] = {}, ["inventory"] = {}}, ["y"] = 8, ["param1"] = 152, ["z"] = 6, ["name"] = "default:brick"}, {["x"] = 0, ["meta"] = {["fields"] = {}, ["inventory"] = {}}, ["y"] = 8, ["param1"] = 152, ["z"] = 24, ["name"] = "default:brick"}, {["x"] = 0, ["meta"] = {["fields"] = {}, ["inventory"] = {}}, ["y"] = 8, ["param1"] = 152, ["z"] = 25, ["name"] = "default:brick"}, {["x"] = 0, ["meta"] = {["fields"] = {}, ["inventory"] = {}}, ["y"] = 8, ["param1"] = 152, ["z"] = 26, ["name"] = "default:brick"}, {["x"] = 0, ["meta"] = {["fields"] = {}, ["inventory"] = {}}, ["y"] = 8, ["param1"] = 152, ["z"] = 27, ["name"] = "default:brick"}, {["x"] = 0, ["meta"] = {["fields"] = {}, ["inventory"] = {}}, ["y"] = 8, ["param1"] = 152, ["z"] = 28, ["name"] = "default:brick"}, {["x"] = 0, ["meta"] = {["fields"] = {}, ["inventory"] = {}}, ["y"] = 8, ["param1"] = 152, ["z"] = 29, ["name"] = "default:brick"}, {["x"] = 0, ["meta"] = {["fields"] = {}, ["inventory"] = {}}, ["y"] = 8, ["param1"] = 152, ["z"] = 30, ["name"] = "default:brick"}, {["x"] = 0, ["meta"] = {["fields"] = {}, ["inventory"] = {}}, ["y"] = 9, ["param1"] = 152, ["z"] = 0, ["name"] = "default:brick"}, {["x"] = 0, ["y"] = 9, ["param1"] = 174, ["z"] = 1, ["name"] = "default:glass"}, {["x"] = 0, ["y"] = 9, ["param1"] = 158, ["z"] = 2, ["name"] = "default:glass"}, {["x"] = 0, ["meta"] = {["fields"] = {}, ["inventory"] = {}}, ["y"] = 9, ["param1"] = 152, ["z"] = 3, ["name"] = "default:brick"}, {["x"] = 0, ["y"] = 9, ["param1"] = 158, ["z"] = 4, ["name"] = "default:glass"}, {["x"] = 0, ["y"] = 9, ["param1"] = 174, ["z"] = 5, ["name"] = "default:glass"}, {["x"] = 0, ["meta"] = {["fields"] = {}, ["inventory"] = {}}, ["y"] = 9, ["param1"] = 152, ["z"] = 6, ["name"] = "default:brick"}, {["x"] = 0, ["meta"] = {["fields"] = {}, ["inventory"] = {}}, ["y"] = 9, ["param1"] = 152, ["z"] = 24, ["name"] = "default:brick"}, {["x"] = 0, ["y"] = 9, ["param1"] = 174, ["z"] = 25, ["name"] = "default:glass"}, {["x"] = 0, ["y"] = 9, ["param1"] = 158, ["z"] = 26, ["name"] = "default:glass"}, {["x"] = 0, ["meta"] = {["fields"] = {}, ["inventory"] = {}}, ["y"] = 9, ["param1"] = 152, ["z"] = 27, ["name"] = "default:brick"}, {["x"] = 0, ["y"] = 9, ["param1"] = 158, ["z"] = 28, ["name"] = "default:glass"}, {["x"] = 0, ["y"] = 9, ["param1"] = 174, ["z"] = 29, ["name"] = "default:glass"}, {["x"] = 0, ["y"] = 9, ["z"] = 30, ["name"] = "default:brick"}, {["x"] = 0, ["meta"] = {["fields"] = {}, ["inventory"] = {}}, ["y"] = 10, ["param1"] = 152, ["z"] = 0, ["name"] = "default:brick"}, {["x"] = 0, ["y"] = 10, ["param1"] = 190, ["z"] = 1, ["name"] = "default:glass"}, {["x"] = 0, ["y"] = 10, ["param1"] = 174, ["z"] = 2, ["name"] = "default:glass"}, {["x"] = 0, ["meta"] = {["fields"] = {}, ["inventory"] = {}}, ["y"] = 10, ["param1"] = 152, ["z"] = 3, ["name"] = "default:brick"}, {["x"] = 0, ["y"] = 10, ["param1"] = 174, ["z"] = 4, ["name"] = "default:glass"}, {["x"] = 0, ["y"] = 10, ["param1"] = 190, ["z"] = 5, ["name"] = "default:glass"}, {["x"] = 0, ["meta"] = {["fields"] = {}, ["inventory"] = {}}, ["y"] = 10, ["param1"] = 152, ["z"] = 6, ["name"] = "default:brick"}, {["x"] = 0, ["meta"] = {["fields"] = {}, ["inventory"] = {}}, ["y"] = 10, ["param1"] = 152, ["z"] = 24, ["name"] = "default:brick"}, {["x"] = 0, ["y"] = 10, ["param1"] = 190, ["z"] = 25, ["name"] = "default:glass"}, {["x"] = 0, ["y"] = 10, ["param1"] = 174, ["z"] = 26, ["name"] = "default:glass"}, {["x"] = 0, ["meta"] = {["fields"] = {}, ["inventory"] = {}}, ["y"] = 10, ["param1"] = 152, ["z"] = 27, ["name"] = "default:brick"}, {["x"] = 0, ["y"] = 10, ["param1"] = 174, ["z"] = 28, ["name"] = "default:glass"}, {["x"] = 0, ["y"] = 10, ["param1"] = 190, ["z"] = 29, ["name"] = "default:glass"}, {["x"] = 0, ["meta"] = {["fields"] = {}, ["inventory"] = {}}, ["y"] = 10, ["param1"] = 152, ["z"] = 30, ["name"] = "default:brick"}, {["x"] = 0, ["meta"] = {["fields"] = {}, ["inventory"] = {}}, ["y"] = 11, ["param1"] = 152, ["z"] = 0, ["name"] = "default:brick"}, {["x"] = 0, ["y"] = 11, ["param1"] = 206, ["z"] = 1, ["name"] = "default:glass"}, {["x"] = 0, ["y"] = 11, ["param1"] = 190, ["z"] = 2, ["name"] = "default:glass"}, {["x"] = 0, ["meta"] = {["fields"] = {}, ["inventory"] = {}}, ["y"] = 11, ["param1"] = 152, ["z"] = 3, ["name"] = "default:brick"}, {["x"] = 0, ["y"] = 11, ["param1"] = 190, ["z"] = 4, ["name"] = "default:glass"}, {["x"] = 0, ["y"] = 11, ["param1"] = 206, ["z"] = 5, ["name"] = "default:glass"}, {["x"] = 0, ["meta"] = {["fields"] = {}, ["inventory"] = {}}, ["y"] = 11, ["param1"] = 152, ["z"] = 6, ["name"] = "default:brick"}, {["x"] = 0, ["meta"] = {["fields"] = {}, ["inventory"] = {}}, ["y"] = 11, ["param1"] = 152, ["z"] = 24, ["name"] = "default:brick"}, {["x"] = 0, ["y"] = 11, ["param1"] = 206, ["z"] = 25, ["name"] = "default:glass"}, {["x"] = 0, ["y"] = 11, ["param1"] = 190, ["z"] = 26, ["name"] = "default:glass"}, {["x"] = 0, ["meta"] = {["fields"] = {}, ["inventory"] = {}}, ["y"] = 11, ["param1"] = 152, ["z"] = 27, ["name"] = "default:brick"}, {["x"] = 0, ["y"] = 11, ["param1"] = 190, ["z"] = 28, ["name"] = "default:glass"}, {["x"] = 0, ["y"] = 11, ["param1"] = 206, ["z"] = 29, ["name"] = "default:glass"}, {["x"] = 0, ["meta"] = {["fields"] = {}, ["inventory"] = {}}, ["y"] = 11, ["param1"] = 152, ["z"] = 30, ["name"] = "default:brick"}, {["x"] = 0, ["meta"] = {["fields"] = {}, ["inventory"] = {}}, ["y"] = 12, ["param1"] = 152, ["z"] = 0, ["name"] = "default:brick"}, {["x"] = 0, ["meta"] = {["fields"] = {}, ["inventory"] = {}}, ["y"] = 12, ["param1"] = 152, ["z"] = 1, ["name"] = "default:brick"}, {["x"] = 0, ["meta"] = {["fields"] = {}, ["inventory"] = {}}, ["y"] = 12, ["param1"] = 152, ["z"] = 2, ["name"] = "default:brick"}, {["x"] = 0, ["meta"] = {["fields"] = {}, ["inventory"] = {}}, ["y"] = 12, ["param1"] = 152, ["z"] = 3, ["name"] = "default:brick"}, {["x"] = 0, ["meta"] = {["fields"] = {}, ["inventory"] = {}}, ["y"] = 12, ["param1"] = 152, ["z"] = 4, ["name"] = "default:brick"}, {["x"] = 0, ["meta"] = {["fields"] = {}, ["inventory"] = {}}, ["y"] = 12, ["param1"] = 152, ["z"] = 5, ["name"] = "default:brick"}, {["x"] = 0, ["meta"] = {["fields"] = {}, ["inventory"] = {}}, ["y"] = 12, ["param1"] = 152, ["z"] = 6, ["name"] = "default:brick"}, {["x"] = 0, ["meta"] = {["fields"] = {}, ["inventory"] = {}}, ["y"] = 12, ["param1"] = 152, ["z"] = 24, ["name"] = "default:brick"}, {["x"] = 0, ["meta"] = {["fields"] = {}, ["inventory"] = {}}, ["y"] = 12, ["param1"] = 152, ["z"] = 25, ["name"] = "default:brick"}, {["x"] = 0, ["meta"] = {["fields"] = {}, ["inventory"] = {}}, ["y"] = 12, ["param1"] = 152, ["z"] = 26, ["name"] = "default:brick"}, {["x"] = 0, ["meta"] = {["fields"] = {}, ["inventory"] = {}}, ["y"] = 12, ["param1"] = 152, ["z"] = 27, ["name"] = "default:brick"}, {["x"] = 0, ["meta"] = {["fields"] = {}, ["inventory"] = {}}, ["y"] = 12, ["param1"] = 152, ["z"] = 28, ["name"] = "default:brick"}, {["x"] = 0, ["meta"] = {["fields"] = {}, ["inventory"] = {}}, ["y"] = 12, ["param1"] = 152, ["z"] = 29, ["name"] = "default:brick"}, {["x"] = 0, ["meta"] = {["fields"] = {}, ["inventory"] = {}}, ["y"] = 12, ["param1"] = 152, ["z"] = 30, ["name"] = "default:brick"}, {["x"] = 0, ["y"] = 13, ["param1"] = 190, ["z"] = 0, ["name"] = "stairs:slab_stone_block"}, {["x"] = 0, ["y"] = 13, ["param1"] = 206, ["z"] = 1, ["name"] = "stairs:slab_stone_block"}, {["x"] = 0, ["y"] = 13, ["param1"] = 190, ["z"] = 2, ["name"] = "stairs:slab_stone_block"}, {["x"] = 0, ["y"] = 13, ["param1"] = 174, ["z"] = 3, ["name"] = "stairs:slab_stone_block"}, {["x"] = 0, ["y"] = 13, ["param1"] = 190, ["z"] = 4, ["name"] = "stairs:slab_stone_block"}, {["x"] = 0, ["y"] = 13, ["param1"] = 206, ["z"] = 5, ["name"] = "stairs:slab_stone_block"}, {["x"] = 0, ["y"] = 13, ["param1"] = 190, ["z"] = 6, ["name"] = "stairs:slab_stone_block"}, {["x"] = 0, ["y"] = 13, ["param1"] = 190, ["z"] = 24, ["name"] = "stairs:slab_stone_block"}, {["x"] = 0, ["y"] = 13, ["param1"] = 206, ["z"] = 25, ["name"] = "stairs:slab_stone_block"}, {["x"] = 0, ["y"] = 13, ["param1"] = 190, ["z"] = 26, ["name"] = "stairs:slab_stone_block"}, {["x"] = 0, ["y"] = 13, ["param1"] = 174, ["z"] = 27, ["name"] = "stairs:slab_stone_block"}, {["x"] = 0, ["param2"] = 2, ["y"] = 13, ["param1"] = 190, ["z"] = 28, ["name"] = "stairs:slab_stone_block"}, {["x"] = 0, ["y"] = 13, ["param1"] = 206, ["z"] = 29, ["name"] = "stairs:slab_stone_block"}, {["x"] = 0, ["param2"] = 1, ["y"] = 13, ["param1"] = 190, ["z"] = 30, ["name"] = "stairs:slab_stone_block"}, {["x"] = 1, ["meta"] = {["fields"] = {}, ["inventory"] = {}}, ["y"] = 0, ["param1"] = 8, ["z"] = 0, ["name"] = "default:stonebrick"}, {["x"] = 1, ["meta"] = {["fields"] = {}, ["inventory"] = {}}, ["y"] = 0, ["param1"] = 6, ["z"] = 1, ["name"] = "default:stone"}, {["x"] = 1, ["meta"] = {["fields"] = {}, ["inventory"] = {}}, ["y"] = 0, ["param1"] = 6, ["z"] = 2, ["name"] = "default:stone"}, {["x"] = 1, ["meta"] = {["fields"] = {}, ["inventory"] = {}}, ["y"] = 0, ["param1"] = 6, ["z"] = 3, ["name"] = "default:stone"}, {["x"] = 1, ["meta"] = {["fields"] = {}, ["inventory"] = {}}, ["y"] = 0, ["param1"] = 6, ["z"] = 4, ["name"] = "default:stone"}, {["x"] = 1, ["meta"] = {["fields"] = {}, ["inventory"] = {}}, ["y"] = 0, ["param1"] = 6, ["z"] = 5, ["name"] = "default:stone"}, {["x"] = 1, ["meta"] = {["fields"] = {}, ["inventory"] = {}}, ["y"] = 0, ["param1"] = 8, ["z"] = 6, ["name"] = "default:stonebrick"}, {["x"] = 1, ["meta"] = {["fields"] = {}, ["inventory"] = {}}, ["y"] = 0, ["param1"] = 6, ["z"] = 7, ["name"] = "default:stone"}, {["x"] = 1, ["meta"] = {["fields"] = {}, ["inventory"] = {}}, ["y"] = 0, ["param1"] = 6, ["z"] = 8, ["name"] = "default:stone"}, {["x"] = 1, ["meta"] = {["fields"] = {}, ["inventory"] = {}}, ["y"] = 0, ["param1"] = 6, ["z"] = 9, ["name"] = "default:stone"}, {["x"] = 1, ["meta"] = {["fields"] = {}, ["inventory"] = {}}, ["y"] = 0, ["param1"] = 6, ["z"] = 10, ["name"] = "default:stone"}, {["x"] = 1, ["meta"] = {["fields"] = {}, ["inventory"] = {}}, ["y"] = 0, ["param1"] = 6, ["z"] = 11, ["name"] = "default:stone_block"}, {["x"] = 1, ["meta"] = {["fields"] = {}, ["inventory"] = {}}, ["y"] = 0, ["param1"] = 6, ["z"] = 12, ["name"] = "default:stone_block"}, {["x"] = 1, ["meta"] = {["fields"] = {}, ["inventory"] = {}}, ["y"] = 0, ["param1"] = 6, ["z"] = 13, ["name"] = "default:stone_block"}, {["x"] = 1, ["meta"] = {["fields"] = {}, ["inventory"] = {}}, ["y"] = 0, ["param1"] = 6, ["z"] = 14, ["name"] = "default:stone_block"}, {["x"] = 1, ["meta"] = {["fields"] = {}, ["inventory"] = {}}, ["y"] = 0, ["param1"] = 6, ["z"] = 15, ["name"] = "default:stone_block"}, {["x"] = 1, ["meta"] = {["fields"] = {}, ["inventory"] = {}}, ["y"] = 0, ["param1"] = 6, ["z"] = 16, ["name"] = "default:stone_block"}, {["x"] = 1, ["meta"] = {["fields"] = {}, ["inventory"] = {}}, ["y"] = 0, ["param1"] = 6, ["z"] = 17, ["name"] = "default:stone_block"}, {["x"] = 1, ["meta"] = {["fields"] = {}, ["inventory"] = {}}, ["y"] = 0, ["param1"] = 6, ["z"] = 18, ["name"] = "default:stone_block"}, {["x"] = 1, ["meta"] = {["fields"] = {}, ["inventory"] = {}}, ["y"] = 0, ["param1"] = 6, ["z"] = 19, ["name"] = "default:stone_block"}, {["x"] = 1, ["meta"] = {["fields"] = {}, ["inventory"] = {}}, ["y"] = 0, ["param1"] = 6, ["z"] = 20, ["name"] = "default:stone"}, {["x"] = 1, ["meta"] = {["fields"] = {}, ["inventory"] = {}}, ["y"] = 0, ["param1"] = 6, ["z"] = 21, ["name"] = "default:stone"}, {["x"] = 1, ["meta"] = {["fields"] = {}, ["inventory"] = {}}, ["y"] = 0, ["param1"] = 6, ["z"] = 22, ["name"] = "default:stone"}, {["x"] = 1, ["meta"] = {["fields"] = {}, ["inventory"] = {}}, ["y"] = 0, ["param1"] = 6, ["z"] = 23, ["name"] = "default:stone"}, {["x"] = 1, ["meta"] = {["fields"] = {}, ["inventory"] = {}}, ["y"] = 0, ["param1"] = 8, ["z"] = 24, ["name"] = "default:stonebrick"}, {["x"] = 1, ["meta"] = {["fields"] = {}, ["inventory"] = {}}, ["y"] = 0, ["param1"] = 6, ["z"] = 25, ["name"] = "default:stone"}, {["x"] = 1, ["meta"] = {["fields"] = {}, ["inventory"] = {}}, ["y"] = 0, ["param1"] = 6, ["z"] = 26, ["name"] = "default:stone"}, {["x"] = 1, ["meta"] = {["fields"] = {}, ["inventory"] = {}}, ["y"] = 0, ["param1"] = 6, ["z"] = 27, ["name"] = "default:stone"}, {["x"] = 1, ["meta"] = {["fields"] = {}, ["inventory"] = {}}, ["y"] = 0, ["param1"] = 6, ["z"] = 28, ["name"] = "default:stone"}, {["x"] = 1, ["meta"] = {["fields"] = {}, ["inventory"] = {}}, ["y"] = 0, ["param1"] = 6, ["z"] = 29, ["name"] = "default:stone"}, {["x"] = 1, ["meta"] = {["fields"] = {}, ["inventory"] = {}}, ["y"] = 0, ["param1"] = 8, ["z"] = 30, ["name"] = "default:stonebrick"}, {["x"] = 1, ["meta"] = {["fields"] = {}, ["inventory"] = {}}, ["y"] = 1, ["param1"] = 8, ["z"] = 0, ["name"] = "default:stonebrick"}, {["x"] = 1, ["y"] = 1, ["param1"] = 9, ["z"] = 1, ["name"] = "default:stone_block"}, {["x"] = 1, ["meta"] = {["fields"] = {}, ["inventory"] = {}}, ["y"] = 1, ["param1"] = 9, ["z"] = 2, ["name"] = "default:stone_block"}, {["x"] = 1, ["y"] = 1, ["param1"] = 9, ["z"] = 3, ["name"] = "default:stone_block"}, {["x"] = 1, ["meta"] = {["fields"] = {}, ["inventory"] = {}}, ["y"] = 1, ["param1"] = 9, ["z"] = 4, ["name"] = "default:stone_block"}, {["x"] = 1, ["meta"] = {["fields"] = {}, ["inventory"] = {}}, ["y"] = 1, ["param1"] = 9, ["z"] = 5, ["name"] = "default:stone_block"}, {["x"] = 1, ["meta"] = {["fields"] = {}, ["inventory"] = {}}, ["y"] = 1, ["param1"] = 8, ["z"] = 6, ["name"] = "default:stonebrick"}, {["x"] = 1, ["meta"] = {["fields"] = {}, ["inventory"] = {}}, ["y"] = 1, ["param1"] = 8, ["z"] = 24, ["name"] = "default:stonebrick"}, {["x"] = 1, ["meta"] = {["fields"] = {}, ["inventory"] = {}}, ["y"] = 1, ["param1"] = 9, ["z"] = 25, ["name"] = "default:stone_block"}, {["x"] = 1, ["meta"] = {["fields"] = {}, ["inventory"] = {}}, ["y"] = 1, ["param1"] = 9, ["z"] = 26, ["name"] = "default:stone_block"}, {["x"] = 1, ["meta"] = {["fields"] = {}, ["inventory"] = {}}, ["y"] = 1, ["param1"] = 9, ["z"] = 27, ["name"] = "default:stone_block"}, {["x"] = 1, ["meta"] = {["fields"] = {}, ["inventory"] = {}}, ["y"] = 1, ["param1"] = 9, ["z"] = 28, ["name"] = "default:stone_block"}, {["x"] = 1, ["meta"] = {["fields"] = {}, ["inventory"] = {}}, ["y"] = 1, ["param1"] = 9, ["z"] = 29, ["name"] = "default:stone_block"}, {["x"] = 1, ["meta"] = {["fields"] = {}, ["inventory"] = {}}, ["y"] = 1, ["param1"] = 8, ["z"] = 30, ["name"] = "default:stonebrick"}, {["x"] = 1, ["meta"] = {["fields"] = {}, ["inventory"] = {}}, ["y"] = 2, ["param1"] = 152, ["z"] = 0, ["name"] = "default:brick"}, {["x"] = 1, ["param2"] = 3, ["y"] = 2, ["param1"] = 140, ["z"] = 1, ["name"] = "stairs:stair_inner_wood"}, {["x"] = 1, ["param2"] = 3, ["y"] = 2, ["param1"] = 124, ["z"] = 2, ["name"] = "stairs:stair_wood"}, {["x"] = 1, ["param2"] = 3, ["y"] = 2, ["param1"] = 124, ["z"] = 4, ["name"] = "stairs:stair_wood"}, {["x"] = 1, ["y"] = 2, ["param1"] = 140, ["z"] = 5, ["name"] = "stairs:stair_inner_wood"}, {["x"] = 1, ["meta"] = {["fields"] = {}, ["inventory"] = {}}, ["y"] = 2, ["param1"] = 152, ["z"] = 6, ["name"] = "default:brick"}, {["x"] = 1, ["meta"] = {["fields"] = {}, ["inventory"] = {}}, ["y"] = 2, ["param1"] = 152, ["z"] = 24, ["name"] = "default:brick"}, {["x"] = 1, ["param2"] = 2, ["y"] = 2, ["param1"] = 172, ["z"] = 25, ["name"] = "stairs:stair_wood"}, {["x"] = 1, ["y"] = 2, ["param1"] = 156, ["z"] = 26, ["name"] = "default:fence_wood"}, {["x"] = 1, ["param2"] = 3, ["y"] = 2, ["param1"] = 172, ["z"] = 29, ["name"] = "stairs:stair_wood"}, {["x"] = 1, ["meta"] = {["fields"] = {}, ["inventory"] = {}}, ["y"] = 2, ["param1"] = 152, ["z"] = 30, ["name"] = "default:brick"}, {["x"] = 1, ["y"] = 3, ["param1"] = 142, ["z"] = 0, ["name"] = "default:glass"}, {["x"] = 1, ["y"] = 3, ["param1"] = 142, ["z"] = 6, ["name"] = "default:glass"}, {["x"] = 1, ["y"] = 3, ["param1"] = 174, ["z"] = 24, ["name"] = "default:glass"}, {["x"] = 1, ["param2"] = 2, ["y"] = 3, ["param1"] = 173, ["z"] = 26, ["name"] = "stairs:slab_wood"}, {["x"] = 1, ["y"] = 3, ["param1"] = 173, ["z"] = 30, ["name"] = "default:glass"}, {["x"] = 1, ["y"] = 4, ["param1"] = 158, ["z"] = 0, ["name"] = "default:glass"}, {["x"] = 1, ["y"] = 4, ["param1"] = 158, ["z"] = 6, ["name"] = "default:glass"}, {["x"] = 1, ["y"] = 4, ["param1"] = 190, ["z"] = 24, ["name"] = "default:glass"}, {["x"] = 1, ["y"] = 4, ["param1"] = 189, ["z"] = 30, ["name"] = "default:glass"}, {["x"] = 1, ["y"] = 5, ["param1"] = 174, ["z"] = 0, ["name"] = "default:glass"}, {["x"] = 1, ["y"] = 5, ["param1"] = 174, ["z"] = 6, ["name"] = "default:glass"}, {["x"] = 1, ["y"] = 5, ["param1"] = 206, ["z"] = 24, ["name"] = "default:glass"}, {["x"] = 1, ["y"] = 5, ["param1"] = 205, ["z"] = 30, ["name"] = "default:glass"}, {["x"] = 1, ["meta"] = {["fields"] = {}, ["inventory"] = {}}, ["y"] = 6, ["param1"] = 152, ["z"] = 0, ["name"] = "default:brick"}, {["x"] = 1, ["param2"] = 22, ["y"] = 6, ["param1"] = 204, ["z"] = 1, ["name"] = "stairs:slab_wood"}, {["x"] = 1, ["param2"] = 22, ["y"] = 6, ["param1"] = 188, ["z"] = 2, ["name"] = "stairs:slab_wood"}, {["x"] = 1, ["param2"] = 22, ["y"] = 6, ["param1"] = 204, ["z"] = 3, ["name"] = "stairs:slab_wood"}, {["x"] = 1, ["param2"] = 21, ["y"] = 6, ["param1"] = 188, ["z"] = 4, ["name"] = "stairs:slab_wood"}, {["x"] = 1, ["param2"] = 20, ["y"] = 6, ["param1"] = 204, ["z"] = 5, ["name"] = "stairs:slab_wood"}, {["x"] = 1, ["meta"] = {["fields"] = {}, ["inventory"] = {}}, ["y"] = 6, ["param1"] = 152, ["z"] = 6, ["name"] = "default:brick"}, {["x"] = 1, ["meta"] = {["fields"] = {}, ["inventory"] = {}}, ["y"] = 6, ["param1"] = 152, ["z"] = 24, ["name"] = "default:brick"}, {["x"] = 1, ["y"] = 6, ["param1"] = 238, ["z"] = 25, ["name"] = "default:meselamp"}, {["x"] = 1, ["y"] = 6, ["param1"] = 238, ["z"] = 29, ["name"] = "default:meselamp"}, {["x"] = 1, ["meta"] = {["fields"] = {}, ["inventory"] = {}}, ["y"] = 6, ["param1"] = 152, ["z"] = 30, ["name"] = "default:brick"}, {["x"] = 1, ["y"] = 7, ["z"] = 0, ["name"] = "default:stonebrick"}, {["x"] = 1, ["y"] = 7, ["param1"] = 11, ["z"] = 1, ["name"] = "default:stone_block"}, {["x"] = 1, ["y"] = 7, ["param1"] = 11, ["z"] = 2, ["name"] = "default:stone_block"}, {["x"] = 1, ["y"] = 7, ["param1"] = 10, ["z"] = 3, ["name"] = "default:stone_block"}, {["x"] = 1, ["y"] = 7, ["param1"] = 11, ["z"] = 4, ["name"] = "default:stone_block"}, {["x"] = 1, ["y"] = 7, ["z"] = 5, ["name"] = "default:stone_block"}, {["x"] = 1, ["y"] = 7, ["z"] = 6, ["name"] = "default:stonebrick"}, {["x"] = 1, ["y"] = 7, ["z"] = 24, ["name"] = "default:stonebrick"}, {["x"] = 1, ["y"] = 7, ["z"] = 25, ["name"] = "default:stone_block"}, {["x"] = 1, ["y"] = 7, ["param1"] = 11, ["z"] = 26, ["name"] = "default:stone_block"}, {["x"] = 1, ["y"] = 7, ["param1"] = 10, ["z"] = 27, ["name"] = "default:stone_block"}, {["x"] = 1, ["y"] = 7, ["param1"] = 11, ["z"] = 28, ["name"] = "default:stone_block"}, {["x"] = 1, ["y"] = 7, ["param1"] = 11, ["z"] = 29, ["name"] = "default:stone_block"}, {["x"] = 1, ["y"] = 7, ["z"] = 30, ["name"] = "default:stonebrick"}, {["x"] = 1, ["meta"] = {["fields"] = {}, ["inventory"] = {}}, ["y"] = 8, ["param1"] = 152, ["z"] = 0, ["name"] = "default:brick"}, {["x"] = 1, ["param2"] = 3, ["y"] = 8, ["param1"] = 172, ["z"] = 1, ["name"] = "stairs:stair_wood"}, {["x"] = 1, ["param2"] = 3, ["y"] = 8, ["param1"] = 139, ["z"] = 3, ["name"] = "stairs:stair_wood"}, {["x"] = 1, ["param2"] = 3, ["y"] = 8, ["param1"] = 172, ["z"] = 5, ["name"] = "stairs:stair_wood"}, {["x"] = 1, ["meta"] = {["fields"] = {}, ["inventory"] = {}}, ["y"] = 8, ["param1"] = 152, ["z"] = 6, ["name"] = "default:brick"}, {["x"] = 1, ["meta"] = {["fields"] = {}, ["inventory"] = {}}, ["y"] = 8, ["param1"] = 152, ["z"] = 24, ["name"] = "default:brick"}, {["x"] = 1, ["param2"] = 3, ["y"] = 8, ["param1"] = 172, ["z"] = 25, ["name"] = "stairs:stair_wood"}, {["x"] = 1, ["param2"] = 3, ["y"] = 8, ["param1"] = 139, ["z"] = 27, ["name"] = "stairs:stair_wood"}, {["x"] = 1, ["param2"] = 3, ["y"] = 8, ["param1"] = 172, ["z"] = 29, ["name"] = "stairs:stair_wood"}, {["x"] = 1, ["meta"] = {["fields"] = {}, ["inventory"] = {}}, ["y"] = 8, ["param1"] = 152, ["z"] = 30, ["name"] = "default:brick"}, {["x"] = 1, ["y"] = 9, ["param1"] = 174, ["z"] = 0, ["name"] = "default:glass"}, {["x"] = 1, ["y"] = 9, ["param1"] = 174, ["z"] = 6, ["name"] = "default:glass"}, {["x"] = 1, ["y"] = 9, ["param1"] = 174, ["z"] = 24, ["name"] = "default:glass"}, {["x"] = 1, ["y"] = 9, ["param1"] = 174, ["z"] = 30, ["name"] = "default:glass"}, {["x"] = 1, ["y"] = 10, ["param1"] = 190, ["z"] = 0, ["name"] = "default:glass"}, {["x"] = 1, ["y"] = 10, ["param1"] = 190, ["z"] = 6, ["name"] = "default:glass"}, {["x"] = 1, ["y"] = 10, ["param1"] = 190, ["z"] = 24, ["name"] = "default:glass"}, {["x"] = 1, ["y"] = 10, ["param1"] = 190, ["z"] = 30, ["name"] = "default:glass"}, {["x"] = 1, ["y"] = 11, ["param1"] = 206, ["z"] = 0, ["name"] = "default:glass"}, {["x"] = 1, ["y"] = 11, ["param1"] = 206, ["z"] = 6, ["name"] = "default:glass"}, {["x"] = 1, ["y"] = 11, ["param1"] = 206, ["z"] = 24, ["name"] = "default:glass"}, {["x"] = 1, ["y"] = 11, ["param1"] = 206, ["z"] = 30, ["name"] = "default:glass"}, {["x"] = 1, ["meta"] = {["fields"] = {}, ["inventory"] = {}}, ["y"] = 12, ["param1"] = 152, ["z"] = 0, ["name"] = "default:brick"}, {["x"] = 1, ["y"] = 12, ["param1"] = 238, ["z"] = 1, ["name"] = "default:meselamp"}, {["x"] = 1, ["y"] = 12, ["param1"] = 238, ["z"] = 5, ["name"] = "default:meselamp"}, {["x"] = 1, ["meta"] = {["fields"] = {}, ["inventory"] = {}}, ["y"] = 12, ["param1"] = 152, ["z"] = 6, ["name"] = "default:brick"}, {["x"] = 1, ["meta"] = {["fields"] = {}, ["inventory"] = {}}, ["y"] = 12, ["param1"] = 152, ["z"] = 24, ["name"] = "default:brick"}, {["x"] = 1, ["y"] = 12, ["param1"] = 238, ["z"] = 25, ["name"] = "default:meselamp"}, {["x"] = 1, ["y"] = 12, ["param1"] = 238, ["z"] = 29, ["name"] = "default:meselamp"}, {["x"] = 1, ["meta"] = {["fields"] = {}, ["inventory"] = {}}, ["y"] = 12, ["param1"] = 152, ["z"] = 30, ["name"] = "default:brick"}, {["x"] = 1, ["y"] = 13, ["param1"] = 206, ["z"] = 0, ["name"] = "stairs:slab_stone_block"}, {["x"] = 1, ["y"] = 13, ["param1"] = 222, ["z"] = 1, ["name"] = "stairs:slab_stone_block"}, {["x"] = 1, ["y"] = 13, ["param1"] = 206, ["z"] = 2, ["name"] = "stairs:slab_stone_block"}, {["x"] = 1, ["y"] = 13, ["param1"] = 190, ["z"] = 3, ["name"] = "stairs:slab_stone_block"}, {["x"] = 1, ["y"] = 13, ["param1"] = 206, ["z"] = 4, ["name"] = "stairs:slab_stone_block"}, {["x"] = 1, ["y"] = 13, ["param1"] = 222, ["z"] = 5, ["name"] = "stairs:slab_stone_block"}, {["x"] = 1, ["y"] = 13, ["param1"] = 206, ["z"] = 6, ["name"] = "stairs:slab_stone_block"}, {["x"] = 1, ["y"] = 13, ["param1"] = 206, ["z"] = 24, ["name"] = "stairs:slab_stone_block"}, {["x"] = 1, ["y"] = 13, ["param1"] = 222, ["z"] = 25, ["name"] = "stairs:slab_stone_block"}, {["x"] = 1, ["y"] = 13, ["param1"] = 206, ["z"] = 26, ["name"] = "stairs:slab_stone_block"}, {["x"] = 1, ["y"] = 13, ["param1"] = 190, ["z"] = 27, ["name"] = "stairs:slab_stone_block"}, {["x"] = 1, ["y"] = 13, ["param1"] = 206, ["z"] = 28, ["name"] = "stairs:slab_stone_block"}, {["x"] = 1, ["y"] = 13, ["param1"] = 222, ["z"] = 29, ["name"] = "stairs:slab_stone_block"}, {["x"] = 1, ["y"] = 13, ["param1"] = 206, ["z"] = 30, ["name"] = "stairs:slab_stone_block"}, {["x"] = 2, ["meta"] = {["fields"] = {}, ["inventory"] = {}}, ["y"] = 0, ["param1"] = 8, ["z"] = 0, ["name"] = "default:stonebrick"}, {["x"] = 2, ["meta"] = {["fields"] = {}, ["inventory"] = {}}, ["y"] = 0, ["param1"] = 6, ["z"] = 1, ["name"] = "default:stone"}, {["x"] = 2, ["meta"] = {["fields"] = {}, ["inventory"] = {}}, ["y"] = 0, ["param1"] = 6, ["z"] = 2, ["name"] = "default:stone"}, {["x"] = 2, ["meta"] = {["fields"] = {}, ["inventory"] = {}}, ["y"] = 0, ["param1"] = 6, ["z"] = 3, ["name"] = "default:stone"}, {["x"] = 2, ["meta"] = {["fields"] = {}, ["inventory"] = {}}, ["y"] = 0, ["param1"] = 6, ["z"] = 4, ["name"] = "default:stone"}, {["x"] = 2, ["meta"] = {["fields"] = {}, ["inventory"] = {}}, ["y"] = 0, ["param1"] = 6, ["z"] = 5, ["name"] = "default:stone"}, {["x"] = 2, ["meta"] = {["fields"] = {}, ["inventory"] = {}}, ["y"] = 0, ["param1"] = 8, ["z"] = 6, ["name"] = "default:stonebrick"}, {["x"] = 2, ["meta"] = {["fields"] = {}, ["inventory"] = {}}, ["y"] = 0, ["param1"] = 6, ["z"] = 7, ["name"] = "default:stone"}, {["x"] = 2, ["meta"] = {["fields"] = {}, ["inventory"] = {}}, ["y"] = 0, ["param1"] = 6, ["z"] = 8, ["name"] = "default:stone"}, {["x"] = 2, ["meta"] = {["fields"] = {}, ["inventory"] = {}}, ["y"] = 0, ["param1"] = 6, ["z"] = 9, ["name"] = "default:stone"}, {["x"] = 2, ["meta"] = {["fields"] = {}, ["inventory"] = {}}, ["y"] = 0, ["param1"] = 6, ["z"] = 10, ["name"] = "default:stone"}, {["x"] = 2, ["meta"] = {["fields"] = {}, ["inventory"] = {}}, ["y"] = 0, ["param1"] = 6, ["z"] = 11, ["name"] = "default:stone_block"}, {["x"] = 2, ["meta"] = {["fields"] = {}, ["inventory"] = {}}, ["y"] = 0, ["param1"] = 6, ["z"] = 12, ["name"] = "default:stone_block"}, {["x"] = 2, ["meta"] = {["fields"] = {}, ["inventory"] = {}}, ["y"] = 0, ["param1"] = 6, ["z"] = 13, ["name"] = "default:stone_block"}, {["x"] = 2, ["meta"] = {["fields"] = {}, ["inventory"] = {}}, ["y"] = 0, ["param1"] = 6, ["z"] = 14, ["name"] = "default:stone_block"}, {["x"] = 2, ["meta"] = {["fields"] = {}, ["inventory"] = {}}, ["y"] = 0, ["param1"] = 6, ["z"] = 15, ["name"] = "default:stone_block"}, {["x"] = 2, ["meta"] = {["fields"] = {}, ["inventory"] = {}}, ["y"] = 0, ["param1"] = 6, ["z"] = 16, ["name"] = "default:stone_block"}, {["x"] = 2, ["meta"] = {["fields"] = {}, ["inventory"] = {}}, ["y"] = 0, ["param1"] = 6, ["z"] = 17, ["name"] = "default:stone_block"}, {["x"] = 2, ["meta"] = {["fields"] = {}, ["inventory"] = {}}, ["y"] = 0, ["param1"] = 6, ["z"] = 18, ["name"] = "default:stone_block"}, {["x"] = 2, ["meta"] = {["fields"] = {}, ["inventory"] = {}}, ["y"] = 0, ["param1"] = 6, ["z"] = 19, ["name"] = "default:stone_block"}, {["x"] = 2, ["meta"] = {["fields"] = {}, ["inventory"] = {}}, ["y"] = 0, ["param1"] = 6, ["z"] = 20, ["name"] = "default:stone"}, {["x"] = 2, ["meta"] = {["fields"] = {}, ["inventory"] = {}}, ["y"] = 0, ["param1"] = 6, ["z"] = 21, ["name"] = "default:stone"}, {["x"] = 2, ["meta"] = {["fields"] = {}, ["inventory"] = {}}, ["y"] = 0, ["param1"] = 6, ["z"] = 22, ["name"] = "default:stone"}, {["x"] = 2, ["meta"] = {["fields"] = {}, ["inventory"] = {}}, ["y"] = 0, ["param1"] = 6, ["z"] = 23, ["name"] = "default:stone"}, {["x"] = 2, ["meta"] = {["fields"] = {}, ["inventory"] = {}}, ["y"] = 0, ["param1"] = 8, ["z"] = 24, ["name"] = "default:stonebrick"}, {["x"] = 2, ["meta"] = {["fields"] = {}, ["inventory"] = {}}, ["y"] = 0, ["param1"] = 6, ["z"] = 25, ["name"] = "default:stone"}, {["x"] = 2, ["meta"] = {["fields"] = {}, ["inventory"] = {}}, ["y"] = 0, ["param1"] = 6, ["z"] = 26, ["name"] = "default:stone"}, {["x"] = 2, ["meta"] = {["fields"] = {}, ["inventory"] = {}}, ["y"] = 0, ["param1"] = 6, ["z"] = 27, ["name"] = "default:stone"}, {["x"] = 2, ["meta"] = {["fields"] = {}, ["inventory"] = {}}, ["y"] = 0, ["param1"] = 6, ["z"] = 28, ["name"] = "default:stone"}, {["x"] = 2, ["meta"] = {["fields"] = {}, ["inventory"] = {}}, ["y"] = 0, ["param1"] = 6, ["z"] = 29, ["name"] = "default:stone"}, {["x"] = 2, ["meta"] = {["fields"] = {}, ["inventory"] = {}}, ["y"] = 0, ["param1"] = 8, ["z"] = 30, ["name"] = "default:stonebrick"}, {["x"] = 2, ["meta"] = {["fields"] = {}, ["inventory"] = {}}, ["y"] = 1, ["param1"] = 8, ["z"] = 0, ["name"] = "default:stonebrick"}, {["x"] = 2, ["y"] = 1, ["param1"] = 9, ["z"] = 1, ["name"] = "default:stone_block"}, {["x"] = 2, ["meta"] = {["fields"] = {}, ["inventory"] = {}}, ["y"] = 1, ["param1"] = 9, ["z"] = 2, ["name"] = "default:stone_block"}, {["x"] = 2, ["meta"] = {["fields"] = {}, ["inventory"] = {}}, ["y"] = 1, ["param1"] = 9, ["z"] = 3, ["name"] = "default:stone_block"}, {["x"] = 2, ["y"] = 1, ["param1"] = 9, ["z"] = 4, ["name"] = "default:stone_block"}, {["x"] = 2, ["meta"] = {["fields"] = {}, ["inventory"] = {}}, ["y"] = 1, ["param1"] = 9, ["z"] = 5, ["name"] = "default:stone_block"}, {["x"] = 2, ["meta"] = {["fields"] = {}, ["inventory"] = {}}, ["y"] = 1, ["param1"] = 8, ["z"] = 6, ["name"] = "default:stonebrick"}, {["x"] = 2, ["meta"] = {["fields"] = {}, ["inventory"] = {}}, ["y"] = 1, ["param1"] = 8, ["z"] = 24, ["name"] = "default:stonebrick"}, {["x"] = 2, ["meta"] = {["fields"] = {}, ["inventory"] = {}}, ["y"] = 1, ["param1"] = 9, ["z"] = 25, ["name"] = "default:stone_block"}, {["x"] = 2, ["meta"] = {["fields"] = {}, ["inventory"] = {}}, ["y"] = 1, ["param1"] = 9, ["z"] = 26, ["name"] = "default:stone_block"}, {["x"] = 2, ["meta"] = {["fields"] = {}, ["inventory"] = {}}, ["y"] = 1, ["param1"] = 9, ["z"] = 27, ["name"] = "default:stone_block"}, {["x"] = 2, ["meta"] = {["fields"] = {}, ["inventory"] = {}}, ["y"] = 1, ["param1"] = 9, ["z"] = 28, ["name"] = "default:stone_block"}, {["x"] = 2, ["meta"] = {["fields"] = {}, ["inventory"] = {}}, ["y"] = 1, ["param1"] = 9, ["z"] = 29, ["name"] = "default:stone_block"}, {["x"] = 2, ["meta"] = {["fields"] = {}, ["inventory"] = {}}, ["y"] = 1, ["param1"] = 8, ["z"] = 30, ["name"] = "default:stonebrick"}, {["x"] = 2, ["meta"] = {["fields"] = {}, ["inventory"] = {}}, ["y"] = 2, ["param1"] = 152, ["z"] = 0, ["name"] = "default:brick"}, {["x"] = 2, ["param2"] = 2, ["y"] = 2, ["param1"] = 156, ["z"] = 1, ["name"] = "stairs:stair_wood"}, {["x"] = 2, ["y"] = 2, ["param1"] = 139, ["z"] = 2, ["name"] = "default:fence_wood"}, {["x"] = 2, ["y"] = 2, ["param1"] = 139, ["z"] = 4, ["name"] = "default:fence_wood"}, {["x"] = 2, ["y"] = 2, ["param1"] = 156, ["z"] = 5, ["name"] = "stairs:stair_wood"}, {["x"] = 2, ["meta"] = {["fields"] = {}, ["inventory"] = {}}, ["y"] = 2, ["param1"] = 152, ["z"] = 6, ["name"] = "default:brick"}, {["x"] = 2, ["meta"] = {["fields"] = {}, ["inventory"] = {}}, ["y"] = 2, ["param1"] = 152, ["z"] = 24, ["name"] = "default:brick"}, {["x"] = 2, ["y"] = 2, ["param1"] = 156, ["z"] = 29, ["name"] = "default:fence_wood"}, {["x"] = 2, ["meta"] = {["fields"] = {}, ["inventory"] = {}}, ["y"] = 2, ["param1"] = 152, ["z"] = 30, ["name"] = "default:brick"}, {["x"] = 2, ["y"] = 3, ["param1"] = 158, ["z"] = 0, ["name"] = "default:glass"}, {["x"] = 2, ["param2"] = 3, ["y"] = 3, ["param1"] = 156, ["z"] = 2, ["name"] = "stairs:slab_wood"}, {["x"] = 2, ["param2"] = 3, ["y"] = 3, ["param1"] = 156, ["z"] = 4, ["name"] = "stairs:slab_wood"}, {["x"] = 2, ["y"] = 3, ["param1"] = 158, ["z"] = 6, ["name"] = "default:glass"}, {["x"] = 2, ["y"] = 3, ["param1"] = 158, ["z"] = 24, ["name"] = "default:glass"}, {["x"] = 2, ["y"] = 3, ["param1"] = 173, ["z"] = 29, ["name"] = "stairs:slab_wood"}, {["x"] = 2, ["y"] = 3, ["param1"] = 158, ["z"] = 30, ["name"] = "default:glass"}, {["x"] = 2, ["y"] = 4, ["param1"] = 174, ["z"] = 0, ["name"] = "default:glass"}, {["x"] = 2, ["y"] = 4, ["param1"] = 174, ["z"] = 6, ["name"] = "default:glass"}, {["x"] = 2, ["y"] = 4, ["param1"] = 174, ["z"] = 24, ["name"] = "default:glass"}, {["x"] = 2, ["y"] = 4, ["param1"] = 174, ["z"] = 30, ["name"] = "default:glass"}, {["x"] = 2, ["y"] = 5, ["param1"] = 190, ["z"] = 0, ["name"] = "default:glass"}, {["x"] = 2, ["y"] = 5, ["param1"] = 190, ["z"] = 6, ["name"] = "default:glass"}, {["x"] = 2, ["y"] = 5, ["param1"] = 190, ["z"] = 24, ["name"] = "default:glass"}, {["x"] = 2, ["y"] = 5, ["param1"] = 190, ["z"] = 30, ["name"] = "default:glass"}, {["x"] = 2, ["meta"] = {["fields"] = {}, ["inventory"] = {}}, ["y"] = 6, ["param1"] = 152, ["z"] = 0, ["name"] = "default:brick"}, {["x"] = 2, ["param2"] = 22, ["y"] = 6, ["param1"] = 221, ["z"] = 1, ["name"] = "stairs:slab_wood"}, {["x"] = 2, ["param2"] = 21, ["y"] = 6, ["param1"] = 204, ["z"] = 2, ["name"] = "stairs:slab_wood"}, {["x"] = 2, ["param2"] = 20, ["y"] = 6, ["param1"] = 221, ["z"] = 3, ["name"] = "stairs:slab_wood"}, {["x"] = 2, ["param2"] = 20, ["y"] = 6, ["param1"] = 204, ["z"] = 4, ["name"] = "stairs:slab_wood"}, {["x"] = 2, ["param2"] = 20, ["y"] = 6, ["param1"] = 221, ["z"] = 5, ["name"] = "stairs:slab_wood"}, {["x"] = 2, ["meta"] = {["fields"] = {}, ["inventory"] = {}}, ["y"] = 6, ["param1"] = 152, ["z"] = 6, ["name"] = "default:brick"}, {["x"] = 2, ["param2"] = 2, ["y"] = 6, ["param1"] = 126, ["z"] = 12, ["name"] = "stairs:slab_stone_block"}, {["x"] = 2, ["param2"] = 2, ["y"] = 6, ["param1"] = 142, ["z"] = 13, ["name"] = "stairs:slab_stone_block"}, {["x"] = 2, ["param2"] = 2, ["y"] = 6, ["param1"] = 126, ["z"] = 14, ["name"] = "stairs:slab_stone_block"}, {["x"] = 2, ["param2"] = 2, ["y"] = 6, ["param1"] = 110, ["z"] = 15, ["name"] = "stairs:slab_stone_block"}, {["x"] = 2, ["param2"] = 1, ["y"] = 6, ["param1"] = 126, ["z"] = 16, ["name"] = "stairs:slab_stone_block"}, {["x"] = 2, ["param2"] = 1, ["y"] = 6, ["param1"] = 142, ["z"] = 17, ["name"] = "stairs:slab_stone_block"}, {["x"] = 2, ["param2"] = 1, ["y"] = 6, ["param1"] = 126, ["z"] = 18, ["name"] = "stairs:slab_stone_block"}, {["x"] = 2, ["meta"] = {["fields"] = {}, ["inventory"] = {}}, ["y"] = 6, ["param1"] = 152, ["z"] = 24, ["name"] = "default:brick"}, {["x"] = 2, ["meta"] = {["fields"] = {}, ["inventory"] = {}}, ["y"] = 6, ["param1"] = 152, ["z"] = 30, ["name"] = "default:brick"}, {["x"] = 2, ["y"] = 7, ["z"] = 0, ["name"] = "default:stonebrick"}, {["x"] = 2, ["y"] = 7, ["param1"] = 11, ["z"] = 1, ["name"] = "default:stone_block"}, {["x"] = 2, ["y"] = 7, ["param1"] = 10, ["z"] = 2, ["name"] = "default:stone_block"}, {["x"] = 2, ["y"] = 7, ["param1"] = 9, ["z"] = 3, ["name"] = "default:stone_block"}, {["x"] = 2, ["y"] = 7, ["param1"] = 10, ["z"] = 4, ["name"] = "default:stone_block"}, {["x"] = 2, ["y"] = 7, ["param1"] = 11, ["z"] = 5, ["name"] = "default:stone_block"}, {["x"] = 2, ["y"] = 7, ["z"] = 6, ["name"] = "default:stonebrick"}, {["x"] = 2, ["y"] = 7, ["z"] = 24, ["name"] = "default:stonebrick"}, {["x"] = 2, ["y"] = 7, ["param1"] = 11, ["z"] = 25, ["name"] = "default:stone_block"}, {["x"] = 2, ["y"] = 7, ["param1"] = 10, ["z"] = 26, ["name"] = "default:stone_block"}, {["x"] = 2, ["y"] = 7, ["param1"] = 9, ["z"] = 27, ["name"] = "default:stone_block"}, {["x"] = 2, ["y"] = 7, ["param1"] = 10, ["z"] = 28, ["name"] = "default:stone_block"}, {["x"] = 2, ["y"] = 7, ["param1"] = 11, ["z"] = 29, ["name"] = "default:stone_block"}, {["x"] = 2, ["y"] = 7, ["z"] = 30, ["name"] = "default:stonebrick"}, {["x"] = 2, ["meta"] = {["fields"] = {}, ["inventory"] = {}}, ["y"] = 8, ["param1"] = 152, ["z"] = 0, ["name"] = "default:brick"}, {["x"] = 2, ["y"] = 8, ["param1"] = 156, ["z"] = 1, ["name"] = "default:fence_wood"}, {["x"] = 2, ["y"] = 8, ["param1"] = 122, ["z"] = 3, ["name"] = "default:fence_wood"}, {["x"] = 2, ["y"] = 8, ["param1"] = 156, ["z"] = 5, ["name"] = "default:fence_wood"}, {["x"] = 2, ["meta"] = {["fields"] = {}, ["inventory"] = {}}, ["y"] = 8, ["param1"] = 152, ["z"] = 6, ["name"] = "default:brick"}, {["x"] = 2, ["meta"] = {["fields"] = {}, ["inventory"] = {}}, ["y"] = 8, ["param1"] = 152, ["z"] = 24, ["name"] = "default:brick"}, {["x"] = 2, ["y"] = 8, ["param1"] = 156, ["z"] = 25, ["name"] = "default:fence_wood"}, {["x"] = 2, ["y"] = 8, ["param1"] = 122, ["z"] = 27, ["name"] = "default:fence_wood"}, {["x"] = 2, ["y"] = 8, ["param1"] = 156, ["z"] = 29, ["name"] = "default:fence_wood"}, {["x"] = 2, ["meta"] = {["fields"] = {}, ["inventory"] = {}}, ["y"] = 8, ["param1"] = 152, ["z"] = 30, ["name"] = "default:brick"}, {["x"] = 2, ["y"] = 9, ["param1"] = 158, ["z"] = 0, ["name"] = "default:glass"}, {["x"] = 2, ["param2"] = 3, ["y"] = 9, ["param1"] = 173, ["z"] = 1, ["name"] = "stairs:slab_wood"}, {["x"] = 2, ["param2"] = 3, ["y"] = 9, ["param1"] = 139, ["z"] = 3, ["name"] = "stairs:slab_wood"}, {["x"] = 2, ["param2"] = 3, ["y"] = 9, ["param1"] = 173, ["z"] = 5, ["name"] = "stairs:slab_wood"}, {["x"] = 2, ["y"] = 9, ["param1"] = 158, ["z"] = 6, ["name"] = "default:glass"}, {["x"] = 2, ["y"] = 9, ["param1"] = 158, ["z"] = 24, ["name"] = "default:glass"}, {["x"] = 2, ["param2"] = 3, ["y"] = 9, ["param1"] = 173, ["z"] = 25, ["name"] = "stairs:slab_wood"}, {["x"] = 2, ["param2"] = 3, ["y"] = 9, ["param1"] = 139, ["z"] = 27, ["name"] = "stairs:slab_wood"}, {["x"] = 2, ["param2"] = 3, ["y"] = 9, ["param1"] = 173, ["z"] = 29, ["name"] = "stairs:slab_wood"}, {["x"] = 2, ["y"] = 9, ["param1"] = 158, ["z"] = 30, ["name"] = "default:glass"}, {["x"] = 2, ["y"] = 10, ["param1"] = 174, ["z"] = 0, ["name"] = "default:glass"}, {["x"] = 2, ["y"] = 10, ["param1"] = 174, ["z"] = 6, ["name"] = "default:glass"}, {["x"] = 2, ["y"] = 10, ["param1"] = 174, ["z"] = 24, ["name"] = "default:glass"}, {["x"] = 2, ["y"] = 10, ["param1"] = 174, ["z"] = 30, ["name"] = "default:glass"}, {["x"] = 2, ["y"] = 11, ["param1"] = 190, ["z"] = 0, ["name"] = "default:glass"}, {["x"] = 2, ["y"] = 11, ["param1"] = 190, ["z"] = 6, ["name"] = "default:glass"}, {["x"] = 2, ["y"] = 11, ["param1"] = 190, ["z"] = 24, ["name"] = "default:glass"}, {["x"] = 2, ["y"] = 11, ["param1"] = 190, ["z"] = 30, ["name"] = "default:glass"}, {["x"] = 2, ["meta"] = {["fields"] = {}, ["inventory"] = {}}, ["y"] = 12, ["param1"] = 152, ["z"] = 0, ["name"] = "default:brick"}, {["x"] = 2, ["meta"] = {["fields"] = {}, ["inventory"] = {}}, ["y"] = 12, ["param1"] = 152, ["z"] = 6, ["name"] = "default:brick"}, {["x"] = 2, ["meta"] = {["fields"] = {}, ["inventory"] = {}}, ["y"] = 12, ["param1"] = 152, ["z"] = 24, ["name"] = "default:brick"}, {["x"] = 2, ["meta"] = {["fields"] = {}, ["inventory"] = {}}, ["y"] = 12, ["param1"] = 152, ["z"] = 30, ["name"] = "default:brick"}, {["x"] = 2, ["y"] = 13, ["param1"] = 190, ["z"] = 0, ["name"] = "stairs:slab_stone_block"}, {["x"] = 2, ["y"] = 13, ["param1"] = 206, ["z"] = 1, ["name"] = "stairs:slab_stone_block"}, {["x"] = 2, ["y"] = 13, ["param1"] = 190, ["z"] = 2, ["name"] = "stairs:slab_stone_block"}, {["x"] = 2, ["y"] = 13, ["param1"] = 174, ["z"] = 3, ["name"] = "stairs:slab_stone_block"}, {["x"] = 2, ["y"] = 13, ["param1"] = 190, ["z"] = 4, ["name"] = "stairs:slab_stone_block"}, {["x"] = 2, ["y"] = 13, ["param1"] = 206, ["z"] = 5, ["name"] = "stairs:slab_stone_block"}, {["x"] = 2, ["y"] = 13, ["param1"] = 190, ["z"] = 6, ["name"] = "stairs:slab_stone_block"}, {["x"] = 2, ["y"] = 13, ["param1"] = 190, ["z"] = 24, ["name"] = "stairs:slab_stone_block"}, {["x"] = 2, ["y"] = 13, ["param1"] = 206, ["z"] = 25, ["name"] = "stairs:slab_stone_block"}, {["x"] = 2, ["y"] = 13, ["param1"] = 190, ["z"] = 26, ["name"] = "stairs:slab_stone_block"}, {["x"] = 2, ["y"] = 13, ["param1"] = 174, ["z"] = 27, ["name"] = "stairs:slab_stone_block"}, {["x"] = 2, ["y"] = 13, ["param1"] = 190, ["z"] = 28, ["name"] = "stairs:slab_stone_block"}, {["x"] = 2, ["y"] = 13, ["param1"] = 206, ["z"] = 29, ["name"] = "stairs:slab_stone_block"}, {["x"] = 2, ["y"] = 13, ["param1"] = 190, ["z"] = 30, ["name"] = "stairs:slab_stone_block"}, {["x"] = 3, ["meta"] = {["fields"] = {}, ["inventory"] = {}}, ["y"] = 0, ["param1"] = 8, ["z"] = 0, ["name"] = "default:stonebrick"}, {["x"] = 3, ["meta"] = {["fields"] = {}, ["inventory"] = {}}, ["y"] = 0, ["param1"] = 6, ["z"] = 1, ["name"] = "default:stone"}, {["x"] = 3, ["meta"] = {["fields"] = {}, ["inventory"] = {}}, ["y"] = 0, ["param1"] = 6, ["z"] = 2, ["name"] = "default:stone"}, {["x"] = 3, ["meta"] = {["fields"] = {}, ["inventory"] = {}}, ["y"] = 0, ["param1"] = 6, ["z"] = 3, ["name"] = "default:stone"}, {["x"] = 3, ["meta"] = {["fields"] = {}, ["inventory"] = {}}, ["y"] = 0, ["param1"] = 6, ["z"] = 4, ["name"] = "default:stone"}, {["x"] = 3, ["meta"] = {["fields"] = {}, ["inventory"] = {}}, ["y"] = 0, ["param1"] = 6, ["z"] = 5, ["name"] = "default:stone"}, {["x"] = 3, ["meta"] = {["fields"] = {}, ["inventory"] = {}}, ["y"] = 0, ["param1"] = 8, ["z"] = 6, ["name"] = "default:stonebrick"}, {["x"] = 3, ["meta"] = {["fields"] = {}, ["inventory"] = {}}, ["y"] = 0, ["param1"] = 6, ["z"] = 7, ["name"] = "default:stone"}, {["x"] = 3, ["meta"] = {["fields"] = {}, ["inventory"] = {}}, ["y"] = 0, ["param1"] = 6, ["z"] = 8, ["name"] = "default:stone"}, {["x"] = 3, ["meta"] = {["fields"] = {}, ["inventory"] = {}}, ["y"] = 0, ["param1"] = 6, ["z"] = 9, ["name"] = "default:stone"}, {["x"] = 3, ["meta"] = {["fields"] = {}, ["inventory"] = {}}, ["y"] = 0, ["param1"] = 6, ["z"] = 10, ["name"] = "default:stone"}, {["x"] = 3, ["meta"] = {["fields"] = {}, ["inventory"] = {}}, ["y"] = 0, ["param1"] = 6, ["z"] = 11, ["name"] = "default:stone"}, {["x"] = 3, ["meta"] = {["fields"] = {}, ["inventory"] = {}}, ["y"] = 0, ["param1"] = 6, ["z"] = 12, ["name"] = "default:stone"}, {["x"] = 3, ["meta"] = {["fields"] = {}, ["inventory"] = {}}, ["y"] = 0, ["param1"] = 6, ["z"] = 13, ["name"] = "default:stone"}, {["x"] = 3, ["meta"] = {["fields"] = {}, ["inventory"] = {}}, ["y"] = 0, ["param1"] = 6, ["z"] = 14, ["name"] = "default:stone"}, {["x"] = 3, ["meta"] = {["fields"] = {}, ["inventory"] = {}}, ["y"] = 0, ["param1"] = 6, ["z"] = 15, ["name"] = "default:stone"}, {["x"] = 3, ["meta"] = {["fields"] = {}, ["inventory"] = {}}, ["y"] = 0, ["param1"] = 6, ["z"] = 16, ["name"] = "default:stone"}, {["x"] = 3, ["meta"] = {["fields"] = {}, ["inventory"] = {}}, ["y"] = 0, ["param1"] = 6, ["z"] = 17, ["name"] = "default:stone"}, {["x"] = 3, ["meta"] = {["fields"] = {}, ["inventory"] = {}}, ["y"] = 0, ["param1"] = 6, ["z"] = 18, ["name"] = "default:stone"}, {["x"] = 3, ["meta"] = {["fields"] = {}, ["inventory"] = {}}, ["y"] = 0, ["param1"] = 6, ["z"] = 19, ["name"] = "default:stone"}, {["x"] = 3, ["meta"] = {["fields"] = {}, ["inventory"] = {}}, ["y"] = 0, ["param1"] = 6, ["z"] = 20, ["name"] = "default:stone"}, {["x"] = 3, ["meta"] = {["fields"] = {}, ["inventory"] = {}}, ["y"] = 0, ["param1"] = 6, ["z"] = 21, ["name"] = "default:stone"}, {["x"] = 3, ["meta"] = {["fields"] = {}, ["inventory"] = {}}, ["y"] = 0, ["param1"] = 6, ["z"] = 22, ["name"] = "default:stone"}, {["x"] = 3, ["meta"] = {["fields"] = {}, ["inventory"] = {}}, ["y"] = 0, ["param1"] = 6, ["z"] = 23, ["name"] = "default:stone"}, {["x"] = 3, ["meta"] = {["fields"] = {}, ["inventory"] = {}}, ["y"] = 0, ["param1"] = 8, ["z"] = 24, ["name"] = "default:stonebrick"}, {["x"] = 3, ["meta"] = {["fields"] = {}, ["inventory"] = {}}, ["y"] = 0, ["param1"] = 6, ["z"] = 25, ["name"] = "default:stone"}, {["x"] = 3, ["meta"] = {["fields"] = {}, ["inventory"] = {}}, ["y"] = 0, ["param1"] = 6, ["z"] = 26, ["name"] = "default:stone"}, {["x"] = 3, ["meta"] = {["fields"] = {}, ["inventory"] = {}}, ["y"] = 0, ["param1"] = 6, ["z"] = 27, ["name"] = "default:stone"}, {["x"] = 3, ["meta"] = {["fields"] = {}, ["inventory"] = {}}, ["y"] = 0, ["param1"] = 6, ["z"] = 28, ["name"] = "default:stone"}, {["x"] = 3, ["meta"] = {["fields"] = {}, ["inventory"] = {}}, ["y"] = 0, ["param1"] = 6, ["z"] = 29, ["name"] = "default:stone"}, {["x"] = 3, ["meta"] = {["fields"] = {}, ["inventory"] = {}}, ["y"] = 0, ["param1"] = 8, ["z"] = 30, ["name"] = "default:stonebrick"}, {["x"] = 3, ["meta"] = {["fields"] = {}, ["inventory"] = {}}, ["y"] = 1, ["param1"] = 8, ["z"] = 0, ["name"] = "default:stonebrick"}, {["x"] = 3, ["meta"] = {["fields"] = {}, ["inventory"] = {}}, ["y"] = 1, ["param1"] = 9, ["z"] = 1, ["name"] = "default:stone_block"}, {["x"] = 3, ["meta"] = {["fields"] = {}, ["inventory"] = {}}, ["y"] = 1, ["param1"] = 9, ["z"] = 2, ["name"] = "default:stone_block"}, {["x"] = 3, ["meta"] = {["fields"] = {}, ["inventory"] = {}}, ["y"] = 1, ["param1"] = 9, ["z"] = 3, ["name"] = "default:stone_block"}, {["x"] = 3, ["meta"] = {["fields"] = {}, ["inventory"] = {}}, ["y"] = 1, ["param1"] = 9, ["z"] = 4, ["name"] = "default:stone_block"}, {["x"] = 3, ["meta"] = {["fields"] = {}, ["inventory"] = {}}, ["y"] = 1, ["param1"] = 9, ["z"] = 5, ["name"] = "default:stone_block"}, {["x"] = 3, ["meta"] = {["fields"] = {}, ["inventory"] = {}}, ["y"] = 1, ["param1"] = 8, ["z"] = 6, ["name"] = "default:stonebrick"}, {["x"] = 3, ["param2"] = 1, ["y"] = 1, ["param1"] = 78, ["z"] = 11, ["name"] = "stairs:stair_outer_stone_block"}, {["x"] = 3, ["param2"] = 1, ["y"] = 1, ["param1"] = 93, ["z"] = 12, ["name"] = "stairs:stair_stone_block"}, {["x"] = 3, ["param2"] = 1, ["y"] = 1, ["param1"] = 109, ["z"] = 13, ["name"] = "stairs:stair_stone_block"}, {["x"] = 3, ["param2"] = 1, ["y"] = 1, ["param1"] = 93, ["z"] = 14, ["name"] = "stairs:stair_stone_block"}, {["x"] = 3, ["param2"] = 1, ["y"] = 1, ["param1"] = 77, ["z"] = 15, ["name"] = "stairs:stair_stone_block"}, {["x"] = 3, ["param2"] = 1, ["y"] = 1, ["param1"] = 93, ["z"] = 16, ["name"] = "stairs:stair_stone_block"}, {["x"] = 3, ["param2"] = 1, ["y"] = 1, ["param1"] = 109, ["z"] = 17, ["name"] = "stairs:stair_stone_block"}, {["x"] = 3, ["param2"] = 1, ["y"] = 1, ["param1"] = 93, ["z"] = 18, ["name"] = "stairs:stair_stone_block"}, {["x"] = 3, ["param2"] = 2, ["y"] = 1, ["param1"] = 78, ["z"] = 19, ["name"] = "stairs:stair_outer_stone_block"}, {["x"] = 3, ["meta"] = {["fields"] = {}, ["inventory"] = {}}, ["y"] = 1, ["param1"] = 8, ["z"] = 24, ["name"] = "default:stonebrick"}, {["x"] = 3, ["meta"] = {["fields"] = {}, ["inventory"] = {}}, ["y"] = 1, ["param1"] = 9, ["z"] = 25, ["name"] = "default:stone_block"}, {["x"] = 3, ["meta"] = {["fields"] = {}, ["inventory"] = {}}, ["y"] = 1, ["param1"] = 9, ["z"] = 26, ["name"] = "default:stone_block"}, {["x"] = 3, ["meta"] = {["fields"] = {}, ["inventory"] = {}}, ["y"] = 1, ["param1"] = 9, ["z"] = 27, ["name"] = "default:stone_block"}, {["x"] = 3, ["meta"] = {["fields"] = {}, ["inventory"] = {}}, ["y"] = 1, ["param1"] = 9, ["z"] = 28, ["name"] = "default:stone_block"}, {["x"] = 3, ["meta"] = {["fields"] = {}, ["inventory"] = {}}, ["y"] = 1, ["param1"] = 9, ["z"] = 29, ["name"] = "default:stone_block"}, {["x"] = 3, ["meta"] = {["fields"] = {}, ["inventory"] = {}}, ["y"] = 1, ["param1"] = 8, ["z"] = 30, ["name"] = "default:stonebrick"}, {["x"] = 3, ["meta"] = {["fields"] = {}, ["inventory"] = {}}, ["y"] = 2, ["param1"] = 152, ["z"] = 0, ["name"] = "default:brick"}, {["x"] = 3, ["param2"] = 2, ["y"] = 2, ["param1"] = 171, ["z"] = 1, ["name"] = "stairs:stair_wood"}, {["x"] = 3, ["y"] = 2, ["param1"] = 171, ["z"] = 5, ["name"] = "stairs:stair_wood"}, {["x"] = 3, ["meta"] = {["fields"] = {}, ["inventory"] = {}}, ["y"] = 2, ["param1"] = 152, ["z"] = 6, ["name"] = "default:brick"}, {["x"] = 3, ["meta"] = {["fields"] = {}, ["inventory"] = {}}, ["y"] = 2, ["param1"] = 152, ["z"] = 24, ["name"] = "default:brick"}, {["x"] = 3, ["meta"] = {["fields"] = {["infotext"] = "\27(T@default)Empty Bookshelf\27E", ["formspec"] = "size[8,7;]list[context;books;0,0.3;8,2;]list[current_player;main;0,2.85;8,1;]list[current_player;main;0,4.08;8,3;8]listring[context;books]listring[current_player;main]image[0,2.85;1,1;gui_hb_bg.png]image[1,2.85;1,1;gui_hb_bg.png]image[2,2.85;1,1;gui_hb_bg.png]image[3,2.85;1,1;gui_hb_bg.png]image[4,2.85;1,1;gui_hb_bg.png]image[5,2.85;1,1;gui_hb_bg.png]image[6,2.85;1,1;gui_hb_bg.png]image[7,2.85;1,1;gui_hb_bg.png]image[0,0.3;1,1;default_bookshelf_slot.png]image[1,0.3;1,1;default_bookshelf_slot.png]image[2,0.3;1,1;default_bookshelf_slot.png]image[3,0.3;1,1;default_bookshelf_slot.png]image[4,0.3;1,1;default_bookshelf_slot.png]image[5,0.3;1,1;default_bookshelf_slot.png]image[6,0.3;1,1;default_bookshelf_slot.png]image[7,0.3;1,1;default_bookshelf_slot.png]image[0,1.3;1,1;default_bookshelf_slot.png]image[1,1.3;1,1;default_bookshelf_slot.png]image[2,1.3;1,1;default_bookshelf_slot.png]image[3,1.3;1,1;default_bookshelf_slot.png]image[4,1.3;1,1;default_bookshelf_slot.png]image[5,1.3;1,1;default_bookshelf_slot.png]image[6,1.3;1,1;default_bookshelf_slot.png]image[7,1.3;1,1;default_bookshelf_slot.png]"}, ["inventory"] = {["books"] = {"", "", "", "", "", "", "", "", "", "", "", "", "", "", "", ""}}}, ["param2"] = 1, ["y"] = 2, ["param1"] = 139, ["z"] = 25, ["name"] = "default:bookshelf"}, {["x"] = 3, ["meta"] = {["fields"] = {["infotext"] = "\27(T@default)Empty Bookshelf\27E", ["formspec"] = "size[8,7;]list[context;books;0,0.3;8,2;]list[current_player;main;0,2.85;8,1;]list[current_player;main;0,4.08;8,3;8]listring[context;books]listring[current_player;main]image[0,2.85;1,1;gui_hb_bg.png]image[1,2.85;1,1;gui_hb_bg.png]image[2,2.85;1,1;gui_hb_bg.png]image[3,2.85;1,1;gui_hb_bg.png]image[4,2.85;1,1;gui_hb_bg.png]image[5,2.85;1,1;gui_hb_bg.png]image[6,2.85;1,1;gui_hb_bg.png]image[7,2.85;1,1;gui_hb_bg.png]image[0,0.3;1,1;default_bookshelf_slot.png]image[1,0.3;1,1;default_bookshelf_slot.png]image[2,0.3;1,1;default_bookshelf_slot.png]image[3,0.3;1,1;default_bookshelf_slot.png]image[4,0.3;1,1;default_bookshelf_slot.png]image[5,0.3;1,1;default_bookshelf_slot.png]image[6,0.3;1,1;default_bookshelf_slot.png]image[7,0.3;1,1;default_bookshelf_slot.png]image[0,1.3;1,1;default_bookshelf_slot.png]image[1,1.3;1,1;default_bookshelf_slot.png]image[2,1.3;1,1;default_bookshelf_slot.png]image[3,1.3;1,1;default_bookshelf_slot.png]image[4,1.3;1,1;default_bookshelf_slot.png]image[5,1.3;1,1;default_bookshelf_slot.png]image[6,1.3;1,1;default_bookshelf_slot.png]image[7,1.3;1,1;default_bookshelf_slot.png]"}, ["inventory"] = {["books"] = {"", "", "", "", "", "", "", "", "", "", "", "", "", "", "", ""}}}, ["param2"] = 1, ["y"] = 2, ["param1"] = 122, ["z"] = 26, ["name"] = "default:bookshelf"}, {["x"] = 3, ["param2"] = 1, ["y"] = 2, ["param1"] = 139, ["z"] = 29, ["name"] = "stairs:stair_wood"}, {["x"] = 3, ["meta"] = {["fields"] = {}, ["inventory"] = {}}, ["y"] = 2, ["param1"] = 152, ["z"] = 30, ["name"] = "default:brick"}, {["x"] = 3, ["meta"] = {["fields"] = {}, ["inventory"] = {}}, ["y"] = 3, ["param1"] = 152, ["z"] = 0, ["name"] = "default:brick"}, {["x"] = 3, ["meta"] = {["fields"] = {}, ["inventory"] = {}}, ["y"] = 3, ["param1"] = 152, ["z"] = 6, ["name"] = "default:brick"}, {["x"] = 3, ["meta"] = {["fields"] = {}, ["inventory"] = {}}, ["y"] = 3, ["param1"] = 152, ["z"] = 24, ["name"] = "default:brick"}, {["x"] = 3, ["meta"] = {["fields"] = {["infotext"] = "\27(T@default)Empty Bookshelf\27E", ["formspec"] = "size[8,7;]list[context;books;0,0.3;8,2;]list[current_player;main;0,2.85;8,1;]list[current_player;main;0,4.08;8,3;8]listring[context;books]listring[current_player;main]image[0,2.85;1,1;gui_hb_bg.png]image[1,2.85;1,1;gui_hb_bg.png]image[2,2.85;1,1;gui_hb_bg.png]image[3,2.85;1,1;gui_hb_bg.png]image[4,2.85;1,1;gui_hb_bg.png]image[5,2.85;1,1;gui_hb_bg.png]image[6,2.85;1,1;gui_hb_bg.png]image[7,2.85;1,1;gui_hb_bg.png]image[0,0.3;1,1;default_bookshelf_slot.png]image[1,0.3;1,1;default_bookshelf_slot.png]image[2,0.3;1,1;default_bookshelf_slot.png]image[3,0.3;1,1;default_bookshelf_slot.png]image[4,0.3;1,1;default_bookshelf_slot.png]image[5,0.3;1,1;default_bookshelf_slot.png]image[6,0.3;1,1;default_bookshelf_slot.png]image[7,0.3;1,1;default_bookshelf_slot.png]image[0,1.3;1,1;default_bookshelf_slot.png]image[1,1.3;1,1;default_bookshelf_slot.png]image[2,1.3;1,1;default_bookshelf_slot.png]image[3,1.3;1,1;default_bookshelf_slot.png]image[4,1.3;1,1;default_bookshelf_slot.png]image[5,1.3;1,1;default_bookshelf_slot.png]image[6,1.3;1,1;default_bookshelf_slot.png]image[7,1.3;1,1;default_bookshelf_slot.png]"}, ["inventory"] = {["books"] = {"", "", "", "", "", "", "", "", "", "", "", "", "", "", "", ""}}}, ["param2"] = 1, ["y"] = 3, ["param1"] = 156, ["z"] = 25, ["name"] = "default:bookshelf"}, {["x"] = 3, ["meta"] = {["fields"] = {["infotext"] = "\27(T@default)Empty Bookshelf\27E", ["formspec"] = "size[8,7;]list[context;books;0,0.3;8,2;]list[current_player;main;0,2.85;8,1;]list[current_player;main;0,4.08;8,3;8]listring[context;books]listring[current_player;main]image[0,2.85;1,1;gui_hb_bg.png]image[1,2.85;1,1;gui_hb_bg.png]image[2,2.85;1,1;gui_hb_bg.png]image[3,2.85;1,1;gui_hb_bg.png]image[4,2.85;1,1;gui_hb_bg.png]image[5,2.85;1,1;gui_hb_bg.png]image[6,2.85;1,1;gui_hb_bg.png]image[7,2.85;1,1;gui_hb_bg.png]image[0,0.3;1,1;default_bookshelf_slot.png]image[1,0.3;1,1;default_bookshelf_slot.png]image[2,0.3;1,1;default_bookshelf_slot.png]image[3,0.3;1,1;default_bookshelf_slot.png]image[4,0.3;1,1;default_bookshelf_slot.png]image[5,0.3;1,1;default_bookshelf_slot.png]image[6,0.3;1,1;default_bookshelf_slot.png]image[7,0.3;1,1;default_bookshelf_slot.png]image[0,1.3;1,1;default_bookshelf_slot.png]image[1,1.3;1,1;default_bookshelf_slot.png]image[2,1.3;1,1;default_bookshelf_slot.png]image[3,1.3;1,1;default_bookshelf_slot.png]image[4,1.3;1,1;default_bookshelf_slot.png]image[5,1.3;1,1;default_bookshelf_slot.png]image[6,1.3;1,1;default_bookshelf_slot.png]image[7,1.3;1,1;default_bookshelf_slot.png]"}, ["inventory"] = {["books"] = {"", "", "", "", "", "", "", "", "", "", "", "", "", "", "", ""}}}, ["param2"] = 1, ["y"] = 3, ["param1"] = 139, ["z"] = 26, ["name"] = "default:bookshelf"}, {["x"] = 3, ["meta"] = {["fields"] = {}, ["inventory"] = {}}, ["y"] = 3, ["param1"] = 152, ["z"] = 30, ["name"] = "default:brick"}, {["x"] = 3, ["meta"] = {["fields"] = {}, ["inventory"] = {}}, ["y"] = 4, ["param1"] = 152, ["z"] = 0, ["name"] = "default:brick"}, {["x"] = 3, ["meta"] = {["fields"] = {}, ["inventory"] = {}}, ["y"] = 4, ["param1"] = 152, ["z"] = 6, ["name"] = "default:brick"}, {["x"] = 3, ["meta"] = {["fields"] = {}, ["inventory"] = {}}, ["y"] = 4, ["param1"] = 152, ["z"] = 24, ["name"] = "default:brick"}, {["x"] = 3, ["meta"] = {["fields"] = {}, ["inventory"] = {}}, ["y"] = 4, ["param1"] = 152, ["z"] = 30, ["name"] = "default:brick"}, {["x"] = 3, ["meta"] = {["fields"] = {}, ["inventory"] = {}}, ["y"] = 5, ["param1"] = 152, ["z"] = 0, ["name"] = "default:brick"}, {["x"] = 3, ["meta"] = {["fields"] = {}, ["inventory"] = {}}, ["y"] = 5, ["param1"] = 152, ["z"] = 6, ["name"] = "default:brick"}, {["x"] = 3, ["meta"] = {["fields"] = {}, ["inventory"] = {}}, ["y"] = 5, ["param1"] = 152, ["z"] = 24, ["name"] = "default:brick"}, {["x"] = 3, ["y"] = 5, ["z"] = 30, ["name"] = "default:brick"}, {["x"] = 3, ["meta"] = {["fields"] = {}, ["inventory"] = {}}, ["y"] = 6, ["param1"] = 152, ["z"] = 0, ["name"] = "default:brick"}, {["x"] = 3, ["y"] = 6, ["param1"] = 238, ["z"] = 1, ["name"] = "default:meselamp"}, {["x"] = 3, ["param2"] = 21, ["y"] = 6, ["param1"] = 221, ["z"] = 2, ["name"] = "stairs:slab_wood"}, {["x"] = 3, ["y"] = 6, ["param1"] = 238, ["z"] = 3, ["name"] = "default:meselamp"}, {["x"] = 3, ["param2"] = 20, ["y"] = 6, ["param1"] = 221, ["z"] = 4, ["name"] = "stairs:slab_wood"}, {["x"] = 3, ["y"] = 6, ["param1"] = 238, ["z"] = 5, ["name"] = "default:meselamp"}, {["x"] = 3, ["meta"] = {["fields"] = {}, ["inventory"] = {}}, ["y"] = 6, ["param1"] = 152, ["z"] = 6, ["name"] = "default:brick"}, {["x"] = 3, ["param2"] = 2, ["y"] = 6, ["param1"] = 142, ["z"] = 12, ["name"] = "stairs:slab_stone_block"}, {["x"] = 3, ["param2"] = 2, ["y"] = 6, ["param1"] = 158, ["z"] = 13, ["name"] = "stairs:slab_stone_block"}, {["x"] = 3, ["param2"] = 2, ["y"] = 6, ["param1"] = 142, ["z"] = 14, ["name"] = "stairs:slab_stone_block"}, {["x"] = 3, ["param2"] = 1, ["y"] = 6, ["param1"] = 126, ["z"] = 15, ["name"] = "stairs:slab_stone_block"}, {["x"] = 3, ["param2"] = 1, ["y"] = 6, ["param1"] = 142, ["z"] = 16, ["name"] = "stairs:slab_stone_block"}, {["x"] = 3, ["param2"] = 1, ["y"] = 6, ["param1"] = 158, ["z"] = 17, ["name"] = "stairs:slab_stone_block"}, {["x"] = 3, ["param2"] = 1, ["y"] = 6, ["param1"] = 142, ["z"] = 18, ["name"] = "stairs:slab_stone_block"}, {["x"] = 3, ["meta"] = {["fields"] = {}, ["inventory"] = {}}, ["y"] = 6, ["param1"] = 152, ["z"] = 24, ["name"] = "default:brick"}, {["x"] = 3, ["meta"] = {["fields"] = {}, ["inventory"] = {}}, ["y"] = 6, ["param1"] = 152, ["z"] = 30, ["name"] = "default:brick"}, {["x"] = 3, ["y"] = 7, ["z"] = 0, ["name"] = "default:stonebrick"}, {["x"] = 3, ["y"] = 7, ["param1"] = 10, ["z"] = 1, ["name"] = "default:stone_block"}, {["x"] = 3, ["y"] = 7, ["param1"] = 9, ["z"] = 2, ["name"] = "default:stone_block"}, {["x"] = 3, ["y"] = 7, ["param1"] = 8, ["z"] = 3, ["name"] = "default:stone_block"}, {["x"] = 3, ["y"] = 7, ["param1"] = 9, ["z"] = 4, ["name"] = "default:stone_block"}, {["x"] = 3, ["y"] = 7, ["param1"] = 10, ["z"] = 5, ["name"] = "default:stone_block"}, {["x"] = 3, ["y"] = 7, ["z"] = 6, ["name"] = "default:stonebrick"}, {["x"] = 3, ["y"] = 7, ["z"] = 24, ["name"] = "default:stonebrick"}, {["x"] = 3, ["y"] = 7, ["param1"] = 10, ["z"] = 25, ["name"] = "default:stone_block"}, {["x"] = 3, ["y"] = 7, ["param1"] = 9, ["z"] = 26, ["name"] = "default:stone_block"}, {["x"] = 3, ["y"] = 7, ["param1"] = 8, ["z"] = 27, ["name"] = "default:stone_block"}, {["x"] = 3, ["y"] = 7, ["param1"] = 9, ["z"] = 28, ["name"] = "default:stone_block"}, {["x"] = 3, ["y"] = 7, ["param1"] = 10, ["z"] = 29, ["name"] = "default:stone_block"}, {["x"] = 3, ["y"] = 7, ["z"] = 30, ["name"] = "default:stonebrick"}, {["x"] = 3, ["meta"] = {["fields"] = {}, ["inventory"] = {}}, ["y"] = 8, ["param1"] = 152, ["z"] = 0, ["name"] = "default:brick"}, {["x"] = 3, ["meta"] = {["fields"] = {}, ["inventory"] = {}}, ["y"] = 8, ["param1"] = 152, ["z"] = 6, ["name"] = "default:brick"}, {["x"] = 3, ["meta"] = {["fields"] = {}, ["inventory"] = {}}, ["y"] = 8, ["param1"] = 152, ["z"] = 24, ["name"] = "default:brick"}, {["x"] = 3, ["meta"] = {["fields"] = {}, ["inventory"] = {}}, ["y"] = 8, ["param1"] = 152, ["z"] = 30, ["name"] = "default:brick"}, {["x"] = 3, ["meta"] = {["fields"] = {}, ["inventory"] = {}}, ["y"] = 9, ["param1"] = 152, ["z"] = 0, ["name"] = "default:brick"}, {["x"] = 3, ["meta"] = {["fields"] = {}, ["inventory"] = {}}, ["y"] = 9, ["param1"] = 152, ["z"] = 6, ["name"] = "default:brick"}, {["x"] = 3, ["meta"] = {["fields"] = {}, ["inventory"] = {}}, ["y"] = 9, ["param1"] = 152, ["z"] = 24, ["name"] = "default:brick"}, {["x"] = 3, ["meta"] = {["fields"] = {}, ["inventory"] = {}}, ["y"] = 9, ["param1"] = 152, ["z"] = 30, ["name"] = "default:brick"}, {["x"] = 3, ["meta"] = {["fields"] = {}, ["inventory"] = {}}, ["y"] = 10, ["param1"] = 152, ["z"] = 0, ["name"] = "default:brick"}, {["x"] = 3, ["meta"] = {["fields"] = {}, ["inventory"] = {}}, ["y"] = 10, ["param1"] = 152, ["z"] = 6, ["name"] = "default:brick"}, {["x"] = 3, ["meta"] = {["fields"] = {}, ["inventory"] = {}}, ["y"] = 10, ["param1"] = 152, ["z"] = 24, ["name"] = "default:brick"}, {["x"] = 3, ["meta"] = {["fields"] = {}, ["inventory"] = {}}, ["y"] = 10, ["param1"] = 152, ["z"] = 30, ["name"] = "default:brick"}, {["x"] = 3, ["meta"] = {["fields"] = {}, ["inventory"] = {}}, ["y"] = 11, ["param1"] = 152, ["z"] = 0, ["name"] = "default:brick"}, {["x"] = 3, ["meta"] = {["fields"] = {}, ["inventory"] = {}}, ["y"] = 11, ["param1"] = 152, ["z"] = 6, ["name"] = "default:brick"}, {["x"] = 3, ["y"] = 11, ["z"] = 24, ["name"] = "default:brick"}, {["x"] = 3, ["meta"] = {["fields"] = {}, ["inventory"] = {}}, ["y"] = 11, ["param1"] = 152, ["z"] = 30, ["name"] = "default:brick"}, {["x"] = 3, ["meta"] = {["fields"] = {}, ["inventory"] = {}}, ["y"] = 12, ["param1"] = 152, ["z"] = 0, ["name"] = "default:brick"}, {["x"] = 3, ["meta"] = {["fields"] = {}, ["inventory"] = {}}, ["y"] = 12, ["param1"] = 152, ["z"] = 6, ["name"] = "default:brick"}, {["x"] = 3, ["meta"] = {["fields"] = {}, ["inventory"] = {}}, ["y"] = 12, ["param1"] = 152, ["z"] = 24, ["name"] = "default:brick"}, {["x"] = 3, ["meta"] = {["fields"] = {}, ["inventory"] = {}}, ["y"] = 12, ["param1"] = 152, ["z"] = 30, ["name"] = "default:brick"}, {["x"] = 3, ["y"] = 13, ["param1"] = 174, ["z"] = 0, ["name"] = "stairs:slab_stone_block"}, {["x"] = 3, ["y"] = 13, ["param1"] = 190, ["z"] = 1, ["name"] = "stairs:slab_stone_block"}, {["x"] = 3, ["y"] = 13, ["param1"] = 174, ["z"] = 2, ["name"] = "stairs:slab_stone_block"}, {["x"] = 3, ["y"] = 13, ["param1"] = 158, ["z"] = 3, ["name"] = "stairs:slab_stone_block"}, {["x"] = 3, ["y"] = 13, ["param1"] = 174, ["z"] = 4, ["name"] = "stairs:slab_stone_block"}, {["x"] = 3, ["y"] = 13, ["param1"] = 190, ["z"] = 5, ["name"] = "stairs:slab_stone_block"}, {["x"] = 3, ["y"] = 13, ["param1"] = 174, ["z"] = 6, ["name"] = "stairs:slab_stone_block"}, {["x"] = 3, ["y"] = 13, ["param1"] = 174, ["z"] = 24, ["name"] = "stairs:slab_stone_block"}, {["x"] = 3, ["y"] = 13, ["param1"] = 190, ["z"] = 25, ["name"] = "stairs:slab_stone_block"}, {["x"] = 3, ["y"] = 13, ["param1"] = 174, ["z"] = 26, ["name"] = "stairs:slab_stone_block"}, {["x"] = 3, ["y"] = 13, ["param1"] = 158, ["z"] = 27, ["name"] = "stairs:slab_stone_block"}, {["x"] = 3, ["y"] = 13, ["param1"] = 174, ["z"] = 28, ["name"] = "stairs:slab_stone_block"}, {["x"] = 3, ["y"] = 13, ["param1"] = 190, ["z"] = 29, ["name"] = "stairs:slab_stone_block"}, {["x"] = 3, ["y"] = 13, ["param1"] = 174, ["z"] = 30, ["name"] = "stairs:slab_stone_block"}, {["x"] = 4, ["meta"] = {["fields"] = {}, ["inventory"] = {}}, ["y"] = 0, ["param1"] = 8, ["z"] = 0, ["name"] = "default:stonebrick"}, {["x"] = 4, ["meta"] = {["fields"] = {}, ["inventory"] = {}}, ["y"] = 0, ["param1"] = 6, ["z"] = 1, ["name"] = "default:stone"}, {["x"] = 4, ["meta"] = {["fields"] = {}, ["inventory"] = {}}, ["y"] = 0, ["param1"] = 6, ["z"] = 2, ["name"] = "default:stone"}, {["x"] = 4, ["meta"] = {["fields"] = {}, ["inventory"] = {}}, ["y"] = 0, ["param1"] = 6, ["z"] = 3, ["name"] = "default:stone"}, {["x"] = 4, ["meta"] = {["fields"] = {}, ["inventory"] = {}}, ["y"] = 0, ["param1"] = 6, ["z"] = 4, ["name"] = "default:stone"}, {["x"] = 4, ["meta"] = {["fields"] = {}, ["inventory"] = {}}, ["y"] = 0, ["param1"] = 6, ["z"] = 5, ["name"] = "default:stone"}, {["x"] = 4, ["meta"] = {["fields"] = {}, ["inventory"] = {}}, ["y"] = 0, ["param1"] = 8, ["z"] = 6, ["name"] = "default:stonebrick"}, {["x"] = 4, ["meta"] = {["fields"] = {}, ["inventory"] = {}}, ["y"] = 0, ["param1"] = 6, ["z"] = 7, ["name"] = "default:stone"}, {["x"] = 4, ["meta"] = {["fields"] = {}, ["inventory"] = {}}, ["y"] = 0, ["param1"] = 6, ["z"] = 8, ["name"] = "default:stone"}, {["x"] = 4, ["meta"] = {["fields"] = {}, ["inventory"] = {}}, ["y"] = 0, ["param1"] = 6, ["z"] = 9, ["name"] = "default:stone"}, {["x"] = 4, ["meta"] = {["fields"] = {}, ["inventory"] = {}}, ["y"] = 0, ["param1"] = 6, ["z"] = 10, ["name"] = "default:stone"}, {["x"] = 4, ["meta"] = {["fields"] = {}, ["inventory"] = {}}, ["y"] = 0, ["param1"] = 6, ["z"] = 11, ["name"] = "default:stone"}, {["x"] = 4, ["meta"] = {["fields"] = {}, ["inventory"] = {}}, ["y"] = 0, ["param1"] = 6, ["z"] = 12, ["name"] = "default:stone"}, {["x"] = 4, ["meta"] = {["fields"] = {}, ["inventory"] = {}}, ["y"] = 0, ["param1"] = 6, ["z"] = 13, ["name"] = "default:stone"}, {["x"] = 4, ["meta"] = {["fields"] = {}, ["inventory"] = {}}, ["y"] = 0, ["param1"] = 6, ["z"] = 14, ["name"] = "default:stone"}, {["x"] = 4, ["meta"] = {["fields"] = {}, ["inventory"] = {}}, ["y"] = 0, ["param1"] = 6, ["z"] = 15, ["name"] = "default:stone"}, {["x"] = 4, ["meta"] = {["fields"] = {}, ["inventory"] = {}}, ["y"] = 0, ["param1"] = 6, ["z"] = 16, ["name"] = "default:stone"}, {["x"] = 4, ["meta"] = {["fields"] = {}, ["inventory"] = {}}, ["y"] = 0, ["param1"] = 6, ["z"] = 17, ["name"] = "default:stone"}, {["x"] = 4, ["meta"] = {["fields"] = {}, ["inventory"] = {}}, ["y"] = 0, ["param1"] = 6, ["z"] = 18, ["name"] = "default:stone"}, {["x"] = 4, ["meta"] = {["fields"] = {}, ["inventory"] = {}}, ["y"] = 0, ["param1"] = 6, ["z"] = 19, ["name"] = "default:stone"}, {["x"] = 4, ["meta"] = {["fields"] = {}, ["inventory"] = {}}, ["y"] = 0, ["param1"] = 6, ["z"] = 20, ["name"] = "default:stone"}, {["x"] = 4, ["meta"] = {["fields"] = {}, ["inventory"] = {}}, ["y"] = 0, ["param1"] = 6, ["z"] = 21, ["name"] = "default:stone"}, {["x"] = 4, ["meta"] = {["fields"] = {}, ["inventory"] = {}}, ["y"] = 0, ["param1"] = 6, ["z"] = 22, ["name"] = "default:stone"}, {["x"] = 4, ["meta"] = {["fields"] = {}, ["inventory"] = {}}, ["y"] = 0, ["param1"] = 6, ["z"] = 23, ["name"] = "default:stone"}, {["x"] = 4, ["meta"] = {["fields"] = {}, ["inventory"] = {}}, ["y"] = 0, ["param1"] = 8, ["z"] = 24, ["name"] = "default:stonebrick"}, {["x"] = 4, ["meta"] = {["fields"] = {}, ["inventory"] = {}}, ["y"] = 0, ["param1"] = 6, ["z"] = 25, ["name"] = "default:stone"}, {["x"] = 4, ["meta"] = {["fields"] = {}, ["inventory"] = {}}, ["y"] = 0, ["param1"] = 6, ["z"] = 26, ["name"] = "default:stone"}, {["x"] = 4, ["meta"] = {["fields"] = {}, ["inventory"] = {}}, ["y"] = 0, ["param1"] = 6, ["z"] = 27, ["name"] = "default:stone"}, {["x"] = 4, ["meta"] = {["fields"] = {}, ["inventory"] = {}}, ["y"] = 0, ["param1"] = 6, ["z"] = 28, ["name"] = "default:stone"}, {["x"] = 4, ["meta"] = {["fields"] = {}, ["inventory"] = {}}, ["y"] = 0, ["param1"] = 6, ["z"] = 29, ["name"] = "default:stone"}, {["x"] = 4, ["meta"] = {["fields"] = {}, ["inventory"] = {}}, ["y"] = 0, ["param1"] = 8, ["z"] = 30, ["name"] = "default:stonebrick"}, {["x"] = 4, ["meta"] = {["fields"] = {}, ["inventory"] = {}}, ["y"] = 1, ["param1"] = 8, ["z"] = 0, ["name"] = "default:stonebrick"}, {["x"] = 4, ["meta"] = {["fields"] = {}, ["inventory"] = {}}, ["y"] = 1, ["param1"] = 9, ["z"] = 1, ["name"] = "default:stone_block"}, {["x"] = 4, ["meta"] = {["fields"] = {}, ["inventory"] = {}}, ["y"] = 1, ["param1"] = 9, ["z"] = 2, ["name"] = "default:stone_block"}, {["x"] = 4, ["meta"] = {["fields"] = {}, ["inventory"] = {}}, ["y"] = 1, ["param1"] = 9, ["z"] = 3, ["name"] = "default:stone_block"}, {["x"] = 4, ["meta"] = {["fields"] = {}, ["inventory"] = {}}, ["y"] = 1, ["param1"] = 9, ["z"] = 4, ["name"] = "default:stone_block"}, {["x"] = 4, ["meta"] = {["fields"] = {}, ["inventory"] = {}}, ["y"] = 1, ["param1"] = 9, ["z"] = 5, ["name"] = "default:stone_block"}, {["x"] = 4, ["meta"] = {["fields"] = {}, ["inventory"] = {}}, ["y"] = 1, ["param1"] = 8, ["z"] = 6, ["name"] = "default:stonebrick"}, {["x"] = 4, ["y"] = 1, ["param1"] = 94, ["z"] = 11, ["name"] = "stairs:stair_stone_block"}, {["x"] = 4, ["y"] = 1, ["z"] = 12, ["name"] = "default:stone_block"}, {["x"] = 4, ["y"] = 1, ["z"] = 13, ["name"] = "default:stone_block"}, {["x"] = 4, ["y"] = 1, ["z"] = 14, ["name"] = "default:stone_block"}, {["x"] = 4, ["y"] = 1, ["z"] = 15, ["name"] = "default:stone_block"}, {["x"] = 4, ["y"] = 1, ["z"] = 16, ["name"] = "default:stone_block"}, {["x"] = 4, ["y"] = 1, ["z"] = 17, ["name"] = "default:stone_block"}, {["x"] = 4, ["y"] = 1, ["z"] = 18, ["name"] = "default:stone_block"}, {["x"] = 4, ["param2"] = 2, ["y"] = 1, ["param1"] = 94, ["z"] = 19, ["name"] = "stairs:stair_stone_block"}, {["x"] = 4, ["meta"] = {["fields"] = {}, ["inventory"] = {}}, ["y"] = 1, ["param1"] = 8, ["z"] = 24, ["name"] = "default:stonebrick"}, {["x"] = 4, ["meta"] = {["fields"] = {}, ["inventory"] = {}}, ["y"] = 1, ["param1"] = 9, ["z"] = 25, ["name"] = "default:stone_block"}, {["x"] = 4, ["meta"] = {["fields"] = {}, ["inventory"] = {}}, ["y"] = 1, ["param1"] = 9, ["z"] = 26, ["name"] = "default:stone_block"}, {["x"] = 4, ["meta"] = {["fields"] = {}, ["inventory"] = {}}, ["y"] = 1, ["param1"] = 9, ["z"] = 27, ["name"] = "default:stone_block"}, {["x"] = 4, ["meta"] = {["fields"] = {}, ["inventory"] = {}}, ["y"] = 1, ["param1"] = 9, ["z"] = 28, ["name"] = "default:stone_block"}, {["x"] = 4, ["meta"] = {["fields"] = {}, ["inventory"] = {}}, ["y"] = 1, ["param1"] = 9, ["z"] = 29, ["name"] = "default:stone_block"}, {["x"] = 4, ["meta"] = {["fields"] = {}, ["inventory"] = {}}, ["y"] = 1, ["param1"] = 8, ["z"] = 30, ["name"] = "default:stonebrick"}, {["x"] = 4, ["meta"] = {["fields"] = {}, ["inventory"] = {}}, ["y"] = 2, ["param1"] = 152, ["z"] = 0, ["name"] = "default:brick"}, {["x"] = 4, ["param2"] = 3, ["y"] = 2, ["param1"] = 156, ["z"] = 1, ["name"] = "stairs:stair_inner_wood"}, {["x"] = 4, ["param2"] = 3, ["y"] = 2, ["param1"] = 139, ["z"] = 2, ["name"] = "stairs:stair_wood"}, {["x"] = 4, ["param2"] = 3, ["y"] = 2, ["param1"] = 139, ["z"] = 4, ["name"] = "stairs:stair_wood"}, {["x"] = 4, ["y"] = 2, ["param1"] = 156, ["z"] = 5, ["name"] = "stairs:stair_inner_wood"}, {["x"] = 4, ["meta"] = {["fields"] = {}, ["inventory"] = {}}, ["y"] = 2, ["param1"] = 152, ["z"] = 6, ["name"] = "default:brick"}, {["x"] = 4, ["meta"] = {["fields"] = {}, ["inventory"] = {}}, ["y"] = 2, ["param1"] = 152, ["z"] = 24, ["name"] = "default:brick"}, {["x"] = 4, ["param2"] = 2, ["y"] = 2, ["param1"] = 124, ["z"] = 25, ["name"] = "stairs:stair_wood"}, {["x"] = 4, ["y"] = 2, ["param1"] = 107, ["z"] = 26, ["name"] = "default:fence_wood"}, {["x"] = 4, ["meta"] = {["fields"] = {}, ["inventory"] = {}}, ["y"] = 2, ["param1"] = 152, ["z"] = 30, ["name"] = "default:brick"}, {["x"] = 4, ["y"] = 3, ["param1"] = 158, ["z"] = 0, ["name"] = "default:glass"}, {["x"] = 4, ["y"] = 3, ["param1"] = 158, ["z"] = 6, ["name"] = "default:glass"}, {["x"] = 4, ["y"] = 3, ["param1"] = 126, ["z"] = 24, ["name"] = "default:glass"}, {["x"] = 4, ["param2"] = 2, ["y"] = 3, ["param1"] = 124, ["z"] = 26, ["name"] = "stairs:slab_wood"}, {["x"] = 4, ["y"] = 3, ["param1"] = 126, ["z"] = 30, ["name"] = "default:glass"}, {["x"] = 4, ["y"] = 4, ["param1"] = 174, ["z"] = 0, ["name"] = "default:glass"}, {["x"] = 4, ["y"] = 4, ["param1"] = 174, ["z"] = 6, ["name"] = "default:glass"}, {["x"] = 4, ["y"] = 4, ["param1"] = 142, ["z"] = 24, ["name"] = "default:glass"}, {["x"] = 4, ["y"] = 4, ["param1"] = 142, ["z"] = 30, ["name"] = "default:glass"}, {["x"] = 4, ["y"] = 5, ["param1"] = 190, ["z"] = 0, ["name"] = "default:glass"}, {["x"] = 4, ["y"] = 5, ["param1"] = 190, ["z"] = 6, ["name"] = "default:glass"}, {["x"] = 4, ["y"] = 5, ["param1"] = 158, ["z"] = 24, ["name"] = "default:glass"}, {["x"] = 4, ["y"] = 5, ["param1"] = 158, ["z"] = 30, ["name"] = "default:glass"}, {["x"] = 4, ["meta"] = {["fields"] = {}, ["inventory"] = {}}, ["y"] = 6, ["param1"] = 152, ["z"] = 0, ["name"] = "default:brick"}, {["x"] = 4, ["param2"] = 21, ["y"] = 6, ["param1"] = 221, ["z"] = 1, ["name"] = "stairs:slab_wood"}, {["x"] = 4, ["param2"] = 22, ["y"] = 6, ["param1"] = 204, ["z"] = 2, ["name"] = "stairs:slab_wood"}, {["x"] = 4, ["param2"] = 21, ["y"] = 6, ["param1"] = 221, ["z"] = 3, ["name"] = "stairs:slab_wood"}, {["x"] = 4, ["param2"] = 21, ["y"] = 6, ["param1"] = 204, ["z"] = 4, ["name"] = "stairs:slab_wood"}, {["x"] = 4, ["param2"] = 20, ["y"] = 6, ["param1"] = 221, ["z"] = 5, ["name"] = "stairs:slab_wood"}, {["x"] = 4, ["meta"] = {["fields"] = {}, ["inventory"] = {}}, ["y"] = 6, ["param1"] = 152, ["z"] = 6, ["name"] = "default:brick"}, {["x"] = 4, ["param2"] = 2, ["y"] = 6, ["param1"] = 158, ["z"] = 12, ["name"] = "stairs:slab_stone_block"}, {["x"] = 4, ["param2"] = 1, ["y"] = 6, ["param1"] = 174, ["z"] = 13, ["name"] = "stairs:slab_stone_block"}, {["x"] = 4, ["param2"] = 1, ["y"] = 6, ["param1"] = 158, ["z"] = 14, ["name"] = "stairs:slab_stone_block"}, {["x"] = 4, ["param2"] = 1, ["y"] = 6, ["param1"] = 142, ["z"] = 15, ["name"] = "stairs:slab_stone_block"}, {["x"] = 4, ["param2"] = 1, ["y"] = 6, ["param1"] = 158, ["z"] = 16, ["name"] = "stairs:slab_stone_block"}, {["x"] = 4, ["param2"] = 1, ["y"] = 6, ["param1"] = 174, ["z"] = 17, ["name"] = "stairs:slab_stone_block"}, {["x"] = 4, ["param2"] = 1, ["y"] = 6, ["param1"] = 158, ["z"] = 18, ["name"] = "stairs:slab_stone_block"}, {["x"] = 4, ["meta"] = {["fields"] = {}, ["inventory"] = {}}, ["y"] = 6, ["param1"] = 152, ["z"] = 24, ["name"] = "default:brick"}, {["x"] = 4, ["meta"] = {["fields"] = {}, ["inventory"] = {}}, ["y"] = 6, ["param1"] = 152, ["z"] = 30, ["name"] = "default:brick"}, {["x"] = 4, ["y"] = 7, ["z"] = 0, ["name"] = "default:stonebrick"}, {["x"] = 4, ["y"] = 7, ["param1"] = 11, ["z"] = 1, ["name"] = "default:stone_block"}, {["x"] = 4, ["y"] = 7, ["param1"] = 10, ["z"] = 2, ["name"] = "default:stone_block"}, {["x"] = 4, ["y"] = 7, ["param1"] = 9, ["z"] = 3, ["name"] = "default:stone_block"}, {["x"] = 4, ["y"] = 7, ["param1"] = 10, ["z"] = 4, ["name"] = "default:stone_block"}, {["x"] = 4, ["y"] = 7, ["param1"] = 11, ["z"] = 5, ["name"] = "default:stone_block"}, {["x"] = 4, ["y"] = 7, ["z"] = 6, ["name"] = "default:stonebrick"}, {["x"] = 4, ["y"] = 7, ["z"] = 24, ["name"] = "default:stonebrick"}, {["x"] = 4, ["y"] = 7, ["param1"] = 11, ["z"] = 25, ["name"] = "default:stone_block"}, {["x"] = 4, ["y"] = 7, ["param1"] = 10, ["z"] = 26, ["name"] = "default:stone_block"}, {["x"] = 4, ["y"] = 7, ["param1"] = 9, ["z"] = 27, ["name"] = "default:stone_block"}, {["x"] = 4, ["y"] = 7, ["param1"] = 10, ["z"] = 28, ["name"] = "default:stone_block"}, {["x"] = 4, ["y"] = 7, ["param1"] = 11, ["z"] = 29, ["name"] = "default:stone_block"}, {["x"] = 4, ["y"] = 7, ["z"] = 30, ["name"] = "default:stonebrick"}, {["x"] = 4, ["meta"] = {["fields"] = {}, ["inventory"] = {}}, ["y"] = 8, ["param1"] = 152, ["z"] = 0, ["name"] = "default:brick"}, {["x"] = 4, ["param2"] = 3, ["y"] = 8, ["param1"] = 124, ["z"] = 1, ["name"] = "stairs:stair_wood"}, {["x"] = 4, ["param2"] = 3, ["y"] = 8, ["param1"] = 90, ["z"] = 3, ["name"] = "stairs:stair_wood"}, {["x"] = 4, ["param2"] = 3, ["y"] = 8, ["param1"] = 124, ["z"] = 5, ["name"] = "stairs:stair_wood"}, {["x"] = 4, ["meta"] = {["fields"] = {}, ["inventory"] = {}}, ["y"] = 8, ["param1"] = 152, ["z"] = 6, ["name"] = "default:brick"}, {["x"] = 4, ["meta"] = {["fields"] = {}, ["inventory"] = {}}, ["y"] = 8, ["param1"] = 152, ["z"] = 24, ["name"] = "default:brick"}, {["x"] = 4, ["param2"] = 3, ["y"] = 8, ["param1"] = 124, ["z"] = 25, ["name"] = "stairs:stair_wood"}, {["x"] = 4, ["param2"] = 3, ["y"] = 8, ["param1"] = 90, ["z"] = 27, ["name"] = "stairs:stair_wood"}, {["x"] = 4, ["param2"] = 3, ["y"] = 8, ["param1"] = 124, ["z"] = 29, ["name"] = "stairs:stair_wood"}, {["x"] = 4, ["meta"] = {["fields"] = {}, ["inventory"] = {}}, ["y"] = 8, ["param1"] = 152, ["z"] = 30, ["name"] = "default:brick"}, {["x"] = 4, ["y"] = 9, ["param1"] = 126, ["z"] = 0, ["name"] = "default:glass"}, {["x"] = 4, ["y"] = 9, ["param1"] = 126, ["z"] = 6, ["name"] = "default:glass"}, {["x"] = 4, ["y"] = 9, ["param1"] = 126, ["z"] = 24, ["name"] = "default:glass"}, {["x"] = 4, ["y"] = 9, ["param1"] = 126, ["z"] = 30, ["name"] = "default:glass"}, {["x"] = 4, ["y"] = 10, ["param1"] = 142, ["z"] = 0, ["name"] = "default:glass"}, {["x"] = 4, ["y"] = 10, ["param1"] = 142, ["z"] = 6, ["name"] = "default:glass"}, {["x"] = 4, ["y"] = 10, ["param1"] = 142, ["z"] = 24, ["name"] = "default:glass"}, {["x"] = 4, ["y"] = 10, ["param1"] = 142, ["z"] = 30, ["name"] = "default:glass"}, {["x"] = 4, ["y"] = 11, ["param1"] = 158, ["z"] = 0, ["name"] = "default:glass"}, {["x"] = 4, ["y"] = 11, ["param1"] = 158, ["z"] = 6, ["name"] = "default:glass"}, {["x"] = 4, ["y"] = 11, ["param1"] = 158, ["z"] = 24, ["name"] = "default:glass"}, {["x"] = 4, ["y"] = 11, ["param1"] = 158, ["z"] = 30, ["name"] = "default:glass"}, {["x"] = 4, ["meta"] = {["fields"] = {}, ["inventory"] = {}}, ["y"] = 12, ["param1"] = 152, ["z"] = 0, ["name"] = "default:brick"}, {["x"] = 4, ["meta"] = {["fields"] = {}, ["inventory"] = {}}, ["y"] = 12, ["param1"] = 152, ["z"] = 6, ["name"] = "default:brick"}, {["x"] = 4, ["meta"] = {["fields"] = {}, ["inventory"] = {}}, ["y"] = 12, ["param1"] = 152, ["z"] = 24, ["name"] = "default:brick"}, {["x"] = 4, ["y"] = 12, ["z"] = 30, ["name"] = "default:brick"}, {["x"] = 4, ["y"] = 13, ["param1"] = 158, ["z"] = 0, ["name"] = "stairs:slab_stone_block"}, {["x"] = 4, ["y"] = 13, ["param1"] = 174, ["z"] = 1, ["name"] = "stairs:slab_stone_block"}, {["x"] = 4, ["y"] = 13, ["param1"] = 158, ["z"] = 2, ["name"] = "stairs:slab_stone_block"}, {["x"] = 4, ["y"] = 13, ["param1"] = 142, ["z"] = 3, ["name"] = "stairs:slab_stone_block"}, {["x"] = 4, ["y"] = 13, ["param1"] = 158, ["z"] = 4, ["name"] = "stairs:slab_stone_block"}, {["x"] = 4, ["y"] = 13, ["param1"] = 174, ["z"] = 5, ["name"] = "stairs:slab_stone_block"}, {["x"] = 4, ["y"] = 13, ["param1"] = 158, ["z"] = 6, ["name"] = "stairs:slab_stone_block"}, {["x"] = 4, ["y"] = 13, ["param1"] = 158, ["z"] = 24, ["name"] = "stairs:slab_stone_block"}, {["x"] = 4, ["y"] = 13, ["param1"] = 174, ["z"] = 25, ["name"] = "stairs:slab_stone_block"}, {["x"] = 4, ["y"] = 13, ["param1"] = 158, ["z"] = 26, ["name"] = "stairs:slab_stone_block"}, {["x"] = 4, ["y"] = 13, ["param1"] = 142, ["z"] = 27, ["name"] = "stairs:slab_stone_block"}, {["x"] = 4, ["y"] = 13, ["param1"] = 158, ["z"] = 28, ["name"] = "stairs:slab_stone_block"}, {["x"] = 4, ["y"] = 13, ["param1"] = 174, ["z"] = 29, ["name"] = "stairs:slab_stone_block"}, {["x"] = 4, ["y"] = 13, ["param1"] = 158, ["z"] = 30, ["name"] = "stairs:slab_stone_block"}, {["x"] = 5, ["meta"] = {["fields"] = {}, ["inventory"] = {}}, ["y"] = 0, ["param1"] = 8, ["z"] = 0, ["name"] = "default:stonebrick"}, {["x"] = 5, ["meta"] = {["fields"] = {}, ["inventory"] = {}}, ["y"] = 0, ["param1"] = 6, ["z"] = 1, ["name"] = "default:stone"}, {["x"] = 5, ["meta"] = {["fields"] = {}, ["inventory"] = {}}, ["y"] = 0, ["param1"] = 6, ["z"] = 2, ["name"] = "default:stone"}, {["x"] = 5, ["meta"] = {["fields"] = {}, ["inventory"] = {}}, ["y"] = 0, ["param1"] = 6, ["z"] = 3, ["name"] = "default:stone"}, {["x"] = 5, ["meta"] = {["fields"] = {}, ["inventory"] = {}}, ["y"] = 0, ["param1"] = 6, ["z"] = 4, ["name"] = "default:stone"}, {["x"] = 5, ["meta"] = {["fields"] = {}, ["inventory"] = {}}, ["y"] = 0, ["param1"] = 6, ["z"] = 5, ["name"] = "default:stone"}, {["x"] = 5, ["meta"] = {["fields"] = {}, ["inventory"] = {}}, ["y"] = 0, ["param1"] = 8, ["z"] = 6, ["name"] = "default:stonebrick"}, {["x"] = 5, ["meta"] = {["fields"] = {}, ["inventory"] = {}}, ["y"] = 0, ["param1"] = 6, ["z"] = 7, ["name"] = "default:stone"}, {["x"] = 5, ["meta"] = {["fields"] = {}, ["inventory"] = {}}, ["y"] = 0, ["param1"] = 6, ["z"] = 8, ["name"] = "default:stone"}, {["x"] = 5, ["meta"] = {["fields"] = {}, ["inventory"] = {}}, ["y"] = 0, ["param1"] = 6, ["z"] = 9, ["name"] = "default:stone"}, {["x"] = 5, ["meta"] = {["fields"] = {}, ["inventory"] = {}}, ["y"] = 0, ["param1"] = 6, ["z"] = 10, ["name"] = "default:stone"}, {["x"] = 5, ["meta"] = {["fields"] = {}, ["inventory"] = {}}, ["y"] = 0, ["param1"] = 6, ["z"] = 11, ["name"] = "default:stone"}, {["x"] = 5, ["meta"] = {["fields"] = {}, ["inventory"] = {}}, ["y"] = 0, ["param1"] = 6, ["z"] = 12, ["name"] = "default:stone"}, {["x"] = 5, ["meta"] = {["fields"] = {}, ["inventory"] = {}}, ["y"] = 0, ["param1"] = 6, ["z"] = 13, ["name"] = "default:stone"}, {["x"] = 5, ["meta"] = {["fields"] = {}, ["inventory"] = {}}, ["y"] = 0, ["param1"] = 6, ["z"] = 14, ["name"] = "default:stone"}, {["x"] = 5, ["meta"] = {["fields"] = {}, ["inventory"] = {}}, ["y"] = 0, ["param1"] = 6, ["z"] = 15, ["name"] = "default:stone"}, {["x"] = 5, ["meta"] = {["fields"] = {}, ["inventory"] = {}}, ["y"] = 0, ["param1"] = 6, ["z"] = 16, ["name"] = "default:stone"}, {["x"] = 5, ["meta"] = {["fields"] = {}, ["inventory"] = {}}, ["y"] = 0, ["param1"] = 6, ["z"] = 17, ["name"] = "default:stone"}, {["x"] = 5, ["meta"] = {["fields"] = {}, ["inventory"] = {}}, ["y"] = 0, ["param1"] = 6, ["z"] = 18, ["name"] = "default:stone"}, {["x"] = 5, ["meta"] = {["fields"] = {}, ["inventory"] = {}}, ["y"] = 0, ["param1"] = 6, ["z"] = 19, ["name"] = "default:stone"}, {["x"] = 5, ["meta"] = {["fields"] = {}, ["inventory"] = {}}, ["y"] = 0, ["param1"] = 6, ["z"] = 20, ["name"] = "default:stone"}, {["x"] = 5, ["meta"] = {["fields"] = {}, ["inventory"] = {}}, ["y"] = 0, ["param1"] = 6, ["z"] = 21, ["name"] = "default:stone"}, {["x"] = 5, ["meta"] = {["fields"] = {}, ["inventory"] = {}}, ["y"] = 0, ["param1"] = 6, ["z"] = 22, ["name"] = "default:stone"}, {["x"] = 5, ["meta"] = {["fields"] = {}, ["inventory"] = {}}, ["y"] = 0, ["param1"] = 6, ["z"] = 23, ["name"] = "default:stone"}, {["x"] = 5, ["meta"] = {["fields"] = {}, ["inventory"] = {}}, ["y"] = 0, ["param1"] = 8, ["z"] = 24, ["name"] = "default:stonebrick"}, {["x"] = 5, ["meta"] = {["fields"] = {}, ["inventory"] = {}}, ["y"] = 0, ["param1"] = 6, ["z"] = 25, ["name"] = "default:stone"}, {["x"] = 5, ["meta"] = {["fields"] = {}, ["inventory"] = {}}, ["y"] = 0, ["param1"] = 6, ["z"] = 26, ["name"] = "default:stone"}, {["x"] = 5, ["meta"] = {["fields"] = {}, ["inventory"] = {}}, ["y"] = 0, ["param1"] = 6, ["z"] = 27, ["name"] = "default:stone"}, {["x"] = 5, ["meta"] = {["fields"] = {}, ["inventory"] = {}}, ["y"] = 0, ["param1"] = 6, ["z"] = 28, ["name"] = "default:stone"}, {["x"] = 5, ["meta"] = {["fields"] = {}, ["inventory"] = {}}, ["y"] = 0, ["param1"] = 6, ["z"] = 29, ["name"] = "default:stone"}, {["x"] = 5, ["meta"] = {["fields"] = {}, ["inventory"] = {}}, ["y"] = 0, ["param1"] = 8, ["z"] = 30, ["name"] = "default:stonebrick"}, {["x"] = 5, ["meta"] = {["fields"] = {}, ["inventory"] = {}}, ["y"] = 1, ["param1"] = 8, ["z"] = 0, ["name"] = "default:stonebrick"}, {["x"] = 5, ["meta"] = {["fields"] = {}, ["inventory"] = {}}, ["y"] = 1, ["param1"] = 9, ["z"] = 1, ["name"] = "default:stone_block"}, {["x"] = 5, ["meta"] = {["fields"] = {}, ["inventory"] = {}}, ["y"] = 1, ["param1"] = 9, ["z"] = 2, ["name"] = "default:stone_block"}, {["x"] = 5, ["meta"] = {["fields"] = {}, ["inventory"] = {}}, ["y"] = 1, ["param1"] = 9, ["z"] = 3, ["name"] = "default:stone_block"}, {["x"] = 5, ["meta"] = {["fields"] = {}, ["inventory"] = {}}, ["y"] = 1, ["param1"] = 9, ["z"] = 4, ["name"] = "default:stone_block"}, {["x"] = 5, ["meta"] = {["fields"] = {}, ["inventory"] = {}}, ["y"] = 1, ["param1"] = 9, ["z"] = 5, ["name"] = "default:stone_block"}, {["x"] = 5, ["meta"] = {["fields"] = {}, ["inventory"] = {}}, ["y"] = 1, ["param1"] = 8, ["z"] = 6, ["name"] = "default:stonebrick"}, {["x"] = 5, ["y"] = 1, ["param1"] = 78, ["z"] = 11, ["name"] = "stairs:stair_stone_block"}, {["x"] = 5, ["y"] = 1, ["z"] = 12, ["name"] = "default:stonebrick"}, {["x"] = 5, ["y"] = 1, ["z"] = 13, ["name"] = "default:stonebrick"}, {["x"] = 5, ["y"] = 1, ["z"] = 14, ["name"] = "default:stonebrick"}, {["x"] = 5, ["y"] = 1, ["z"] = 15, ["name"] = "default:stonebrick"}, {["x"] = 5, ["y"] = 1, ["z"] = 16, ["name"] = "default:stonebrick"}, {["x"] = 5, ["y"] = 1, ["z"] = 17, ["name"] = "default:stonebrick"}, {["x"] = 5, ["y"] = 1, ["z"] = 18, ["name"] = "default:stonebrick"}, {["x"] = 5, ["param2"] = 2, ["y"] = 1, ["param1"] = 78, ["z"] = 19, ["name"] = "stairs:stair_stone_block"}, {["x"] = 5, ["meta"] = {["fields"] = {}, ["inventory"] = {}}, ["y"] = 1, ["param1"] = 8, ["z"] = 24, ["name"] = "default:stonebrick"}, {["x"] = 5, ["meta"] = {["fields"] = {}, ["inventory"] = {}}, ["y"] = 1, ["param1"] = 9, ["z"] = 25, ["name"] = "default:stone_block"}, {["x"] = 5, ["meta"] = {["fields"] = {}, ["inventory"] = {}}, ["y"] = 1, ["param1"] = 9, ["z"] = 26, ["name"] = "default:stone_block"}, {["x"] = 5, ["meta"] = {["fields"] = {}, ["inventory"] = {}}, ["y"] = 1, ["param1"] = 9, ["z"] = 27, ["name"] = "default:stone_block"}, {["x"] = 5, ["meta"] = {["fields"] = {}, ["inventory"] = {}}, ["y"] = 1, ["param1"] = 9, ["z"] = 28, ["name"] = "default:stone_block"}, {["x"] = 5, ["meta"] = {["fields"] = {}, ["inventory"] = {}}, ["y"] = 1, ["param1"] = 9, ["z"] = 29, ["name"] = "default:stone_block"}, {["x"] = 5, ["meta"] = {["fields"] = {}, ["inventory"] = {}}, ["y"] = 1, ["param1"] = 8, ["z"] = 30, ["name"] = "default:stonebrick"}, {["x"] = 5, ["meta"] = {["fields"] = {}, ["inventory"] = {}}, ["y"] = 2, ["param1"] = 152, ["z"] = 0, ["name"] = "default:brick"}, {["x"] = 5, ["param2"] = 2, ["y"] = 2, ["param1"] = 156, ["z"] = 1, ["name"] = "stairs:stair_wood"}, {["x"] = 5, ["y"] = 2, ["param1"] = 139, ["z"] = 2, ["name"] = "default:fence_wood"}, {["x"] = 5, ["y"] = 2, ["param1"] = 139, ["z"] = 4, ["name"] = "default:fence_wood"}, {["x"] = 5, ["y"] = 2, ["param1"] = 156, ["z"] = 5, ["name"] = "stairs:stair_wood"}, {["x"] = 5, ["meta"] = {["fields"] = {}, ["inventory"] = {}}, ["y"] = 2, ["param1"] = 152, ["z"] = 6, ["name"] = "default:brick"}, {["x"] = 5, ["y"] = 2, ["z"] = 12, ["name"] = "default:brick"}, {["x"] = 5, ["meta"] = {["fields"] = {["state"] = "2"}, ["inventory"] = {}}, ["param2"] = 1, ["y"] = 2, ["param1"] = 156, ["z"] = 13, ["name"] = "doors:door_wood_b"}, {["x"] = 5, ["meta"] = {["fields"] = {["state"] = "0"}, ["inventory"] = {}}, ["param2"] = 1, ["y"] = 2, ["param1"] = 139, ["z"] = 14, ["name"] = "doors:door_wood_a"}, {["x"] = 5, ["y"] = 2, ["z"] = 15, ["name"] = "default:brick"}, {["x"] = 5, ["meta"] = {["fields"] = {["state"] = "2"}, ["inventory"] = {}}, ["param2"] = 1, ["y"] = 2, ["param1"] = 139, ["z"] = 16, ["name"] = "doors:door_wood_b"}, {["x"] = 5, ["meta"] = {["fields"] = {["state"] = "0"}, ["inventory"] = {}}, ["param2"] = 1, ["y"] = 2, ["param1"] = 156, ["z"] = 17, ["name"] = "doors:door_wood_a"}, {["x"] = 5, ["y"] = 2, ["z"] = 18, ["name"] = "default:brick"}, {["x"] = 5, ["meta"] = {["fields"] = {}, ["inventory"] = {}}, ["y"] = 2, ["param1"] = 152, ["z"] = 24, ["name"] = "default:brick"},