5:return {{["x"] = 0, ["y"] = 0, ["param1"] = 92, ["z"] = 0, ["name"] = "default:goldblock"}, {["x"] = 0, ["y"] = 0, ["param1"] = 92, ["z"] = 1, ["name"] = "default:goldblock"}, {["x"] = 0, ["y"] = 0, ["param1"] = 92, ["z"] = 2, ["name"] = "default:goldblock"}, {["x"] = 0, ["y"] = 0, ["param1"] = 92, ["z"] = 3, ["name"] = "default:goldblock"}, {["x"] = 0, ["y"] = 0, ["param1"] = 87, ["z"] = 4, ["name"] = "default:tinblock"}, {["x"] = 0, ["y"] = 0, ["param1"] = 87, ["z"] = 5, ["name"] = "default:tinblock"}, {["x"] = 0, ["y"] = 0, ["param1"] = 92, ["z"] = 6, ["name"] = "default:goldblock"}, {["x"] = 0, ["y"] = 0, ["param1"] = 92, ["z"] = 7, ["name"] = "default:goldblock"}, {["x"] = 0, ["y"] = 0, ["param1"] = 92, ["z"] = 8, ["name"] = "default:goldblock"}, {["x"] = 0, ["y"] = 0, ["param1"] = 92, ["z"] = 9, ["name"] = "default:goldblock"}, {["x"] = 0, ["y"] = 1, ["param1"] = 83, ["z"] = 0, ["name"] = "default:steelblock"}, {["x"] = 0, ["y"] = 1, ["param1"] = 83, ["z"] = 1, ["name"] = "default:steelblock"}, {["x"] = 0, ["y"] = 1, ["param1"] = 83, ["z"] = 2, ["name"] = "default:steelblock"}, {["x"] = 0, ["y"] = 1, ["param1"] = 190, ["z"] = 3, ["name"] = "default:glass"}, {["x"] = 0, ["y"] = 1, ["param1"] = 190, ["z"] = 6, ["name"] = "default:glass"}, {["x"] = 0, ["y"] = 1, ["param1"] = 83, ["z"] = 7, ["name"] = "default:steelblock"}, {["x"] = 0, ["y"] = 1, ["param1"] = 83, ["z"] = 8, ["name"] = "default:steelblock"}, {["x"] = 0, ["y"] = 1, ["param1"] = 83, ["z"] = 9, ["name"] = "default:steelblock"}, {["x"] = 0, ["y"] = 2, ["param1"] = 88, ["z"] = 0, ["name"] = "default:bronzeblock"}, {["x"] = 0, ["y"] = 2, ["param1"] = 88, ["z"] = 1, ["name"] = "default:bronzeblock"}, {["x"] = 0, ["y"] = 2, ["param1"] = 88, ["z"] = 2, ["name"] = "default:bronzeblock"}, {["x"] = 0, ["y"] = 2, ["param1"] = 206, ["z"] = 3, ["name"] = "default:glass"}, {["x"] = 0, ["y"] = 2, ["param1"] = 206, ["z"] = 6, ["name"] = "default:glass"}, {["x"] = 0, ["y"] = 2, ["param1"] = 88, ["z"] = 7, ["name"] = "default:bronzeblock"}, {["x"] = 0, ["y"] = 2, ["param1"] = 88, ["z"] = 8, ["name"] = "default:bronzeblock"}, {["x"] = 0, ["y"] = 2, ["param1"] = 88, ["z"] = 9, ["name"] = "default:bronzeblock"}, {["x"] = 0, ["y"] = 3, ["param1"] = 238, ["z"] = 0, ["name"] = "default:meselamp"}, {["x"] = 0, ["y"] = 3, ["param1"] = 238, ["z"] = 1, ["name"] = "default:meselamp"}, {["x"] = 0, ["y"] = 3, ["param1"] = 238, ["z"] = 2, ["name"] = "default:meselamp"}, {["x"] = 0, ["y"] = 3, ["param1"] = 222, ["z"] = 3, ["name"] = "default:glass"}, {["x"] = 0, ["y"] = 3, ["param1"] = 223, ["z"] = 4, ["name"] = "default:glass"}, {["x"] = 0, ["y"] = 3, ["param1"] = 223, ["z"] = 5, ["name"] = "default:glass"}, {["x"] = 0, ["y"] = 3, ["param1"] = 222, ["z"] = 6, ["name"] = "default:glass"}, {["x"] = 0, ["y"] = 3, ["param1"] = 238, ["z"] = 7, ["name"] = "default:meselamp"}, {["x"] = 0, ["y"] = 3, ["param1"] = 238, ["z"] = 8, ["name"] = "default:meselamp"}, {["x"] = 0, ["y"] = 3, ["param1"] = 238, ["z"] = 9, ["name"] = "default:meselamp"}, {["x"] = 0, ["y"] = 4, ["param1"] = 83, ["z"] = 0, ["name"] = "default:steelblock"}, {["x"] = 0, ["y"] = 4, ["param1"] = 83, ["z"] = 1, ["name"] = "default:steelblock"}, {["x"] = 0, ["y"] = 4, ["param1"] = 238, ["z"] = 2, ["name"] = "default:meselamp"}, {["x"] = 0, ["y"] = 4, ["param1"] = 238, ["z"] = 3, ["name"] = "default:meselamp"}, {["x"] = 0, ["y"] = 4, ["param1"] = 239, ["z"] = 4, ["name"] = "default:meselamp"}, {["x"] = 0, ["y"] = 4, ["param1"] = 239, ["z"] = 5, ["name"] = "default:meselamp"}, {["x"] = 0, ["y"] = 4, ["param1"] = 238, ["z"] = 6, ["name"] = "default:meselamp"}, {["x"] = 0, ["y"] = 4, ["param1"] = 238, ["z"] = 7, ["name"] = "default:meselamp"}, {["x"] = 0, ["y"] = 4, ["param1"] = 83, ["z"] = 8, ["name"] = "default:steelblock"}, {["x"] = 0, ["y"] = 4, ["param1"] = 83, ["z"] = 9, ["name"] = "default:steelblock"}, {["x"] = 0, ["meta"] = {["fields"] = {}, ["inventory"] = {}}, ["y"] = 5, ["param1"] = 92, ["z"] = 0, ["name"] = "default:goldblock"}, {["x"] = 0, ["meta"] = {["fields"] = {}, ["inventory"] = {}}, ["y"] = 5, ["param1"] = 92, ["z"] = 1, ["name"] = "default:goldblock"}, {["x"] = 0, ["meta"] = {["fields"] = {}, ["inventory"] = {}}, ["y"] = 5, ["param1"] = 92, ["z"] = 2, ["name"] = "default:goldblock"}, {["x"] = 0, ["meta"] = {["fields"] = {}, ["inventory"] = {}}, ["y"] = 5, ["param1"] = 92, ["z"] = 3, ["name"] = "default:goldblock"}, {["x"] = 0, ["meta"] = {["fields"] = {}, ["inventory"] = {}}, ["y"] = 5, ["param1"] = 223, ["z"] = 4, ["name"] = "default:glass"}, {["x"] = 0, ["meta"] = {["fields"] = {}, ["inventory"] = {}}, ["y"] = 5, ["param1"] = 223, ["z"] = 5, ["name"] = "default:glass"}, {["x"] = 0, ["meta"] = {["fields"] = {}, ["inventory"] = {}}, ["y"] = 5, ["param1"] = 92, ["z"] = 6, ["name"] = "default:goldblock"}, {["x"] = 0, ["meta"] = {["fields"] = {}, ["inventory"] = {}}, ["y"] = 5, ["param1"] = 92, ["z"] = 7, ["name"] = "default:goldblock"}, {["x"] = 0, ["meta"] = {["fields"] = {}, ["inventory"] = {}}, ["y"] = 5, ["param1"] = 92, ["z"] = 8, ["name"] = "default:goldblock"}, {["x"] = 0, ["meta"] = {["fields"] = {}, ["inventory"] = {}}, ["y"] = 5, ["param1"] = 92, ["z"] = 9, ["name"] = "default:goldblock"}, {["x"] = 0, ["meta"] = {["fields"] = {}, ["inventory"] = {}}, ["y"] = 6, ["param1"] = 92, ["z"] = 0, ["name"] = "default:goldblock"}, {["x"] = 0, ["meta"] = {["fields"] = {}, ["inventory"] = {}}, ["y"] = 6, ["param1"] = 92, ["z"] = 1, ["name"] = "default:goldblock"}, {["x"] = 0, ["meta"] = {["fields"] = {}, ["inventory"] = {}}, ["y"] = 6, ["param1"] = 92, ["z"] = 2, ["name"] = "default:goldblock"}, {["x"] = 0, ["meta"] = {["fields"] = {}, ["inventory"] = {}}, ["y"] = 6, ["param1"] = 92, ["z"] = 3, ["name"] = "default:goldblock"}, {["x"] = 0, ["meta"] = {["fields"] = {}, ["inventory"] = {}}, ["y"] = 6, ["param1"] = 207, ["z"] = 4, ["name"] = "default:glass"}, {["x"] = 0, ["meta"] = {["fields"] = {}, ["inventory"] = {}}, ["y"] = 6, ["param1"] = 207, ["z"] = 5, ["name"] = "default:glass"}, {["x"] = 0, ["meta"] = {["fields"] = {}, ["inventory"] = {}}, ["y"] = 6, ["param1"] = 92, ["z"] = 6, ["name"] = "default:goldblock"}, {["x"] = 0, ["meta"] = {["fields"] = {}, ["inventory"] = {}}, ["y"] = 6, ["param1"] = 92, ["z"] = 7, ["name"] = "default:goldblock"}, {["x"] = 0, ["meta"] = {["fields"] = {}, ["inventory"] = {}}, ["y"] = 6, ["param1"] = 92, ["z"] = 8, ["name"] = "default:goldblock"}, {["x"] = 0, ["meta"] = {["fields"] = {}, ["inventory"] = {}}, ["y"] = 6, ["param1"] = 92, ["z"] = 9, ["name"] = "default:goldblock"}, {["x"] = 0, ["meta"] = {["fields"] = {}, ["inventory"] = {}}, ["y"] = 7, ["param1"] = 92, ["z"] = 0, ["name"] = "default:goldblock"}, {["x"] = 0, ["meta"] = {["fields"] = {}, ["inventory"] = {}}, ["y"] = 7, ["param1"] = 92, ["z"] = 1, ["name"] = "default:goldblock"}, {["x"] = 0, ["meta"] = {["fields"] = {}, ["inventory"] = {}}, ["y"] = 7, ["param1"] = 92, ["z"] = 2, ["name"] = "default:goldblock"}, {["x"] = 0, ["meta"] = {["fields"] = {}, ["inventory"] = {}}, ["y"] = 7, ["param1"] = 92, ["z"] = 3, ["name"] = "default:goldblock"}, {["x"] = 0, ["meta"] = {["fields"] = {}, ["inventory"] = {}}, ["y"] = 7, ["param1"] = 191, ["z"] = 4, ["name"] = "default:glass"}, {["x"] = 0, ["meta"] = {["fields"] = {}, ["inventory"] = {}}, ["y"] = 7, ["param1"] = 191, ["z"] = 5, ["name"] = "default:glass"}, {["x"] = 0, ["meta"] = {["fields"] = {}, ["inventory"] = {}}, ["y"] = 7, ["param1"] = 92, ["z"] = 6, ["name"] = "default:goldblock"}, {["x"] = 0, ["meta"] = {["fields"] = {}, ["inventory"] = {}}, ["y"] = 7, ["param1"] = 92, ["z"] = 7, ["name"] = "default:goldblock"}, {["x"] = 0, ["meta"] = {["fields"] = {}, ["inventory"] = {}}, ["y"] = 7, ["param1"] = 92, ["z"] = 8, ["name"] = "default:goldblock"}, {["x"] = 0, ["meta"] = {["fields"] = {}, ["inventory"] = {}}, ["y"] = 7, ["param1"] = 92, ["z"] = 9, ["name"] = "default:goldblock"}, {["x"] = 0, ["meta"] = {["fields"] = {}, ["inventory"] = {}}, ["y"] = 8, ["param1"] = 92, ["z"] = 0, ["name"] = "default:goldblock"}, {["x"] = 0, ["meta"] = {["fields"] = {}, ["inventory"] = {}}, ["y"] = 8, ["param1"] = 92, ["z"] = 1, ["name"] = "default:goldblock"}, {["x"] = 0, ["meta"] = {["fields"] = {}, ["inventory"] = {}}, ["y"] = 8, ["param1"] = 92, ["z"] = 2, ["name"] = "default:goldblock"}, {["x"] = 0, ["meta"] = {["fields"] = {}, ["inventory"] = {}}, ["y"] = 8, ["param1"] = 92, ["z"] = 3, ["name"] = "default:goldblock"}, {["x"] = 0, ["meta"] = {["fields"] = {}, ["inventory"] = {}}, ["y"] = 8, ["param1"] = 175, ["z"] = 4, ["name"] = "default:glass"}, {["x"] = 0, ["meta"] = {["fields"] = {}, ["inventory"] = {}}, ["y"] = 8, ["param1"] = 175, ["z"] = 5, ["name"] = "default:glass"}, {["x"] = 0, ["meta"] = {["fields"] = {}, ["inventory"] = {}}, ["y"] = 8, ["param1"] = 92, ["z"] = 6, ["name"] = "default:goldblock"}, {["x"] = 0, ["meta"] = {["fields"] = {}, ["inventory"] = {}}, ["y"] = 8, ["param1"] = 92, ["z"] = 7, ["name"] = "default:goldblock"}, {["x"] = 0, ["meta"] = {["fields"] = {}, ["inventory"] = {}}, ["y"] = 8, ["param1"] = 92, ["z"] = 8, ["name"] = "default:goldblock"}, {["x"] = 0, ["meta"] = {["fields"] = {}, ["inventory"] = {}}, ["y"] = 8, ["param1"] = 92, ["z"] = 9, ["name"] = "default:goldblock"}, {["x"] = 0, ["meta"] = {["fields"] = {}, ["inventory"] = {}}, ["y"] = 9, ["param1"] = 92, ["z"] = 0, ["name"] = "default:goldblock"}, {["x"] = 0, ["meta"] = {["fields"] = {}, ["inventory"] = {}}, ["y"] = 9, ["param1"] = 92, ["z"] = 1, ["name"] = "default:goldblock"}, {["x"] = 0, ["meta"] = {["fields"] = {}, ["inventory"] = {}}, ["y"] = 9, ["param1"] = 92, ["z"] = 2, ["name"] = "default:goldblock"}, {["x"] = 0, ["meta"] = {["fields"] = {}, ["inventory"] = {}}, ["y"] = 9, ["param1"] = 92, ["z"] = 3, ["name"] = "default:goldblock"}, {["x"] = 0, ["meta"] = {["fields"] = {}, ["inventory"] = {}}, ["y"] = 9, ["param1"] = 159, ["z"] = 4, ["name"] = "default:glass"}, {["x"] = 0, ["meta"] = {["fields"] = {}, ["inventory"] = {}}, ["y"] = 9, ["param1"] = 159, ["z"] = 5, ["name"] = "default:glass"}, {["x"] = 0, ["meta"] = {["fields"] = {}, ["inventory"] = {}}, ["y"] = 9, ["param1"] = 92, ["z"] = 6, ["name"] = "default:goldblock"}, {["x"] = 0, ["meta"] = {["fields"] = {}, ["inventory"] = {}}, ["y"] = 9, ["param1"] = 92, ["z"] = 7, ["name"] = "default:goldblock"}, {["x"] = 0, ["meta"] = {["fields"] = {}, ["inventory"] = {}}, ["y"] = 9, ["param1"] = 92, ["z"] = 8, ["name"] = "default:goldblock"}, {["x"] = 0, ["meta"] = {["fields"] = {}, ["inventory"] = {}}, ["y"] = 9, ["param1"] = 92, ["z"] = 9, ["name"] = "default:goldblock"}, {["x"] = 0, ["meta"] = {["fields"] = {}, ["inventory"] = {}}, ["y"] = 10, ["param1"] = 92, ["z"] = 0, ["name"] = "default:goldblock"}, {["x"] = 0, ["meta"] = {["fields"] = {}, ["inventory"] = {}}, ["y"] = 10, ["param1"] = 92, ["z"] = 1, ["name"] = "default:goldblock"}, {["x"] = 0, ["meta"] = {["fields"] = {}, ["inventory"] = {}}, ["y"] = 10, ["param1"] = 92, ["z"] = 2, ["name"] = "default:goldblock"}, {["x"] = 0, ["meta"] = {["fields"] = {}, ["inventory"] = {}}, ["y"] = 10, ["param1"] = 92, ["z"] = 3, ["name"] = "default:goldblock"}, {["x"] = 0, ["meta"] = {["fields"] = {}, ["inventory"] = {}}, ["y"] = 10, ["param1"] = 143, ["z"] = 4, ["name"] = "default:glass"}, {["x"] = 0, ["meta"] = {["fields"] = {}, ["inventory"] = {}}, ["y"] = 10, ["param1"] = 143, ["z"] = 5, ["name"] = "default:glass"}, {["x"] = 0, ["meta"] = {["fields"] = {}, ["inventory"] = {}}, ["y"] = 10, ["param1"] = 92, ["z"] = 6, ["name"] = "default:goldblock"}, {["x"] = 0, ["meta"] = {["fields"] = {}, ["inventory"] = {}}, ["y"] = 10, ["param1"] = 92, ["z"] = 7, ["name"] = "default:goldblock"}, {["x"] = 0, ["meta"] = {["fields"] = {}, ["inventory"] = {}}, ["y"] = 10, ["param1"] = 92, ["z"] = 8, ["name"] = "default:goldblock"}, {["x"] = 0, ["meta"] = {["fields"] = {}, ["inventory"] = {}}, ["y"] = 10, ["param1"] = 92, ["z"] = 9, ["name"] = "default:goldblock"}, {["x"] = 0, ["meta"] = {["fields"] = {}, ["inventory"] = {}}, ["y"] = 11, ["param1"] = 92, ["z"] = 0, ["name"] = "default:goldblock"}, {["x"] = 0, ["meta"] = {["fields"] = {}, ["inventory"] = {}}, ["y"] = 11, ["param1"] = 92, ["z"] = 1, ["name"] = "default:goldblock"}, {["x"] = 0, ["meta"] = {["fields"] = {}, ["inventory"] = {}}, ["y"] = 11, ["param1"] = 92, ["z"] = 2, ["name"] = "default:goldblock"}, {["x"] = 0, ["meta"] = {["fields"] = {}, ["inventory"] = {}}, ["y"] = 11, ["param1"] = 92, ["z"] = 3, ["name"] = "default:goldblock"}, {["x"] = 0, ["meta"] = {["fields"] = {}, ["inventory"] = {}}, ["y"] = 11, ["param1"] = 127, ["z"] = 4, ["name"] = "default:glass"}, {["x"] = 0, ["meta"] = {["fields"] = {}, ["inventory"] = {}}, ["y"] = 11, ["param1"] = 127, ["z"] = 5, ["name"] = "default:glass"}, {["x"] = 0, ["meta"] = {["fields"] = {}, ["inventory"] = {}}, ["y"] = 11, ["param1"] = 92, ["z"] = 6, ["name"] = "default:goldblock"}, {["x"] = 0, ["meta"] = {["fields"] = {}, ["inventory"] = {}}, ["y"] = 11, ["param1"] = 92, ["z"] = 7, ["name"] = "default:goldblock"}, {["x"] = 0, ["meta"] = {["fields"] = {}, ["inventory"] = {}}, ["y"] = 11, ["param1"] = 92, ["z"] = 8, ["name"] = "default:goldblock"}, {["x"] = 0, ["meta"] = {["fields"] = {}, ["inventory"] = {}}, ["y"] = 11, ["param1"] = 92, ["z"] = 9, ["name"] = "default:goldblock"}, {["x"] = 0, ["meta"] = {["fields"] = {}, ["inventory"] = {}}, ["y"] = 12, ["param1"] = 92, ["z"] = 0, ["name"] = "default:goldblock"}, {["x"] = 0, ["meta"] = {["fields"] = {}, ["inventory"] = {}}, ["y"] = 12, ["param1"] = 92, ["z"] = 1, ["name"] = "default:goldblock"}, {["x"] = 0, ["meta"] = {["fields"] = {}, ["inventory"] = {}}, ["y"] = 12, ["param1"] = 92, ["z"] = 2, ["name"] = "default:goldblock"}, {["x"] = 0, ["meta"] = {["fields"] = {}, ["inventory"] = {}}, ["y"] = 12, ["param1"] = 92, ["z"] = 3, ["name"] = "default:goldblock"}, {["x"] = 0, ["meta"] = {["fields"] = {}, ["inventory"] = {}}, ["y"] = 12, ["param1"] = 111, ["z"] = 4, ["name"] = "default:glass"}, {["x"] = 0, ["meta"] = {["fields"] = {}, ["inventory"] = {}}, ["y"] = 12, ["param1"] = 111, ["z"] = 5, ["name"] = "default:glass"}, {["x"] = 0, ["meta"] = {["fields"] = {}, ["inventory"] = {}}, ["y"] = 12, ["param1"] = 92, ["z"] = 6, ["name"] = "default:goldblock"}, {["x"] = 0, ["meta"] = {["fields"] = {}, ["inventory"] = {}}, ["y"] = 12, ["param1"] = 92, ["z"] = 7, ["name"] = "default:goldblock"}, {["x"] = 0, ["meta"] = {["fields"] = {}, ["inventory"] = {}}, ["y"] = 12, ["param1"] = 92, ["z"] = 8, ["name"] = "default:goldblock"}, {["x"] = 0, ["meta"] = {["fields"] = {}, ["inventory"] = {}}, ["y"] = 12, ["param1"] = 92, ["z"] = 9, ["name"] = "default:goldblock"}, {["x"] = 0, ["meta"] = {["fields"] = {}, ["inventory"] = {}}, ["y"] = 13, ["param1"] = 92, ["z"] = 0, ["name"] = "default:goldblock"}, {["x"] = 0, ["meta"] = {["fields"] = {}, ["inventory"] = {}}, ["y"] = 13, ["param1"] = 92, ["z"] = 1, ["name"] = "default:goldblock"}, {["x"] = 0, ["meta"] = {["fields"] = {}, ["inventory"] = {}}, ["y"] = 13, ["param1"] = 92, ["z"] = 2, ["name"] = "default:goldblock"}, {["x"] = 0, ["meta"] = {["fields"] = {}, ["inventory"] = {}}, ["y"] = 13, ["param1"] = 92, ["z"] = 3, ["name"] = "default:goldblock"}, {["x"] = 0, ["meta"] = {["fields"] = {}, ["inventory"] = {}}, ["y"] = 13, ["param1"] = 95, ["z"] = 4, ["name"] = "default:glass"}, {["x"] = 0, ["meta"] = {["fields"] = {}, ["inventory"] = {}}, ["y"] = 13, ["param1"] = 95, ["z"] = 5, ["name"] = "default:glass"}, {["x"] = 0, ["meta"] = {["fields"] = {}, ["inventory"] = {}}, ["y"] = 13, ["param1"] = 92, ["z"] = 6, ["name"] = "default:goldblock"}, {["x"] = 0, ["meta"] = {["fields"] = {}, ["inventory"] = {}}, ["y"] = 13, ["param1"] = 92, ["z"] = 7, ["name"] = "default:goldblock"}, {["x"] = 0, ["meta"] = {["fields"] = {}, ["inventory"] = {}}, ["y"] = 13, ["param1"] = 92, ["z"] = 8, ["name"] = "default:goldblock"}, {["x"] = 0, ["meta"] = {["fields"] = {}, ["inventory"] = {}}, ["y"] = 13, ["param1"] = 92, ["z"] = 9, ["name"] = "default:goldblock"}, {["x"] = 0, ["meta"] = {["fields"] = {}, ["inventory"] = {}}, ["y"] = 14, ["param1"] = 92, ["z"] = 0, ["name"] = "default:goldblock"}, {["x"] = 0, ["meta"] = {["fields"] = {}, ["inventory"] = {}}, ["y"] = 14, ["param1"] = 92, ["z"] = 1, ["name"] = "default:goldblock"}, {["x"] = 0, ["meta"] = {["fields"] = {}, ["inventory"] = {}}, ["y"] = 14, ["param1"] = 92, ["z"] = 2, ["name"] = "default:goldblock"}, {["x"] = 0, ["meta"] = {["fields"] = {}, ["inventory"] = {}}, ["y"] = 14, ["param1"] = 92, ["z"] = 3, ["name"] = "default:goldblock"}, {["x"] = 0, ["meta"] = {["fields"] = {}, ["inventory"] = {}}, ["y"] = 14, ["param1"] = 79, ["z"] = 4, ["name"] = "default:glass"}, {["x"] = 0, ["meta"] = {["fields"] = {}, ["inventory"] = {}}, ["y"] = 14, ["param1"] = 79, ["z"] = 5, ["name"] = "default:glass"}, {["x"] = 0, ["meta"] = {["fields"] = {}, ["inventory"] = {}}, ["y"] = 14, ["param1"] = 92, ["z"] = 6, ["name"] = "default:goldblock"}, {["x"] = 0, ["meta"] = {["fields"] = {}, ["inventory"] = {}}, ["y"] = 14, ["param1"] = 92, ["z"] = 7, ["name"] = "default:goldblock"}, {["x"] = 0, ["meta"] = {["fields"] = {}, ["inventory"] = {}}, ["y"] = 14, ["param1"] = 92, ["z"] = 8, ["name"] = "default:goldblock"}, {["x"] = 0, ["meta"] = {["fields"] = {}, ["inventory"] = {}}, ["y"] = 14, ["param1"] = 92, ["z"] = 9, ["name"] = "default:goldblock"}, {["x"] = 0, ["meta"] = {["fields"] = {}, ["inventory"] = {}}, ["y"] = 15, ["param1"] = 92, ["z"] = 0, ["name"] = "default:goldblock"}, {["x"] = 0, ["meta"] = {["fields"] = {}, ["inventory"] = {}}, ["y"] = 15, ["param1"] = 92, ["z"] = 1, ["name"] = "default:goldblock"}, {["x"] = 0, ["meta"] = {["fields"] = {}, ["inventory"] = {}}, ["y"] = 15, ["param1"] = 92, ["z"] = 2, ["name"] = "default:goldblock"}, {["x"] = 0, ["meta"] = {["fields"] = {}, ["inventory"] = {}}, ["y"] = 15, ["param1"] = 92, ["z"] = 3, ["name"] = "default:goldblock"}, {["x"] = 0, ["meta"] = {["fields"] = {}, ["inventory"] = {}}, ["y"] = 15, ["param1"] = 63, ["z"] = 4, ["name"] = "default:glass"}, {["x"] = 0, ["meta"] = {["fields"] = {}, ["inventory"] = {}}, ["y"] = 15, ["param1"] = 63, ["z"] = 5, ["name"] = "default:glass"}, {["x"] = 0, ["meta"] = {["fields"] = {}, ["inventory"] = {}}, ["y"] = 15, ["param1"] = 92, ["z"] = 6, ["name"] = "default:goldblock"}, {["x"] = 0, ["meta"] = {["fields"] = {}, ["inventory"] = {}}, ["y"] = 15, ["param1"] = 92, ["z"] = 7, ["name"] = "default:goldblock"}, {["x"] = 0, ["meta"] = {["fields"] = {}, ["inventory"] = {}}, ["y"] = 15, ["param1"] = 92, ["z"] = 8, ["name"] = "default:goldblock"}, {["x"] = 0, ["meta"] = {["fields"] = {}, ["inventory"] = {}}, ["y"] = 15, ["param1"] = 92, ["z"] = 9, ["name"] = "default:goldblock"}, {["x"] = 0, ["meta"] = {["fields"] = {}, ["inventory"] = {}}, ["y"] = 16, ["param1"] = 92, ["z"] = 0, ["name"] = "default:goldblock"}, {["x"] = 0, ["meta"] = {["fields"] = {}, ["inventory"] = {}}, ["y"] = 16, ["param1"] = 92, ["z"] = 1, ["name"] = "default:goldblock"}, {["x"] = 0, ["meta"] = {["fields"] = {}, ["inventory"] = {}}, ["y"] = 16, ["param1"] = 92, ["z"] = 2, ["name"] = "default:goldblock"}, {["x"] = 0, ["meta"] = {["fields"] = {}, ["inventory"] = {}}, ["y"] = 16, ["param1"] = 92, ["z"] = 3, ["name"] = "default:goldblock"}, {["x"] = 0, ["meta"] = {["fields"] = {}, ["inventory"] = {}}, ["y"] = 16, ["param1"] = 47, ["z"] = 4, ["name"] = "default:glass"}, {["x"] = 0, ["meta"] = {["fields"] = {}, ["inventory"] = {}}, ["y"] = 16, ["param1"] = 47, ["z"] = 5, ["name"] = "default:glass"}, {["x"] = 0, ["meta"] = {["fields"] = {}, ["inventory"] = {}}, ["y"] = 16, ["param1"] = 92, ["z"] = 6, ["name"] = "default:goldblock"}, {["x"] = 0, ["meta"] = {["fields"] = {}, ["inventory"] = {}}, ["y"] = 16, ["param1"] = 92, ["z"] = 7, ["name"] = "default:goldblock"}, {["x"] = 0, ["meta"] = {["fields"] = {}, ["inventory"] = {}}, ["y"] = 16, ["param1"] = 92, ["z"] = 8, ["name"] = "default:goldblock"}, {["x"] = 0, ["meta"] = {["fields"] = {}, ["inventory"] = {}}, ["y"] = 16, ["param1"] = 92, ["z"] = 9, ["name"] = "default:goldblock"}, {["x"] = 0, ["meta"] = {["fields"] = {}, ["inventory"] = {}}, ["y"] = 17, ["param1"] = 92, ["z"] = 0, ["name"] = "default:goldblock"}, {["x"] = 0, ["meta"] = {["fields"] = {}, ["inventory"] = {}}, ["y"] = 17, ["param1"] = 92, ["z"] = 1, ["name"] = "default:goldblock"}, {["x"] = 0, ["meta"] = {["fields"] = {}, ["inventory"] = {}}, ["y"] = 17, ["param1"] = 92, ["z"] = 2, ["name"] = "default:goldblock"}, {["x"] = 0, ["meta"] = {["fields"] = {}, ["inventory"] = {}}, ["y"] = 17, ["param1"] = 92, ["z"] = 3, ["name"] = "default:goldblock"}, {["x"] = 0, ["meta"] = {["fields"] = {}, ["inventory"] = {}}, ["y"] = 17, ["param1"] = 31, ["z"] = 4, ["name"] = "default:glass"}, {["x"] = 0, ["meta"] = {["fields"] = {}, ["inventory"] = {}}, ["y"] = 17, ["param1"] = 31, ["z"] = 5, ["name"] = "default:glass"}, {["x"] = 0, ["meta"] = {["fields"] = {}, ["inventory"] = {}}, ["y"] = 17, ["param1"] = 92, ["z"] = 6, ["name"] = "default:goldblock"}, {["x"] = 0, ["meta"] = {["fields"] = {}, ["inventory"] = {}}, ["y"] = 17, ["param1"] = 92, ["z"] = 7, ["name"] = "default:goldblock"}, {["x"] = 0, ["meta"] = {["fields"] = {}, ["inventory"] = {}}, ["y"] = 17, ["param1"] = 92, ["z"] = 8, ["name"] = "default:goldblock"}, {["x"] = 0, ["meta"] = {["fields"] = {}, ["inventory"] = {}}, ["y"] = 17, ["param1"] = 92, ["z"] = 9, ["name"] = "default:goldblock"}, {["x"] = 0, ["meta"] = {["fields"] = {}, ["inventory"] = {}}, ["y"] = 18, ["param1"] = 92, ["z"] = 0, ["name"] = "default:goldblock"}, {["x"] = 0, ["meta"] = {["fields"] = {}, ["inventory"] = {}}, ["y"] = 18, ["param1"] = 92, ["z"] = 1, ["name"] = "default:goldblock"}, {["x"] = 0, ["meta"] = {["fields"] = {}, ["inventory"] = {}}, ["y"] = 18, ["param1"] = 92, ["z"] = 2, ["name"] = "default:goldblock"}, {["x"] = 0, ["meta"] = {["fields"] = {}, ["inventory"] = {}}, ["y"] = 18, ["param1"] = 92, ["z"] = 3, ["name"] = "default:goldblock"}, {["x"] = 0, ["meta"] = {["fields"] = {}, ["inventory"] = {}}, ["y"] = 18, ["param1"] = 15, ["z"] = 4, ["name"] = "default:glass"}, {["x"] = 0, ["meta"] = {["fields"] = {}, ["inventory"] = {}}, ["y"] = 18, ["param1"] = 15, ["z"] = 5, ["name"] = "default:glass"}, {["x"] = 0, ["meta"] = {["fields"] = {}, ["inventory"] = {}}, ["y"] = 18, ["param1"] = 92, ["z"] = 6, ["name"] = "default:goldblock"}, {["x"] = 0, ["meta"] = {["fields"] = {}, ["inventory"] = {}}, ["y"] = 18, ["param1"] = 92, ["z"] = 7, ["name"] = "default:goldblock"}, {["x"] = 0, ["meta"] = {["fields"] = {}, ["inventory"] = {}}, ["y"] = 18, ["param1"] = 92, ["z"] = 8, ["name"] = "default:goldblock"}, {["x"] = 0, ["meta"] = {["fields"] = {}, ["inventory"] = {}}, ["y"] = 18, ["param1"] = 92, ["z"] = 9, ["name"] = "default:goldblock"}, {["x"] = 0, ["meta"] = {["fields"] = {}, ["inventory"] = {}}, ["y"] = 19, ["param1"] = 92, ["z"] = 0, ["name"] = "default:goldblock"}, {["x"] = 0, ["meta"] = {["fields"] = {}, ["inventory"] = {}}, ["y"] = 19, ["param1"] = 92, ["z"] = 1, ["name"] = "default:goldblock"}, {["x"] = 0, ["meta"] = {["fields"] = {}, ["inventory"] = {}}, ["y"] = 19, ["param1"] = 92, ["z"] = 2, ["name"] = "default:goldblock"}, {["x"] = 0, ["meta"] = {["fields"] = {}, ["inventory"] = {}}, ["y"] = 19, ["param1"] = 92, ["z"] = 3, ["name"] = "default:goldblock"}, {["x"] = 0, ["meta"] = {["fields"] = {}, ["inventory"] = {}}, ["y"] = 19, ["param1"] = 15, ["z"] = 4, ["name"] = "default:glass"}, {["x"] = 0, ["meta"] = {["fields"] = {}, ["inventory"] = {}}, ["y"] = 19, ["param1"] = 15, ["z"] = 5, ["name"] = "default:glass"}, {["x"] = 0, ["meta"] = {["fields"] = {}, ["inventory"] = {}}, ["y"] = 19, ["param1"] = 92, ["z"] = 6, ["name"] = "default:goldblock"}, {["x"] = 0, ["meta"] = {["fields"] = {}, ["inventory"] = {}}, ["y"] = 19, ["param1"] = 92, ["z"] = 7, ["name"] = "default:goldblock"}, {["x"] = 0, ["meta"] = {["fields"] = {}, ["inventory"] = {}}, ["y"] = 19, ["param1"] = 92, ["z"] = 8, ["name"] = "default:goldblock"}, {["x"] = 0, ["meta"] = {["fields"] = {}, ["inventory"] = {}}, ["y"] = 19, ["param1"] = 92, ["z"] = 9, ["name"] = "default:goldblock"}, {["x"] = 0, ["meta"] = {["fields"] = {}, ["inventory"] = {}}, ["y"] = 20, ["param1"] = 92, ["z"] = 0, ["name"] = "default:goldblock"}, {["x"] = 0, ["meta"] = {["fields"] = {}, ["inventory"] = {}}, ["y"] = 20, ["param1"] = 92, ["z"] = 1, ["name"] = "default:goldblock"}, {["x"] = 0, ["meta"] = {["fields"] = {}, ["inventory"] = {}}, ["y"] = 20, ["param1"] = 92, ["z"] = 2, ["name"] = "default:goldblock"}, {["x"] = 0, ["meta"] = {["fields"] = {}, ["inventory"] = {}}, ["y"] = 20, ["param1"] = 92, ["z"] = 3, ["name"] = "default:goldblock"}, {["x"] = 0, ["meta"] = {["fields"] = {}, ["inventory"] = {}}, ["y"] = 20, ["param1"] = 15, ["z"] = 4, ["name"] = "default:glass"}, {["x"] = 0, ["meta"] = {["fields"] = {}, ["inventory"] = {}}, ["y"] = 20, ["param1"] = 15, ["z"] = 5, ["name"] = "default:glass"}, {["x"] = 0, ["meta"] = {["fields"] = {}, ["inventory"] = {}}, ["y"] = 20, ["param1"] = 92, ["z"] = 6, ["name"] = "default:goldblock"}, {["x"] = 0, ["meta"] = {["fields"] = {}, ["inventory"] = {}}, ["y"] = 20, ["param1"] = 92, ["z"] = 7, ["name"] = "default:goldblock"}, {["x"] = 0, ["meta"] = {["fields"] = {}, ["inventory"] = {}}, ["y"] = 20, ["param1"] = 92, ["z"] = 8, ["name"] = "default:goldblock"}, {["x"] = 0, ["meta"] = {["fields"] = {}, ["inventory"] = {}}, ["y"] = 20, ["param1"] = 92, ["z"] = 9, ["name"] = "default:goldblock"}, {["x"] = 0, ["meta"] = {["fields"] = {}, ["inventory"] = {}}, ["y"] = 21, ["param1"] = 92, ["z"] = 0, ["name"] = "default:goldblock"}, {["x"] = 0, ["meta"] = {["fields"] = {}, ["inventory"] = {}}, ["y"] = 21, ["param1"] = 92, ["z"] = 1, ["name"] = "default:goldblock"}, {["x"] = 0, ["meta"] = {["fields"] = {}, ["inventory"] = {}}, ["y"] = 21, ["param1"] = 92, ["z"] = 2, ["name"] = "default:goldblock"}, {["x"] = 0, ["meta"] = {["fields"] = {}, ["inventory"] = {}}, ["y"] = 21, ["param1"] = 92, ["z"] = 3, ["name"] = "default:goldblock"}, {["x"] = 0, ["meta"] = {["fields"] = {}, ["inventory"] = {}}, ["y"] = 21, ["param1"] = 15, ["z"] = 4, ["name"] = "default:glass"}, {["x"] = 0, ["meta"] = {["fields"] = {}, ["inventory"] = {}}, ["y"] = 21, ["param1"] = 15, ["z"] = 5, ["name"] = "default:glass"}, {["x"] = 0, ["meta"] = {["fields"] = {}, ["inventory"] = {}}, ["y"] = 21, ["param1"] = 92, ["z"] = 6, ["name"] = "default:goldblock"}, {["x"] = 0, ["meta"] = {["fields"] = {}, ["inventory"] = {}}, ["y"] = 21, ["param1"] = 92, ["z"] = 7, ["name"] = "default:goldblock"}, {["x"] = 0, ["meta"] = {["fields"] = {}, ["inventory"] = {}}, ["y"] = 21, ["param1"] = 92, ["z"] = 8, ["name"] = "default:goldblock"}, {["x"] = 0, ["meta"] = {["fields"] = {}, ["inventory"] = {}}, ["y"] = 21, ["param1"] = 92, ["z"] = 9, ["name"] = "default:goldblock"}, {["x"] = 0, ["meta"] = {["fields"] = {}, ["inventory"] = {}}, ["y"] = 22, ["param1"] = 92, ["z"] = 0, ["name"] = "default:goldblock"}, {["x"] = 0, ["meta"] = {["fields"] = {}, ["inventory"] = {}}, ["y"] = 22, ["param1"] = 92, ["z"] = 1, ["name"] = "default:goldblock"}, {["x"] = 0, ["meta"] = {["fields"] = {}, ["inventory"] = {}}, ["y"] = 22, ["param1"] = 92, ["z"] = 2, ["name"] = "default:goldblock"}, {["x"] = 0, ["meta"] = {["fields"] = {}, ["inventory"] = {}}, ["y"] = 22, ["param1"] = 92, ["z"] = 3, ["name"] = "default:goldblock"}, {["x"] = 0, ["meta"] = {["fields"] = {}, ["inventory"] = {}}, ["y"] = 22, ["param1"] = 15, ["z"] = 4, ["name"] = "default:glass"}, {["x"] = 0, ["meta"] = {["fields"] = {}, ["inventory"] = {}}, ["y"] = 22, ["param1"] = 15, ["z"] = 5, ["name"] = "default:glass"}, {["x"] = 0, ["meta"] = {["fields"] = {}, ["inventory"] = {}}, ["y"] = 22, ["param1"] = 92, ["z"] = 6, ["name"] = "default:goldblock"}, {["x"] = 0, ["meta"] = {["fields"] = {}, ["inventory"] = {}}, ["y"] = 22, ["param1"] = 92, ["z"] = 7, ["name"] = "default:goldblock"}, {["x"] = 0, ["meta"] = {["fields"] = {}, ["inventory"] = {}}, ["y"] = 22, ["param1"] = 92, ["z"] = 8, ["name"] = "default:goldblock"}, {["x"] = 0, ["meta"] = {["fields"] = {}, ["inventory"] = {}}, ["y"] = 22, ["param1"] = 92, ["z"] = 9, ["name"] = "default:goldblock"}, {["x"] = 0, ["meta"] = {["fields"] = {}, ["inventory"] = {}}, ["y"] = 23, ["param1"] = 92, ["z"] = 0, ["name"] = "default:goldblock"}, {["x"] = 0, ["meta"] = {["fields"] = {}, ["inventory"] = {}}, ["y"] = 23, ["param1"] = 92, ["z"] = 1, ["name"] = "default:goldblock"}, {["x"] = 0, ["meta"] = {["fields"] = {}, ["inventory"] = {}}, ["y"] = 23, ["param1"] = 92, ["z"] = 2, ["name"] = "default:goldblock"}, {["x"] = 0, ["meta"] = {["fields"] = {}, ["inventory"] = {}}, ["y"] = 23, ["param1"] = 92, ["z"] = 3, ["name"] = "default:goldblock"}, {["x"] = 0, ["meta"] = {["fields"] = {}, ["inventory"] = {}}, ["y"] = 23, ["param1"] = 15, ["z"] = 4, ["name"] = "default:glass"}, {["x"] = 0, ["meta"] = {["fields"] = {}, ["inventory"] = {}}, ["y"] = 23, ["param1"] = 15, ["z"] = 5, ["name"] = "default:glass"}, {["x"] = 0, ["meta"] = {["fields"] = {}, ["inventory"] = {}}, ["y"] = 23, ["param1"] = 92, ["z"] = 6, ["name"] = "default:goldblock"}, {["x"] = 0, ["meta"] = {["fields"] = {}, ["inventory"] = {}}, ["y"] = 23, ["param1"] = 92, ["z"] = 7, ["name"] = "default:goldblock"}, {["x"] = 0, ["meta"] = {["fields"] = {}, ["inventory"] = {}}, ["y"] = 23, ["param1"] = 92, ["z"] = 8, ["name"] = "default:goldblock"}, {["x"] = 0, ["meta"] = {["fields"] = {}, ["inventory"] = {}}, ["y"] = 23, ["param1"] = 92, ["z"] = 9, ["name"] = "default:goldblock"}, {["x"] = 0, ["meta"] = {["fields"] = {}, ["inventory"] = {}}, ["y"] = 24, ["param1"] = 92, ["z"] = 0, ["name"] = "default:goldblock"}, {["x"] = 0, ["meta"] = {["fields"] = {}, ["inventory"] = {}}, ["y"] = 24, ["param1"] = 92, ["z"] = 1, ["name"] = "default:goldblock"}, {["x"] = 0, ["meta"] = {["fields"] = {}, ["inventory"] = {}}, ["y"] = 24, ["param1"] = 92, ["z"] = 2, ["name"] = "default:goldblock"}, {["x"] = 0, ["meta"] = {["fields"] = {}, ["inventory"] = {}}, ["y"] = 24, ["param1"] = 92, ["z"] = 3, ["name"] = "default:goldblock"}, {["x"] = 0, ["meta"] = {["fields"] = {}, ["inventory"] = {}}, ["y"] = 24, ["param1"] = 14, ["z"] = 4, ["name"] = "default:glass"}, {["x"] = 0, ["meta"] = {["fields"] = {}, ["inventory"] = {}}, ["y"] = 24, ["param1"] = 14, ["z"] = 5, ["name"] = "default:glass"}, {["x"] = 0, ["meta"] = {["fields"] = {}, ["inventory"] = {}}, ["y"] = 24, ["param1"] = 92, ["z"] = 6, ["name"] = "default:goldblock"}, {["x"] = 0, ["meta"] = {["fields"] = {}, ["inventory"] = {}}, ["y"] = 24, ["param1"] = 92, ["z"] = 7, ["name"] = "default:goldblock"}, {["x"] = 0, ["meta"] = {["fields"] = {}, ["inventory"] = {}}, ["y"] = 24, ["param1"] = 92, ["z"] = 8, ["name"] = "default:goldblock"}, {["x"] = 0, ["meta"] = {["fields"] = {}, ["inventory"] = {}}, ["y"] = 24, ["param1"] = 92, ["z"] = 9, ["name"] = "default:goldblock"}, {["x"] = 0, ["meta"] = {["fields"] = {}, ["inventory"] = {}}, ["y"] = 25, ["param1"] = 92, ["z"] = 0, ["name"] = "default:goldblock"}, {["x"] = 0, ["meta"] = {["fields"] = {}, ["inventory"] = {}}, ["y"] = 25, ["param1"] = 92, ["z"] = 1, ["name"] = "default:goldblock"}, {["x"] = 0, ["meta"] = {["fields"] = {}, ["inventory"] = {}}, ["y"] = 25, ["param1"] = 92, ["z"] = 2, ["name"] = "default:goldblock"}, {["x"] = 0, ["meta"] = {["fields"] = {}, ["inventory"] = {}}, ["y"] = 25, ["param1"] = 92, ["z"] = 3, ["name"] = "default:goldblock"}, {["x"] = 0, ["meta"] = {["fields"] = {}, ["inventory"] = {}}, ["y"] = 25, ["param1"] = 14, ["z"] = 4, ["name"] = "default:glass"}, {["x"] = 0, ["meta"] = {["fields"] = {}, ["inventory"] = {}}, ["y"] = 25, ["param1"] = 14, ["z"] = 5, ["name"] = "default:glass"}, {["x"] = 0, ["meta"] = {["fields"] = {}, ["inventory"] = {}}, ["y"] = 25, ["param1"] = 92, ["z"] = 6, ["name"] = "default:goldblock"}, {["x"] = 0, ["meta"] = {["fields"] = {}, ["inventory"] = {}}, ["y"] = 25, ["param1"] = 92, ["z"] = 7, ["name"] = "default:goldblock"}, {["x"] = 0, ["meta"] = {["fields"] = {}, ["inventory"] = {}}, ["y"] = 25, ["param1"] = 92, ["z"] = 8, ["name"] = "default:goldblock"}, {["x"] = 0, ["meta"] = {["fields"] = {}, ["inventory"] = {}}, ["y"] = 25, ["param1"] = 92, ["z"] = 9, ["name"] = "default:goldblock"}, {["x"] = 0, ["y"] = 26, ["z"] = 0, ["name"] = "default:goldblock"}, {["x"] = 0, ["meta"] = {["fields"] = {}, ["inventory"] = {}}, ["y"] = 26, ["param1"] = 92, ["z"] = 2, ["name"] = "default:goldblock"}, {["x"] = 0, ["meta"] = {["fields"] = {}, ["inventory"] = {}}, ["y"] = 26, ["param1"] = 92, ["z"] = 3, ["name"] = "default:goldblock"}, {["x"] = 0, ["meta"] = {["fields"] = {}, ["inventory"] = {}}, ["y"] = 26, ["param1"] = 92, ["z"] = 4, ["name"] = "default:goldblock"}, {["x"] = 0, ["meta"] = {["fields"] = {}, ["inventory"] = {}}, ["y"] = 26, ["param1"] = 92, ["z"] = 5, ["name"] = "default:goldblock"}, {["x"] = 0, ["meta"] = {["fields"] = {}, ["inventory"] = {}}, ["y"] = 26, ["param1"] = 92, ["z"] = 6, ["name"] = "default:goldblock"}, {["x"] = 0, ["y"] = 26, ["z"] = 7, ["name"] = "default:goldblock"}, {["x"] = 0, ["y"] = 26, ["param1"] = 92, ["z"] = 9, ["name"] = "default:goldblock"}, {["x"] = 1, ["y"] = 0, ["param1"] = 92, ["z"] = 0, ["name"] = "default:goldblock"}, {["x"] = 1, ["y"] = 0, ["param1"] = 92, ["z"] = 1, ["name"] = "default:goldblock"}, {["x"] = 1, ["y"] = 0, ["param1"] = 92, ["z"] = 2, ["name"] = "default:goldblock"}, {["x"] = 1, ["y"] = 0, ["param1"] = 92, ["z"] = 3, ["name"] = "default:goldblock"}, {["x"] = 1, ["y"] = 0, ["param1"] = 92, ["z"] = 4, ["name"] = "default:goldblock"}, {["x"] = 1, ["y"] = 0, ["param1"] = 92, ["z"] = 5, ["name"] = "default:goldblock"}, {["x"] = 1, ["y"] = 0, ["param1"] = 92, ["z"] = 6, ["name"] = "default:goldblock"}, {["x"] = 1, ["y"] = 0, ["param1"] = 92, ["z"] = 7, ["name"] = "default:goldblock"}, {["x"] = 1, ["y"] = 0, ["param1"] = 92, ["z"] = 8, ["name"] = "default:goldblock"}, {["x"] = 1, ["y"] = 0, ["param1"] = 92, ["z"] = 9, ["name"] = "default:goldblock"}, {["x"] = 1, ["y"] = 1, ["param1"] = 83, ["z"] = 0, ["name"] = "default:steelblock"}, {["x"] = 1, ["y"] = 1, ["param1"] = 238, ["z"] = 1, ["name"] = "default:meselamp"}, {["x"] = 1, ["y"] = 1, ["param1"] = 238, ["z"] = 8, ["name"] = "default:meselamp"}, {["x"] = 1, ["y"] = 1, ["param1"] = 83, ["z"] = 9, ["name"] = "default:steelblock"}, {["x"] = 1, ["y"] = 2, ["param1"] = 88, ["z"] = 0, ["name"] = "default:bronzeblock"}, {["x"] = 1, ["y"] = 2, ["param1"] = 83, ["z"] = 1, ["name"] = "default:steelblock"}, {["x"] = 1, ["y"] = 2, ["param1"] = 83, ["z"] = 8, ["name"] = "default:steelblock"}, {["x"] = 1, ["y"] = 2, ["param1"] = 88, ["z"] = 9, ["name"] = "default:bronzeblock"}, {["x"] = 1, ["y"] = 3, ["param1"] = 238, ["z"] = 0, ["name"] = "default:meselamp"}, {["x"] = 1, ["y"] = 3, ["param1"] = 83, ["z"] = 1, ["name"] = "default:steelblock"}, {["x"] = 1, ["y"] = 3, ["param1"] = 83, ["z"] = 8, ["name"] = "default:steelblock"}, {["x"] = 1, ["y"] = 3, ["param1"] = 238, ["z"] = 9, ["name"] = "default:meselamp"}, {["x"] = 1, ["y"] = 4, ["param1"] = 83, ["z"] = 0, ["name"] = "default:steelblock"}, {["x"] = 1, ["y"] = 4, ["param1"] = 83, ["z"] = 1, ["name"] = "default:steelblock"}, {["x"] = 1, ["y"] = 4, ["param1"] = 83, ["z"] = 8, ["name"] = "default:steelblock"}, {["x"] = 1, ["y"] = 4, ["param1"] = 83, ["z"] = 9, ["name"] = "default:steelblock"}, {["x"] = 1, ["meta"] = {["fields"] = {}, ["inventory"] = {}}, ["y"] = 5, ["param1"] = 92, ["z"] = 0, ["name"] = "default:goldblock"}, {["x"] = 1, ["meta"] = {["fields"] = {}, ["inventory"] = {}}, ["y"] = 5, ["param1"] = 92, ["z"] = 1, ["name"] = "default:goldblock"}, {["x"] = 1, ["meta"] = {["fields"] = {}, ["inventory"] = {}}, ["y"] = 5, ["param1"] = 92, ["z"] = 2, ["name"] = "default:goldblock"}, {["x"] = 1, ["meta"] = {["fields"] = {}, ["inventory"] = {}}, ["y"] = 5, ["param1"] = 92, ["z"] = 3, ["name"] = "default:goldblock"}, {["x"] = 1, ["meta"] = {["fields"] = {}, ["inventory"] = {}}, ["y"] = 5, ["param1"] = 207, ["z"] = 4, ["name"] = "default:glass"}, {["x"] = 1, ["meta"] = {["fields"] = {}, ["inventory"] = {}}, ["y"] = 5, ["param1"] = 207, ["z"] = 5, ["name"] = "default:glass"}, {["x"] = 1, ["meta"] = {["fields"] = {}, ["inventory"] = {}}, ["y"] = 5, ["param1"] = 92, ["z"] = 6, ["name"] = "default:goldblock"}, {["x"] = 1, ["meta"] = {["fields"] = {}, ["inventory"] = {}}, ["y"] = 5, ["param1"] = 92, ["z"] = 7, ["name"] = "default:goldblock"}, {["x"] = 1, ["meta"] = {["fields"] = {}, ["inventory"] = {}}, ["y"] = 5, ["param1"] = 92, ["z"] = 8, ["name"] = "default:goldblock"}, {["x"] = 1, ["meta"] = {["fields"] = {}, ["inventory"] = {}}, ["y"] = 5, ["param1"] = 92, ["z"] = 9, ["name"] = "default:goldblock"}, {["x"] = 1, ["meta"] = {["fields"] = {}, ["inventory"] = {}}, ["y"] = 6, ["param1"] = 92, ["z"] = 0, ["name"] = "default:goldblock"}, {["x"] = 1, ["meta"] = {["fields"] = {}, ["inventory"] = {}}, ["y"] = 6, ["param1"] = 92, ["z"] = 1, ["name"] = "default:goldblock"}, {["x"] = 1, ["meta"] = {["fields"] = {}, ["inventory"] = {}}, ["y"] = 6, ["param1"] = 92, ["z"] = 2, ["name"] = "default:goldblock"}, {["x"] = 1, ["meta"] = {["fields"] = {}, ["inventory"] = {}}, ["y"] = 6, ["param1"] = 92, ["z"] = 3, ["name"] = "default:goldblock"}, {["x"] = 1, ["meta"] = {["fields"] = {}, ["inventory"] = {}}, ["y"] = 6, ["param1"] = 191, ["z"] = 4, ["name"] = "default:glass"}, {["x"] = 1, ["meta"] = {["fields"] = {}, ["inventory"] = {}}, ["y"] = 6, ["param1"] = 191, ["z"] = 5, ["name"] = "default:glass"}, {["x"] = 1, ["meta"] = {["fields"] = {}, ["inventory"] = {}}, ["y"] = 6, ["param1"] = 92, ["z"] = 6, ["name"] = "default:goldblock"}, {["x"] = 1, ["meta"] = {["fields"] = {}, ["inventory"] = {}}, ["y"] = 6, ["param1"] = 92, ["z"] = 7, ["name"] = "default:goldblock"}, {["x"] = 1, ["meta"] = {["fields"] = {}, ["inventory"] = {}}, ["y"] = 6, ["param1"] = 92, ["z"] = 8, ["name"] = "default:goldblock"}, {["x"] = 1, ["meta"] = {["fields"] = {}, ["inventory"] = {}}, ["y"] = 6, ["param1"] = 92, ["z"] = 9, ["name"] = "default:goldblock"}, {["x"] = 1, ["meta"] = {["fields"] = {}, ["inventory"] = {}}, ["y"] = 7, ["param1"] = 92, ["z"] = 0, ["name"] = "default:goldblock"}, {["x"] = 1, ["meta"] = {["fields"] = {}, ["inventory"] = {}}, ["y"] = 7, ["param1"] = 92, ["z"] = 1, ["name"] = "default:goldblock"}, {["x"] = 1, ["meta"] = {["fields"] = {}, ["inventory"] = {}}, ["y"] = 7, ["param1"] = 92, ["z"] = 2, ["name"] = "default:goldblock"}, {["x"] = 1, ["meta"] = {["fields"] = {}, ["inventory"] = {}}, ["y"] = 7, ["param1"] = 92, ["z"] = 3, ["name"] = "default:goldblock"}, {["x"] = 1, ["meta"] = {["fields"] = {}, ["inventory"] = {}}, ["y"] = 7, ["param1"] = 175, ["z"] = 4, ["name"] = "default:glass"}, {["x"] = 1, ["meta"] = {["fields"] = {}, ["inventory"] = {}}, ["y"] = 7, ["param1"] = 175, ["z"] = 5, ["name"] = "default:glass"}, {["x"] = 1, ["meta"] = {["fields"] = {}, ["inventory"] = {}}, ["y"] = 7, ["param1"] = 92, ["z"] = 6, ["name"] = "default:goldblock"}, {["x"] = 1, ["meta"] = {["fields"] = {}, ["inventory"] = {}}, ["y"] = 7, ["param1"] = 92, ["z"] = 7, ["name"] = "default:goldblock"}, {["x"] = 1, ["meta"] = {["fields"] = {}, ["inventory"] = {}}, ["y"] = 7, ["param1"] = 92, ["z"] = 8, ["name"] = "default:goldblock"}, {["x"] = 1, ["meta"] = {["fields"] = {}, ["inventory"] = {}}, ["y"] = 7, ["param1"] = 92, ["z"] = 9, ["name"] = "default:goldblock"}, {["x"] = 1, ["meta"] = {["fields"] = {}, ["inventory"] = {}}, ["y"] = 8, ["param1"] = 92, ["z"] = 0, ["name"] = "default:goldblock"}, {["x"] = 1, ["meta"] = {["fields"] = {}, ["inventory"] = {}}, ["y"] = 8, ["param1"] = 92, ["z"] = 1, ["name"] = "default:goldblock"}, {["x"] = 1, ["meta"] = {["fields"] = {}, ["inventory"] = {}}, ["y"] = 8, ["param1"] = 92, ["z"] = 2, ["name"] = "default:goldblock"}, {["x"] = 1, ["meta"] = {["fields"] = {}, ["inventory"] = {}}, ["y"] = 8, ["param1"] = 92, ["z"] = 3, ["name"] = "default:goldblock"}, {["x"] = 1, ["meta"] = {["fields"] = {}, ["inventory"] = {}}, ["y"] = 8, ["param1"] = 159, ["z"] = 4, ["name"] = "default:glass"}, {["x"] = 1, ["meta"] = {["fields"] = {}, ["inventory"] = {}}, ["y"] = 8, ["param1"] = 159, ["z"] = 5, ["name"] = "default:glass"}, {["x"] = 1, ["meta"] = {["fields"] = {}, ["inventory"] = {}}, ["y"] = 8, ["param1"] = 92, ["z"] = 6, ["name"] = "default:goldblock"}, {["x"] = 1, ["meta"] = {["fields"] = {}, ["inventory"] = {}}, ["y"] = 8, ["param1"] = 92, ["z"] = 7, ["name"] = "default:goldblock"}, {["x"] = 1, ["meta"] = {["fields"] = {}, ["inventory"] = {}}, ["y"] = 8, ["param1"] = 92, ["z"] = 8, ["name"] = "default:goldblock"}, {["x"] = 1, ["meta"] = {["fields"] = {}, ["inventory"] = {}}, ["y"] = 8, ["param1"] = 92, ["z"] = 9, ["name"] = "default:goldblock"}, {["x"] = 1, ["meta"] = {["fields"] = {}, ["inventory"] = {}}, ["y"] = 9, ["param1"] = 92, ["z"] = 0, ["name"] = "default:goldblock"}, {["x"] = 1, ["meta"] = {["fields"] = {}, ["inventory"] = {}}, ["y"] = 9, ["param1"] = 92, ["z"] = 1, ["name"] = "default:goldblock"}, {["x"] = 1, ["meta"] = {["fields"] = {}, ["inventory"] = {}}, ["y"] = 9, ["param1"] = 92, ["z"] = 2, ["name"] = "default:goldblock"}, {["x"] = 1, ["meta"] = {["fields"] = {}, ["inventory"] = {}}, ["y"] = 9, ["param1"] = 92, ["z"] = 3, ["name"] = "default:goldblock"}, {["x"] = 1, ["meta"] = {["fields"] = {}, ["inventory"] = {}}, ["y"] = 9, ["param1"] = 143, ["z"] = 4, ["name"] = "default:glass"}, {["x"] = 1, ["meta"] = {["fields"] = {}, ["inventory"] = {}}, ["y"] = 9, ["param1"] = 143, ["z"] = 5, ["name"] = "default:glass"}, {["x"] = 1, ["meta"] = {["fields"] = {}, ["inventory"] = {}}, ["y"] = 9, ["param1"] = 92, ["z"] = 6, ["name"] = "default:goldblock"}, {["x"] = 1, ["meta"] = {["fields"] = {}, ["inventory"] = {}}, ["y"] = 9, ["param1"] = 92, ["z"] = 7, ["name"] = "default:goldblock"}, {["x"] = 1, ["meta"] = {["fields"] = {}, ["inventory"] = {}}, ["y"] = 9, ["param1"] = 92, ["z"] = 8, ["name"] = "default:goldblock"}, {["x"] = 1, ["meta"] = {["fields"] = {}, ["inventory"] = {}}, ["y"] = 9, ["param1"] = 92, ["z"] = 9, ["name"] = "default:goldblock"}, {["x"] = 1, ["meta"] = {["fields"] = {}, ["inventory"] = {}}, ["y"] = 10, ["param1"] = 92, ["z"] = 0, ["name"] = "default:goldblock"}, {["x"] = 1, ["meta"] = {["fields"] = {}, ["inventory"] = {}}, ["y"] = 10, ["param1"] = 92, ["z"] = 1, ["name"] = "default:goldblock"}, {["x"] = 1, ["meta"] = {["fields"] = {}, ["inventory"] = {}}, ["y"] = 10, ["param1"] = 92, ["z"] = 2, ["name"] = "default:goldblock"}, {["x"] = 1, ["meta"] = {["fields"] = {}, ["inventory"] = {}}, ["y"] = 10, ["param1"] = 92, ["z"] = 3, ["name"] = "default:goldblock"}, {["x"] = 1, ["meta"] = {["fields"] = {}, ["inventory"] = {}}, ["y"] = 10, ["param1"] = 127, ["z"] = 4, ["name"] = "default:glass"}, {["x"] = 1, ["meta"] = {["fields"] = {}, ["inventory"] = {}}, ["y"] = 10, ["param1"] = 127, ["z"] = 5, ["name"] = "default:glass"}, {["x"] = 1, ["meta"] = {["fields"] = {}, ["inventory"] = {}}, ["y"] = 10, ["param1"] = 92, ["z"] = 6, ["name"] = "default:goldblock"}, {["x"] = 1, ["meta"] = {["fields"] = {}, ["inventory"] = {}}, ["y"] = 10, ["param1"] = 92, ["z"] = 7, ["name"] = "default:goldblock"}, {["x"] = 1, ["meta"] = {["fields"] = {}, ["inventory"] = {}}, ["y"] = 10, ["param1"] = 92, ["z"] = 8, ["name"] = "default:goldblock"}, {["x"] = 1, ["meta"] = {["fields"] = {}, ["inventory"] = {}}, ["y"] = 10, ["param1"] = 92, ["z"] = 9, ["name"] = "default:goldblock"}, {["x"] = 1, ["meta"] = {["fields"] = {}, ["inventory"] = {}}, ["y"] = 11, ["param1"] = 92, ["z"] = 0, ["name"] = "default:goldblock"}, {["x"] = 1, ["meta"] = {["fields"] = {}, ["inventory"] = {}}, ["y"] = 11, ["param1"] = 92, ["z"] = 1, ["name"] = "default:goldblock"}, {["x"] = 1, ["meta"] = {["fields"] = {}, ["inventory"] = {}}, ["y"] = 11, ["param1"] = 92, ["z"] = 2, ["name"] = "default:goldblock"}, {["x"] = 1, ["meta"] = {["fields"] = {}, ["inventory"] = {}}, ["y"] = 11, ["param1"] = 92, ["z"] = 3, ["name"] = "default:goldblock"}, {["x"] = 1, ["meta"] = {["fields"] = {}, ["inventory"] = {}}, ["y"] = 11, ["param1"] = 111, ["z"] = 4, ["name"] = "default:glass"}, {["x"] = 1, ["meta"] = {["fields"] = {}, ["inventory"] = {}}, ["y"] = 11, ["param1"] = 111, ["z"] = 5, ["name"] = "default:glass"}, {["x"] = 1, ["meta"] = {["fields"] = {}, ["inventory"] = {}}, ["y"] = 11, ["param1"] = 92, ["z"] = 6, ["name"] = "default:goldblock"}, {["x"] = 1, ["meta"] = {["fields"] = {}, ["inventory"] = {}}, ["y"] = 11, ["param1"] = 92, ["z"] = 7, ["name"] = "default:goldblock"}, {["x"] = 1, ["meta"] = {["fields"] = {}, ["inventory"] = {}}, ["y"] = 11, ["param1"] = 92, ["z"] = 8, ["name"] = "default:goldblock"}, {["x"] = 1, ["meta"] = {["fields"] = {}, ["inventory"] = {}}, ["y"] = 11, ["param1"] = 92, ["z"] = 9, ["name"] = "default:goldblock"}, {["x"] = 1, ["meta"] = {["fields"] = {}, ["inventory"] = {}}, ["y"] = 12, ["param1"] = 92, ["z"] = 0, ["name"] = "default:goldblock"}, {["x"] = 1, ["meta"] = {["fields"] = {}, ["inventory"] = {}}, ["y"] = 12, ["param1"] = 92, ["z"] = 1, ["name"] = "default:goldblock"}, {["x"] = 1, ["meta"] = {["fields"] = {}, ["inventory"] = {}}, ["y"] = 12, ["param1"] = 92, ["z"] = 2, ["name"] = "default:goldblock"}, {["x"] = 1, ["meta"] = {["fields"] = {}, ["inventory"] = {}}, ["y"] = 12, ["param1"] = 92, ["z"] = 3, ["name"] = "default:goldblock"}, {["x"] = 1, ["meta"] = {["fields"] = {}, ["inventory"] = {}}, ["y"] = 12, ["param1"] = 95, ["z"] = 4, ["name"] = "default:glass"}, {["x"] = 1, ["meta"] = {["fields"] = {}, ["inventory"] = {}}, ["y"] = 12, ["param1"] = 95, ["z"] = 5, ["name"] = "default:glass"}, {["x"] = 1, ["meta"] = {["fields"] = {}, ["inventory"] = {}}, ["y"] = 12, ["param1"] = 92, ["z"] = 6, ["name"] = "default:goldblock"}, {["x"] = 1, ["meta"] = {["fields"] = {}, ["inventory"] = {}}, ["y"] = 12, ["param1"] = 92, ["z"] = 7, ["name"] = "default:goldblock"}, {["x"] = 1, ["meta"] = {["fields"] = {}, ["inventory"] = {}}, ["y"] = 12, ["param1"] = 92, ["z"] = 8, ["name"] = "default:goldblock"}, {["x"] = 1, ["meta"] = {["fields"] = {}, ["inventory"] = {}}, ["y"] = 12, ["param1"] = 92, ["z"] = 9, ["name"] = "default:goldblock"}, {["x"] = 1, ["meta"] = {["fields"] = {}, ["inventory"] = {}}, ["y"] = 13, ["param1"] = 92, ["z"] = 0, ["name"] = "default:goldblock"}, {["x"] = 1, ["meta"] = {["fields"] = {}, ["inventory"] = {}}, ["y"] = 13, ["param1"] = 92, ["z"] = 1, ["name"] = "default:goldblock"}, {["x"] = 1, ["meta"] = {["fields"] = {}, ["inventory"] = {}}, ["y"] = 13, ["param1"] = 92, ["z"] = 2, ["name"] = "default:goldblock"}, {["x"] = 1, ["meta"] = {["fields"] = {}, ["inventory"] = {}}, ["y"] = 13, ["param1"] = 92, ["z"] = 3, ["name"] = "default:goldblock"}, {["x"] = 1, ["meta"] = {["fields"] = {}, ["inventory"] = {}}, ["y"] = 13, ["param1"] = 79, ["z"] = 4, ["name"] = "default:glass"}, {["x"] = 1, ["meta"] = {["fields"] = {}, ["inventory"] = {}}, ["y"] = 13, ["param1"] = 79, ["z"] = 5, ["name"] = "default:glass"}, {["x"] = 1, ["meta"] = {["fields"] = {}, ["inventory"] = {}}, ["y"] = 13, ["param1"] = 92, ["z"] = 6, ["name"] = "default:goldblock"}, {["x"] = 1, ["meta"] = {["fields"] = {}, ["inventory"] = {}}, ["y"] = 13, ["param1"] = 92, ["z"] = 7, ["name"] = "default:goldblock"}, {["x"] = 1, ["meta"] = {["fields"] = {}, ["inventory"] = {}}, ["y"] = 13, ["param1"] = 92, ["z"] = 8, ["name"] = "default:goldblock"}, {["x"] = 1, ["meta"] = {["fields"] = {}, ["inventory"] = {}}, ["y"] = 13, ["param1"] = 92, ["z"] = 9, ["name"] = "default:goldblock"}, {["x"] = 1, ["meta"] = {["fields"] = {}, ["inventory"] = {}}, ["y"] = 14, ["param1"] = 92, ["z"] = 0, ["name"] = "default:goldblock"}, {["x"] = 1, ["meta"] = {["fields"] = {}, ["inventory"] = {}}, ["y"] = 14, ["param1"] = 92, ["z"] = 1, ["name"] = "default:goldblock"}, {["x"] = 1, ["meta"] = {["fields"] = {}, ["inventory"] = {}}, ["y"] = 14, ["param1"] = 92, ["z"] = 2, ["name"] = "default:goldblock"}, {["x"] = 1, ["meta"] = {["fields"] = {}, ["inventory"] = {}}, ["y"] = 14, ["param1"] = 92, ["z"] = 3, ["name"] = "default:goldblock"}, {["x"] = 1, ["meta"] = {["fields"] = {}, ["inventory"] = {}}, ["y"] = 14, ["param1"] = 63, ["z"] = 4, ["name"] = "default:glass"}, {["x"] = 1, ["meta"] = {["fields"] = {}, ["inventory"] = {}}, ["y"] = 14, ["param1"] = 63, ["z"] = 5, ["name"] = "default:glass"}, {["x"] = 1, ["meta"] = {["fields"] = {}, ["inventory"] = {}}, ["y"] = 14, ["param1"] = 92, ["z"] = 6, ["name"] = "default:goldblock"}, {["x"] = 1, ["meta"] = {["fields"] = {}, ["inventory"] = {}}, ["y"] = 14, ["param1"] = 92, ["z"] = 7, ["name"] = "default:goldblock"}, {["x"] = 1, ["meta"] = {["fields"] = {}, ["inventory"] = {}}, ["y"] = 14, ["param1"] = 92, ["z"] = 8, ["name"] = "default:goldblock"}, {["x"] = 1, ["meta"] = {["fields"] = {}, ["inventory"] = {}}, ["y"] = 14, ["param1"] = 92, ["z"] = 9, ["name"] = "default:goldblock"}, {["x"] = 1, ["meta"] = {["fields"] = {}, ["inventory"] = {}}, ["y"] = 15, ["param1"] = 92, ["z"] = 0, ["name"] = "default:goldblock"}, {["x"] = 1, ["meta"] = {["fields"] = {}, ["inventory"] = {}}, ["y"] = 15, ["param1"] = 92, ["z"] = 1, ["name"] = "default:goldblock"}, {["x"] = 1, ["meta"] = {["fields"] = {}, ["inventory"] = {}}, ["y"] = 15, ["param1"] = 92, ["z"] = 2, ["name"] = "default:goldblock"}, {["x"] = 1, ["meta"] = {["fields"] = {}, ["inventory"] = {}}, ["y"] = 15, ["param1"] = 92, ["z"] = 3, ["name"] = "default:goldblock"}, {["x"] = 1, ["meta"] = {["fields"] = {}, ["inventory"] = {}}, ["y"] = 15, ["param1"] = 47, ["z"] = 4, ["name"] = "default:glass"}, {["x"] = 1, ["meta"] = {["fields"] = {}, ["inventory"] = {}}, ["y"] = 15, ["param1"] = 47, ["z"] = 5, ["name"] = "default:glass"}, {["x"] = 1, ["meta"] = {["fields"] = {}, ["inventory"] = {}}, ["y"] = 15, ["param1"] = 92, ["z"] = 6, ["name"] = "default:goldblock"}, {["x"] = 1, ["meta"] = {["fields"] = {}, ["inventory"] = {}}, ["y"] = 15, ["param1"] = 92, ["z"] = 7, ["name"] = "default:goldblock"}, {["x"] = 1, ["meta"] = {["fields"] = {}, ["inventory"] = {}}, ["y"] = 15, ["param1"] = 92, ["z"] = 8, ["name"] = "default:goldblock"}, {["x"] = 1, ["meta"] = {["fields"] = {}, ["inventory"] = {}}, ["y"] = 15, ["param1"] = 92, ["z"] = 9, ["name"] = "default:goldblock"}, {["x"] = 1, ["meta"] = {["fields"] = {}, ["inventory"] = {}}, ["y"] = 16, ["param1"] = 92, ["z"] = 0, ["name"] = "default:goldblock"}, {["x"] = 1, ["meta"] = {["fields"] = {}, ["inventory"] = {}}, ["y"] = 16, ["param1"] = 92, ["z"] = 1, ["name"] = "default:goldblock"}, {["x"] = 1, ["meta"] = {["fields"] = {}, ["inventory"] = {}}, ["y"] = 16, ["param1"] = 92, ["z"] = 2, ["name"] = "default:goldblock"}, {["x"] = 1, ["meta"] = {["fields"] = {}, ["inventory"] = {}}, ["y"] = 16, ["param1"] = 92, ["z"] = 3, ["name"] = "default:goldblock"}, {["x"] = 1, ["meta"] = {["fields"] = {}, ["inventory"] = {}}, ["y"] = 16, ["param1"] = 31, ["z"] = 4, ["name"] = "default:glass"}, {["x"] = 1, ["meta"] = {["fields"] = {}, ["inventory"] = {}}, ["y"] = 16, ["param1"] = 31, ["z"] = 5, ["name"] = "default:glass"}, {["x"] = 1, ["meta"] = {["fields"] = {}, ["inventory"] = {}}, ["y"] = 16, ["param1"] = 92, ["z"] = 6, ["name"] = "default:goldblock"}, {["x"] = 1, ["meta"] = {["fields"] = {}, ["inventory"] = {}}, ["y"] = 16, ["param1"] = 92, ["z"] = 7, ["name"] = "default:goldblock"}, {["x"] = 1, ["meta"] = {["fields"] = {}, ["inventory"] = {}}, ["y"] = 16, ["param1"] = 92, ["z"] = 8, ["name"] = "default:goldblock"}, {["x"] = 1, ["meta"] = {["fields"] = {}, ["inventory"] = {}}, ["y"] = 16, ["param1"] = 92, ["z"] = 9, ["name"] = "default:goldblock"}, {["x"] = 1, ["meta"] = {["fields"] = {}, ["inventory"] = {}}, ["y"] = 17, ["param1"] = 92, ["z"] = 0, ["name"] = "default:goldblock"}, {["x"] = 1, ["meta"] = {["fields"] = {}, ["inventory"] = {}}, ["y"] = 17, ["param1"] = 92, ["z"] = 1, ["name"] = "default:goldblock"}, {["x"] = 1, ["meta"] = {["fields"] = {}, ["inventory"] = {}}, ["y"] = 17, ["param1"] = 92, ["z"] = 2, ["name"] = "default:goldblock"}, {["x"] = 1, ["meta"] = {["fields"] = {}, ["inventory"] = {}}, ["y"] = 17, ["param1"] = 92, ["z"] = 3, ["name"] = "default:goldblock"}, {["x"] = 1, ["meta"] = {["fields"] = {}, ["inventory"] = {}}, ["y"] = 17, ["param1"] = 15, ["z"] = 4, ["name"] = "default:glass"}, {["x"] = 1, ["meta"] = {["fields"] = {}, ["inventory"] = {}}, ["y"] = 17, ["param1"] = 15, ["z"] = 5, ["name"] = "default:glass"}, {["x"] = 1, ["meta"] = {["fields"] = {}, ["inventory"] = {}}, ["y"] = 17, ["param1"] = 92, ["z"] = 6, ["name"] = "default:goldblock"}, {["x"] = 1, ["meta"] = {["fields"] = {}, ["inventory"] = {}}, ["y"] = 17, ["param1"] = 92, ["z"] = 7, ["name"] = "default:goldblock"}, {["x"] = 1, ["meta"] = {["fields"] = {}, ["inventory"] = {}}, ["y"] = 17, ["param1"] = 92, ["z"] = 8, ["name"] = "default:goldblock"}, {["x"] = 1, ["meta"] = {["fields"] = {}, ["inventory"] = {}}, ["y"] = 17, ["param1"] = 92, ["z"] = 9, ["name"] = "default:goldblock"}, {["x"] = 1, ["meta"] = {["fields"] = {}, ["inventory"] = {}}, ["y"] = 18, ["param1"] = 92, ["z"] = 0, ["name"] = "default:goldblock"}, {["x"] = 1, ["meta"] = {["fields"] = {}, ["inventory"] = {}}, ["y"] = 18, ["param1"] = 92, ["z"] = 1, ["name"] = "default:goldblock"}, {["x"] = 1, ["meta"] = {["fields"] = {}, ["inventory"] = {}}, ["y"] = 18, ["param1"] = 92, ["z"] = 2, ["name"] = "default:goldblock"}, {["x"] = 1, ["meta"] = {["fields"] = {}, ["inventory"] = {}}, ["y"] = 18, ["param1"] = 92, ["z"] = 3, ["name"] = "default:goldblock"}, {["x"] = 1, ["meta"] = {["fields"] = {}, ["inventory"] = {}}, ["y"] = 18, ["param1"] = 15, ["z"] = 4, ["name"] = "default:glass"}, {["x"] = 1, ["meta"] = {["fields"] = {}, ["inventory"] = {}}, ["y"] = 18, ["param1"] = 15, ["z"] = 5, ["name"] = "default:glass"}, {["x"] = 1, ["meta"] = {["fields"] = {}, ["inventory"] = {}}, ["y"] = 18, ["param1"] = 92, ["z"] = 6, ["name"] = "default:goldblock"}, {["x"] = 1, ["meta"] = {["fields"] = {}, ["inventory"] = {}}, ["y"] = 18, ["param1"] = 92, ["z"] = 7, ["name"] = "default:goldblock"}, {["x"] = 1, ["meta"] = {["fields"] = {}, ["inventory"] = {}}, ["y"] = 18, ["param1"] = 92, ["z"] = 8, ["name"] = "default:goldblock"}, {["x"] = 1, ["meta"] = {["fields"] = {}, ["inventory"] = {}}, ["y"] = 18, ["param1"] = 92, ["z"] = 9, ["name"] = "default:goldblock"}, {["x"] = 1, ["meta"] = {["fields"] = {}, ["inventory"] = {}}, ["y"] = 19, ["param1"] = 92, ["z"] = 0, ["name"] = "default:goldblock"}, {["x"] = 1, ["meta"] = {["fields"] = {}, ["inventory"] = {}}, ["y"] = 19, ["param1"] = 92, ["z"] = 1, ["name"] = "default:goldblock"}, {["x"] = 1, ["meta"] = {["fields"] = {}, ["inventory"] = {}}, ["y"] = 19, ["param1"] = 92, ["z"] = 2, ["name"] = "default:goldblock"}, {["x"] = 1, ["meta"] = {["fields"] = {}, ["inventory"] = {}}, ["y"] = 19, ["param1"] = 92, ["z"] = 3, ["name"] = "default:goldblock"}, {["x"] = 1, ["meta"] = {["fields"] = {}, ["inventory"] = {}}, ["y"] = 19, ["param1"] = 15, ["z"] = 4, ["name"] = "default:glass"}, {["x"] = 1, ["meta"] = {["fields"] = {}, ["inventory"] = {}}, ["y"] = 19, ["param1"] = 15, ["z"] = 5, ["name"] = "default:glass"}, {["x"] = 1, ["meta"] = {["fields"] = {}, ["inventory"] = {}}, ["y"] = 19, ["param1"] = 92, ["z"] = 6, ["name"] = "default:goldblock"}, {["x"] = 1, ["meta"] = {["fields"] = {}, ["inventory"] = {}}, ["y"] = 19, ["param1"] = 92, ["z"] = 7, ["name"] = "default:goldblock"}, {["x"] = 1, ["meta"] = {["fields"] = {}, ["inventory"] = {}}, ["y"] = 19, ["param1"] = 92, ["z"] = 8, ["name"] = "default:goldblock"}, {["x"] = 1, ["meta"] = {["fields"] = {}, ["inventory"] = {}}, ["y"] = 19, ["param1"] = 92, ["z"] = 9, ["name"] = "default:goldblock"}, {["x"] = 1, ["meta"] = {["fields"] = {}, ["inventory"] = {}}, ["y"] = 20, ["param1"] = 92, ["z"] = 0, ["name"] = "default:goldblock"}, {["x"] = 1, ["meta"] = {["fields"] = {}, ["inventory"] = {}}, ["y"] = 20, ["param1"] = 92, ["z"] = 1, ["name"] = "default:goldblock"}, {["x"] = 1, ["meta"] = {["fields"] = {}, ["inventory"] = {}}, ["y"] = 20, ["param1"] = 92, ["z"] = 2, ["name"] = "default:goldblock"}, {["x"] = 1, ["meta"] = {["fields"] = {}, ["inventory"] = {}}, ["y"] = 20, ["param1"] = 92, ["z"] = 3, ["name"] = "default:goldblock"}, {["x"] = 1, ["meta"] = {["fields"] = {}, ["inventory"] = {}}, ["y"] = 20, ["param1"] = 15, ["z"] = 4, ["name"] = "default:glass"}, {["x"] = 1, ["meta"] = {["fields"] = {}, ["inventory"] = {}}, ["y"] = 20, ["param1"] = 15, ["z"] = 5, ["name"] = "default:glass"}, {["x"] = 1, ["meta"] = {["fields"] = {}, ["inventory"] = {}}, ["y"] = 20, ["param1"] = 92, ["z"] = 6, ["name"] = "default:goldblock"}, {["x"] = 1, ["meta"] = {["fields"] = {}, ["inventory"] = {}}, ["y"] = 20, ["param1"] = 92, ["z"] = 7, ["name"] = "default:goldblock"}, {["x"] = 1, ["meta"] = {["fields"] = {}, ["inventory"] = {}}, ["y"] = 20, ["param1"] = 92, ["z"] = 8, ["name"] = "default:goldblock"}, {["x"] = 1, ["meta"] = {["fields"] = {}, ["inventory"] = {}}, ["y"] = 20, ["param1"] = 92, ["z"] = 9, ["name"] = "default:goldblock"}, {["x"] = 1, ["meta"] = {["fields"] = {}, ["inventory"] = {}}, ["y"] = 21, ["param1"] = 92, ["z"] = 0, ["name"] = "default:goldblock"}, {["x"] = 1, ["meta"] = {["fields"] = {}, ["inventory"] = {}}, ["y"] = 21, ["param1"] = 92, ["z"] = 1, ["name"] = "default:goldblock"}, {["x"] = 1, ["meta"] = {["fields"] = {}, ["inventory"] = {}}, ["y"] = 21, ["param1"] = 92, ["z"] = 2, ["name"] = "default:goldblock"}, {["x"] = 1, ["meta"] = {["fields"] = {}, ["inventory"] = {}}, ["y"] = 21, ["param1"] = 92, ["z"] = 3, ["name"] = "default:goldblock"}, {["x"] = 1, ["meta"] = {["fields"] = {}, ["inventory"] = {}}, ["y"] = 21, ["param1"] = 15, ["z"] = 4, ["name"] = "default:glass"}, {["x"] = 1, ["meta"] = {["fields"] = {}, ["inventory"] = {}}, ["y"] = 21, ["param1"] = 15, ["z"] = 5, ["name"] = "default:glass"}, {["x"] = 1, ["meta"] = {["fields"] = {}, ["inventory"] = {}}, ["y"] = 21, ["param1"] = 92, ["z"] = 6, ["name"] = "default:goldblock"}, {["x"] = 1, ["meta"] = {["fields"] = {}, ["inventory"] = {}}, ["y"] = 21, ["param1"] = 92, ["z"] = 7, ["name"] = "default:goldblock"}, {["x"] = 1, ["meta"] = {["fields"] = {}, ["inventory"] = {}}, ["y"] = 21, ["param1"] = 92, ["z"] = 8, ["name"] = "default:goldblock"}, {["x"] = 1, ["meta"] = {["fields"] = {}, ["inventory"] = {}}, ["y"] = 21, ["param1"] = 92, ["z"] = 9, ["name"] = "default:goldblock"}, {["x"] = 1, ["meta"] = {["fields"] = {}, ["inventory"] = {}}, ["y"] = 22, ["param1"] = 92, ["z"] = 0, ["name"] = "default:goldblock"}, {["x"] = 1, ["meta"] = {["fields"] = {}, ["inventory"] = {}}, ["y"] = 22, ["param1"] = 92, ["z"] = 1, ["name"] = "default:goldblock"}, {["x"] = 1, ["meta"] = {["fields"] = {}, ["inventory"] = {}}, ["y"] = 22, ["param1"] = 92, ["z"] = 2, ["name"] = "default:goldblock"}, {["x"] = 1, ["meta"] = {["fields"] = {}, ["inventory"] = {}}, ["y"] = 22, ["param1"] = 92, ["z"] = 3, ["name"] = "default:goldblock"}, {["x"] = 1, ["meta"] = {["fields"] = {}, ["inventory"] = {}}, ["y"] = 22, ["param1"] = 15, ["z"] = 4, ["name"] = "default:glass"}, {["x"] = 1, ["meta"] = {["fields"] = {}, ["inventory"] = {}}, ["y"] = 22, ["param1"] = 15, ["z"] = 5, ["name"] = "default:glass"}, {["x"] = 1, ["meta"] = {["fields"] = {}, ["inventory"] = {}}, ["y"] = 22, ["param1"] = 92, ["z"] = 6, ["name"] = "default:goldblock"}, {["x"] = 1, ["meta"] = {["fields"] = {}, ["inventory"] = {}}, ["y"] = 22, ["param1"] = 92, ["z"] = 7, ["name"] = "default:goldblock"}, {["x"] = 1, ["meta"] = {["fields"] = {}, ["inventory"] = {}}, ["y"] = 22, ["param1"] = 92, ["z"] = 8, ["name"] = "default:goldblock"}, {["x"] = 1, ["meta"] = {["fields"] = {}, ["inventory"] = {}}, ["y"] = 22, ["param1"] = 92, ["z"] = 9, ["name"] = "default:goldblock"}, {["x"] = 1, ["meta"] = {["fields"] = {}, ["inventory"] = {}}, ["y"] = 23, ["param1"] = 92, ["z"] = 0, ["name"] = "default:goldblock"}, {["x"] = 1, ["meta"] = {["fields"] = {}, ["inventory"] = {}}, ["y"] = 23, ["param1"] = 92, ["z"] = 1, ["name"] = "default:goldblock"}, {["x"] = 1, ["meta"] = {["fields"] = {}, ["inventory"] = {}}, ["y"] = 23, ["param1"] = 92, ["z"] = 2, ["name"] = "default:goldblock"}, {["x"] = 1, ["meta"] = {["fields"] = {}, ["inventory"] = {}}, ["y"] = 23, ["param1"] = 92, ["z"] = 3, ["name"] = "default:goldblock"}, {["x"] = 1, ["meta"] = {["fields"] = {}, ["inventory"] = {}}, ["y"] = 23, ["param1"] = 15, ["z"] = 4, ["name"] = "default:glass"}, {["x"] = 1, ["meta"] = {["fields"] = {}, ["inventory"] = {}}, ["y"] = 23, ["param1"] = 15, ["z"] = 5, ["name"] = "default:glass"}, {["x"] = 1, ["meta"] = {["fields"] = {}, ["inventory"] = {}}, ["y"] = 23, ["param1"] = 92, ["z"] = 6, ["name"] = "default:goldblock"}, {["x"] = 1, ["meta"] = {["fields"] = {}, ["inventory"] = {}}, ["y"] = 23, ["param1"] = 92, ["z"] = 7, ["name"] = "default:goldblock"}, {["x"] = 1, ["meta"] = {["fields"] = {}, ["inventory"] = {}}, ["y"] = 23, ["param1"] = 92, ["z"] = 8, ["name"] = "default:goldblock"}, {["x"] = 1, ["meta"] = {["fields"] = {}, ["inventory"] = {}}, ["y"] = 23, ["param1"] = 92, ["z"] = 9, ["name"] = "default:goldblock"}, {["x"] = 1, ["meta"] = {["fields"] = {}, ["inventory"] = {}}, ["y"] = 24, ["param1"] = 92, ["z"] = 0, ["name"] = "default:goldblock"}, {["x"] = 1, ["meta"] = {["fields"] = {}, ["inventory"] = {}}, ["y"] = 24, ["param1"] = 92, ["z"] = 1, ["name"] = "default:goldblock"}, {["x"] = 1, ["meta"] = {["fields"] = {}, ["inventory"] = {}}, ["y"] = 24, ["param1"] = 92, ["z"] = 2, ["name"] = "default:goldblock"}, {["x"] = 1, ["meta"] = {["fields"] = {}, ["inventory"] = {}}, ["y"] = 24, ["param1"] = 92, ["z"] = 3, ["name"] = "default:goldblock"}, {["x"] = 1, ["meta"] = {["fields"] = {}, ["inventory"] = {}}, ["y"] = 24, ["param1"] = 14, ["z"] = 4, ["name"] = "default:glass"}, {["x"] = 1, ["meta"] = {["fields"] = {}, ["inventory"] = {}}, ["y"] = 24, ["param1"] = 14, ["z"] = 5, ["name"] = "default:glass"}, {["x"] = 1, ["meta"] = {["fields"] = {}, ["inventory"] = {}}, ["y"] = 24, ["param1"] = 92, ["z"] = 6, ["name"] = "default:goldblock"}, {["x"] = 1, ["meta"] = {["fields"] = {}, ["inventory"] = {}}, ["y"] = 24, ["param1"] = 92, ["z"] = 7, ["name"] = "default:goldblock"}, {["x"] = 1, ["meta"] = {["fields"] = {}, ["inventory"] = {}}, ["y"] = 24, ["param1"] = 92, ["z"] = 8, ["name"] = "default:goldblock"}, {["x"] = 1, ["meta"] = {["fields"] = {}, ["inventory"] = {}}, ["y"] = 24, ["param1"] = 92, ["z"] = 9, ["name"] = "default:goldblock"}, {["x"] = 1, ["meta"] = {["fields"] = {}, ["inventory"] = {}}, ["y"] = 25, ["param1"] = 92, ["z"] = 0, ["name"] = "default:goldblock"}, {["x"] = 1, ["meta"] = {["fields"] = {}, ["inventory"] = {}}, ["y"] = 25, ["param1"] = 92, ["z"] = 1, ["name"] = "default:goldblock"}, {["x"] = 1, ["meta"] = {["fields"] = {}, ["inventory"] = {}}, ["y"] = 25, ["param1"] = 92, ["z"] = 2, ["name"] = "default:goldblock"}, {["x"] = 1, ["meta"] = {["fields"] = {}, ["inventory"] = {}}, ["y"] = 25, ["param1"] = 92, ["z"] = 3, ["name"] = "default:goldblock"}, {["x"] = 1, ["meta"] = {["fields"] = {}, ["inventory"] = {}}, ["y"] = 25, ["param1"] = 13, ["z"] = 4, ["name"] = "default:glass"}, {["x"] = 1, ["meta"] = {["fields"] = {}, ["inventory"] = {}}, ["y"] = 25, ["param1"] = 13, ["z"] = 5, ["name"] = "default:glass"}, {["x"] = 1, ["meta"] = {["fields"] = {}, ["inventory"] = {}}, ["y"] = 25, ["param1"] = 92, ["z"] = 6, ["name"] = "default:goldblock"}, {["x"] = 1, ["meta"] = {["fields"] = {}, ["inventory"] = {}}, ["y"] = 25, ["param1"] = 92, ["z"] = 7, ["name"] = "default:goldblock"}, {["x"] = 1, ["meta"] = {["fields"] = {}, ["inventory"] = {}}, ["y"] = 25, ["param1"] = 92, ["z"] = 8, ["name"] = "default:goldblock"}, {["x"] = 1, ["meta"] = {["fields"] = {}, ["inventory"] = {}}, ["y"] = 25, ["param1"] = 92, ["z"] = 9, ["name"] = "default:goldblock"}, {["x"] = 1, ["meta"] = {["fields"] = {}, ["inventory"] = {}}, ["y"] = 26, ["param1"] = 92, ["z"] = 1, ["name"] = "default:goldblock"}, {["x"] = 1, ["meta"] = {["fields"] = {}, ["inventory"] = {}}, ["y"] = 26, ["param1"] = 92, ["z"] = 2, ["name"] = "default:goldblock"}, {["x"] = 1, ["meta"] = {["fields"] = {}, ["inventory"] = {}}, ["y"] = 26, ["param1"] = 92, ["z"] = 6, ["name"] = "default:goldblock"}, {["x"] = 1, ["meta"] = {["fields"] = {}, ["inventory"] = {}}, ["y"] = 26, ["param1"] = 92, ["z"] = 7, ["name"] = "default:goldblock"}, {["x"] = 1, ["y"] = 27, ["param1"] = 92, ["z"] = 3, ["name"] = "default:goldblock"}, {["x"] = 1, ["y"] = 27, ["param1"] = 92, ["z"] = 4, ["name"] = "default:goldblock"}, {["x"] = 1, ["y"] = 27, ["param1"] = 92, ["z"] = 5, ["name"] = "default:goldblock"}, {["x"] = 1, ["y"] = 28, ["param1"] = 92, ["z"] = 4, ["name"] = "default:goldblock"}, {["x"] = 2, ["y"] = 0, ["param1"] = 92, ["z"] = 0, ["name"] = "default:goldblock"}, {["x"] = 2, ["y"] = 0, ["param1"] = 92, ["z"] = 1, ["name"] = "default:goldblock"}, {["x"] = 2, ["y"] = 0, ["param1"] = 92, ["z"] = 2, ["name"] = "default:goldblock"}, {["x"] = 2, ["y"] = 0, ["param1"] = 92, ["z"] = 3, ["name"] = "default:goldblock"}, {["x"] = 2, ["y"] = 0, ["param1"] = 92, ["z"] = 4, ["name"] = "default:goldblock"}, {["x"] = 2, ["y"] = 0, ["param1"] = 92, ["z"] = 5, ["name"] = "default:goldblock"}, {["x"] = 2, ["y"] = 0, ["param1"] = 92, ["z"] = 6, ["name"] = "default:goldblock"}, {["x"] = 2, ["y"] = 0, ["param1"] = 92, ["z"] = 7, ["name"] = "default:goldblock"}, {["x"] = 2, ["y"] = 0, ["param1"] = 92, ["z"] = 8, ["name"] = "default:goldblock"}, {["x"] = 2, ["y"] = 0, ["param1"] = 92, ["z"] = 9, ["name"] = "default:goldblock"}, {["x"] = 2, ["y"] = 1, ["param1"] = 83, ["z"] = 0, ["name"] = "default:steelblock"}, {["x"] = 2, ["param2"] = 3, ["y"] = 1, ["param1"] = 223, ["z"] = 1, ["name"] = "default:ladder_steel"}, {["x"] = 2, ["param2"] = 3, ["y"] = 1, ["param1"] = 223, ["z"] = 8, ["name"] = "default:ladder_steel"}, {["x"] = 2, ["y"] = 1, ["param1"] = 83, ["z"] = 9, ["name"] = "default:steelblock"}, {["x"] = 2, ["y"] = 2, ["param1"] = 88, ["z"] = 0, ["name"] = "default:bronzeblock"}, {["x"] = 2, ["param2"] = 3, ["y"] = 2, ["param1"] = 207, ["z"] = 1, ["name"] = "default:ladder_steel"}, {["x"] = 2, ["param2"] = 3, ["y"] = 2, ["param1"] = 207, ["z"] = 8, ["name"] = "default:ladder_steel"}, {["x"] = 2, ["y"] = 2, ["param1"] = 88, ["z"] = 9, ["name"] = "default:bronzeblock"}, {["x"] = 2, ["y"] = 3, ["param1"] = 238, ["z"] = 0, ["name"] = "default:meselamp"}, {["x"] = 2, ["param2"] = 3, ["y"] = 3, ["param1"] = 223, ["z"] = 1, ["name"] = "default:ladder_steel"}, {["x"] = 2, ["param2"] = 3, ["y"] = 3, ["param1"] = 223, ["z"] = 8, ["name"] = "default:ladder_steel"}, {["x"] = 2, ["y"] = 3, ["param1"] = 238, ["z"] = 9, ["name"] = "default:meselamp"}, {["x"] = 2, ["y"] = 4, ["param1"] = 238, ["z"] = 0, ["name"] = "default:meselamp"}, {["x"] = 2, ["param2"] = 3, ["y"] = 4, ["param1"] = 223, ["z"] = 1, ["name"] = "default:ladder_steel"}, {["x"] = 2, ["param2"] = 3, ["y"] = 4, ["param1"] = 223, ["z"] = 8, ["name"] = "default:ladder_steel"}, {["x"] = 2, ["y"] = 4, ["param1"] = 238, ["z"] = 9, ["name"] = "default:meselamp"}, {["x"] = 2, ["meta"] = {["fields"] = {}, ["inventory"] = {}}, ["y"] = 5, ["param1"] = 92, ["z"] = 0, ["name"] = "default:goldblock"}, {["x"] = 2, ["meta"] = {["fields"] = {}, ["inventory"] = {}}, ["param2"] = 3, ["y"] = 5, ["param1"] = 207, ["z"] = 1, ["name"] = "default:ladder_steel"}, {["x"] = 2, ["meta"] = {["fields"] = {}, ["inventory"] = {}}, ["y"] = 5, ["param1"] = 191, ["z"] = 2, ["name"] = "default:goldblock"}, {["x"] = 2, ["meta"] = {["fields"] = {}, ["inventory"] = {}}, ["y"] = 5, ["param1"] = 191, ["z"] = 3, ["name"] = "default:goldblock"}, {["x"] = 2, ["meta"] = {["fields"] = {}, ["inventory"] = {}}, ["y"] = 5, ["param1"] = 191, ["z"] = 4, ["name"] = "default:goldblock"}, {["x"] = 2, ["meta"] = {["fields"] = {}, ["inventory"] = {}}, ["y"] = 5, ["param1"] = 191, ["z"] = 5, ["name"] = "default:goldblock"}, {["x"] = 2, ["meta"] = {["fields"] = {}, ["inventory"] = {}}, ["y"] = 5, ["param1"] = 191, ["z"] = 6, ["name"] = "default:goldblock"}, {["x"] = 2, ["y"] = 5, ["z"] = 7, ["name"] = "default:goldblock"}, {["x"] = 2, ["meta"] = {["fields"] = {}, ["inventory"] = {}}, ["param2"] = 3, ["y"] = 5, ["param1"] = 207, ["z"] = 8, ["name"] = "default:ladder_steel"}, {["x"] = 2, ["meta"] = {["fields"] = {}, ["inventory"] = {}}, ["y"] = 5, ["param1"] = 92, ["z"] = 9, ["name"] = "default:goldblock"}, {["x"] = 2, ["meta"] = {["fields"] = {}, ["inventory"] = {}}, ["y"] = 6, ["param1"] = 92, ["z"] = 0, ["name"] = "default:goldblock"}, {["x"] = 2, ["meta"] = {["fields"] = {}, ["inventory"] = {}}, ["param2"] = 3, ["y"] = 6, ["param1"] = 191, ["z"] = 1, ["name"] = "default:ladder_steel"}, {["x"] = 2, ["meta"] = {["fields"] = {}, ["inventory"] = {}}, ["param2"] = 3, ["y"] = 6, ["param1"] = 191, ["z"] = 8, ["name"] = "default:ladder_steel"}, {["x"] = 2, ["meta"] = {["fields"] = {}, ["inventory"] = {}}, ["y"] = 6, ["param1"] = 92, ["z"] = 9, ["name"] = "default:goldblock"}, {["x"] = 2, ["meta"] = {["fields"] = {}, ["inventory"] = {}}, ["y"] = 7, ["param1"] = 92, ["z"] = 0, ["name"] = "default:goldblock"}, {["x"] = 2, ["meta"] = {["fields"] = {}, ["inventory"] = {}}, ["param2"] = 3, ["y"] = 7, ["param1"] = 175, ["z"] = 1, ["name"] = "default:ladder_steel"}, {["x"] = 2, ["meta"] = {["fields"] = {}, ["inventory"] = {}}, ["param2"] = 3, ["y"] = 7, ["param1"] = 175, ["z"] = 8, ["name"] = "default:ladder_steel"}, {["x"] = 2, ["meta"] = {["fields"] = {}, ["inventory"] = {}}, ["y"] = 7, ["param1"] = 92, ["z"] = 9, ["name"] = "default:goldblock"}, {["x"] = 2, ["meta"] = {["fields"] = {}, ["inventory"] = {}}, ["y"] = 8, ["param1"] = 92, ["z"] = 0, ["name"] = "default:goldblock"}, {["x"] = 2, ["meta"] = {["fields"] = {}, ["inventory"] = {}}, ["param2"] = 3, ["y"] = 8, ["param1"] = 159, ["z"] = 1, ["name"] = "default:ladder_steel"}, {["x"] = 2, ["meta"] = {["fields"] = {}, ["inventory"] = {}}, ["param2"] = 3, ["y"] = 8, ["param1"] = 159, ["z"] = 8, ["name"] = "default:ladder_steel"}, {["x"] = 2, ["meta"] = {["fields"] = {}, ["inventory"] = {}}, ["y"] = 8, ["param1"] = 92, ["z"] = 9, ["name"] = "default:goldblock"}, {["x"] = 2, ["meta"] = {["fields"] = {}, ["inventory"] = {}}, ["y"] = 9, ["param1"] = 92, ["z"] = 0, ["name"] = "default:goldblock"}, {["x"] = 2, ["meta"] = {["fields"] = {}, ["inventory"] = {}}, ["param2"] = 3, ["y"] = 9, ["param1"] = 143, ["z"] = 1, ["name"] = "default:ladder_steel"}, {["x"] = 2, ["meta"] = {["fields"] = {}, ["inventory"] = {}}, ["param2"] = 3, ["y"] = 9, ["param1"] = 143, ["z"] = 8, ["name"] = "default:ladder_steel"}, {["x"] = 2, ["meta"] = {["fields"] = {}, ["inventory"] = {}}, ["y"] = 9, ["param1"] = 92, ["z"] = 9, ["name"] = "default:goldblock"}, {["x"] = 2, ["meta"] = {["fields"] = {}, ["inventory"] = {}}, ["y"] = 10, ["param1"] = 92, ["z"] = 0, ["name"] = "default:goldblock"}, {["x"] = 2, ["meta"] = {["fields"] = {}, ["inventory"] = {}}, ["param2"] = 3, ["y"] = 10, ["param1"] = 127, ["z"] = 1, ["name"] = "default:ladder_steel"}, {["x"] = 2, ["meta"] = {["fields"] = {}, ["inventory"] = {}}, ["y"] = 10, ["param1"] = 111, ["z"] = 2, ["name"] = "default:goldblock"}, {["x"] = 2, ["meta"] = {["fields"] = {}, ["inventory"] = {}}, ["y"] = 10, ["param1"] = 111, ["z"] = 3, ["name"] = "default:goldblock"}, {["x"] = 2, ["meta"] = {["fields"] = {}, ["inventory"] = {}}, ["y"] = 10, ["param1"] = 111, ["z"] = 4, ["name"] = "default:goldblock"}, {["x"] = 2, ["meta"] = {["fields"] = {}, ["inventory"] = {}}, ["y"] = 10, ["param1"] = 111, ["z"] = 5, ["name"] = "default:goldblock"}, {["x"] = 2, ["meta"] = {["fields"] = {}, ["inventory"] = {}}, ["y"] = 10, ["param1"] = 111, ["z"] = 6, ["name"] = "default:goldblock"}, {["x"] = 2, ["y"] = 10, ["z"] = 7, ["name"] = "default:goldblock"}, {["x"] = 2, ["meta"] = {["fields"] = {}, ["inventory"] = {}}, ["param2"] = 3, ["y"] = 10, ["param1"] = 127, ["z"] = 8, ["name"] = "default:ladder_steel"}, {["x"] = 2, ["meta"] = {["fields"] = {}, ["inventory"] = {}}, ["y"] = 10, ["param1"] = 92, ["z"] = 9, ["name"] = "default:goldblock"}, {["x"] = 2, ["meta"] = {["fields"] = {}, ["inventory"] = {}}, ["y"] = 11, ["param1"] = 92, ["z"] = 0, ["name"] = "default:goldblock"}, {["x"] = 2, ["meta"] = {["fields"] = {}, ["inventory"] = {}}, ["param2"] = 3, ["y"] = 11, ["param1"] = 111, ["z"] = 1, ["name"] = "default:ladder_steel"}, {["x"] = 2, ["meta"] = {["fields"] = {}, ["inventory"] = {}}, ["param2"] = 3, ["y"] = 11, ["param1"] = 111, ["z"] = 8, ["name"] = "default:ladder_steel"}, {["x"] = 2, ["meta"] = {["fields"] = {}, ["inventory"] = {}}, ["y"] = 11, ["param1"] = 92, ["z"] = 9, ["name"] = "default:goldblock"}, {["x"] = 2, ["meta"] = {["fields"] = {}, ["inventory"] = {}}, ["y"] = 12, ["param1"] = 92, ["z"] = 0, ["name"] = "default:goldblock"}, {["x"] = 2, ["meta"] = {["fields"] = {}, ["inventory"] = {}}, ["param2"] = 3, ["y"] = 12, ["param1"] = 95, ["z"] = 1, ["name"] = "default:ladder_steel"}, {["x"] = 2, ["meta"] = {["fields"] = {}, ["inventory"] = {}}, ["param2"] = 3, ["y"] = 12, ["param1"] = 95, ["z"] = 8, ["name"] = "default:ladder_steel"}, {["x"] = 2, ["meta"] = {["fields"] = {}, ["inventory"] = {}}, ["y"] = 12, ["param1"] = 92, ["z"] = 9, ["name"] = "default:goldblock"}, {["x"] = 2, ["meta"] = {["fields"] = {}, ["inventory"] = {}}, ["y"] = 13, ["param1"] = 92, ["z"] = 0, ["name"] = "default:goldblock"}, {["x"] = 2, ["meta"] = {["fields"] = {}, ["inventory"] = {}}, ["param2"] = 3, ["y"] = 13, ["param1"] = 79, ["z"] = 1, ["name"] = "default:ladder_steel"}, {["x"] = 2, ["meta"] = {["fields"] = {}, ["inventory"] = {}}, ["param2"] = 3, ["y"] = 13, ["param1"] = 79, ["z"] = 8, ["name"] = "default:ladder_steel"}, {["x"] = 2, ["meta"] = {["fields"] = {}, ["inventory"] = {}}, ["y"] = 13, ["param1"] = 92, ["z"] = 9, ["name"] = "default:goldblock"}, {["x"] = 2, ["meta"] = {["fields"] = {}, ["inventory"] = {}}, ["y"] = 14, ["param1"] = 92, ["z"] = 0, ["name"] = "default:goldblock"}, {["x"] = 2, ["meta"] = {["fields"] = {}, ["inventory"] = {}}, ["param2"] = 3, ["y"] = 14, ["param1"] = 63, ["z"] = 1, ["name"] = "default:ladder_steel"}, {["x"] = 2, ["meta"] = {["fields"] = {}, ["inventory"] = {}}, ["param2"] = 3, ["y"] = 14, ["param1"] = 63, ["z"] = 8, ["name"] = "default:ladder_steel"}, {["x"] = 2, ["meta"] = {["fields"] = {}, ["inventory"] = {}}, ["y"] = 14, ["param1"] = 92, ["z"] = 9, ["name"] = "default:goldblock"}, {["x"] = 2, ["meta"] = {["fields"] = {}, ["inventory"] = {}}, ["y"] = 15, ["param1"] = 92, ["z"] = 0, ["name"] = "default:goldblock"}, {["x"] = 2, ["meta"] = {["fields"] = {}, ["inventory"] = {}}, ["param2"] = 3, ["y"] = 15, ["param1"] = 47, ["z"] = 1, ["name"] = "default:ladder_steel"}, {["x"] = 2, ["meta"] = {["fields"] = {}, ["inventory"] = {}}, ["y"] = 15, ["param1"] = 30, ["z"] = 2, ["name"] = "default:goldblock"}, {["x"] = 2, ["meta"] = {["fields"] = {}, ["inventory"] = {}}, ["y"] = 15, ["param1"] = 31, ["z"] = 3, ["name"] = "default:goldblock"}, {["x"] = 2, ["meta"] = {["fields"] = {}, ["inventory"] = {}}, ["y"] = 15, ["param1"] = 31, ["z"] = 4, ["name"] = "default:goldblock"}, {["x"] = 2, ["meta"] = {["fields"] = {}, ["inventory"] = {}}, ["y"] = 15, ["param1"] = 31, ["z"] = 5, ["name"] = "default:goldblock"}, {["x"] = 2, ["meta"] = {["fields"] = {}, ["inventory"] = {}}, ["y"] = 15, ["param1"] = 31, ["z"] = 6, ["name"] = "default:goldblock"}, {["x"] = 2, ["y"] = 15, ["z"] = 7, ["name"] = "default:goldblock"}, {["x"] = 2, ["meta"] = {["fields"] = {}, ["inventory"] = {}}, ["param2"] = 3, ["y"] = 15, ["param1"] = 47, ["z"] = 8, ["name"] = "default:ladder_steel"}, {["x"] = 2, ["meta"] = {["fields"] = {}, ["inventory"] = {}}, ["y"] = 15, ["param1"] = 92, ["z"] = 9, ["name"] = "default:goldblock"}, {["x"] = 2, ["meta"] = {["fields"] = {}, ["inventory"] = {}}, ["y"] = 16, ["param1"] = 92, ["z"] = 0, ["name"] = "default:goldblock"}, {["x"] = 2, ["meta"] = {["fields"] = {}, ["inventory"] = {}}, ["param2"] = 3, ["y"] = 16, ["param1"] = 31, ["z"] = 1, ["name"] = "default:ladder_steel"}, {["x"] = 2, ["meta"] = {["fields"] = {}, ["inventory"] = {}}, ["param2"] = 3, ["y"] = 16, ["param1"] = 31, ["z"] = 8, ["name"] = "default:ladder_steel"}, {["x"] = 2, ["meta"] = {["fields"] = {}, ["inventory"] = {}}, ["y"] = 16, ["param1"] = 92, ["z"] = 9, ["name"] = "default:goldblock"}, {["x"] = 2, ["meta"] = {["fields"] = {}, ["inventory"] = {}}, ["y"] = 17, ["param1"] = 92, ["z"] = 0, ["name"] = "default:goldblock"}, {["x"] = 2, ["meta"] = {["fields"] = {}, ["inventory"] = {}}, ["param2"] = 3, ["y"] = 17, ["param1"] = 15, ["z"] = 1, ["name"] = "default:ladder_steel"}, {["x"] = 2, ["meta"] = {["fields"] = {}, ["inventory"] = {}}, ["param2"] = 3, ["y"] = 17, ["param1"] = 15, ["z"] = 8, ["name"] = "default:ladder_steel"}, {["x"] = 2, ["meta"] = {["fields"] = {}, ["inventory"] = {}}, ["y"] = 17, ["param1"] = 92, ["z"] = 9, ["name"] = "default:goldblock"}, {["x"] = 2, ["meta"] = {["fields"] = {}, ["inventory"] = {}}, ["y"] = 18, ["param1"] = 92, ["z"] = 0, ["name"] = "default:goldblock"}, {["x"] = 2, ["meta"] = {["fields"] = {}, ["inventory"] = {}}, ["param2"] = 3, ["y"] = 18, ["param1"] = 15, ["z"] = 1, ["name"] = "default:ladder_steel"}, {["x"] = 2, ["meta"] = {["fields"] = {}, ["inventory"] = {}}, ["param2"] = 3, ["y"] = 18, ["param1"] = 15, ["z"] = 8, ["name"] = "default:ladder_steel"}, {["x"] = 2, ["meta"] = {["fields"] = {}, ["inventory"] = {}}, ["y"] = 18, ["param1"] = 92, ["z"] = 9, ["name"] = "default:goldblock"}, {["x"] = 2, ["meta"] = {["fields"] = {}, ["inventory"] = {}}, ["y"] = 19, ["param1"] = 92, ["z"] = 0, ["name"] = "default:goldblock"}, {["x"] = 2, ["meta"] = {["fields"] = {}, ["inventory"] = {}}, ["param2"] = 3, ["y"] = 19, ["param1"] = 15, ["z"] = 1, ["name"] = "default:ladder_steel"}, {["x"] = 2, ["meta"] = {["fields"] = {}, ["inventory"] = {}}, ["param2"] = 3, ["y"] = 19, ["param1"] = 15, ["z"] = 8, ["name"] = "default:ladder_steel"}, {["x"] = 2, ["meta"] = {["fields"] = {}, ["inventory"] = {}}, ["y"] = 19, ["param1"] = 92, ["z"] = 9, ["name"] = "default:goldblock"}, {["x"] = 2, ["meta"] = {["fields"] = {}, ["inventory"] = {}}, ["y"] = 20, ["param1"] = 92, ["z"] = 0, ["name"] = "default:goldblock"}, {["x"] = 2, ["meta"] = {["fields"] = {}, ["inventory"] = {}}, ["param2"] = 3, ["y"] = 20, ["param1"] = 15, ["z"] = 1, ["name"] = "default:ladder_steel"}, {["x"] = 2, ["meta"] = {["fields"] = {}, ["inventory"] = {}}, ["y"] = 20, ["param1"] = 14, ["z"] = 2, ["name"] = "default:goldblock"}, {["x"] = 2, ["meta"] = {["fields"] = {}, ["inventory"] = {}}, ["y"] = 20, ["param1"] = 15, ["z"] = 3, ["name"] = "default:goldblock"}, {["x"] = 2, ["meta"] = {["fields"] = {}, ["inventory"] = {}}, ["y"] = 20, ["param1"] = 15, ["z"] = 4, ["name"] = "default:goldblock"}, {["x"] = 2, ["meta"] = {["fields"] = {}, ["inventory"] = {}}, ["y"] = 20, ["param1"] = 15, ["z"] = 5, ["name"] = "default:goldblock"}, {["x"] = 2, ["meta"] = {["fields"] = {}, ["inventory"] = {}}, ["y"] = 20, ["param1"] = 15, ["z"] = 6, ["name"] = "default:goldblock"}, {["x"] = 2, ["y"] = 20, ["z"] = 7, ["name"] = "default:goldblock"}, {["x"] = 2, ["meta"] = {["fields"] = {}, ["inventory"] = {}}, ["param2"] = 3, ["y"] = 20, ["param1"] = 15, ["z"] = 8, ["name"] = "default:ladder_steel"}, {["x"] = 2, ["meta"] = {["fields"] = {}, ["inventory"] = {}}, ["y"] = 20, ["param1"] = 92, ["z"] = 9, ["name"] = "default:goldblock"}, {["x"] = 2, ["meta"] = {["fields"] = {}, ["inventory"] = {}}, ["y"] = 21, ["param1"] = 92, ["z"] = 0, ["name"] = "default:goldblock"}, {["x"] = 2, ["meta"] = {["fields"] = {}, ["inventory"] = {}}, ["param2"] = 3, ["y"] = 21, ["param1"] = 15, ["z"] = 1, ["name"] = "default:ladder_steel"}, {["x"] = 2, ["meta"] = {["fields"] = {}, ["inventory"] = {}}, ["param2"] = 3, ["y"] = 21, ["param1"] = 15, ["z"] = 8, ["name"] = "default:ladder_steel"}, {["x"] = 2, ["meta"] = {["fields"] = {}, ["inventory"] = {}}, ["y"] = 21, ["param1"] = 92, ["z"] = 9, ["name"] = "default:goldblock"}, {["x"] = 2, ["meta"] = {["fields"] = {}, ["inventory"] = {}}, ["y"] = 22, ["param1"] = 92, ["z"] = 0, ["name"] = "default:goldblock"}, {["x"] = 2, ["meta"] = {["fields"] = {}, ["inventory"] = {}}, ["param2"] = 3, ["y"] = 22, ["param1"] = 15, ["z"] = 1, ["name"] = "default:ladder_steel"}, {["x"] = 2, ["meta"] = {["fields"] = {}, ["inventory"] = {}}, ["param2"] = 3, ["y"] = 22, ["param1"] = 15, ["z"] = 8, ["name"] = "default:ladder_steel"}, {["x"] = 2, ["meta"] = {["fields"] = {}, ["inventory"] = {}}, ["y"] = 22, ["param1"] = 92, ["z"] = 9, ["name"] = "default:goldblock"}, {["x"] = 2, ["meta"] = {["fields"] = {}, ["inventory"] = {}}, ["y"] = 23, ["param1"] = 92, ["z"] = 0, ["name"] = "default:goldblock"}, {["x"] = 2, ["meta"] = {["fields"] = {}, ["inventory"] = {}}, ["param2"] = 3, ["y"] = 23, ["param1"] = 15, ["z"] = 1, ["name"] = "default:ladder_steel"}, {["x"] = 2, ["meta"] = {["fields"] = {}, ["inventory"] = {}}, ["param2"] = 3, ["y"] = 23, ["param1"] = 15, ["z"] = 8, ["name"] = "default:ladder_steel"}, {["x"] = 2, ["meta"] = {["fields"] = {}, ["inventory"] = {}}, ["y"] = 23, ["param1"] = 92, ["z"] = 9, ["name"] = "default:goldblock"}, {["x"] = 2, ["meta"] = {["fields"] = {}, ["inventory"] = {}}, ["y"] = 24, ["param1"] = 92, ["z"] = 0, ["name"] = "default:goldblock"}, {["x"] = 2, ["meta"] = {["fields"] = {}, ["inventory"] = {}}, ["param2"] = 3, ["y"] = 24, ["param1"] = 14, ["z"] = 1, ["name"] = "default:ladder_steel"}, {["x"] = 2, ["meta"] = {["fields"] = {}, ["inventory"] = {}}, ["param2"] = 3, ["y"] = 24, ["param1"] = 14, ["z"] = 8, ["name"] = "default:ladder_steel"}, {["x"] = 2, ["meta"] = {["fields"] = {}, ["inventory"] = {}}, ["y"] = 24, ["param1"] = 92, ["z"] = 9, ["name"] = "default:goldblock"}, {["x"] = 2, ["meta"] = {["fields"] = {}, ["inventory"] = {}}, ["y"] = 25, ["param1"] = 92, ["z"] = 0, ["name"] = "default:goldblock"}, {["x"] = 2, ["meta"] = {["fields"] = {}, ["inventory"] = {}}, ["param2"] = 3, ["y"] = 25, ["param1"] = 13, ["z"] = 1, ["name"] = "default:ladder_steel"}, {["x"] = 2, ["meta"] = {["fields"] = {}, ["inventory"] = {}}, ["y"] = 25, ["param1"] = 92, ["z"] = 2, ["name"] = "default:goldblock"}, {["x"] = 2, ["meta"] = {["fields"] = {}, ["inventory"] = {}}, ["y"] = 25, ["param1"] = 92, ["z"] = 3, ["name"] = "default:goldblock"}, {["x"] = 2, ["meta"] = {["fields"] = {}, ["inventory"] = {}}, ["y"] = 25, ["param1"] = 92, ["z"] = 4, ["name"] = "default:goldblock"}, {["x"] = 2, ["meta"] = {["fields"] = {}, ["inventory"] = {}}, ["y"] = 25, ["param1"] = 92, ["z"] = 5, ["name"] = "default:goldblock"}, {["x"] = 2, ["meta"] = {["fields"] = {}, ["inventory"] = {}}, ["y"] = 25, ["param1"] = 92, ["z"] = 6, ["name"] = "default:goldblock"}, {["x"] = 2, ["y"] = 25, ["param1"] = 92, ["z"] = 7, ["name"] = "default:goldblock"}, {["x"] = 2, ["meta"] = {["fields"] = {}, ["inventory"] = {}}, ["param2"] = 3, ["y"] = 25, ["param1"] = 13, ["z"] = 8, ["name"] = "default:ladder_steel"}, {["x"] = 2, ["meta"] = {["fields"] = {}, ["inventory"] = {}}, ["y"] = 25, ["param1"] = 92, ["z"] = 9, ["name"] = "default:goldblock"}, {["x"] = 2, ["meta"] = {["fields"] = {}, ["inventory"] = {}}, ["y"] = 26, ["param1"] = 92, ["z"] = 0, ["name"] = "default:goldblock"}, {["x"] = 2, ["meta"] = {["fields"] = {}, ["inventory"] = {}}, ["y"] = 26, ["param1"] = 92, ["z"] = 1, ["name"] = "default:goldblock"}, {["x"] = 2, ["meta"] = {["fields"] = {}, ["inventory"] = {}}, ["y"] = 26, ["param1"] = 92, ["z"] = 7, ["name"] = "default:goldblock"}, {["x"] = 2, ["meta"] = {["fields"] = {}, ["inventory"] = {}}, ["y"] = 26, ["param1"] = 92, ["z"] = 8, ["name"] = "default:goldblock"}, {["x"] = 2, ["y"] = 27, ["param1"] = 92, ["z"] = 1, ["name"] = "default:goldblock"}, {["x"] = 2, ["y"] = 27, ["param1"] = 92, ["z"] = 2, ["name"] = "default:goldblock"}, {["x"] = 2, ["y"] = 27, ["param1"] = 92, ["z"] = 6, ["name"] = "default:goldblock"}, {["x"] = 2, ["y"] = 27, ["param1"] = 92, ["z"] = 7, ["name"] = "default:goldblock"}, {["x"] = 2, ["y"] = 28, ["param1"] = 92, ["z"] = 2, ["name"] = "default:goldblock"}, {["x"] = 2, ["y"] = 28, ["param1"] = 92, ["z"] = 3, ["name"] = "default:goldblock"}, {["x"] = 2, ["y"] = 28, ["param1"] = 92, ["z"] = 4, ["name"] = "default:goldblock"}, {["x"] = 2, ["y"] = 28, ["param1"] = 92, ["z"] = 5, ["name"] = "default:goldblock"}, {["x"] = 2, ["y"] = 28, ["param1"] = 92, ["z"] = 6, ["name"] = "default:goldblock"}, {["x"] = 2, ["y"] = 29, ["param1"] = 92, ["z"] = 3, ["name"] = "default:goldblock"}, {["x"] = 2, ["y"] = 29, ["param1"] = 92, ["z"] = 4, ["name"] = "default:goldblock"}, {["x"] = 2, ["y"] = 29, ["param1"] = 92, ["z"] = 5, ["name"] = "default:goldblock"}, {["x"] = 3, ["y"] = 0, ["param1"] = 92, ["z"] = 0, ["name"] = "default:goldblock"}, {["x"] = 3, ["y"] = 0, ["param1"] = 92, ["z"] = 1, ["name"] = "default:goldblock"}, {["x"] = 3, ["y"] = 0, ["param1"] = 92, ["z"] = 2, ["name"] = "default:goldblock"}, {["x"] = 3, ["y"] = 0, ["param1"] = 92, ["z"] = 3, ["name"] = "default:goldblock"}, {["x"] = 3, ["y"] = 0, ["param1"] = 92, ["z"] = 4, ["name"] = "default:goldblock"}, {["x"] = 3, ["y"] = 0, ["param1"] = 92, ["z"] = 5, ["name"] = "default:goldblock"}, {["x"] = 3, ["y"] = 0, ["param1"] = 92, ["z"] = 6, ["name"] = "default:goldblock"}, {["x"] = 3, ["y"] = 0, ["param1"] = 92, ["z"] = 7, ["name"] = "default:goldblock"}, {["x"] = 3, ["y"] = 0, ["param1"] = 92, ["z"] = 8, ["name"] = "default:goldblock"}, {["x"] = 3, ["y"] = 0, ["param1"] = 92, ["z"] = 9, ["name"] = "default:goldblock"}, {["x"] = 3, ["y"] = 1, ["param1"] = 190, ["z"] = 0, ["name"] = "default:glass"}, {["x"] = 3, ["y"] = 1, ["param1"] = 190, ["z"] = 9, ["name"] = "default:glass"}, {["x"] = 3, ["y"] = 2, ["param1"] = 206, ["z"] = 0, ["name"] = "default:glass"}, {["x"] = 3, ["y"] = 2, ["param1"] = 206, ["z"] = 9, ["name"] = "default:glass"}, {["x"] = 3, ["y"] = 3, ["param1"] = 222, ["z"] = 0, ["name"] = "default:glass"}, {["x"] = 3, ["y"] = 3, ["param1"] = 222, ["z"] = 9, ["name"] = "default:glass"}, {["x"] = 3, ["y"] = 4, ["param1"] = 238, ["z"] = 0, ["name"] = "default:meselamp"}, {["x"] = 3, ["y"] = 4, ["param1"] = 238, ["z"] = 9, ["name"] = "default:meselamp"}, {["x"] = 3, ["meta"] = {["fields"] = {}, ["inventory"] = {}}, ["y"] = 5, ["param1"] = 92, ["z"] = 0, ["name"] = "default:goldblock"}, {["x"] = 3, ["meta"] = {["fields"] = {}, ["inventory"] = {}}, ["y"] = 5, ["param1"] = 92, ["z"] = 1, ["name"] = "default:goldblock"}, {["x"] = 3, ["meta"] = {["fields"] = {}, ["inventory"] = {}}, ["y"] = 5, ["param1"] = 191, ["z"] = 2, ["name"] = "default:goldblock"}, {["x"] = 3, ["meta"] = {["fields"] = {}, ["inventory"] = {}}, ["y"] = 5, ["param1"] = 175, ["z"] = 3, ["name"] = "default:goldblock"}, {["x"] = 3, ["meta"] = {["fields"] = {}, ["inventory"] = {}}, ["y"] = 5, ["param1"] = 175, ["z"] = 4, ["name"] = "default:goldblock"}, {["x"] = 3, ["meta"] = {["fields"] = {}, ["inventory"] = {}}, ["y"] = 5, ["param1"] = 175, ["z"] = 5, ["name"] = "default:goldblock"}, {["x"] = 3, ["meta"] = {["fields"] = {}, ["inventory"] = {}}, ["y"] = 5, ["param1"] = 175, ["z"] = 6, ["name"] = "default:goldblock"}, {["x"] = 3, ["meta"] = {["fields"] = {}, ["inventory"] = {}}, ["y"] = 5, ["param1"] = 191, ["z"] = 7, ["name"] = "default:goldblock"}, {["x"] = 3, ["meta"] = {["fields"] = {}, ["inventory"] = {}}, ["y"] = 5, ["param1"] = 92, ["z"] = 8, ["name"] = "default:goldblock"}, {["x"] = 3, ["meta"] = {["fields"] = {}, ["inventory"] = {}}, ["y"] = 5, ["param1"] = 92, ["z"] = 9, ["name"] = "default:goldblock"}, {["x"] = 3, ["meta"] = {["fields"] = {}, ["inventory"] = {}}, ["y"] = 6, ["param1"] = 92, ["z"] = 0, ["name"] = "default:goldblock"}, {["x"] = 3, ["meta"] = {["fields"] = {}, ["inventory"] = {}}, ["y"] = 6, ["param1"] = 92, ["z"] = 1, ["name"] = "default:goldblock"}, {["x"] = 3, ["meta"] = {["fields"] = {}, ["inventory"] = {}}, ["y"] = 6, ["param1"] = 92, ["z"] = 8, ["name"] = "default:goldblock"}, {["x"] = 3, ["meta"] = {["fields"] = {}, ["inventory"] = {}}, ["y"] = 6, ["param1"] = 92, ["z"] = 9, ["name"] = "default:goldblock"}, {["x"] = 3, ["meta"] = {["fields"] = {}, ["inventory"] = {}}, ["y"] = 7, ["param1"] = 92, ["z"] = 0, ["name"] = "default:goldblock"}, {["x"] = 3, ["meta"] = {["fields"] = {}, ["inventory"] = {}}, ["y"] = 7, ["param1"] = 92, ["z"] = 1, ["name"] = "default:goldblock"}, {["x"] = 3, ["meta"] = {["fields"] = {}, ["inventory"] = {}}, ["y"] = 7, ["param1"] = 92, ["z"] = 8, ["name"] = "default:goldblock"}, {["x"] = 3, ["meta"] = {["fields"] = {}, ["inventory"] = {}}, ["y"] = 7, ["param1"] = 92, ["z"] = 9, ["name"] = "default:goldblock"}, {["x"] = 3, ["meta"] = {["fields"] = {}, ["inventory"] = {}}, ["y"] = 8, ["param1"] = 92, ["z"] = 0, ["name"] = "default:goldblock"}, {["x"] = 3, ["meta"] = {["fields"] = {}, ["inventory"] = {}}, ["y"] = 8, ["param1"] = 92, ["z"] = 1, ["name"] = "default:goldblock"}, {["x"] = 3, ["meta"] = {["fields"] = {}, ["inventory"] = {}}, ["y"] = 8, ["param1"] = 92, ["z"] = 8, ["name"] = "default:goldblock"}, {["x"] = 3, ["meta"] = {["fields"] = {}, ["inventory"] = {}}, ["y"] = 8, ["param1"] = 92, ["z"] = 9, ["name"] = "default:goldblock"}, {["x"] = 3, ["meta"] = {["fields"] = {}, ["inventory"] = {}}, ["y"] = 9, ["param1"] = 92, ["z"] = 0, ["name"] = "default:goldblock"}, {["x"] = 3, ["meta"] = {["fields"] = {}, ["inventory"] = {}}, ["y"] = 9, ["param1"] = 92, ["z"] = 1, ["name"] = "default:goldblock"}, {["x"] = 3, ["meta"] = {["fields"] = {}, ["inventory"] = {}}, ["y"] = 9, ["param1"] = 92, ["z"] = 8, ["name"] = "default:goldblock"}, {["x"] = 3, ["meta"] = {["fields"] = {}, ["inventory"] = {}}, ["y"] = 9, ["param1"] = 92, ["z"] = 9, ["name"] = "default:goldblock"}, {["x"] = 3, ["meta"] = {["fields"] = {}, ["inventory"] = {}}, ["y"] = 10, ["param1"] = 92, ["z"] = 0, ["name"] = "default:goldblock"}, {["x"] = 3, ["meta"] = {["fields"] = {}, ["inventory"] = {}}, ["y"] = 10, ["param1"] = 92, ["z"] = 1, ["name"] = "default:goldblock"}, {["x"] = 3, ["meta"] = {["fields"] = {}, ["inventory"] = {}}, ["y"] = 10, ["param1"] = 95, ["z"] = 2, ["name"] = "default:goldblock"}, {["x"] = 3, ["meta"] = {["fields"] = {}, ["inventory"] = {}}, ["y"] = 10, ["param1"] = 95, ["z"] = 3, ["name"] = "default:goldblock"}, {["x"] = 3, ["meta"] = {["fields"] = {}, ["inventory"] = {}}, ["y"] = 10, ["param1"] = 95, ["z"] = 4, ["name"] = "default:goldblock"}, {["x"] = 3, ["meta"] = {["fields"] = {}, ["inventory"] = {}}, ["y"] = 10, ["param1"] = 95, ["z"] = 5, ["name"] = "default:goldblock"}, {["x"] = 3, ["meta"] = {["fields"] = {}, ["inventory"] = {}}, ["y"] = 10, ["param1"] = 95, ["z"] = 6, ["name"] = "default:goldblock"}, {["x"] = 3, ["meta"] = {["fields"] = {}, ["inventory"] = {}}, ["y"] = 10, ["param1"] = 111, ["z"] = 7, ["name"] = "default:goldblock"}, {["x"] = 3, ["meta"] = {["fields"] = {}, ["inventory"] = {}}, ["y"] = 10, ["param1"] = 92, ["z"] = 8, ["name"] = "default:goldblock"}, {["x"] = 3, ["meta"] = {["fields"] = {}, ["inventory"] = {}}, ["y"] = 10, ["param1"] = 92, ["z"] = 9, ["name"] = "default:goldblock"}, {["x"] = 3, ["meta"] = {["fields"] = {}, ["inventory"] = {}}, ["y"] = 11, ["param1"] = 92, ["z"] = 0, ["name"] = "default:goldblock"}, {["x"] = 3, ["meta"] = {["fields"] = {}, ["inventory"] = {}}, ["y"] = 11, ["param1"] = 92, ["z"] = 1, ["name"] = "default:goldblock"}, {["x"] = 3, ["meta"] = {["fields"] = {}, ["inventory"] = {}}, ["y"] = 11, ["param1"] = 92, ["z"] = 8, ["name"] = "default:goldblock"}, {["x"] = 3, ["meta"] = {["fields"] = {}, ["inventory"] = {}}, ["y"] = 11, ["param1"] = 92, ["z"] = 9, ["name"] = "default:goldblock"}, {["x"] = 3, ["meta"] = {["fields"] = {}, ["inventory"] = {}}, ["y"] = 12, ["param1"] = 92, ["z"] = 0, ["name"] = "default:goldblock"}, {["x"] = 3, ["meta"] = {["fields"] = {}, ["inventory"] = {}}, ["y"] = 12, ["param1"] = 92, ["z"] = 1, ["name"] = "default:goldblock"}, {["x"] = 3, ["meta"] = {["fields"] = {}, ["inventory"] = {}}, ["y"] = 12, ["param1"] = 92, ["z"] = 8, ["name"] = "default:goldblock"}, {["x"] = 3, ["meta"] = {["fields"] = {}, ["inventory"] = {}}, ["y"] = 12, ["param1"] = 92, ["z"] = 9, ["name"] = "default:goldblock"}, {["x"] = 3, ["meta"] = {["fields"] = {}, ["inventory"] = {}}, ["y"] = 13, ["param1"] = 92, ["z"] = 0, ["name"] = "default:goldblock"}, {["x"] = 3, ["meta"] = {["fields"] = {}, ["inventory"] = {}}, ["y"] = 13, ["param1"] = 92, ["z"] = 1, ["name"] = "default:goldblock"}, {["x"] = 3, ["meta"] = {["fields"] = {}, ["inventory"] = {}}, ["y"] = 13, ["param1"] = 92, ["z"] = 8, ["name"] = "default:goldblock"}, {["x"] = 3, ["meta"] = {["fields"] = {}, ["inventory"] = {}}, ["y"] = 13, ["param1"] = 92, ["z"] = 9, ["name"] = "default:goldblock"}, {["x"] = 3, ["meta"] = {["fields"] = {}, ["inventory"] = {}}, ["y"] = 14, ["param1"] = 92, ["z"] = 0, ["name"] = "default:goldblock"}, {["x"] = 3, ["meta"] = {["fields"] = {}, ["inventory"] = {}}, ["y"] = 14, ["param1"] = 92, ["z"] = 1, ["name"] = "default:goldblock"}, {["x"] = 3, ["meta"] = {["fields"] = {}, ["inventory"] = {}}, ["y"] = 14, ["param1"] = 92, ["z"] = 8, ["name"] = "default:goldblock"}, {["x"] = 3, ["meta"] = {["fields"] = {}, ["inventory"] = {}}, ["y"] = 14, ["param1"] = 92, ["z"] = 9, ["name"] = "default:goldblock"}, {["x"] = 3, ["meta"] = {["fields"] = {}, ["inventory"] = {}}, ["y"] = 15, ["param1"] = 92, ["z"] = 0, ["name"] = "default:goldblock"}, {["x"] = 3, ["meta"] = {["fields"] = {}, ["inventory"] = {}}, ["y"] = 15, ["param1"] = 92, ["z"] = 1, ["name"] = "default:goldblock"}, {["x"] = 3, ["meta"] = {["fields"] = {}, ["inventory"] = {}}, ["y"] = 15, ["param1"] = 14, ["z"] = 2, ["name"] = "default:goldblock"}, {["x"] = 3, ["meta"] = {["fields"] = {}, ["inventory"] = {}}, ["y"] = 15, ["param1"] = 15, ["z"] = 3, ["name"] = "default:goldblock"}, {["x"] = 3, ["meta"] = {["fields"] = {}, ["inventory"] = {}}, ["y"] = 15, ["param1"] = 15, ["z"] = 4, ["name"] = "default:goldblock"}, {["x"] = 3, ["meta"] = {["fields"] = {}, ["inventory"] = {}}, ["y"] = 15, ["param1"] = 15, ["z"] = 5, ["name"] = "default:goldblock"}, {["x"] = 3, ["meta"] = {["fields"] = {}, ["inventory"] = {}}, ["y"] = 15, ["param1"] = 15, ["z"] = 6, ["name"] = "default:goldblock"}, {["x"] = 3, ["meta"] = {["fields"] = {}, ["inventory"] = {}}, ["y"] = 15, ["param1"] = 31, ["z"] = 7, ["name"] = "default:goldblock"}, {["x"] = 3, ["meta"] = {["fields"] = {}, ["inventory"] = {}}, ["y"] = 15, ["param1"] = 92, ["z"] = 8, ["name"] = "default:goldblock"}, {["x"] = 3, ["meta"] = {["fields"] = {}, ["inventory"] = {}}, ["y"] = 15, ["param1"] = 92, ["z"] = 9, ["name"] = "default:goldblock"}, {["x"] = 3, ["meta"] = {["fields"] = {}, ["inventory"] = {}}, ["y"] = 16, ["param1"] = 92, ["z"] = 0, ["name"] = "default:goldblock"}, {["x"] = 3, ["meta"] = {["fields"] = {}, ["inventory"] = {}}, ["y"] = 16, ["param1"] = 92, ["z"] = 1, ["name"] = "default:goldblock"}, {["x"] = 3, ["meta"] = {["fields"] = {}, ["inventory"] = {}}, ["y"] = 16, ["param1"] = 92, ["z"] = 8, ["name"] = "default:goldblock"}, {["x"] = 3, ["meta"] = {["fields"] = {}, ["inventory"] = {}}, ["y"] = 16, ["param1"] = 92, ["z"] = 9, ["name"] = "default:goldblock"}, {["x"] = 3, ["meta"] = {["fields"] = {}, ["inventory"] = {}}, ["y"] = 17, ["param1"] = 92, ["z"] = 0, ["name"] = "default:goldblock"}, {["x"] = 3, ["meta"] = {["fields"] = {}, ["inventory"] = {}}, ["y"] = 17, ["param1"] = 92, ["z"] = 1, ["name"] = "default:goldblock"}, {["x"] = 3, ["meta"] = {["fields"] = {}, ["inventory"] = {}}, ["y"] = 17, ["param1"] = 92, ["z"] = 8, ["name"] = "default:goldblock"}, {["x"] = 3, ["meta"] = {["fields"] = {}, ["inventory"] = {}}, ["y"] = 17, ["param1"] = 92, ["z"] = 9, ["name"] = "default:goldblock"}, {["x"] = 3, ["meta"] = {["fields"] = {}, ["inventory"] = {}}, ["y"] = 18, ["param1"] = 92, ["z"] = 0, ["name"] = "default:goldblock"}, {["x"] = 3, ["meta"] = {["fields"] = {}, ["inventory"] = {}}, ["y"] = 18, ["param1"] = 92, ["z"] = 1, ["name"] = "default:goldblock"}, {["x"] = 3, ["meta"] = {["fields"] = {}, ["inventory"] = {}}, ["y"] = 18, ["param1"] = 92, ["z"] = 8, ["name"] = "default:goldblock"}, {["x"] = 3, ["meta"] = {["fields"] = {}, ["inventory"] = {}}, ["y"] = 18, ["param1"] = 92, ["z"] = 9, ["name"] = "default:goldblock"}, {["x"] = 3, ["meta"] = {["fields"] = {}, ["inventory"] = {}}, ["y"] = 19, ["param1"] = 92, ["z"] = 0, ["name"] = "default:goldblock"}, {["x"] = 3, ["meta"] = {["fields"] = {}, ["inventory"] = {}}, ["y"] = 19, ["param1"] = 92, ["z"] = 1, ["name"] = "default:goldblock"}, {["x"] = 3, ["meta"] = {["fields"] = {}, ["inventory"] = {}}, ["y"] = 19, ["param1"] = 92, ["z"] = 8, ["name"] = "default:goldblock"}, {["x"] = 3, ["meta"] = {["fields"] = {}, ["inventory"] = {}}, ["y"] = 19, ["param1"] = 92, ["z"] = 9, ["name"] = "default:goldblock"}, {["x"] = 3, ["meta"] = {["fields"] = {}, ["inventory"] = {}}, ["y"] = 20, ["param1"] = 92, ["z"] = 0, ["name"] = "default:goldblock"}, {["x"] = 3, ["meta"] = {["fields"] = {}, ["inventory"] = {}}, ["y"] = 20, ["param1"] = 92, ["z"] = 1, ["name"] = "default:goldblock"}, {["x"] = 3, ["meta"] = {["fields"] = {}, ["inventory"] = {}}, ["y"] = 20, ["param1"] = 14, ["z"] = 2, ["name"] = "default:goldblock"}, {["x"] = 3, ["meta"] = {["fields"] = {}, ["inventory"] = {}}, ["y"] = 20, ["param1"] = 15, ["z"] = 3, ["name"] = "default:goldblock"}, {["x"] = 3, ["meta"] = {["fields"] = {}, ["inventory"] = {}}, ["y"] = 20, ["param1"] = 15, ["z"] = 4, ["name"] = "default:goldblock"}, {["x"] = 3, ["meta"] = {["fields"] = {}, ["inventory"] = {}}, ["y"] = 20, ["param1"] = 15, ["z"] = 5, ["name"] = "default:goldblock"}, {["x"] = 3, ["meta"] = {["fields"] = {}, ["inventory"] = {}}, ["y"] = 20, ["param1"] = 15, ["z"] = 6, ["name"] = "default:goldblock"}, {["x"] = 3, ["meta"] = {["fields"] = {}, ["inventory"] = {}}, ["y"] = 20, ["param1"] = 15, ["z"] = 7, ["name"] = "default:goldblock"}, {["x"] = 3, ["meta"] = {["fields"] = {}, ["inventory"] = {}}, ["y"] = 20, ["param1"] = 92, ["z"] = 8, ["name"] = "default:goldblock"}, {["x"] = 3, ["meta"] = {["fields"] = {}, ["inventory"] = {}}, ["y"] = 20, ["param1"] = 92, ["z"] = 9, ["name"] = "default:goldblock"}, {["x"] = 3, ["meta"] = {["fields"] = {}, ["inventory"] = {}}, ["y"] = 21, ["param1"] = 92, ["z"] = 0, ["name"] = "default:goldblock"}, {["x"] = 3, ["meta"] = {["fields"] = {}, ["inventory"] = {}}, ["y"] = 21, ["param1"] = 92, ["z"] = 1, ["name"] = "default:goldblock"}, {["x"] = 3, ["meta"] = {["fields"] = {}, ["inventory"] = {}}, ["y"] = 21, ["param1"] = 92, ["z"] = 8, ["name"] = "default:goldblock"}, {["x"] = 3, ["meta"] = {["fields"] = {}, ["inventory"] = {}}, ["y"] = 21, ["param1"] = 92, ["z"] = 9, ["name"] = "default:goldblock"}, {["x"] = 3, ["meta"] = {["fields"] = {}, ["inventory"] = {}}, ["y"] = 22, ["param1"] = 92, ["z"] = 0, ["name"] = "default:goldblock"}, {["x"] = 3, ["meta"] = {["fields"] = {}, ["inventory"] = {}}, ["y"] = 22, ["param1"] = 92, ["z"] = 1, ["name"] = "default:goldblock"}, {["x"] = 3, ["meta"] = {["fields"] = {}, ["inventory"] = {}}, ["y"] = 22, ["param1"] = 92, ["z"] = 8, ["name"] = "default:goldblock"}, {["x"] = 3, ["meta"] = {["fields"] = {}, ["inventory"] = {}}, ["y"] = 22, ["param1"] = 92, ["z"] = 9, ["name"] = "default:goldblock"}, {["x"] = 3, ["meta"] = {["fields"] = {}, ["inventory"] = {}}, ["y"] = 23, ["param1"] = 92, ["z"] = 0, ["name"] = "default:goldblock"}, {["x"] = 3, ["meta"] = {["fields"] = {}, ["inventory"] = {}}, ["y"] = 23, ["param1"] = 92, ["z"] = 1, ["name"] = "default:goldblock"}, {["x"] = 3, ["meta"] = {["fields"] = {}, ["inventory"] = {}}, ["y"] = 23, ["param1"] = 92, ["z"] = 8, ["name"] = "default:goldblock"}, {["x"] = 3, ["meta"] = {["fields"] = {}, ["inventory"] = {}}, ["y"] = 23, ["param1"] = 92, ["z"] = 9, ["name"] = "default:goldblock"}, {["x"] = 3, ["meta"] = {["fields"] = {}, ["inventory"] = {}}, ["y"] = 24, ["param1"] = 92, ["z"] = 0, ["name"] = "default:goldblock"}, {["x"] = 3, ["meta"] = {["fields"] = {}, ["inventory"] = {}}, ["y"] = 24, ["param1"] = 92, ["z"] = 1, ["name"] = "default:goldblock"}, {["x"] = 3, ["meta"] = {["fields"] = {}, ["inventory"] = {}}, ["y"] = 24, ["param1"] = 92, ["z"] = 8, ["name"] = "default:goldblock"}, {["x"] = 3, ["meta"] = {["fields"] = {}, ["inventory"] = {}}, ["y"] = 24, ["param1"] = 92, ["z"] = 9, ["name"] = "default:goldblock"}, {["x"] = 3, ["meta"] = {["fields"] = {}, ["inventory"] = {}}, ["y"] = 25, ["param1"] = 92, ["z"] = 0, ["name"] = "default:goldblock"}, {["x"] = 3, ["meta"] = {["fields"] = {}, ["inventory"] = {}}, ["y"] = 25, ["param1"] = 92, ["z"] = 1, ["name"] = "default:goldblock"}, {["x"] = 3, ["meta"] = {["fields"] = {}, ["inventory"] = {}}, ["y"] = 25, ["param1"] = 92, ["z"] = 2, ["name"] = "default:goldblock"}, {["x"] = 3, ["meta"] = {["fields"] = {}, ["inventory"] = {}}, ["y"] = 25, ["param1"] = 92, ["z"] = 3, ["name"] = "default:goldblock"},