5:return {{["x"] = 0, ["y"] = 0, ["z"] = 0, ["name"] = "default:bronzeblock"}, {["x"] = 0, ["y"] = 0, ["param1"] = 37, ["z"] = 1, ["name"] = "default:bronzeblock"}, {["x"] = 0, ["y"] = 0, ["param1"] = 37, ["z"] = 2, ["name"] = "default:bronzeblock"}, {["x"] = 0, ["y"] = 0, ["z"] = 3, ["name"] = "default:bronzeblock"}, {["x"] = 0, ["y"] = 0, ["z"] = 4, ["name"] = "default:bronzeblock"}, {["x"] = 0, ["y"] = 1, ["param1"] = 88, ["z"] = 0, ["name"] = "default:bronzeblock"}, {["x"] = 0, ["y"] = 1, ["param1"] = 88, ["z"] = 1, ["name"] = "default:bronzeblock"}, {["x"] = 0, ["y"] = 1, ["param1"] = 88, ["z"] = 2, ["name"] = "default:bronzeblock"}, {["x"] = 0, ["y"] = 1, ["param1"] = 88, ["z"] = 3, ["name"] = "default:bronzeblock"}, {["x"] = 0, ["y"] = 1, ["param1"] = 88, ["z"] = 4, ["name"] = "default:bronzeblock"}, {["x"] = 0, ["y"] = 2, ["param1"] = 88, ["z"] = 0, ["name"] = "default:bronzeblock"}, {["x"] = 0, ["y"] = 2, ["param1"] = 88, ["z"] = 1, ["name"] = "default:bronzeblock"}, {["x"] = 0, ["y"] = 2, ["param1"] = 88, ["z"] = 2, ["name"] = "default:bronzeblock"}, {["x"] = 0, ["y"] = 2, ["param1"] = 88, ["z"] = 3, ["name"] = "default:bronzeblock"}, {["x"] = 0, ["y"] = 2, ["param1"] = 88, ["z"] = 4, ["name"] = "default:bronzeblock"}, {["x"] = 0, ["y"] = 3, ["param1"] = 88, ["z"] = 0, ["name"] = "default:bronzeblock"}, {["x"] = 0, ["y"] = 3, ["param1"] = 88, ["z"] = 1, ["name"] = "default:bronzeblock"}, {["x"] = 0, ["y"] = 3, ["param1"] = 88, ["z"] = 2, ["name"] = "default:bronzeblock"}, {["x"] = 0, ["y"] = 3, ["param1"] = 88, ["z"] = 3, ["name"] = "default:bronzeblock"}, {["x"] = 0, ["y"] = 3, ["param1"] = 88, ["z"] = 4, ["name"] = "default:bronzeblock"}, {["x"] = 0, ["y"] = 4, ["param1"] = 88, ["z"] = 0, ["name"] = "default:bronzeblock"}, {["x"] = 0, ["y"] = 4, ["param1"] = 88, ["z"] = 1, ["name"] = "default:bronzeblock"}, {["x"] = 0, ["y"] = 4, ["param1"] = 88, ["z"] = 2, ["name"] = "default:bronzeblock"}, {["x"] = 0, ["y"] = 4, ["param1"] = 88, ["z"] = 3, ["name"] = "default:bronzeblock"}, {["x"] = 0, ["y"] = 4, ["param1"] = 88, ["z"] = 4, ["name"] = "default:bronzeblock"}, {["x"] = 0, ["y"] = 5, ["param1"] = 88, ["z"] = 0, ["name"] = "default:bronzeblock"}, {["x"] = 0, ["y"] = 5, ["param1"] = 88, ["z"] = 1, ["name"] = "default:bronzeblock"}, {["x"] = 0, ["y"] = 5, ["param1"] = 88, ["z"] = 2, ["name"] = "default:bronzeblock"}, {["x"] = 0, ["y"] = 5, ["param1"] = 88, ["z"] = 3, ["name"] = "default:bronzeblock"}, {["x"] = 0, ["y"] = 5, ["param1"] = 88, ["z"] = 4, ["name"] = "default:bronzeblock"}, {["x"] = 0, ["y"] = 6, ["param1"] = 88, ["z"] = 0, ["name"] = "default:bronzeblock"}, {["x"] = 0, ["y"] = 6, ["param1"] = 88, ["z"] = 1, ["name"] = "default:bronzeblock"}, {["x"] = 0, ["y"] = 6, ["param1"] = 88, ["z"] = 2, ["name"] = "default:bronzeblock"}, {["x"] = 0, ["y"] = 6, ["param1"] = 88, ["z"] = 3, ["name"] = "default:bronzeblock"}, {["x"] = 0, ["y"] = 6, ["param1"] = 88, ["z"] = 4, ["name"] = "default:bronzeblock"}, {["x"] = 0, ["y"] = 7, ["param1"] = 88, ["z"] = 0, ["name"] = "default:bronzeblock"}, {["x"] = 0, ["y"] = 7, ["param1"] = 88, ["z"] = 1, ["name"] = "default:bronzeblock"}, {["x"] = 0, ["y"] = 7, ["param1"] = 88, ["z"] = 2, ["name"] = "default:bronzeblock"}, {["x"] = 0, ["y"] = 7, ["param1"] = 88, ["z"] = 3, ["name"] = "default:bronzeblock"}, {["x"] = 0, ["y"] = 7, ["param1"] = 88, ["z"] = 4, ["name"] = "default:bronzeblock"}, {["x"] = 0, ["y"] = 8, ["param1"] = 88, ["z"] = 0, ["name"] = "default:bronzeblock"}, {["x"] = 0, ["y"] = 8, ["param1"] = 88, ["z"] = 1, ["name"] = "default:bronzeblock"}, {["x"] = 0, ["y"] = 8, ["param1"] = 88, ["z"] = 2, ["name"] = "default:bronzeblock"}, {["x"] = 0, ["y"] = 8, ["param1"] = 88, ["z"] = 3, ["name"] = "default:bronzeblock"}, {["x"] = 0, ["y"] = 8, ["param1"] = 88, ["z"] = 4, ["name"] = "default:bronzeblock"}, {["x"] = 0, ["y"] = 9, ["param1"] = 88, ["z"] = 0, ["name"] = "default:bronzeblock"}, {["x"] = 0, ["y"] = 9, ["param1"] = 88, ["z"] = 1, ["name"] = "default:bronzeblock"}, {["x"] = 0, ["y"] = 9, ["param1"] = 88, ["z"] = 2, ["name"] = "default:bronzeblock"}, {["x"] = 0, ["y"] = 9, ["param1"] = 88, ["z"] = 3, ["name"] = "default:bronzeblock"}, {["x"] = 0, ["y"] = 9, ["param1"] = 88, ["z"] = 4, ["name"] = "default:bronzeblock"}, {["x"] = 0, ["y"] = 10, ["param1"] = 88, ["z"] = 0, ["name"] = "default:bronzeblock"}, {["x"] = 0, ["y"] = 10, ["param1"] = 88, ["z"] = 1, ["name"] = "default:bronzeblock"}, {["x"] = 0, ["y"] = 10, ["param1"] = 88, ["z"] = 2, ["name"] = "default:bronzeblock"}, {["x"] = 0, ["y"] = 10, ["param1"] = 88, ["z"] = 3, ["name"] = "default:bronzeblock"}, {["x"] = 0, ["y"] = 10, ["param1"] = 88, ["z"] = 4, ["name"] = "default:bronzeblock"}, {["x"] = 0, ["y"] = 11, ["param1"] = 88, ["z"] = 0, ["name"] = "default:bronzeblock"}, {["x"] = 0, ["y"] = 11, ["param1"] = 88, ["z"] = 1, ["name"] = "default:bronzeblock"}, {["x"] = 0, ["y"] = 11, ["param1"] = 88, ["z"] = 2, ["name"] = "default:bronzeblock"}, {["x"] = 0, ["y"] = 11, ["param1"] = 88, ["z"] = 3, ["name"] = "default:bronzeblock"}, {["x"] = 0, ["y"] = 11, ["param1"] = 88, ["z"] = 4, ["name"] = "default:bronzeblock"}, {["x"] = 0, ["y"] = 12, ["param1"] = 88, ["z"] = 0, ["name"] = "default:bronzeblock"}, {["x"] = 0, ["y"] = 12, ["param1"] = 88, ["z"] = 1, ["name"] = "default:bronzeblock"}, {["x"] = 0, ["y"] = 12, ["param1"] = 88, ["z"] = 2, ["name"] = "default:bronzeblock"}, {["x"] = 0, ["y"] = 12, ["param1"] = 88, ["z"] = 3, ["name"] = "default:bronzeblock"}, {["x"] = 0, ["y"] = 12, ["param1"] = 88, ["z"] = 4, ["name"] = "default:bronzeblock"}, {["x"] = 0, ["y"] = 13, ["param1"] = 88, ["z"] = 0, ["name"] = "default:bronzeblock"}, {["x"] = 0, ["y"] = 13, ["param1"] = 88, ["z"] = 1, ["name"] = "default:bronzeblock"}, {["x"] = 0, ["y"] = 13, ["param1"] = 88, ["z"] = 2, ["name"] = "default:bronzeblock"}, {["x"] = 0, ["y"] = 13, ["param1"] = 88, ["z"] = 3, ["name"] = "default:bronzeblock"}, {["x"] = 0, ["y"] = 13, ["param1"] = 88, ["z"] = 4, ["name"] = "default:bronzeblock"}, {["x"] = 0, ["y"] = 14, ["param1"] = 88, ["z"] = 0, ["name"] = "default:bronzeblock"}, {["x"] = 0, ["y"] = 14, ["param1"] = 88, ["z"] = 1, ["name"] = "default:bronzeblock"}, {["x"] = 0, ["y"] = 14, ["param1"] = 88, ["z"] = 2, ["name"] = "default:bronzeblock"}, {["x"] = 0, ["y"] = 14, ["param1"] = 88, ["z"] = 3, ["name"] = "default:bronzeblock"}, {["x"] = 0, ["y"] = 14, ["param1"] = 88, ["z"] = 4, ["name"] = "default:bronzeblock"}, {["x"] = 0, ["y"] = 15, ["param1"] = 88, ["z"] = 0, ["name"] = "default:bronzeblock"}, {["x"] = 0, ["y"] = 15, ["param1"] = 88, ["z"] = 1, ["name"] = "default:bronzeblock"}, {["x"] = 0, ["y"] = 15, ["param1"] = 88, ["z"] = 2, ["name"] = "default:bronzeblock"}, {["x"] = 0, ["y"] = 15, ["param1"] = 88, ["z"] = 3, ["name"] = "default:bronzeblock"}, {["x"] = 0, ["y"] = 15, ["param1"] = 88, ["z"] = 4, ["name"] = "default:bronzeblock"}, {["x"] = 0, ["y"] = 16, ["param1"] = 88, ["z"] = 0, ["name"] = "default:bronzeblock"}, {["x"] = 0, ["y"] = 16, ["param1"] = 88, ["z"] = 1, ["name"] = "default:bronzeblock"}, {["x"] = 0, ["y"] = 16, ["param1"] = 88, ["z"] = 2, ["name"] = "default:bronzeblock"}, {["x"] = 0, ["y"] = 16, ["param1"] = 88, ["z"] = 3, ["name"] = "default:bronzeblock"}, {["x"] = 0, ["y"] = 16, ["param1"] = 88, ["z"] = 4, ["name"] = "default:bronzeblock"}, {["x"] = 0, ["y"] = 17, ["param1"] = 88, ["z"] = 0, ["name"] = "default:bronzeblock"}, {["x"] = 0, ["y"] = 17, ["param1"] = 88, ["z"] = 1, ["name"] = "default:bronzeblock"}, {["x"] = 0, ["y"] = 17, ["param1"] = 88, ["z"] = 2, ["name"] = "default:bronzeblock"}, {["x"] = 0, ["y"] = 17, ["param1"] = 88, ["z"] = 3, ["name"] = "default:bronzeblock"}, {["x"] = 0, ["y"] = 17, ["param1"] = 88, ["z"] = 4, ["name"] = "default:bronzeblock"}, {["x"] = 0, ["y"] = 18, ["param1"] = 88, ["z"] = 0, ["name"] = "default:bronzeblock"}, {["x"] = 0, ["y"] = 18, ["param1"] = 88, ["z"] = 1, ["name"] = "default:bronzeblock"}, {["x"] = 0, ["y"] = 18, ["param1"] = 88, ["z"] = 2, ["name"] = "default:bronzeblock"}, {["x"] = 0, ["y"] = 18, ["param1"] = 88, ["z"] = 3, ["name"] = "default:bronzeblock"}, {["x"] = 0, ["y"] = 18, ["param1"] = 88, ["z"] = 4, ["name"] = "default:bronzeblock"}, {["x"] = 0, ["y"] = 19, ["param1"] = 88, ["z"] = 0, ["name"] = "default:bronzeblock"}, {["x"] = 0, ["y"] = 19, ["param1"] = 88, ["z"] = 1, ["name"] = "default:bronzeblock"}, {["x"] = 0, ["y"] = 19, ["param1"] = 88, ["z"] = 2, ["name"] = "default:bronzeblock"}, {["x"] = 0, ["y"] = 19, ["param1"] = 88, ["z"] = 3, ["name"] = "default:bronzeblock"}, {["x"] = 0, ["y"] = 19, ["param1"] = 88, ["z"] = 4, ["name"] = "default:bronzeblock"}, {["x"] = 0, ["y"] = 20, ["param1"] = 88, ["z"] = 0, ["name"] = "default:bronzeblock"}, {["x"] = 0, ["y"] = 20, ["param1"] = 88, ["z"] = 1, ["name"] = "default:bronzeblock"}, {["x"] = 0, ["y"] = 20, ["param1"] = 88, ["z"] = 2, ["name"] = "default:bronzeblock"}, {["x"] = 0, ["y"] = 20, ["param1"] = 88, ["z"] = 3, ["name"] = "default:bronzeblock"}, {["x"] = 0, ["y"] = 20, ["param1"] = 88, ["z"] = 4, ["name"] = "default:bronzeblock"}, {["x"] = 0, ["y"] = 21, ["param1"] = 88, ["z"] = 0, ["name"] = "default:bronzeblock"}, {["x"] = 0, ["y"] = 21, ["param1"] = 88, ["z"] = 1, ["name"] = "default:bronzeblock"}, {["x"] = 0, ["y"] = 21, ["param1"] = 88, ["z"] = 2, ["name"] = "default:bronzeblock"}, {["x"] = 0, ["y"] = 21, ["param1"] = 88, ["z"] = 3, ["name"] = "default:bronzeblock"}, {["x"] = 0, ["y"] = 21, ["param1"] = 88, ["z"] = 4, ["name"] = "default:bronzeblock"}, {["x"] = 1, ["y"] = 0, ["z"] = 0, ["name"] = "default:bronzeblock"}, {["x"] = 1, ["y"] = 0, ["z"] = 1, ["name"] = "default:bronzeblock"}, {["x"] = 1, ["y"] = 0, ["z"] = 2, ["name"] = "default:bronzeblock"}, {["x"] = 1, ["y"] = 0, ["z"] = 3, ["name"] = "default:bronzeblock"}, {["x"] = 1, ["y"] = 0, ["z"] = 4, ["name"] = "default:bronzeblock"}, {["x"] = 1, ["y"] = 1, ["param1"] = 88, ["z"] = 0, ["name"] = "default:bronzeblock"}, {["x"] = 1, ["y"] = 1, ["param1"] = 88, ["z"] = 4, ["name"] = "default:bronzeblock"}, {["x"] = 1, ["y"] = 2, ["param1"] = 88, ["z"] = 0, ["name"] = "default:bronzeblock"}, {["x"] = 1, ["y"] = 2, ["param1"] = 88, ["z"] = 4, ["name"] = "default:bronzeblock"}, {["x"] = 1, ["y"] = 3, ["param1"] = 88, ["z"] = 0, ["name"] = "default:bronzeblock"}, {["x"] = 1, ["y"] = 3, ["param1"] = 88, ["z"] = 4, ["name"] = "default:bronzeblock"}, {["x"] = 1, ["y"] = 4, ["param1"] = 88, ["z"] = 0, ["name"] = "default:bronzeblock"}, {["x"] = 1, ["y"] = 4, ["z"] = 1, ["name"] = "default:bronzeblock"}, {["x"] = 1, ["y"] = 4, ["z"] = 2, ["name"] = "default:bronzeblock"}, {["x"] = 1, ["y"] = 4, ["z"] = 3, ["name"] = "default:bronzeblock"}, {["x"] = 1, ["y"] = 4, ["param1"] = 88, ["z"] = 4, ["name"] = "default:bronzeblock"}, {["x"] = 1, ["y"] = 5, ["param1"] = 88, ["z"] = 0, ["name"] = "default:bronzeblock"}, {["x"] = 1, ["y"] = 5, ["param1"] = 88, ["z"] = 4, ["name"] = "default:bronzeblock"}, {["x"] = 1, ["y"] = 6, ["param1"] = 88, ["z"] = 0, ["name"] = "default:bronzeblock"}, {["x"] = 1, ["y"] = 6, ["param1"] = 88, ["z"] = 4, ["name"] = "default:bronzeblock"}, {["x"] = 1, ["y"] = 7, ["param1"] = 88, ["z"] = 0, ["name"] = "default:bronzeblock"}, {["x"] = 1, ["y"] = 7, ["param1"] = 88, ["z"] = 4, ["name"] = "default:bronzeblock"}, {["x"] = 1, ["y"] = 8, ["param1"] = 88, ["z"] = 0, ["name"] = "default:bronzeblock"}, {["x"] = 1, ["y"] = 8, ["param1"] = 88, ["z"] = 4, ["name"] = "default:bronzeblock"}, {["x"] = 1, ["y"] = 9, ["param1"] = 88, ["z"] = 0, ["name"] = "default:bronzeblock"}, {["x"] = 1, ["y"] = 9, ["param1"] = 88, ["z"] = 4, ["name"] = "default:bronzeblock"}, {["x"] = 1, ["y"] = 10, ["param1"] = 88, ["z"] = 0, ["name"] = "default:bronzeblock"}, {["x"] = 1, ["y"] = 10, ["param1"] = 88, ["z"] = 4, ["name"] = "default:bronzeblock"}, {["x"] = 1, ["y"] = 11, ["param1"] = 88, ["z"] = 0, ["name"] = "default:bronzeblock"}, {["x"] = 1, ["y"] = 11, ["param1"] = 88, ["z"] = 4, ["name"] = "default:bronzeblock"}, {["x"] = 1, ["y"] = 12, ["param1"] = 88, ["z"] = 0, ["name"] = "default:bronzeblock"}, {["x"] = 1, ["y"] = 12, ["param1"] = 88, ["z"] = 4, ["name"] = "default:bronzeblock"}, {["x"] = 1, ["y"] = 13, ["param1"] = 88, ["z"] = 0, ["name"] = "default:bronzeblock"}, {["x"] = 1, ["y"] = 13, ["param1"] = 88, ["z"] = 4, ["name"] = "default:bronzeblock"}, {["x"] = 1, ["y"] = 14, ["param1"] = 88, ["z"] = 0, ["name"] = "default:bronzeblock"}, {["x"] = 1, ["y"] = 14, ["param1"] = 88, ["z"] = 4, ["name"] = "default:bronzeblock"}, {["x"] = 1, ["y"] = 15, ["param1"] = 88, ["z"] = 0, ["name"] = "default:bronzeblock"}, {["x"] = 1, ["y"] = 15, ["param1"] = 88, ["z"] = 4, ["name"] = "default:bronzeblock"}, {["x"] = 1, ["y"] = 16, ["param1"] = 88, ["z"] = 0, ["name"] = "default:bronzeblock"}, {["x"] = 1, ["y"] = 16, ["param1"] = 88, ["z"] = 4, ["name"] = "default:bronzeblock"}, {["x"] = 1, ["y"] = 17, ["param1"] = 88, ["z"] = 0, ["name"] = "default:bronzeblock"}, {["x"] = 1, ["y"] = 17, ["param1"] = 88, ["z"] = 4, ["name"] = "default:bronzeblock"}, {["x"] = 1, ["y"] = 18, ["param1"] = 88, ["z"] = 0, ["name"] = "default:bronzeblock"}, {["x"] = 1, ["y"] = 18, ["param1"] = 88, ["z"] = 4, ["name"] = "default:bronzeblock"}, {["x"] = 1, ["y"] = 19, ["param1"] = 88, ["z"] = 0, ["name"] = "default:bronzeblock"}, {["x"] = 1, ["y"] = 19, ["param1"] = 88, ["z"] = 4, ["name"] = "default:bronzeblock"}, {["x"] = 1, ["y"] = 20, ["param1"] = 88, ["z"] = 0, ["name"] = "default:bronzeblock"}, {["x"] = 1, ["y"] = 20, ["param1"] = 88, ["z"] = 4, ["name"] = "default:bronzeblock"}, {["x"] = 1, ["y"] = 21, ["param1"] = 88, ["z"] = 0, ["name"] = "default:bronzeblock"}, {["x"] = 1, ["y"] = 21, ["z"] = 1, ["name"] = "default:bronzeblock"}, {["x"] = 1, ["y"] = 21, ["z"] = 2, ["name"] = "default:bronzeblock"}, {["x"] = 1, ["y"] = 21, ["z"] = 3, ["name"] = "default:bronzeblock"}, {["x"] = 1, ["y"] = 21, ["param1"] = 88, ["z"] = 4, ["name"] = "default:bronzeblock"}, {["x"] = 2, ["y"] = 0, ["z"] = 0, ["name"] = "default:bronzeblock"}, {["x"] = 2, ["y"] = 0, ["z"] = 1, ["name"] = "default:bronzeblock"}, {["x"] = 2, ["y"] = 0, ["z"] = 2, ["name"] = "default:bronzeblock"}, {["x"] = 2, ["y"] = 0, ["z"] = 3, ["name"] = "default:bronzeblock"}, {["x"] = 2, ["y"] = 0, ["z"] = 4, ["name"] = "default:bronzeblock"}, {["x"] = 2, ["y"] = 1, ["param1"] = 88, ["z"] = 0, ["name"] = "default:bronzeblock"}, {["x"] = 2, ["y"] = 1, ["param1"] = 15, ["z"] = 4, ["name"] = "default:glass"}, {["x"] = 2, ["y"] = 2, ["param1"] = 88, ["z"] = 0, ["name"] = "default:bronzeblock"}, {["x"] = 2, ["y"] = 2, ["param1"] = 15, ["z"] = 4, ["name"] = "default:glass"}, {["x"] = 2, ["y"] = 3, ["param1"] = 88, ["z"] = 0, ["name"] = "default:bronzeblock"}, {["x"] = 2, ["y"] = 3, ["param1"] = 15, ["z"] = 4, ["name"] = "default:glass"}, {["x"] = 2, ["y"] = 4, ["param1"] = 88, ["z"] = 0, ["name"] = "default:bronzeblock"}, {["x"] = 2, ["y"] = 4, ["z"] = 1, ["name"] = "default:bronzeblock"}, {["x"] = 2, ["y"] = 4, ["z"] = 2, ["name"] = "default:bronzeblock"}, {["x"] = 2, ["y"] = 4, ["z"] = 3, ["name"] = "default:bronzeblock"}, {["x"] = 2, ["y"] = 4, ["param1"] = 15, ["z"] = 4, ["name"] = "default:glass"}, {["x"] = 2, ["y"] = 5, ["param1"] = 88, ["z"] = 0, ["name"] = "default:bronzeblock"}, {["x"] = 2, ["y"] = 5, ["param1"] = 15, ["z"] = 4, ["name"] = "default:glass"}, {["x"] = 2, ["y"] = 6, ["param1"] = 88, ["z"] = 0, ["name"] = "default:bronzeblock"}, {["x"] = 2, ["y"] = 6, ["param1"] = 15, ["z"] = 4, ["name"] = "default:glass"}, {["x"] = 2, ["y"] = 7, ["param1"] = 88, ["z"] = 0, ["name"] = "default:bronzeblock"}, {["x"] = 2, ["y"] = 7, ["param1"] = 14, ["z"] = 4, ["name"] = "default:glass"}, {["x"] = 2, ["y"] = 8, ["param1"] = 88, ["z"] = 0, ["name"] = "default:bronzeblock"}, {["x"] = 2, ["y"] = 8, ["param1"] = 15, ["z"] = 4, ["name"] = "default:glass"}, {["x"] = 2, ["y"] = 9, ["param1"] = 88, ["z"] = 0, ["name"] = "default:bronzeblock"}, {["x"] = 2, ["y"] = 9, ["param1"] = 15, ["z"] = 4, ["name"] = "default:glass"}, {["x"] = 2, ["y"] = 10, ["param1"] = 88, ["z"] = 0, ["name"] = "default:bronzeblock"}, {["x"] = 2, ["y"] = 10, ["param1"] = 15, ["z"] = 4, ["name"] = "default:glass"}, {["x"] = 2, ["y"] = 11, ["param1"] = 88, ["z"] = 0, ["name"] = "default:bronzeblock"}, {["x"] = 2, ["y"] = 11, ["param1"] = 15, ["z"] = 4, ["name"] = "default:glass"}, {["x"] = 2, ["y"] = 12, ["param1"] = 88, ["z"] = 0, ["name"] = "default:bronzeblock"}, {["x"] = 2, ["y"] = 12, ["param1"] = 15, ["z"] = 4, ["name"] = "default:glass"}, {["x"] = 2, ["y"] = 13, ["param1"] = 88, ["z"] = 0, ["name"] = "default:bronzeblock"}, {["x"] = 2, ["y"] = 13, ["param1"] = 15, ["z"] = 4, ["name"] = "default:glass"}, {["x"] = 2, ["y"] = 14, ["param1"] = 88, ["z"] = 0, ["name"] = "default:bronzeblock"}, {["x"] = 2, ["y"] = 14, ["param1"] = 15, ["z"] = 4, ["name"] = "default:glass"}, {["x"] = 2, ["y"] = 15, ["param1"] = 88, ["z"] = 0, ["name"] = "default:bronzeblock"}, {["x"] = 2, ["y"] = 15, ["param1"] = 15, ["z"] = 4, ["name"] = "default:glass"}, {["x"] = 2, ["y"] = 16, ["param1"] = 88, ["z"] = 0, ["name"] = "default:bronzeblock"}, {["x"] = 2, ["y"] = 16, ["param1"] = 15, ["z"] = 4, ["name"] = "default:glass"}, {["x"] = 2, ["y"] = 17, ["param1"] = 88, ["z"] = 0, ["name"] = "default:bronzeblock"}, {["x"] = 2, ["y"] = 17, ["param1"] = 15, ["z"] = 4, ["name"] = "default:glass"}, {["x"] = 2, ["y"] = 18, ["param1"] = 88, ["z"] = 0, ["name"] = "default:bronzeblock"}, {["x"] = 2, ["y"] = 18, ["param1"] = 15, ["z"] = 4, ["name"] = "default:glass"}, {["x"] = 2, ["y"] = 19, ["param1"] = 88, ["z"] = 0, ["name"] = "default:bronzeblock"}, {["x"] = 2, ["y"] = 19, ["param1"] = 15, ["z"] = 4, ["name"] = "default:glass"}, {["x"] = 2, ["y"] = 20, ["param1"] = 88, ["z"] = 0, ["name"] = "default:bronzeblock"}, {["x"] = 2, ["y"] = 20, ["param1"] = 15, ["z"] = 4, ["name"] = "default:glass"}, {["x"] = 2, ["y"] = 21, ["param1"] = 88, ["z"] = 0, ["name"] = "default:bronzeblock"}, {["x"] = 2, ["y"] = 21, ["z"] = 1, ["name"] = "default:bronzeblock"}, {["x"] = 2, ["y"] = 21, ["param1"] = 15, ["z"] = 2, ["name"] = "default:glass"}, {["x"] = 2, ["y"] = 21, ["param1"] = 15, ["z"] = 3, ["name"] = "default:glass"}, {["x"] = 2, ["y"] = 21, ["param1"] = 15, ["z"] = 4, ["name"] = "default:glass"}, {["x"] = 3, ["y"] = 0, ["z"] = 0, ["name"] = "default:bronzeblock"}, {["x"] = 3, ["y"] = 0, ["z"] = 1, ["name"] = "default:bronzeblock"}, {["x"] = 3, ["y"] = 0, ["z"] = 2, ["name"] = "default:bronzeblock"}, {["x"] = 3, ["y"] = 0, ["z"] = 3, ["name"] = "default:bronzeblock"}, {["x"] = 3, ["y"] = 0, ["z"] = 4, ["name"] = "default:bronzeblock"}, {["x"] = 3, ["y"] = 1, ["param1"] = 88, ["z"] = 0, ["name"] = "default:bronzeblock"}, {["x"] = 3, ["y"] = 1, ["param1"] = 88, ["z"] = 4, ["name"] = "default:bronzeblock"}, {["x"] = 3, ["y"] = 2, ["param1"] = 88, ["z"] = 0, ["name"] = "default:bronzeblock"}, {["x"] = 3, ["y"] = 2, ["param1"] = 88, ["z"] = 4, ["name"] = "default:bronzeblock"}, {["x"] = 3, ["y"] = 3, ["param1"] = 88, ["z"] = 0, ["name"] = "default:bronzeblock"}, {["x"] = 3, ["y"] = 3, ["param1"] = 88, ["z"] = 4, ["name"] = "default:bronzeblock"}, {["x"] = 3, ["y"] = 4, ["param1"] = 88, ["z"] = 0, ["name"] = "default:bronzeblock"}, {["x"] = 3, ["y"] = 4, ["z"] = 1, ["name"] = "default:bronzeblock"}, {["x"] = 3, ["y"] = 4, ["z"] = 2, ["name"] = "default:bronzeblock"}, {["x"] = 3, ["y"] = 4, ["z"] = 3, ["name"] = "default:bronzeblock"}, {["x"] = 3, ["y"] = 4, ["param1"] = 88, ["z"] = 4, ["name"] = "default:bronzeblock"}, {["x"] = 3, ["y"] = 5, ["param1"] = 88, ["z"] = 0, ["name"] = "default:bronzeblock"}, {["x"] = 3, ["y"] = 5, ["param1"] = 88, ["z"] = 4, ["name"] = "default:bronzeblock"}, {["x"] = 3, ["y"] = 6, ["param1"] = 88, ["z"] = 0, ["name"] = "default:bronzeblock"}, {["x"] = 3, ["y"] = 6, ["param1"] = 88, ["z"] = 4, ["name"] = "default:bronzeblock"}, {["x"] = 3, ["y"] = 7, ["param1"] = 88, ["z"] = 0, ["name"] = "default:bronzeblock"}, {["x"] = 3, ["y"] = 7, ["param1"] = 88, ["z"] = 4, ["name"] = "default:bronzeblock"}, {["x"] = 3, ["y"] = 8, ["param1"] = 88, ["z"] = 0, ["name"] = "default:bronzeblock"}, {["x"] = 3, ["y"] = 8, ["param1"] = 88, ["z"] = 4, ["name"] = "default:bronzeblock"}, {["x"] = 3, ["y"] = 9, ["param1"] = 88, ["z"] = 0, ["name"] = "default:bronzeblock"}, {["x"] = 3, ["y"] = 9, ["param1"] = 88, ["z"] = 4, ["name"] = "default:bronzeblock"}, {["x"] = 3, ["y"] = 10, ["param1"] = 88, ["z"] = 0, ["name"] = "default:bronzeblock"}, {["x"] = 3, ["y"] = 10, ["param1"] = 88, ["z"] = 4, ["name"] = "default:bronzeblock"}, {["x"] = 3, ["y"] = 11, ["param1"] = 88, ["z"] = 0, ["name"] = "default:bronzeblock"}, {["x"] = 3, ["y"] = 11, ["param1"] = 88, ["z"] = 4, ["name"] = "default:bronzeblock"}, {["x"] = 3, ["y"] = 12, ["param1"] = 88, ["z"] = 0, ["name"] = "default:bronzeblock"}, {["x"] = 3, ["y"] = 12, ["param1"] = 88, ["z"] = 4, ["name"] = "default:bronzeblock"}, {["x"] = 3, ["y"] = 13, ["param1"] = 88, ["z"] = 0, ["name"] = "default:bronzeblock"}, {["x"] = 3, ["y"] = 13, ["param1"] = 88, ["z"] = 4, ["name"] = "default:bronzeblock"}, {["x"] = 3, ["y"] = 14, ["param1"] = 88, ["z"] = 0, ["name"] = "default:bronzeblock"}, {["x"] = 3, ["y"] = 14, ["param1"] = 88, ["z"] = 4, ["name"] = "default:bronzeblock"}, {["x"] = 3, ["y"] = 15, ["param1"] = 88, ["z"] = 0, ["name"] = "default:bronzeblock"}, {["x"] = 3, ["y"] = 15, ["param1"] = 88, ["z"] = 4, ["name"] = "default:bronzeblock"}, {["x"] = 3, ["y"] = 16, ["param1"] = 88, ["z"] = 0, ["name"] = "default:bronzeblock"}, {["x"] = 3, ["y"] = 16, ["param1"] = 88, ["z"] = 4, ["name"] = "default:bronzeblock"}, {["x"] = 3, ["y"] = 17, ["param1"] = 88, ["z"] = 0, ["name"] = "default:bronzeblock"}, {["x"] = 3, ["y"] = 17, ["param1"] = 88, ["z"] = 4, ["name"] = "default:bronzeblock"}, {["x"] = 3, ["y"] = 18, ["param1"] = 88, ["z"] = 0, ["name"] = "default:bronzeblock"}, {["x"] = 3, ["y"] = 18, ["param1"] = 88, ["z"] = 4, ["name"] = "default:bronzeblock"}, {["x"] = 3, ["y"] = 19, ["param1"] = 88, ["z"] = 0, ["name"] = "default:bronzeblock"}, {["x"] = 3, ["y"] = 19, ["param1"] = 88, ["z"] = 4, ["name"] = "default:bronzeblock"}, {["x"] = 3, ["y"] = 20, ["param1"] = 88, ["z"] = 0, ["name"] = "default:bronzeblock"}, {["x"] = 3, ["y"] = 20, ["param1"] = 88, ["z"] = 4, ["name"] = "default:bronzeblock"}, {["x"] = 3, ["y"] = 21, ["param1"] = 88, ["z"] = 0, ["name"] = "default:bronzeblock"}, {["x"] = 3, ["y"] = 21, ["z"] = 1, ["name"] = "default:bronzeblock"}, {["x"] = 3, ["y"] = 21, ["z"] = 2, ["name"] = "default:bronzeblock"}, {["x"] = 3, ["y"] = 21, ["z"] = 3, ["name"] = "default:bronzeblock"}, {["x"] = 3, ["y"] = 21, ["param1"] = 88, ["z"] = 4, ["name"] = "default:bronzeblock"}, {["x"] = 4, ["y"] = 0, ["param1"] = 37, ["z"] = 0, ["name"] = "default:bronzeblock"}, {["x"] = 4, ["y"] = 0, ["z"] = 1, ["name"] = "default:bronzeblock"}, {["x"] = 4, ["y"] = 0, ["z"] = 2, ["name"] = "default:bronzeblock"}, {["x"] = 4, ["y"] = 0, ["z"] = 3, ["name"] = "default:bronzeblock"}, {["x"] = 4, ["y"] = 0, ["z"] = 4, ["name"] = "default:bronzeblock"}, {["x"] = 4, ["y"] = 1, ["param1"] = 88, ["z"] = 0, ["name"] = "default:bronzeblock"}, {["x"] = 4, ["y"] = 1, ["param1"] = 15, ["z"] = 4, ["name"] = "default:glass"}, {["x"] = 4, ["y"] = 2, ["param1"] = 88, ["z"] = 0, ["name"] = "default:bronzeblock"}, {["x"] = 4, ["y"] = 2, ["param1"] = 15, ["z"] = 4, ["name"] = "default:glass"}, {["x"] = 4, ["y"] = 3, ["param1"] = 88, ["z"] = 0, ["name"] = "default:bronzeblock"}, {["x"] = 4, ["y"] = 3, ["param1"] = 15, ["z"] = 4, ["name"] = "default:glass"}, {["x"] = 4, ["y"] = 4, ["param1"] = 88, ["z"] = 0, ["name"] = "default:bronzeblock"}, {["x"] = 4, ["y"] = 4, ["z"] = 1, ["name"] = "default:bronzeblock"}, {["x"] = 4, ["y"] = 4, ["z"] = 2, ["name"] = "default:bronzeblock"}, {["x"] = 4, ["y"] = 4, ["z"] = 3, ["name"] = "default:bronzeblock"}, {["x"] = 4, ["y"] = 4, ["param1"] = 15, ["z"] = 4, ["name"] = "default:glass"}, {["x"] = 4, ["y"] = 5, ["param1"] = 88, ["z"] = 0, ["name"] = "default:bronzeblock"}, {["x"] = 4, ["y"] = 5, ["param1"] = 15, ["z"] = 4, ["name"] = "default:glass"}, {["x"] = 4, ["y"] = 6, ["param1"] = 88, ["z"] = 0, ["name"] = "default:bronzeblock"}, {["x"] = 4, ["y"] = 6, ["param1"] = 15, ["z"] = 4, ["name"] = "default:glass"}, {["x"] = 4, ["y"] = 7, ["param1"] = 88, ["z"] = 0, ["name"] = "default:bronzeblock"}, {["x"] = 4, ["y"] = 7, ["param1"] = 14, ["z"] = 4, ["name"] = "default:glass"}, {["x"] = 4, ["y"] = 8, ["param1"] = 88, ["z"] = 0, ["name"] = "default:bronzeblock"}, {["x"] = 4, ["y"] = 8, ["param1"] = 15, ["z"] = 4, ["name"] = "default:glass"}, {["x"] = 4, ["y"] = 9, ["param1"] = 88, ["z"] = 0, ["name"] = "default:bronzeblock"}, {["x"] = 4, ["y"] = 9, ["param1"] = 15, ["z"] = 4, ["name"] = "default:glass"}, {["x"] = 4, ["y"] = 10, ["param1"] = 88, ["z"] = 0, ["name"] = "default:bronzeblock"}, {["x"] = 4, ["y"] = 10, ["param1"] = 15, ["z"] = 4, ["name"] = "default:glass"}, {["x"] = 4, ["y"] = 11, ["param1"] = 88, ["z"] = 0, ["name"] = "default:bronzeblock"}, {["x"] = 4, ["y"] = 11, ["param1"] = 15, ["z"] = 4, ["name"] = "default:glass"}, {["x"] = 4, ["y"] = 12, ["param1"] = 88, ["z"] = 0, ["name"] = "default:bronzeblock"}, {["x"] = 4, ["y"] = 12, ["param1"] = 15, ["z"] = 4, ["name"] = "default:glass"}, {["x"] = 4, ["y"] = 13, ["param1"] = 88, ["z"] = 0, ["name"] = "default:bronzeblock"}, {["x"] = 4, ["y"] = 13, ["param1"] = 15, ["z"] = 4, ["name"] = "default:glass"}, {["x"] = 4, ["y"] = 14, ["param1"] = 88, ["z"] = 0, ["name"] = "default:bronzeblock"}, {["x"] = 4, ["y"] = 14, ["param1"] = 15, ["z"] = 4, ["name"] = "default:glass"}, {["x"] = 4, ["y"] = 15, ["param1"] = 88, ["z"] = 0, ["name"] = "default:bronzeblock"}, {["x"] = 4, ["y"] = 15, ["param1"] = 15, ["z"] = 4, ["name"] = "default:glass"}, {["x"] = 4, ["y"] = 16, ["param1"] = 88, ["z"] = 0, ["name"] = "default:bronzeblock"}, {["x"] = 4, ["y"] = 16, ["param1"] = 15, ["z"] = 4, ["name"] = "default:glass"}, {["x"] = 4, ["y"] = 17, ["param1"] = 88, ["z"] = 0, ["name"] = "default:bronzeblock"}, {["x"] = 4, ["y"] = 17, ["param1"] = 15, ["z"] = 4, ["name"] = "default:glass"}, {["x"] = 4, ["y"] = 18, ["param1"] = 88, ["z"] = 0, ["name"] = "default:bronzeblock"}, {["x"] = 4, ["y"] = 18, ["param1"] = 15, ["z"] = 4, ["name"] = "default:glass"}, {["x"] = 4, ["y"] = 19, ["param1"] = 88, ["z"] = 0, ["name"] = "default:bronzeblock"}, {["x"] = 4, ["y"] = 19, ["param1"] = 15, ["z"] = 4, ["name"] = "default:glass"}, {["x"] = 4, ["y"] = 20, ["param1"] = 88, ["z"] = 0, ["name"] = "default:bronzeblock"}, {["x"] = 4, ["y"] = 20, ["param1"] = 15, ["z"] = 4, ["name"] = "default:glass"}, {["x"] = 4, ["y"] = 21, ["param1"] = 88, ["z"] = 0, ["name"] = "default:bronzeblock"}, {["x"] = 4, ["y"] = 21, ["z"] = 1, ["name"] = "default:bronzeblock"}, {["x"] = 4, ["y"] = 21, ["param1"] = 15, ["z"] = 2, ["name"] = "default:glass"}, {["x"] = 4, ["y"] = 21, ["param1"] = 15, ["z"] = 3, ["name"] = "default:glass"}, {["x"] = 4, ["y"] = 21, ["param1"] = 15, ["z"] = 4, ["name"] = "default:glass"}, {["x"] = 5, ["y"] = 0, ["z"] = 0, ["name"] = "default:bronzeblock"}, {["x"] = 5, ["y"] = 0, ["z"] = 1, ["name"] = "default:bronzeblock"}, {["x"] = 5, ["y"] = 0, ["z"] = 2, ["name"] = "default:bronzeblock"}, {["x"] = 5, ["y"] = 0, ["z"] = 3, ["name"] = "default:bronzeblock"}, {["x"] = 5, ["y"] = 0, ["z"] = 4, ["name"] = "default:bronzeblock"}, {["x"] = 5, ["y"] = 1, ["param1"] = 88, ["z"] = 0, ["name"] = "default:bronzeblock"}, {["x"] = 5, ["y"] = 1, ["param1"] = 88, ["z"] = 4, ["name"] = "default:bronzeblock"}, {["x"] = 5, ["y"] = 2, ["param1"] = 88, ["z"] = 0, ["name"] = "default:bronzeblock"}, {["x"] = 5, ["y"] = 2, ["param1"] = 88, ["z"] = 4, ["name"] = "default:bronzeblock"}, {["x"] = 5, ["y"] = 3, ["param1"] = 88, ["z"] = 0, ["name"] = "default:bronzeblock"}, {["x"] = 5, ["y"] = 3, ["param1"] = 88, ["z"] = 4, ["name"] = "default:bronzeblock"}, {["x"] = 5, ["y"] = 4, ["param1"] = 88, ["z"] = 0, ["name"] = "default:bronzeblock"}, {["x"] = 5, ["y"] = 4, ["z"] = 2, ["name"] = "default:bronzeblock"}, {["x"] = 5, ["y"] = 4, ["z"] = 3, ["name"] = "default:bronzeblock"}, {["x"] = 5, ["y"] = 4, ["param1"] = 88, ["z"] = 4, ["name"] = "default:bronzeblock"}, {["x"] = 5, ["y"] = 5, ["param1"] = 88, ["z"] = 0, ["name"] = "default:bronzeblock"}, {["x"] = 5, ["y"] = 5, ["param1"] = 88, ["z"] = 4, ["name"] = "default:bronzeblock"}, {["x"] = 5, ["y"] = 6, ["param1"] = 88, ["z"] = 0, ["name"] = "default:bronzeblock"}, {["x"] = 5, ["y"] = 6, ["param1"] = 88, ["z"] = 4, ["name"] = "default:bronzeblock"}, {["x"] = 5, ["y"] = 7, ["param1"] = 88, ["z"] = 0, ["name"] = "default:bronzeblock"}, {["x"] = 5, ["y"] = 7, ["param1"] = 88, ["z"] = 4, ["name"] = "default:bronzeblock"}, {["x"] = 5, ["y"] = 8, ["param1"] = 88, ["z"] = 0, ["name"] = "default:bronzeblock"}, {["x"] = 5, ["y"] = 8, ["param1"] = 88, ["z"] = 4, ["name"] = "default:bronzeblock"}, {["x"] = 5, ["y"] = 9, ["param1"] = 88, ["z"] = 0, ["name"] = "default:bronzeblock"}, {["x"] = 5, ["y"] = 9, ["param1"] = 88, ["z"] = 4, ["name"] = "default:bronzeblock"}, {["x"] = 5, ["y"] = 10, ["param1"] = 88, ["z"] = 0, ["name"] = "default:bronzeblock"}, {["x"] = 5, ["y"] = 10, ["param1"] = 88, ["z"] = 4, ["name"] = "default:bronzeblock"}, {["x"] = 5, ["y"] = 11, ["param1"] = 88, ["z"] = 0, ["name"] = "default:bronzeblock"}, {["x"] = 5, ["y"] = 11, ["param1"] = 88, ["z"] = 4, ["name"] = "default:bronzeblock"}, {["x"] = 5, ["y"] = 12, ["param1"] = 88, ["z"] = 0, ["name"] = "default:bronzeblock"}, {["x"] = 5, ["y"] = 12, ["param1"] = 88, ["z"] = 4, ["name"] = "default:bronzeblock"}, {["x"] = 5, ["y"] = 13, ["param1"] = 88, ["z"] = 0, ["name"] = "default:bronzeblock"}, {["x"] = 5, ["y"] = 13, ["param1"] = 88, ["z"] = 4, ["name"] = "default:bronzeblock"}, {["x"] = 5, ["y"] = 14, ["param1"] = 88, ["z"] = 0, ["name"] = "default:bronzeblock"}, {["x"] = 5, ["y"] = 14, ["param1"] = 88, ["z"] = 4, ["name"] = "default:bronzeblock"}, {["x"] = 5, ["y"] = 15, ["param1"] = 88, ["z"] = 0, ["name"] = "default:bronzeblock"}, {["x"] = 5, ["y"] = 15, ["param1"] = 88, ["z"] = 4, ["name"] = "default:bronzeblock"}, {["x"] = 5, ["y"] = 16, ["param1"] = 88, ["z"] = 0, ["name"] = "default:bronzeblock"}, {["x"] = 5, ["y"] = 16, ["param1"] = 88, ["z"] = 4, ["name"] = "default:bronzeblock"}, {["x"] = 5, ["y"] = 17, ["param1"] = 88, ["z"] = 0, ["name"] = "default:bronzeblock"}, {["x"] = 5, ["y"] = 17, ["param1"] = 88, ["z"] = 4, ["name"] = "default:bronzeblock"}, {["x"] = 5, ["y"] = 18, ["param1"] = 88, ["z"] = 0, ["name"] = "default:bronzeblock"}, {["x"] = 5, ["y"] = 18, ["param1"] = 88, ["z"] = 4, ["name"] = "default:bronzeblock"}, {["x"] = 5, ["y"] = 19, ["param1"] = 88, ["z"] = 0, ["name"] = "default:bronzeblock"}, {["x"] = 5, ["y"] = 19, ["param1"] = 88, ["z"] = 4, ["name"] = "default:bronzeblock"}, {["x"] = 5, ["y"] = 20, ["param1"] = 88, ["z"] = 0, ["name"] = "default:bronzeblock"}, {["x"] = 5, ["y"] = 20, ["param1"] = 88, ["z"] = 4, ["name"] = "default:bronzeblock"}, {["x"] = 5, ["y"] = 21, ["param1"] = 88, ["z"] = 0, ["name"] = "default:bronzeblock"}, {["x"] = 5, ["y"] = 21, ["z"] = 1, ["name"] = "default:bronzeblock"}, {["x"] = 5, ["y"] = 21, ["z"] = 2, ["name"] = "default:bronzeblock"}, {["x"] = 5, ["y"] = 21, ["z"] = 3, ["name"] = "default:bronzeblock"}, {["x"] = 5, ["y"] = 21, ["param1"] = 88, ["z"] = 4, ["name"] = "default:bronzeblock"}, {["x"] = 6, ["y"] = 0, ["param1"] = 36, ["z"] = 0, ["name"] = "default:bronzeblock"}, {["x"] = 6, ["y"] = 0, ["param1"] = 37, ["z"] = 1, ["name"] = "default:bronzeblock"}, {["x"] = 6, ["y"] = 0, ["z"] = 2, ["name"] = "default:bronzeblock"}, {["x"] = 6, ["y"] = 0, ["z"] = 3, ["name"] = "default:bronzeblock"}, {["x"] = 6, ["y"] = 0, ["z"] = 4, ["name"] = "default:bronzeblock"}, {["x"] = 6, ["y"] = 1, ["param1"] = 88, ["z"] = 0, ["name"] = "default:bronzeblock"}, {["x"] = 6, ["y"] = 1, ["param1"] = 88, ["z"] = 1, ["name"] = "default:bronzeblock"}, {["x"] = 6, ["y"] = 1, ["param1"] = 88, ["z"] = 3, ["name"] = "default:bronzeblock"}, {["x"] = 6, ["y"] = 1, ["param1"] = 88, ["z"] = 4, ["name"] = "default:bronzeblock"}, {["x"] = 6, ["y"] = 2, ["param1"] = 88, ["z"] = 0, ["name"] = "default:bronzeblock"}, {["x"] = 6, ["y"] = 2, ["param1"] = 88, ["z"] = 1, ["name"] = "default:bronzeblock"}, {["x"] = 6, ["y"] = 2, ["param1"] = 88, ["z"] = 3, ["name"] = "default:bronzeblock"}, {["x"] = 6, ["y"] = 2, ["param1"] = 88, ["z"] = 4, ["name"] = "default:bronzeblock"}, {["x"] = 6, ["y"] = 3, ["param1"] = 88, ["z"] = 0, ["name"] = "default:bronzeblock"}, {["x"] = 6, ["y"] = 3, ["param1"] = 88, ["z"] = 1, ["name"] = "default:bronzeblock"}, {["x"] = 6, ["y"] = 3, ["param1"] = 88, ["z"] = 2, ["name"] = "default:bronzeblock"}, {["x"] = 6, ["y"] = 3, ["param1"] = 88, ["z"] = 3, ["name"] = "default:bronzeblock"}, {["x"] = 6, ["y"] = 3, ["param1"] = 88, ["z"] = 4, ["name"] = "default:bronzeblock"}, {["x"] = 6, ["y"] = 4, ["param1"] = 88, ["z"] = 0, ["name"] = "default:bronzeblock"}, {["x"] = 6, ["y"] = 4, ["param1"] = 88, ["z"] = 1, ["name"] = "default:bronzeblock"}, {["x"] = 6, ["y"] = 4, ["param1"] = 88, ["z"] = 2, ["name"] = "default:bronzeblock"}, {["x"] = 6, ["y"] = 4, ["param1"] = 88, ["z"] = 3, ["name"] = "default:bronzeblock"}, {["x"] = 6, ["y"] = 4, ["param1"] = 88, ["z"] = 4, ["name"] = "default:bronzeblock"}, {["x"] = 6, ["y"] = 5, ["param1"] = 88, ["z"] = 0, ["name"] = "default:bronzeblock"}, {["x"] = 6, ["y"] = 5, ["param1"] = 88, ["z"] = 1, ["name"] = "default:bronzeblock"}, {["x"] = 6, ["y"] = 5, ["param1"] = 88, ["z"] = 2, ["name"] = "default:bronzeblock"}, {["x"] = 6, ["y"] = 5, ["param1"] = 88, ["z"] = 3, ["name"] = "default:bronzeblock"}, {["x"] = 6, ["y"] = 5, ["param1"] = 88, ["z"] = 4, ["name"] = "default:bronzeblock"}, {["x"] = 6, ["y"] = 6, ["param1"] = 88, ["z"] = 0, ["name"] = "default:bronzeblock"}, {["x"] = 6, ["y"] = 6, ["param1"] = 88, ["z"] = 1, ["name"] = "default:bronzeblock"}, {["x"] = 6, ["y"] = 6, ["param1"] = 88, ["z"] = 2, ["name"] = "default:bronzeblock"}, {["x"] = 6, ["y"] = 6, ["param1"] = 88, ["z"] = 3, ["name"] = "default:bronzeblock"}, {["x"] = 6, ["y"] = 6, ["param1"] = 88, ["z"] = 4, ["name"] = "default:bronzeblock"}, {["x"] = 6, ["y"] = 7, ["param1"] = 88, ["z"] = 0, ["name"] = "default:bronzeblock"}, {["x"] = 6, ["y"] = 7, ["param1"] = 88, ["z"] = 1, ["name"] = "default:bronzeblock"}, {["x"] = 6, ["y"] = 7, ["param1"] = 88, ["z"] = 2, ["name"] = "default:bronzeblock"}, {["x"] = 6, ["y"] = 7, ["param1"] = 88, ["z"] = 3, ["name"] = "default:bronzeblock"}, {["x"] = 6, ["y"] = 7, ["param1"] = 88, ["z"] = 4, ["name"] = "default:bronzeblock"}, {["x"] = 6, ["y"] = 8, ["param1"] = 88, ["z"] = 0, ["name"] = "default:bronzeblock"}, {["x"] = 6, ["y"] = 8, ["param1"] = 88, ["z"] = 1, ["name"] = "default:bronzeblock"}, {["x"] = 6, ["y"] = 8, ["param1"] = 88, ["z"] = 2, ["name"] = "default:bronzeblock"}, {["x"] = 6, ["y"] = 8, ["param1"] = 88, ["z"] = 3, ["name"] = "default:bronzeblock"}, {["x"] = 6, ["y"] = 8, ["param1"] = 88, ["z"] = 4, ["name"] = "default:bronzeblock"}, {["x"] = 6, ["y"] = 9, ["param1"] = 88, ["z"] = 0, ["name"] = "default:bronzeblock"}, {["x"] = 6, ["y"] = 9, ["param1"] = 88, ["z"] = 1, ["name"] = "default:bronzeblock"}, {["x"] = 6, ["y"] = 9, ["param1"] = 88, ["z"] = 2, ["name"] = "default:bronzeblock"}, {["x"] = 6, ["y"] = 9, ["param1"] = 88, ["z"] = 3, ["name"] = "default:bronzeblock"}, {["x"] = 6, ["y"] = 9, ["param1"] = 88, ["z"] = 4, ["name"] = "default:bronzeblock"}, {["x"] = 6, ["y"] = 10, ["param1"] = 88, ["z"] = 0, ["name"] = "default:bronzeblock"}, {["x"] = 6, ["y"] = 10, ["param1"] = 88, ["z"] = 1, ["name"] = "default:bronzeblock"}, {["x"] = 6, ["y"] = 10, ["param1"] = 88, ["z"] = 2, ["name"] = "default:bronzeblock"}, {["x"] = 6, ["y"] = 10, ["param1"] = 88, ["z"] = 3, ["name"] = "default:bronzeblock"}, {["x"] = 6, ["y"] = 10, ["param1"] = 88, ["z"] = 4, ["name"] = "default:bronzeblock"}, {["x"] = 6, ["y"] = 11, ["param1"] = 88, ["z"] = 0, ["name"] = "default:bronzeblock"}, {["x"] = 6, ["y"] = 11, ["param1"] = 88, ["z"] = 1, ["name"] = "default:bronzeblock"}, {["x"] = 6, ["y"] = 11, ["param1"] = 88, ["z"] = 2, ["name"] = "default:bronzeblock"}, {["x"] = 6, ["y"] = 11, ["param1"] = 88, ["z"] = 3, ["name"] = "default:bronzeblock"}, {["x"] = 6, ["y"] = 11, ["param1"] = 88, ["z"] = 4, ["name"] = "default:bronzeblock"}, {["x"] = 6, ["y"] = 12, ["param1"] = 88, ["z"] = 0, ["name"] = "default:bronzeblock"}, {["x"] = 6, ["y"] = 12, ["param1"] = 88, ["z"] = 1, ["name"] = "default:bronzeblock"}, {["x"] = 6, ["y"] = 12, ["param1"] = 88, ["z"] = 2, ["name"] = "default:bronzeblock"}, {["x"] = 6, ["y"] = 12, ["param1"] = 88, ["z"] = 3, ["name"] = "default:bronzeblock"}, {["x"] = 6, ["y"] = 12, ["param1"] = 88, ["z"] = 4, ["name"] = "default:bronzeblock"}, {["x"] = 6, ["y"] = 13, ["param1"] = 88, ["z"] = 0, ["name"] = "default:bronzeblock"}, {["x"] = 6, ["y"] = 13, ["param1"] = 88, ["z"] = 1, ["name"] = "default:bronzeblock"}, {["x"] = 6, ["y"] = 13, ["param1"] = 88, ["z"] = 2, ["name"] = "default:bronzeblock"}, {["x"] = 6, ["y"] = 13, ["param1"] = 88, ["z"] = 3, ["name"] = "default:bronzeblock"}, {["x"] = 6, ["y"] = 13, ["param1"] = 88, ["z"] = 4, ["name"] = "default:bronzeblock"}, {["x"] = 6, ["y"] = 14, ["param1"] = 88, ["z"] = 0, ["name"] = "default:bronzeblock"}, {["x"] = 6, ["y"] = 14, ["param1"] = 88, ["z"] = 1, ["name"] = "default:bronzeblock"}, {["x"] = 6, ["y"] = 14, ["param1"] = 88, ["z"] = 2, ["name"] = "default:bronzeblock"}, {["x"] = 6, ["y"] = 14, ["param1"] = 88, ["z"] = 3, ["name"] = "default:bronzeblock"}, {["x"] = 6, ["y"] = 14, ["param1"] = 88, ["z"] = 4, ["name"] = "default:bronzeblock"}, {["x"] = 6, ["y"] = 15, ["param1"] = 88, ["z"] = 0, ["name"] = "default:bronzeblock"}, {["x"] = 6, ["y"] = 15, ["param1"] = 88, ["z"] = 1, ["name"] = "default:bronzeblock"}, {["x"] = 6, ["y"] = 15, ["param1"] = 88, ["z"] = 2, ["name"] = "default:bronzeblock"}, {["x"] = 6, ["y"] = 15, ["param1"] = 88, ["z"] = 3, ["name"] = "default:bronzeblock"}, {["x"] = 6, ["y"] = 15, ["param1"] = 88, ["z"] = 4, ["name"] = "default:bronzeblock"}, {["x"] = 6, ["y"] = 16, ["param1"] = 88, ["z"] = 0, ["name"] = "default:bronzeblock"}, {["x"] = 6, ["y"] = 16, ["param1"] = 88, ["z"] = 1, ["name"] = "default:bronzeblock"}, {["x"] = 6, ["y"] = 16, ["param1"] = 88, ["z"] = 2, ["name"] = "default:bronzeblock"}, {["x"] = 6, ["y"] = 16, ["param1"] = 88, ["z"] = 3, ["name"] = "default:bronzeblock"}, {["x"] = 6, ["y"] = 16, ["param1"] = 88, ["z"] = 4, ["name"] = "default:bronzeblock"}, {["x"] = 6, ["y"] = 17, ["param1"] = 88, ["z"] = 0, ["name"] = "default:bronzeblock"}, {["x"] = 6, ["y"] = 17, ["param1"] = 88, ["z"] = 1, ["name"] = "default:bronzeblock"}, {["x"] = 6, ["y"] = 17, ["param1"] = 88, ["z"] = 2, ["name"] = "default:bronzeblock"}, {["x"] = 6, ["y"] = 17, ["param1"] = 88, ["z"] = 3, ["name"] = "default:bronzeblock"}, {["x"] = 6, ["y"] = 17, ["param1"] = 88, ["z"] = 4, ["name"] = "default:bronzeblock"}, {["x"] = 6, ["y"] = 18, ["param1"] = 88, ["z"] = 0, ["name"] = "default:bronzeblock"}, {["x"] = 6, ["y"] = 18, ["param1"] = 88, ["z"] = 1, ["name"] = "default:bronzeblock"}, {["x"] = 6, ["y"] = 18, ["param1"] = 88, ["z"] = 2, ["name"] = "default:bronzeblock"}, {["x"] = 6, ["y"] = 18, ["param1"] = 88, ["z"] = 3, ["name"] = "default:bronzeblock"}, {["x"] = 6, ["y"] = 18, ["param1"] = 88, ["z"] = 4, ["name"] = "default:bronzeblock"}, {["x"] = 6, ["y"] = 19, ["param1"] = 88, ["z"] = 0, ["name"] = "default:bronzeblock"}, {["x"] = 6, ["y"] = 19, ["param1"] = 88, ["z"] = 1, ["name"] = "default:bronzeblock"}, {["x"] = 6, ["y"] = 19, ["param1"] = 88, ["z"] = 2, ["name"] = "default:bronzeblock"}, {["x"] = 6, ["y"] = 19, ["param1"] = 88, ["z"] = 3, ["name"] = "default:bronzeblock"}, {["x"] = 6, ["y"] = 19, ["param1"] = 88, ["z"] = 4, ["name"] = "default:bronzeblock"}, {["x"] = 6, ["y"] = 20, ["param1"] = 88, ["z"] = 0, ["name"] = "default:bronzeblock"}, {["x"] = 6, ["y"] = 20, ["param1"] = 88, ["z"] = 1, ["name"] = "default:bronzeblock"}, {["x"] = 6, ["y"] = 20, ["param1"] = 88, ["z"] = 2, ["name"] = "default:bronzeblock"}, {["x"] = 6, ["y"] = 20, ["param1"] = 88, ["z"] = 3, ["name"] = "default:bronzeblock"}, {["x"] = 6, ["y"] = 20, ["param1"] = 88, ["z"] = 4, ["name"] = "default:bronzeblock"}, {["x"] = 6, ["y"] = 21, ["z"] = 0, ["name"] = "default:bronzeblock"}, {["x"] = 6, ["y"] = 21, ["param1"] = 88, ["z"] = 1, ["name"] = "default:bronzeblock"}, {["x"] = 6, ["y"] = 21, ["param1"] = 88, ["z"] = 2, ["name"] = "default:bronzeblock"}, {["x"] = 6, ["y"] = 21, ["param1"] = 88, ["z"] = 3, ["name"] = "default:bronzeblock"}, {["x"] = 6, ["y"] = 21, ["param1"] = 88, ["z"] = 4, ["name"] = "default:bronzeblock"}}