5:return {{["x"] = 0, ["y"] = 0, ["param1"] = 88, ["z"] = 0, ["name"] = "default:bronzeblock"}, {["x"] = 0, ["y"] = 0, ["param1"] = 88, ["z"] = 1, ["name"] = "default:bronzeblock"}, {["x"] = 0, ["y"] = 0, ["param1"] = 88, ["z"] = 2, ["name"] = "default:bronzeblock"}, {["x"] = 0, ["y"] = 0, ["param1"] = 88, ["z"] = 3, ["name"] = "default:bronzeblock"}, {["x"] = 0, ["y"] = 0, ["param1"] = 88, ["z"] = 4, ["name"] = "default:bronzeblock"}, {["x"] = 0, ["y"] = 0, ["param1"] = 88, ["z"] = 5, ["name"] = "default:bronzeblock"}, {["x"] = 0, ["y"] = 1, ["param1"] = 88, ["z"] = 0, ["name"] = "default:bronzeblock"}, {["x"] = 0, ["y"] = 1, ["param1"] = 88, ["z"] = 1, ["name"] = "default:bronzeblock"}, {["x"] = 0, ["y"] = 1, ["param1"] = 88, ["z"] = 3, ["name"] = "default:bronzeblock"}, {["x"] = 0, ["y"] = 1, ["param1"] = 88, ["z"] = 4, ["name"] = "default:bronzeblock"}, {["x"] = 0, ["y"] = 2, ["param1"] = 238, ["z"] = 0, ["name"] = "default:meselamp"}, {["x"] = 0, ["y"] = 2, ["param1"] = 88, ["z"] = 1, ["name"] = "default:bronzeblock"}, {["x"] = 0, ["y"] = 2, ["param1"] = 88, ["z"] = 3, ["name"] = "default:bronzeblock"}, {["x"] = 0, ["y"] = 2, ["param1"] = 238, ["z"] = 4, ["name"] = "default:meselamp"}, {["x"] = 0, ["y"] = 3, ["param1"] = 238, ["z"] = 0, ["name"] = "default:meselamp"}, {["x"] = 0, ["y"] = 3, ["param1"] = 88, ["z"] = 1, ["name"] = "default:bronzeblock"}, {["x"] = 0, ["y"] = 3, ["param1"] = 88, ["z"] = 2, ["name"] = "default:bronzeblock"}, {["x"] = 0, ["y"] = 3, ["param1"] = 88, ["z"] = 3, ["name"] = "default:bronzeblock"}, {["x"] = 0, ["y"] = 3, ["param1"] = 238, ["z"] = 4, ["name"] = "default:meselamp"}, {["x"] = 0, ["y"] = 4, ["param1"] = 238, ["z"] = 0, ["name"] = "default:meselamp"}, {["x"] = 0, ["y"] = 4, ["param1"] = 88, ["z"] = 1, ["name"] = "default:bronzeblock"}, {["x"] = 0, ["y"] = 4, ["param1"] = 174, ["z"] = 2, ["name"] = "default:glass"}, {["x"] = 0, ["y"] = 4, ["param1"] = 88, ["z"] = 3, ["name"] = "default:bronzeblock"}, {["x"] = 0, ["y"] = 4, ["param1"] = 238, ["z"] = 4, ["name"] = "default:meselamp"}, {["x"] = 0, ["y"] = 5, ["param1"] = 238, ["z"] = 0, ["name"] = "default:meselamp"}, {["x"] = 0, ["y"] = 5, ["param1"] = 88, ["z"] = 1, ["name"] = "default:bronzeblock"}, {["x"] = 0, ["y"] = 5, ["param1"] = 174, ["z"] = 2, ["name"] = "default:glass"}, {["x"] = 0, ["y"] = 5, ["param1"] = 88, ["z"] = 3, ["name"] = "default:bronzeblock"}, {["x"] = 0, ["y"] = 5, ["param1"] = 238, ["z"] = 4, ["name"] = "default:meselamp"}, {["x"] = 0, ["y"] = 6, ["param1"] = 238, ["z"] = 0, ["name"] = "default:meselamp"}, {["x"] = 0, ["y"] = 6, ["param1"] = 88, ["z"] = 1, ["name"] = "default:bronzeblock"}, {["x"] = 0, ["y"] = 6, ["param1"] = 174, ["z"] = 2, ["name"] = "default:glass"}, {["x"] = 0, ["y"] = 6, ["param1"] = 88, ["z"] = 3, ["name"] = "default:bronzeblock"}, {["x"] = 0, ["y"] = 6, ["param1"] = 238, ["z"] = 4, ["name"] = "default:meselamp"}, {["x"] = 0, ["y"] = 7, ["param1"] = 238, ["z"] = 0, ["name"] = "default:meselamp"}, {["x"] = 0, ["y"] = 7, ["param1"] = 88, ["z"] = 1, ["name"] = "default:bronzeblock"}, {["x"] = 0, ["y"] = 7, ["param1"] = 174, ["z"] = 2, ["name"] = "default:glass"}, {["x"] = 0, ["y"] = 7, ["param1"] = 88, ["z"] = 3, ["name"] = "default:bronzeblock"}, {["x"] = 0, ["y"] = 7, ["param1"] = 238, ["z"] = 4, ["name"] = "default:meselamp"}, {["x"] = 0, ["y"] = 8, ["param1"] = 238, ["z"] = 0, ["name"] = "default:meselamp"}, {["x"] = 0, ["y"] = 8, ["param1"] = 88, ["z"] = 1, ["name"] = "default:bronzeblock"}, {["x"] = 0, ["y"] = 8, ["param1"] = 174, ["z"] = 2, ["name"] = "default:glass"}, {["x"] = 0, ["y"] = 8, ["param1"] = 88, ["z"] = 3, ["name"] = "default:bronzeblock"}, {["x"] = 0, ["y"] = 8, ["param1"] = 238, ["z"] = 4, ["name"] = "default:meselamp"}, {["x"] = 0, ["y"] = 9, ["param1"] = 238, ["z"] = 0, ["name"] = "default:meselamp"}, {["x"] = 0, ["y"] = 9, ["param1"] = 88, ["z"] = 1, ["name"] = "default:bronzeblock"}, {["x"] = 0, ["y"] = 9, ["param1"] = 174, ["z"] = 2, ["name"] = "default:glass"}, {["x"] = 0, ["y"] = 9, ["param1"] = 88, ["z"] = 3, ["name"] = "default:bronzeblock"}, {["x"] = 0, ["y"] = 9, ["param1"] = 238, ["z"] = 4, ["name"] = "default:meselamp"}, {["x"] = 0, ["y"] = 10, ["param1"] = 238, ["z"] = 0, ["name"] = "default:meselamp"}, {["x"] = 0, ["y"] = 10, ["param1"] = 88, ["z"] = 1, ["name"] = "default:bronzeblock"}, {["x"] = 0, ["y"] = 10, ["param1"] = 174, ["z"] = 2, ["name"] = "default:glass"}, {["x"] = 0, ["y"] = 10, ["param1"] = 88, ["z"] = 3, ["name"] = "default:bronzeblock"}, {["x"] = 0, ["y"] = 10, ["param1"] = 238, ["z"] = 4, ["name"] = "default:meselamp"}, {["x"] = 0, ["y"] = 11, ["param1"] = 238, ["z"] = 0, ["name"] = "default:meselamp"}, {["x"] = 0, ["y"] = 11, ["param1"] = 88, ["z"] = 1, ["name"] = "default:bronzeblock"}, {["x"] = 0, ["y"] = 11, ["param1"] = 174, ["z"] = 2, ["name"] = "default:glass"}, {["x"] = 0, ["y"] = 11, ["param1"] = 88, ["z"] = 3, ["name"] = "default:bronzeblock"}, {["x"] = 0, ["y"] = 11, ["param1"] = 238, ["z"] = 4, ["name"] = "default:meselamp"}, {["x"] = 0, ["y"] = 12, ["param1"] = 238, ["z"] = 0, ["name"] = "default:meselamp"}, {["x"] = 0, ["y"] = 12, ["param1"] = 88, ["z"] = 1, ["name"] = "default:bronzeblock"}, {["x"] = 0, ["y"] = 12, ["param1"] = 174, ["z"] = 2, ["name"] = "default:glass"}, {["x"] = 0, ["y"] = 12, ["param1"] = 88, ["z"] = 3, ["name"] = "default:bronzeblock"}, {["x"] = 0, ["y"] = 12, ["param1"] = 238, ["z"] = 4, ["name"] = "default:meselamp"}, {["x"] = 0, ["y"] = 13, ["param1"] = 238, ["z"] = 0, ["name"] = "default:meselamp"}, {["x"] = 0, ["y"] = 13, ["param1"] = 88, ["z"] = 1, ["name"] = "default:bronzeblock"}, {["x"] = 0, ["y"] = 13, ["param1"] = 174, ["z"] = 2, ["name"] = "default:glass"}, {["x"] = 0, ["y"] = 13, ["param1"] = 88, ["z"] = 3, ["name"] = "default:bronzeblock"}, {["x"] = 0, ["y"] = 13, ["param1"] = 238, ["z"] = 4, ["name"] = "default:meselamp"}, {["x"] = 0, ["y"] = 14, ["param1"] = 238, ["z"] = 0, ["name"] = "default:meselamp"}, {["x"] = 0, ["y"] = 14, ["param1"] = 88, ["z"] = 1, ["name"] = "default:bronzeblock"}, {["x"] = 0, ["y"] = 14, ["param1"] = 174, ["z"] = 2, ["name"] = "default:glass"}, {["x"] = 0, ["y"] = 14, ["param1"] = 88, ["z"] = 3, ["name"] = "default:bronzeblock"}, {["x"] = 0, ["y"] = 14, ["param1"] = 238, ["z"] = 4, ["name"] = "default:meselamp"}, {["x"] = 0, ["y"] = 15, ["param1"] = 238, ["z"] = 0, ["name"] = "default:meselamp"}, {["x"] = 0, ["y"] = 15, ["param1"] = 88, ["z"] = 1, ["name"] = "default:bronzeblock"}, {["x"] = 0, ["y"] = 15, ["param1"] = 174, ["z"] = 2, ["name"] = "default:glass"}, {["x"] = 0, ["y"] = 15, ["param1"] = 88, ["z"] = 3, ["name"] = "default:bronzeblock"}, {["x"] = 0, ["y"] = 15, ["param1"] = 238, ["z"] = 4, ["name"] = "default:meselamp"}, {["x"] = 0, ["y"] = 16, ["param1"] = 238, ["z"] = 0, ["name"] = "default:meselamp"}, {["x"] = 0, ["y"] = 16, ["param1"] = 88, ["z"] = 1, ["name"] = "default:bronzeblock"}, {["x"] = 0, ["y"] = 16, ["param1"] = 174, ["z"] = 2, ["name"] = "default:glass"}, {["x"] = 0, ["y"] = 16, ["param1"] = 88, ["z"] = 3, ["name"] = "default:bronzeblock"}, {["x"] = 0, ["y"] = 16, ["param1"] = 238, ["z"] = 4, ["name"] = "default:meselamp"}, {["x"] = 0, ["y"] = 17, ["param1"] = 238, ["z"] = 0, ["name"] = "default:meselamp"}, {["x"] = 0, ["y"] = 17, ["param1"] = 88, ["z"] = 1, ["name"] = "default:bronzeblock"}, {["x"] = 0, ["y"] = 17, ["param1"] = 174, ["z"] = 2, ["name"] = "default:glass"}, {["x"] = 0, ["y"] = 17, ["param1"] = 88, ["z"] = 3, ["name"] = "default:bronzeblock"}, {["x"] = 0, ["y"] = 17, ["param1"] = 238, ["z"] = 4, ["name"] = "default:meselamp"}, {["x"] = 0, ["y"] = 18, ["param1"] = 238, ["z"] = 0, ["name"] = "default:meselamp"}, {["x"] = 0, ["y"] = 18, ["param1"] = 88, ["z"] = 1, ["name"] = "default:bronzeblock"}, {["x"] = 0, ["y"] = 18, ["param1"] = 174, ["z"] = 2, ["name"] = "default:glass"}, {["x"] = 0, ["y"] = 18, ["param1"] = 88, ["z"] = 3, ["name"] = "default:bronzeblock"}, {["x"] = 0, ["y"] = 18, ["param1"] = 238, ["z"] = 4, ["name"] = "default:meselamp"}, {["x"] = 0, ["y"] = 19, ["param1"] = 238, ["z"] = 0, ["name"] = "default:meselamp"}, {["x"] = 0, ["y"] = 19, ["param1"] = 88, ["z"] = 1, ["name"] = "default:bronzeblock"}, {["x"] = 0, ["y"] = 19, ["param1"] = 174, ["z"] = 2, ["name"] = "default:glass"}, {["x"] = 0, ["y"] = 19, ["param1"] = 88, ["z"] = 3, ["name"] = "default:bronzeblock"}, {["x"] = 0, ["y"] = 19, ["param1"] = 238, ["z"] = 4, ["name"] = "default:meselamp"}, {["x"] = 0, ["y"] = 20, ["param1"] = 238, ["z"] = 0, ["name"] = "default:meselamp"}, {["x"] = 0, ["y"] = 20, ["param1"] = 88, ["z"] = 1, ["name"] = "default:bronzeblock"}, {["x"] = 0, ["y"] = 20, ["param1"] = 174, ["z"] = 2, ["name"] = "default:glass"}, {["x"] = 0, ["y"] = 20, ["param1"] = 88, ["z"] = 3, ["name"] = "default:bronzeblock"}, {["x"] = 0, ["y"] = 20, ["param1"] = 238, ["z"] = 4, ["name"] = "default:meselamp"}, {["x"] = 0, ["y"] = 21, ["param1"] = 238, ["z"] = 0, ["name"] = "default:meselamp"}, {["x"] = 0, ["y"] = 21, ["param1"] = 88, ["z"] = 1, ["name"] = "default:bronzeblock"}, {["x"] = 0, ["y"] = 21, ["param1"] = 174, ["z"] = 2, ["name"] = "default:glass"}, {["x"] = 0, ["y"] = 21, ["param1"] = 88, ["z"] = 3, ["name"] = "default:bronzeblock"}, {["x"] = 0, ["y"] = 21, ["param1"] = 238, ["z"] = 4, ["name"] = "default:meselamp"}, {["x"] = 0, ["y"] = 22, ["param1"] = 238, ["z"] = 0, ["name"] = "default:meselamp"}, {["x"] = 0, ["y"] = 22, ["param1"] = 88, ["z"] = 1, ["name"] = "default:bronzeblock"}, {["x"] = 0, ["y"] = 22, ["param1"] = 174, ["z"] = 2, ["name"] = "default:glass"}, {["x"] = 0, ["y"] = 22, ["param1"] = 88, ["z"] = 3, ["name"] = "default:bronzeblock"}, {["x"] = 0, ["y"] = 22, ["param1"] = 238, ["z"] = 4, ["name"] = "default:meselamp"}, {["x"] = 0, ["y"] = 23, ["param1"] = 238, ["z"] = 0, ["name"] = "default:meselamp"}, {["x"] = 0, ["y"] = 23, ["param1"] = 88, ["z"] = 1, ["name"] = "default:bronzeblock"}, {["x"] = 0, ["y"] = 23, ["param1"] = 174, ["z"] = 2, ["name"] = "default:glass"}, {["x"] = 0, ["y"] = 23, ["param1"] = 88, ["z"] = 3, ["name"] = "default:bronzeblock"}, {["x"] = 0, ["y"] = 23, ["param1"] = 238, ["z"] = 4, ["name"] = "default:meselamp"}, {["x"] = 0, ["y"] = 24, ["param1"] = 239, ["z"] = 0, ["name"] = "default:bronzeblock"}, {["x"] = 0, ["y"] = 24, ["param1"] = 88, ["z"] = 1, ["name"] = "default:bronzeblock"}, {["x"] = 0, ["y"] = 24, ["param1"] = 175, ["z"] = 2, ["name"] = "default:bronzeblock"}, {["x"] = 0, ["y"] = 24, ["param1"] = 88, ["z"] = 3, ["name"] = "default:bronzeblock"}, {["x"] = 0, ["y"] = 24, ["param1"] = 239, ["z"] = 4, ["name"] = "default:bronzeblock"}, {["x"] = 1, ["y"] = 0, ["param1"] = 88, ["z"] = 0, ["name"] = "default:bronzeblock"}, {["x"] = 1, ["y"] = 0, ["param1"] = 88, ["z"] = 1, ["name"] = "default:bronzeblock"}, {["x"] = 1, ["y"] = 0, ["param1"] = 88, ["z"] = 2, ["name"] = "default:bronzeblock"}, {["x"] = 1, ["y"] = 0, ["param1"] = 88, ["z"] = 3, ["name"] = "default:bronzeblock"}, {["x"] = 1, ["y"] = 0, ["param1"] = 88, ["z"] = 4, ["name"] = "default:bronzeblock"}, {["x"] = 1, ["y"] = 0, ["param1"] = 88, ["z"] = 5, ["name"] = "default:bronzeblock"}, {["x"] = 1, ["y"] = 1, ["param1"] = 88, ["z"] = 0, ["name"] = "default:bronzeblock"}, {["x"] = 1, ["y"] = 1, ["param1"] = 88, ["z"] = 4, ["name"] = "default:bronzeblock"}, {["x"] = 1, ["y"] = 2, ["param1"] = 88, ["z"] = 0, ["name"] = "default:bronzeblock"}, {["x"] = 1, ["y"] = 2, ["param1"] = 88, ["z"] = 4, ["name"] = "default:bronzeblock"}, {["x"] = 1, ["y"] = 3, ["param1"] = 88, ["z"] = 0, ["name"] = "default:bronzeblock"}, {["x"] = 1, ["y"] = 3, ["param1"] = 88, ["z"] = 4, ["name"] = "default:bronzeblock"}, {["x"] = 1, ["y"] = 4, ["param1"] = 88, ["z"] = 0, ["name"] = "default:bronzeblock"}, {["x"] = 1, ["y"] = 4, ["param1"] = 88, ["z"] = 4, ["name"] = "default:bronzeblock"}, {["x"] = 1, ["y"] = 5, ["param1"] = 88, ["z"] = 0, ["name"] = "default:bronzeblock"}, {["x"] = 1, ["y"] = 5, ["param1"] = 88, ["z"] = 4, ["name"] = "default:bronzeblock"}, {["x"] = 1, ["y"] = 6, ["param1"] = 88, ["z"] = 0, ["name"] = "default:bronzeblock"}, {["x"] = 1, ["y"] = 6, ["param1"] = 88, ["z"] = 4, ["name"] = "default:bronzeblock"}, {["x"] = 1, ["y"] = 7, ["param1"] = 88, ["z"] = 0, ["name"] = "default:bronzeblock"}, {["x"] = 1, ["y"] = 7, ["param1"] = 88, ["z"] = 4, ["name"] = "default:bronzeblock"}, {["x"] = 1, ["y"] = 8, ["param1"] = 88, ["z"] = 0, ["name"] = "default:bronzeblock"}, {["x"] = 1, ["y"] = 8, ["param1"] = 88, ["z"] = 4, ["name"] = "default:bronzeblock"}, {["x"] = 1, ["y"] = 9, ["param1"] = 88, ["z"] = 0, ["name"] = "default:bronzeblock"}, {["x"] = 1, ["y"] = 9, ["param1"] = 88, ["z"] = 4, ["name"] = "default:bronzeblock"}, {["x"] = 1, ["y"] = 10, ["param1"] = 88, ["z"] = 0, ["name"] = "default:bronzeblock"}, {["x"] = 1, ["y"] = 10, ["param1"] = 88, ["z"] = 4, ["name"] = "default:bronzeblock"}, {["x"] = 1, ["y"] = 11, ["param1"] = 88, ["z"] = 0, ["name"] = "default:bronzeblock"}, {["x"] = 1, ["y"] = 11, ["param1"] = 88, ["z"] = 4, ["name"] = "default:bronzeblock"}, {["x"] = 1, ["y"] = 12, ["param1"] = 88, ["z"] = 0, ["name"] = "default:bronzeblock"}, {["x"] = 1, ["y"] = 12, ["param1"] = 88, ["z"] = 4, ["name"] = "default:bronzeblock"}, {["x"] = 1, ["y"] = 13, ["param1"] = 88, ["z"] = 0, ["name"] = "default:bronzeblock"}, {["x"] = 1, ["y"] = 13, ["param1"] = 88, ["z"] = 4, ["name"] = "default:bronzeblock"}, {["x"] = 1, ["y"] = 14, ["param1"] = 88, ["z"] = 0, ["name"] = "default:bronzeblock"}, {["x"] = 1, ["y"] = 14, ["param1"] = 88, ["z"] = 4, ["name"] = "default:bronzeblock"}, {["x"] = 1, ["y"] = 15, ["param1"] = 88, ["z"] = 0, ["name"] = "default:bronzeblock"}, {["x"] = 1, ["y"] = 15, ["param1"] = 88, ["z"] = 4, ["name"] = "default:bronzeblock"}, {["x"] = 1, ["y"] = 16, ["param1"] = 88, ["z"] = 0, ["name"] = "default:bronzeblock"}, {["x"] = 1, ["y"] = 16, ["param1"] = 88, ["z"] = 4, ["name"] = "default:bronzeblock"}, {["x"] = 1, ["y"] = 17, ["param1"] = 88, ["z"] = 0, ["name"] = "default:bronzeblock"}, {["x"] = 1, ["y"] = 17, ["param1"] = 88, ["z"] = 4, ["name"] = "default:bronzeblock"}, {["x"] = 1, ["y"] = 18, ["param1"] = 88, ["z"] = 0, ["name"] = "default:bronzeblock"}, {["x"] = 1, ["y"] = 18, ["param1"] = 88, ["z"] = 4, ["name"] = "default:bronzeblock"}, {["x"] = 1, ["y"] = 19, ["param1"] = 88, ["z"] = 0, ["name"] = "default:bronzeblock"}, {["x"] = 1, ["y"] = 19, ["param1"] = 88, ["z"] = 4, ["name"] = "default:bronzeblock"}, {["x"] = 1, ["y"] = 20, ["param1"] = 88, ["z"] = 0, ["name"] = "default:bronzeblock"}, {["x"] = 1, ["y"] = 20, ["param1"] = 88, ["z"] = 4, ["name"] = "default:bronzeblock"}, {["x"] = 1, ["y"] = 21, ["param1"] = 88, ["z"] = 0, ["name"] = "default:bronzeblock"}, {["x"] = 1, ["y"] = 21, ["param1"] = 88, ["z"] = 4, ["name"] = "default:bronzeblock"}, {["x"] = 1, ["y"] = 22, ["param1"] = 88, ["z"] = 0, ["name"] = "default:bronzeblock"}, {["x"] = 1, ["y"] = 22, ["param1"] = 88, ["z"] = 4, ["name"] = "default:bronzeblock"}, {["x"] = 1, ["y"] = 23, ["param1"] = 88, ["z"] = 0, ["name"] = "default:bronzeblock"}, {["x"] = 1, ["y"] = 23, ["param1"] = 88, ["z"] = 4, ["name"] = "default:bronzeblock"}, {["x"] = 1, ["y"] = 24, ["param1"] = 88, ["z"] = 0, ["name"] = "default:bronzeblock"}, {["x"] = 1, ["y"] = 24, ["param1"] = 175, ["z"] = 1, ["name"] = "default:bronzeblock"}, {["x"] = 1, ["y"] = 24, ["param1"] = 159, ["z"] = 2, ["name"] = "default:bronzeblock"}, {["x"] = 1, ["y"] = 24, ["param1"] = 175, ["z"] = 3, ["name"] = "default:bronzeblock"}, {["x"] = 1, ["y"] = 24, ["param1"] = 88, ["z"] = 4, ["name"] = "default:bronzeblock"}, {["x"] = 2, ["y"] = 0, ["param1"] = 88, ["z"] = 0, ["name"] = "default:bronzeblock"}, {["x"] = 2, ["y"] = 0, ["param1"] = 88, ["z"] = 1, ["name"] = "default:bronzeblock"}, {["x"] = 2, ["y"] = 0, ["param1"] = 88, ["z"] = 2, ["name"] = "default:bronzeblock"}, {["x"] = 2, ["y"] = 0, ["param1"] = 88, ["z"] = 3, ["name"] = "default:bronzeblock"}, {["x"] = 2, ["y"] = 0, ["param1"] = 88, ["z"] = 4, ["name"] = "default:bronzeblock"}, {["x"] = 2, ["y"] = 0, ["param1"] = 88, ["z"] = 5, ["name"] = "default:bronzeblock"}, {["x"] = 2, ["y"] = 3, ["param1"] = 88, ["z"] = 0, ["name"] = "default:bronzeblock"}, {["x"] = 2, ["y"] = 3, ["param1"] = 88, ["z"] = 4, ["name"] = "default:bronzeblock"}, {["x"] = 2, ["y"] = 4, ["param1"] = 174, ["z"] = 0, ["name"] = "default:glass"}, {["x"] = 2, ["y"] = 4, ["param1"] = 174, ["z"] = 4, ["name"] = "default:glass"}, {["x"] = 2, ["y"] = 5, ["param1"] = 174, ["z"] = 0, ["name"] = "default:glass"}, {["x"] = 2, ["y"] = 5, ["param1"] = 174, ["z"] = 4, ["name"] = "default:glass"}, {["x"] = 2, ["y"] = 6, ["param1"] = 174, ["z"] = 0, ["name"] = "default:glass"}, {["x"] = 2, ["y"] = 6, ["param1"] = 174, ["z"] = 4, ["name"] = "default:glass"}, {["x"] = 2, ["y"] = 7, ["param1"] = 174, ["z"] = 0, ["name"] = "default:glass"}, {["x"] = 2, ["y"] = 7, ["param1"] = 174, ["z"] = 4, ["name"] = "default:glass"}, {["x"] = 2, ["y"] = 8, ["param1"] = 174, ["z"] = 0, ["name"] = "default:glass"}, {["x"] = 2, ["y"] = 8, ["param1"] = 174, ["z"] = 4, ["name"] = "default:glass"}, {["x"] = 2, ["y"] = 9, ["param1"] = 174, ["z"] = 0, ["name"] = "default:glass"}, {["x"] = 2, ["y"] = 9, ["param1"] = 174, ["z"] = 4, ["name"] = "default:glass"}, {["x"] = 2, ["y"] = 10, ["param1"] = 174, ["z"] = 0, ["name"] = "default:glass"}, {["x"] = 2, ["y"] = 10, ["param1"] = 174, ["z"] = 4, ["name"] = "default:glass"}, {["x"] = 2, ["y"] = 11, ["param1"] = 174, ["z"] = 0, ["name"] = "default:glass"}, {["x"] = 2, ["y"] = 11, ["param1"] = 174, ["z"] = 4, ["name"] = "default:glass"}, {["x"] = 2, ["y"] = 12, ["param1"] = 174, ["z"] = 0, ["name"] = "default:glass"}, {["x"] = 2, ["y"] = 12, ["param1"] = 174, ["z"] = 4, ["name"] = "default:glass"}, {["x"] = 2, ["y"] = 13, ["param1"] = 174, ["z"] = 0, ["name"] = "default:glass"}, {["x"] = 2, ["y"] = 13, ["param1"] = 174, ["z"] = 4, ["name"] = "default:glass"}, {["x"] = 2, ["y"] = 14, ["param1"] = 174, ["z"] = 0, ["name"] = "default:glass"}, {["x"] = 2, ["y"] = 14, ["param1"] = 174, ["z"] = 4, ["name"] = "default:glass"}, {["x"] = 2, ["y"] = 15, ["param1"] = 174, ["z"] = 0, ["name"] = "default:glass"}, {["x"] = 2, ["y"] = 15, ["param1"] = 174, ["z"] = 4, ["name"] = "default:glass"}, {["x"] = 2, ["y"] = 16, ["param1"] = 174, ["z"] = 0, ["name"] = "default:glass"}, {["x"] = 2, ["y"] = 16, ["param1"] = 174, ["z"] = 4, ["name"] = "default:glass"}, {["x"] = 2, ["y"] = 17, ["param1"] = 174, ["z"] = 0, ["name"] = "default:glass"}, {["x"] = 2, ["y"] = 17, ["param1"] = 174, ["z"] = 4, ["name"] = "default:glass"}, {["x"] = 2, ["y"] = 18, ["param1"] = 174, ["z"] = 0, ["name"] = "default:glass"}, {["x"] = 2, ["y"] = 18, ["param1"] = 174, ["z"] = 4, ["name"] = "default:glass"}, {["x"] = 2, ["y"] = 19, ["param1"] = 174, ["z"] = 0, ["name"] = "default:glass"}, {["x"] = 2, ["y"] = 19, ["param1"] = 174, ["z"] = 4, ["name"] = "default:glass"}, {["x"] = 2, ["y"] = 20, ["param1"] = 174, ["z"] = 0, ["name"] = "default:glass"}, {["x"] = 2, ["y"] = 20, ["param1"] = 174, ["z"] = 4, ["name"] = "default:glass"}, {["x"] = 2, ["y"] = 21, ["param1"] = 174, ["z"] = 0, ["name"] = "default:glass"}, {["x"] = 2, ["y"] = 21, ["param1"] = 174, ["z"] = 4, ["name"] = "default:glass"}, {["x"] = 2, ["y"] = 22, ["param1"] = 174, ["z"] = 0, ["name"] = "default:glass"}, {["x"] = 2, ["y"] = 22, ["param1"] = 174, ["z"] = 4, ["name"] = "default:glass"}, {["x"] = 2, ["y"] = 23, ["param1"] = 174, ["z"] = 0, ["name"] = "default:glass"}, {["x"] = 2, ["y"] = 23, ["param1"] = 174, ["z"] = 4, ["name"] = "default:glass"}, {["x"] = 2, ["y"] = 24, ["param1"] = 175, ["z"] = 0, ["name"] = "default:bronzeblock"}, {["x"] = 2, ["y"] = 24, ["param1"] = 159, ["z"] = 1, ["name"] = "default:bronzeblock"}, {["x"] = 2, ["y"] = 24, ["param1"] = 143, ["z"] = 2, ["name"] = "default:bronzeblock"}, {["x"] = 2, ["y"] = 24, ["param1"] = 159, ["z"] = 3, ["name"] = "default:bronzeblock"}, {["x"] = 2, ["y"] = 24, ["param1"] = 175, ["z"] = 4, ["name"] = "default:bronzeblock"}, {["x"] = 3, ["y"] = 0, ["param1"] = 88, ["z"] = 0, ["name"] = "default:bronzeblock"}, {["x"] = 3, ["y"] = 0, ["param1"] = 88, ["z"] = 1, ["name"] = "default:bronzeblock"}, {["x"] = 3, ["y"] = 0, ["param1"] = 88, ["z"] = 2, ["name"] = "default:bronzeblock"}, {["x"] = 3, ["y"] = 0, ["param1"] = 88, ["z"] = 3, ["name"] = "default:bronzeblock"}, {["x"] = 3, ["y"] = 0, ["param1"] = 88, ["z"] = 4, ["name"] = "default:bronzeblock"}, {["x"] = 3, ["y"] = 0, ["param1"] = 88, ["z"] = 5, ["name"] = "default:bronzeblock"}, {["x"] = 3, ["y"] = 1, ["param1"] = 88, ["z"] = 0, ["name"] = "default:bronzeblock"}, {["x"] = 3, ["y"] = 1, ["param1"] = 88, ["z"] = 4, ["name"] = "default:bronzeblock"}, {["x"] = 3, ["y"] = 2, ["param1"] = 88, ["z"] = 0, ["name"] = "default:bronzeblock"}, {["x"] = 3, ["y"] = 2, ["param1"] = 88, ["z"] = 4, ["name"] = "default:bronzeblock"}, {["x"] = 3, ["y"] = 3, ["param1"] = 88, ["z"] = 0, ["name"] = "default:bronzeblock"}, {["x"] = 3, ["y"] = 3, ["param1"] = 88, ["z"] = 4, ["name"] = "default:bronzeblock"}, {["x"] = 3, ["y"] = 4, ["param1"] = 88, ["z"] = 0, ["name"] = "default:bronzeblock"}, {["x"] = 3, ["y"] = 4, ["param1"] = 88, ["z"] = 4, ["name"] = "default:bronzeblock"}, {["x"] = 3, ["y"] = 5, ["param1"] = 88, ["z"] = 0, ["name"] = "default:bronzeblock"}, {["x"] = 3, ["y"] = 5, ["param1"] = 88, ["z"] = 4, ["name"] = "default:bronzeblock"}, {["x"] = 3, ["y"] = 6, ["param1"] = 88, ["z"] = 0, ["name"] = "default:bronzeblock"}, {["x"] = 3, ["y"] = 6, ["param1"] = 88, ["z"] = 4, ["name"] = "default:bronzeblock"}, {["x"] = 3, ["y"] = 7, ["param1"] = 88, ["z"] = 0, ["name"] = "default:bronzeblock"}, {["x"] = 3, ["y"] = 7, ["param1"] = 88, ["z"] = 4, ["name"] = "default:bronzeblock"}, {["x"] = 3, ["y"] = 8, ["param1"] = 88, ["z"] = 0, ["name"] = "default:bronzeblock"}, {["x"] = 3, ["y"] = 8, ["param1"] = 88, ["z"] = 4, ["name"] = "default:bronzeblock"}, {["x"] = 3, ["y"] = 9, ["param1"] = 88, ["z"] = 0, ["name"] = "default:bronzeblock"}, {["x"] = 3, ["y"] = 9, ["param1"] = 88, ["z"] = 4, ["name"] = "default:bronzeblock"}, {["x"] = 3, ["y"] = 10, ["param1"] = 88, ["z"] = 0, ["name"] = "default:bronzeblock"}, {["x"] = 3, ["y"] = 10, ["param1"] = 88, ["z"] = 4, ["name"] = "default:bronzeblock"}, {["x"] = 3, ["y"] = 11, ["param1"] = 88, ["z"] = 0, ["name"] = "default:bronzeblock"}, {["x"] = 3, ["y"] = 11, ["param1"] = 88, ["z"] = 4, ["name"] = "default:bronzeblock"}, {["x"] = 3, ["y"] = 12, ["param1"] = 88, ["z"] = 0, ["name"] = "default:bronzeblock"}, {["x"] = 3, ["y"] = 12, ["param1"] = 88, ["z"] = 4, ["name"] = "default:bronzeblock"}, {["x"] = 3, ["y"] = 13, ["param1"] = 88, ["z"] = 0, ["name"] = "default:bronzeblock"}, {["x"] = 3, ["y"] = 13, ["param1"] = 88, ["z"] = 4, ["name"] = "default:bronzeblock"}, {["x"] = 3, ["y"] = 14, ["param1"] = 88, ["z"] = 0, ["name"] = "default:bronzeblock"}, {["x"] = 3, ["y"] = 14, ["param1"] = 88, ["z"] = 4, ["name"] = "default:bronzeblock"}, {["x"] = 3, ["y"] = 15, ["param1"] = 88, ["z"] = 0, ["name"] = "default:bronzeblock"}, {["x"] = 3, ["y"] = 15, ["param1"] = 88, ["z"] = 4, ["name"] = "default:bronzeblock"}, {["x"] = 3, ["y"] = 16, ["param1"] = 88, ["z"] = 0, ["name"] = "default:bronzeblock"}, {["x"] = 3, ["y"] = 16, ["param1"] = 88, ["z"] = 4, ["name"] = "default:bronzeblock"}, {["x"] = 3, ["y"] = 17, ["param1"] = 88, ["z"] = 0, ["name"] = "default:bronzeblock"}, {["x"] = 3, ["y"] = 17, ["param1"] = 88, ["z"] = 4, ["name"] = "default:bronzeblock"}, {["x"] = 3, ["y"] = 18, ["param1"] = 88, ["z"] = 0, ["name"] = "default:bronzeblock"}, {["x"] = 3, ["y"] = 18, ["param1"] = 88, ["z"] = 4, ["name"] = "default:bronzeblock"}, {["x"] = 3, ["y"] = 19, ["param1"] = 88, ["z"] = 0, ["name"] = "default:bronzeblock"}, {["x"] = 3, ["y"] = 19, ["param1"] = 88, ["z"] = 4, ["name"] = "default:bronzeblock"}, {["x"] = 3, ["y"] = 20, ["param1"] = 88, ["z"] = 0, ["name"] = "default:bronzeblock"}, {["x"] = 3, ["y"] = 20, ["param1"] = 88, ["z"] = 4, ["name"] = "default:bronzeblock"}, {["x"] = 3, ["y"] = 21, ["param1"] = 88, ["z"] = 0, ["name"] = "default:bronzeblock"}, {["x"] = 3, ["y"] = 21, ["param1"] = 88, ["z"] = 4, ["name"] = "default:bronzeblock"}, {["x"] = 3, ["y"] = 22, ["param1"] = 88, ["z"] = 0, ["name"] = "default:bronzeblock"}, {["x"] = 3, ["y"] = 22, ["param1"] = 88, ["z"] = 4, ["name"] = "default:bronzeblock"}, {["x"] = 3, ["y"] = 23, ["param1"] = 88, ["z"] = 0, ["name"] = "default:bronzeblock"}, {["x"] = 3, ["y"] = 23, ["param1"] = 88, ["z"] = 4, ["name"] = "default:bronzeblock"}, {["x"] = 3, ["y"] = 24, ["param1"] = 88, ["z"] = 0, ["name"] = "default:bronzeblock"}, {["x"] = 3, ["y"] = 24, ["param1"] = 175, ["z"] = 1, ["name"] = "default:bronzeblock"}, {["x"] = 3, ["y"] = 24, ["param1"] = 159, ["z"] = 2, ["name"] = "default:bronzeblock"}, {["x"] = 3, ["y"] = 24, ["param1"] = 175, ["z"] = 3, ["name"] = "default:bronzeblock"}, {["x"] = 3, ["y"] = 24, ["param1"] = 88, ["z"] = 4, ["name"] = "default:bronzeblock"}, {["x"] = 4, ["y"] = 0, ["param1"] = 88, ["z"] = 0, ["name"] = "default:bronzeblock"}, {["x"] = 4, ["y"] = 0, ["param1"] = 88, ["z"] = 1, ["name"] = "default:bronzeblock"}, {["x"] = 4, ["y"] = 0, ["param1"] = 88, ["z"] = 2, ["name"] = "default:bronzeblock"}, {["x"] = 4, ["y"] = 0, ["param1"] = 88, ["z"] = 3, ["name"] = "default:bronzeblock"}, {["x"] = 4, ["y"] = 0, ["param1"] = 88, ["z"] = 4, ["name"] = "default:bronzeblock"}, {["x"] = 4, ["y"] = 0, ["param1"] = 88, ["z"] = 5, ["name"] = "default:bronzeblock"}, {["x"] = 4, ["y"] = 1, ["param1"] = 88, ["z"] = 0, ["name"] = "default:bronzeblock"}, {["x"] = 4, ["y"] = 1, ["param1"] = 88, ["z"] = 1, ["name"] = "default:bronzeblock"}, {["x"] = 4, ["y"] = 1, ["param1"] = 88, ["z"] = 3, ["name"] = "default:bronzeblock"}, {["x"] = 4, ["y"] = 1, ["param1"] = 88, ["z"] = 4, ["name"] = "default:bronzeblock"}, {["x"] = 4, ["y"] = 2, ["param1"] = 238, ["z"] = 0, ["name"] = "default:meselamp"}, {["x"] = 4, ["y"] = 2, ["param1"] = 88, ["z"] = 1, ["name"] = "default:bronzeblock"}, {["x"] = 4, ["y"] = 2, ["param1"] = 88, ["z"] = 3, ["name"] = "default:bronzeblock"}, {["x"] = 4, ["y"] = 2, ["param1"] = 238, ["z"] = 4, ["name"] = "default:meselamp"}, {["x"] = 4, ["y"] = 3, ["param1"] = 238, ["z"] = 0, ["name"] = "default:meselamp"}, {["x"] = 4, ["y"] = 3, ["param1"] = 88, ["z"] = 1, ["name"] = "default:bronzeblock"}, {["x"] = 4, ["y"] = 3, ["param1"] = 88, ["z"] = 2, ["name"] = "default:bronzeblock"}, {["x"] = 4, ["y"] = 3, ["param1"] = 88, ["z"] = 3, ["name"] = "default:bronzeblock"}, {["x"] = 4, ["y"] = 3, ["param1"] = 238, ["z"] = 4, ["name"] = "default:meselamp"}, {["x"] = 4, ["y"] = 4, ["param1"] = 238, ["z"] = 0, ["name"] = "default:meselamp"}, {["x"] = 4, ["y"] = 4, ["param1"] = 88, ["z"] = 1, ["name"] = "default:bronzeblock"}, {["x"] = 4, ["y"] = 4, ["param1"] = 174, ["z"] = 2, ["name"] = "default:glass"}, {["x"] = 4, ["y"] = 4, ["param1"] = 88, ["z"] = 3, ["name"] = "default:bronzeblock"}, {["x"] = 4, ["y"] = 4, ["param1"] = 238, ["z"] = 4, ["name"] = "default:meselamp"}, {["x"] = 4, ["y"] = 5, ["param1"] = 238, ["z"] = 0, ["name"] = "default:meselamp"}, {["x"] = 4, ["y"] = 5, ["param1"] = 88, ["z"] = 1, ["name"] = "default:bronzeblock"}, {["x"] = 4, ["y"] = 5, ["param1"] = 174, ["z"] = 2, ["name"] = "default:glass"}, {["x"] = 4, ["y"] = 5, ["param1"] = 88, ["z"] = 3, ["name"] = "default:bronzeblock"}, {["x"] = 4, ["y"] = 5, ["param1"] = 238, ["z"] = 4, ["name"] = "default:meselamp"}, {["x"] = 4, ["y"] = 6, ["param1"] = 238, ["z"] = 0, ["name"] = "default:meselamp"}, {["x"] = 4, ["y"] = 6, ["param1"] = 88, ["z"] = 1, ["name"] = "default:bronzeblock"}, {["x"] = 4, ["y"] = 6, ["param1"] = 174, ["z"] = 2, ["name"] = "default:glass"}, {["x"] = 4, ["y"] = 6, ["param1"] = 88, ["z"] = 3, ["name"] = "default:bronzeblock"}, {["x"] = 4, ["y"] = 6, ["param1"] = 238, ["z"] = 4, ["name"] = "default:meselamp"}, {["x"] = 4, ["y"] = 7, ["param1"] = 238, ["z"] = 0, ["name"] = "default:meselamp"}, {["x"] = 4, ["y"] = 7, ["param1"] = 88, ["z"] = 1, ["name"] = "default:bronzeblock"}, {["x"] = 4, ["y"] = 7, ["param1"] = 174, ["z"] = 2, ["name"] = "default:glass"}, {["x"] = 4, ["y"] = 7, ["param1"] = 88, ["z"] = 3, ["name"] = "default:bronzeblock"}, {["x"] = 4, ["y"] = 7, ["param1"] = 238, ["z"] = 4, ["name"] = "default:meselamp"}, {["x"] = 4, ["y"] = 8, ["param1"] = 238, ["z"] = 0, ["name"] = "default:meselamp"}, {["x"] = 4, ["y"] = 8, ["param1"] = 88, ["z"] = 1, ["name"] = "default:bronzeblock"}, {["x"] = 4, ["y"] = 8, ["param1"] = 174, ["z"] = 2, ["name"] = "default:glass"}, {["x"] = 4, ["y"] = 8, ["param1"] = 88, ["z"] = 3, ["name"] = "default:bronzeblock"}, {["x"] = 4, ["y"] = 8, ["param1"] = 238, ["z"] = 4, ["name"] = "default:meselamp"}, {["x"] = 4, ["y"] = 9, ["param1"] = 238, ["z"] = 0, ["name"] = "default:meselamp"}, {["x"] = 4, ["y"] = 9, ["param1"] = 88, ["z"] = 1, ["name"] = "default:bronzeblock"}, {["x"] = 4, ["y"] = 9, ["param1"] = 174, ["z"] = 2, ["name"] = "default:glass"}, {["x"] = 4, ["y"] = 9, ["param1"] = 88, ["z"] = 3, ["name"] = "default:bronzeblock"}, {["x"] = 4, ["y"] = 9, ["param1"] = 238, ["z"] = 4, ["name"] = "default:meselamp"}, {["x"] = 4, ["y"] = 10, ["param1"] = 238, ["z"] = 0, ["name"] = "default:meselamp"}, {["x"] = 4, ["y"] = 10, ["param1"] = 88, ["z"] = 1, ["name"] = "default:bronzeblock"}, {["x"] = 4, ["y"] = 10, ["param1"] = 174, ["z"] = 2, ["name"] = "default:glass"}, {["x"] = 4, ["y"] = 10, ["param1"] = 88, ["z"] = 3, ["name"] = "default:bronzeblock"}, {["x"] = 4, ["y"] = 10, ["param1"] = 238, ["z"] = 4, ["name"] = "default:meselamp"}, {["x"] = 4, ["y"] = 11, ["param1"] = 238, ["z"] = 0, ["name"] = "default:meselamp"}, {["x"] = 4, ["y"] = 11, ["param1"] = 88, ["z"] = 1, ["name"] = "default:bronzeblock"}, {["x"] = 4, ["y"] = 11, ["param1"] = 174, ["z"] = 2, ["name"] = "default:glass"}, {["x"] = 4, ["y"] = 11, ["param1"] = 88, ["z"] = 3, ["name"] = "default:bronzeblock"}, {["x"] = 4, ["y"] = 11, ["param1"] = 238, ["z"] = 4, ["name"] = "default:meselamp"}, {["x"] = 4, ["y"] = 12, ["param1"] = 238, ["z"] = 0, ["name"] = "default:meselamp"}, {["x"] = 4, ["y"] = 12, ["param1"] = 88, ["z"] = 1, ["name"] = "default:bronzeblock"}, {["x"] = 4, ["y"] = 12, ["param1"] = 174, ["z"] = 2, ["name"] = "default:glass"}, {["x"] = 4, ["y"] = 12, ["param1"] = 88, ["z"] = 3, ["name"] = "default:bronzeblock"}, {["x"] = 4, ["y"] = 12, ["param1"] = 238, ["z"] = 4, ["name"] = "default:meselamp"}, {["x"] = 4, ["y"] = 13, ["param1"] = 238, ["z"] = 0, ["name"] = "default:meselamp"}, {["x"] = 4, ["y"] = 13, ["param1"] = 88, ["z"] = 1, ["name"] = "default:bronzeblock"}, {["x"] = 4, ["y"] = 13, ["param1"] = 174, ["z"] = 2, ["name"] = "default:glass"}, {["x"] = 4, ["y"] = 13, ["param1"] = 88, ["z"] = 3, ["name"] = "default:bronzeblock"}, {["x"] = 4, ["y"] = 13, ["param1"] = 238, ["z"] = 4, ["name"] = "default:meselamp"}, {["x"] = 4, ["y"] = 14, ["param1"] = 238, ["z"] = 0, ["name"] = "default:meselamp"}, {["x"] = 4, ["y"] = 14, ["param1"] = 88, ["z"] = 1, ["name"] = "default:bronzeblock"}, {["x"] = 4, ["y"] = 14, ["param1"] = 174, ["z"] = 2, ["name"] = "default:glass"}, {["x"] = 4, ["y"] = 14, ["param1"] = 88, ["z"] = 3, ["name"] = "default:bronzeblock"}, {["x"] = 4, ["y"] = 14, ["param1"] = 238, ["z"] = 4, ["name"] = "default:meselamp"}, {["x"] = 4, ["y"] = 15, ["param1"] = 238, ["z"] = 0, ["name"] = "default:meselamp"}, {["x"] = 4, ["y"] = 15, ["param1"] = 88, ["z"] = 1, ["name"] = "default:bronzeblock"}, {["x"] = 4, ["y"] = 15, ["param1"] = 174, ["z"] = 2, ["name"] = "default:glass"}, {["x"] = 4, ["y"] = 15, ["param1"] = 88, ["z"] = 3, ["name"] = "default:bronzeblock"}, {["x"] = 4, ["y"] = 15, ["param1"] = 238, ["z"] = 4, ["name"] = "default:meselamp"}, {["x"] = 4, ["y"] = 16, ["param1"] = 238, ["z"] = 0, ["name"] = "default:meselamp"}, {["x"] = 4, ["y"] = 16, ["param1"] = 88, ["z"] = 1, ["name"] = "default:bronzeblock"}, {["x"] = 4, ["y"] = 16, ["param1"] = 174, ["z"] = 2, ["name"] = "default:glass"}, {["x"] = 4, ["y"] = 16, ["param1"] = 88, ["z"] = 3, ["name"] = "default:bronzeblock"}, {["x"] = 4, ["y"] = 16, ["param1"] = 238, ["z"] = 4, ["name"] = "default:meselamp"}, {["x"] = 4, ["y"] = 17, ["param1"] = 238, ["z"] = 0, ["name"] = "default:meselamp"}, {["x"] = 4, ["y"] = 17, ["param1"] = 88, ["z"] = 1, ["name"] = "default:bronzeblock"}, {["x"] = 4, ["y"] = 17, ["param1"] = 174, ["z"] = 2, ["name"] = "default:glass"}, {["x"] = 4, ["y"] = 17, ["param1"] = 88, ["z"] = 3, ["name"] = "default:bronzeblock"}, {["x"] = 4, ["y"] = 17, ["param1"] = 238, ["z"] = 4, ["name"] = "default:meselamp"}, {["x"] = 4, ["y"] = 18, ["param1"] = 238, ["z"] = 0, ["name"] = "default:meselamp"}, {["x"] = 4, ["y"] = 18, ["param1"] = 88, ["z"] = 1, ["name"] = "default:bronzeblock"}, {["x"] = 4, ["y"] = 18, ["param1"] = 174, ["z"] = 2, ["name"] = "default:glass"}, {["x"] = 4, ["y"] = 18, ["param1"] = 88, ["z"] = 3, ["name"] = "default:bronzeblock"}, {["x"] = 4, ["y"] = 18, ["param1"] = 238, ["z"] = 4, ["name"] = "default:meselamp"}, {["x"] = 4, ["y"] = 19, ["param1"] = 238, ["z"] = 0, ["name"] = "default:meselamp"}, {["x"] = 4, ["y"] = 19, ["param1"] = 88, ["z"] = 1, ["name"] = "default:bronzeblock"}, {["x"] = 4, ["y"] = 19, ["param1"] = 174, ["z"] = 2, ["name"] = "default:glass"}, {["x"] = 4, ["y"] = 19, ["param1"] = 88, ["z"] = 3, ["name"] = "default:bronzeblock"}, {["x"] = 4, ["y"] = 19, ["param1"] = 238, ["z"] = 4, ["name"] = "default:meselamp"}, {["x"] = 4, ["y"] = 20, ["param1"] = 238, ["z"] = 0, ["name"] = "default:meselamp"}, {["x"] = 4, ["y"] = 20, ["param1"] = 88, ["z"] = 1, ["name"] = "default:bronzeblock"}, {["x"] = 4, ["y"] = 20, ["param1"] = 174, ["z"] = 2, ["name"] = "default:glass"}, {["x"] = 4, ["y"] = 20, ["param1"] = 88, ["z"] = 3, ["name"] = "default:bronzeblock"}, {["x"] = 4, ["y"] = 20, ["param1"] = 238, ["z"] = 4, ["name"] = "default:meselamp"}, {["x"] = 4, ["y"] = 21, ["param1"] = 238, ["z"] = 0, ["name"] = "default:meselamp"}, {["x"] = 4, ["y"] = 21, ["param1"] = 88, ["z"] = 1, ["name"] = "default:bronzeblock"}, {["x"] = 4, ["y"] = 21, ["param1"] = 174, ["z"] = 2, ["name"] = "default:glass"}, {["x"] = 4, ["y"] = 21, ["param1"] = 88, ["z"] = 3, ["name"] = "default:bronzeblock"}, {["x"] = 4, ["y"] = 21, ["param1"] = 238, ["z"] = 4, ["name"] = "default:meselamp"}, {["x"] = 4, ["y"] = 22, ["param1"] = 238, ["z"] = 0, ["name"] = "default:meselamp"}, {["x"] = 4, ["y"] = 22, ["param1"] = 88, ["z"] = 1, ["name"] = "default:bronzeblock"}, {["x"] = 4, ["y"] = 22, ["param1"] = 174, ["z"] = 2, ["name"] = "default:glass"}, {["x"] = 4, ["y"] = 22, ["param1"] = 88, ["z"] = 3, ["name"] = "default:bronzeblock"}, {["x"] = 4, ["y"] = 22, ["param1"] = 238, ["z"] = 4, ["name"] = "default:meselamp"}, {["x"] = 4, ["y"] = 23, ["param1"] = 238, ["z"] = 0, ["name"] = "default:meselamp"}, {["x"] = 4, ["y"] = 23, ["param1"] = 88, ["z"] = 1, ["name"] = "default:bronzeblock"}, {["x"] = 4, ["y"] = 23, ["param1"] = 174, ["z"] = 2, ["name"] = "default:glass"}, {["x"] = 4, ["y"] = 23, ["param1"] = 88, ["z"] = 3, ["name"] = "default:bronzeblock"}, {["x"] = 4, ["y"] = 23, ["param1"] = 238, ["z"] = 4, ["name"] = "default:meselamp"}, {["x"] = 4, ["y"] = 24, ["param1"] = 239, ["z"] = 0, ["name"] = "default:bronzeblock"}, {["x"] = 4, ["y"] = 24, ["param1"] = 88, ["z"] = 1, ["name"] = "default:bronzeblock"}, {["x"] = 4, ["y"] = 24, ["param1"] = 175, ["z"] = 2, ["name"] = "default:bronzeblock"}, {["x"] = 4, ["y"] = 24, ["param1"] = 88, ["z"] = 3, ["name"] = "default:bronzeblock"}, {["x"] = 4, ["y"] = 24, ["param1"] = 239, ["z"] = 4, ["name"] = "default:bronzeblock"}, {["x"] = 5, ["y"] = 0, ["param1"] = 88, ["z"] = 0, ["name"] = "default:bronzeblock"}, {["x"] = 5, ["y"] = 0, ["param1"] = 88, ["z"] = 1, ["name"] = "default:bronzeblock"}, {["x"] = 5, ["y"] = 0, ["param1"] = 88, ["z"] = 2, ["name"] = "default:bronzeblock"}, {["x"] = 5, ["y"] = 0, ["param1"] = 88, ["z"] = 3, ["name"] = "default:bronzeblock"}, {["x"] = 5, ["y"] = 0, ["param1"] = 88, ["z"] = 4, ["name"] = "default:bronzeblock"}, {["x"] = 5, ["y"] = 0, ["param1"] = 88, ["z"] = 5, ["name"] = "default:bronzeblock"}}